ts_event,rtype,publisher_id,instrument_id,action,side,depth,price,size,flags,ts_in_delta,sequence,bid_px_00,ask_px_00,bid_sz_00,ask_sz_00,bid_ct_00,ask_ct_00,bid_px_01,ask_px_01,bid_sz_01,ask_sz_01,bid_ct_01,ask_ct_01,bid_px_02,ask_px_02,bid_sz_02,ask_sz_02,bid_ct_02,ask_ct_02,bid_px_03,ask_px_03,bid_sz_03,ask_sz_03,bid_ct_03,ask_ct_03,bid_px_04,ask_px_04,bid_sz_04,ask_sz_04,bid_ct_04,ask_ct_04,bid_px_05,ask_px_05,bid_sz_05,ask_sz_05,bid_ct_05,ask_ct_05,bid_px_06,ask_px_06,bid_sz_06,ask_sz_06,bid_ct_06,ask_ct_06,bid_px_07,ask_px_07,bid_sz_07,ask_sz_07,bid_ct_07,ask_ct_07,bid_px_08,ask_px_08,bid_sz_08,ask_sz_08,bid_ct_08,ask_ct_08,bid_px_09,ask_px_09,bid_sz_09,ask_sz_09,bid_ct_09,ask_ct_09,symbol
2024-10-22 13:15:17.816356187+00:00,10,40,38,A,A,0,,0,194,202875,118892,233.87,,200,0,0,0,,,0,0,0,0,,,0,0,0,0,,,0,0,0,0,,,0,0,0,0,,,0,0,0,0,,,0,0,0,0,,,0,0,0,0,,,0,0,0,0,,,0,0,0,0,AAPL
2024-10-22 13:15:17.901867030+00:00,10,41,38,A,A,0,,0,194,55271,285182,233.92,,200,0,0,0,,,0,0,0,0,,,0,0,0,0,,,0,0,0,0,,,0,0,0,0,,,0,0,0,0,,,0,0,0,0,,,0,0,0,0,,,0,0,0,0,,,0,0,0,0,AAPL
2024-10-22 13:15:19.077307097+00:00,10,40,38,A,A,0,234.47,200,194,203170,118914,233.87,234.47,200,200,0,0,,,0,0,0,0,,,0,0,0,0,,,0,0,0,0,,,0,0,0,0,,,0,0,0,0,,,0,0,0,0,,,0,0,0,0,,,0,0,0,0,,,0,0,0,0,AAPL
2024-10-22 13:15:19.077806300+00:00,10,41,38,A,A,0,234.42,200,194,55746,285258,233.92,234.42,200,200,0,0,,,0,0,0,0,,,0,0,0,0,,,0,0,0,0,,,0,0,0,0,,,0,0,0,0,,,0,0,0,0,,,0,0,0,0,,,0,0,0,0,,,0,0,0,0,AAPL
2024-10-22 13:15:19.279942480+00:00,10,40,38,A,A,0,,0,194,203086,118915,233.87,,200,0,0,0,,,0,0,0,0,,,0,0,0,0,,,0,0,0,0,,,0,0,0,0,,,0,0,0,0,,,0,0,0,0,,,0,0,0,0,,,0,0,0,0,,,0,0,0,0,AAPL
2024-10-22 13:15:19.280312877+00:00,10,41,38,A,A,0,,0,194,56026,285261,233.92,,200,0,0,0,,,0,0,0,0,,,0,0,0,0,,,0,0,0,0,,,0,0,0,0,,,0,0,0,0,,,0,0,0,0,,,0,0,0,0,,,0,0,0,0,,,0,0,0,0,AAPL
2024-10-22 13:15:19.644723567+00:00,10,40,38,A,A,0,234.47,200,194,203156,118916,233.87,234.47,200,200,0,0,,,0,0,0,0,,,0,0,0,0,,,0,0,0,0,,,0,0,0,0,,,0,0,0,0,,,0,0,0,0,,,0,0,0,0,,,0,0,0,0,,,0,0,0,0,AAPL
2024-10-22 13:15:19.644998123+00:00,10,41,38,A,A,0,234.42,200,194,55885,285268,233.92,234.42,200,200,0,0,,,0,0,0,0,,,0,0,0,0,,,0,0,0,0,,,0,0,0,0,,,0,0,0,0,,,0,0,0,0,,,0,0,0,0,,,0,0,0,0,,,0,0,0,0,AAPL
2024-10-22 13:15:19.681639066+00:00,10,39,38,A,A,0,236.4,2000,130,203611,69946,232.4,236.4,2000,2000,1,1,,,0,0,0,0,,,0,0,0,0,,,0,0,0,0,,,0,0,0,0,,,0,0,0,0,,,0,0,0,0,,,0,0,0,0,,,0,0,0,0,,,0,0,0,0,AAPL
2024-10-22 13:15:19.681688672+00:00,10,40,38,A,A,0,,0,194,202939,118920,233.87,,200,0,0,0,,,0,0,0,0,,,0,0,0,0,,,0,0,0,0,,,0,0,0,0,,,0,0,0,0,,,0,0,0,0,,,0,0,0,0,,,0,0,0,0,,,0,0,0,0,AAPL
2024-10-22 13:15:19.683669325+00:00,10,39,38,C,A,0,236.4,2000,130,203654,69947,232.4,,2000,0,1,0,,,0,0,0,0,,,0,0,0,0,,,0,0,0,0,,,0,0,0,0,,,0,0,0,0,,,0,0,0,0,,,0,0,0,0,,,0,0,0,0,,,0,0,0,0,AAPL
2024-10-22 13:15:19.697819769+00:00,10,39,38,A,A,0,236.4,2000,130,203625,69948,232.4,236.4,2000,2000,1,1,,,0,0,0,0,,,0,0,0,0,,,0,0,0,0,,,0,0,0,0,,,0,0,0,0,,,0,0,0,0,,,0,0,0,0,,,0,0,0,0,,,0,0,0,0,AAPL
2024-10-22 13:15:19.714103176+00:00,10,39,38,C,A,0,236.4,2000,130,203572,69949,232.4,,2000,0,1,0,,,0,0,0,0,,,0,0,0,0,,,0,0,0,0,,,0,0,0,0,,,0,0,0,0,,,0,0,0,0,,,0,0,0,0,,,0,0,0,0,,,0,0,0,0,AAPL
2024-10-22 13:15:19.728299715+00:00,10,39,38,A,A,0,236.4,2000,130,203536,69950,232.4,236.4,2000,2000,1,1,,,0,0,0,0,,,0,0,0,0,,,0,0,0,0,,,0,0,0,0,,,0,0,0,0,,,0,0,0,0,,,0,0,0,0,,,0,0,0,0,,,0,0,0,0,AAPL
2024-10-22 13:15:19.854656398+00:00,10,41,38,A,A,0,,0,194,55491,285278,233.92,,200,0,0,0,,,0,0,0,0,,,0,0,0,0,,,0,0,0,0,,,0,0,0,0,,,0,0,0,0,,,0,0,0,0,,,0,0,0,0,,,0,0,0,0,,,0,0,0,0,AAPL
2024-10-22 13:15:22.287677289+00:00,10,40,38,A,A,0,234.5,200,194,202780,118939,233.87,234.5,200,200,0,0,,,0,0,0,0,,,0,0,0,0,,,0,0,0,0,,,0,0,0,0,,,0,0,0,0,,,0,0,0,0,,,0,0,0,0,,,0,0,0,0,,,0,0,0,0,AAPL
2024-10-22 13:15:22.287939985+00:00,10,41,38,A,A,0,234.45,200,194,55354,285420,233.92,234.45,200,200,0,0,,,0,0,0,0,,,0,0,0,0,,,0,0,0,0,,,0,0,0,0,,,0,0,0,0,,,0,0,0,0,,,0,0,0,0,,,0,0,0,0,,,0,0,0,0,AAPL
2024-10-22 13:15:22.288283036+00:00,10,39,38,C,A,0,236.4,2000,130,203950,69962,232.4,,2000,0,1,0,,,0,0,0,0,,,0,0,0,0,,,0,0,0,0,,,0,0,0,0,,,0,0,0,0,,,0,0,0,0,,,0,0,0,0,,,0,0,0,0,,,0,0,0,0,AAPL
2024-10-22 13:15:22.325663312+00:00,10,39,38,A,A,0,236.4,2000,130,203391,69963,232.4,236.4,2000,2000,1,1,,,0,0,0,0,,,0,0,0,0,,,0,0,0,0,,,0,0,0,0,,,0,0,0,0,,,0,0,0,0,,,0,0,0,0,,,0,0,0,0,,,0,0,0,0,AAPL
2024-10-22 13:15:22.489219939+00:00,10,41,38,A,A,0,,0,194,55515,285426,233.92,,200,0,0,0,,,0,0,0,0,,,0,0,0,0,,,0,0,0,0,,,0,0,0,0,,,0,0,0,0,,,0,0,0,0,,,0,0,0,0,,,0,0,0,0,,,0,0,0,0,AAPL
2024-10-22 13:15:22.489111404+00:00,10,40,38,A,A,0,,0,194,202846,118942,233.87,,200,0,0,0,,,0,0,0,0,,,0,0,0,0,,,0,0,0,0,,,0,0,0,0,,,0,0,0,0,,,0,0,0,0,,,0,0,0,0,,,0,0,0,0,,,0,0,0,0,AAPL
2024-10-22 13:15:26.865241215+00:00,10,39,10888,C,A,0,421.2,2000,130,203406,102741,,,0,0,0,0,,,0,0,0,0,,,0,0,0,0,,,0,0,0,0,,,0,0,0,0,,,0,0,0,0,,,0,0,0,0,,,0,0,0,0,,,0,0,0,0,,,0,0,0,0,MSFT
2024-10-22 13:15:26.901392904+00:00,10,39,10888,A,A,0,421.2,2000,130,203346,102742,,421.2,0,2000,0,1,,,0,0,0,0,,,0,0,0,0,,,0,0,0,0,,,0,0,0,0,,,0,0,0,0,,,0,0,0,0,,,0,0,0,0,,,0,0,0,0,,,0,0,0,0,MSFT
2024-10-22 13:15:31.981681384+00:00,10,39,10888,C,A,0,421.2,2000,130,203768,102763,,,0,0,0,0,,,0,0,0,0,,,0,0,0,0,,,0,0,0,0,,,0,0,0,0,,,0,0,0,0,,,0,0,0,0,,,0,0,0,0,,,0,0,0,0,,,0,0,0,0,MSFT
2024-10-22 13:15:32.017872931+00:00,10,39,10888,A,A,0,421.2,2000,130,203471,102765,,421.2,0,2000,0,1,,,0,0,0,0,,,0,0,0,0,,,0,0,0,0,,,0,0,0,0,,,0,0,0,0,,,0,0,0,0,,,0,0,0,0,,,0,0,0,0,,,0,0,0,0,MSFT
2024-10-22 13:15:38.802624675+00:00,10,40,38,A,A,0,234.5,200,194,203120,119142,233.87,234.5,200,200,0,0,,,0,0,0,0,,,0,0,0,0,,,0,0,0,0,,,0,0,0,0,,,0,0,0,0,,,0,0,0,0,,,0,0,0,0,,,0,0,0,0,,,0,0,0,0,AAPL
2024-10-22 13:15:38.802870933+00:00,10,41,38,A,A,0,234.45,200,194,56035,286222,233.92,234.45,200,200,0,0,,,0,0,0,0,,,0,0,0,0,,,0,0,0,0,,,0,0,0,0,,,0,0,0,0,,,0,0,0,0,,,0,0,0,0,,,0,0,0,0,,,0,0,0,0,AAPL
2024-10-22 13:15:39.004448640+00:00,10,41,38,A,A,0,,0,194,55925,286237,233.92,,200,0,0,0,,,0,0,0,0,,,0,0,0,0,,,0,0,0,0,,,0,0,0,0,,,0,0,0,0,,,0,0,0,0,,,0,0,0,0,,,0,0,0,0,,,0,0,0,0,AAPL
2024-10-22 13:15:39.981719436+00:00,10,40,38,A,A,0,,0,194,203008,119154,233.87,,200,0,0,0,,,0,0,0,0,,,0,0,0,0,,,0,0,0,0,,,0,0,0,0,,,0,0,0,0,,,0,0,0,0,,,0,0,0,0,,,0,0,0,0,,,0,0,0,0,AAPL
2024-10-22 13:15:40.268236411+00:00,10,40,38,A,A,0,234.5,200,194,203274,119160,233.87,234.5,200,200,0,0,,,0,0,0,0,,,0,0,0,0,,,0,0,0,0,,,0,0,0,0,,,0,0,0,0,,,0,0,0,0,,,0,0,0,0,,,0,0,0,0,,,0,0,0,0,AAPL
2024-10-22 13:15:40.268500970+00:00,10,41,38,A,A,0,234.45,200,194,55664,286299,233.92,234.45,200,200,0,0,,,0,0,0,0,,,0,0,0,0,,,0,0,0,0,,,0,0,0,0,,,0,0,0,0,,,0,0,0,0,,,0,0,0,0,,,0,0,0,0,,,0,0,0,0,AAPL
2024-10-22 13:15:40.269353490+00:00,10,39,38,C,A,0,236.4,2000,130,204106,70009,232.4,,2000,0,1,0,,,0,0,0,0,,,0,0,0,0,,,0,0,0,0,,,0,0,0,0,,,0,0,0,0,,,0,0,0,0,,,0,0,0,0,,,0,0,0,0,,,0,0,0,0,AAPL
2024-10-22 13:15:40.304569643+00:00,10,39,38,A,A,0,236.4,2000,130,204042,70010,232.4,236.4,2000,2000,1,1,,,0,0,0,0,,,0,0,0,0,,,0,0,0,0,,,0,0,0,0,,,0,0,0,0,,,0,0,0,0,,,0,0,0,0,,,0,0,0,0,,,0,0,0,0,AAPL
2024-10-22 13:15:40.651700506+00:00,10,40,38,A,A,0,,0,194,203085,119161,233.87,,200,0,0,0,,,0,0,0,0,,,0,0,0,0,,,0,0,0,0,,,0,0,0,0,,,0,0,0,0,,,0,0,0,0,,,0,0,0,0,,,0,0,0,0,,,0,0,0,0,AAPL
2024-10-22 13:15:40.651860496+00:00,10,41,38,A,A,0,,0,194,55701,286319,233.92,,200,0,0,0,,,0,0,0,0,,,0,0,0,0,,,0,0,0,0,,,0,0,0,0,,,0,0,0,0,,,0,0,0,0,,,0,0,0,0,,,0,0,0,0,,,0,0,0,0,AAPL
2024-10-22 13:15:41.073394973+00:00,10,40,38,A,A,0,234.5,200,194,203078,119165,233.87,234.5,200,200,0,0,,,0,0,0,0,,,0,0,0,0,,,0,0,0,0,,,0,0,0,0,,,0,0,0,0,,,0,0,0,0,,,0,0,0,0,,,0,0,0,0,,,0,0,0,0,AAPL
2024-10-22 13:15:41.073851791+00:00,10,41,38,A,A,0,234.45,200,194,55960,286337,233.92,234.45,200,200,0,0,,,0,0,0,0,,,0,0,0,0,,,0,0,0,0,,,0,0,0,0,,,0,0,0,0,,,0,0,0,0,,,0,0,0,0,,,0,0,0,0,,,0,0,0,0,AAPL
2024-10-22 13:15:41.260685973+00:00,10,40,38,A,A,0,,0,194,202933,119171,233.87,,200,0,0,0,,,0,0,0,0,,,0,0,0,0,,,0,0,0,0,,,0,0,0,0,,,0,0,0,0,,,0,0,0,0,,,0,0,0,0,,,0,0,0,0,,,0,0,0,0,AAPL
2024-10-22 13:15:41.260927709+00:00,10,41,38,A,A,0,,0,194,54582,286355,233.92,,200,0,0,0,,,0,0,0,0,,,0,0,0,0,,,0,0,0,0,,,0,0,0,0,,,0,0,0,0,,,0,0,0,0,,,0,0,0,0,,,0,0,0,0,,,0,0,0,0,AAPL
2024-10-22 13:15:48.438896892+00:00,10,40,38,A,A,0,234.5,200,194,203219,119230,233.87,234.5,200,200,0,0,,,0,0,0,0,,,0,0,0,0,,,0,0,0,0,,,0,0,0,0,,,0,0,0,0,,,0,0,0,0,,,0,0,0,0,,,0,0,0,0,,,0,0,0,0,AAPL
2024-10-22 13:15:48.439154021+00:00,10,41,38,A,A,0,234.45,200,194,60847,286684,233.92,234.45,200,200,0,0,,,0,0,0,0,,,0,0,0,0,,,0,0,0,0,,,0,0,0,0,,,0,0,0,0,,,0,0,0,0,,,0,0,0,0,,,0,0,0,0,,,0,0,0,0,AAPL
2024-10-22 13:15:48.640553063+00:00,10,39,38,C,B,0,232.4,2000,130,204270,70044,,236.4,0,2000,0,1,,,0,0,0,0,,,0,0,0,0,,,0,0,0,0,,,0,0,0,0,,,0,0,0,0,,,0,0,0,0,,,0,0,0,0,,,0,0,0,0,,,0,0,0,0,AAPL
2024-10-22 13:15:48.651304997+00:00,10,39,38,A,B,0,232.2,2000,130,204197,70045,232.2,236.4,2000,2000,1,1,,,0,0,0,0,,,0,0,0,0,,,0,0,0,0,,,0,0,0,0,,,0,0,0,0,,,0,0,0,0,,,0,0,0,0,,,0,0,0,0,,,0,0,0,0,AAPL
2024-10-22 13:15:49.635244859+00:00,10,40,38,A,A,0,,0,194,203487,119233,233.87,,200,0,0,0,,,0,0,0,0,,,0,0,0,0,,,0,0,0,0,,,0,0,0,0,,,0,0,0,0,,,0,0,0,0,,,0,0,0,0,,,0,0,0,0,,,0,0,0,0,AAPL
2024-10-22 13:15:49.635632043+00:00,10,41,38,A,A,0,,0,194,55957,286710,233.92,,200,0,0,0,,,0,0,0,0,,,0,0,0,0,,,0,0,0,0,,,0,0,0,0,,,0,0,0,0,,,0,0,0,0,,,0,0,0,0,,,0,0,0,0,,,0,0,0,0,AAPL
2024-10-22 13:15:58.517735336+00:00,10,40,38,A,A,0,234.5,200,194,203086,119307,233.87,234.5,200,200,0,0,,,0,0,0,0,,,0,0,0,0,,,0,0,0,0,,,0,0,0,0,,,0,0,0,0,,,0,0,0,0,,,0,0,0,0,,,0,0,0,0,,,0,0,0,0,AAPL
2024-10-22 13:15:58.517982817+00:00,10,41,38,A,A,0,234.45,200,194,55870,287216,233.92,234.45,200,200,0,0,,,0,0,0,0,,,0,0,0,0,,,0,0,0,0,,,0,0,0,0,,,0,0,0,0,,,0,0,0,0,,,0,0,0,0,,,0,0,0,0,,,0,0,0,0,AAPL
2024-10-22 13:15:59.621556985+00:00,10,40,38,A,A,0,,0,194,202881,119322,233.87,,200,0,0,0,,,0,0,0,0,,,0,0,0,0,,,0,0,0,0,,,0,0,0,0,,,0,0,0,0,,,0,0,0,0,,,0,0,0,0,,,0,0,0,0,,,0,0,0,0,AAPL
2024-10-22 13:15:59.922647078+00:00,10,41,38,A,A,0,,0,194,55654,287326,233.92,,200,0,0,0,,,0,0,0,0,,,0,0,0,0,,,0,0,0,0,,,0,0,0,0,,,0,0,0,0,,,0,0,0,0,,,0,0,0,0,,,0,0,0,0,,,0,0,0,0,AAPL
2024-10-22 13:16:00.023353361+00:00,10,40,38,A,B,0,,0,194,202904,119342,,,0,0,0,0,,,0,0,0,0,,,0,0,0,0,,,0,0,0,0,,,0,0,0,0,,,0,0,0,0,,,0,0,0,0,,,0,0,0,0,,,0,0,0,0,,,0,0,0,0,AAPL
2024-10-22 13:16:00.023507810+00:00,10,41,38,A,B,0,,0,194,55811,287383,,,0,0,0,0,,,0,0,0,0,,,0,0,0,0,,,0,0,0,0,,,0,0,0,0,,,0,0,0,0,,,0,0,0,0,,,0,0,0,0,,,0,0,0,0,,,0,0,0,0,AAPL
2024-10-22 13:16:02.588809064+00:00,10,40,38,A,B,0,,0,194,203646,119427,233.89,,200,0,0,0,,,0,0,0,0,,,0,0,0,0,,,0,0,0,0,,,0,0,0,0,,,0,0,0,0,,,0,0,0,0,,,0,0,0,0,,,0,0,0,0,,,0,0,0,0,AAPL
2024-10-22 13:16:02.689932707+00:00,10,41,38,A,B,0,,0,194,55855,287839,233.94,,200,0,0,0,,,0,0,0,0,,,0,0,0,0,,,0,0,0,0,,,0,0,0,0,,,0,0,0,0,,,0,0,0,0,,,0,0,0,0,,,0,0,0,0,,,0,0,0,0,AAPL
2024-10-22 13:16:03.323463991+00:00,10,39,38,A,B,0,232.4,2000,130,204465,70096,232.4,236.4,2000,2000,1,1,232.2,,2000,0,1,0,,,0,0,0,0,,,0,0,0,0,,,0,0,0,0,,,0,0,0,0,,,0,0,0,0,,,0,0,0,0,,,0,0,0,0,,,0,0,0,0,AAPL
2024-10-22 13:16:03.323662124+00:00,10,39,38,C,B,1,232.2,2000,130,204057,70097,232.4,236.4,2000,2000,1,1,,,0,0,0,0,,,0,0,0,0,,,0,0,0,0,,,0,0,0,0,,,0,0,0,0,,,0,0,0,0,,,0,0,0,0,,,0,0,0,0,,,0,0,0,0,AAPL
2024-10-22 13:16:03.518172270+00:00,10,40,38,A,A,0,234.5,200,194,203668,119431,233.89,234.5,200,200,0,0,,,0,0,0,0,,,0,0,0,0,,,0,0,0,0,,,0,0,0,0,,,0,0,0,0,,,0,0,0,0,,,0,0,0,0,,,0,0,0,0,,,0,0,0,0,AAPL
2024-10-22 13:16:03.518635756+00:00,10,41,38,A,A,0,234.45,200,194,55894,287885,233.94,234.45,200,200,0,0,,,0,0,0,0,,,0,0,0,0,,,0,0,0,0,,,0,0,0,0,,,0,0,0,0,,,0,0,0,0,,,0,0,0,0,,,0,0,0,0,,,0,0,0,0,AAPL
2024-10-22 13:16:03.720768881+00:00,10,40,38,A,A,0,,0,194,203175,119432,233.89,,200,0,0,0,,,0,0,0,0,,,0,0,0,0,,,0,0,0,0,,,0,0,0,0,,,0,0,0,0,,,0,0,0,0,,,0,0,0,0,,,0,0,0,0,,,0,0,0,0,AAPL
2024-10-22 13:16:03.720934967+00:00,10,41,38,A,A,0,,0,194,55502,287895,233.94,,200,0,0,0,,,0,0,0,0,,,0,0,0,0,,,0,0,0,0,,,0,0,0,0,,,0,0,0,0,,,0,0,0,0,,,0,0,0,0,,,0,0,0,0,,,0,0,0,0,AAPL
2024-10-22 13:16:05.343186022+00:00,10,40,38,A,A,0,234.5,200,194,203110,119443,233.89,234.5,200,200,0,0,,,0,0,0,0,,,0,0,0,0,,,0,0,0,0,,,0,0,0,0,,,0,0,0,0,,,0,0,0,0,,,0,0,0,0,,,0,0,0,0,,,0,0,0,0,AAPL
2024-10-22 13:16:05.343430298+00:00,10,41,38,A,A,0,234.45,200,194,55252,287981,233.94,234.45,200,200,0,0,,,0,0,0,0,,,0,0,0,0,,,0,0,0,0,,,0,0,0,0,,,0,0,0,0,,,0,0,0,0,,,0,0,0,0,,,0,0,0,0,,,0,0,0,0,AAPL
2024-10-22 13:16:05.507278859+00:00,10,40,38,A,A,0,,0,194,203202,119445,233.89,,200,0,0,0,,,0,0,0,0,,,0,0,0,0,,,0,0,0,0,,,0,0,0,0,,,0,0,0,0,,,0,0,0,0,,,0,0,0,0,,,0,0,0,0,,,0,0,0,0,AAPL
2024-10-22 13:16:05.507513814+00:00,10,41,38,A,A,0,,0,194,55862,287987,233.94,,200,0,0,0,,,0,0,0,0,,,0,0,0,0,,,0,0,0,0,,,0,0,0,0,,,0,0,0,0,,,0,0,0,0,,,0,0,0,0,,,0,0,0,0,,,0,0,0,0,AAPL
2024-10-22 13:16:06.659321798+00:00,10,40,38,A,A,0,234.5,200,194,203515,119454,233.89,234.5,200,200,0,0,,,0,0,0,0,,,0,0,0,0,,,0,0,0,0,,,0,0,0,0,,,0,0,0,0,,,0,0,0,0,,,0,0,0,0,,,0,0,0,0,,,0,0,0,0,AAPL
2024-10-22 13:16:06.659789744+00:00,10,41,38,A,A,0,234.45,200,194,55513,288054,233.94,234.45,200,200,0,0,,,0,0,0,0,,,0,0,0,0,,,0,0,0,0,,,0,0,0,0,,,0,0,0,0,,,0,0,0,0,,,0,0,0,0,,,0,0,0,0,,,0,0,0,0,AAPL
2024-10-22 13:16:06.660155018+00:00,10,39,38,C,A,0,236.4,2000,130,204419,70099,232.4,,2000,0,1,0,,,0,0,0,0,,,0,0,0,0,,,0,0,0,0,,,0,0,0,0,,,0,0,0,0,,,0,0,0,0,,,0,0,0,0,,,0,0,0,0,,,0,0,0,0,AAPL
2024-10-22 13:16:06.670330680+00:00,10,39,38,A,B,0,232.6,2000,130,204046,70100,232.6,,2000,0,1,0,232.4,,2000,0,1,0,,,0,0,0,0,,,0,0,0,0,,,0,0,0,0,,,0,0,0,0,,,0,0,0,0,,,0,0,0,0,,,0,0,0,0,,,0,0,0,0,AAPL
2024-10-22 13:16:06.670499774+00:00,10,39,38,C,B,1,232.4,2000,130,204082,70101,232.6,,2000,0,1,0,,,0,0,0,0,,,0,0,0,0,,,0,0,0,0,,,0,0,0,0,,,0,0,0,0,,,0,0,0,0,,,0,0,0,0,,,0,0,0,0,,,0,0,0,0,AAPL
2024-10-22 13:16:06.696301326+00:00,10,39,38,A,A,0,236.4,2000,130,204119,70102,232.6,236.4,2000,2000,1,1,,,0,0,0,0,,,0,0,0,0,,,0,0,0,0,,,0,0,0,0,,,0,0,0,0,,,0,0,0,0,,,0,0,0,0,,,0,0,0,0,,,0,0,0,0,AAPL
2024-10-22 13:16:06.790666809+00:00,10,40,38,A,A,0,,0,194,203226,119464,233.89,,200,0,0,0,,,0,0,0,0,,,0,0,0,0,,,0,0,0,0,,,0,0,0,0,,,0,0,0,0,,,0,0,0,0,,,0,0,0,0,,,0,0,0,0,,,0,0,0,0,AAPL
2024-10-22 13:16:06.790852321+00:00,10,41,38,A,A,0,,0,194,55362,288079,233.94,,200,0,0,0,,,0,0,0,0,,,0,0,0,0,,,0,0,0,0,,,0,0,0,0,,,0,0,0,0,,,0,0,0,0,,,0,0,0,0,,,0,0,0,0,,,0,0,0,0,AAPL
2024-10-22 13:16:09.028092741+00:00,10,40,38,A,A,0,234.5,200,194,203491,119490,233.89,234.5,200,200,0,0,,,0,0,0,0,,,0,0,0,0,,,0,0,0,0,,,0,0,0,0,,,0,0,0,0,,,0,0,0,0,,,0,0,0,0,,,0,0,0,0,,,0,0,0,0,AAPL
2024-10-22 13:16:09.028362621+00:00,10,41,38,A,A,0,234.45,200,194,55764,288196,233.94,234.45,200,200,0,0,,,0,0,0,0,,,0,0,0,0,,,0,0,0,0,,,0,0,0,0,,,0,0,0,0,,,0,0,0,0,,,0,0,0,0,,,0,0,0,0,,,0,0,0,0,AAPL
2024-10-22 13:16:09.028714480+00:00,10,39,38,C,A,0,236.4,2000,130,204413,70110,232.6,,2000,0,1,0,,,0,0,0,0,,,0,0,0,0,,,0,0,0,0,,,0,0,0,0,,,0,0,0,0,,,0,0,0,0,,,0,0,0,0,,,0,0,0,0,,,0,0,0,0,AAPL
2024-10-22 13:16:09.065234678+00:00,10,39,38,A,A,0,236.4,2000,130,204019,70111,232.6,236.4,2000,2000,1,1,,,0,0,0,0,,,0,0,0,0,,,0,0,0,0,,,0,0,0,0,,,0,0,0,0,,,0,0,0,0,,,0,0,0,0,,,0,0,0,0,,,0,0,0,0,AAPL
2024-10-22 13:16:09.065283628+00:00,10,40,38,A,A,0,,0,194,203330,119491,233.89,,200,0,0,0,,,0,0,0,0,,,0,0,0,0,,,0,0,0,0,,,0,0,0,0,,,0,0,0,0,,,0,0,0,0,,,0,0,0,0,,,0,0,0,0,,,0,0,0,0,AAPL
2024-10-22 13:16:09.206896909+00:00,10,41,38,A,A,0,,0,194,55490,288218,233.94,,200,0,0,0,,,0,0,0,0,,,0,0,0,0,,,0,0,0,0,,,0,0,0,0,,,0,0,0,0,,,0,0,0,0,,,0,0,0,0,,,0,0,0,0,,,0,0,0,0,AAPL
2024-10-22 13:16:09.702783394+00:00,10,40,38,A,A,0,234.5,200,194,203229,119506,233.89,234.5,200,200,0,0,,,0,0,0,0,,,0,0,0,0,,,0,0,0,0,,,0,0,0,0,,,0,0,0,0,,,0,0,0,0,,,0,0,0,0,,,0,0,0,0,,,0,0,0,0,AAPL
2024-10-22 13:16:09.703022107+00:00,10,41,38,A,A,0,234.45,200,194,55803,288243,233.94,234.45,200,200,0,0,,,0,0,0,0,,,0,0,0,0,,,0,0,0,0,,,0,0,0,0,,,0,0,0,0,,,0,0,0,0,,,0,0,0,0,,,0,0,0,0,,,0,0,0,0,AAPL
2024-10-22 13:16:09.804137263+00:00,10,40,38,A,A,0,,0,194,203188,119508,233.89,,200,0,0,0,,,0,0,0,0,,,0,0,0,0,,,0,0,0,0,,,0,0,0,0,,,0,0,0,0,,,0,0,0,0,,,0,0,0,0,,,0,0,0,0,,,0,0,0,0,AAPL
2024-10-22 13:16:09.804494309+00:00,10,41,38,A,A,0,,0,194,55391,288246,233.94,,200,0,0,0,,,0,0,0,0,,,0,0,0,0,,,0,0,0,0,,,0,0,0,0,,,0,0,0,0,,,0,0,0,0,,,0,0,0,0,,,0,0,0,0,,,0,0,0,0,AAPL
2024-10-22 13:16:10.282423251+00:00,10,40,38,A,A,0,234.5,200,194,203317,119521,233.89,234.5,200,200,0,0,,,0,0,0,0,,,0,0,0,0,,,0,0,0,0,,,0,0,0,0,,,0,0,0,0,,,0,0,0,0,,,0,0,0,0,,,0,0,0,0,,,0,0,0,0,AAPL
2024-10-22 13:16:10.282694175+00:00,10,41,38,A,A,0,234.45,200,194,55536,288272,233.94,234.45,200,200,0,0,,,0,0,0,0,,,0,0,0,0,,,0,0,0,0,,,0,0,0,0,,,0,0,0,0,,,0,0,0,0,,,0,0,0,0,,,0,0,0,0,,,0,0,0,0,AAPL
2024-10-22 13:16:10.283053746+00:00,10,39,38,C,A,0,236.4,2000,130,203970,70115,232.6,,2000,0,1,0,,,0,0,0,0,,,0,0,0,0,,,0,0,0,0,,,0,0,0,0,,,0,0,0,0,,,0,0,0,0,,,0,0,0,0,,,0,0,0,0,,,0,0,0,0,AAPL
2024-10-22 13:16:10.318362609+00:00,10,39,38,A,A,0,236.4,2000,130,203920,70116,232.6,236.4,2000,2000,1,1,,,0,0,0,0,,,0,0,0,0,,,0,0,0,0,,,0,0,0,0,,,0,0,0,0,,,0,0,0,0,,,0,0,0,0,,,0,0,0,0,,,0,0,0,0,AAPL
2024-10-22 13:16:10.318411559+00:00,10,40,38,A,A,0,,0,194,203238,119523,233.89,,200,0,0,0,,,0,0,0,0,,,0,0,0,0,,,0,0,0,0,,,0,0,0,0,,,0,0,0,0,,,0,0,0,0,,,0,0,0,0,,,0,0,0,0,,,0,0,0,0,AAPL
2024-10-22 13:16:10.474584385+00:00,10,41,38,A,A,0,,0,194,55735,288282,233.94,,200,0,0,0,,,0,0,0,0,,,0,0,0,0,,,0,0,0,0,,,0,0,0,0,,,0,0,0,0,,,0,0,0,0,,,0,0,0,0,,,0,0,0,0,,,0,0,0,0,AAPL
2024-10-22 13:16:14.977797827+00:00,10,39,38,C,B,0,232.6,2000,130,204464,70128,,236.4,0,2000,0,1,,,0,0,0,0,,,0,0,0,0,,,0,0,0,0,,,0,0,0,0,,,0,0,0,0,,,0,0,0,0,,,0,0,0,0,,,0,0,0,0,,,0,0,0,0,AAPL
2024-10-22 13:16:14.988700524+00:00,10,39,38,A,B,0,232.4,2000,130,204049,70129,232.4,236.4,2000,2000,1,1,,,0,0,0,0,,,0,0,0,0,,,0,0,0,0,,,0,0,0,0,,,0,0,0,0,,,0,0,0,0,,,0,0,0,0,,,0,0,0,0,,,0,0,0,0,AAPL
2024-10-22 13:16:15.183579986+00:00,10,39,38,A,B,0,232.6,2000,130,204325,70132,232.6,236.4,2000,2000,1,1,232.4,,2000,0,1,0,,,0,0,0,0,,,0,0,0,0,,,0,0,0,0,,,0,0,0,0,,,0,0,0,0,,,0,0,0,0,,,0,0,0,0,,,0,0,0,0,AAPL
2024-10-22 13:16:15.183772144+00:00,10,39,38,C,B,1,232.4,2000,130,203997,70133,232.6,236.4,2000,2000,1,1,,,0,0,0,0,,,0,0,0,0,,,0,0,0,0,,,0,0,0,0,,,0,0,0,0,,,0,0,0,0,,,0,0,0,0,,,0,0,0,0,,,0,0,0,0,AAPL
2024-10-22 13:16:15.792704083+00:00,10,41,38,A,A,0,234.45,200,194,55842,288494,233.94,234.45,200,200,0,0,,,0,0,0,0,,,0,0,0,0,,,0,0,0,0,,,0,0,0,0,,,0,0,0,0,,,0,0,0,0,,,0,0,0,0,,,0,0,0,0,,,0,0,0,0,AAPL
2024-10-22 13:16:15.793059009+00:00,10,39,38,C,A,0,236.4,2000,130,204202,70135,232.6,,2000,0,1,0,,,0,0,0,0,,,0,0,0,0,,,0,0,0,0,,,0,0,0,0,,,0,0,0,0,,,0,0,0,0,,,0,0,0,0,,,0,0,0,0,,,0,0,0,0,AAPL
2024-10-22 13:16:15.829786456+00:00,10,39,38,A,A,0,236.4,2000,130,204100,70136,232.6,236.4,2000,2000,1,1,,,0,0,0,0,,,0,0,0,0,,,0,0,0,0,,,0,0,0,0,,,0,0,0,0,,,0,0,0,0,,,0,0,0,0,,,0,0,0,0,,,0,0,0,0,AAPL
2024-10-22 13:16:15.898981417+00:00,10,40,38,A,B,0,,0,194,203772,119581,,,0,0,0,0,,,0,0,0,0,,,0,0,0,0,,,0,0,0,0,,,0,0,0,0,,,0,0,0,0,,,0,0,0,0,,,0,0,0,0,,,0,0,0,0,,,0,0,0,0,AAPL
2024-10-22 13:16:15.963896300+00:00,10,41,38,A,A,0,,0,194,56467,288499,233.94,,200,0,0,0,,,0,0,0,0,,,0,0,0,0,,,0,0,0,0,,,0,0,0,0,,,0,0,0,0,,,0,0,0,0,,,0,0,0,0,,,0,0,0,0,,,0,0,0,0,AAPL
2024-10-22 13:16:16.402926943+00:00,10,40,38,A,B,0,,0,194,203962,119585,233.89,,200,0,0,0,,,0,0,0,0,,,0,0,0,0,,,0,0,0,0,,,0,0,0,0,,,0,0,0,0,,,0,0,0,0,,,0,0,0,0,,,0,0,0,0,,,0,0,0,0,AAPL
2024-10-22 13:16:16.403165754+00:00,10,41,38,A,A,0,234.45,200,194,55285,288511,233.94,234.45,200,200,0,0,,,0,0,0,0,,,0,0,0,0,,,0,0,0,0,,,0,0,0,0,,,0,0,0,0,,,0,0,0,0,,,0,0,0,0,,,0,0,0,0,,,0,0,0,0,AAPL
2024-10-22 13:16:16.403055599+00:00,10,40,38,A,A,0,234.5,200,194,203720,119586,233.89,234.5,200,200,0,0,,,0,0,0,0,,,0,0,0,0,,,0,0,0,0,,,0,0,0,0,,,0,0,0,0,,,0,0,0,0,,,0,0,0,0,,,0,0,0,0,,,0,0,0,0,AAPL
2024-10-22 13:16:16.403592035+00:00,10,39,38,C,A,0,236.4,2000,130,204387,70138,232.6,,2000,0,1,0,,,0,0,0,0,,,0,0,0,0,,,0,0,0,0,,,0,0,0,0,,,0,0,0,0,,,0,0,0,0,,,0,0,0,0,,,0,0,0,0,,,0,0,0,0,AAPL
2024-10-22 13:16:16.440717765+00:00,10,39,38,A,A,0,236.4,2000,130,204193,70139,232.6,236.4,2000,2000,1,1,,,0,0,0,0,,,0,0,0,0,,,0,0,0,0,,,0,0,0,0,,,0,0,0,0,,,0,0,0,0,,,0,0,0,0,,,0,0,0,0,,,0,0,0,0,AAPL
2024-10-22 13:16:16.509418151+00:00,10,40,38,A,B,0,234.5,200,194,203808,119587,,234.5,0,200,0,0,,,0,0,0,0,,,0,0,0,0,,,0,0,0,0,,,0,0,0,0,,,0,0,0,0,,,0,0,0,0,,,0,0,0,0,,,0,0,0,0,,,0,0,0,0,AAPL
2024-10-22 13:16:16.509427006+00:00,10,40,38,A,A,0,,0,194,203825,119588,,,0,0,0,0,,,0,0,0,0,,,0,0,0,0,,,0,0,0,0,,,0,0,0,0,,,0,0,0,0,,,0,0,0,0,,,0,0,0,0,,,0,0,0,0,,,0,0,0,0,AAPL
2024-10-22 13:16:16.509660776+00:00,10,41,38,A,A,0,,0,194,55103,288517,233.94,,200,0,0,0,,,0,0,0,0,,,0,0,0,0,,,0,0,0,0,,,0,0,0,0,,,0,0,0,0,,,0,0,0,0,,,0,0,0,0,,,0,0,0,0,,,0,0,0,0,AAPL
2024-10-22 13:16:17.977710415+00:00,10,40,38,A,B,0,,0,194,203715,119607,233.89,,200,0,0,0,,,0,0,0,0,,,0,0,0,0,,,0,0,0,0,,,0,0,0,0,,,0,0,0,0,,,0,0,0,0,,,0,0,0,0,,,0,0,0,0,,,0,0,0,0,AAPL
2024-10-22 13:16:17.978179068+00:00,10,39,38,C,B,0,232.6,2000,130,204501,70141,,236.4,0,2000,0,1,,,0,0,0,0,,,0,0,0,0,,,0,0,0,0,,,0,0,0,0,,,0,0,0,0,,,0,0,0,0,,,0,0,0,0,,,0,0,0,0,,,0,0,0,0,AAPL
2024-10-22 13:16:17.990605596+00:00,10,39,38,A,B,0,232.4,2000,130,204077,70142,232.4,236.4,2000,2000,1,1,,,0,0,0,0,,,0,0,0,0,,,0,0,0,0,,,0,0,0,0,,,0,0,0,0,,,0,0,0,0,,,0,0,0,0,,,0,0,0,0,,,0,0,0,0,AAPL
2024-10-22 13:16:18.248932775+00:00,10,39,38,A,B,0,232.6,2000,130,204531,70144,232.6,236.4,2000,2000,1,1,232.4,,2000,0,1,0,,,0,0,0,0,,,0,0,0,0,,,0,0,0,0,,,0,0,0,0,,,0,0,0,0,,,0,0,0,0,,,0,0,0,0,,,0,0,0,0,AAPL
2024-10-22 13:16:18.249127733+00:00,10,39,38,C,B,1,232.4,2000,130,204044,70145,232.6,236.4,2000,2000,1,1,,,0,0,0,0,,,0,0,0,0,,,0,0,0,0,,,0,0,0,0,,,0,0,0,0,,,0,0,0,0,,,0,0,0,0,,,0,0,0,0,,,0,0,0,0,AAPL
2024-10-22 13:16:18.924771938+00:00,10,40,38,A,A,0,234.5,200,194,203669,119620,233.89,234.5,200,200,0,0,,,0,0,0,0,,,0,0,0,0,,,0,0,0,0,,,0,0,0,0,,,0,0,0,0,,,0,0,0,0,,,0,0,0,0,,,0,0,0,0,,,0,0,0,0,AAPL
2024-10-22 13:16:18.925016798+00:00,10,41,38,A,A,0,234.45,200,194,60439,288617,233.94,234.45,200,200,0,0,,,0,0,0,0,,,0,0,0,0,,,0,0,0,0,,,0,0,0,0,,,0,0,0,0,,,0,0,0,0,,,0,0,0,0,,,0,0,0,0,,,0,0,0,0,AAPL
2024-10-22 13:16:19.025640709+00:00,10,40,38,A,A,0,,0,194,203754,119622,233.89,,200,0,0,0,,,0,0,0,0,,,0,0,0,0,,,0,0,0,0,,,0,0,0,0,,,0,0,0,0,,,0,0,0,0,,,0,0,0,0,,,0,0,0,0,,,0,0,0,0,AAPL
2024-10-22 13:16:19.119295776+00:00,10,41,38,A,A,0,,0,194,54437,288628,233.94,,200,0,0,0,,,0,0,0,0,,,0,0,0,0,,,0,0,0,0,,,0,0,0,0,,,0,0,0,0,,,0,0,0,0,,,0,0,0,0,,,0,0,0,0,,,0,0,0,0,AAPL
2024-10-22 13:16:28.456639833+00:00,10,40,38,A,A,0,234.5,200,194,203780,119775,233.89,234.5,200,200,0,0,,,0,0,0,0,,,0,0,0,0,,,0,0,0,0,,,0,0,0,0,,,0,0,0,0,,,0,0,0,0,,,0,0,0,0,,,0,0,0,0,,,0,0,0,0,AAPL
2024-10-22 13:16:28.457121268+00:00,10,41,38,A,A,0,234.45,200,194,60568,289256,233.94,234.45,200,200,0,0,,,0,0,0,0,,,0,0,0,0,,,0,0,0,0,,,0,0,0,0,,,0,0,0,0,,,0,0,0,0,,,0,0,0,0,,,0,0,0,0,,,0,0,0,0,AAPL
2024-10-22 13:16:28.457499315+00:00,10,39,38,C,A,0,236.4,2000,130,203339,70204,232.6,,2000,0,1,0,,,0,0,0,0,,,0,0,0,0,,,0,0,0,0,,,0,0,0,0,,,0,0,0,0,,,0,0,0,0,,,0,0,0,0,,,0,0,0,0,,,0,0,0,0,AAPL
2024-10-22 13:16:28.493641850+00:00,10,39,38,A,A,0,236.4,2000,130,203323,70205,232.6,236.4,2000,2000,1,1,,,0,0,0,0,,,0,0,0,0,,,0,0,0,0,,,0,0,0,0,,,0,0,0,0,,,0,0,0,0,,,0,0,0,0,,,0,0,0,0,,,0,0,0,0,AAPL
2024-10-22 13:16:28.493690600+00:00,10,40,38,A,A,0,,0,194,203777,119776,233.89,,200,0,0,0,,,0,0,0,0,,,0,0,0,0,,,0,0,0,0,,,0,0,0,0,,,0,0,0,0,,,0,0,0,0,,,0,0,0,0,,,0,0,0,0,,,0,0,0,0,AAPL
2024-10-22 13:16:28.658144051+00:00,10,41,38,A,A,0,,0,194,55479,289275,233.94,,200,0,0,0,,,0,0,0,0,,,0,0,0,0,,,0,0,0,0,,,0,0,0,0,,,0,0,0,0,,,0,0,0,0,,,0,0,0,0,,,0,0,0,0,,,0,0,0,0,AAPL
2024-10-22 13:16:41.709434083+00:00,10,39,10888,C,A,0,421.2,2000,130,203464,103222,,,0,0,0,0,,,0,0,0,0,,,0,0,0,0,,,0,0,0,0,,,0,0,0,0,,,0,0,0,0,,,0,0,0,0,,,0,0,0,0,,,0,0,0,0,,,0,0,0,0,MSFT
2024-10-22 13:16:41.746613671+00:00,10,39,10888,A,A,0,421.2,2000,130,203309,103223,,421.2,0,2000,0,1,,,0,0,0,0,,,0,0,0,0,,,0,0,0,0,,,0,0,0,0,,,0,0,0,0,,,0,0,0,0,,,0,0,0,0,,,0,0,0,0,,,0,0,0,0,MSFT
2024-10-22 13:16:44.761617440+00:00,10,40,38,A,A,0,234.5,200,194,204433,119903,233.89,234.5,200,200,0,0,,,0,0,0,0,,,0,0,0,0,,,0,0,0,0,,,0,0,0,0,,,0,0,0,0,,,0,0,0,0,,,0,0,0,0,,,0,0,0,0,,,0,0,0,0,AAPL
2024-10-22 13:16:44.761865172+00:00,10,41,38,A,A,0,234.45,200,194,56533,290212,233.94,234.45,200,200,0,0,,,0,0,0,0,,,0,0,0,0,,,0,0,0,0,,,0,0,0,0,,,0,0,0,0,,,0,0,0,0,,,0,0,0,0,,,0,0,0,0,,,0,0,0,0,AAPL
2024-10-22 13:16:44.864468783+00:00,10,40,38,A,A,0,,0,194,204329,119905,233.89,,200,0,0,0,,,0,0,0,0,,,0,0,0,0,,,0,0,0,0,,,0,0,0,0,,,0,0,0,0,,,0,0,0,0,,,0,0,0,0,,,0,0,0,0,,,0,0,0,0,AAPL
2024-10-22 13:16:44.963495017+00:00,10,41,38,A,A,0,,0,194,55540,290233,233.94,,200,0,0,0,,,0,0,0,0,,,0,0,0,0,,,0,0,0,0,,,0,0,0,0,,,0,0,0,0,,,0,0,0,0,,,0,0,0,0,,,0,0,0,0,,,0,0,0,0,AAPL
2024-10-22 13:16:45.644132674+00:00,10,39,10888,C,A,0,421.2,2000,130,203193,103242,,,0,0,0,0,,,0,0,0,0,,,0,0,0,0,,,0,0,0,0,,,0,0,0,0,,,0,0,0,0,,,0,0,0,0,,,0,0,0,0,,,0,0,0,0,,,0,0,0,0,MSFT
2024-10-22 13:16:45.679370092+00:00,10,39,10888,A,A,0,421.2,2000,130,203236,103243,,421.2,0,2000,0,1,,,0,0,0,0,,,0,0,0,0,,,0,0,0,0,,,0,0,0,0,,,0,0,0,0,,,0,0,0,0,,,0,0,0,0,,,0,0,0,0,,,0,0,0,0,MSFT
2024-10-22 13:16:48.672280461+00:00,10,40,38,A,B,0,,0,194,204302,119941,,,0,0,0,0,,,0,0,0,0,,,0,0,0,0,,,0,0,0,0,,,0,0,0,0,,,0,0,0,0,,,0,0,0,0,,,0,0,0,0,,,0,0,0,0,,,0,0,0,0,AAPL
2024-10-22 13:16:48.736889318+00:00,10,39,38,C,B,0,232.6,2000,130,203139,70328,,236.4,0,2000,0,1,,,0,0,0,0,,,0,0,0,0,,,0,0,0,0,,,0,0,0,0,,,0,0,0,0,,,0,0,0,0,,,0,0,0,0,,,0,0,0,0,,,0,0,0,0,AAPL
2024-10-22 13:16:48.747629159+00:00,10,39,38,A,B,0,232.4,2000,130,203115,70329,232.4,236.4,2000,2000,1,1,,,0,0,0,0,,,0,0,0,0,,,0,0,0,0,,,0,0,0,0,,,0,0,0,0,,,0,0,0,0,,,0,0,0,0,,,0,0,0,0,,,0,0,0,0,AAPL
2024-10-22 13:16:48.932476475+00:00,10,41,38,A,B,0,,0,194,56104,290438,,,0,0,0,0,,,0,0,0,0,,,0,0,0,0,,,0,0,0,0,,,0,0,0,0,,,0,0,0,0,,,0,0,0,0,,,0,0,0,0,,,0,0,0,0,,,0,0,0,0,AAPL
2024-10-22 13:16:48.942962909+00:00,10,39,38,A,B,0,232.6,2000,130,203079,70332,232.6,236.4,2000,2000,1,1,232.4,,2000,0,1,0,,,0,0,0,0,,,0,0,0,0,,,0,0,0,0,,,0,0,0,0,,,0,0,0,0,,,0,0,0,0,,,0,0,0,0,,,0,0,0,0,AAPL
2024-10-22 13:16:48.943156082+00:00,10,39,38,C,B,1,232.4,2000,130,203007,70333,232.6,236.4,2000,2000,1,1,,,0,0,0,0,,,0,0,0,0,,,0,0,0,0,,,0,0,0,0,,,0,0,0,0,,,0,0,0,0,,,0,0,0,0,,,0,0,0,0,,,0,0,0,0,AAPL
2024-10-22 13:16:50.292207906+00:00,10,41,38,A,B,0,,0,194,55940,290483,233.94,,200,0,0,0,,,0,0,0,0,,,0,0,0,0,,,0,0,0,0,,,0,0,0,0,,,0,0,0,0,,,0,0,0,0,,,0,0,0,0,,,0,0,0,0,,,0,0,0,0,AAPL
2024-10-22 13:16:51.734799976+00:00,10,40,38,A,B,0,,0,194,204243,119952,233.89,,200,0,0,0,,,0,0,0,0,,,0,0,0,0,,,0,0,0,0,,,0,0,0,0,,,0,0,0,0,,,0,0,0,0,,,0,0,0,0,,,0,0,0,0,,,0,0,0,0,AAPL
2024-10-22 13:16:51.735270014+00:00,10,39,38,C,B,0,232.6,2000,130,203764,70337,,236.4,0,2000,0,1,,,0,0,0,0,,,0,0,0,0,,,0,0,0,0,,,0,0,0,0,,,0,0,0,0,,,0,0,0,0,,,0,0,0,0,,,0,0,0,0,,,0,0,0,0,AAPL
2024-10-22 13:16:51.747338014+00:00,10,39,38,A,B,0,232.4,2000,130,203247,70338,232.4,236.4,2000,2000,1,1,,,0,0,0,0,,,0,0,0,0,,,0,0,0,0,,,0,0,0,0,,,0,0,0,0,,,0,0,0,0,,,0,0,0,0,,,0,0,0,0,,,0,0,0,0,AAPL
2024-10-22 13:16:52.005760995+00:00,10,39,38,A,B,0,232.6,2000,130,203452,70346,232.6,236.4,2000,2000,1,1,232.4,,2000,0,1,0,,,0,0,0,0,,,0,0,0,0,,,0,0,0,0,,,0,0,0,0,,,0,0,0,0,,,0,0,0,0,,,0,0,0,0,,,0,0,0,0,AAPL
2024-10-22 13:16:52.005954492+00:00,10,39,38,C,B,1,232.4,2000,130,203126,70347,232.6,236.4,2000,2000,1,1,,,0,0,0,0,,,0,0,0,0,,,0,0,0,0,,,0,0,0,0,,,0,0,0,0,,,0,0,0,0,,,0,0,0,0,,,0,0,0,0,,,0,0,0,0,AAPL
2024-10-22 13:16:54.046530935+00:00,10,40,38,A,B,0,,0,194,204235,119969,,,0,0,0,0,,,0,0,0,0,,,0,0,0,0,,,0,0,0,0,,,0,0,0,0,,,0,0,0,0,,,0,0,0,0,,,0,0,0,0,,,0,0,0,0,,,0,0,0,0,AAPL
2024-10-22 13:16:54.060659195+00:00,10,40,38,A,B,0,,0,194,204247,119972,233.89,,200,0,0,0,,,0,0,0,0,,,0,0,0,0,,,0,0,0,0,,,0,0,0,0,,,0,0,0,0,,,0,0,0,0,,,0,0,0,0,,,0,0,0,0,,,0,0,0,0,AAPL
2024-10-22 13:16:54.062090379+00:00,10,40,38,A,B,0,,0,194,204154,119973,,,0,0,0,0,,,0,0,0,0,,,0,0,0,0,,,0,0,0,0,,,0,0,0,0,,,0,0,0,0,,,0,0,0,0,,,0,0,0,0,,,0,0,0,0,,,0,0,0,0,AAPL
2024-10-22 13:16:54.327931029+00:00,10,40,38,A,B,0,,0,194,204209,119981,233.89,,200,0,0,0,,,0,0,0,0,,,0,0,0,0,,,0,0,0,0,,,0,0,0,0,,,0,0,0,0,,,0,0,0,0,,,0,0,0,0,,,0,0,0,0,,,0,0,0,0,AAPL
2024-10-22 13:16:56.504841420+00:00,10,41,38,A,A,0,234.45,200,194,56061,290772,233.94,234.45,200,200,0,0,,,0,0,0,0,,,0,0,0,0,,,0,0,0,0,,,0,0,0,0,,,0,0,0,0,,,0,0,0,0,,,0,0,0,0,,,0,0,0,0,,,0,0,0,0,AAPL
2024-10-22 13:16:56.505187709+00:00,10,39,38,C,B,0,232.6,2000,130,203411,70365,,236.4,0,2000,0,1,,,0,0,0,0,,,0,0,0,0,,,0,0,0,0,,,0,0,0,0,,,0,0,0,0,,,0,0,0,0,,,0,0,0,0,,,0,0,0,0,,,0,0,0,0,AAPL
2024-10-22 13:16:56.505640842+00:00,10,40,38,A,A,0,234.5,200,194,204197,120023,233.89,234.5,200,200,0,0,,,0,0,0,0,,,0,0,0,0,,,0,0,0,0,,,0,0,0,0,,,0,0,0,0,,,0,0,0,0,,,0,0,0,0,,,0,0,0,0,,,0,0,0,0,AAPL
2024-10-22 13:16:56.518487025+00:00,10,40,38,A,A,0,,0,194,204160,120025,233.89,,200,0,0,0,,,0,0,0,0,,,0,0,0,0,,,0,0,0,0,,,0,0,0,0,,,0,0,0,0,,,0,0,0,0,,,0,0,0,0,,,0,0,0,0,,,0,0,0,0,AAPL
2024-10-22 13:16:56.541348356+00:00,10,39,38,A,B,0,232.6,2000,130,202954,70368,232.6,236.4,2000,2000,1,1,,,0,0,0,0,,,0,0,0,0,,,0,0,0,0,,,0,0,0,0,,,0,0,0,0,,,0,0,0,0,,,0,0,0,0,,,0,0,0,0,,,0,0,0,0,AAPL
2024-10-22 13:16:56.714440081+00:00,10,41,38,A,A,0,,0,194,55499,290788,233.94,,200,0,0,0,,,0,0,0,0,,,0,0,0,0,,,0,0,0,0,,,0,0,0,0,,,0,0,0,0,,,0,0,0,0,,,0,0,0,0,,,0,0,0,0,,,0,0,0,0,AAPL
2024-10-22 13:16:56.992032048+00:00,10,40,38,A,A,0,234.5,200,194,204366,120028,233.89,234.5,200,200,0,0,,,0,0,0,0,,,0,0,0,0,,,0,0,0,0,,,0,0,0,0,,,0,0,0,0,,,0,0,0,0,,,0,0,0,0,,,0,0,0,0,,,0,0,0,0,AAPL
2024-10-22 13:16:56.992298956+00:00,10,41,38,A,A,0,234.45,200,194,56050,290793,233.94,234.45,200,200,0,0,,,0,0,0,0,,,0,0,0,0,,,0,0,0,0,,,0,0,0,0,,,0,0,0,0,,,0,0,0,0,,,0,0,0,0,,,0,0,0,0,,,0,0,0,0,AAPL
2024-10-22 13:16:56.992635240+00:00,10,39,38,C,A,0,236.4,2000,130,202744,70377,232.6,,2000,0,1,0,,,0,0,0,0,,,0,0,0,0,,,0,0,0,0,,,0,0,0,0,,,0,0,0,0,,,0,0,0,0,,,0,0,0,0,,,0,0,0,0,,,0,0,0,0,AAPL
2024-10-22 13:16:57.029707029+00:00,10,39,38,A,A,0,236.4,2000,130,202880,70379,232.6,236.4,2000,2000,1,1,,,0,0,0,0,,,0,0,0,0,,,0,0,0,0,,,0,0,0,0,,,0,0,0,0,,,0,0,0,0,,,0,0,0,0,,,0,0,0,0,,,0,0,0,0,AAPL
2024-10-22 13:16:57.113120385+00:00,10,40,38,A,A,0,,0,194,204348,120030,233.89,,200,0,0,0,,,0,0,0,0,,,0,0,0,0,,,0,0,0,0,,,0,0,0,0,,,0,0,0,0,,,0,0,0,0,,,0,0,0,0,,,0,0,0,0,,,0,0,0,0,AAPL
2024-10-22 13:16:57.113357462+00:00,10,41,38,A,A,0,,0,194,55132,290803,233.94,,200,0,0,0,,,0,0,0,0,,,0,0,0,0,,,0,0,0,0,,,0,0,0,0,,,0,0,0,0,,,0,0,0,0,,,0,0,0,0,,,0,0,0,0,,,0,0,0,0,AAPL
2024-10-22 13:16:58.609235426+00:00,10,40,38,A,A,0,234.5,200,194,204389,120041,233.89,234.5,200,200,0,0,,,0,0,0,0,,,0,0,0,0,,,0,0,0,0,,,0,0,0,0,,,0,0,0,0,,,0,0,0,0,,,0,0,0,0,,,0,0,0,0,,,0,0,0,0,AAPL
2024-10-22 13:16:58.609464712+00:00,10,41,38,A,A,0,234.45,200,194,55768,290867,233.94,234.45,200,200,0,0,,,0,0,0,0,,,0,0,0,0,,,0,0,0,0,,,0,0,0,0,,,0,0,0,0,,,0,0,0,0,,,0,0,0,0,,,0,0,0,0,,,0,0,0,0,AAPL
2024-10-22 13:16:58.609899067+00:00,10,39,38,C,B,0,232.6,2000,130,203116,70389,,236.4,0,2000,0,1,,,0,0,0,0,,,0,0,0,0,,,0,0,0,0,,,0,0,0,0,,,0,0,0,0,,,0,0,0,0,,,0,0,0,0,,,0,0,0,0,,,0,0,0,0,AAPL
2024-10-22 13:16:58.646471814+00:00,10,39,38,A,B,0,232.6,2000,130,203071,70390,232.6,236.4,2000,2000,1,1,,,0,0,0,0,,,0,0,0,0,,,0,0,0,0,,,0,0,0,0,,,0,0,0,0,,,0,0,0,0,,,0,0,0,0,,,0,0,0,0,,,0,0,0,0,AAPL
2024-10-22 13:16:58.671724378+00:00,10,39,38,C,A,0,236.4,2000,130,202756,70391,232.6,,2000,0,1,0,,,0,0,0,0,,,0,0,0,0,,,0,0,0,0,,,0,0,0,0,,,0,0,0,0,,,0,0,0,0,,,0,0,0,0,,,0,0,0,0,,,0,0,0,0,AAPL
2024-10-22 13:16:58.771888702+00:00,10,41,38,A,A,0,,0,194,55505,290872,233.94,,200,0,0,0,,,0,0,0,0,,,0,0,0,0,,,0,0,0,0,,,0,0,0,0,,,0,0,0,0,,,0,0,0,0,,,0,0,0,0,,,0,0,0,0,,,0,0,0,0,AAPL
2024-10-22 13:16:59.069784630+00:00,10,41,38,A,A,0,234.43,200,194,55596,290883,233.94,234.43,200,200,0,0,,,0,0,0,0,,,0,0,0,0,,,0,0,0,0,,,0,0,0,0,,,0,0,0,0,,,0,0,0,0,,,0,0,0,0,,,0,0,0,0,,,0,0,0,0,AAPL
2024-10-22 13:16:59.080319667+00:00,10,39,38,A,A,0,236.4,2000,130,203615,70393,232.6,236.4,2000,2000,1,1,,,0,0,0,0,,,0,0,0,0,,,0,0,0,0,,,0,0,0,0,,,0,0,0,0,,,0,0,0,0,,,0,0,0,0,,,0,0,0,0,,,0,0,0,0,AAPL
2024-10-22 13:16:59.242338930+00:00,10,41,38,A,A,0,,0,194,56047,290890,233.94,,200,0,0,0,,,0,0,0,0,,,0,0,0,0,,,0,0,0,0,,,0,0,0,0,,,0,0,0,0,,,0,0,0,0,,,0,0,0,0,,,0,0,0,0,,,0,0,0,0,AAPL
2024-10-22 13:16:59.242612365+00:00,10,39,38,C,B,0,232.6,2000,130,203243,70394,,236.4,0,2000,0,1,,,0,0,0,0,,,0,0,0,0,,,0,0,0,0,,,0,0,0,0,,,0,0,0,0,,,0,0,0,0,,,0,0,0,0,,,0,0,0,0,,,0,0,0,0,AAPL
2024-10-22 13:16:59.253323547+00:00,10,39,38,A,B,0,232.4,2000,130,202961,70395,232.4,236.4,2000,2000,1,1,,,0,0,0,0,,,0,0,0,0,,,0,0,0,0,,,0,0,0,0,,,0,0,0,0,,,0,0,0,0,,,0,0,0,0,,,0,0,0,0,,,0,0,0,0,AAPL
2024-10-22 13:16:59.373758999+00:00,10,39,38,C,B,0,232.4,2000,130,203007,70396,,236.4,0,2000,0,1,,,0,0,0,0,,,0,0,0,0,,,0,0,0,0,,,0,0,0,0,,,0,0,0,0,,,0,0,0,0,,,0,0,0,0,,,0,0,0,0,,,0,0,0,0,AAPL
2024-10-22 13:16:59.384820618+00:00,10,39,38,A,B,0,232.2,2000,130,202916,70397,232.2,236.4,2000,2000,1,1,,,0,0,0,0,,,0,0,0,0,,,0,0,0,0,,,0,0,0,0,,,0,0,0,0,,,0,0,0,0,,,0,0,0,0,,,0,0,0,0,,,0,0,0,0,AAPL
2024-10-22 13:17:00.036365080+00:00,10,40,38,A,B,0,234.5,200,194,204051,120080,,234.5,0,200,0,0,,,0,0,0,0,,,0,0,0,0,,,0,0,0,0,,,0,0,0,0,,,0,0,0,0,,,0,0,0,0,,,0,0,0,0,,,0,0,0,0,,,0,0,0,0,AAPL
2024-10-22 13:17:00.036385861+00:00,10,40,38,A,B,0,234.5,200,194,203959,120081,233.81,234.5,200,200,0,0,,,0,0,0,0,,,0,0,0,0,,,0,0,0,0,,,0,0,0,0,,,0,0,0,0,,,0,0,0,0,,,0,0,0,0,,,0,0,0,0,,,0,0,0,0,AAPL
2024-10-22 13:17:00.036901382+00:00,10,41,38,A,B,0,,0,194,55516,291007,,,0,0,0,0,,,0,0,0,0,,,0,0,0,0,,,0,0,0,0,,,0,0,0,0,,,0,0,0,0,,,0,0,0,0,,,0,0,0,0,,,0,0,0,0,,,0,0,0,0,AAPL
2024-10-22 13:17:00.197442615+00:00,10,41,38,A,B,0,,0,194,55796,291130,233.86,,200,0,0,0,,,0,0,0,0,,,0,0,0,0,,,0,0,0,0,,,0,0,0,0,,,0,0,0,0,,,0,0,0,0,,,0,0,0,0,,,0,0,0,0,,,0,0,0,0,AAPL
2024-10-22 13:17:00.197953649+00:00,10,41,38,A,A,0,234.41,200,194,57433,291131,233.86,234.41,200,200,0,0,,,0,0,0,0,,,0,0,0,0,,,0,0,0,0,,,0,0,0,0,,,0,0,0,0,,,0,0,0,0,,,0,0,0,0,,,0,0,0,0,,,0,0,0,0,AAPL
2024-10-22 13:17:00.274754954+00:00,10,40,38,A,B,0,234.5,200,194,204076,120119,,234.5,0,200,0,0,,,0,0,0,0,,,0,0,0,0,,,0,0,0,0,,,0,0,0,0,,,0,0,0,0,,,0,0,0,0,,,0,0,0,0,,,0,0,0,0,,,0,0,0,0,AAPL
2024-10-22 13:17:00.274765563+00:00,10,40,38,A,A,0,,0,194,204027,120120,,,0,0,0,0,,,0,0,0,0,,,0,0,0,0,,,0,0,0,0,,,0,0,0,0,,,0,0,0,0,,,0,0,0,0,,,0,0,0,0,,,0,0,0,0,,,0,0,0,0,AAPL
2024-10-22 13:17:00.275122670+00:00,10,41,38,A,B,0,234.41,200,194,54291,291163,,234.41,0,200,0,0,,,0,0,0,0,,,0,0,0,0,,,0,0,0,0,,,0,0,0,0,,,0,0,0,0,,,0,0,0,0,,,0,0,0,0,,,0,0,0,0,,,0,0,0,0,AAPL
2024-10-22 13:17:00.275136525+00:00,10,41,38,A,A,0,,0,194,54582,291164,,,0,0,0,0,,,0,0,0,0,,,0,0,0,0,,,0,0,0,0,,,0,0,0,0,,,0,0,0,0,,,0,0,0,0,,,0,0,0,0,,,0,0,0,0,,,0,0,0,0,AAPL
2024-10-22 13:17:00.275804995+00:00,10,40,38,A,B,0,,0,194,204004,120122,233.81,,200,0,0,0,,,0,0,0,0,,,0,0,0,0,,,0,0,0,0,,,0,0,0,0,,,0,0,0,0,,,0,0,0,0,,,0,0,0,0,,,0,0,0,0,,,0,0,0,0,AAPL
2024-10-22 13:17:00.275812295+00:00,10,40,38,A,A,0,234.46,200,194,203980,120123,233.81,234.46,200,200,0,0,,,0,0,0,0,,,0,0,0,0,,,0,0,0,0,,,0,0,0,0,,,0,0,0,0,,,0,0,0,0,,,0,0,0,0,,,0,0,0,0,,,0,0,0,0,AAPL
2024-10-22 13:17:00.376912368+00:00,10,41,38,A,A,0,234.41,200,194,54542,291179,,234.41,0,200,0,0,,,0,0,0,0,,,0,0,0,0,,,0,0,0,0,,,0,0,0,0,,,0,0,0,0,,,0,0,0,0,,,0,0,0,0,,,0,0,0,0,,,0,0,0,0,AAPL
2024-10-22 13:17:00.473577340+00:00,10,41,38,A,A,0,,0,194,56529,291197,,,0,0,0,0,,,0,0,0,0,,,0,0,0,0,,,0,0,0,0,,,0,0,0,0,,,0,0,0,0,,,0,0,0,0,,,0,0,0,0,,,0,0,0,0,,,0,0,0,0,AAPL
2024-10-22 13:17:00.474030902+00:00,10,41,38,A,B,0,,0,194,54294,291199,233.86,,200,0,0,0,,,0,0,0,0,,,0,0,0,0,,,0,0,0,0,,,0,0,0,0,,,0,0,0,0,,,0,0,0,0,,,0,0,0,0,,,0,0,0,0,,,0,0,0,0,AAPL
2024-10-22 13:17:00.510830871+00:00,10,41,38,A,B,0,,0,194,54363,291213,,,0,0,0,0,,,0,0,0,0,,,0,0,0,0,,,0,0,0,0,,,0,0,0,0,,,0,0,0,0,,,0,0,0,0,,,0,0,0,0,,,0,0,0,0,,,0,0,0,0,AAPL
2024-10-22 13:17:00.563693924+00:00,10,41,38,A,A,0,234.41,200,194,54967,291217,,234.41,0,200,0,0,,,0,0,0,0,,,0,0,0,0,,,0,0,0,0,,,0,0,0,0,,,0,0,0,0,,,0,0,0,0,,,0,0,0,0,,,0,0,0,0,,,0,0,0,0,AAPL
2024-10-22 13:17:00.900655741+00:00,10,41,38,A,B,0,234.41,200,194,55479,291243,233.85,234.41,200,200,0,0,,,0,0,0,0,,,0,0,0,0,,,0,0,0,0,,,0,0,0,0,,,0,0,0,0,,,0,0,0,0,,,0,0,0,0,,,0,0,0,0,,,0,0,0,0,AAPL
2024-10-22 13:17:00.901142069+00:00,10,39,38,C,B,0,232.2,2000,130,203122,70406,,236.4,0,2000,0,1,,,0,0,0,0,,,0,0,0,0,,,0,0,0,0,,,0,0,0,0,,,0,0,0,0,,,0,0,0,0,,,0,0,0,0,,,0,0,0,0,,,0,0,0,0,AAPL
2024-10-22 13:17:00.931618443+00:00,10,40,38,A,A,0,,0,194,203889,120148,233.81,,200,0,0,0,,,0,0,0,0,,,0,0,0,0,,,0,0,0,0,,,0,0,0,0,,,0,0,0,0,,,0,0,0,0,,,0,0,0,0,,,0,0,0,0,,,0,0,0,0,AAPL
2024-10-22 13:17:00.937299718+00:00,10,39,38,A,B,0,232.4,2000,130,202958,70407,232.4,236.4,2000,2000,1,1,,,0,0,0,0,,,0,0,0,0,,,0,0,0,0,,,0,0,0,0,,,0,0,0,0,,,0,0,0,0,,,0,0,0,0,,,0,0,0,0,,,0,0,0,0,AAPL
2024-10-22 13:17:01.022809889+00:00,10,41,38,A,B,0,234.41,200,194,55875,291268,,234.41,0,200,0,0,,,0,0,0,0,,,0,0,0,0,,,0,0,0,0,,,0,0,0,0,,,0,0,0,0,,,0,0,0,0,,,0,0,0,0,,,0,0,0,0,,,0,0,0,0,AAPL
2024-10-22 13:17:01.111034671+00:00,10,41,38,A,B,0,234.41,200,194,55441,291285,233.79,234.41,200,200,0,0,,,0,0,0,0,,,0,0,0,0,,,0,0,0,0,,,0,0,0,0,,,0,0,0,0,,,0,0,0,0,,,0,0,0,0,,,0,0,0,0,,,0,0,0,0,AAPL
2024-10-22 13:17:01.612982359+00:00,10,40,38,A,A,0,234.46,200,194,203909,120161,233.81,234.46,200,200,0,0,,,0,0,0,0,,,0,0,0,0,,,0,0,0,0,,,0,0,0,0,,,0,0,0,0,,,0,0,0,0,,,0,0,0,0,,,0,0,0,0,,,0,0,0,0,AAPL
2024-10-22 13:17:02.090257562+00:00,10,40,38,A,A,0,,0,194,204083,120169,233.81,,200,0,0,0,,,0,0,0,0,,,0,0,0,0,,,0,0,0,0,,,0,0,0,0,,,0,0,0,0,,,0,0,0,0,,,0,0,0,0,,,0,0,0,0,,,0,0,0,0,AAPL
2024-10-22 13:17:02.392147089+00:00,10,40,38,A,A,0,234.46,200,194,203980,120172,233.81,234.46,200,200,0,0,,,0,0,0,0,,,0,0,0,0,,,0,0,0,0,,,0,0,0,0,,,0,0,0,0,,,0,0,0,0,,,0,0,0,0,,,0,0,0,0,,,0,0,0,0,AAPL
2024-10-22 13:17:02.692704096+00:00,10,40,38,A,A,0,,0,194,203910,120176,233.81,,200,0,0,0,,,0,0,0,0,,,0,0,0,0,,,0,0,0,0,,,0,0,0,0,,,0,0,0,0,,,0,0,0,0,,,0,0,0,0,,,0,0,0,0,,,0,0,0,0,AAPL
2024-10-22 13:17:03.326373825+00:00,10,40,38,A,A,0,234.46,200,194,203826,120187,233.81,234.46,200,200,0,0,,,0,0,0,0,,,0,0,0,0,,,0,0,0,0,,,0,0,0,0,,,0,0,0,0,,,0,0,0,0,,,0,0,0,0,,,0,0,0,0,,,0,0,0,0,AAPL
2024-10-22 13:17:04.131849931+00:00,10,41,38,A,B,0,234.41,200,194,55472,291471,,234.41,0,200,0,0,,,0,0,0,0,,,0,0,0,0,,,0,0,0,0,,,0,0,0,0,,,0,0,0,0,,,0,0,0,0,,,0,0,0,0,,,0,0,0,0,,,0,0,0,0,AAPL
2024-10-22 13:17:05.869908748+00:00,10,41,38,A,B,0,234.41,200,194,56163,291551,233.79,234.41,200,200,0,0,,,0,0,0,0,,,0,0,0,0,,,0,0,0,0,,,0,0,0,0,,,0,0,0,0,,,0,0,0,0,,,0,0,0,0,,,0,0,0,0,,,0,0,0,0,AAPL
2024-10-22 13:17:07.080261600+00:00,10,41,38,A,B,0,234.41,200,194,55622,291621,,234.41,0,200,0,0,,,0,0,0,0,,,0,0,0,0,,,0,0,0,0,,,0,0,0,0,,,0,0,0,0,,,0,0,0,0,,,0,0,0,0,,,0,0,0,0,,,0,0,0,0,AAPL
2024-10-22 13:17:08.207679821+00:00,10,41,38,A,B,0,234.41,200,194,55618,291797,233.78,234.41,200,200,0,0,,,0,0,0,0,,,0,0,0,0,,,0,0,0,0,,,0,0,0,0,,,0,0,0,0,,,0,0,0,0,,,0,0,0,0,,,0,0,0,0,,,0,0,0,0,AAPL
2024-10-22 13:17:08.268212871+00:00,10,39,38,C,A,0,236.4,2000,130,203175,70471,232.4,,2000,0,1,0,,,0,0,0,0,,,0,0,0,0,,,0,0,0,0,,,0,0,0,0,,,0,0,0,0,,,0,0,0,0,,,0,0,0,0,,,0,0,0,0,,,0,0,0,0,AAPL
2024-10-22 13:17:08.416881770+00:00,10,40,38,A,B,0,234.46,200,194,203922,120260,,234.46,0,200,0,0,,,0,0,0,0,,,0,0,0,0,,,0,0,0,0,,,0,0,0,0,,,0,0,0,0,,,0,0,0,0,,,0,0,0,0,,,0,0,0,0,,,0,0,0,0,AAPL
2024-10-22 13:17:08.417113784+00:00,10,41,38,A,B,0,234.41,200,194,60842,291816,,234.41,0,200,0,0,,,0,0,0,0,,,0,0,0,0,,,0,0,0,0,,,0,0,0,0,,,0,0,0,0,,,0,0,0,0,,,0,0,0,0,,,0,0,0,0,,,0,0,0,0,AAPL
2024-10-22 13:17:08.417214975+00:00,10,40,38,A,B,0,234.46,200,194,203953,120261,233.73,234.46,200,200,0,0,,,0,0,0,0,,,0,0,0,0,,,0,0,0,0,,,0,0,0,0,,,0,0,0,0,,,0,0,0,0,,,0,0,0,0,,,0,0,0,0,,,0,0,0,0,AAPL
2024-10-22 13:17:08.417448917+00:00,10,41,38,A,B,0,234.41,200,194,55585,291817,233.78,234.41,200,200,0,0,,,0,0,0,0,,,0,0,0,0,,,0,0,0,0,,,0,0,0,0,,,0,0,0,0,,,0,0,0,0,,,0,0,0,0,,,0,0,0,0,,,0,0,0,0,AAPL
2024-10-22 13:17:08.616920931+00:00,10,40,38,A,B,0,234.46,200,194,203858,120266,,234.46,0,200,0,0,,,0,0,0,0,,,0,0,0,0,,,0,0,0,0,,,0,0,0,0,,,0,0,0,0,,,0,0,0,0,,,0,0,0,0,,,0,0,0,0,,,0,0,0,0,AAPL
2024-10-22 13:17:08.617165890+00:00,10,41,38,A,B,0,234.41,200,194,55310,291831,,234.41,0,200,0,0,,,0,0,0,0,,,0,0,0,0,,,0,0,0,0,,,0,0,0,0,,,0,0,0,0,,,0,0,0,0,,,0,0,0,0,,,0,0,0,0,,,0,0,0,0,AAPL
2024-10-22 13:17:10.146368783+00:00,10,40,38,A,B,0,234.46,200,194,204127,120294,233.73,234.46,200,200,0,0,,,0,0,0,0,,,0,0,0,0,,,0,0,0,0,,,0,0,0,0,,,0,0,0,0,,,0,0,0,0,,,0,0,0,0,,,0,0,0,0,,,0,0,0,0,AAPL
2024-10-22 13:17:12.158826020+00:00,10,40,38,A,B,0,234.46,200,194,204177,120315,,234.46,0,200,0,0,,,0,0,0,0,,,0,0,0,0,,,0,0,0,0,,,0,0,0,0,,,0,0,0,0,,,0,0,0,0,,,0,0,0,0,,,0,0,0,0,,,0,0,0,0,AAPL
2024-10-22 13:17:12.461710938+00:00,10,40,38,A,B,0,234.46,200,194,204443,120316,233.73,234.46,200,200,0,0,,,0,0,0,0,,,0,0,0,0,,,0,0,0,0,,,0,0,0,0,,,0,0,0,0,,,0,0,0,0,,,0,0,0,0,,,0,0,0,0,,,0,0,0,0,AAPL
2024-10-22 13:17:17.204227786+00:00,10,41,38,A,B,0,234.41,200,194,59689,292343,233.78,234.41,200,200,0,0,,,0,0,0,0,,,0,0,0,0,,,0,0,0,0,,,0,0,0,0,,,0,0,0,0,,,0,0,0,0,,,0,0,0,0,,,0,0,0,0,,,0,0,0,0,AAPL
2024-10-22 13:17:18.299844215+00:00,10,41,38,A,B,0,234.41,200,194,55426,292393,,234.41,0,200,0,0,,,0,0,0,0,,,0,0,0,0,,,0,0,0,0,,,0,0,0,0,,,0,0,0,0,,,0,0,0,0,,,0,0,0,0,,,0,0,0,0,,,0,0,0,0,AAPL
2024-10-22 13:17:21.219869951+00:00,10,39,38,A,B,0,232.6,2000,130,203627,70546,232.6,,2000,0,1,0,232.4,,2000,0,1,0,,,0,0,0,0,,,0,0,0,0,,,0,0,0,0,,,0,0,0,0,,,0,0,0,0,,,0,0,0,0,,,0,0,0,0,,,0,0,0,0,AAPL
2024-10-22 13:17:21.220598651+00:00,10,39,38,C,B,1,232.4,2000,130,203578,70547,232.6,,2000,0,1,0,,,0,0,0,0,,,0,0,0,0,,,0,0,0,0,,,0,0,0,0,,,0,0,0,0,,,0,0,0,0,,,0,0,0,0,,,0,0,0,0,,,0,0,0,0,AAPL
2024-10-22 13:17:26.354159711+00:00,10,41,38,A,B,0,234.41,200,194,55790,292899,233.84,234.41,200,200,0,0,,,0,0,0,0,,,0,0,0,0,,,0,0,0,0,,,0,0,0,0,,,0,0,0,0,,,0,0,0,0,,,0,0,0,0,,,0,0,0,0,,,0,0,0,0,AAPL
2024-10-22 13:17:26.391723275+00:00,10,39,38,C,B,0,232.6,2000,130,203753,70603,,,0,0,0,0,,,0,0,0,0,,,0,0,0,0,,,0,0,0,0,,,0,0,0,0,,,0,0,0,0,,,0,0,0,0,,,0,0,0,0,,,0,0,0,0,,,0,0,0,0,AAPL
2024-10-22 13:17:26.403237304+00:00,10,39,38,A,B,0,232.4,2000,130,203786,70604,232.4,,2000,0,1,0,,,0,0,0,0,,,0,0,0,0,,,0,0,0,0,,,0,0,0,0,,,0,0,0,0,,,0,0,0,0,,,0,0,0,0,,,0,0,0,0,,,0,0,0,0,AAPL
2024-10-22 13:17:26.416216096+00:00,10,39,38,C,B,0,232.4,2000,130,203660,70605,,,0,0,0,0,,,0,0,0,0,,,0,0,0,0,,,0,0,0,0,,,0,0,0,0,,,0,0,0,0,,,0,0,0,0,,,0,0,0,0,,,0,0,0,0,,,0,0,0,0,AAPL
2024-10-22 13:17:26.429606052+00:00,10,39,38,A,B,0,232.2,2000,130,203648,70606,232.2,,2000,0,1,0,,,0,0,0,0,,,0,0,0,0,,,0,0,0,0,,,0,0,0,0,,,0,0,0,0,,,0,0,0,0,,,0,0,0,0,,,0,0,0,0,,,0,0,0,0,AAPL
2024-10-22 13:17:35.712247787+00:00,10,39,38,A,B,0,232.4,2000,130,203809,70696,232.4,,2000,0,1,0,232.2,,2000,0,1,0,,,0,0,0,0,,,0,0,0,0,,,0,0,0,0,,,0,0,0,0,,,0,0,0,0,,,0,0,0,0,,,0,0,0,0,,,0,0,0,0,AAPL
2024-10-22 13:17:35.712433182+00:00,10,39,38,C,B,1,232.2,2000,130,203758,70697,232.4,,2000,0,1,0,,,0,0,0,0,,,0,0,0,0,,,0,0,0,0,,,0,0,0,0,,,0,0,0,0,,,0,0,0,0,,,0,0,0,0,,,0,0,0,0,,,0,0,0,0,AAPL
2024-10-22 13:17:41.567299687+00:00,10,39,38,C,B,0,232.4,2000,130,204237,70744,,,0,0,0,0,,,0,0,0,0,,,0,0,0,0,,,0,0,0,0,,,0,0,0,0,,,0,0,0,0,,,0,0,0,0,,,0,0,0,0,,,0,0,0,0,,,0,0,0,0,AAPL
2024-10-22 13:17:41.578150260+00:00,10,39,38,A,B,0,232.2,2000,130,203925,70745,232.2,,2000,0,1,0,,,0,0,0,0,,,0,0,0,0,,,0,0,0,0,,,0,0,0,0,,,0,0,0,0,,,0,0,0,0,,,0,0,0,0,,,0,0,0,0,,,0,0,0,0,AAPL
2024-10-22 13:17:41.775299185+00:00,10,39,10888,C,A,0,421.2,2000,130,203858,103680,,,0,0,0,0,,,0,0,0,0,,,0,0,0,0,,,0,0,0,0,,,0,0,0,0,,,0,0,0,0,,,0,0,0,0,,,0,0,0,0,,,0,0,0,0,,,0,0,0,0,MSFT
2024-10-22 13:17:41.810765363+00:00,10,39,10888,A,A,0,421.2,2000,130,203590,103681,,421.2,0,2000,0,1,,,0,0,0,0,,,0,0,0,0,,,0,0,0,0,,,0,0,0,0,,,0,0,0,0,,,0,0,0,0,,,0,0,0,0,,,0,0,0,0,,,0,0,0,0,MSFT
2024-10-22 13:17:43.004864735+00:00,10,39,38,A,B,0,232.6,2000,130,204085,70760,232.6,,2000,0,1,0,232.2,,2000,0,1,0,,,0,0,0,0,,,0,0,0,0,,,0,0,0,0,,,0,0,0,0,,,0,0,0,0,,,0,0,0,0,,,0,0,0,0,,,0,0,0,0,AAPL
2024-10-22 13:17:43.005073382+00:00,10,39,38,C,B,1,232.2,2000,130,203841,70761,232.6,,2000,0,1,0,,,0,0,0,0,,,0,0,0,0,,,0,0,0,0,,,0,0,0,0,,,0,0,0,0,,,0,0,0,0,,,0,0,0,0,,,0,0,0,0,,,0,0,0,0,AAPL
2024-10-22 13:17:43.030367859+00:00,10,39,38,C,B,0,232.6,2000,130,203773,70762,,,0,0,0,0,,,0,0,0,0,,,0,0,0,0,,,0,0,0,0,,,0,0,0,0,,,0,0,0,0,,,0,0,0,0,,,0,0,0,0,,,0,0,0,0,,,0,0,0,0,AAPL
2024-10-22 13:17:43.041074777+00:00,10,39,38,A,B,0,232.6,2000,130,203843,70763,232.6,,2000,0,1,0,,,0,0,0,0,,,0,0,0,0,,,0,0,0,0,,,0,0,0,0,,,0,0,0,0,,,0,0,0,0,,,0,0,0,0,,,0,0,0,0,,,0,0,0,0,AAPL
2024-10-22 13:17:51.352293857+00:00,10,39,10888,C,A,0,421.2,2000,130,203731,103745,,,0,0,0,0,,,0,0,0,0,,,0,0,0,0,,,0,0,0,0,,,0,0,0,0,,,0,0,0,0,,,0,0,0,0,,,0,0,0,0,,,0,0,0,0,,,0,0,0,0,MSFT
2024-10-22 13:17:51.387734843+00:00,10,39,10888,A,A,0,421.2,2000,130,203499,103746,,421.2,0,2000,0,1,,,0,0,0,0,,,0,0,0,0,,,0,0,0,0,,,0,0,0,0,,,0,0,0,0,,,0,0,0,0,,,0,0,0,0,,,0,0,0,0,,,0,0,0,0,MSFT
2024-10-22 13:17:58.905069204+00:00,10,39,38,A,A,0,236.4,2000,130,204740,70863,232.6,236.4,2000,2000,1,1,,,0,0,0,0,,,0,0,0,0,,,0,0,0,0,,,0,0,0,0,,,0,0,0,0,,,0,0,0,0,,,0,0,0,0,,,0,0,0,0,,,0,0,0,0,AAPL
2024-10-22 13:18:00.009974036+00:00,10,40,38,A,A,0,,0,194,203129,120766,233.73,,200,0,0,0,,,0,0,0,0,,,0,0,0,0,,,0,0,0,0,,,0,0,0,0,,,0,0,0,0,,,0,0,0,0,,,0,0,0,0,,,0,0,0,0,,,0,0,0,0,AAPL
2024-10-22 13:18:00.010205586+00:00,10,41,38,A,B,0,234.41,200,194,55103,294588,,234.41,0,200,0,0,,,0,0,0,0,,,0,0,0,0,,,0,0,0,0,,,0,0,0,0,,,0,0,0,0,,,0,0,0,0,,,0,0,0,0,,,0,0,0,0,,,0,0,0,0,AAPL
2024-10-22 13:18:00.010217361+00:00,10,41,38,A,A,0,,0,194,55250,294589,,,0,0,0,0,,,0,0,0,0,,,0,0,0,0,,,0,0,0,0,,,0,0,0,0,,,0,0,0,0,,,0,0,0,0,,,0,0,0,0,,,0,0,0,0,,,0,0,0,0,AAPL
2024-10-22 13:18:00.109853526+00:00,10,41,38,A,A,0,234.38,200,194,55159,294780,,234.38,0,200,0,0,,,0,0,0,0,,,0,0,0,0,,,0,0,0,0,,,0,0,0,0,,,0,0,0,0,,,0,0,0,0,,,0,0,0,0,,,0,0,0,0,,,0,0,0,0,AAPL
2024-10-22 13:18:00.613698210+00:00,10,40,38,A,A,0,234.43,200,194,203111,120832,233.73,234.43,200,200,0,0,,,0,0,0,0,,,0,0,0,0,,,0,0,0,0,,,0,0,0,0,,,0,0,0,0,,,0,0,0,0,,,0,0,0,0,,,0,0,0,0,,,0,0,0,0,AAPL
2024-10-22 13:18:00.915457256+00:00,10,40,38,A,A,0,,0,194,203176,120837,233.73,,200,0,0,0,,,0,0,0,0,,,0,0,0,0,,,0,0,0,0,,,0,0,0,0,,,0,0,0,0,,,0,0,0,0,,,0,0,0,0,,,0,0,0,0,,,0,0,0,0,AAPL
2024-10-22 13:18:01.786368940+00:00,10,40,38,A,A,0,234.43,200,194,203158,120858,233.73,234.43,200,200,0,0,,,0,0,0,0,,,0,0,0,0,,,0,0,0,0,,,0,0,0,0,,,0,0,0,0,,,0,0,0,0,,,0,0,0,0,,,0,0,0,0,,,0,0,0,0,AAPL
2024-10-22 13:18:05.024939983+00:00,10,41,38,A,B,0,234.38,200,194,55863,295158,233.86,234.38,200,200,0,0,,,0,0,0,0,,,0,0,0,0,,,0,0,0,0,,,0,0,0,0,,,0,0,0,0,,,0,0,0,0,,,0,0,0,0,,,0,0,0,0,,,0,0,0,0,AAPL
2024-10-22 13:18:05.057661783+00:00,10,40,38,A,B,0,234.43,200,194,203209,120887,,234.43,0,200,0,0,,,0,0,0,0,,,0,0,0,0,,,0,0,0,0,,,0,0,0,0,,,0,0,0,0,,,0,0,0,0,,,0,0,0,0,,,0,0,0,0,,,0,0,0,0,AAPL
2024-10-22 13:18:05.057681969+00:00,10,40,38,A,B,0,234.43,200,194,203176,120888,233.81,234.43,200,200,0,0,,,0,0,0,0,,,0,0,0,0,,,0,0,0,0,,,0,0,0,0,,,0,0,0,0,,,0,0,0,0,,,0,0,0,0,,,0,0,0,0,,,0,0,0,0,AAPL
2024-10-22 13:18:05.058052605+00:00,10,41,38,A,B,0,234.38,200,194,56184,295162,,234.38,0,200,0,0,,,0,0,0,0,,,0,0,0,0,,,0,0,0,0,,,0,0,0,0,,,0,0,0,0,,,0,0,0,0,,,0,0,0,0,,,0,0,0,0,,,0,0,0,0,AAPL
2024-10-22 13:18:05.158108652+00:00,10,40,38,A,B,0,234.43,200,194,203158,120892,,234.43,0,200,0,0,,,0,0,0,0,,,0,0,0,0,,,0,0,0,0,,,0,0,0,0,,,0,0,0,0,,,0,0,0,0,,,0,0,0,0,,,0,0,0,0,,,0,0,0,0,AAPL
2024-10-22 13:18:06.444372192+00:00,10,40,38,A,B,0,234.43,200,194,203245,120901,233.81,234.43,200,200,0,0,,,0,0,0,0,,,0,0,0,0,,,0,0,0,0,,,0,0,0,0,,,0,0,0,0,,,0,0,0,0,,,0,0,0,0,,,0,0,0,0,,,0,0,0,0,AAPL
2024-10-22 13:18:06.444592781+00:00,10,41,38,A,B,0,234.38,200,194,55057,295231,233.86,234.38,200,200,0,0,,,0,0,0,0,,,0,0,0,0,,,0,0,0,0,,,0,0,0,0,,,0,0,0,0,,,0,0,0,0,,,0,0,0,0,,,0,0,0,0,,,0,0,0,0,AAPL
2024-10-22 13:18:06.473931229+00:00,10,39,38,C,B,0,232.6,2000,130,204641,70940,,236.4,0,2000,0,1,,,0,0,0,0,,,0,0,0,0,,,0,0,0,0,,,0,0,0,0,,,0,0,0,0,,,0,0,0,0,,,0,0,0,0,,,0,0,0,0,,,0,0,0,0,AAPL
2024-10-22 13:18:06.485412018+00:00,10,39,38,A,B,0,232.4,2000,130,204519,70941,232.4,236.4,2000,2000,1,1,,,0,0,0,0,,,0,0,0,0,,,0,0,0,0,,,0,0,0,0,,,0,0,0,0,,,0,0,0,0,,,0,0,0,0,,,0,0,0,0,,,0,0,0,0,AAPL
2024-10-22 13:18:06.564997619+00:00,10,39,38,C,B,0,232.4,2000,130,204472,70942,,236.4,0,2000,0,1,,,0,0,0,0,,,0,0,0,0,,,0,0,0,0,,,0,0,0,0,,,0,0,0,0,,,0,0,0,0,,,0,0,0,0,,,0,0,0,0,,,0,0,0,0,AAPL
2024-10-22 13:18:06.600646477+00:00,10,39,38,A,B,0,232.4,2000,130,204406,70943,232.4,236.4,2000,2000,1,1,,,0,0,0,0,,,0,0,0,0,,,0,0,0,0,,,0,0,0,0,,,0,0,0,0,,,0,0,0,0,,,0,0,0,0,,,0,0,0,0,,,0,0,0,0,AAPL
2024-10-22 13:18:06.630202787+00:00,10,39,38,C,A,0,236.4,2000,130,204445,70944,232.4,,2000,0,1,0,,,0,0,0,0,,,0,0,0,0,,,0,0,0,0,,,0,0,0,0,,,0,0,0,0,,,0,0,0,0,,,0,0,0,0,,,0,0,0,0,,,0,0,0,0,AAPL
2024-10-22 13:18:06.641493383+00:00,10,39,38,A,A,0,236.4,2000,130,204368,70945,232.4,236.4,2000,2000,1,1,,,0,0,0,0,,,0,0,0,0,,,0,0,0,0,,,0,0,0,0,,,0,0,0,0,,,0,0,0,0,,,0,0,0,0,,,0,0,0,0,,,0,0,0,0,AAPL
2024-10-22 13:18:06.688333653+00:00,10,40,38,A,B,0,234.43,200,194,203266,120915,,234.43,0,200,0,0,,,0,0,0,0,,,0,0,0,0,,,0,0,0,0,,,0,0,0,0,,,0,0,0,0,,,0,0,0,0,,,0,0,0,0,,,0,0,0,0,,,0,0,0,0,AAPL
2024-10-22 13:18:06.688350349+00:00,10,40,38,A,B,0,234.43,200,194,203124,120916,233.73,234.43,200,200,0,0,,,0,0,0,0,,,0,0,0,0,,,0,0,0,0,,,0,0,0,0,,,0,0,0,0,,,0,0,0,0,,,0,0,0,0,,,0,0,0,0,,,0,0,0,0,AAPL
2024-10-22 13:18:06.688588030+00:00,10,41,38,A,B,0,234.38,200,194,55492,295307,,234.38,0,200,0,0,,,0,0,0,0,,,0,0,0,0,,,0,0,0,0,,,0,0,0,0,,,0,0,0,0,,,0,0,0,0,,,0,0,0,0,,,0,0,0,0,,,0,0,0,0,AAPL
2024-10-22 13:18:09.787425636+00:00,10,41,38,A,B,0,234.38,200,194,55316,295547,233.81,234.38,200,200,0,0,,,0,0,0,0,,,0,0,0,0,,,0,0,0,0,,,0,0,0,0,,,0,0,0,0,,,0,0,0,0,,,0,0,0,0,,,0,0,0,0,,,0,0,0,0,AAPL
2024-10-22 13:18:09.787633241+00:00,10,39,38,C,A,0,236.4,2000,130,204261,70961,232.4,,2000,0,1,0,,,0,0,0,0,,,0,0,0,0,,,0,0,0,0,,,0,0,0,0,,,0,0,0,0,,,0,0,0,0,,,0,0,0,0,,,0,0,0,0,,,0,0,0,0,AAPL
2024-10-22 13:18:09.825529030+00:00,10,39,38,A,A,0,236.4,2000,130,204160,70963,232.4,236.4,2000,2000,1,1,,,0,0,0,0,,,0,0,0,0,,,0,0,0,0,,,0,0,0,0,,,0,0,0,0,,,0,0,0,0,,,0,0,0,0,,,0,0,0,0,,,0,0,0,0,AAPL
2024-10-22 13:18:09.850544131+00:00,10,39,38,C,B,0,232.4,2000,130,204124,70964,,236.4,0,2000,0,1,,,0,0,0,0,,,0,0,0,0,,,0,0,0,0,,,0,0,0,0,,,0,0,0,0,,,0,0,0,0,,,0,0,0,0,,,0,0,0,0,,,0,0,0,0,AAPL
2024-10-22 13:18:09.859196439+00:00,10,39,38,C,A,0,236.4,2000,130,204140,70965,,,0,0,0,0,,,0,0,0,0,,,0,0,0,0,,,0,0,0,0,,,0,0,0,0,,,0,0,0,0,,,0,0,0,0,,,0,0,0,0,,,0,0,0,0,,,0,0,0,0,AAPL
2024-10-22 13:18:09.861440393+00:00,10,39,38,A,B,0,232.2,2000,130,204164,70966,232.2,,2000,0,1,0,,,0,0,0,0,,,0,0,0,0,,,0,0,0,0,,,0,0,0,0,,,0,0,0,0,,,0,0,0,0,,,0,0,0,0,,,0,0,0,0,,,0,0,0,0,AAPL
2024-10-22 13:18:10.309456804+00:00,10,39,38,A,A,0,236.4,2000,130,205046,70968,232.2,236.4,2000,2000,1,1,,,0,0,0,0,,,0,0,0,0,,,0,0,0,0,,,0,0,0,0,,,0,0,0,0,,,0,0,0,0,,,0,0,0,0,,,0,0,0,0,,,0,0,0,0,AAPL
2024-10-22 13:18:10.367071318+00:00,10,39,38,C,A,0,236.4,2000,130,204200,70969,232.2,,2000,0,1,0,,,0,0,0,0,,,0,0,0,0,,,0,0,0,0,,,0,0,0,0,,,0,0,0,0,,,0,0,0,0,,,0,0,0,0,,,0,0,0,0,,,0,0,0,0,AAPL
2024-10-22 13:18:10.382369830+00:00,10,39,38,A,A,0,236.4,2000,130,204381,70970,232.2,236.4,2000,2000,1,1,,,0,0,0,0,,,0,0,0,0,,,0,0,0,0,,,0,0,0,0,,,0,0,0,0,,,0,0,0,0,,,0,0,0,0,,,0,0,0,0,,,0,0,0,0,AAPL
2024-10-22 13:18:12.130553385+00:00,10,39,38,A,B,0,232.4,2000,130,204521,71013,232.4,236.4,2000,2000,1,1,232.2,,2000,0,1,0,,,0,0,0,0,,,0,0,0,0,,,0,0,0,0,,,0,0,0,0,,,0,0,0,0,,,0,0,0,0,,,0,0,0,0,,,0,0,0,0,AAPL
2024-10-22 13:18:12.130748694+00:00,10,39,38,C,B,1,232.2,2000,130,204092,71014,232.4,236.4,2000,2000,1,1,,,0,0,0,0,,,0,0,0,0,,,0,0,0,0,,,0,0,0,0,,,0,0,0,0,,,0,0,0,0,,,0,0,0,0,,,0,0,0,0,,,0,0,0,0,AAPL
2024-10-22 13:18:12.157289863+00:00,10,39,38,C,B,0,232.4,2000,130,204175,71015,,236.4,0,2000,0,1,,,0,0,0,0,,,0,0,0,0,,,0,0,0,0,,,0,0,0,0,,,0,0,0,0,,,0,0,0,0,,,0,0,0,0,,,0,0,0,0,,,0,0,0,0,AAPL
2024-10-22 13:18:12.168442852+00:00,10,39,38,A,B,0,232.2,2000,130,204099,71016,232.2,236.4,2000,2000,1,1,,,0,0,0,0,,,0,0,0,0,,,0,0,0,0,,,0,0,0,0,,,0,0,0,0,,,0,0,0,0,,,0,0,0,0,,,0,0,0,0,,,0,0,0,0,AAPL
2024-10-22 13:18:20.454630250+00:00,10,39,38,C,A,0,236.4,2000,130,203807,71059,232.2,,2000,0,1,0,,,0,0,0,0,,,0,0,0,0,,,0,0,0,0,,,0,0,0,0,,,0,0,0,0,,,0,0,0,0,,,0,0,0,0,,,0,0,0,0,,,0,0,0,0,AAPL
2024-10-22 13:18:26.729255431+00:00,10,41,38,T,N,0,234.1,50,194,59357,296691,233.81,234.38,200,200,0,0,,,0,0,0,0,,,0,0,0,0,,,0,0,0,0,,,0,0,0,0,,,0,0,0,0,,,0,0,0,0,,,0,0,0,0,,,0,0,0,0,,,0,0,0,0,AAPL
2024-10-22 13:18:26.729684527+00:00,10,39,38,C,B,0,232.2,2000,130,203956,71094,,,0,0,0,0,,,0,0,0,0,,,0,0,0,0,,,0,0,0,0,,,0,0,0,0,,,0,0,0,0,,,0,0,0,0,,,0,0,0,0,,,0,0,0,0,,,0,0,0,0,AAPL
2024-10-22 13:18:26.740082140+00:00,10,39,38,A,A,0,236.4,2000,130,203790,71095,,236.4,0,2000,0,1,,,0,0,0,0,,,0,0,0,0,,,0,0,0,0,,,0,0,0,0,,,0,0,0,0,,,0,0,0,0,,,0,0,0,0,,,0,0,0,0,,,0,0,0,0,AAPL
2024-10-22 13:18:26.775582061+00:00,10,39,38,A,B,0,232.4,2000,130,203775,71096,232.4,236.4,2000,2000,1,1,,,0,0,0,0,,,0,0,0,0,,,0,0,0,0,,,0,0,0,0,,,0,0,0,0,,,0,0,0,0,,,0,0,0,0,,,0,0,0,0,,,0,0,0,0,AAPL
2024-10-22 13:18:26.784684040+00:00,10,39,38,C,A,0,236.4,2000,130,203719,71097,232.4,,2000,0,1,0,,,0,0,0,0,,,0,0,0,0,,,0,0,0,0,,,0,0,0,0,,,0,0,0,0,,,0,0,0,0,,,0,0,0,0,,,0,0,0,0,,,0,0,0,0,AAPL
2024-10-22 13:18:26.800770999+00:00,10,39,38,A,A,0,236.4,2000,130,203789,71098,232.4,236.4,2000,2000,1,1,,,0,0,0,0,,,0,0,0,0,,,0,0,0,0,,,0,0,0,0,,,0,0,0,0,,,0,0,0,0,,,0,0,0,0,,,0,0,0,0,,,0,0,0,0,AAPL
2024-10-22 13:18:26.810277150+00:00,10,39,38,C,A,0,236.4,2000,130,203678,71099,232.4,,2000,0,1,0,,,0,0,0,0,,,0,0,0,0,,,0,0,0,0,,,0,0,0,0,,,0,0,0,0,,,0,0,0,0,,,0,0,0,0,,,0,0,0,0,,,0,0,0,0,AAPL
2024-10-22 13:18:26.821294428+00:00,10,39,38,A,A,0,236.4,2000,130,203723,71100,232.4,236.4,2000,2000,1,1,,,0,0,0,0,,,0,0,0,0,,,0,0,0,0,,,0,0,0,0,,,0,0,0,0,,,0,0,0,0,,,0,0,0,0,,,0,0,0,0,,,0,0,0,0,AAPL
2024-10-22 13:18:26.872001786+00:00,10,40,38,A,B,0,234.43,200,194,202821,121192,,234.43,0,200,0,0,,,0,0,0,0,,,0,0,0,0,,,0,0,0,0,,,0,0,0,0,,,0,0,0,0,,,0,0,0,0,,,0,0,0,0,,,0,0,0,0,,,0,0,0,0,AAPL
2024-10-22 13:18:26.872174685+00:00,10,41,38,A,B,0,234.38,200,194,55602,296695,,234.38,0,200,0,0,,,0,0,0,0,,,0,0,0,0,,,0,0,0,0,,,0,0,0,0,,,0,0,0,0,,,0,0,0,0,,,0,0,0,0,,,0,0,0,0,,,0,0,0,0,AAPL
2024-10-22 13:18:27.043002466+00:00,10,40,38,A,A,0,,0,194,202900,121195,,,0,0,0,0,,,0,0,0,0,,,0,0,0,0,,,0,0,0,0,,,0,0,0,0,,,0,0,0,0,,,0,0,0,0,,,0,0,0,0,,,0,0,0,0,,,0,0,0,0,AAPL
2024-10-22 13:18:27.043020695+00:00,10,40,38,A,A,0,234.3,200,194,202829,121196,,234.3,0,200,0,0,,,0,0,0,0,,,0,0,0,0,,,0,0,0,0,,,0,0,0,0,,,0,0,0,0,,,0,0,0,0,,,0,0,0,0,,,0,0,0,0,,,0,0,0,0,AAPL
2024-10-22 13:18:27.043262400+00:00,10,41,38,A,A,0,,0,194,55692,296702,,,0,0,0,0,,,0,0,0,0,,,0,0,0,0,,,0,0,0,0,,,0,0,0,0,,,0,0,0,0,,,0,0,0,0,,,0,0,0,0,,,0,0,0,0,,,0,0,0,0,AAPL
2024-10-22 13:18:27.043269917+00:00,10,41,38,A,A,0,234.25,200,194,55517,296703,,234.25,0,200,0,0,,,0,0,0,0,,,0,0,0,0,,,0,0,0,0,,,0,0,0,0,,,0,0,0,0,,,0,0,0,0,,,0,0,0,0,,,0,0,0,0,,,0,0,0,0,AAPL
2024-10-22 13:18:32.686673998+00:00,10,40,38,A,B,0,234.3,200,194,202860,121310,233.68,234.3,200,200,0,0,,,0,0,0,0,,,0,0,0,0,,,0,0,0,0,,,0,0,0,0,,,0,0,0,0,,,0,0,0,0,,,0,0,0,0,,,0,0,0,0,,,0,0,0,0,AAPL
2024-10-22 13:18:34.516691642+00:00,10,41,38,A,B,0,234.25,200,194,55469,297239,233.73,234.25,200,200,0,0,,,0,0,0,0,,,0,0,0,0,,,0,0,0,0,,,0,0,0,0,,,0,0,0,0,,,0,0,0,0,,,0,0,0,0,,,0,0,0,0,,,0,0,0,0,AAPL
2024-10-22 13:18:36.643733534+00:00,10,40,38,A,B,0,234.3,200,194,202844,121370,,234.3,0,200,0,0,,,0,0,0,0,,,0,0,0,0,,,0,0,0,0,,,0,0,0,0,,,0,0,0,0,,,0,0,0,0,,,0,0,0,0,,,0,0,0,0,,,0,0,0,0,AAPL
2024-10-22 13:18:36.644138920+00:00,10,40,38,A,B,0,234.3,200,194,202795,121373,233.68,234.3,200,200,0,0,,,0,0,0,0,,,0,0,0,0,,,0,0,0,0,,,0,0,0,0,,,0,0,0,0,,,0,0,0,0,,,0,0,0,0,,,0,0,0,0,,,0,0,0,0,AAPL
2024-10-22 13:18:39.149337768+00:00,10,39,38,C,B,0,232.4,2000,130,204102,71116,,236.4,0,2000,0,1,,,0,0,0,0,,,0,0,0,0,,,0,0,0,0,,,0,0,0,0,,,0,0,0,0,,,0,0,0,0,,,0,0,0,0,,,0,0,0,0,,,0,0,0,0,AAPL
2024-10-22 13:18:39.160359181+00:00,10,39,38,A,B,0,232.2,2000,130,203907,71117,232.2,236.4,2000,2000,1,1,,,0,0,0,0,,,0,0,0,0,,,0,0,0,0,,,0,0,0,0,,,0,0,0,0,,,0,0,0,0,,,0,0,0,0,,,0,0,0,0,,,0,0,0,0,AAPL
2024-10-22 13:18:50.094961647+00:00,10,41,38,A,B,0,234.25,200,194,55731,298426,,234.25,0,200,0,0,,,0,0,0,0,,,0,0,0,0,,,0,0,0,0,,,0,0,0,0,,,0,0,0,0,,,0,0,0,0,,,0,0,0,0,,,0,0,0,0,,,0,0,0,0,AAPL
2024-10-22 13:18:50.095014719+00:00,10,41,38,A,B,0,234.25,200,194,54525,298427,233.71,234.25,200,200,0,0,,,0,0,0,0,,,0,0,0,0,,,0,0,0,0,,,0,0,0,0,,,0,0,0,0,,,0,0,0,0,,,0,0,0,0,,,0,0,0,0,,,0,0,0,0,AAPL
2024-10-22 13:18:58.833003097+00:00,10,39,38,C,A,0,236.4,2000,130,203799,71183,232.2,,2000,0,1,0,,,0,0,0,0,,,0,0,0,0,,,0,0,0,0,,,0,0,0,0,,,0,0,0,0,,,0,0,0,0,,,0,0,0,0,,,0,0,0,0,,,0,0,0,0,AAPL
2024-10-22 13:18:58.842671352+00:00,10,39,38,A,B,0,232.4,2000,130,203642,71185,232.4,,2000,0,1,0,232.2,,2000,0,1,0,,,0,0,0,0,,,0,0,0,0,,,0,0,0,0,,,0,0,0,0,,,0,0,0,0,,,0,0,0,0,,,0,0,0,0,,,0,0,0,0,AAPL
2024-10-22 13:18:58.842863408+00:00,10,39,38,C,B,1,232.2,2000,130,203561,71186,232.4,,2000,0,1,0,,,0,0,0,0,,,0,0,0,0,,,0,0,0,0,,,0,0,0,0,,,0,0,0,0,,,0,0,0,0,,,0,0,0,0,,,0,0,0,0,,,0,0,0,0,AAPL
2024-10-22 13:19:00.000912193+00:00,10,40,38,A,B,0,234.3,200,194,202702,121619,,234.3,0,200,0,0,,,0,0,0,0,,,0,0,0,0,,,0,0,0,0,,,0,0,0,0,,,0,0,0,0,,,0,0,0,0,,,0,0,0,0,,,0,0,0,0,,,0,0,0,0,AAPL
2024-10-22 13:19:00.000920513+00:00,10,40,38,A,A,0,,0,194,202740,121620,,,0,0,0,0,,,0,0,0,0,,,0,0,0,0,,,0,0,0,0,,,0,0,0,0,,,0,0,0,0,,,0,0,0,0,,,0,0,0,0,,,0,0,0,0,,,0,0,0,0,AAPL
2024-10-22 13:19:00.001379156+00:00,10,41,38,A,B,0,234.25,200,194,56020,299077,,234.25,0,200,0,0,,,0,0,0,0,,,0,0,0,0,,,0,0,0,0,,,0,0,0,0,,,0,0,0,0,,,0,0,0,0,,,0,0,0,0,,,0,0,0,0,,,0,0,0,0,AAPL
2024-10-22 13:19:00.001382465+00:00,10,41,38,A,A,0,,0,194,54401,299078,,,0,0,0,0,,,0,0,0,0,,,0,0,0,0,,,0,0,0,0,,,0,0,0,0,,,0,0,0,0,,,0,0,0,0,,,0,0,0,0,,,0,0,0,0,,,0,0,0,0,AAPL
2024-10-22 13:19:00.112009293+00:00,10,41,38,A,A,0,234.25,200,194,55558,299293,,234.25,0,200,0,0,,,0,0,0,0,,,0,0,0,0,,,0,0,0,0,,,0,0,0,0,,,0,0,0,0,,,0,0,0,0,,,0,0,0,0,,,0,0,0,0,,,0,0,0,0,AAPL
2024-10-22 13:19:00.231227205+00:00,10,41,38,A,B,0,234.25,200,194,55907,299353,233.71,234.25,200,200,0,0,,,0,0,0,0,,,0,0,0,0,,,0,0,0,0,,,0,0,0,0,,,0,0,0,0,,,0,0,0,0,,,0,0,0,0,,,0,0,0,0,,,0,0,0,0,AAPL
2024-10-22 13:19:00.600900905+00:00,10,40,38,A,A,0,234.3,200,194,202671,121711,,234.3,0,200,0,0,,,0,0,0,0,,,0,0,0,0,,,0,0,0,0,,,0,0,0,0,,,0,0,0,0,,,0,0,0,0,,,0,0,0,0,,,0,0,0,0,,,0,0,0,0,AAPL
2024-10-22 13:19:00.601023598+00:00,10,40,38,A,B,0,234.3,200,194,202721,121712,233.66,234.3,200,200,0,0,,,0,0,0,0,,,0,0,0,0,,,0,0,0,0,,,0,0,0,0,,,0,0,0,0,,,0,0,0,0,,,0,0,0,0,,,0,0,0,0,,,0,0,0,0,AAPL
2024-10-22 13:19:00.939952482+00:00,10,41,38,A,B,0,234.25,200,194,60090,299446,,234.25,0,200,0,0,,,0,0,0,0,,,0,0,0,0,,,0,0,0,0,,,0,0,0,0,,,0,0,0,0,,,0,0,0,0,,,0,0,0,0,,,0,0,0,0,,,0,0,0,0,AAPL
2024-10-22 13:19:01.591401543+00:00,10,41,38,A,B,0,234.25,200,194,55364,299501,233.71,234.25,200,200,0,0,,,0,0,0,0,,,0,0,0,0,,,0,0,0,0,,,0,0,0,0,,,0,0,0,0,,,0,0,0,0,,,0,0,0,0,,,0,0,0,0,,,0,0,0,0,AAPL
2024-10-22 13:19:09.622991028+00:00,10,39,38,A,A,0,236.4,2000,130,204000,71256,232.4,236.4,2000,2000,1,1,,,0,0,0,0,,,0,0,0,0,,,0,0,0,0,,,0,0,0,0,,,0,0,0,0,,,0,0,0,0,,,0,0,0,0,,,0,0,0,0,,,0,0,0,0,AAPL
2024-10-22 13:19:31.751435058+00:00,10,39,38,C,B,0,232.4,2000,130,203528,71371,,236.4,0,2000,0,1,,,0,0,0,0,,,0,0,0,0,,,0,0,0,0,,,0,0,0,0,,,0,0,0,0,,,0,0,0,0,,,0,0,0,0,,,0,0,0,0,,,0,0,0,0,AAPL
2024-10-22 13:19:31.764607955+00:00,10,39,38,A,B,0,232.2,2000,130,203114,71372,232.2,236.4,2000,2000,1,1,,,0,0,0,0,,,0,0,0,0,,,0,0,0,0,,,0,0,0,0,,,0,0,0,0,,,0,0,0,0,,,0,0,0,0,,,0,0,0,0,,,0,0,0,0,AAPL
2024-10-22 13:19:33.073472084+00:00,10,39,10888,C,A,0,421.2,2000,130,203330,104503,,,0,0,0,0,,,0,0,0,0,,,0,0,0,0,,,0,0,0,0,,,0,0,0,0,,,0,0,0,0,,,0,0,0,0,,,0,0,0,0,,,0,0,0,0,,,0,0,0,0,MSFT
2024-10-22 13:19:33.109859786+00:00,10,39,10888,A,A,0,421.2,2000,130,203038,104504,,421.2,0,2000,0,1,,,0,0,0,0,,,0,0,0,0,,,0,0,0,0,,,0,0,0,0,,,0,0,0,0,,,0,0,0,0,,,0,0,0,0,,,0,0,0,0,,,0,0,0,0,MSFT
2024-10-22 13:19:41.620457752+00:00,10,39,38,A,B,0,232.4,2000,130,203731,71402,232.4,236.4,2000,2000,1,1,232.2,,2000,0,1,0,,,0,0,0,0,,,0,0,0,0,,,0,0,0,0,,,0,0,0,0,,,0,0,0,0,,,0,0,0,0,,,0,0,0,0,,,0,0,0,0,AAPL
2024-10-22 13:19:41.620663100+00:00,10,39,38,C,B,1,232.2,2000,130,203389,71403,232.4,236.4,2000,2000,1,1,,,0,0,0,0,,,0,0,0,0,,,0,0,0,0,,,0,0,0,0,,,0,0,0,0,,,0,0,0,0,,,0,0,0,0,,,0,0,0,0,,,0,0,0,0,AAPL
2024-10-22 13:19:50.179716812+00:00,10,39,38,C,A,0,236.4,2000,130,202927,71443,232.4,,2000,0,1,0,,,0,0,0,0,,,0,0,0,0,,,0,0,0,0,,,0,0,0,0,,,0,0,0,0,,,0,0,0,0,,,0,0,0,0,,,0,0,0,0,,,0,0,0,0,AAPL
2024-10-22 13:19:50.215938279+00:00,10,39,38,A,A,0,236.4,2000,130,202892,71444,232.4,236.4,2000,2000,1,1,,,0,0,0,0,,,0,0,0,0,,,0,0,0,0,,,0,0,0,0,,,0,0,0,0,,,0,0,0,0,,,0,0,0,0,,,0,0,0,0,,,0,0,0,0,AAPL
2024-10-22 13:19:50.445465870+00:00,10,39,10888,C,A,0,421.2,2000,130,202695,104712,,,0,0,0,0,,,0,0,0,0,,,0,0,0,0,,,0,0,0,0,,,0,0,0,0,,,0,0,0,0,,,0,0,0,0,,,0,0,0,0,,,0,0,0,0,,,0,0,0,0,MSFT
2024-10-22 13:19:50.482406393+00:00,10,39,10888,A,A,0,421.2,2000,130,202827,104717,,421.2,0,2000,0,1,,,0,0,0,0,,,0,0,0,0,,,0,0,0,0,,,0,0,0,0,,,0,0,0,0,,,0,0,0,0,,,0,0,0,0,,,0,0,0,0,,,0,0,0,0,MSFT
2024-10-22 13:19:50.552004567+00:00,10,39,38,C,A,0,236.4,2000,130,203010,71448,232.4,,2000,0,1,0,,,0,0,0,0,,,0,0,0,0,,,0,0,0,0,,,0,0,0,0,,,0,0,0,0,,,0,0,0,0,,,0,0,0,0,,,0,0,0,0,,,0,0,0,0,AAPL
2024-10-22 13:19:50.580827347+00:00,10,39,38,A,A,0,236.4,2000,130,202805,71449,232.4,236.4,2000,2000,1,1,,,0,0,0,0,,,0,0,0,0,,,0,0,0,0,,,0,0,0,0,,,0,0,0,0,,,0,0,0,0,,,0,0,0,0,,,0,0,0,0,,,0,0,0,0,AAPL
2024-10-22 13:19:58.660072751+00:00,10,40,10888,A,B,0,,0,194,202561,122856,398.2,,100,0,0,0,,,0,0,0,0,,,0,0,0,0,,,0,0,0,0,,,0,0,0,0,,,0,0,0,0,,,0,0,0,0,,,0,0,0,0,,,0,0,0,0,,,0,0,0,0,MSFT
2024-10-22 13:19:58.660080367+00:00,10,40,10888,A,A,0,440.22,100,194,202518,122857,398.2,440.22,100,100,0,0,,,0,0,0,0,,,0,0,0,0,,,0,0,0,0,,,0,0,0,0,,,0,0,0,0,,,0,0,0,0,,,0,0,0,0,,,0,0,0,0,,,0,0,0,0,MSFT
2024-10-22 13:19:59.579043360+00:00,10,39,38,C,A,0,236.4,2000,130,202798,71527,232.4,,2000,0,1,0,,,0,0,0,0,,,0,0,0,0,,,0,0,0,0,,,0,0,0,0,,,0,0,0,0,,,0,0,0,0,,,0,0,0,0,,,0,0,0,0,,,0,0,0,0,AAPL
2024-10-22 13:19:59.614426696+00:00,10,39,38,A,A,0,236.4,2000,130,202777,71530,232.4,236.4,2000,2000,1,1,,,0,0,0,0,,,0,0,0,0,,,0,0,0,0,,,0,0,0,0,,,0,0,0,0,,,0,0,0,0,,,0,0,0,0,,,0,0,0,0,,,0,0,0,0,AAPL
2024-10-22 13:20:00.022532016+00:00,10,40,38,A,B,0,234.3,200,194,202626,123102,222.26,234.3,100,200,0,0,,,0,0,0,0,,,0,0,0,0,,,0,0,0,0,,,0,0,0,0,,,0,0,0,0,,,0,0,0,0,,,0,0,0,0,,,0,0,0,0,,,0,0,0,0,AAPL
2024-10-22 13:20:00.022540921+00:00,10,40,38,A,A,0,245.7,100,194,202675,123103,222.26,245.7,100,100,0,0,,,0,0,0,0,,,0,0,0,0,,,0,0,0,0,,,0,0,0,0,,,0,0,0,0,,,0,0,0,0,,,0,0,0,0,,,0,0,0,0,,,0,0,0,0,AAPL
2024-10-22 13:20:00.023030104+00:00,10,41,38,A,B,0,234.25,200,194,54779,303236,,234.25,0,200,0,0,,,0,0,0,0,,,0,0,0,0,,,0,0,0,0,,,0,0,0,0,,,0,0,0,0,,,0,0,0,0,,,0,0,0,0,,,0,0,0,0,,,0,0,0,0,AAPL
2024-10-22 13:20:00.023039003+00:00,10,41,38,A,A,0,,0,194,55083,303237,,,0,0,0,0,,,0,0,0,0,,,0,0,0,0,,,0,0,0,0,,,0,0,0,0,,,0,0,0,0,,,0,0,0,0,,,0,0,0,0,,,0,0,0,0,,,0,0,0,0,AAPL
2024-10-22 13:20:00.653877828+00:00,10,40,38,A,N,0,,0,194,202769,123510,,,0,0,0,0,,,0,0,0,0,,,0,0,0,0,,,0,0,0,0,,,0,0,0,0,,,0,0,0,0,,,0,0,0,0,,,0,0,0,0,,,0,0,0,0,,,0,0,0,0,AAPL
2024-10-22 13:20:00.870642628+00:00,10,40,10888,A,N,0,,0,194,202803,123636,,,0,0,0,0,,,0,0,0,0,,,0,0,0,0,,,0,0,0,0,,,0,0,0,0,,,0,0,0,0,,,0,0,0,0,,,0,0,0,0,,,0,0,0,0,,,0,0,0,0,MSFT
2024-10-22 13:20:03.348540077+00:00,10,40,38,A,B,0,,0,194,202781,123747,233.68,,200,0,0,0,,,0,0,0,0,,,0,0,0,0,,,0,0,0,0,,,0,0,0,0,,,0,0,0,0,,,0,0,0,0,,,0,0,0,0,,,0,0,0,0,,,0,0,0,0,AAPL
2024-10-22 13:20:03.701762802+00:00,10,40,38,A,B,0,,0,194,202720,123757,,,0,0,0,0,,,0,0,0,0,,,0,0,0,0,,,0,0,0,0,,,0,0,0,0,,,0,0,0,0,,,0,0,0,0,,,0,0,0,0,,,0,0,0,0,,,0,0,0,0,AAPL
2024-10-22 13:20:04.999288680+00:00,10,40,38,A,B,0,,0,194,202759,123771,233.68,,200,0,0,0,,,0,0,0,0,,,0,0,0,0,,,0,0,0,0,,,0,0,0,0,,,0,0,0,0,,,0,0,0,0,,,0,0,0,0,,,0,0,0,0,,,0,0,0,0,AAPL
2024-10-22 13:20:04.999294404+00:00,10,40,38,A,A,0,234.3,200,194,202753,123772,233.68,234.3,200,200,0,0,,,0,0,0,0,,,0,0,0,0,,,0,0,0,0,,,0,0,0,0,,,0,0,0,0,,,0,0,0,0,,,0,0,0,0,,,0,0,0,0,,,0,0,0,0,AAPL
2024-10-22 13:20:04.999770135+00:00,10,41,38,A,A,0,234.25,200,194,55683,303888,,234.25,0,200,0,0,,,0,0,0,0,,,0,0,0,0,,,0,0,0,0,,,0,0,0,0,,,0,0,0,0,,,0,0,0,0,,,0,0,0,0,,,0,0,0,0,,,0,0,0,0,AAPL
2024-10-22 13:20:05.000090442+00:00,10,39,38,C,B,0,232.4,2000,130,203056,71587,,236.4,0,2000,0,1,,,0,0,0,0,,,0,0,0,0,,,0,0,0,0,,,0,0,0,0,,,0,0,0,0,,,0,0,0,0,,,0,0,0,0,,,0,0,0,0,,,0,0,0,0,AAPL
2024-10-22 13:20:05.035971553+00:00,10,39,38,A,B,0,232.4,2000,130,203068,71589,232.4,236.4,2000,2000,1,1,,,0,0,0,0,,,0,0,0,0,,,0,0,0,0,,,0,0,0,0,,,0,0,0,0,,,0,0,0,0,,,0,0,0,0,,,0,0,0,0,,,0,0,0,0,AAPL
2024-10-22 13:20:05.036276804+00:00,10,41,38,A,B,0,234.25,200,194,55516,303901,233.72,234.25,200,200,0,0,,,0,0,0,0,,,0,0,0,0,,,0,0,0,0,,,0,0,0,0,,,0,0,0,0,,,0,0,0,0,,,0,0,0,0,,,0,0,0,0,,,0,0,0,0,AAPL
2024-10-22 13:20:05.067742572+00:00,10,39,38,C,A,0,236.4,2000,130,202962,71590,232.4,,2000,0,1,0,,,0,0,0,0,,,0,0,0,0,,,0,0,0,0,,,0,0,0,0,,,0,0,0,0,,,0,0,0,0,,,0,0,0,0,,,0,0,0,0,,,0,0,0,0,AAPL
2024-10-22 13:20:05.100094959+00:00,10,41,38,A,A,0,,0,194,55118,303941,233.72,,200,0,0,0,,,0,0,0,0,,,0,0,0,0,,,0,0,0,0,,,0,0,0,0,,,0,0,0,0,,,0,0,0,0,,,0,0,0,0,,,0,0,0,0,,,0,0,0,0,AAPL
2024-10-22 13:20:05.132010538+00:00,10,40,38,A,A,0,,0,194,202750,123786,233.68,,200,0,0,0,,,0,0,0,0,,,0,0,0,0,,,0,0,0,0,,,0,0,0,0,,,0,0,0,0,,,0,0,0,0,,,0,0,0,0,,,0,0,0,0,,,0,0,0,0,AAPL
2024-10-22 13:20:05.334816205+00:00,10,41,38,A,B,0,,0,194,56057,303980,,,0,0,0,0,,,0,0,0,0,,,0,0,0,0,,,0,0,0,0,,,0,0,0,0,,,0,0,0,0,,,0,0,0,0,,,0,0,0,0,,,0,0,0,0,,,0,0,0,0,AAPL
2024-10-22 13:20:05.588045967+00:00,10,40,38,A,A,0,234.3,200,194,202825,123795,233.68,234.3,200,200,0,0,,,0,0,0,0,,,0,0,0,0,,,0,0,0,0,,,0,0,0,0,,,0,0,0,0,,,0,0,0,0,,,0,0,0,0,,,0,0,0,0,,,0,0,0,0,AAPL
2024-10-22 13:20:05.588522013+00:00,10,41,38,A,A,0,234.25,200,194,55696,304006,,234.25,0,200,0,0,,,0,0,0,0,,,0,0,0,0,,,0,0,0,0,,,0,0,0,0,,,0,0,0,0,,,0,0,0,0,,,0,0,0,0,,,0,0,0,0,,,0,0,0,0,AAPL
2024-10-22 13:20:05.631877225+00:00,10,41,38,A,B,0,234.25,200,194,55534,304007,233.72,234.25,200,200,0,0,,,0,0,0,0,,,0,0,0,0,,,0,0,0,0,,,0,0,0,0,,,0,0,0,0,,,0,0,0,0,,,0,0,0,0,,,0,0,0,0,,,0,0,0,0,AAPL
2024-10-22 13:20:05.731712577+00:00,10,40,38,A,A,0,,0,194,202866,123798,233.68,,200,0,0,0,,,0,0,0,0,,,0,0,0,0,,,0,0,0,0,,,0,0,0,0,,,0,0,0,0,,,0,0,0,0,,,0,0,0,0,,,0,0,0,0,,,0,0,0,0,AAPL
2024-10-22 13:20:05.732171325+00:00,10,41,38,A,B,0,234.25,200,194,56145,304016,,234.25,0,200,0,0,,,0,0,0,0,,,0,0,0,0,,,0,0,0,0,,,0,0,0,0,,,0,0,0,0,,,0,0,0,0,,,0,0,0,0,,,0,0,0,0,,,0,0,0,0,AAPL
2024-10-22 13:20:05.732180813+00:00,10,41,38,A,A,0,,0,194,54526,304017,,,0,0,0,0,,,0,0,0,0,,,0,0,0,0,,,0,0,0,0,,,0,0,0,0,,,0,0,0,0,,,0,0,0,0,,,0,0,0,0,,,0,0,0,0,,,0,0,0,0,AAPL
2024-10-22 13:20:06.645612352+00:00,10,40,38,A,B,0,,0,194,202829,123813,,,0,0,0,0,,,0,0,0,0,,,0,0,0,0,,,0,0,0,0,,,0,0,0,0,,,0,0,0,0,,,0,0,0,0,,,0,0,0,0,,,0,0,0,0,,,0,0,0,0,AAPL
2024-10-22 13:20:06.645637723+00:00,10,40,38,A,B,0,,0,194,202801,123814,233.67,,200,0,0,0,,,0,0,0,0,,,0,0,0,0,,,0,0,0,0,,,0,0,0,0,,,0,0,0,0,,,0,0,0,0,,,0,0,0,0,,,0,0,0,0,,,0,0,0,0,AAPL
2024-10-22 13:20:07.495249106+00:00,10,40,38,A,B,0,,0,194,202901,123832,,,0,0,0,0,,,0,0,0,0,,,0,0,0,0,,,0,0,0,0,,,0,0,0,0,,,0,0,0,0,,,0,0,0,0,,,0,0,0,0,,,0,0,0,0,,,0,0,0,0,AAPL
2024-10-22 13:20:09.034938109+00:00,10,40,38,A,B,0,,0,194,203182,123851,233.68,,200,0,0,0,,,0,0,0,0,,,0,0,0,0,,,0,0,0,0,,,0,0,0,0,,,0,0,0,0,,,0,0,0,0,,,0,0,0,0,,,0,0,0,0,,,0,0,0,0,AAPL
2024-10-22 13:20:09.034944830+00:00,10,40,38,A,A,0,234.3,200,194,203004,123852,233.68,234.3,200,200,0,0,,,0,0,0,0,,,0,0,0,0,,,0,0,0,0,,,0,0,0,0,,,0,0,0,0,,,0,0,0,0,,,0,0,0,0,,,0,0,0,0,,,0,0,0,0,AAPL
2024-10-22 13:20:09.035432297+00:00,10,41,38,A,A,0,234.25,200,194,55820,304263,,234.25,0,200,0,0,,,0,0,0,0,,,0,0,0,0,,,0,0,0,0,,,0,0,0,0,,,0,0,0,0,,,0,0,0,0,,,0,0,0,0,,,0,0,0,0,,,0,0,0,0,AAPL
2024-10-22 13:20:09.035447404+00:00,10,41,38,A,B,0,234.25,200,194,58290,304265,233.73,234.25,200,200,0,0,,,0,0,0,0,,,0,0,0,0,,,0,0,0,0,,,0,0,0,0,,,0,0,0,0,,,0,0,0,0,,,0,0,0,0,,,0,0,0,0,,,0,0,0,0,AAPL
2024-10-22 13:20:09.124452034+00:00,10,41,38,A,A,0,,0,194,55014,304286,233.73,,200,0,0,0,,,0,0,0,0,,,0,0,0,0,,,0,0,0,0,,,0,0,0,0,,,0,0,0,0,,,0,0,0,0,,,0,0,0,0,,,0,0,0,0,,,0,0,0,0,AAPL
2024-10-22 13:20:09.171715378+00:00,10,40,38,A,A,0,,0,194,202951,123857,233.68,,200,0,0,0,,,0,0,0,0,,,0,0,0,0,,,0,0,0,0,,,0,0,0,0,,,0,0,0,0,,,0,0,0,0,,,0,0,0,0,,,0,0,0,0,,,0,0,0,0,AAPL
2024-10-22 13:20:09.171824767+00:00,10,40,38,A,B,0,,0,194,202930,123858,,,0,0,0,0,,,0,0,0,0,,,0,0,0,0,,,0,0,0,0,,,0,0,0,0,,,0,0,0,0,,,0,0,0,0,,,0,0,0,0,,,0,0,0,0,,,0,0,0,0,AAPL
2024-10-22 13:20:12.231119369+00:00,10,39,10888,C,A,0,421.2,2000,130,202597,104894,,,0,0,0,0,,,0,0,0,0,,,0,0,0,0,,,0,0,0,0,,,0,0,0,0,,,0,0,0,0,,,0,0,0,0,,,0,0,0,0,,,0,0,0,0,,,0,0,0,0,MSFT
2024-10-22 13:20:12.267141893+00:00,10,39,10888,A,A,0,421.2,2000,130,202618,104895,,421.2,0,2000,0,1,,,0,0,0,0,,,0,0,0,0,,,0,0,0,0,,,0,0,0,0,,,0,0,0,0,,,0,0,0,0,,,0,0,0,0,,,0,0,0,0,,,0,0,0,0,MSFT
2024-10-22 13:20:13.271483759+00:00,10,39,10888,C,A,0,421.2,2000,130,202742,104899,,,0,0,0,0,,,0,0,0,0,,,0,0,0,0,,,0,0,0,0,,,0,0,0,0,,,0,0,0,0,,,0,0,0,0,,,0,0,0,0,,,0,0,0,0,,,0,0,0,0,MSFT
2024-10-22 13:20:13.308330390+00:00,10,39,10888,A,A,0,421.2,2000,130,202639,104900,,421.2,0,2000,0,1,,,0,0,0,0,,,0,0,0,0,,,0,0,0,0,,,0,0,0,0,,,0,0,0,0,,,0,0,0,0,,,0,0,0,0,,,0,0,0,0,,,0,0,0,0,MSFT
2024-10-22 13:20:13.838865005+00:00,10,40,38,A,B,0,,0,194,203065,123904,233.68,,200,0,0,0,,,0,0,0,0,,,0,0,0,0,,,0,0,0,0,,,0,0,0,0,,,0,0,0,0,,,0,0,0,0,,,0,0,0,0,,,0,0,0,0,,,0,0,0,0,AAPL
2024-10-22 13:20:13.838958571+00:00,10,40,38,A,A,0,234.3,200,194,203168,123905,233.68,234.3,200,200,0,0,,,0,0,0,0,,,0,0,0,0,,,0,0,0,0,,,0,0,0,0,,,0,0,0,0,,,0,0,0,0,,,0,0,0,0,,,0,0,0,0,,,0,0,0,0,AAPL
2024-10-22 13:20:14.040113823+00:00,10,40,38,A,A,0,,0,194,203191,123907,233.68,,200,0,0,0,,,0,0,0,0,,,0,0,0,0,,,0,0,0,0,,,0,0,0,0,,,0,0,0,0,,,0,0,0,0,,,0,0,0,0,,,0,0,0,0,,,0,0,0,0,AAPL
2024-10-22 13:20:14.767624157+00:00,10,40,38,A,A,0,234.3,200,194,203583,123908,233.68,234.3,200,200,0,0,,,0,0,0,0,,,0,0,0,0,,,0,0,0,0,,,0,0,0,0,,,0,0,0,0,,,0,0,0,0,,,0,0,0,0,,,0,0,0,0,,,0,0,0,0,AAPL
2024-10-22 13:20:14.767881720+00:00,10,41,38,A,A,0,234.25,200,194,55674,304695,233.73,234.25,200,200,0,0,,,0,0,0,0,,,0,0,0,0,,,0,0,0,0,,,0,0,0,0,,,0,0,0,0,,,0,0,0,0,,,0,0,0,0,,,0,0,0,0,,,0,0,0,0,AAPL
2024-10-22 13:20:14.770737753+00:00,10,39,38,C,B,0,232.4,2000,130,202519,71645,,,0,0,0,0,,,0,0,0,0,,,0,0,0,0,,,0,0,0,0,,,0,0,0,0,,,0,0,0,0,,,0,0,0,0,,,0,0,0,0,,,0,0,0,0,,,0,0,0,0,AAPL
2024-10-22 13:20:14.781626829+00:00,10,39,38,A,B,0,232.2,2000,130,202470,71646,232.2,,2000,0,1,0,,,0,0,0,0,,,0,0,0,0,,,0,0,0,0,,,0,0,0,0,,,0,0,0,0,,,0,0,0,0,,,0,0,0,0,,,0,0,0,0,,,0,0,0,0,AAPL
2024-10-22 13:20:14.793305151+00:00,10,39,38,A,B,0,232.4,2000,130,202470,71647,232.4,,2000,0,1,0,232.2,,2000,0,1,0,,,0,0,0,0,,,0,0,0,0,,,0,0,0,0,,,0,0,0,0,,,0,0,0,0,,,0,0,0,0,,,0,0,0,0,,,0,0,0,0,AAPL
2024-10-22 13:20:14.793495323+00:00,10,39,38,C,B,1,232.2,2000,130,202363,71648,232.4,,2000,0,1,0,,,0,0,0,0,,,0,0,0,0,,,0,0,0,0,,,0,0,0,0,,,0,0,0,0,,,0,0,0,0,,,0,0,0,0,,,0,0,0,0,,,0,0,0,0,AAPL
2024-10-22 13:20:14.974913022+00:00,10,41,38,A,B,0,234.25,200,194,55810,304705,,234.25,0,200,0,0,,,0,0,0,0,,,0,0,0,0,,,0,0,0,0,,,0,0,0,0,,,0,0,0,0,,,0,0,0,0,,,0,0,0,0,,,0,0,0,0,,,0,0,0,0,AAPL
2024-10-22 13:20:14.974921293+00:00,10,41,38,A,A,0,,0,194,55327,304706,,,0,0,0,0,,,0,0,0,0,,,0,0,0,0,,,0,0,0,0,,,0,0,0,0,,,0,0,0,0,,,0,0,0,0,,,0,0,0,0,,,0,0,0,0,,,0,0,0,0,AAPL
2024-10-22 13:20:14.975443927+00:00,10,41,38,A,A,0,234.25,200,194,55552,304707,,234.25,0,200,0,0,,,0,0,0,0,,,0,0,0,0,,,0,0,0,0,,,0,0,0,0,,,0,0,0,0,,,0,0,0,0,,,0,0,0,0,,,0,0,0,0,,,0,0,0,0,AAPL
2024-10-22 13:20:14.975483274+00:00,10,41,38,A,B,0,234.25,200,194,54364,304708,233.7,234.25,200,200,0,0,,,0,0,0,0,,,0,0,0,0,,,0,0,0,0,,,0,0,0,0,,,0,0,0,0,,,0,0,0,0,,,0,0,0,0,,,0,0,0,0,,,0,0,0,0,AAPL
2024-10-22 13:20:15.112991084+00:00,10,41,38,A,A,0,,0,194,55365,304718,233.7,,200,0,0,0,,,0,0,0,0,,,0,0,0,0,,,0,0,0,0,,,0,0,0,0,,,0,0,0,0,,,0,0,0,0,,,0,0,0,0,,,0,0,0,0,,,0,0,0,0,AAPL
2024-10-22 13:20:16.692205357+00:00,10,41,38,A,A,0,234.25,200,194,55519,304846,233.7,234.25,200,200,0,0,,,0,0,0,0,,,0,0,0,0,,,0,0,0,0,,,0,0,0,0,,,0,0,0,0,,,0,0,0,0,,,0,0,0,0,,,0,0,0,0,,,0,0,0,0,AAPL
2024-10-22 13:20:21.195065525+00:00,10,41,38,A,A,0,,0,194,55877,305272,233.7,,200,0,0,0,,,0,0,0,0,,,0,0,0,0,,,0,0,0,0,,,0,0,0,0,,,0,0,0,0,,,0,0,0,0,,,0,0,0,0,,,0,0,0,0,,,0,0,0,0,AAPL
2024-10-22 13:20:21.503006614+00:00,10,39,10888,C,A,0,421.2,2000,130,202946,104998,,,0,0,0,0,,,0,0,0,0,,,0,0,0,0,,,0,0,0,0,,,0,0,0,0,,,0,0,0,0,,,0,0,0,0,,,0,0,0,0,,,0,0,0,0,,,0,0,0,0,MSFT
2024-10-22 13:20:21.541145156+00:00,10,39,10888,A,A,0,421.2,2000,130,202659,104999,,421.2,0,2000,0,1,,,0,0,0,0,,,0,0,0,0,,,0,0,0,0,,,0,0,0,0,,,0,0,0,0,,,0,0,0,0,,,0,0,0,0,,,0,0,0,0,,,0,0,0,0,MSFT
2024-10-22 13:20:23.722879714+00:00,10,41,38,A,A,0,234.25,200,194,64896,305544,233.7,234.25,200,200,0,0,,,0,0,0,0,,,0,0,0,0,,,0,0,0,0,,,0,0,0,0,,,0,0,0,0,,,0,0,0,0,,,0,0,0,0,,,0,0,0,0,,,0,0,0,0,AAPL
2024-10-22 13:20:24.995909469+00:00,10,41,38,A,B,0,234.25,200,194,60298,305613,,234.25,0,200,0,0,,,0,0,0,0,,,0,0,0,0,,,0,0,0,0,,,0,0,0,0,,,0,0,0,0,,,0,0,0,0,,,0,0,0,0,,,0,0,0,0,,,0,0,0,0,AAPL
2024-10-22 13:20:25.094786639+00:00,10,40,38,A,B,0,234.3,200,194,203414,124056,,234.3,0,200,0,0,,,0,0,0,0,,,0,0,0,0,,,0,0,0,0,,,0,0,0,0,,,0,0,0,0,,,0,0,0,0,,,0,0,0,0,,,0,0,0,0,,,0,0,0,0,AAPL
2024-10-22 13:20:25.296361136+00:00,10,40,38,A,B,0,234.3,200,194,203376,124057,233.67,234.3,200,200,0,0,,,0,0,0,0,,,0,0,0,0,,,0,0,0,0,,,0,0,0,0,,,0,0,0,0,,,0,0,0,0,,,0,0,0,0,,,0,0,0,0,,,0,0,0,0,AAPL
2024-10-22 13:20:25.464418203+00:00,10,41,38,A,B,0,234.25,200,194,60615,305635,233.72,234.25,200,200,0,0,,,0,0,0,0,,,0,0,0,0,,,0,0,0,0,,,0,0,0,0,,,0,0,0,0,,,0,0,0,0,,,0,0,0,0,,,0,0,0,0,,,0,0,0,0,AAPL
2024-10-22 13:20:25.465010527+00:00,10,41,38,T,N,0,233.99,10,194,62037,305636,233.72,234.25,200,200,0,0,,,0,0,0,0,,,0,0,0,0,,,0,0,0,0,,,0,0,0,0,,,0,0,0,0,,,0,0,0,0,,,0,0,0,0,,,0,0,0,0,,,0,0,0,0,AAPL
2024-10-22 13:20:25.666414529+00:00,10,41,38,A,B,0,234.25,200,194,60890,305643,,234.25,0,200,0,0,,,0,0,0,0,,,0,0,0,0,,,0,0,0,0,,,0,0,0,0,,,0,0,0,0,,,0,0,0,0,,,0,0,0,0,,,0,0,0,0,,,0,0,0,0,AAPL
2024-10-22 13:20:26.333565196+00:00,10,41,38,A,B,0,234.25,200,194,55333,305683,233.72,234.25,200,200,0,0,,,0,0,0,0,,,0,0,0,0,,,0,0,0,0,,,0,0,0,0,,,0,0,0,0,,,0,0,0,0,,,0,0,0,0,,,0,0,0,0,,,0,0,0,0,AAPL
2024-10-22 13:20:26.471862706+00:00,10,41,38,A,B,0,234.25,200,194,60562,305685,,234.25,0,200,0,0,,,0,0,0,0,,,0,0,0,0,,,0,0,0,0,,,0,0,0,0,,,0,0,0,0,,,0,0,0,0,,,0,0,0,0,,,0,0,0,0,,,0,0,0,0,AAPL
2024-10-22 13:20:28.282728985+00:00,10,41,38,A,B,0,234.25,200,194,55516,305776,233.72,234.25,200,200,0,0,,,0,0,0,0,,,0,0,0,0,,,0,0,0,0,,,0,0,0,0,,,0,0,0,0,,,0,0,0,0,,,0,0,0,0,,,0,0,0,0,,,0,0,0,0,AAPL
2024-10-22 13:20:30.816194193+00:00,10,41,38,A,A,0,,0,194,54486,305943,233.72,,200,0,0,0,,,0,0,0,0,,,0,0,0,0,,,0,0,0,0,,,0,0,0,0,,,0,0,0,0,,,0,0,0,0,,,0,0,0,0,,,0,0,0,0,,,0,0,0,0,AAPL
2024-10-22 13:20:33.521366493+00:00,10,41,38,A,A,0,234.25,200,194,55611,306045,233.72,234.25,200,200,0,0,,,0,0,0,0,,,0,0,0,0,,,0,0,0,0,,,0,0,0,0,,,0,0,0,0,,,0,0,0,0,,,0,0,0,0,,,0,0,0,0,,,0,0,0,0,AAPL
2024-10-22 13:20:33.773726793+00:00,10,41,38,A,A,0,,0,194,55319,306060,233.72,,200,0,0,0,,,0,0,0,0,,,0,0,0,0,,,0,0,0,0,,,0,0,0,0,,,0,0,0,0,,,0,0,0,0,,,0,0,0,0,,,0,0,0,0,,,0,0,0,0,AAPL
2024-10-22 13:20:36.114156942+00:00,10,41,38,A,A,0,234.25,200,194,55719,306186,233.72,234.25,200,200,0,0,,,0,0,0,0,,,0,0,0,0,,,0,0,0,0,,,0,0,0,0,,,0,0,0,0,,,0,0,0,0,,,0,0,0,0,,,0,0,0,0,,,0,0,0,0,AAPL
2024-10-22 13:20:37.210623243+00:00,10,41,38,A,A,0,,0,194,60140,306236,233.72,,200,0,0,0,,,0,0,0,0,,,0,0,0,0,,,0,0,0,0,,,0,0,0,0,,,0,0,0,0,,,0,0,0,0,,,0,0,0,0,,,0,0,0,0,,,0,0,0,0,AAPL
2024-10-22 13:20:37.735391322+00:00,10,41,38,A,A,0,234.25,200,194,55510,306271,233.72,234.25,200,200,0,0,,,0,0,0,0,,,0,0,0,0,,,0,0,0,0,,,0,0,0,0,,,0,0,0,0,,,0,0,0,0,,,0,0,0,0,,,0,0,0,0,,,0,0,0,0,AAPL
2024-10-22 13:20:37.926157532+00:00,10,41,38,A,A,0,,0,194,55704,306294,233.72,,200,0,0,0,,,0,0,0,0,,,0,0,0,0,,,0,0,0,0,,,0,0,0,0,,,0,0,0,0,,,0,0,0,0,,,0,0,0,0,,,0,0,0,0,,,0,0,0,0,AAPL
2024-10-22 13:20:38.937560054+00:00,10,41,38,A,B,0,,0,194,60525,306368,,,0,0,0,0,,,0,0,0,0,,,0,0,0,0,,,0,0,0,0,,,0,0,0,0,,,0,0,0,0,,,0,0,0,0,,,0,0,0,0,,,0,0,0,0,,,0,0,0,0,AAPL
2024-10-22 13:20:38.937580805+00:00,10,41,38,A,B,0,,0,194,54417,306369,233.7,,200,0,0,0,,,0,0,0,0,,,0,0,0,0,,,0,0,0,0,,,0,0,0,0,,,0,0,0,0,,,0,0,0,0,,,0,0,0,0,,,0,0,0,0,,,0,0,0,0,AAPL
2024-10-22 13:20:38.937600340+00:00,10,41,38,A,A,0,234.22,200,194,54460,306370,233.7,234.22,200,200,0,0,,,0,0,0,0,,,0,0,0,0,,,0,0,0,0,,,0,0,0,0,,,0,0,0,0,,,0,0,0,0,,,0,0,0,0,,,0,0,0,0,,,0,0,0,0,AAPL
2024-10-22 13:20:38.952986351+00:00,10,41,38,A,B,0,234.22,200,194,55317,306371,,234.22,0,200,0,0,,,0,0,0,0,,,0,0,0,0,,,0,0,0,0,,,0,0,0,0,,,0,0,0,0,,,0,0,0,0,,,0,0,0,0,,,0,0,0,0,,,0,0,0,0,AAPL
2024-10-22 13:20:39.155208927+00:00,10,41,38,A,B,0,234.22,200,194,55371,306373,233.7,234.22,200,200,0,0,,,0,0,0,0,,,0,0,0,0,,,0,0,0,0,,,0,0,0,0,,,0,0,0,0,,,0,0,0,0,,,0,0,0,0,,,0,0,0,0,,,0,0,0,0,AAPL
2024-10-22 13:20:40.060325881+00:00,10,41,38,A,A,0,,0,194,55465,306416,233.7,,200,0,0,0,,,0,0,0,0,,,0,0,0,0,,,0,0,0,0,,,0,0,0,0,,,0,0,0,0,,,0,0,0,0,,,0,0,0,0,,,0,0,0,0,,,0,0,0,0,AAPL
2024-10-22 13:20:41.764548547+00:00,10,41,38,A,A,0,234.22,200,194,55397,306517,233.7,234.22,200,200,0,0,,,0,0,0,0,,,0,0,0,0,,,0,0,0,0,,,0,0,0,0,,,0,0,0,0,,,0,0,0,0,,,0,0,0,0,,,0,0,0,0,,,0,0,0,0,AAPL
2024-10-22 13:20:41.859501544+00:00,10,41,38,A,B,0,234.22,200,194,55707,306519,,234.22,0,200,0,0,,,0,0,0,0,,,0,0,0,0,,,0,0,0,0,,,0,0,0,0,,,0,0,0,0,,,0,0,0,0,,,0,0,0,0,,,0,0,0,0,,,0,0,0,0,AAPL
2024-10-22 13:20:41.863806782+00:00,10,41,38,A,A,0,,0,194,55225,306520,,,0,0,0,0,,,0,0,0,0,,,0,0,0,0,,,0,0,0,0,,,0,0,0,0,,,0,0,0,0,,,0,0,0,0,,,0,0,0,0,,,0,0,0,0,,,0,0,0,0,AAPL
2024-10-22 13:20:41.867341117+00:00,10,40,38,A,B,0,234.3,200,194,202698,124238,,234.3,0,200,0,0,,,0,0,0,0,,,0,0,0,0,,,0,0,0,0,,,0,0,0,0,,,0,0,0,0,,,0,0,0,0,,,0,0,0,0,,,0,0,0,0,,,0,0,0,0,AAPL
2024-10-22 13:20:41.896316893+00:00,10,39,38,A,A,0,236.4,2000,130,202119,71790,232.4,236.4,2000,2000,1,1,,,0,0,0,0,,,0,0,0,0,,,0,0,0,0,,,0,0,0,0,,,0,0,0,0,,,0,0,0,0,,,0,0,0,0,,,0,0,0,0,,,0,0,0,0,AAPL
2024-10-22 13:20:42.105188247+00:00,10,40,38,A,A,0,,0,194,202855,124245,,,0,0,0,0,,,0,0,0,0,,,0,0,0,0,,,0,0,0,0,,,0,0,0,0,,,0,0,0,0,,,0,0,0,0,,,0,0,0,0,,,0,0,0,0,,,0,0,0,0,AAPL
2024-10-22 13:20:43.917387378+00:00,10,40,38,A,A,0,234.3,200,194,202646,124266,,234.3,0,200,0,0,,,0,0,0,0,,,0,0,0,0,,,0,0,0,0,,,0,0,0,0,,,0,0,0,0,,,0,0,0,0,,,0,0,0,0,,,0,0,0,0,,,0,0,0,0,AAPL
2024-10-22 13:20:43.917481573+00:00,10,40,38,A,B,0,234.3,200,194,202601,124267,233.68,234.3,200,200,0,0,,,0,0,0,0,,,0,0,0,0,,,0,0,0,0,,,0,0,0,0,,,0,0,0,0,,,0,0,0,0,,,0,0,0,0,,,0,0,0,0,,,0,0,0,0,AAPL
2024-10-22 13:20:44.825986810+00:00,10,40,38,A,B,0,234.3,200,194,202687,124280,,234.3,0,200,0,0,,,0,0,0,0,,,0,0,0,0,,,0,0,0,0,,,0,0,0,0,,,0,0,0,0,,,0,0,0,0,,,0,0,0,0,,,0,0,0,0,,,0,0,0,0,AAPL
2024-10-22 13:20:48.499528021+00:00,10,39,10888,C,A,0,421.2,2000,130,203082,105241,,,0,0,0,0,,,0,0,0,0,,,0,0,0,0,,,0,0,0,0,,,0,0,0,0,,,0,0,0,0,,,0,0,0,0,,,0,0,0,0,,,0,0,0,0,,,0,0,0,0,MSFT
2024-10-22 13:20:48.535496598+00:00,10,39,10888,A,A,0,421.2,2000,130,203049,105248,,421.2,0,2000,0,1,,,0,0,0,0,,,0,0,0,0,,,0,0,0,0,,,0,0,0,0,,,0,0,0,0,,,0,0,0,0,,,0,0,0,0,,,0,0,0,0,,,0,0,0,0,MSFT
2024-10-22 13:20:50.829182752+00:00,10,40,38,A,B,0,234.3,200,194,202777,124334,233.68,234.3,200,200,0,0,,,0,0,0,0,,,0,0,0,0,,,0,0,0,0,,,0,0,0,0,,,0,0,0,0,,,0,0,0,0,,,0,0,0,0,,,0,0,0,0,,,0,0,0,0,AAPL
2024-10-22 13:20:50.829379922+00:00,10,41,38,A,A,0,234.25,200,194,55905,306936,,234.25,0,200,0,0,,,0,0,0,0,,,0,0,0,0,,,0,0,0,0,,,0,0,0,0,,,0,0,0,0,,,0,0,0,0,,,0,0,0,0,,,0,0,0,0,,,0,0,0,0,AAPL
2024-10-22 13:20:50.829312683+00:00,10,40,38,A,B,0,234.3,200,194,202621,124335,,234.3,0,200,0,0,,,0,0,0,0,,,0,0,0,0,,,0,0,0,0,,,0,0,0,0,,,0,0,0,0,,,0,0,0,0,,,0,0,0,0,,,0,0,0,0,,,0,0,0,0,AAPL
2024-10-22 13:20:51.030880038+00:00,10,41,38,A,A,0,,0,194,55094,306952,,,0,0,0,0,,,0,0,0,0,,,0,0,0,0,,,0,0,0,0,,,0,0,0,0,,,0,0,0,0,,,0,0,0,0,,,0,0,0,0,,,0,0,0,0,,,0,0,0,0,AAPL
2024-10-22 13:20:51.471063568+00:00,10,39,10888,C,A,0,421.2,2000,130,203854,105277,,,0,0,0,0,,,0,0,0,0,,,0,0,0,0,,,0,0,0,0,,,0,0,0,0,,,0,0,0,0,,,0,0,0,0,,,0,0,0,0,,,0,0,0,0,,,0,0,0,0,MSFT
2024-10-22 13:20:51.481813664+00:00,10,39,10888,A,A,0,422.4,2000,130,203433,105279,,422.4,0,2000,0,1,,,0,0,0,0,,,0,0,0,0,,,0,0,0,0,,,0,0,0,0,,,0,0,0,0,,,0,0,0,0,,,0,0,0,0,,,0,0,0,0,,,0,0,0,0,MSFT
2024-10-22 13:20:51.497602293+00:00,10,39,10888,A,A,0,421.2,2000,130,203455,105280,,421.2,0,2000,0,1,,422.4,0,2000,0,1,,,0,0,0,0,,,0,0,0,0,,,0,0,0,0,,,0,0,0,0,,,0,0,0,0,,,0,0,0,0,,,0,0,0,0,,,0,0,0,0,MSFT
2024-10-22 13:20:51.497791139+00:00,10,39,10888,C,A,1,422.4,2000,130,203461,105281,,421.2,0,2000,0,1,,,0,0,0,0,,,0,0,0,0,,,0,0,0,0,,,0,0,0,0,,,0,0,0,0,,,0,0,0,0,,,0,0,0,0,,,0,0,0,0,,,0,0,0,0,MSFT
2024-10-22 13:20:51.936598563+00:00,10,41,38,A,A,0,234.25,200,194,55618,306998,,234.25,0,200,0,0,,,0,0,0,0,,,0,0,0,0,,,0,0,0,0,,,0,0,0,0,,,0,0,0,0,,,0,0,0,0,,,0,0,0,0,,,0,0,0,0,,,0,0,0,0,AAPL
2024-10-22 13:20:52.152412431+00:00,10,40,38,A,B,0,234.3,200,194,202630,124356,233.68,234.3,200,200,0,0,,,0,0,0,0,,,0,0,0,0,,,0,0,0,0,,,0,0,0,0,,,0,0,0,0,,,0,0,0,0,,,0,0,0,0,,,0,0,0,0,,,0,0,0,0,AAPL
2024-10-22 13:20:52.239718276+00:00,10,40,38,A,B,0,234.3,200,194,202641,124357,,234.3,0,200,0,0,,,0,0,0,0,,,0,0,0,0,,,0,0,0,0,,,0,0,0,0,,,0,0,0,0,,,0,0,0,0,,,0,0,0,0,,,0,0,0,0,,,0,0,0,0,AAPL
2024-10-22 13:20:53.346354881+00:00,10,40,38,A,A,0,,0,194,202789,124368,,,0,0,0,0,,,0,0,0,0,,,0,0,0,0,,,0,0,0,0,,,0,0,0,0,,,0,0,0,0,,,0,0,0,0,,,0,0,0,0,,,0,0,0,0,,,0,0,0,0,AAPL
2024-10-22 13:20:54.804015585+00:00,10,40,38,A,B,0,,0,194,202796,124380,233.68,,200,0,0,0,,,0,0,0,0,,,0,0,0,0,,,0,0,0,0,,,0,0,0,0,,,0,0,0,0,,,0,0,0,0,,,0,0,0,0,,,0,0,0,0,,,0,0,0,0,AAPL
2024-10-22 13:20:54.804026743+00:00,10,40,38,A,A,0,234.3,200,194,202582,124381,233.68,234.3,200,200,0,0,,,0,0,0,0,,,0,0,0,0,,,0,0,0,0,,,0,0,0,0,,,0,0,0,0,,,0,0,0,0,,,0,0,0,0,,,0,0,0,0,,,0,0,0,0,AAPL
2024-10-22 13:20:54.804072029+00:00,10,40,38,A,B,0,234.3,200,194,202629,124382,,234.3,0,200,0,0,,,0,0,0,0,,,0,0,0,0,,,0,0,0,0,,,0,0,0,0,,,0,0,0,0,,,0,0,0,0,,,0,0,0,0,,,0,0,0,0,,,0,0,0,0,AAPL
2024-10-22 13:20:54.804828336+00:00,10,41,38,A,B,0,234.25,200,194,55474,307187,233.73,234.25,200,200,0,0,,,0,0,0,0,,,0,0,0,0,,,0,0,0,0,,,0,0,0,0,,,0,0,0,0,,,0,0,0,0,,,0,0,0,0,,,0,0,0,0,,,0,0,0,0,AAPL
2024-10-22 13:20:54.804868661+00:00,10,39,38,C,B,0,232.4,2000,130,203037,71849,,236.4,0,2000,0,1,,,0,0,0,0,,,0,0,0,0,,,0,0,0,0,,,0,0,0,0,,,0,0,0,0,,,0,0,0,0,,,0,0,0,0,,,0,0,0,0,,,0,0,0,0,AAPL
2024-10-22 13:20:54.841584331+00:00,10,39,38,A,B,0,232.4,2000,130,202705,71850,232.4,236.4,2000,2000,1,1,,,0,0,0,0,,,0,0,0,0,,,0,0,0,0,,,0,0,0,0,,,0,0,0,0,,,0,0,0,0,,,0,0,0,0,,,0,0,0,0,,,0,0,0,0,AAPL
2024-10-22 13:20:54.953966150+00:00,10,41,38,A,B,0,234.25,200,194,55526,307205,,234.25,0,200,0,0,,,0,0,0,0,,,0,0,0,0,,,0,0,0,0,,,0,0,0,0,,,0,0,0,0,,,0,0,0,0,,,0,0,0,0,,,0,0,0,0,,,0,0,0,0,AAPL
2024-10-22 13:20:54.954326610+00:00,10,40,38,A,B,0,234.3,200,194,202535,124391,233.65,234.3,200,200,0,0,,,0,0,0,0,,,0,0,0,0,,,0,0,0,0,,,0,0,0,0,,,0,0,0,0,,,0,0,0,0,,,0,0,0,0,,,0,0,0,0,,,0,0,0,0,AAPL
2024-10-22 13:20:54.954963099+00:00,10,41,38,A,B,0,234.25,200,194,55574,307208,233.7,234.25,200,200,0,0,,,0,0,0,0,,,0,0,0,0,,,0,0,0,0,,,0,0,0,0,,,0,0,0,0,,,0,0,0,0,,,0,0,0,0,,,0,0,0,0,,,0,0,0,0,AAPL
2024-10-22 13:20:55.040034388+00:00,10,39,38,C,B,0,232.4,2000,130,202796,71852,,236.4,0,2000,0,1,,,0,0,0,0,,,0,0,0,0,,,0,0,0,0,,,0,0,0,0,,,0,0,0,0,,,0,0,0,0,,,0,0,0,0,,,0,0,0,0,,,0,0,0,0,AAPL
2024-10-22 13:20:55.071329682+00:00,10,39,38,C,A,0,236.4,2000,130,202603,71853,,,0,0,0,0,,,0,0,0,0,,,0,0,0,0,,,0,0,0,0,,,0,0,0,0,,,0,0,0,0,,,0,0,0,0,,,0,0,0,0,,,0,0,0,0,,,0,0,0,0,AAPL
2024-10-22 13:20:55.077613168+00:00,10,39,38,A,B,0,232.0,2000,130,202700,71854,232.0,,2000,0,1,0,,,0,0,0,0,,,0,0,0,0,,,0,0,0,0,,,0,0,0,0,,,0,0,0,0,,,0,0,0,0,,,0,0,0,0,,,0,0,0,0,,,0,0,0,0,AAPL
2024-10-22 13:20:55.088291698+00:00,10,39,38,A,B,0,232.2,2000,130,202544,71855,232.2,,2000,0,1,0,232.0,,2000,0,1,0,,,0,0,0,0,,,0,0,0,0,,,0,0,0,0,,,0,0,0,0,,,0,0,0,0,,,0,0,0,0,,,0,0,0,0,,,0,0,0,0,AAPL
2024-10-22 13:20:55.088485568+00:00,10,39,38,C,B,1,232.0,2000,130,202544,71856,232.2,,2000,0,1,0,,,0,0,0,0,,,0,0,0,0,,,0,0,0,0,,,0,0,0,0,,,0,0,0,0,,,0,0,0,0,,,0,0,0,0,,,0,0,0,0,,,0,0,0,0,AAPL
2024-10-22 13:20:55.203450064+00:00,10,40,38,A,B,0,234.3,200,194,202670,124397,,234.3,0,200,0,0,,,0,0,0,0,,,0,0,0,0,,,0,0,0,0,,,0,0,0,0,,,0,0,0,0,,,0,0,0,0,,,0,0,0,0,,,0,0,0,0,,,0,0,0,0,AAPL
2024-10-22 13:20:55.203472584+00:00,10,40,38,A,B,0,234.3,200,194,202596,124398,233.55,234.3,200,200,0,0,,,0,0,0,0,,,0,0,0,0,,,0,0,0,0,,,0,0,0,0,,,0,0,0,0,,,0,0,0,0,,,0,0,0,0,,,0,0,0,0,,,0,0,0,0,AAPL
2024-10-22 13:20:55.204053690+00:00,10,41,38,A,B,0,234.25,200,194,59897,307227,,234.25,0,200,0,0,,,0,0,0,0,,,0,0,0,0,,,0,0,0,0,,,0,0,0,0,,,0,0,0,0,,,0,0,0,0,,,0,0,0,0,,,0,0,0,0,,,0,0,0,0,AAPL
2024-10-22 13:20:56.071344764+00:00,10,41,38,A,B,0,234.25,200,194,56924,307283,233.6,234.25,200,200,0,0,,,0,0,0,0,,,0,0,0,0,,,0,0,0,0,,,0,0,0,0,,,0,0,0,0,,,0,0,0,0,,,0,0,0,0,,,0,0,0,0,,,0,0,0,0,AAPL
2024-10-22 13:20:56.239364851+00:00,10,41,38,A,B,0,234.25,200,194,55479,307320,,234.25,0,200,0,0,,,0,0,0,0,,,0,0,0,0,,,0,0,0,0,,,0,0,0,0,,,0,0,0,0,,,0,0,0,0,,,0,0,0,0,,,0,0,0,0,,,0,0,0,0,AAPL
2024-10-22 13:20:57.175438314+00:00,10,39,10888,C,A,0,421.2,2000,130,204259,105332,,,0,0,0,0,,,0,0,0,0,,,0,0,0,0,,,0,0,0,0,,,0,0,0,0,,,0,0,0,0,,,0,0,0,0,,,0,0,0,0,,,0,0,0,0,,,0,0,0,0,MSFT
2024-10-22 13:20:57.186470950+00:00,10,39,10888,A,A,0,421.6,2000,130,203884,105333,,421.6,0,2000,0,1,,,0,0,0,0,,,0,0,0,0,,,0,0,0,0,,,0,0,0,0,,,0,0,0,0,,,0,0,0,0,,,0,0,0,0,,,0,0,0,0,,,0,0,0,0,MSFT
2024-10-22 13:20:59.104784307+00:00,10,41,38,A,B,0,234.25,200,194,55350,307564,233.6,234.25,200,200,0,0,,,0,0,0,0,,,0,0,0,0,,,0,0,0,0,,,0,0,0,0,,,0,0,0,0,,,0,0,0,0,,,0,0,0,0,,,0,0,0,0,,,0,0,0,0,AAPL
2024-10-22 13:20:59.291853087+00:00,10,41,38,A,B,0,234.25,200,194,55443,307583,,234.25,0,200,0,0,,,0,0,0,0,,,0,0,0,0,,,0,0,0,0,,,0,0,0,0,,,0,0,0,0,,,0,0,0,0,,,0,0,0,0,,,0,0,0,0,,,0,0,0,0,AAPL
2024-10-22 13:20:59.291747035+00:00,10,40,38,A,B,0,234.3,200,194,202678,124429,,234.3,0,200,0,0,,,0,0,0,0,,,0,0,0,0,,,0,0,0,0,,,0,0,0,0,,,0,0,0,0,,,0,0,0,0,,,0,0,0,0,,,0,0,0,0,,,0,0,0,0,AAPL
2024-10-22 13:20:59.844694039+00:00,10,40,38,A,B,0,234.3,200,194,202576,124439,233.54,234.3,200,200,0,0,,,0,0,0,0,,,0,0,0,0,,,0,0,0,0,,,0,0,0,0,,,0,0,0,0,,,0,0,0,0,,,0,0,0,0,,,0,0,0,0,,,0,0,0,0,AAPL
2024-10-22 13:20:59.844930241+00:00,10,41,38,A,B,0,234.25,200,194,55032,307666,233.59,234.25,200,200,0,0,,,0,0,0,0,,,0,0,0,0,,,0,0,0,0,,,0,0,0,0,,,0,0,0,0,,,0,0,0,0,,,0,0,0,0,,,0,0,0,0,,,0,0,0,0,AAPL
2024-10-22 13:20:59.909920883+00:00,10,41,38,A,B,0,234.25,200,194,54501,307670,,234.25,0,200,0,0,,,0,0,0,0,,,0,0,0,0,,,0,0,0,0,,,0,0,0,0,,,0,0,0,0,,,0,0,0,0,,,0,0,0,0,,,0,0,0,0,,,0,0,0,0,AAPL
2024-10-22 13:21:00.066921180+00:00,10,40,38,A,B,0,234.3,200,194,202568,124481,,234.3,0,200,0,0,,,0,0,0,0,,,0,0,0,0,,,0,0,0,0,,,0,0,0,0,,,0,0,0,0,,,0,0,0,0,,,0,0,0,0,,,0,0,0,0,,,0,0,0,0,AAPL
2024-10-22 13:21:00.966404083+00:00,10,40,38,A,B,0,234.3,200,194,202598,124507,233.54,234.3,200,200,0,0,,,0,0,0,0,,,0,0,0,0,,,0,0,0,0,,,0,0,0,0,,,0,0,0,0,,,0,0,0,0,,,0,0,0,0,,,0,0,0,0,,,0,0,0,0,AAPL
2024-10-22 13:21:00.966867446+00:00,10,41,38,A,B,0,234.25,200,194,63987,307984,233.59,234.25,200,200,0,0,,,0,0,0,0,,,0,0,0,0,,,0,0,0,0,,,0,0,0,0,,,0,0,0,0,,,0,0,0,0,,,0,0,0,0,,,0,0,0,0,,,0,0,0,0,AAPL
2024-10-22 13:21:01.066587657+00:00,10,40,38,A,B,0,234.3,200,194,202731,124509,,234.3,0,200,0,0,,,0,0,0,0,,,0,0,0,0,,,0,0,0,0,,,0,0,0,0,,,0,0,0,0,,,0,0,0,0,,,0,0,0,0,,,0,0,0,0,,,0,0,0,0,AAPL
2024-10-22 13:21:01.104086064+00:00,10,41,38,A,B,0,234.25,200,194,55428,307996,,234.25,0,200,0,0,,,0,0,0,0,,,0,0,0,0,,,0,0,0,0,,,0,0,0,0,,,0,0,0,0,,,0,0,0,0,,,0,0,0,0,,,0,0,0,0,,,0,0,0,0,AAPL
2024-10-22 13:21:02.262925695+00:00,10,39,10888,A,A,0,421.2,2000,130,203559,105391,,421.2,0,2000,0,1,,421.6,0,2000,0,1,,,0,0,0,0,,,0,0,0,0,,,0,0,0,0,,,0,0,0,0,,,0,0,0,0,,,0,0,0,0,,,0,0,0,0,,,0,0,0,0,MSFT
2024-10-22 13:21:02.263655303+00:00,10,39,10888,C,A,1,421.6,2000,130,203516,105392,,421.2,0,2000,0,1,,,0,0,0,0,,,0,0,0,0,,,0,0,0,0,,,0,0,0,0,,,0,0,0,0,,,0,0,0,0,,,0,0,0,0,,,0,0,0,0,,,0,0,0,0,MSFT
2024-10-22 13:21:02.305430318+00:00,10,39,10888,C,A,0,421.2,2000,130,203513,105393,,,0,0,0,0,,,0,0,0,0,,,0,0,0,0,,,0,0,0,0,,,0,0,0,0,,,0,0,0,0,,,0,0,0,0,,,0,0,0,0,,,0,0,0,0,,,0,0,0,0,MSFT
2024-10-22 13:21:02.341520792+00:00,10,39,10888,A,A,0,421.2,2000,130,203707,105394,,421.2,0,2000,0,1,,,0,0,0,0,,,0,0,0,0,,,0,0,0,0,,,0,0,0,0,,,0,0,0,0,,,0,0,0,0,,,0,0,0,0,,,0,0,0,0,,,0,0,0,0,MSFT
2024-10-22 13:21:02.825517630+00:00,10,40,38,A,B,0,234.3,200,194,202744,124530,233.54,234.3,200,200,0,0,,,0,0,0,0,,,0,0,0,0,,,0,0,0,0,,,0,0,0,0,,,0,0,0,0,,,0,0,0,0,,,0,0,0,0,,,0,0,0,0,,,0,0,0,0,AAPL
2024-10-22 13:21:02.826066833+00:00,10,41,38,A,B,0,234.25,200,194,55389,308137,233.59,234.25,200,200,0,0,,,0,0,0,0,,,0,0,0,0,,,0,0,0,0,,,0,0,0,0,,,0,0,0,0,,,0,0,0,0,,,0,0,0,0,,,0,0,0,0,,,0,0,0,0,AAPL
2024-10-22 13:21:02.836813670+00:00,10,39,38,A,A,0,236.4,2000,130,203281,71919,232.2,236.4,2000,2000,1,1,,,0,0,0,0,,,0,0,0,0,,,0,0,0,0,,,0,0,0,0,,,0,0,0,0,,,0,0,0,0,,,0,0,0,0,,,0,0,0,0,,,0,0,0,0,AAPL
2024-10-22 13:21:02.984225964+00:00,10,41,38,A,B,0,234.25,200,194,55395,308163,,234.25,0,200,0,0,,,0,0,0,0,,,0,0,0,0,,,0,0,0,0,,,0,0,0,0,,,0,0,0,0,,,0,0,0,0,,,0,0,0,0,,,0,0,0,0,,,0,0,0,0,AAPL
2024-10-22 13:21:09.256230627+00:00,10,41,38,A,B,0,234.25,200,194,55818,308669,233.59,234.25,200,200,0,0,,,0,0,0,0,,,0,0,0,0,,,0,0,0,0,,,0,0,0,0,,,0,0,0,0,,,0,0,0,0,,,0,0,0,0,,,0,0,0,0,,,0,0,0,0,AAPL
2024-10-22 13:21:10.113448574+00:00,10,39,10888,C,A,0,421.2,2000,130,203906,105444,,,0,0,0,0,,,0,0,0,0,,,0,0,0,0,,,0,0,0,0,,,0,0,0,0,,,0,0,0,0,,,0,0,0,0,,,0,0,0,0,,,0,0,0,0,,,0,0,0,0,MSFT
2024-10-22 13:21:10.130996383+00:00,10,39,10888,A,A,0,421.6,2000,130,203476,105445,,421.6,0,2000,0,1,,,0,0,0,0,,,0,0,0,0,,,0,0,0,0,,,0,0,0,0,,,0,0,0,0,,,0,0,0,0,,,0,0,0,0,,,0,0,0,0,,,0,0,0,0,MSFT
2024-10-22 13:21:19.247877762+00:00,10,40,38,A,B,0,234.3,200,194,202639,124728,,234.3,0,200,0,0,,,0,0,0,0,,,0,0,0,0,,,0,0,0,0,,,0,0,0,0,,,0,0,0,0,,,0,0,0,0,,,0,0,0,0,,,0,0,0,0,,,0,0,0,0,AAPL
2024-10-22 13:21:19.247897576+00:00,10,40,38,A,B,0,234.3,200,194,202433,124729,233.64,234.3,200,200,0,0,,,0,0,0,0,,,0,0,0,0,,,0,0,0,0,,,0,0,0,0,,,0,0,0,0,,,0,0,0,0,,,0,0,0,0,,,0,0,0,0,,,0,0,0,0,AAPL
2024-10-22 13:21:19.248322231+00:00,10,41,38,A,B,0,234.25,200,194,56702,309279,,234.25,0,200,0,0,,,0,0,0,0,,,0,0,0,0,,,0,0,0,0,,,0,0,0,0,,,0,0,0,0,,,0,0,0,0,,,0,0,0,0,,,0,0,0,0,,,0,0,0,0,AAPL
2024-10-22 13:21:19.248347368+00:00,10,41,38,A,B,0,234.25,200,194,55873,309280,233.69,234.25,200,200,0,0,,,0,0,0,0,,,0,0,0,0,,,0,0,0,0,,,0,0,0,0,,,0,0,0,0,,,0,0,0,0,,,0,0,0,0,,,0,0,0,0,,,0,0,0,0,AAPL
2024-10-22 13:21:19.451322148+00:00,10,41,38,A,B,0,234.25,200,194,57218,309292,,234.25,0,200,0,0,,,0,0,0,0,,,0,0,0,0,,,0,0,0,0,,,0,0,0,0,,,0,0,0,0,,,0,0,0,0,,,0,0,0,0,,,0,0,0,0,,,0,0,0,0,AAPL
2024-10-22 13:21:19.451337223+00:00,10,41,38,A,B,0,234.25,200,194,55906,309293,233.6,234.25,200,200,0,0,,,0,0,0,0,,,0,0,0,0,,,0,0,0,0,,,0,0,0,0,,,0,0,0,0,,,0,0,0,0,,,0,0,0,0,,,0,0,0,0,,,0,0,0,0,AAPL
2024-10-22 13:21:19.851661806+00:00,10,40,38,A,B,0,234.3,200,194,202600,124731,,234.3,0,200,0,0,,,0,0,0,0,,,0,0,0,0,,,0,0,0,0,,,0,0,0,0,,,0,0,0,0,,,0,0,0,0,,,0,0,0,0,,,0,0,0,0,,,0,0,0,0,AAPL
2024-10-22 13:21:19.851686033+00:00,10,40,38,A,B,0,234.3,200,194,202438,124732,233.54,234.3,200,200,0,0,,,0,0,0,0,,,0,0,0,0,,,0,0,0,0,,,0,0,0,0,,,0,0,0,0,,,0,0,0,0,,,0,0,0,0,,,0,0,0,0,,,0,0,0,0,AAPL
2024-10-22 13:21:22.568921918+00:00,10,40,38,A,B,0,234.3,200,194,202872,124759,,234.3,0,200,0,0,,,0,0,0,0,,,0,0,0,0,,,0,0,0,0,,,0,0,0,0,,,0,0,0,0,,,0,0,0,0,,,0,0,0,0,,,0,0,0,0,,,0,0,0,0,AAPL
2024-10-22 13:21:22.568941632+00:00,10,40,38,A,B,0,234.3,200,194,202409,124760,233.62,234.3,200,200,0,0,,,0,0,0,0,,,0,0,0,0,,,0,0,0,0,,,0,0,0,0,,,0,0,0,0,,,0,0,0,0,,,0,0,0,0,,,0,0,0,0,,,0,0,0,0,AAPL
2024-10-22 13:21:22.569136980+00:00,10,41,38,A,B,0,234.25,200,194,55740,309521,,234.25,0,200,0,0,,,0,0,0,0,,,0,0,0,0,,,0,0,0,0,,,0,0,0,0,,,0,0,0,0,,,0,0,0,0,,,0,0,0,0,,,0,0,0,0,,,0,0,0,0,AAPL
2024-10-22 13:21:22.569190783+00:00,10,41,38,A,B,0,234.25,200,194,54869,309522,233.67,234.25,200,200,0,0,,,0,0,0,0,,,0,0,0,0,,,0,0,0,0,,,0,0,0,0,,,0,0,0,0,,,0,0,0,0,,,0,0,0,0,,,0,0,0,0,,,0,0,0,0,AAPL
2024-10-22 13:21:26.560689609+00:00,10,39,38,C,B,0,232.2,2000,130,203553,72014,,236.4,0,2000,0,1,,,0,0,0,0,,,0,0,0,0,,,0,0,0,0,,,0,0,0,0,,,0,0,0,0,,,0,0,0,0,,,0,0,0,0,,,0,0,0,0,,,0,0,0,0,AAPL
2024-10-22 13:21:26.573742067+00:00,10,39,38,A,B,0,231.8,2000,130,203578,72015,231.8,236.4,2000,2000,1,1,,,0,0,0,0,,,0,0,0,0,,,0,0,0,0,,,0,0,0,0,,,0,0,0,0,,,0,0,0,0,,,0,0,0,0,,,0,0,0,0,,,0,0,0,0,AAPL
2024-10-22 13:21:30.211488905+00:00,10,39,38,A,B,0,232.4,2000,130,203909,72034,232.4,236.4,2000,2000,1,1,231.8,,2000,0,1,0,,,0,0,0,0,,,0,0,0,0,,,0,0,0,0,,,0,0,0,0,,,0,0,0,0,,,0,0,0,0,,,0,0,0,0,,,0,0,0,0,AAPL
2024-10-22 13:21:30.211798528+00:00,10,39,38,C,B,1,231.8,2000,130,203348,72035,232.4,236.4,2000,2000,1,1,,,0,0,0,0,,,0,0,0,0,,,0,0,0,0,,,0,0,0,0,,,0,0,0,0,,,0,0,0,0,,,0,0,0,0,,,0,0,0,0,,,0,0,0,0,AAPL
2024-10-22 13:21:30.235792475+00:00,10,39,38,C,B,0,232.4,2000,130,203386,72036,,236.4,0,2000,0,1,,,0,0,0,0,,,0,0,0,0,,,0,0,0,0,,,0,0,0,0,,,0,0,0,0,,,0,0,0,0,,,0,0,0,0,,,0,0,0,0,,,0,0,0,0,AAPL
2024-10-22 13:21:30.247034502+00:00,10,39,38,A,B,0,232.4,2000,130,203382,72037,232.4,236.4,2000,2000,1,1,,,0,0,0,0,,,0,0,0,0,,,0,0,0,0,,,0,0,0,0,,,0,0,0,0,,,0,0,0,0,,,0,0,0,0,,,0,0,0,0,,,0,0,0,0,AAPL
2024-10-22 13:21:30.262975513+00:00,10,39,38,C,B,0,232.4,2000,130,203317,72038,,236.4,0,2000,0,1,,,0,0,0,0,,,0,0,0,0,,,0,0,0,0,,,0,0,0,0,,,0,0,0,0,,,0,0,0,0,,,0,0,0,0,,,0,0,0,0,,,0,0,0,0,AAPL
2024-10-22 13:21:30.277307626+00:00,10,39,38,A,B,0,232.4,2000,130,203418,72039,232.4,236.4,2000,2000,1,1,,,0,0,0,0,,,0,0,0,0,,,0,0,0,0,,,0,0,0,0,,,0,0,0,0,,,0,0,0,0,,,0,0,0,0,,,0,0,0,0,,,0,0,0,0,AAPL
2024-10-22 13:21:35.136522463+00:00,10,39,10888,C,A,0,421.6,2000,130,203589,105578,,,0,0,0,0,,,0,0,0,0,,,0,0,0,0,,,0,0,0,0,,,0,0,0,0,,,0,0,0,0,,,0,0,0,0,,,0,0,0,0,,,0,0,0,0,,,0,0,0,0,MSFT
2024-10-22 13:21:35.173337362+00:00,10,39,10888,A,A,0,421.2,2000,130,203452,105580,,421.2,0,2000,0,1,,,0,0,0,0,,,0,0,0,0,,,0,0,0,0,,,0,0,0,0,,,0,0,0,0,,,0,0,0,0,,,0,0,0,0,,,0,0,0,0,,,0,0,0,0,MSFT
2024-10-22 13:21:40.382316055+00:00,10,39,38,C,A,0,236.4,2000,130,203895,72085,232.4,,2000,0,1,0,,,0,0,0,0,,,0,0,0,0,,,0,0,0,0,,,0,0,0,0,,,0,0,0,0,,,0,0,0,0,,,0,0,0,0,,,0,0,0,0,,,0,0,0,0,AAPL
2024-10-22 13:21:40.613980036+00:00,10,39,10888,C,A,0,421.2,2000,130,203735,105620,,,0,0,0,0,,,0,0,0,0,,,0,0,0,0,,,0,0,0,0,,,0,0,0,0,,,0,0,0,0,,,0,0,0,0,,,0,0,0,0,,,0,0,0,0,,,0,0,0,0,MSFT
2024-10-22 13:21:40.650476312+00:00,10,39,10888,A,A,0,421.6,2000,130,203735,105621,,421.6,0,2000,0,1,,,0,0,0,0,,,0,0,0,0,,,0,0,0,0,,,0,0,0,0,,,0,0,0,0,,,0,0,0,0,,,0,0,0,0,,,0,0,0,0,,,0,0,0,0,MSFT
2024-10-22 13:21:40.914310208+00:00,10,39,38,A,B,0,233.4,2000,130,203376,72090,233.4,,2000,0,1,0,232.4,,2000,0,1,0,,,0,0,0,0,,,0,0,0,0,,,0,0,0,0,,,0,0,0,0,,,0,0,0,0,,,0,0,0,0,,,0,0,0,0,,,0,0,0,0,AAPL
2024-10-22 13:21:40.914398966+00:00,10,39,38,A,A,0,234.4,2000,130,203296,72091,233.4,234.4,2000,2000,1,1,232.4,,2000,0,1,0,,,0,0,0,0,,,0,0,0,0,,,0,0,0,0,,,0,0,0,0,,,0,0,0,0,,,0,0,0,0,,,0,0,0,0,,,0,0,0,0,AAPL
2024-10-22 13:21:40.914502894+00:00,10,39,10888,A,A,0,420.4,2000,130,203573,105624,,420.4,0,2000,0,1,,421.6,0,2000,0,1,,,0,0,0,0,,,0,0,0,0,,,0,0,0,0,,,0,0,0,0,,,0,0,0,0,,,0,0,0,0,,,0,0,0,0,,,0,0,0,0,MSFT
2024-10-22 13:21:40.914510244+00:00,10,39,10888,A,B,0,418.8,2000,130,203574,105625,418.8,420.4,2000,2000,1,1,,421.6,0,2000,0,1,,,0,0,0,0,,,0,0,0,0,,,0,0,0,0,,,0,0,0,0,,,0,0,0,0,,,0,0,0,0,,,0,0,0,0,,,0,0,0,0,MSFT
2024-10-22 13:21:40.924933153+00:00,10,39,38,A,B,1,233.2,2000,130,203295,72093,233.4,234.4,2000,2000,1,1,233.2,,2000,0,1,0,232.4,,2000,0,1,0,,,0,0,0,0,,,0,0,0,0,,,0,0,0,0,,,0,0,0,0,,,0,0,0,0,,,0,0,0,0,,,0,0,0,0,AAPL
2024-10-22 13:21:40.925007776+00:00,10,39,38,A,A,1,234.6,2000,130,203319,72094,233.4,234.4,2000,2000,1,1,233.2,234.6,2000,2000,1,1,232.4,,2000,0,1,0,,,0,0,0,0,,,0,0,0,0,,,0,0,0,0,,,0,0,0,0,,,0,0,0,0,,,0,0,0,0,,,0,0,0,0,AAPL
2024-10-22 13:21:40.925452721+00:00,10,39,10888,A,A,1,420.8,2000,130,203520,105628,418.8,420.4,2000,2000,1,1,,420.8,0,2000,0,1,,421.6,0,2000,0,1,,,0,0,0,0,,,0,0,0,0,,,0,0,0,0,,,0,0,0,0,,,0,0,0,0,,,0,0,0,0,,,0,0,0,0,MSFT
2024-10-22 13:21:40.925978667+00:00,10,39,10888,C,A,2,421.6,2000,130,203446,105631,418.8,420.4,2000,2000,1,1,,420.8,0,2000,0,1,,,0,0,0,0,,,0,0,0,0,,,0,0,0,0,,,0,0,0,0,,,0,0,0,0,,,0,0,0,0,,,0,0,0,0,,,0,0,0,0,MSFT
2024-10-22 13:21:40.935575654+00:00,10,39,38,A,B,2,232.8,2000,130,203285,72095,233.4,234.4,2000,2000,1,1,233.2,234.6,2000,2000,1,1,232.8,,2000,0,1,0,232.4,,2000,0,1,0,,,0,0,0,0,,,0,0,0,0,,,0,0,0,0,,,0,0,0,0,,,0,0,0,0,,,0,0,0,0,AAPL
2024-10-22 13:21:40.935748599+00:00,10,39,38,C,B,3,232.4,2000,130,203284,72096,233.4,234.4,2000,2000,1,1,233.2,234.6,2000,2000,1,1,232.8,,2000,0,1,0,,,0,0,0,0,,,0,0,0,0,,,0,0,0,0,,,0,0,0,0,,,0,0,0,0,,,0,0,0,0,,,0,0,0,0,AAPL
2024-10-22 13:21:40.936151449+00:00,10,39,38,A,A,2,235.8,2000,130,203272,72097,233.4,234.4,2000,2000,1,1,233.2,234.6,2000,2000,1,1,232.8,235.8,2000,2000,1,1,,,0,0,0,0,,,0,0,0,0,,,0,0,0,0,,,0,0,0,0,,,0,0,0,0,,,0,0,0,0,,,0,0,0,0,AAPL
2024-10-22 13:21:41.008545319+00:00,10,39,10888,A,A,2,422.4,2000,130,203765,105633,418.8,420.4,2000,2000,1,1,,420.8,0,2000,0,1,,422.4,0,2000,0,1,,,0,0,0,0,,,0,0,0,0,,,0,0,0,0,,,0,0,0,0,,,0,0,0,0,,,0,0,0,0,,,0,0,0,0,MSFT
2024-10-22 13:21:41.044349478+00:00,10,39,10888,A,B,1,417.2,2000,130,203569,105634,418.8,420.4,2000,2000,1,1,417.2,420.8,2000,2000,1,1,,422.4,0,2000,0,1,,,0,0,0,0,,,0,0,0,0,,,0,0,0,0,,,0,0,0,0,,,0,0,0,0,,,0,0,0,0,,,0,0,0,0,MSFT
2024-10-22 13:21:41.044618073+00:00,10,39,10888,A,A,2,421.6,2000,130,203543,105635,418.8,420.4,2000,2000,1,1,417.2,420.8,2000,2000,1,1,,421.6,0,2000,0,1,,422.4,0,2000,0,1,,,0,0,0,0,,,0,0,0,0,,,0,0,0,0,,,0,0,0,0,,,0,0,0,0,,,0,0,0,0,MSFT
2024-10-22 13:21:41.044778311+00:00,10,39,10888,C,A,3,422.4,2000,130,203503,105636,418.8,420.4,2000,2000,1,1,417.2,420.8,2000,2000,1,1,,421.6,0,2000,0,1,,,0,0,0,0,,,0,0,0,0,,,0,0,0,0,,,0,0,0,0,,,0,0,0,0,,,0,0,0,0,,,0,0,0,0,MSFT
2024-10-22 13:21:41.045296242+00:00,10,39,38,A,B,2,233.0,2000,130,203294,72117,233.4,234.4,2000,2000,1,1,233.2,234.6,2000,2000,1,1,233.0,235.8,2000,2000,1,1,232.8,,2000,0,1,0,,,0,0,0,0,,,0,0,0,0,,,0,0,0,0,,,0,0,0,0,,,0,0,0,0,,,0,0,0,0,AAPL
2024-10-22 13:21:41.045503367+00:00,10,39,38,C,B,3,232.8,2000,130,203322,72118,233.4,234.4,2000,2000,1,1,233.2,234.6,2000,2000,1,1,233.0,235.8,2000,2000,1,1,,,0,0,0,0,,,0,0,0,0,,,0,0,0,0,,,0,0,0,0,,,0,0,0,0,,,0,0,0,0,,,0,0,0,0,AAPL
2024-10-22 13:21:41.108377382+00:00,10,39,38,A,A,2,235.6,2000,130,203303,72131,233.4,234.4,2000,2000,1,1,233.2,234.6,2000,2000,1,1,233.0,235.6,2000,2000,1,1,,235.8,0,2000,0,1,,,0,0,0,0,,,0,0,0,0,,,0,0,0,0,,,0,0,0,0,,,0,0,0,0,,,0,0,0,0,AAPL
2024-10-22 13:21:41.108942467+00:00,10,39,38,C,A,3,235.8,2000,130,203268,72132,233.4,234.4,2000,2000,1,1,233.2,234.6,2000,2000,1,1,233.0,235.6,2000,2000,1,1,,,0,0,0,0,,,0,0,0,0,,,0,0,0,0,,,0,0,0,0,,,0,0,0,0,,,0,0,0,0,,,0,0,0,0,AAPL
2024-10-22 13:21:41.109465510+00:00,10,39,10888,A,B,1,418.0,2000,130,203521,105638,418.8,420.4,2000,2000,1,1,418.0,420.8,2000,2000,1,1,417.2,421.6,2000,2000,1,1,,,0,0,0,0,,,0,0,0,0,,,0,0,0,0,,,0,0,0,0,,,0,0,0,0,,,0,0,0,0,,,0,0,0,0,MSFT
2024-10-22 13:21:41.109646989+00:00,10,39,10888,C,B,2,417.2,2000,130,203506,105639,418.8,420.4,2000,2000,1,1,418.0,420.8,2000,2000,1,1,,421.6,0,2000,0,1,,,0,0,0,0,,,0,0,0,0,,,0,0,0,0,,,0,0,0,0,,,0,0,0,0,,,0,0,0,0,,,0,0,0,0,MSFT
2024-10-22 13:21:41.120553718+00:00,10,39,10888,A,B,2,416.8,2000,130,203577,105640,418.8,420.4,2000,2000,1,1,418.0,420.8,2000,2000,1,1,416.8,421.6,2000,2000,1,1,,,0,0,0,0,,,0,0,0,0,,,0,0,0,0,,,0,0,0,0,,,0,0,0,0,,,0,0,0,0,,,0,0,0,0,MSFT
2024-10-22 13:21:41.144545347+00:00,10,39,10888,A,B,2,417.6,2000,130,203506,105641,418.8,420.4,2000,2000,1,1,418.0,420.8,2000,2000,1,1,417.6,421.6,2000,2000,1,1,416.8,,2000,0,1,0,,,0,0,0,0,,,0,0,0,0,,,0,0,0,0,,,0,0,0,0,,,0,0,0,0,,,0,0,0,0,MSFT
2024-10-22 13:21:41.209120764+00:00,10,39,38,A,A,2,235.4,2000,130,203408,72138,233.4,234.4,2000,2000,1,1,233.2,234.6,2000,2000,1,1,233.0,235.4,2000,2000,1,1,,235.6,0,2000,0,1,,,0,0,0,0,,,0,0,0,0,,,0,0,0,0,,,0,0,0,0,,,0,0,0,0,,,0,0,0,0,AAPL
2024-10-22 13:21:41.209299945+00:00,10,39,38,C,A,3,235.6,2000,130,203221,72139,233.4,234.4,2000,2000,1,1,233.2,234.6,2000,2000,1,1,233.0,235.4,2000,2000,1,1,,,0,0,0,0,,,0,0,0,0,,,0,0,0,0,,,0,0,0,0,,,0,0,0,0,,,0,0,0,0,,,0,0,0,0,AAPL
2024-10-22 13:21:41.244556521+00:00,10,39,38,A,A,2,235.0,2000,130,203387,72140,233.4,234.4,2000,2000,1,1,233.2,234.6,2000,2000,1,1,233.0,235.0,2000,2000,1,1,,235.4,0,2000,0,1,,,0,0,0,0,,,0,0,0,0,,,0,0,0,0,,,0,0,0,0,,,0,0,0,0,,,0,0,0,0,AAPL
2024-10-22 13:21:41.244740590+00:00,10,39,38,C,A,3,235.4,2000,130,203209,72141,233.4,234.4,2000,2000,1,1,233.2,234.6,2000,2000,1,1,233.0,235.0,2000,2000,1,1,,,0,0,0,0,,,0,0,0,0,,,0,0,0,0,,,0,0,0,0,,,0,0,0,0,,,0,0,0,0,,,0,0,0,0,AAPL
2024-10-22 13:21:41.302276247+00:00,10,39,38,A,A,2,234.8,2000,130,203455,72142,233.4,234.4,2000,2000,1,1,233.2,234.6,2000,2000,1,1,233.0,234.8,2000,2000,1,1,,235.0,0,2000,0,1,,,0,0,0,0,,,0,0,0,0,,,0,0,0,0,,,0,0,0,0,,,0,0,0,0,,,0,0,0,0,AAPL
2024-10-22 13:21:41.303003714+00:00,10,39,38,C,A,3,235.0,2000,130,203280,72143,233.4,234.4,2000,2000,1,1,233.2,234.6,2000,2000,1,1,233.0,234.8,2000,2000,1,1,,,0,0,0,0,,,0,0,0,0,,,0,0,0,0,,,0,0,0,0,,,0,0,0,0,,,0,0,0,0,,,0,0,0,0,AAPL
2024-10-22 13:21:41.309164232+00:00,10,39,10888,A,A,2,421.2,2000,130,203557,105649,418.8,420.4,2000,2000,1,1,418.0,420.8,2000,2000,1,1,417.6,421.2,2000,2000,1,1,416.8,421.6,2000,2000,1,1,,,0,0,0,0,,,0,0,0,0,,,0,0,0,0,,,0,0,0,0,,,0,0,0,0,,,0,0,0,0,MSFT
2024-10-22 13:21:49.137659224+00:00,10,40,38,A,B,0,234.3,200,194,203088,125040,,234.3,0,200,0,0,,,0,0,0,0,,,0,0,0,0,,,0,0,0,0,,,0,0,0,0,,,0,0,0,0,,,0,0,0,0,,,0,0,0,0,,,0,0,0,0,,,0,0,0,0,AAPL
2024-10-22 13:21:49.138131284+00:00,10,41,38,A,B,0,234.25,200,194,55547,311231,,234.25,0,200,0,0,,,0,0,0,0,,,0,0,0,0,,,0,0,0,0,,,0,0,0,0,,,0,0,0,0,,,0,0,0,0,,,0,0,0,0,,,0,0,0,0,,,0,0,0,0,AAPL
2024-10-22 13:21:50.023657264+00:00,10,40,38,A,B,0,234.3,200,194,203222,125047,233.64,234.3,200,200,0,0,,,0,0,0,0,,,0,0,0,0,,,0,0,0,0,,,0,0,0,0,,,0,0,0,0,,,0,0,0,0,,,0,0,0,0,,,0,0,0,0,,,0,0,0,0,AAPL
2024-10-22 13:21:50.034558082+00:00,10,39,38,A,B,0,233.6,2000,130,204202,72171,233.6,234.4,2000,2000,1,1,233.4,234.6,2000,2000,1,1,233.2,234.8,2000,2000,1,1,233.0,,2000,0,1,0,,,0,0,0,0,,,0,0,0,0,,,0,0,0,0,,,0,0,0,0,,,0,0,0,0,,,0,0,0,0,AAPL
2024-10-22 13:21:50.126360650+00:00,10,40,38,A,B,0,234.3,200,194,203064,125048,,234.3,0,200,0,0,,,0,0,0,0,,,0,0,0,0,,,0,0,0,0,,,0,0,0,0,,,0,0,0,0,,,0,0,0,0,,,0,0,0,0,,,0,0,0,0,,,0,0,0,0,AAPL
2024-10-22 13:21:50.946919717+00:00,10,40,38,A,B,0,234.3,200,194,203135,125051,233.64,234.3,200,200,0,0,,,0,0,0,0,,,0,0,0,0,,,0,0,0,0,,,0,0,0,0,,,0,0,0,0,,,0,0,0,0,,,0,0,0,0,,,0,0,0,0,,,0,0,0,0,AAPL
2024-10-22 13:21:51.051696865+00:00,10,40,38,A,B,0,234.3,200,194,203087,125057,,234.3,0,200,0,0,,,0,0,0,0,,,0,0,0,0,,,0,0,0,0,,,0,0,0,0,,,0,0,0,0,,,0,0,0,0,,,0,0,0,0,,,0,0,0,0,,,0,0,0,0,AAPL
2024-10-22 13:22:00.000834538+00:00,10,40,38,A,A,0,,0,194,203348,125150,,,0,0,0,0,,,0,0,0,0,,,0,0,0,0,,,0,0,0,0,,,0,0,0,0,,,0,0,0,0,,,0,0,0,0,,,0,0,0,0,,,0,0,0,0,,,0,0,0,0,AAPL
2024-10-22 13:22:00.001067220+00:00,10,41,38,A,A,0,,0,194,54776,311814,,,0,0,0,0,,,0,0,0,0,,,0,0,0,0,,,0,0,0,0,,,0,0,0,0,,,0,0,0,0,,,0,0,0,0,,,0,0,0,0,,,0,0,0,0,,,0,0,0,0,AAPL
2024-10-22 13:22:00.126462603+00:00,10,40,38,A,A,0,234.25,200,194,203365,125181,,234.25,0,200,0,0,,,0,0,0,0,,,0,0,0,0,,,0,0,0,0,,,0,0,0,0,,,0,0,0,0,,,0,0,0,0,,,0,0,0,0,,,0,0,0,0,,,0,0,0,0,AAPL
2024-10-22 13:22:00.163915474+00:00,10,40,38,A,B,0,234.25,200,194,203333,125183,233.64,234.25,200,200,0,0,,,0,0,0,0,,,0,0,0,0,,,0,0,0,0,,,0,0,0,0,,,0,0,0,0,,,0,0,0,0,,,0,0,0,0,,,0,0,0,0,,,0,0,0,0,AAPL
2024-10-22 13:22:00.164169097+00:00,10,41,38,A,A,0,234.2,200,194,55238,311961,,234.2,0,200,0,0,,,0,0,0,0,,,0,0,0,0,,,0,0,0,0,,,0,0,0,0,,,0,0,0,0,,,0,0,0,0,,,0,0,0,0,,,0,0,0,0,,,0,0,0,0,AAPL
2024-10-22 13:22:00.164899361+00:00,10,39,38,C,A,1,234.6,2000,130,204078,72210,233.6,234.4,2000,2000,1,1,233.4,234.8,2000,2000,1,1,233.2,,2000,0,1,0,233.0,,2000,0,1,0,,,0,0,0,0,,,0,0,0,0,,,0,0,0,0,,,0,0,0,0,,,0,0,0,0,,,0,0,0,0,AAPL
2024-10-22 13:22:00.199955987+00:00,10,39,38,A,A,1,234.6,2000,130,203797,72211,233.6,234.4,2000,2000,1,1,233.4,234.6,2000,2000,1,1,233.2,234.8,2000,2000,1,1,233.0,,2000,0,1,0,,,0,0,0,0,,,0,0,0,0,,,0,0,0,0,,,0,0,0,0,,,0,0,0,0,,,0,0,0,0,AAPL
2024-10-22 13:22:00.200264421+00:00,10,41,38,A,B,0,234.2,200,194,55674,311966,233.69,234.2,200,200,0,0,,,0,0,0,0,,,0,0,0,0,,,0,0,0,0,,,0,0,0,0,,,0,0,0,0,,,0,0,0,0,,,0,0,0,0,,,0,0,0,0,,,0,0,0,0,AAPL
2024-10-22 13:22:00.261227954+00:00,10,40,38,A,B,0,234.25,200,194,203357,125192,,234.25,0,200,0,0,,,0,0,0,0,,,0,0,0,0,,,0,0,0,0,,,0,0,0,0,,,0,0,0,0,,,0,0,0,0,,,0,0,0,0,,,0,0,0,0,,,0,0,0,0,AAPL
2024-10-22 13:22:00.261462902+00:00,10,41,38,A,B,0,234.2,200,194,55124,311988,,234.2,0,200,0,0,,,0,0,0,0,,,0,0,0,0,,,0,0,0,0,,,0,0,0,0,,,0,0,0,0,,,0,0,0,0,,,0,0,0,0,,,0,0,0,0,,,0,0,0,0,AAPL
2024-10-22 13:22:01.947302745+00:00,10,40,38,A,B,0,234.25,200,194,203350,125243,233.64,234.25,200,200,0,0,,,0,0,0,0,,,0,0,0,0,,,0,0,0,0,,,0,0,0,0,,,0,0,0,0,,,0,0,0,0,,,0,0,0,0,,,0,0,0,0,,,0,0,0,0,AAPL
2024-10-22 13:22:01.981131996+00:00,10,40,38,A,B,0,234.25,200,194,203581,125248,,234.25,0,200,0,0,,,0,0,0,0,,,0,0,0,0,,,0,0,0,0,,,0,0,0,0,,,0,0,0,0,,,0,0,0,0,,,0,0,0,0,,,0,0,0,0,,,0,0,0,0,AAPL
2024-10-22 13:22:02.268447194+00:00,10,40,38,A,B,0,234.25,200,194,203379,125261,233.65,234.25,200,200,0,0,,,0,0,0,0,,,0,0,0,0,,,0,0,0,0,,,0,0,0,0,,,0,0,0,0,,,0,0,0,0,,,0,0,0,0,,,0,0,0,0,,,0,0,0,0,AAPL
2024-10-22 13:22:02.329533830+00:00,10,41,38,A,B,0,234.2,200,194,55552,312302,233.7,234.2,200,200,0,0,,,0,0,0,0,,,0,0,0,0,,,0,0,0,0,,,0,0,0,0,,,0,0,0,0,,,0,0,0,0,,,0,0,0,0,,,0,0,0,0,,,0,0,0,0,AAPL
2024-10-22 13:22:02.961435557+00:00,10,41,38,A,B,0,234.2,200,194,55513,312347,,234.2,0,200,0,0,,,0,0,0,0,,,0,0,0,0,,,0,0,0,0,,,0,0,0,0,,,0,0,0,0,,,0,0,0,0,,,0,0,0,0,,,0,0,0,0,,,0,0,0,0,AAPL
2024-10-22 13:22:02.994369458+00:00,10,41,38,A,B,0,234.2,200,194,54900,312350,233.7,234.2,200,200,0,0,,,0,0,0,0,,,0,0,0,0,,,0,0,0,0,,,0,0,0,0,,,0,0,0,0,,,0,0,0,0,,,0,0,0,0,,,0,0,0,0,,,0,0,0,0,AAPL
2024-10-22 13:22:04.131968329+00:00,10,41,38,A,A,0,,0,194,55427,312410,233.7,,200,0,0,0,,,0,0,0,0,,,0,0,0,0,,,0,0,0,0,,,0,0,0,0,,,0,0,0,0,,,0,0,0,0,,,0,0,0,0,,,0,0,0,0,,,0,0,0,0,AAPL
2024-10-22 13:22:04.131987376+00:00,10,41,38,A,A,0,234.25,200,194,54690,312411,233.7,234.25,200,200,0,0,,,0,0,0,0,,,0,0,0,0,,,0,0,0,0,,,0,0,0,0,,,0,0,0,0,,,0,0,0,0,,,0,0,0,0,,,0,0,0,0,,,0,0,0,0,AAPL
2024-10-22 13:22:04.753930127+00:00,10,41,38,A,B,0,234.25,200,194,55606,312449,,234.25,0,200,0,0,,,0,0,0,0,,,0,0,0,0,,,0,0,0,0,,,0,0,0,0,,,0,0,0,0,,,0,0,0,0,,,0,0,0,0,,,0,0,0,0,,,0,0,0,0,AAPL
2024-10-22 13:22:05.806903923+00:00,10,41,38,A,B,0,234.25,200,194,56199,312518,233.7,234.25,200,200,0,0,,,0,0,0,0,,,0,0,0,0,,,0,0,0,0,,,0,0,0,0,,,0,0,0,0,,,0,0,0,0,,,0,0,0,0,,,0,0,0,0,,,0,0,0,0,AAPL
2024-10-22 13:22:06.471786354+00:00,10,40,38,A,B,0,234.25,200,194,203524,125333,,234.25,0,200,0,0,,,0,0,0,0,,,0,0,0,0,,,0,0,0,0,,,0,0,0,0,,,0,0,0,0,,,0,0,0,0,,,0,0,0,0,,,0,0,0,0,,,0,0,0,0,AAPL
2024-10-22 13:22:06.472013351+00:00,10,41,38,A,B,0,234.25,200,194,55388,312574,,234.25,0,200,0,0,,,0,0,0,0,,,0,0,0,0,,,0,0,0,0,,,0,0,0,0,,,0,0,0,0,,,0,0,0,0,,,0,0,0,0,,,0,0,0,0,,,0,0,0,0,AAPL
2024-10-22 13:22:06.504897184+00:00,10,40,38,A,A,0,,0,194,203612,125334,,,0,0,0,0,,,0,0,0,0,,,0,0,0,0,,,0,0,0,0,,,0,0,0,0,,,0,0,0,0,,,0,0,0,0,,,0,0,0,0,,,0,0,0,0,,,0,0,0,0,AAPL
2024-10-22 13:22:06.846966839+00:00,10,41,38,A,A,0,,0,194,54616,312611,,,0,0,0,0,,,0,0,0,0,,,0,0,0,0,,,0,0,0,0,,,0,0,0,0,,,0,0,0,0,,,0,0,0,0,,,0,0,0,0,,,0,0,0,0,,,0,0,0,0,AAPL
2024-10-22 13:22:08.697915879+00:00,10,40,38,A,A,0,234.3,200,194,203663,125354,,234.3,0,200,0,0,,,0,0,0,0,,,0,0,0,0,,,0,0,0,0,,,0,0,0,0,,,0,0,0,0,,,0,0,0,0,,,0,0,0,0,,,0,0,0,0,,,0,0,0,0,AAPL
2024-10-22 13:22:08.698026004+00:00,10,40,38,A,B,0,234.3,200,194,203593,125355,233.67,234.3,200,200,0,0,,,0,0,0,0,,,0,0,0,0,,,0,0,0,0,,,0,0,0,0,,,0,0,0,0,,,0,0,0,0,,,0,0,0,0,,,0,0,0,0,,,0,0,0,0,AAPL
2024-10-22 13:22:08.698163266+00:00,10,41,38,A,A,0,234.25,200,194,55784,312796,,234.25,0,200,0,0,,,0,0,0,0,,,0,0,0,0,,,0,0,0,0,,,0,0,0,0,,,0,0,0,0,,,0,0,0,0,,,0,0,0,0,,,0,0,0,0,,,0,0,0,0,AAPL
2024-10-22 13:22:08.950075091+00:00,10,40,38,A,B,0,234.3,200,194,203742,125357,,234.3,0,200,0,0,,,0,0,0,0,,,0,0,0,0,,,0,0,0,0,,,0,0,0,0,,,0,0,0,0,,,0,0,0,0,,,0,0,0,0,,,0,0,0,0,,,0,0,0,0,AAPL
2024-10-22 13:22:09.010991083+00:00,10,40,38,A,B,0,234.3,200,194,203739,125360,233.67,234.3,200,200,0,0,,,0,0,0,0,,,0,0,0,0,,,0,0,0,0,,,0,0,0,0,,,0,0,0,0,,,0,0,0,0,,,0,0,0,0,,,0,0,0,0,,,0,0,0,0,AAPL
2024-10-22 13:22:09.011247118+00:00,10,41,38,A,B,0,234.25,200,194,55391,312812,233.72,234.25,200,200,0,0,,,0,0,0,0,,,0,0,0,0,,,0,0,0,0,,,0,0,0,0,,,0,0,0,0,,,0,0,0,0,,,0,0,0,0,,,0,0,0,0,,,0,0,0,0,AAPL
2024-10-22 13:22:09.051645450+00:00,10,40,38,A,B,0,234.3,200,194,203803,125361,,234.3,0,200,0,0,,,0,0,0,0,,,0,0,0,0,,,0,0,0,0,,,0,0,0,0,,,0,0,0,0,,,0,0,0,0,,,0,0,0,0,,,0,0,0,0,,,0,0,0,0,AAPL
2024-10-22 13:22:09.051810418+00:00,10,41,38,A,B,0,234.25,200,194,55351,312815,,234.25,0,200,0,0,,,0,0,0,0,,,0,0,0,0,,,0,0,0,0,,,0,0,0,0,,,0,0,0,0,,,0,0,0,0,,,0,0,0,0,,,0,0,0,0,,,0,0,0,0,AAPL
2024-10-22 13:22:09.249808477+00:00,10,40,38,A,B,0,234.3,200,194,203698,125362,233.67,234.3,200,200,0,0,,,0,0,0,0,,,0,0,0,0,,,0,0,0,0,,,0,0,0,0,,,0,0,0,0,,,0,0,0,0,,,0,0,0,0,,,0,0,0,0,,,0,0,0,0,AAPL
2024-10-22 13:22:10.271144661+00:00,10,40,38,A,B,0,234.3,200,194,203737,125370,,234.3,0,200,0,0,,,0,0,0,0,,,0,0,0,0,,,0,0,0,0,,,0,0,0,0,,,0,0,0,0,,,0,0,0,0,,,0,0,0,0,,,0,0,0,0,,,0,0,0,0,AAPL
2024-10-22 13:22:10.671707060+00:00,10,40,38,A,A,0,,0,194,203821,125372,,,0,0,0,0,,,0,0,0,0,,,0,0,0,0,,,0,0,0,0,,,0,0,0,0,,,0,0,0,0,,,0,0,0,0,,,0,0,0,0,,,0,0,0,0,,,0,0,0,0,AAPL
2024-10-22 13:22:12.139843561+00:00,10,40,38,A,A,0,234.3,200,194,203755,125394,,234.3,0,200,0,0,,,0,0,0,0,,,0,0,0,0,,,0,0,0,0,,,0,0,0,0,,,0,0,0,0,,,0,0,0,0,,,0,0,0,0,,,0,0,0,0,,,0,0,0,0,AAPL
2024-10-22 13:22:12.140084148+00:00,10,41,38,A,B,0,234.25,200,194,55379,313013,233.72,234.25,200,200,0,0,,,0,0,0,0,,,0,0,0,0,,,0,0,0,0,,,0,0,0,0,,,0,0,0,0,,,0,0,0,0,,,0,0,0,0,,,0,0,0,0,,,0,0,0,0,AAPL
2024-10-22 13:22:12.139978280+00:00,10,40,38,A,B,0,234.3,200,194,203704,125395,233.67,234.3,200,200,0,0,,,0,0,0,0,,,0,0,0,0,,,0,0,0,0,,,0,0,0,0,,,0,0,0,0,,,0,0,0,0,,,0,0,0,0,,,0,0,0,0,,,0,0,0,0,AAPL
2024-10-22 13:22:12.232180427+00:00,10,41,38,A,B,0,234.25,200,194,55390,313021,,234.25,0,200,0,0,,,0,0,0,0,,,0,0,0,0,,,0,0,0,0,,,0,0,0,0,,,0,0,0,0,,,0,0,0,0,,,0,0,0,0,,,0,0,0,0,,,0,0,0,0,AAPL
2024-10-22 13:22:12.335054758+00:00,10,40,38,A,B,0,234.3,200,194,203769,125401,,234.3,0,200,0,0,,,0,0,0,0,,,0,0,0,0,,,0,0,0,0,,,0,0,0,0,,,0,0,0,0,,,0,0,0,0,,,0,0,0,0,,,0,0,0,0,,,0,0,0,0,AAPL
2024-10-22 13:22:13.350442117+00:00,10,40,38,A,A,0,,0,194,203836,125433,,,0,0,0,0,,,0,0,0,0,,,0,0,0,0,,,0,0,0,0,,,0,0,0,0,,,0,0,0,0,,,0,0,0,0,,,0,0,0,0,,,0,0,0,0,,,0,0,0,0,AAPL
2024-10-22 13:22:13.448356227+00:00,10,40,38,A,A,0,234.3,200,194,203797,125435,,234.3,0,200,0,0,,,0,0,0,0,,,0,0,0,0,,,0,0,0,0,,,0,0,0,0,,,0,0,0,0,,,0,0,0,0,,,0,0,0,0,,,0,0,0,0,,,0,0,0,0,AAPL
2024-10-22 13:22:13.448472808+00:00,10,40,38,A,B,0,234.3,200,194,203770,125436,233.67,234.3,200,200,0,0,,,0,0,0,0,,,0,0,0,0,,,0,0,0,0,,,0,0,0,0,,,0,0,0,0,,,0,0,0,0,,,0,0,0,0,,,0,0,0,0,,,0,0,0,0,AAPL
2024-10-22 13:22:13.448818389+00:00,10,41,38,A,B,0,234.25,200,194,60243,313126,233.72,234.25,200,200,0,0,,,0,0,0,0,,,0,0,0,0,,,0,0,0,0,,,0,0,0,0,,,0,0,0,0,,,0,0,0,0,,,0,0,0,0,,,0,0,0,0,,,0,0,0,0,AAPL
2024-10-22 13:22:13.551867550+00:00,10,41,38,A,B,0,234.25,200,194,55141,313139,,234.25,0,200,0,0,,,0,0,0,0,,,0,0,0,0,,,0,0,0,0,,,0,0,0,0,,,0,0,0,0,,,0,0,0,0,,,0,0,0,0,,,0,0,0,0,,,0,0,0,0,AAPL
2024-10-22 13:22:13.644356356+00:00,10,40,38,A,B,0,234.3,200,194,203855,125440,,234.3,0,200,0,0,,,0,0,0,0,,,0,0,0,0,,,0,0,0,0,,,0,0,0,0,,,0,0,0,0,,,0,0,0,0,,,0,0,0,0,,,0,0,0,0,,,0,0,0,0,AAPL
2024-10-22 13:22:14.412010699+00:00,10,41,38,A,B,0,234.25,200,194,55412,313206,233.72,234.25,200,200,0,0,,,0,0,0,0,,,0,0,0,0,,,0,0,0,0,,,0,0,0,0,,,0,0,0,0,,,0,0,0,0,,,0,0,0,0,,,0,0,0,0,,,0,0,0,0,AAPL
2024-10-22 13:22:14.412278028+00:00,10,40,38,A,B,0,234.3,200,194,203734,125451,233.67,234.3,200,200,0,0,,,0,0,0,0,,,0,0,0,0,,,0,0,0,0,,,0,0,0,0,,,0,0,0,0,,,0,0,0,0,,,0,0,0,0,,,0,0,0,0,,,0,0,0,0,AAPL
2024-10-22 13:22:15.283667476+00:00,10,39,10888,C,B,0,418.8,2000,130,203776,105882,418.0,420.4,2000,2000,1,1,417.6,420.8,2000,2000,1,1,416.8,421.2,2000,2000,1,1,,421.6,0,2000,0,1,,,0,0,0,0,,,0,0,0,0,,,0,0,0,0,,,0,0,0,0,,,0,0,0,0,,,0,0,0,0,MSFT
2024-10-22 13:22:15.319785231+00:00,10,39,10888,A,B,0,418.4,2000,130,203761,105883,418.4,420.4,2000,2000,1,1,418.0,420.8,2000,2000,1,1,417.6,421.2,2000,2000,1,1,416.8,421.6,2000,2000,1,1,,,0,0,0,0,,,0,0,0,0,,,0,0,0,0,,,0,0,0,0,,,0,0,0,0,,,0,0,0,0,MSFT
2024-10-22 13:22:15.319955996+00:00,10,39,10888,C,B,1,418.0,2000,130,203608,105884,418.4,420.4,2000,2000,1,1,417.6,420.8,2000,2000,1,1,416.8,421.2,2000,2000,1,1,,421.6,0,2000,0,1,,,0,0,0,0,,,0,0,0,0,,,0,0,0,0,,,0,0,0,0,,,0,0,0,0,,,0,0,0,0,MSFT
2024-10-22 13:22:15.331723686+00:00,10,39,10888,A,B,2,417.2,2000,130,203763,105885,418.4,420.4,2000,2000,1,1,417.6,420.8,2000,2000,1,1,417.2,421.2,2000,2000,1,1,416.8,421.6,2000,2000,1,1,,,0,0,0,0,,,0,0,0,0,,,0,0,0,0,,,0,0,0,0,,,0,0,0,0,,,0,0,0,0,MSFT
2024-10-22 13:22:16.490209992+00:00,10,39,10888,A,B,1,418.0,2000,130,203782,105894,418.4,420.4,2000,2000,1,1,418.0,420.8,2000,2000,1,1,417.6,421.2,2000,2000,1,1,417.2,421.6,2000,2000,1,1,416.8,,2000,0,1,0,,,0,0,0,0,,,0,0,0,0,,,0,0,0,0,,,0,0,0,0,,,0,0,0,0,MSFT
2024-10-22 13:22:25.637155952+00:00,10,39,10888,C,A,1,420.8,2000,130,203656,105950,418.4,420.4,2000,2000,1,1,418.0,421.2,2000,2000,1,1,417.6,421.6,2000,2000,1,1,417.2,,2000,0,1,0,416.8,,2000,0,1,0,,,0,0,0,0,,,0,0,0,0,,,0,0,0,0,,,0,0,0,0,,,0,0,0,0,MSFT
2024-10-22 13:22:25.646991459+00:00,10,39,10888,A,B,0,418.8,2000,130,203375,105952,418.8,420.4,2000,2000,1,1,418.4,421.2,2000,2000,1,1,418.0,421.6,2000,2000,1,1,417.6,,2000,0,1,0,417.2,,2000,0,1,0,416.8,,2000,0,1,0,,,0,0,0,0,,,0,0,0,0,,,0,0,0,0,,,0,0,0,0,MSFT
2024-10-22 13:22:25.673326661+00:00,10,39,10888,A,A,1,420.8,2000,130,203255,105953,418.8,420.4,2000,2000,1,1,418.4,420.8,2000,2000,1,1,418.0,421.2,2000,2000,1,1,417.6,421.6,2000,2000,1,1,417.2,,2000,0,1,0,416.8,,2000,0,1,0,,,0,0,0,0,,,0,0,0,0,,,0,0,0,0,,,0,0,0,0,MSFT
2024-10-22 13:22:26.715414701+00:00,10,41,38,A,A,0,,0,194,55843,313900,233.72,,200,0,0,0,,,0,0,0,0,,,0,0,0,0,,,0,0,0,0,,,0,0,0,0,,,0,0,0,0,,,0,0,0,0,,,0,0,0,0,,,0,0,0,0,,,0,0,0,0,AAPL
2024-10-22 13:22:28.098790685+00:00,10,40,38,A,A,0,,0,194,203808,125648,233.67,,200,0,0,0,,,0,0,0,0,,,0,0,0,0,,,0,0,0,0,,,0,0,0,0,,,0,0,0,0,,,0,0,0,0,,,0,0,0,0,,,0,0,0,0,,,0,0,0,0,AAPL
2024-10-22 13:22:29.445205280+00:00,10,40,38,A,A,0,234.3,200,194,203386,125657,233.67,234.3,200,200,0,0,,,0,0,0,0,,,0,0,0,0,,,0,0,0,0,,,0,0,0,0,,,0,0,0,0,,,0,0,0,0,,,0,0,0,0,,,0,0,0,0,,,0,0,0,0,AAPL
2024-10-22 13:22:29.445695481+00:00,10,41,38,A,A,0,234.25,200,194,56548,314017,233.72,234.25,200,200,0,0,,,0,0,0,0,,,0,0,0,0,,,0,0,0,0,,,0,0,0,0,,,0,0,0,0,,,0,0,0,0,,,0,0,0,0,,,0,0,0,0,,,0,0,0,0,AAPL
2024-10-22 13:22:30.801242333+00:00,10,41,38,A,B,0,234.25,200,194,56042,314064,,234.25,0,200,0,0,,,0,0,0,0,,,0,0,0,0,,,0,0,0,0,,,0,0,0,0,,,0,0,0,0,,,0,0,0,0,,,0,0,0,0,,,0,0,0,0,,,0,0,0,0,AAPL
2024-10-22 13:22:30.954735943+00:00,10,41,38,A,B,0,234.25,200,194,55373,314075,233.73,234.25,200,200,0,0,,,0,0,0,0,,,0,0,0,0,,,0,0,0,0,,,0,0,0,0,,,0,0,0,0,,,0,0,0,0,,,0,0,0,0,,,0,0,0,0,,,0,0,0,0,AAPL
2024-10-22 13:22:31.156896228+00:00,10,41,38,A,B,0,234.25,200,194,55249,314090,,234.25,0,200,0,0,,,0,0,0,0,,,0,0,0,0,,,0,0,0,0,,,0,0,0,0,,,0,0,0,0,,,0,0,0,0,,,0,0,0,0,,,0,0,0,0,,,0,0,0,0,AAPL
2024-10-22 13:22:32.198813638+00:00,10,40,38,A,A,0,,0,194,203225,125680,233.67,,200,0,0,0,,,0,0,0,0,,,0,0,0,0,,,0,0,0,0,,,0,0,0,0,,,0,0,0,0,,,0,0,0,0,,,0,0,0,0,,,0,0,0,0,,,0,0,0,0,AAPL
2024-10-22 13:22:32.300227898+00:00,10,40,38,A,B,0,,0,194,203186,125681,,,0,0,0,0,,,0,0,0,0,,,0,0,0,0,,,0,0,0,0,,,0,0,0,0,,,0,0,0,0,,,0,0,0,0,,,0,0,0,0,,,0,0,0,0,,,0,0,0,0,AAPL
2024-10-22 13:22:33.006098120+00:00,10,41,38,A,B,0,234.25,200,194,55302,314170,233.73,234.25,200,200,0,0,,,0,0,0,0,,,0,0,0,0,,,0,0,0,0,,,0,0,0,0,,,0,0,0,0,,,0,0,0,0,,,0,0,0,0,,,0,0,0,0,,,0,0,0,0,AAPL
2024-10-22 13:22:34.438546352+00:00,10,40,38,A,N,0,234.3,200,194,203519,125701,233.68,234.3,200,200,0,0,,,0,0,0,0,,,0,0,0,0,,,0,0,0,0,,,0,0,0,0,,,0,0,0,0,,,0,0,0,0,,,0,0,0,0,,,0,0,0,0,,,0,0,0,0,AAPL
2024-10-22 13:22:34.640606898+00:00,10,41,38,A,B,0,234.25,200,194,55647,314267,,234.25,0,200,0,0,,,0,0,0,0,,,0,0,0,0,,,0,0,0,0,,,0,0,0,0,,,0,0,0,0,,,0,0,0,0,,,0,0,0,0,,,0,0,0,0,,,0,0,0,0,AAPL
2024-10-22 13:22:34.942193253+00:00,10,41,38,A,B,0,234.25,200,194,60307,314290,233.73,234.25,200,200,0,0,,,0,0,0,0,,,0,0,0,0,,,0,0,0,0,,,0,0,0,0,,,0,0,0,0,,,0,0,0,0,,,0,0,0,0,,,0,0,0,0,,,0,0,0,0,AAPL
2024-10-22 13:22:37.340934260+00:00,10,41,10888,A,A,0,420.48,100,194,55814,314386,,420.48,0,100,0,0,,,0,0,0,0,,,0,0,0,0,,,0,0,0,0,,,0,0,0,0,,,0,0,0,0,,,0,0,0,0,,,0,0,0,0,,,0,0,0,0,,,0,0,0,0,MSFT
2024-10-22 13:22:39.636358471+00:00,10,40,38,A,A,0,,0,194,203742,125736,233.68,,200,0,0,0,,,0,0,0,0,,,0,0,0,0,,,0,0,0,0,,,0,0,0,0,,,0,0,0,0,,,0,0,0,0,,,0,0,0,0,,,0,0,0,0,,,0,0,0,0,AAPL
2024-10-22 13:22:39.636442529+00:00,10,40,38,A,B,0,,0,194,203667,125737,,,0,0,0,0,,,0,0,0,0,,,0,0,0,0,,,0,0,0,0,,,0,0,0,0,,,0,0,0,0,,,0,0,0,0,,,0,0,0,0,,,0,0,0,0,,,0,0,0,0,AAPL
2024-10-22 13:22:39.884708661+00:00,10,41,38,A,A,0,,0,194,55568,314515,233.73,,200,0,0,0,,,0,0,0,0,,,0,0,0,0,,,0,0,0,0,,,0,0,0,0,,,0,0,0,0,,,0,0,0,0,,,0,0,0,0,,,0,0,0,0,,,0,0,0,0,AAPL
2024-10-22 13:22:45.414700582+00:00,10,39,10888,C,A,1,420.8,2000,130,202806,106063,418.8,420.4,2000,2000,1,1,418.4,421.2,2000,2000,1,1,418.0,421.6,2000,2000,1,1,417.6,,2000,0,1,0,417.2,,2000,0,1,0,416.8,,2000,0,1,0,,,0,0,0,0,,,0,0,0,0,,,0,0,0,0,,,0,0,0,0,MSFT
2024-10-22 13:22:46.965249253+00:00,10,41,38,A,A,0,234.25,200,194,60520,314878,233.73,234.25,200,200,0,0,,,0,0,0,0,,,0,0,0,0,,,0,0,0,0,,,0,0,0,0,,,0,0,0,0,,,0,0,0,0,,,0,0,0,0,,,0,0,0,0,,,0,0,0,0,AAPL
2024-10-22 13:22:47.724571962+00:00,10,39,10888,A,B,0,419.7,2,130,202980,106094,419.7,420.4,2,2000,1,1,418.8,421.2,2000,2000,1,1,418.4,421.6,2000,2000,1,1,418.0,,2000,0,1,0,417.6,,2000,0,1,0,417.2,,2000,0,1,0,416.8,,2000,0,1,0,,,0,0,0,0,,,0,0,0,0,,,0,0,0,0,MSFT
2024-10-22 13:22:48.496663325+00:00,10,40,38,A,B,0,,0,194,203817,125806,233.68,,200,0,0,0,,,0,0,0,0,,,0,0,0,0,,,0,0,0,0,,,0,0,0,0,,,0,0,0,0,,,0,0,0,0,,,0,0,0,0,,,0,0,0,0,,,0,0,0,0,AAPL
2024-10-22 13:22:48.496765022+00:00,10,40,38,A,A,0,234.3,200,194,203725,125807,233.68,234.3,200,200,0,0,,,0,0,0,0,,,0,0,0,0,,,0,0,0,0,,,0,0,0,0,,,0,0,0,0,,,0,0,0,0,,,0,0,0,0,,,0,0,0,0,,,0,0,0,0,AAPL
2024-10-22 13:22:48.748651315+00:00,10,41,38,A,B,0,234.25,200,194,55454,314978,,234.25,0,200,0,0,,,0,0,0,0,,,0,0,0,0,,,0,0,0,0,,,0,0,0,0,,,0,0,0,0,,,0,0,0,0,,,0,0,0,0,,,0,0,0,0,,,0,0,0,0,AAPL
2024-10-22 13:22:48.809295622+00:00,10,41,38,A,B,0,234.25,200,194,55234,314983,233.73,234.25,200,200,0,0,,,0,0,0,0,,,0,0,0,0,,,0,0,0,0,,,0,0,0,0,,,0,0,0,0,,,0,0,0,0,,,0,0,0,0,,,0,0,0,0,,,0,0,0,0,AAPL
2024-10-22 13:22:48.951889312+00:00,10,41,38,A,A,0,,0,194,55387,314988,233.73,,200,0,0,0,,,0,0,0,0,,,0,0,0,0,,,0,0,0,0,,,0,0,0,0,,,0,0,0,0,,,0,0,0,0,,,0,0,0,0,,,0,0,0,0,,,0,0,0,0,AAPL
2024-10-22 13:22:49.592508102+00:00,10,41,38,A,B,0,,0,194,54677,315073,,,0,0,0,0,,,0,0,0,0,,,0,0,0,0,,,0,0,0,0,,,0,0,0,0,,,0,0,0,0,,,0,0,0,0,,,0,0,0,0,,,0,0,0,0,,,0,0,0,0,AAPL
2024-10-22 13:22:49.592543134+00:00,10,41,38,A,A,0,234.25,200,194,56579,315076,,234.25,0,200,0,0,,,0,0,0,0,,,0,0,0,0,,,0,0,0,0,,,0,0,0,0,,,0,0,0,0,,,0,0,0,0,,,0,0,0,0,,,0,0,0,0,,,0,0,0,0,AAPL
2024-10-22 13:22:49.616373989+00:00,10,39,10888,A,A,1,420.8,2000,130,202922,106108,419.7,420.4,2,2000,1,1,418.8,420.8,2000,2000,1,1,418.4,421.2,2000,2000,1,1,418.0,421.6,2000,2000,1,1,417.6,,2000,0,1,0,417.2,,2000,0,1,0,416.8,,2000,0,1,0,,,0,0,0,0,,,0,0,0,0,,,0,0,0,0,MSFT
2024-10-22 13:22:49.693317703+00:00,10,41,38,A,B,0,234.25,200,194,55749,315111,233.73,234.25,200,200,0,0,,,0,0,0,0,,,0,0,0,0,,,0,0,0,0,,,0,0,0,0,,,0,0,0,0,,,0,0,0,0,,,0,0,0,0,,,0,0,0,0,,,0,0,0,0,AAPL
2024-10-22 13:22:49.946301226+00:00,10,41,38,A,A,0,,0,194,55862,315122,233.73,,200,0,0,0,,,0,0,0,0,,,0,0,0,0,,,0,0,0,0,,,0,0,0,0,,,0,0,0,0,,,0,0,0,0,,,0,0,0,0,,,0,0,0,0,,,0,0,0,0,AAPL
2024-10-22 13:22:51.115567091+00:00,10,39,10888,C,A,1,420.8,2000,130,203072,106141,419.7,420.4,2,2000,1,1,418.8,421.2,2000,2000,1,1,418.4,421.6,2000,2000,1,1,418.0,,2000,0,1,0,417.6,,2000,0,1,0,417.2,,2000,0,1,0,416.8,,2000,0,1,0,,,0,0,0,0,,,0,0,0,0,,,0,0,0,0,MSFT
2024-10-22 13:22:51.125318376+00:00,10,39,10888,A,B,1,419.2,2000,130,202923,106142,419.7,420.4,2,2000,1,1,419.2,421.2,2000,2000,1,1,418.8,421.6,2000,2000,1,1,418.4,,2000,0,1,0,418.0,,2000,0,1,0,417.6,,2000,0,1,0,417.2,,2000,0,1,0,416.8,,2000,0,1,0,,,0,0,0,0,,,0,0,0,0,MSFT
2024-10-22 13:22:51.125479627+00:00,10,39,10888,C,B,7,416.8,2000,130,202759,106143,419.7,420.4,2,2000,1,1,419.2,421.2,2000,2000,1,1,418.8,421.6,2000,2000,1,1,418.4,,2000,0,1,0,418.0,,2000,0,1,0,417.6,,2000,0,1,0,417.2,,2000,0,1,0,,,0,0,0,0,,,0,0,0,0,,,0,0,0,0,MSFT
2024-10-22 13:22:51.150577527+00:00,10,39,10888,A,A,1,420.8,2000,130,202877,106145,419.7,420.4,2,2000,1,1,419.2,420.8,2000,2000,1,1,418.8,421.2,2000,2000,1,1,418.4,421.6,2000,2000,1,1,418.0,,2000,0,1,0,417.6,,2000,0,1,0,417.2,,2000,0,1,0,,,0,0,0,0,,,0,0,0,0,,,0,0,0,0,MSFT
2024-10-22 13:22:51.154590922+00:00,10,39,10888,C,B,3,418.4,2000,130,202757,106146,419.7,420.4,2,2000,1,1,419.2,420.8,2000,2000,1,1,418.8,421.2,2000,2000,1,1,418.0,421.6,2000,2000,1,1,417.6,,2000,0,1,0,417.2,,2000,0,1,0,,,0,0,0,0,,,0,0,0,0,,,0,0,0,0,,,0,0,0,0,MSFT
2024-10-22 13:22:51.306086424+00:00,10,40,38,A,A,0,,0,194,203691,125882,233.68,,200,0,0,0,,,0,0,0,0,,,0,0,0,0,,,0,0,0,0,,,0,0,0,0,,,0,0,0,0,,,0,0,0,0,,,0,0,0,0,,,0,0,0,0,,,0,0,0,0,AAPL
2024-10-22 13:22:53.758203540+00:00,10,41,38,A,B,0,,0,194,55155,315336,,,0,0,0,0,,,0,0,0,0,,,0,0,0,0,,,0,0,0,0,,,0,0,0,0,,,0,0,0,0,,,0,0,0,0,,,0,0,0,0,,,0,0,0,0,,,0,0,0,0,AAPL
2024-10-22 13:22:54.371251590+00:00,10,39,10888,C,A,1,420.8,2000,130,202969,106190,419.7,420.4,2,2000,1,1,419.2,421.2,2000,2000,1,1,418.8,421.6,2000,2000,1,1,418.0,,2000,0,1,0,417.6,,2000,0,1,0,417.2,,2000,0,1,0,,,0,0,0,0,,,0,0,0,0,,,0,0,0,0,,,0,0,0,0,MSFT
2024-10-22 13:22:55.182155385+00:00,10,41,38,A,B,0,,0,194,55725,315446,233.73,,200,0,0,0,,,0,0,0,0,,,0,0,0,0,,,0,0,0,0,,,0,0,0,0,,,0,0,0,0,,,0,0,0,0,,,0,0,0,0,,,0,0,0,0,,,0,0,0,0,AAPL
2024-10-22 13:22:55.407178123+00:00,10,39,10888,C,A,0,420.4,2000,130,203172,106214,419.7,421.2,2,2000,1,1,419.2,421.6,2000,2000,1,1,418.8,,2000,0,1,0,418.0,,2000,0,1,0,417.6,,2000,0,1,0,417.2,,2000,0,1,0,,,0,0,0,0,,,0,0,0,0,,,0,0,0,0,,,0,0,0,0,MSFT
2024-10-22 13:22:55.409200647+00:00,10,39,10888,C,A,1,421.6,2000,130,203005,106215,419.7,421.2,2,2000,1,1,419.2,,2000,0,1,0,418.8,,2000,0,1,0,418.0,,2000,0,1,0,417.6,,2000,0,1,0,417.2,,2000,0,1,0,,,0,0,0,0,,,0,0,0,0,,,0,0,0,0,,,0,0,0,0,MSFT
2024-10-22 13:22:55.448529116+00:00,10,39,10888,A,A,0,420.8,2000,130,203073,106222,419.7,420.8,2,2000,1,1,419.2,421.2,2000,2000,1,1,418.8,,2000,0,1,0,418.0,,2000,0,1,0,417.6,,2000,0,1,0,417.2,,2000,0,1,0,,,0,0,0,0,,,0,0,0,0,,,0,0,0,0,,,0,0,0,0,MSFT
2024-10-22 13:22:55.448700220+00:00,10,39,10888,C,A,1,421.2,2000,130,203043,106224,419.7,420.8,2,2000,1,1,419.2,,2000,0,1,0,418.8,,2000,0,1,0,418.0,,2000,0,1,0,417.6,,2000,0,1,0,417.2,,2000,0,1,0,,,0,0,0,0,,,0,0,0,0,,,0,0,0,0,,,0,0,0,0,MSFT
2024-10-22 13:22:55.459297758+00:00,10,39,10888,A,A,1,422.4,2000,130,203084,106225,419.7,420.8,2,2000,1,1,419.2,422.4,2000,2000,1,1,418.8,,2000,0,1,0,418.0,,2000,0,1,0,417.6,,2000,0,1,0,417.2,,2000,0,1,0,,,0,0,0,0,,,0,0,0,0,,,0,0,0,0,,,0,0,0,0,MSFT
2024-10-22 13:22:55.459390829+00:00,10,39,10888,A,A,1,422.0,2000,130,203027,106226,419.7,420.8,2,2000,1,1,419.2,422.0,2000,2000,1,1,418.8,422.4,2000,2000,1,1,418.0,,2000,0,1,0,417.6,,2000,0,1,0,417.2,,2000,0,1,0,,,0,0,0,0,,,0,0,0,0,,,0,0,0,0,,,0,0,0,0,MSFT
2024-10-22 13:22:57.879535194+00:00,10,40,38,A,B,0,,0,194,203609,125991,,,0,0,0,0,,,0,0,0,0,,,0,0,0,0,,,0,0,0,0,,,0,0,0,0,,,0,0,0,0,,,0,0,0,0,,,0,0,0,0,,,0,0,0,0,,,0,0,0,0,AAPL
2024-10-22 13:22:57.879559513+00:00,10,40,38,A,A,0,234.3,200,194,203559,125992,,234.3,0,200,0,0,,,0,0,0,0,,,0,0,0,0,,,0,0,0,0,,,0,0,0,0,,,0,0,0,0,,,0,0,0,0,,,0,0,0,0,,,0,0,0,0,,,0,0,0,0,AAPL
2024-10-22 13:22:57.879700424+00:00,10,40,38,A,B,0,234.3,200,194,203818,125993,233.68,234.3,200,200,0,0,,,0,0,0,0,,,0,0,0,0,,,0,0,0,0,,,0,0,0,0,,,0,0,0,0,,,0,0,0,0,,,0,0,0,0,,,0,0,0,0,,,0,0,0,0,AAPL
2024-10-22 13:22:57.879709480+00:00,10,40,38,A,A,0,,0,194,203568,125994,233.68,,200,0,0,0,,,0,0,0,0,,,0,0,0,0,,,0,0,0,0,,,0,0,0,0,,,0,0,0,0,,,0,0,0,0,,,0,0,0,0,,,0,0,0,0,,,0,0,0,0,AAPL
2024-10-22 13:22:57.879821365+00:00,10,40,38,A,B,0,,0,194,203549,125995,,,0,0,0,0,,,0,0,0,0,,,0,0,0,0,,,0,0,0,0,,,0,0,0,0,,,0,0,0,0,,,0,0,0,0,,,0,0,0,0,,,0,0,0,0,,,0,0,0,0,AAPL
2024-10-22 13:22:57.879982507+00:00,10,41,38,A,B,0,,0,194,55706,315577,,,0,0,0,0,,,0,0,0,0,,,0,0,0,0,,,0,0,0,0,,,0,0,0,0,,,0,0,0,0,,,0,0,0,0,,,0,0,0,0,,,0,0,0,0,,,0,0,0,0,AAPL
2024-10-22 13:22:59.477112151+00:00,10,40,38,A,A,0,234.3,200,194,203970,126010,,234.3,0,200,0,0,,,0,0,0,0,,,0,0,0,0,,,0,0,0,0,,,0,0,0,0,,,0,0,0,0,,,0,0,0,0,,,0,0,0,0,,,0,0,0,0,,,0,0,0,0,AAPL
2024-10-22 13:22:59.477335459+00:00,10,41,38,A,A,0,234.25,200,194,56864,315643,,234.25,0,200,0,0,,,0,0,0,0,,,0,0,0,0,,,0,0,0,0,,,0,0,0,0,,,0,0,0,0,,,0,0,0,0,,,0,0,0,0,,,0,0,0,0,,,0,0,0,0,AAPL
2024-10-22 13:22:59.477290807+00:00,10,40,38,A,B,0,234.3,200,194,203543,126011,233.68,234.3,200,200,0,0,,,0,0,0,0,,,0,0,0,0,,,0,0,0,0,,,0,0,0,0,,,0,0,0,0,,,0,0,0,0,,,0,0,0,0,,,0,0,0,0,,,0,0,0,0,AAPL
2024-10-22 13:22:59.614276343+00:00,10,39,10888,C,B,0,419.7,2,130,203014,106248,419.2,420.8,2000,2000,1,1,418.8,422.0,2000,2000,1,1,418.0,422.4,2000,2000,1,1,417.6,,2000,0,1,0,417.2,,2000,0,1,0,,,0,0,0,0,,,0,0,0,0,,,0,0,0,0,,,0,0,0,0,,,0,0,0,0,MSFT
2024-10-22 13:22:59.630743602+00:00,10,41,38,A,A,0,,0,194,55385,315646,,,0,0,0,0,,,0,0,0,0,,,0,0,0,0,,,0,0,0,0,,,0,0,0,0,,,0,0,0,0,,,0,0,0,0,,,0,0,0,0,,,0,0,0,0,,,0,0,0,0,AAPL
2024-10-22 13:23:00.071257252+00:00,10,40,38,A,B,0,234.3,200,194,203483,126043,,234.3,0,200,0,0,,,0,0,0,0,,,0,0,0,0,,,0,0,0,0,,,0,0,0,0,,,0,0,0,0,,,0,0,0,0,,,0,0,0,0,,,0,0,0,0,,,0,0,0,0,AAPL
2024-10-22 13:23:00.071270328+00:00,10,40,38,A,A,0,,0,194,203522,126044,,,0,0,0,0,,,0,0,0,0,,,0,0,0,0,,,0,0,0,0,,,0,0,0,0,,,0,0,0,0,,,0,0,0,0,,,0,0,0,0,,,0,0,0,0,,,0,0,0,0,AAPL
2024-10-22 13:23:01.097342263+00:00,10,40,38,A,A,0,234.3,200,194,203658,126084,,234.3,0,200,0,0,,,0,0,0,0,,,0,0,0,0,,,0,0,0,0,,,0,0,0,0,,,0,0,0,0,,,0,0,0,0,,,0,0,0,0,,,0,0,0,0,,,0,0,0,0,AAPL
2024-10-22 13:23:01.097608143+00:00,10,41,38,A,A,0,234.25,200,194,55763,316029,,234.25,0,200,0,0,,,0,0,0,0,,,0,0,0,0,,,0,0,0,0,,,0,0,0,0,,,0,0,0,0,,,0,0,0,0,,,0,0,0,0,,,0,0,0,0,,,0,0,0,0,AAPL
2024-10-22 13:23:01.170210726+00:00,10,40,38,A,A,0,,0,194,203507,126086,,,0,0,0,0,,,0,0,0,0,,,0,0,0,0,,,0,0,0,0,,,0,0,0,0,,,0,0,0,0,,,0,0,0,0,,,0,0,0,0,,,0,0,0,0,,,0,0,0,0,AAPL
2024-10-22 13:23:01.170378648+00:00,10,41,38,A,A,0,,0,194,56126,316033,,,0,0,0,0,,,0,0,0,0,,,0,0,0,0,,,0,0,0,0,,,0,0,0,0,,,0,0,0,0,,,0,0,0,0,,,0,0,0,0,,,0,0,0,0,,,0,0,0,0,AAPL
2024-10-22 13:23:04.323424040+00:00,10,39,10888,A,A,1,421.6,2000,130,203198,106335,419.2,420.8,2000,2000,1,1,418.8,421.6,2000,2000,1,1,418.0,422.0,2000,2000,1,1,417.6,422.4,2000,2000,1,1,417.2,,2000,0,1,0,,,0,0,0,0,,,0,0,0,0,,,0,0,0,0,,,0,0,0,0,,,0,0,0,0,MSFT
2024-10-22 13:23:04.323589175+00:00,10,39,10888,C,A,2,422.0,2000,130,203072,106336,419.2,420.8,2000,2000,1,1,418.8,421.6,2000,2000,1,1,418.0,422.4,2000,2000,1,1,417.6,,2000,0,1,0,417.2,,2000,0,1,0,,,0,0,0,0,,,0,0,0,0,,,0,0,0,0,,,0,0,0,0,,,0,0,0,0,MSFT
2024-10-22 13:23:04.346773104+00:00,10,39,10888,A,A,2,422.0,2000,130,203092,106337,419.2,420.8,2000,2000,1,1,418.8,421.6,2000,2000,1,1,418.0,422.0,2000,2000,1,1,417.6,422.4,2000,2000,1,1,417.2,,2000,0,1,0,,,0,0,0,0,,,0,0,0,0,,,0,0,0,0,,,0,0,0,0,,,0,0,0,0,MSFT
2024-10-22 13:23:05.934398575+00:00,10,39,10888,A,B,0,419.9,2,130,203409,106343,419.9,420.8,2,2000,1,1,419.2,421.6,2000,2000,1,1,418.8,422.0,2000,2000,1,1,418.0,422.4,2000,2000,1,1,417.6,,2000,0,1,0,417.2,,2000,0,1,0,,,0,0,0,0,,,0,0,0,0,,,0,0,0,0,,,0,0,0,0,MSFT
2024-10-22 13:23:06.355421686+00:00,10,39,10888,A,B,3,418.4,2000,130,203298,106357,419.9,420.8,2,2000,1,1,419.2,421.6,2000,2000,1,1,418.8,422.0,2000,2000,1,1,418.4,422.4,2000,2000,1,1,418.0,,2000,0,1,0,417.6,,2000,0,1,0,417.2,,2000,0,1,0,,,0,0,0,0,,,0,0,0,0,,,0,0,0,0,MSFT
2024-10-22 13:23:07.732020759+00:00,10,40,38,A,B,0,,0,194,203543,126147,233.68,,200,0,0,0,,,0,0,0,0,,,0,0,0,0,,,0,0,0,0,,,0,0,0,0,,,0,0,0,0,,,0,0,0,0,,,0,0,0,0,,,0,0,0,0,,,0,0,0,0,AAPL
2024-10-22 13:23:07.732029189+00:00,10,40,38,A,A,0,234.3,200,194,203319,126148,233.68,234.3,200,200,0,0,,,0,0,0,0,,,0,0,0,0,,,0,0,0,0,,,0,0,0,0,,,0,0,0,0,,,0,0,0,0,,,0,0,0,0,,,0,0,0,0,,,0,0,0,0,AAPL
2024-10-22 13:23:07.732487881+00:00,10,41,38,A,B,0,,0,194,55671,316619,233.73,,200,0,0,0,,,0,0,0,0,,,0,0,0,0,,,0,0,0,0,,,0,0,0,0,,,0,0,0,0,,,0,0,0,0,,,0,0,0,0,,,0,0,0,0,,,0,0,0,0,AAPL
2024-10-22 13:23:07.732493642+00:00,10,41,38,A,A,0,234.25,200,194,55224,316620,233.73,234.25,200,200,0,0,,,0,0,0,0,,,0,0,0,0,,,0,0,0,0,,,0,0,0,0,,,0,0,0,0,,,0,0,0,0,,,0,0,0,0,,,0,0,0,0,,,0,0,0,0,AAPL
2024-10-22 13:23:07.935458493+00:00,10,41,38,A,B,0,234.25,200,194,60632,316631,,234.25,0,200,0,0,,,0,0,0,0,,,0,0,0,0,,,0,0,0,0,,,0,0,0,0,,,0,0,0,0,,,0,0,0,0,,,0,0,0,0,,,0,0,0,0,,,0,0,0,0,AAPL
2024-10-22 13:23:07.935466027+00:00,10,41,38,A,A,0,,0,194,61272,316632,,,0,0,0,0,,,0,0,0,0,,,0,0,0,0,,,0,0,0,0,,,0,0,0,0,,,0,0,0,0,,,0,0,0,0,,,0,0,0,0,,,0,0,0,0,,,0,0,0,0,AAPL
2024-10-22 13:23:08.277162456+00:00,10,41,38,A,A,0,234.25,200,194,55488,316647,,234.25,0,200,0,0,,,0,0,0,0,,,0,0,0,0,,,0,0,0,0,,,0,0,0,0,,,0,0,0,0,,,0,0,0,0,,,0,0,0,0,,,0,0,0,0,,,0,0,0,0,AAPL
2024-10-22 13:23:08.277168600+00:00,10,41,38,A,B,0,234.25,200,194,56852,316648,233.73,234.25,200,200,0,0,,,0,0,0,0,,,0,0,0,0,,,0,0,0,0,,,0,0,0,0,,,0,0,0,0,,,0,0,0,0,,,0,0,0,0,,,0,0,0,0,,,0,0,0,0,AAPL
2024-10-22 13:23:08.438512429+00:00,10,41,38,A,A,0,,0,194,63782,316663,233.73,,200,0,0,0,,,0,0,0,0,,,0,0,0,0,,,0,0,0,0,,,0,0,0,0,,,0,0,0,0,,,0,0,0,0,,,0,0,0,0,,,0,0,0,0,,,0,0,0,0,AAPL
2024-10-22 13:23:09.255981999+00:00,10,41,38,A,B,0,,0,194,55950,316725,,,0,0,0,0,,,0,0,0,0,,,0,0,0,0,,,0,0,0,0,,,0,0,0,0,,,0,0,0,0,,,0,0,0,0,,,0,0,0,0,,,0,0,0,0,,,0,0,0,0,AAPL
2024-10-22 13:23:09.256715970+00:00,10,41,38,A,A,0,234.25,200,194,54243,316730,,234.25,0,200,0,0,,,0,0,0,0,,,0,0,0,0,,,0,0,0,0,,,0,0,0,0,,,0,0,0,0,,,0,0,0,0,,,0,0,0,0,,,0,0,0,0,,,0,0,0,0,AAPL
2024-10-22 13:23:09.256921479+00:00,10,40,38,A,B,0,234.3,200,194,203260,126159,,234.3,0,200,0,0,,,0,0,0,0,,,0,0,0,0,,,0,0,0,0,,,0,0,0,0,,,0,0,0,0,,,0,0,0,0,,,0,0,0,0,,,0,0,0,0,,,0,0,0,0,AAPL
2024-10-22 13:23:09.257995547+00:00,10,40,38,A,A,0,,0,194,203178,126161,,,0,0,0,0,,,0,0,0,0,,,0,0,0,0,,,0,0,0,0,,,0,0,0,0,,,0,0,0,0,,,0,0,0,0,,,0,0,0,0,,,0,0,0,0,,,0,0,0,0,AAPL
2024-10-22 13:23:09.494846458+00:00,10,40,38,A,A,0,234.29,200,194,203262,126179,,234.29,0,200,0,0,,,0,0,0,0,,,0,0,0,0,,,0,0,0,0,,,0,0,0,0,,,0,0,0,0,,,0,0,0,0,,,0,0,0,0,,,0,0,0,0,,,0,0,0,0,AAPL
2024-10-22 13:23:10.141785194+00:00,10,40,38,A,B,0,234.29,200,194,203195,126186,233.68,234.29,200,200,0,0,,,0,0,0,0,,,0,0,0,0,,,0,0,0,0,,,0,0,0,0,,,0,0,0,0,,,0,0,0,0,,,0,0,0,0,,,0,0,0,0,,,0,0,0,0,AAPL
2024-10-22 13:23:10.142040946+00:00,10,41,38,A,B,0,234.25,200,194,54884,316803,233.73,234.25,200,200,0,0,,,0,0,0,0,,,0,0,0,0,,,0,0,0,0,,,0,0,0,0,,,0,0,0,0,,,0,0,0,0,,,0,0,0,0,,,0,0,0,0,,,0,0,0,0,AAPL
2024-10-22 13:23:10.218962298+00:00,10,39,10888,T,A,0,419.9,2,130,203572,106384,419.9,420.8,2,2000,1,1,419.2,421.6,2000,2000,1,1,418.8,422.0,2000,2000,1,1,418.4,422.4,2000,2000,1,1,418.0,,2000,0,1,0,417.6,,2000,0,1,0,417.2,,2000,0,1,0,,,0,0,0,0,,,0,0,0,0,,,0,0,0,0,MSFT
2024-10-22 13:23:10.218962298+00:00,10,39,10888,C,B,0,419.9,2,130,203572,106384,419.2,420.8,2000,2000,1,1,418.8,421.6,2000,2000,1,1,418.4,422.0,2000,2000,1,1,418.0,422.4,2000,2000,1,1,417.6,,2000,0,1,0,417.2,,2000,0,1,0,,,0,0,0,0,,,0,0,0,0,,,0,0,0,0,,,0,0,0,0,MSFT
2024-10-22 13:23:10.224203239+00:00,10,41,38,A,B,0,234.25,200,194,54780,316815,,234.25,0,200,0,0,,,0,0,0,0,,,0,0,0,0,,,0,0,0,0,,,0,0,0,0,,,0,0,0,0,,,0,0,0,0,,,0,0,0,0,,,0,0,0,0,,,0,0,0,0,AAPL
2024-10-22 13:23:10.271880149+00:00,10,40,38,A,B,0,234.29,200,194,203102,126199,,234.29,0,200,0,0,,,0,0,0,0,,,0,0,0,0,,,0,0,0,0,,,0,0,0,0,,,0,0,0,0,,,0,0,0,0,,,0,0,0,0,,,0,0,0,0,,,0,0,0,0,AAPL
2024-10-22 13:23:10.713868119+00:00,10,40,38,A,B,0,234.29,200,194,203055,126218,233.68,234.29,200,200,0,0,,,0,0,0,0,,,0,0,0,0,,,0,0,0,0,,,0,0,0,0,,,0,0,0,0,,,0,0,0,0,,,0,0,0,0,,,0,0,0,0,,,0,0,0,0,AAPL
2024-10-22 13:23:10.743604996+00:00,10,40,38,A,B,0,234.29,200,194,203170,126222,,234.29,0,200,0,0,,,0,0,0,0,,,0,0,0,0,,,0,0,0,0,,,0,0,0,0,,,0,0,0,0,,,0,0,0,0,,,0,0,0,0,,,0,0,0,0,,,0,0,0,0,AAPL
2024-10-22 13:23:10.876645239+00:00,10,40,38,A,B,0,234.29,200,194,203090,126227,233.68,234.29,200,200,0,0,,,0,0,0,0,,,0,0,0,0,,,0,0,0,0,,,0,0,0,0,,,0,0,0,0,,,0,0,0,0,,,0,0,0,0,,,0,0,0,0,,,0,0,0,0,AAPL
2024-10-22 13:23:11.425608633+00:00,10,41,38,A,B,0,234.25,200,194,60915,316931,233.73,234.25,200,200,0,0,,,0,0,0,0,,,0,0,0,0,,,0,0,0,0,,,0,0,0,0,,,0,0,0,0,,,0,0,0,0,,,0,0,0,0,,,0,0,0,0,,,0,0,0,0,AAPL
2024-10-22 13:23:11.555192030+00:00,10,40,38,A,B,0,234.29,200,194,203413,126234,,234.29,0,200,0,0,,,0,0,0,0,,,0,0,0,0,,,0,0,0,0,,,0,0,0,0,,,0,0,0,0,,,0,0,0,0,,,0,0,0,0,,,0,0,0,0,,,0,0,0,0,AAPL
2024-10-22 13:23:11.555566772+00:00,10,41,38,A,B,0,234.25,200,194,56262,316932,,234.25,0,200,0,0,,,0,0,0,0,,,0,0,0,0,,,0,0,0,0,,,0,0,0,0,,,0,0,0,0,,,0,0,0,0,,,0,0,0,0,,,0,0,0,0,,,0,0,0,0,AAPL
2024-10-22 13:23:11.922714797+00:00,10,39,10888,A,A,1,421.2,2000,130,204135,106392,419.2,420.8,2000,2000,1,1,418.8,421.2,2000,2000,1,1,418.4,421.6,2000,2000,1,1,418.0,422.0,2000,2000,1,1,417.6,422.4,2000,2000,1,1,417.2,,2000,0,1,0,,,0,0,0,0,,,0,0,0,0,,,0,0,0,0,,,0,0,0,0,MSFT
2024-10-22 13:23:11.923278286+00:00,10,39,10888,C,A,2,421.6,2000,130,203209,106393,419.2,420.8,2000,2000,1,1,418.8,421.2,2000,2000,1,1,418.4,422.0,2000,2000,1,1,418.0,422.4,2000,2000,1,1,417.6,,2000,0,1,0,417.2,,2000,0,1,0,,,0,0,0,0,,,0,0,0,0,,,0,0,0,0,,,0,0,0,0,MSFT
2024-10-22 13:23:12.856915397+00:00,10,39,10888,C,B,2,418.4,2000,130,203156,106415,419.2,420.8,2000,2000,1,1,418.8,421.2,2000,2000,1,1,418.0,422.0,2000,2000,1,1,417.6,422.4,2000,2000,1,1,417.2,,2000,0,1,0,,,0,0,0,0,,,0,0,0,0,,,0,0,0,0,,,0,0,0,0,,,0,0,0,0,MSFT
2024-10-22 13:23:12.857393931+00:00,10,39,10888,C,B,0,419.2,2000,130,203194,106416,418.8,420.8,2000,2000,1,1,418.0,421.2,2000,2000,1,1,417.6,422.0,2000,2000,1,1,417.2,422.4,2000,2000,1,1,,,0,0,0,0,,,0,0,0,0,,,0,0,0,0,,,0,0,0,0,,,0,0,0,0,,,0,0,0,0,MSFT
2024-10-22 13:23:12.867316827+00:00,10,39,10888,A,A,0,420.4,2000,130,203292,106417,418.8,420.4,2000,2000,1,1,418.0,420.8,2000,2000,1,1,417.6,421.2,2000,2000,1,1,417.2,422.0,2000,2000,1,1,,422.4,0,2000,0,1,,,0,0,0,0,,,0,0,0,0,,,0,0,0,0,,,0,0,0,0,,,0,0,0,0,MSFT
2024-10-22 13:23:12.867485015+00:00,10,39,10888,C,A,2,421.2,2000,130,203174,106418,418.8,420.4,2000,2000,1,1,418.0,420.8,2000,2000,1,1,417.6,422.0,2000,2000,1,1,417.2,422.4,2000,2000,1,1,,,0,0,0,0,,,0,0,0,0,,,0,0,0,0,,,0,0,0,0,,,0,0,0,0,,,0,0,0,0,MSFT
2024-10-22 13:23:12.878453409+00:00,10,39,10888,A,A,2,421.6,2000,130,203222,106419,418.8,420.4,2000,2000,1,1,418.0,420.8,2000,2000,1,1,417.6,421.6,2000,2000,1,1,417.2,422.0,2000,2000,1,1,,422.4,0,2000,0,1,,,0,0,0,0,,,0,0,0,0,,,0,0,0,0,,,0,0,0,0,,,0,0,0,0,MSFT
2024-10-22 13:23:12.893405436+00:00,10,39,10888,A,B,1,418.4,2000,130,203301,106420,418.8,420.4,2000,2000,1,1,418.4,420.8,2000,2000,1,1,418.0,421.6,2000,2000,1,1,417.6,422.0,2000,2000,1,1,417.2,422.4,2000,2000,1,1,,,0,0,0,0,,,0,0,0,0,,,0,0,0,0,,,0,0,0,0,,,0,0,0,0,MSFT
2024-10-22 13:23:13.206959062+00:00,10,39,10888,C,A,1,420.8,2000,130,203184,106429,418.8,420.4,2000,2000,1,1,418.4,421.6,2000,2000,1,1,418.0,422.0,2000,2000,1,1,417.6,422.4,2000,2000,1,1,417.2,,2000,0,1,0,,,0,0,0,0,,,0,0,0,0,,,0,0,0,0,,,0,0,0,0,,,0,0,0,0,MSFT
2024-10-22 13:23:13.207091160+00:00,10,39,10888,C,A,0,420.4,2000,130,203133,106430,418.8,421.6,2000,2000,1,1,418.4,422.0,2000,2000,1,1,418.0,422.4,2000,2000,1,1,417.6,,2000,0,1,0,417.2,,2000,0,1,0,,,0,0,0,0,,,0,0,0,0,,,0,0,0,0,,,0,0,0,0,,,0,0,0,0,MSFT
2024-10-22 13:23:13.219414962+00:00,10,39,10888,A,B,0,419.2,2000,130,203247,106432,419.2,421.6,2000,2000,1,1,418.8,422.0,2000,2000,1,1,418.4,422.4,2000,2000,1,1,418.0,,2000,0,1,0,417.6,,2000,0,1,0,417.2,,2000,0,1,0,,,0,0,0,0,,,0,0,0,0,,,0,0,0,0,,,0,0,0,0,MSFT
2024-10-22 13:23:13.225389097+00:00,10,39,10888,C,B,2,418.4,2000,130,203167,106433,419.2,421.6,2000,2000,1,1,418.8,422.0,2000,2000,1,1,418.0,422.4,2000,2000,1,1,417.6,,2000,0,1,0,417.2,,2000,0,1,0,,,0,0,0,0,,,0,0,0,0,,,0,0,0,0,,,0,0,0,0,,,0,0,0,0,MSFT
2024-10-22 13:23:13.225494942+00:00,10,39,10888,C,B,0,419.2,2000,130,203174,106434,418.8,421.6,2000,2000,1,1,418.0,422.0,2000,2000,1,1,417.6,422.4,2000,2000,1,1,417.2,,2000,0,1,0,,,0,0,0,0,,,0,0,0,0,,,0,0,0,0,,,0,0,0,0,,,0,0,0,0,,,0,0,0,0,MSFT
2024-10-22 13:23:13.236299524+00:00,10,39,10888,A,B,1,418.4,2000,130,203247,106435,418.8,421.6,2000,2000,1,1,418.4,422.0,2000,2000,1,1,418.0,422.4,2000,2000,1,1,417.6,,2000,0,1,0,417.2,,2000,0,1,0,,,0,0,0,0,,,0,0,0,0,,,0,0,0,0,,,0,0,0,0,,,0,0,0,0,MSFT
2024-10-22 13:23:13.245337121+00:00,10,39,10888,A,A,0,420.8,2000,130,203211,106436,418.8,420.8,2000,2000,1,1,418.4,421.6,2000,2000,1,1,418.0,422.0,2000,2000,1,1,417.6,422.4,2000,2000,1,1,417.2,,2000,0,1,0,,,0,0,0,0,,,0,0,0,0,,,0,0,0,0,,,0,0,0,0,,,0,0,0,0,MSFT
2024-10-22 13:23:16.454059512+00:00,10,39,10888,A,B,0,419.71,8,130,203301,106460,419.71,420.8,8,2000,1,1,418.8,421.6,2000,2000,1,1,418.4,422.0,2000,2000,1,1,418.0,422.4,2000,2000,1,1,417.6,,2000,0,1,0,417.2,,2000,0,1,0,,,0,0,0,0,,,0,0,0,0,,,0,0,0,0,,,0,0,0,0,MSFT
2024-10-22 13:23:17.271842368+00:00,10,40,38,A,B,0,234.29,200,194,203194,126299,233.68,234.29,200,200,0,0,,,0,0,0,0,,,0,0,0,0,,,0,0,0,0,,,0,0,0,0,,,0,0,0,0,,,0,0,0,0,,,0,0,0,0,,,0,0,0,0,,,0,0,0,0,AAPL
2024-10-22 13:23:17.272325969+00:00,10,41,38,A,B,0,234.25,200,194,55971,317342,233.73,234.25,200,200,0,0,,,0,0,0,0,,,0,0,0,0,,,0,0,0,0,,,0,0,0,0,,,0,0,0,0,,,0,0,0,0,,,0,0,0,0,,,0,0,0,0,,,0,0,0,0,AAPL
2024-10-22 13:23:17.375802233+00:00,10,41,38,A,B,0,234.25,200,194,55191,317347,,234.25,0,200,0,0,,,0,0,0,0,,,0,0,0,0,,,0,0,0,0,,,0,0,0,0,,,0,0,0,0,,,0,0,0,0,,,0,0,0,0,,,0,0,0,0,,,0,0,0,0,AAPL
2024-10-22 13:23:17.475710458+00:00,10,40,38,A,B,0,234.29,200,194,203229,126300,,234.29,0,200,0,0,,,0,0,0,0,,,0,0,0,0,,,0,0,0,0,,,0,0,0,0,,,0,0,0,0,,,0,0,0,0,,,0,0,0,0,,,0,0,0,0,,,0,0,0,0,AAPL
2024-10-22 13:23:17.917946937+00:00,10,40,38,A,B,0,234.29,200,194,203124,126309,233.68,234.29,200,200,0,0,,,0,0,0,0,,,0,0,0,0,,,0,0,0,0,,,0,0,0,0,,,0,0,0,0,,,0,0,0,0,,,0,0,0,0,,,0,0,0,0,,,0,0,0,0,AAPL
2024-10-22 13:23:18.186032405+00:00,10,39,10888,A,A,0,420.4,2000,130,203804,106467,419.71,420.4,8,2000,1,1,418.8,420.8,2000,2000,1,1,418.4,421.6,2000,2000,1,1,418.0,422.0,2000,2000,1,1,417.6,422.4,2000,2000,1,1,417.2,,2000,0,1,0,,,0,0,0,0,,,0,0,0,0,,,0,0,0,0,,,0,0,0,0,MSFT
2024-10-22 13:23:18.186320724+00:00,10,39,10888,C,A,1,420.8,2000,130,203312,106468,419.71,420.4,8,2000,1,1,418.8,421.6,2000,2000,1,1,418.4,422.0,2000,2000,1,1,418.0,422.4,2000,2000,1,1,417.6,,2000,0,1,0,417.2,,2000,0,1,0,,,0,0,0,0,,,0,0,0,0,,,0,0,0,0,,,0,0,0,0,MSFT
2024-10-22 13:23:18.197353241+00:00,10,39,10888,A,A,1,421.2,2000,130,203305,106469,419.71,420.4,8,2000,1,1,418.8,421.2,2000,2000,1,1,418.4,421.6,2000,2000,1,1,418.0,422.0,2000,2000,1,1,417.6,422.4,2000,2000,1,1,417.2,,2000,0,1,0,,,0,0,0,0,,,0,0,0,0,,,0,0,0,0,,,0,0,0,0,MSFT
2024-10-22 13:23:18.197783004+00:00,10,39,10888,C,A,2,421.6,2000,130,203219,106470,419.71,420.4,8,2000,1,1,418.8,421.2,2000,2000,1,1,418.4,422.0,2000,2000,1,1,418.0,422.4,2000,2000,1,1,417.6,,2000,0,1,0,417.2,,2000,0,1,0,,,0,0,0,0,,,0,0,0,0,,,0,0,0,0,,,0,0,0,0,MSFT
2024-10-22 13:23:18.709618972+00:00,10,39,10888,C,B,0,419.71,8,130,203380,106474,418.8,420.4,2000,2000,1,1,418.4,421.2,2000,2000,1,1,418.0,422.0,2000,2000,1,1,417.6,422.4,2000,2000,1,1,417.2,,2000,0,1,0,,,0,0,0,0,,,0,0,0,0,,,0,0,0,0,,,0,0,0,0,,,0,0,0,0,MSFT
2024-10-22 13:23:19.117777356+00:00,10,40,38,A,B,0,234.29,200,194,203426,126325,,234.29,0,200,0,0,,,0,0,0,0,,,0,0,0,0,,,0,0,0,0,,,0,0,0,0,,,0,0,0,0,,,0,0,0,0,,,0,0,0,0,,,0,0,0,0,,,0,0,0,0,AAPL
2024-10-22 13:23:19.664473220+00:00,10,40,38,A,B,0,234.29,200,194,203572,126327,233.68,234.29,200,200,0,0,,,0,0,0,0,,,0,0,0,0,,,0,0,0,0,,,0,0,0,0,,,0,0,0,0,,,0,0,0,0,,,0,0,0,0,,,0,0,0,0,,,0,0,0,0,AAPL
2024-10-22 13:23:19.664824048+00:00,10,41,38,A,B,0,234.25,200,194,170688,317460,233.73,234.25,200,200,0,0,,,0,0,0,0,,,0,0,0,0,,,0,0,0,0,,,0,0,0,0,,,0,0,0,0,,,0,0,0,0,,,0,0,0,0,,,0,0,0,0,,,0,0,0,0,AAPL
2024-10-22 13:23:19.741566478+00:00,10,41,38,A,B,0,234.25,200,194,55221,317478,,234.25,0,200,0,0,,,0,0,0,0,,,0,0,0,0,,,0,0,0,0,,,0,0,0,0,,,0,0,0,0,,,0,0,0,0,,,0,0,0,0,,,0,0,0,0,,,0,0,0,0,AAPL
2024-10-22 13:23:19.759928431+00:00,10,40,38,A,B,0,234.29,200,194,203193,126333,,234.29,0,200,0,0,,,0,0,0,0,,,0,0,0,0,,,0,0,0,0,,,0,0,0,0,,,0,0,0,0,,,0,0,0,0,,,0,0,0,0,,,0,0,0,0,,,0,0,0,0,AAPL
2024-10-22 13:23:20.003935662+00:00,10,40,38,A,A,0,,0,194,203354,126342,,,0,0,0,0,,,0,0,0,0,,,0,0,0,0,,,0,0,0,0,,,0,0,0,0,,,0,0,0,0,,,0,0,0,0,,,0,0,0,0,,,0,0,0,0,,,0,0,0,0,AAPL
2024-10-22 13:23:20.003959073+00:00,10,40,38,A,A,0,234.3,200,194,203228,126343,,234.3,0,200,0,0,,,0,0,0,0,,,0,0,0,0,,,0,0,0,0,,,0,0,0,0,,,0,0,0,0,,,0,0,0,0,,,0,0,0,0,,,0,0,0,0,,,0,0,0,0,AAPL
2024-10-22 13:23:20.004092127+00:00,10,40,38,A,B,0,234.3,200,194,203243,126345,233.68,234.3,200,200,0,0,,,0,0,0,0,,,0,0,0,0,,,0,0,0,0,,,0,0,0,0,,,0,0,0,0,,,0,0,0,0,,,0,0,0,0,,,0,0,0,0,,,0,0,0,0,AAPL
2024-10-22 13:23:20.198816197+00:00,10,40,38,A,B,0,234.3,200,194,203308,126348,,234.3,0,200,0,0,,,0,0,0,0,,,0,0,0,0,,,0,0,0,0,,,0,0,0,0,,,0,0,0,0,,,0,0,0,0,,,0,0,0,0,,,0,0,0,0,,,0,0,0,0,AAPL
2024-10-22 13:23:21.104833912+00:00,10,40,38,A,A,0,,0,194,203489,126354,,,0,0,0,0,,,0,0,0,0,,,0,0,0,0,,,0,0,0,0,,,0,0,0,0,,,0,0,0,0,,,0,0,0,0,,,0,0,0,0,,,0,0,0,0,,,0,0,0,0,AAPL
2024-10-22 13:23:21.105468186+00:00,10,41,38,A,A,0,,0,194,55611,317587,,,0,0,0,0,,,0,0,0,0,,,0,0,0,0,,,0,0,0,0,,,0,0,0,0,,,0,0,0,0,,,0,0,0,0,,,0,0,0,0,,,0,0,0,0,,,0,0,0,0,AAPL
2024-10-22 13:23:23.826651892+00:00,10,41,38,A,A,0,234.25,200,194,54479,317820,,234.25,0,200,0,0,,,0,0,0,0,,,0,0,0,0,,,0,0,0,0,,,0,0,0,0,,,0,0,0,0,,,0,0,0,0,,,0,0,0,0,,,0,0,0,0,,,0,0,0,0,AAPL
2024-10-22 13:23:24.820719386+00:00,10,41,38,A,A,0,,0,194,54981,317946,,,0,0,0,0,,,0,0,0,0,,,0,0,0,0,,,0,0,0,0,,,0,0,0,0,,,0,0,0,0,,,0,0,0,0,,,0,0,0,0,,,0,0,0,0,,,0,0,0,0,AAPL
2024-10-22 13:23:25.071159523+00:00,10,40,38,A,B,0,,0,194,203415,126434,233.68,,200,0,0,0,,,0,0,0,0,,,0,0,0,0,,,0,0,0,0,,,0,0,0,0,,,0,0,0,0,,,0,0,0,0,,,0,0,0,0,,,0,0,0,0,,,0,0,0,0,AAPL
2024-10-22 13:23:25.071167907+00:00,10,40,38,A,A,0,234.3,200,194,203430,126435,233.68,234.3,200,200,0,0,,,0,0,0,0,,,0,0,0,0,,,0,0,0,0,,,0,0,0,0,,,0,0,0,0,,,0,0,0,0,,,0,0,0,0,,,0,0,0,0,,,0,0,0,0,AAPL
2024-10-22 13:23:25.071378121+00:00,10,41,38,A,B,0,,0,194,55546,317967,233.73,,200,0,0,0,,,0,0,0,0,,,0,0,0,0,,,0,0,0,0,,,0,0,0,0,,,0,0,0,0,,,0,0,0,0,,,0,0,0,0,,,0,0,0,0,,,0,0,0,0,AAPL
2024-10-22 13:23:25.071448105+00:00,10,41,38,A,A,0,234.25,200,194,56975,317968,233.73,234.25,200,200,0,0,,,0,0,0,0,,,0,0,0,0,,,0,0,0,0,,,0,0,0,0,,,0,0,0,0,,,0,0,0,0,,,0,0,0,0,,,0,0,0,0,,,0,0,0,0,AAPL
2024-10-22 13:23:25.074077517+00:00,10,41,38,A,B,0,234.25,200,194,54560,317975,,234.25,0,200,0,0,,,0,0,0,0,,,0,0,0,0,,,0,0,0,0,,,0,0,0,0,,,0,0,0,0,,,0,0,0,0,,,0,0,0,0,,,0,0,0,0,,,0,0,0,0,AAPL
2024-10-22 13:23:25.179758230+00:00,10,40,38,A,B,0,234.3,200,194,203412,126439,,234.3,0,200,0,0,,,0,0,0,0,,,0,0,0,0,,,0,0,0,0,,,0,0,0,0,,,0,0,0,0,,,0,0,0,0,,,0,0,0,0,,,0,0,0,0,,,0,0,0,0,AAPL
2024-10-22 13:23:25.476162072+00:00,10,41,38,A,A,0,,0,194,60338,318003,,,0,0,0,0,,,0,0,0,0,,,0,0,0,0,,,0,0,0,0,,,0,0,0,0,,,0,0,0,0,,,0,0,0,0,,,0,0,0,0,,,0,0,0,0,,,0,0,0,0,AAPL
2024-10-22 13:23:25.576903830+00:00,10,41,38,A,A,0,234.25,200,194,55193,318007,,234.25,0,200,0,0,,,0,0,0,0,,,0,0,0,0,,,0,0,0,0,,,0,0,0,0,,,0,0,0,0,,,0,0,0,0,,,0,0,0,0,,,0,0,0,0,,,0,0,0,0,AAPL
2024-10-22 13:23:25.996393846+00:00,10,40,38,A,B,0,234.3,200,194,203465,126441,233.67,234.3,200,200,0,0,,,0,0,0,0,,,0,0,0,0,,,0,0,0,0,,,0,0,0,0,,,0,0,0,0,,,0,0,0,0,,,0,0,0,0,,,0,0,0,0,,,0,0,0,0,AAPL
2024-10-22 13:23:25.996918747+00:00,10,41,38,A,B,0,234.25,200,194,55418,318025,233.72,234.25,200,200,0,0,,,0,0,0,0,,,0,0,0,0,,,0,0,0,0,,,0,0,0,0,,,0,0,0,0,,,0,0,0,0,,,0,0,0,0,,,0,0,0,0,,,0,0,0,0,AAPL
2024-10-22 13:23:26.053590289+00:00,10,41,38,A,B,0,234.25,200,194,55601,318026,,234.25,0,200,0,0,,,0,0,0,0,,,0,0,0,0,,,0,0,0,0,,,0,0,0,0,,,0,0,0,0,,,0,0,0,0,,,0,0,0,0,,,0,0,0,0,,,0,0,0,0,AAPL
2024-10-22 13:23:26.165764563+00:00,10,40,38,A,B,0,234.3,200,194,203622,126443,,234.3,0,200,0,0,,,0,0,0,0,,,0,0,0,0,,,0,0,0,0,,,0,0,0,0,,,0,0,0,0,,,0,0,0,0,,,0,0,0,0,,,0,0,0,0,,,0,0,0,0,AAPL
2024-10-22 13:23:28.596356206+00:00,10,40,38,A,A,0,,0,194,203786,126461,,,0,0,0,0,,,0,0,0,0,,,0,0,0,0,,,0,0,0,0,,,0,0,0,0,,,0,0,0,0,,,0,0,0,0,,,0,0,0,0,,,0,0,0,0,,,0,0,0,0,AAPL
2024-10-22 13:23:28.845537399+00:00,10,39,10888,A,A,1,420.8,2000,130,203875,106582,418.8,420.4,2000,2000,1,1,418.4,420.8,2000,2000,1,1,418.0,421.2,2000,2000,1,1,417.6,422.0,2000,2000,1,1,417.2,422.4,2000,2000,1,1,,,0,0,0,0,,,0,0,0,0,,,0,0,0,0,,,0,0,0,0,,,0,0,0,0,MSFT
2024-10-22 13:23:28.846091984+00:00,10,39,10888,C,A,2,421.2,2000,130,203632,106583,418.8,420.4,2000,2000,1,1,418.4,420.8,2000,2000,1,1,418.0,422.0,2000,2000,1,1,417.6,422.4,2000,2000,1,1,417.2,,2000,0,1,0,,,0,0,0,0,,,0,0,0,0,,,0,0,0,0,,,0,0,0,0,,,0,0,0,0,MSFT
2024-10-22 13:23:28.857844527+00:00,10,39,10888,A,A,2,421.6,2000,130,203702,106584,418.8,420.4,2000,2000,1,1,418.4,420.8,2000,2000,1,1,418.0,421.6,2000,2000,1,1,417.6,422.0,2000,2000,1,1,417.2,422.4,2000,2000,1,1,,,0,0,0,0,,,0,0,0,0,,,0,0,0,0,,,0,0,0,0,,,0,0,0,0,MSFT
2024-10-22 13:23:29.988901509+00:00,10,40,38,A,A,0,234.3,200,194,203841,126474,,234.3,0,200,0,0,,,0,0,0,0,,,0,0,0,0,,,0,0,0,0,,,0,0,0,0,,,0,0,0,0,,,0,0,0,0,,,0,0,0,0,,,0,0,0,0,,,0,0,0,0,AAPL
2024-10-22 13:23:29.988991055+00:00,10,40,38,A,B,0,234.3,200,194,203750,126475,233.67,234.3,200,200,0,0,,,0,0,0,0,,,0,0,0,0,,,0,0,0,0,,,0,0,0,0,,,0,0,0,0,,,0,0,0,0,,,0,0,0,0,,,0,0,0,0,,,0,0,0,0,AAPL
2024-10-22 13:23:30.194298665+00:00,10,40,38,A,B,0,234.3,200,194,203704,126482,,234.3,0,200,0,0,,,0,0,0,0,,,0,0,0,0,,,0,0,0,0,,,0,0,0,0,,,0,0,0,0,,,0,0,0,0,,,0,0,0,0,,,0,0,0,0,,,0,0,0,0,AAPL
2024-10-22 13:23:30.379170133+00:00,10,41,38,A,B,0,234.25,200,194,56774,318242,233.73,234.25,200,200,0,0,,,0,0,0,0,,,0,0,0,0,,,0,0,0,0,,,0,0,0,0,,,0,0,0,0,,,0,0,0,0,,,0,0,0,0,,,0,0,0,0,,,0,0,0,0,AAPL
2024-10-22 13:23:30.615538271+00:00,10,40,38,A,B,0,234.3,200,194,203675,126493,233.68,234.3,200,200,0,0,,,0,0,0,0,,,0,0,0,0,,,0,0,0,0,,,0,0,0,0,,,0,0,0,0,,,0,0,0,0,,,0,0,0,0,,,0,0,0,0,,,0,0,0,0,AAPL
2024-10-22 13:23:30.768324931+00:00,10,41,38,A,B,0,234.25,200,194,55833,318256,,234.25,0,200,0,0,,,0,0,0,0,,,0,0,0,0,,,0,0,0,0,,,0,0,0,0,,,0,0,0,0,,,0,0,0,0,,,0,0,0,0,,,0,0,0,0,,,0,0,0,0,AAPL
2024-10-22 13:23:30.908547345+00:00,10,41,38,A,B,0,234.25,200,194,55543,318264,233.73,234.25,200,200,0,0,,,0,0,0,0,,,0,0,0,0,,,0,0,0,0,,,0,0,0,0,,,0,0,0,0,,,0,0,0,0,,,0,0,0,0,,,0,0,0,0,,,0,0,0,0,AAPL
2024-10-22 13:23:32.144148784+00:00,10,41,38,A,A,0,,0,194,55455,318334,233.73,,200,0,0,0,,,0,0,0,0,,,0,0,0,0,,,0,0,0,0,,,0,0,0,0,,,0,0,0,0,,,0,0,0,0,,,0,0,0,0,,,0,0,0,0,,,0,0,0,0,AAPL
2024-10-22 13:23:35.477412388+00:00,10,39,10888,C,A,1,420.8,2000,130,203276,106606,418.8,420.4,2000,2000,1,1,418.4,421.6,2000,2000,1,1,418.0,422.0,2000,2000,1,1,417.6,422.4,2000,2000,1,1,417.2,,2000,0,1,0,,,0,0,0,0,,,0,0,0,0,,,0,0,0,0,,,0,0,0,0,,,0,0,0,0,MSFT
2024-10-22 13:23:35.477577618+00:00,10,39,10888,C,A,0,420.4,2000,130,203156,106607,418.8,421.6,2000,2000,1,1,418.4,422.0,2000,2000,1,1,418.0,422.4,2000,2000,1,1,417.6,,2000,0,1,0,417.2,,2000,0,1,0,,,0,0,0,0,,,0,0,0,0,,,0,0,0,0,,,0,0,0,0,,,0,0,0,0,MSFT
2024-10-22 13:23:35.513397088+00:00,10,39,10888,A,A,0,420.8,2000,130,203230,106608,418.8,420.8,2000,2000,1,1,418.4,421.6,2000,2000,1,1,418.0,422.0,2000,2000,1,1,417.6,422.4,2000,2000,1,1,417.2,,2000,0,1,0,,,0,0,0,0,,,0,0,0,0,,,0,0,0,0,,,0,0,0,0,,,0,0,0,0,MSFT
2024-10-22 13:23:35.524181845+00:00,10,39,10888,A,A,1,421.2,2000,130,203166,106609,418.8,420.8,2000,2000,1,1,418.4,421.2,2000,2000,1,1,418.0,421.6,2000,2000,1,1,417.6,422.0,2000,2000,1,1,417.2,422.4,2000,2000,1,1,,,0,0,0,0,,,0,0,0,0,,,0,0,0,0,,,0,0,0,0,,,0,0,0,0,MSFT
2024-10-22 13:23:35.524615507+00:00,10,39,10888,C,A,2,421.6,2000,130,203047,106610,418.8,420.8,2000,2000,1,1,418.4,421.2,2000,2000,1,1,418.0,422.0,2000,2000,1,1,417.6,422.4,2000,2000,1,1,417.2,,2000,0,1,0,,,0,0,0,0,,,0,0,0,0,,,0,0,0,0,,,0,0,0,0,,,0,0,0,0,MSFT
2024-10-22 13:23:35.614736496+00:00,10,41,38,A,A,0,234.25,200,194,55792,318516,233.73,234.25,200,200,0,0,,,0,0,0,0,,,0,0,0,0,,,0,0,0,0,,,0,0,0,0,,,0,0,0,0,,,0,0,0,0,,,0,0,0,0,,,0,0,0,0,,,0,0,0,0,AAPL
2024-10-22 13:23:35.807855307+00:00,10,41,38,A,A,0,,0,194,55566,318520,233.73,,200,0,0,0,,,0,0,0,0,,,0,0,0,0,,,0,0,0,0,,,0,0,0,0,,,0,0,0,0,,,0,0,0,0,,,0,0,0,0,,,0,0,0,0,,,0,0,0,0,AAPL
2024-10-22 13:23:35.847544144+00:00,10,41,38,A,A,0,234.25,200,194,55411,318524,233.73,234.25,200,200,0,0,,,0,0,0,0,,,0,0,0,0,,,0,0,0,0,,,0,0,0,0,,,0,0,0,0,,,0,0,0,0,,,0,0,0,0,,,0,0,0,0,,,0,0,0,0,AAPL
2024-10-22 13:23:36.017646967+00:00,10,41,38,A,A,0,,0,194,55726,318541,233.73,,200,0,0,0,,,0,0,0,0,,,0,0,0,0,,,0,0,0,0,,,0,0,0,0,,,0,0,0,0,,,0,0,0,0,,,0,0,0,0,,,0,0,0,0,,,0,0,0,0,AAPL
2024-10-22 13:23:36.319231779+00:00,10,40,38,A,A,0,,0,194,203624,126535,233.68,,200,0,0,0,,,0,0,0,0,,,0,0,0,0,,,0,0,0,0,,,0,0,0,0,,,0,0,0,0,,,0,0,0,0,,,0,0,0,0,,,0,0,0,0,,,0,0,0,0,AAPL
2024-10-22 13:23:37.653199105+00:00,10,40,38,A,A,0,234.3,200,194,203871,126539,233.68,234.3,200,200,0,0,,,0,0,0,0,,,0,0,0,0,,,0,0,0,0,,,0,0,0,0,,,0,0,0,0,,,0,0,0,0,,,0,0,0,0,,,0,0,0,0,,,0,0,0,0,AAPL
2024-10-22 13:23:37.653675848+00:00,10,41,38,A,A,0,234.25,200,194,55651,318645,233.73,234.25,200,200,0,0,,,0,0,0,0,,,0,0,0,0,,,0,0,0,0,,,0,0,0,0,,,0,0,0,0,,,0,0,0,0,,,0,0,0,0,,,0,0,0,0,,,0,0,0,0,AAPL
2024-10-22 13:23:37.721357976+00:00,10,39,10888,A,A,0,420.4,2000,130,203191,106628,418.8,420.4,2000,2000,1,1,418.4,420.8,2000,2000,1,1,418.0,421.2,2000,2000,1,1,417.6,422.0,2000,2000,1,1,417.2,422.4,2000,2000,1,1,,,0,0,0,0,,,0,0,0,0,,,0,0,0,0,,,0,0,0,0,,,0,0,0,0,MSFT
2024-10-22 13:23:37.721554537+00:00,10,39,10888,C,A,1,420.8,2000,130,203091,106629,418.8,420.4,2000,2000,1,1,418.4,421.2,2000,2000,1,1,418.0,422.0,2000,2000,1,1,417.6,422.4,2000,2000,1,1,417.2,,2000,0,1,0,,,0,0,0,0,,,0,0,0,0,,,0,0,0,0,,,0,0,0,0,,,0,0,0,0,MSFT
2024-10-22 13:23:37.738790270+00:00,10,39,10888,C,A,0,420.4,2000,130,203089,106632,418.8,421.2,2000,2000,1,1,418.4,422.0,2000,2000,1,1,418.0,422.4,2000,2000,1,1,417.6,,2000,0,1,0,417.2,,2000,0,1,0,,,0,0,0,0,,,0,0,0,0,,,0,0,0,0,,,0,0,0,0,,,0,0,0,0,MSFT
2024-10-22 13:23:37.749692818+00:00,10,39,10888,A,A,0,420.8,2000,130,203138,106633,418.8,420.8,2000,2000,1,1,418.4,421.2,2000,2000,1,1,418.0,422.0,2000,2000,1,1,417.6,422.4,2000,2000,1,1,417.2,,2000,0,1,0,,,0,0,0,0,,,0,0,0,0,,,0,0,0,0,,,0,0,0,0,,,0,0,0,0,MSFT
2024-10-22 13:23:37.854920465+00:00,10,40,38,A,A,0,,0,194,203553,126544,233.68,,200,0,0,0,,,0,0,0,0,,,0,0,0,0,,,0,0,0,0,,,0,0,0,0,,,0,0,0,0,,,0,0,0,0,,,0,0,0,0,,,0,0,0,0,,,0,0,0,0,AAPL
2024-10-22 13:23:37.855135007+00:00,10,41,38,A,A,0,,0,194,55311,318656,233.73,,200,0,0,0,,,0,0,0,0,,,0,0,0,0,,,0,0,0,0,,,0,0,0,0,,,0,0,0,0,,,0,0,0,0,,,0,0,0,0,,,0,0,0,0,,,0,0,0,0,AAPL
2024-10-22 13:23:38.232433551+00:00,10,40,38,A,B,0,,0,194,203667,126548,,,0,0,0,0,,,0,0,0,0,,,0,0,0,0,,,0,0,0,0,,,0,0,0,0,,,0,0,0,0,,,0,0,0,0,,,0,0,0,0,,,0,0,0,0,,,0,0,0,0,AAPL
2024-10-22 13:23:38.232677207+00:00,10,41,38,A,B,0,,0,194,55848,318667,,,0,0,0,0,,,0,0,0,0,,,0,0,0,0,,,0,0,0,0,,,0,0,0,0,,,0,0,0,0,,,0,0,0,0,,,0,0,0,0,,,0,0,0,0,,,0,0,0,0,AAPL
2024-10-22 13:23:39.675360348+00:00,10,40,38,A,A,0,234.3,200,194,203633,126564,,234.3,0,200,0,0,,,0,0,0,0,,,0,0,0,0,,,0,0,0,0,,,0,0,0,0,,,0,0,0,0,,,0,0,0,0,,,0,0,0,0,,,0,0,0,0,,,0,0,0,0,AAPL
2024-10-22 13:23:39.675575197+00:00,10,41,38,A,A,0,234.25,200,194,55433,318781,,234.25,0,200,0,0,,,0,0,0,0,,,0,0,0,0,,,0,0,0,0,,,0,0,0,0,,,0,0,0,0,,,0,0,0,0,,,0,0,0,0,,,0,0,0,0,,,0,0,0,0,AAPL
2024-10-22 13:23:39.820494147+00:00,10,40,38,A,A,0,,0,194,203554,126570,,,0,0,0,0,,,0,0,0,0,,,0,0,0,0,,,0,0,0,0,,,0,0,0,0,,,0,0,0,0,,,0,0,0,0,,,0,0,0,0,,,0,0,0,0,,,0,0,0,0,AAPL
2024-10-22 13:23:39.820734241+00:00,10,41,38,A,A,0,,0,194,55454,318799,,,0,0,0,0,,,0,0,0,0,,,0,0,0,0,,,0,0,0,0,,,0,0,0,0,,,0,0,0,0,,,0,0,0,0,,,0,0,0,0,,,0,0,0,0,,,0,0,0,0,AAPL
2024-10-22 13:23:40.167861636+00:00,10,40,38,A,A,0,234.3,200,194,203709,126576,,234.3,0,200,0,0,,,0,0,0,0,,,0,0,0,0,,,0,0,0,0,,,0,0,0,0,,,0,0,0,0,,,0,0,0,0,,,0,0,0,0,,,0,0,0,0,,,0,0,0,0,AAPL
2024-10-22 13:23:40.168129325+00:00,10,41,38,A,A,0,234.25,200,194,55803,318818,,234.25,0,200,0,0,,,0,0,0,0,,,0,0,0,0,,,0,0,0,0,,,0,0,0,0,,,0,0,0,0,,,0,0,0,0,,,0,0,0,0,,,0,0,0,0,,,0,0,0,0,AAPL
2024-10-22 13:23:40.346181122+00:00,10,40,38,A,A,0,,0,194,203722,126577,,,0,0,0,0,,,0,0,0,0,,,0,0,0,0,,,0,0,0,0,,,0,0,0,0,,,0,0,0,0,,,0,0,0,0,,,0,0,0,0,,,0,0,0,0,,,0,0,0,0,AAPL
2024-10-22 13:23:41.360852677+00:00,10,40,38,A,A,0,234.3,200,194,203744,126590,,234.3,0,200,0,0,,,0,0,0,0,,,0,0,0,0,,,0,0,0,0,,,0,0,0,0,,,0,0,0,0,,,0,0,0,0,,,0,0,0,0,,,0,0,0,0,,,0,0,0,0,AAPL
2024-10-22 13:23:41.360969260+00:00,10,40,38,A,B,0,234.3,200,194,203813,126591,233.69,234.3,200,200,0,0,,,0,0,0,0,,,0,0,0,0,,,0,0,0,0,,,0,0,0,0,,,0,0,0,0,,,0,0,0,0,,,0,0,0,0,,,0,0,0,0,,,0,0,0,0,AAPL
2024-10-22 13:23:43.276421109+00:00,10,40,38,A,B,0,234.3,200,194,203910,126630,,234.3,0,200,0,0,,,0,0,0,0,,,0,0,0,0,,,0,0,0,0,,,0,0,0,0,,,0,0,0,0,,,0,0,0,0,,,0,0,0,0,,,0,0,0,0,,,0,0,0,0,AAPL
2024-10-22 13:23:44.134257547+00:00,10,40,10888,A,A,0,419.87,100,194,204092,126636,,419.87,0,100,0,0,,,0,0,0,0,,,0,0,0,0,,,0,0,0,0,,,0,0,0,0,,,0,0,0,0,,,0,0,0,0,,,0,0,0,0,,,0,0,0,0,,,0,0,0,0,MSFT
2024-10-22 13:23:44.369250269+00:00,10,40,38,A,A,0,,0,194,204032,126641,,,0,0,0,0,,,0,0,0,0,,,0,0,0,0,,,0,0,0,0,,,0,0,0,0,,,0,0,0,0,,,0,0,0,0,,,0,0,0,0,,,0,0,0,0,,,0,0,0,0,AAPL
2024-10-22 13:23:44.733357836+00:00,10,39,10888,A,A,0,420.4,2000,130,203182,106694,418.8,420.4,2000,2000,1,1,418.4,420.8,2000,2000,1,1,418.0,421.2,2000,2000,1,1,417.6,422.0,2000,2000,1,1,417.2,422.4,2000,2000,1,1,,,0,0,0,0,,,0,0,0,0,,,0,0,0,0,,,0,0,0,0,,,0,0,0,0,MSFT
2024-10-22 13:23:44.733526809+00:00,10,39,10888,C,A,1,420.8,2000,130,203026,106695,418.8,420.4,2000,2000,1,1,418.4,421.2,2000,2000,1,1,418.0,422.0,2000,2000,1,1,417.6,422.4,2000,2000,1,1,417.2,,2000,0,1,0,,,0,0,0,0,,,0,0,0,0,,,0,0,0,0,,,0,0,0,0,,,0,0,0,0,MSFT
2024-10-22 13:23:44.744764047+00:00,10,39,10888,A,A,2,421.6,2000,130,203097,106696,418.8,420.4,2000,2000,1,1,418.4,421.2,2000,2000,1,1,418.0,421.6,2000,2000,1,1,417.6,422.0,2000,2000,1,1,417.2,422.4,2000,2000,1,1,,,0,0,0,0,,,0,0,0,0,,,0,0,0,0,,,0,0,0,0,,,0,0,0,0,MSFT
2024-10-22 13:23:47.048851451+00:00,10,40,38,A,A,0,234.3,200,194,203996,126657,,234.3,0,200,0,0,,,0,0,0,0,,,0,0,0,0,,,0,0,0,0,,,0,0,0,0,,,0,0,0,0,,,0,0,0,0,,,0,0,0,0,,,0,0,0,0,,,0,0,0,0,AAPL
2024-10-22 13:23:47.186867465+00:00,10,40,38,A,A,0,,0,194,203921,126658,,,0,0,0,0,,,0,0,0,0,,,0,0,0,0,,,0,0,0,0,,,0,0,0,0,,,0,0,0,0,,,0,0,0,0,,,0,0,0,0,,,0,0,0,0,,,0,0,0,0,AAPL
2024-10-22 13:23:52.165381950+00:00,10,40,10888,A,A,0,,0,194,204111,126739,,,0,0,0,0,,,0,0,0,0,,,0,0,0,0,,,0,0,0,0,,,0,0,0,0,,,0,0,0,0,,,0,0,0,0,,,0,0,0,0,,,0,0,0,0,,,0,0,0,0,MSFT
2024-10-22 13:23:54.091006910+00:00,10,40,38,A,A,0,234.3,200,194,204418,126786,,234.3,0,200,0,0,,,0,0,0,0,,,0,0,0,0,,,0,0,0,0,,,0,0,0,0,,,0,0,0,0,,,0,0,0,0,,,0,0,0,0,,,0,0,0,0,,,0,0,0,0,AAPL
2024-10-22 13:23:54.940849941+00:00,10,40,38,A,B,0,234.3,200,194,204484,126791,233.69,234.3,200,200,0,0,,,0,0,0,0,,,0,0,0,0,,,0,0,0,0,,,0,0,0,0,,,0,0,0,0,,,0,0,0,0,,,0,0,0,0,,,0,0,0,0,,,0,0,0,0,AAPL
2024-10-22 13:23:54.940893759+00:00,10,39,10888,A,A,1,420.8,2000,130,203448,106793,418.8,420.4,2000,2000,1,1,418.4,420.8,2000,2000,1,1,418.0,421.2,2000,2000,1,1,417.6,421.6,2000,2000,1,1,417.2,422.0,2000,2000,1,1,,422.4,0,2000,0,1,,,0,0,0,0,,,0,0,0,0,,,0,0,0,0,,,0,0,0,0,MSFT
2024-10-22 13:23:54.941143045+00:00,10,39,10888,C,A,2,421.2,2000,130,203415,106794,418.8,420.4,2000,2000,1,1,418.4,420.8,2000,2000,1,1,418.0,421.6,2000,2000,1,1,417.6,422.0,2000,2000,1,1,417.2,422.4,2000,2000,1,1,,,0,0,0,0,,,0,0,0,0,,,0,0,0,0,,,0,0,0,0,,,0,0,0,0,MSFT
2024-10-22 13:23:54.960642145+00:00,10,39,10888,C,A,1,420.8,2000,130,203444,106795,418.8,420.4,2000,2000,1,1,418.4,421.6,2000,2000,1,1,418.0,422.0,2000,2000,1,1,417.6,422.4,2000,2000,1,1,417.2,,2000,0,1,0,,,0,0,0,0,,,0,0,0,0,,,0,0,0,0,,,0,0,0,0,,,0,0,0,0,MSFT
2024-10-22 13:23:54.986579395+00:00,10,39,10888,A,A,1,421.2,2000,130,203424,106796,418.8,420.4,2000,2000,1,1,418.4,421.2,2000,2000,1,1,418.0,421.6,2000,2000,1,1,417.6,422.0,2000,2000,1,1,417.2,422.4,2000,2000,1,1,,,0,0,0,0,,,0,0,0,0,,,0,0,0,0,,,0,0,0,0,,,0,0,0,0,MSFT
2024-10-22 13:23:55.076346173+00:00,10,40,38,A,B,0,234.3,200,194,204233,126796,,234.3,0,200,0,0,,,0,0,0,0,,,0,0,0,0,,,0,0,0,0,,,0,0,0,0,,,0,0,0,0,,,0,0,0,0,,,0,0,0,0,,,0,0,0,0,,,0,0,0,0,AAPL
2024-10-22 13:23:56.559102864+00:00,10,40,38,A,B,0,234.3,200,194,205342,126820,233.69,234.3,200,200,0,0,,,0,0,0,0,,,0,0,0,0,,,0,0,0,0,,,0,0,0,0,,,0,0,0,0,,,0,0,0,0,,,0,0,0,0,,,0,0,0,0,,,0,0,0,0,AAPL
2024-10-22 13:23:56.760724843+00:00,10,40,38,A,B,0,234.3,200,194,204544,126821,,234.3,0,200,0,0,,,0,0,0,0,,,0,0,0,0,,,0,0,0,0,,,0,0,0,0,,,0,0,0,0,,,0,0,0,0,,,0,0,0,0,,,0,0,0,0,,,0,0,0,0,AAPL
2024-10-22 13:23:57.365442711+00:00,10,40,38,A,A,0,,0,194,204444,126829,,,0,0,0,0,,,0,0,0,0,,,0,0,0,0,,,0,0,0,0,,,0,0,0,0,,,0,0,0,0,,,0,0,0,0,,,0,0,0,0,,,0,0,0,0,,,0,0,0,0,AAPL
2024-10-22 13:23:57.568636662+00:00,10,40,38,A,A,0,234.3,200,194,204553,126835,,234.3,0,200,0,0,,,0,0,0,0,,,0,0,0,0,,,0,0,0,0,,,0,0,0,0,,,0,0,0,0,,,0,0,0,0,,,0,0,0,0,,,0,0,0,0,,,0,0,0,0,AAPL
2024-10-22 13:23:58.631526357+00:00,10,40,38,A,A,0,,0,194,204362,126854,,,0,0,0,0,,,0,0,0,0,,,0,0,0,0,,,0,0,0,0,,,0,0,0,0,,,0,0,0,0,,,0,0,0,0,,,0,0,0,0,,,0,0,0,0,,,0,0,0,0,AAPL
2024-10-22 13:24:00.019597993+00:00,10,41,38,A,A,0,,0,194,60400,319961,,,0,0,0,0,,,0,0,0,0,,,0,0,0,0,,,0,0,0,0,,,0,0,0,0,,,0,0,0,0,,,0,0,0,0,,,0,0,0,0,,,0,0,0,0,,,0,0,0,0,AAPL
2024-10-22 13:24:03.715641433+00:00,10,41,38,A,A,0,234.25,200,194,55641,320649,,234.25,0,200,0,0,,,0,0,0,0,,,0,0,0,0,,,0,0,0,0,,,0,0,0,0,,,0,0,0,0,,,0,0,0,0,,,0,0,0,0,,,0,0,0,0,,,0,0,0,0,AAPL
2024-10-22 13:24:04.077864232+00:00,10,41,38,A,A,0,,0,194,55469,320664,,,0,0,0,0,,,0,0,0,0,,,0,0,0,0,,,0,0,0,0,,,0,0,0,0,,,0,0,0,0,,,0,0,0,0,,,0,0,0,0,,,0,0,0,0,,,0,0,0,0,AAPL
2024-10-22 13:24:05.488919948+00:00,10,41,38,A,A,0,234.25,200,194,55814,320749,,234.25,0,200,0,0,,,0,0,0,0,,,0,0,0,0,,,0,0,0,0,,,0,0,0,0,,,0,0,0,0,,,0,0,0,0,,,0,0,0,0,,,0,0,0,0,,,0,0,0,0,AAPL
2024-10-22 13:24:10.217266665+00:00,10,40,38,A,A,0,234.3,200,194,204094,127120,,234.3,0,200,0,0,,,0,0,0,0,,,0,0,0,0,,,0,0,0,0,,,0,0,0,0,,,0,0,0,0,,,0,0,0,0,,,0,0,0,0,,,0,0,0,0,,,0,0,0,0,AAPL
2024-10-22 13:24:10.217457605+00:00,10,40,38,A,B,0,234.3,200,194,204131,127121,233.68,234.3,200,200,0,0,,,0,0,0,0,,,0,0,0,0,,,0,0,0,0,,,0,0,0,0,,,0,0,0,0,,,0,0,0,0,,,0,0,0,0,,,0,0,0,0,,,0,0,0,0,AAPL
2024-10-22 13:24:10.217591677+00:00,10,40,38,A,B,0,234.3,200,194,204007,127122,,234.3,0,200,0,0,,,0,0,0,0,,,0,0,0,0,,,0,0,0,0,,,0,0,0,0,,,0,0,0,0,,,0,0,0,0,,,0,0,0,0,,,0,0,0,0,,,0,0,0,0,AAPL
2024-10-22 13:24:10.247323461+00:00,10,40,38,A,A,0,,0,194,204013,127127,,,0,0,0,0,,,0,0,0,0,,,0,0,0,0,,,0,0,0,0,,,0,0,0,0,,,0,0,0,0,,,0,0,0,0,,,0,0,0,0,,,0,0,0,0,,,0,0,0,0,AAPL
2024-10-22 13:24:11.023552303+00:00,10,41,38,A,A,0,,0,194,55973,321276,,,0,0,0,0,,,0,0,0,0,,,0,0,0,0,,,0,0,0,0,,,0,0,0,0,,,0,0,0,0,,,0,0,0,0,,,0,0,0,0,,,0,0,0,0,,,0,0,0,0,AAPL
2024-10-22 13:24:12.509557047+00:00,10,41,38,A,A,0,234.25,200,194,55333,321450,,234.25,0,200,0,0,,,0,0,0,0,,,0,0,0,0,,,0,0,0,0,,,0,0,0,0,,,0,0,0,0,,,0,0,0,0,,,0,0,0,0,,,0,0,0,0,,,0,0,0,0,AAPL
2024-10-22 13:24:13.167212658+00:00,10,40,38,A,A,0,234.3,200,194,203759,127192,,234.3,0,200,0,0,,,0,0,0,0,,,0,0,0,0,,,0,0,0,0,,,0,0,0,0,,,0,0,0,0,,,0,0,0,0,,,0,0,0,0,,,0,0,0,0,,,0,0,0,0,AAPL
2024-10-22 13:24:13.168523578+00:00,10,40,38,A,A,0,,0,194,203765,127194,,,0,0,0,0,,,0,0,0,0,,,0,0,0,0,,,0,0,0,0,,,0,0,0,0,,,0,0,0,0,,,0,0,0,0,,,0,0,0,0,,,0,0,0,0,,,0,0,0,0,AAPL
2024-10-22 13:24:13.745021013+00:00,10,40,38,A,A,0,234.3,200,194,203583,127210,,234.3,0,200,0,0,,,0,0,0,0,,,0,0,0,0,,,0,0,0,0,,,0,0,0,0,,,0,0,0,0,,,0,0,0,0,,,0,0,0,0,,,0,0,0,0,,,0,0,0,0,AAPL
2024-10-22 13:24:13.745165749+00:00,10,40,38,A,B,0,234.3,200,194,203613,127211,233.67,234.3,200,200,0,0,,,0,0,0,0,,,0,0,0,0,,,0,0,0,0,,,0,0,0,0,,,0,0,0,0,,,0,0,0,0,,,0,0,0,0,,,0,0,0,0,,,0,0,0,0,AAPL
2024-10-22 13:24:13.851694097+00:00,10,40,38,A,B,0,234.3,200,194,203730,127212,,234.3,0,200,0,0,,,0,0,0,0,,,0,0,0,0,,,0,0,0,0,,,0,0,0,0,,,0,0,0,0,,,0,0,0,0,,,0,0,0,0,,,0,0,0,0,,,0,0,0,0,AAPL
2024-10-22 13:24:16.220742627+00:00,10,40,38,A,B,0,234.3,200,194,203520,127261,233.67,234.3,200,200,0,0,,,0,0,0,0,,,0,0,0,0,,,0,0,0,0,,,0,0,0,0,,,0,0,0,0,,,0,0,0,0,,,0,0,0,0,,,0,0,0,0,,,0,0,0,0,AAPL
2024-10-22 13:24:16.322506326+00:00,10,40,38,A,B,0,234.3,200,194,203499,127263,,234.3,0,200,0,0,,,0,0,0,0,,,0,0,0,0,,,0,0,0,0,,,0,0,0,0,,,0,0,0,0,,,0,0,0,0,,,0,0,0,0,,,0,0,0,0,,,0,0,0,0,AAPL
2024-10-22 13:24:16.841854157+00:00,10,39,10888,A,A,1,420.8,2000,130,204332,106955,418.8,420.4,2000,2000,1,1,418.4,420.8,2000,2000,1,1,418.0,421.2,2000,2000,1,1,417.6,421.6,2000,2000,1,1,417.2,422.0,2000,2000,1,1,,422.4,0,2000,0,1,,,0,0,0,0,,,0,0,0,0,,,0,0,0,0,,,0,0,0,0,MSFT
2024-10-22 13:24:16.842121623+00:00,10,39,10888,C,A,2,421.2,2000,130,204244,106956,418.8,420.4,2000,2000,1,1,418.4,420.8,2000,2000,1,1,418.0,421.6,2000,2000,1,1,417.6,422.0,2000,2000,1,1,417.2,422.4,2000,2000,1,1,,,0,0,0,0,,,0,0,0,0,,,0,0,0,0,,,0,0,0,0,,,0,0,0,0,MSFT
2024-10-22 13:24:19.204149179+00:00,10,39,10888,C,A,1,420.8,2000,130,204330,106983,418.8,420.4,2000,2000,1,1,418.4,421.6,2000,2000,1,1,418.0,422.0,2000,2000,1,1,417.6,422.4,2000,2000,1,1,417.2,,2000,0,1,0,,,0,0,0,0,,,0,0,0,0,,,0,0,0,0,,,0,0,0,0,,,0,0,0,0,MSFT
2024-10-22 13:24:19.215348690+00:00,10,39,10888,A,A,1,420.8,2000,130,204310,106984,418.8,420.4,2000,2000,1,1,418.4,420.8,2000,2000,1,1,418.0,421.6,2000,2000,1,1,417.6,422.0,2000,2000,1,1,417.2,422.4,2000,2000,1,1,,,0,0,0,0,,,0,0,0,0,,,0,0,0,0,,,0,0,0,0,,,0,0,0,0,MSFT
2024-10-22 13:24:19.541458562+00:00,10,39,10888,C,A,1,420.8,2000,130,204338,106986,418.8,420.4,2000,2000,1,1,418.4,421.6,2000,2000,1,1,418.0,422.0,2000,2000,1,1,417.6,422.4,2000,2000,1,1,417.2,,2000,0,1,0,,,0,0,0,0,,,0,0,0,0,,,0,0,0,0,,,0,0,0,0,,,0,0,0,0,MSFT
2024-10-22 13:24:19.541728423+00:00,10,39,10888,C,A,0,420.4,2000,130,204153,106987,418.8,421.6,2000,2000,1,1,418.4,422.0,2000,2000,1,1,418.0,422.4,2000,2000,1,1,417.6,,2000,0,1,0,417.2,,2000,0,1,0,,,0,0,0,0,,,0,0,0,0,,,0,0,0,0,,,0,0,0,0,,,0,0,0,0,MSFT
2024-10-22 13:24:19.553334385+00:00,10,39,10888,A,A,0,420.4,2000,130,204263,106988,418.8,420.4,2000,2000,1,1,418.4,421.6,2000,2000,1,1,418.0,422.0,2000,2000,1,1,417.6,422.4,2000,2000,1,1,417.2,,2000,0,1,0,,,0,0,0,0,,,0,0,0,0,,,0,0,0,0,,,0,0,0,0,,,0,0,0,0,MSFT
2024-10-22 13:24:19.564289541+00:00,10,39,10888,A,A,1,421.2,2000,130,204266,106989,418.8,420.4,2000,2000,1,1,418.4,421.2,2000,2000,1,1,418.0,421.6,2000,2000,1,1,417.6,422.0,2000,2000,1,1,417.2,422.4,2000,2000,1,1,,,0,0,0,0,,,0,0,0,0,,,0,0,0,0,,,0,0,0,0,,,0,0,0,0,MSFT
2024-10-22 13:24:19.564459260+00:00,10,39,10888,C,A,2,421.6,2000,130,204210,106990,418.8,420.4,2000,2000,1,1,418.4,421.2,2000,2000,1,1,418.0,422.0,2000,2000,1,1,417.6,422.4,2000,2000,1,1,417.2,,2000,0,1,0,,,0,0,0,0,,,0,0,0,0,,,0,0,0,0,,,0,0,0,0,,,0,0,0,0,MSFT
2024-10-22 13:24:19.585279087+00:00,10,39,10888,A,B,0,419.2,2000,130,204252,106991,419.2,420.4,2000,2000,1,1,418.8,421.2,2000,2000,1,1,418.4,422.0,2000,2000,1,1,418.0,422.4,2000,2000,1,1,417.6,,2000,0,1,0,417.2,,2000,0,1,0,,,0,0,0,0,,,0,0,0,0,,,0,0,0,0,,,0,0,0,0,MSFT
2024-10-22 13:24:21.863790793+00:00,10,40,38,A,B,0,234.3,200,194,203298,127400,233.67,234.3,200,200,0,0,,,0,0,0,0,,,0,0,0,0,,,0,0,0,0,,,0,0,0,0,,,0,0,0,0,,,0,0,0,0,,,0,0,0,0,,,0,0,0,0,,,0,0,0,0,AAPL
2024-10-22 13:24:21.864772955+00:00,10,41,38,A,B,0,234.25,200,194,55505,322212,233.72,234.25,200,200,0,0,,,0,0,0,0,,,0,0,0,0,,,0,0,0,0,,,0,0,0,0,,,0,0,0,0,,,0,0,0,0,,,0,0,0,0,,,0,0,0,0,,,0,0,0,0,AAPL
2024-10-22 13:24:21.864841763+00:00,10,41,38,A,B,0,234.25,200,194,55842,322213,,234.25,0,200,0,0,,,0,0,0,0,,,0,0,0,0,,,0,0,0,0,,,0,0,0,0,,,0,0,0,0,,,0,0,0,0,,,0,0,0,0,,,0,0,0,0,,,0,0,0,0,AAPL
2024-10-22 13:24:22.041953629+00:00,10,40,38,A,B,0,234.3,200,194,203395,127408,,234.3,0,200,0,0,,,0,0,0,0,,,0,0,0,0,,,0,0,0,0,,,0,0,0,0,,,0,0,0,0,,,0,0,0,0,,,0,0,0,0,,,0,0,0,0,,,0,0,0,0,AAPL
2024-10-22 13:24:24.961319532+00:00,10,40,38,A,B,0,234.3,200,194,203463,127452,233.65,234.3,200,200,0,0,,,0,0,0,0,,,0,0,0,0,,,0,0,0,0,,,0,0,0,0,,,0,0,0,0,,,0,0,0,0,,,0,0,0,0,,,0,0,0,0,,,0,0,0,0,AAPL
2024-10-22 13:24:24.961687905+00:00,10,41,38,A,B,0,234.25,200,194,60862,322476,233.7,234.25,200,200,0,0,,,0,0,0,0,,,0,0,0,0,,,0,0,0,0,,,0,0,0,0,,,0,0,0,0,,,0,0,0,0,,,0,0,0,0,,,0,0,0,0,,,0,0,0,0,AAPL
2024-10-22 13:24:25.062328508+00:00,10,41,38,A,B,0,234.25,200,194,55206,322482,,234.25,0,200,0,0,,,0,0,0,0,,,0,0,0,0,,,0,0,0,0,,,0,0,0,0,,,0,0,0,0,,,0,0,0,0,,,0,0,0,0,,,0,0,0,0,,,0,0,0,0,AAPL
2024-10-22 13:24:25.161960226+00:00,10,40,38,A,B,0,234.3,200,194,203304,127455,,234.3,0,200,0,0,,,0,0,0,0,,,0,0,0,0,,,0,0,0,0,,,0,0,0,0,,,0,0,0,0,,,0,0,0,0,,,0,0,0,0,,,0,0,0,0,,,0,0,0,0,AAPL
2024-10-22 13:24:26.530573464+00:00,10,40,38,A,B,0,234.3,200,194,203400,127469,233.65,234.3,200,200,0,0,,,0,0,0,0,,,0,0,0,0,,,0,0,0,0,,,0,0,0,0,,,0,0,0,0,,,0,0,0,0,,,0,0,0,0,,,0,0,0,0,,,0,0,0,0,AAPL
2024-10-22 13:24:26.530877970+00:00,10,41,38,A,B,0,234.25,200,194,56155,322603,233.7,234.25,200,200,0,0,,,0,0,0,0,,,0,0,0,0,,,0,0,0,0,,,0,0,0,0,,,0,0,0,0,,,0,0,0,0,,,0,0,0,0,,,0,0,0,0,,,0,0,0,0,AAPL
2024-10-22 13:24:26.733538127+00:00,10,40,38,A,B,0,234.3,200,194,203706,127475,,234.3,0,200,0,0,,,0,0,0,0,,,0,0,0,0,,,0,0,0,0,,,0,0,0,0,,,0,0,0,0,,,0,0,0,0,,,0,0,0,0,,,0,0,0,0,,,0,0,0,0,AAPL
2024-10-22 13:24:26.733707643+00:00,10,41,38,A,B,0,234.25,200,194,55184,322629,,234.25,0,200,0,0,,,0,0,0,0,,,0,0,0,0,,,0,0,0,0,,,0,0,0,0,,,0,0,0,0,,,0,0,0,0,,,0,0,0,0,,,0,0,0,0,,,0,0,0,0,AAPL
2024-10-22 13:24:27.931064488+00:00,10,40,38,A,B,0,234.3,200,194,203393,127490,233.65,234.3,200,200,0,0,,,0,0,0,0,,,0,0,0,0,,,0,0,0,0,,,0,0,0,0,,,0,0,0,0,,,0,0,0,0,,,0,0,0,0,,,0,0,0,0,,,0,0,0,0,AAPL
2024-10-22 13:24:28.136352609+00:00,10,40,38,A,B,0,234.3,200,194,203478,127494,,234.3,0,200,0,0,,,0,0,0,0,,,0,0,0,0,,,0,0,0,0,,,0,0,0,0,,,0,0,0,0,,,0,0,0,0,,,0,0,0,0,,,0,0,0,0,,,0,0,0,0,AAPL
2024-10-22 13:24:29.718786188+00:00,10,40,38,A,B,0,234.3,200,194,203622,127505,233.65,234.3,200,200,0,0,,,0,0,0,0,,,0,0,0,0,,,0,0,0,0,,,0,0,0,0,,,0,0,0,0,,,0,0,0,0,,,0,0,0,0,,,0,0,0,0,,,0,0,0,0,AAPL
2024-10-22 13:24:29.920968807+00:00,10,40,38,A,B,0,234.3,200,194,203649,127507,,234.3,0,200,0,0,,,0,0,0,0,,,0,0,0,0,,,0,0,0,0,,,0,0,0,0,,,0,0,0,0,,,0,0,0,0,,,0,0,0,0,,,0,0,0,0,,,0,0,0,0,AAPL
2024-10-22 13:24:33.183073392+00:00,10,40,38,A,B,0,234.3,200,194,203778,127547,233.65,234.3,200,200,0,0,,,0,0,0,0,,,0,0,0,0,,,0,0,0,0,,,0,0,0,0,,,0,0,0,0,,,0,0,0,0,,,0,0,0,0,,,0,0,0,0,,,0,0,0,0,AAPL
2024-10-22 13:24:38.169489147+00:00,10,39,38,C,B,1,233.4,2000,130,204093,72889,233.6,234.4,2000,2000,1,1,233.2,234.6,2000,2000,1,1,233.0,234.8,2000,2000,1,1,,,0,0,0,0,,,0,0,0,0,,,0,0,0,0,,,0,0,0,0,,,0,0,0,0,,,0,0,0,0,,,0,0,0,0,AAPL
2024-10-22 13:24:38.204456423+00:00,10,39,38,A,B,1,233.4,2000,130,203957,72890,233.6,234.4,2000,2000,1,1,233.4,234.6,2000,2000,1,1,233.2,234.8,2000,2000,1,1,233.0,,2000,0,1,0,,,0,0,0,0,,,0,0,0,0,,,0,0,0,0,,,0,0,0,0,,,0,0,0,0,,,0,0,0,0,AAPL
2024-10-22 13:24:38.204777269+00:00,10,41,38,A,B,0,234.25,200,194,55930,323420,233.7,234.25,200,200,0,0,,,0,0,0,0,,,0,0,0,0,,,0,0,0,0,,,0,0,0,0,,,0,0,0,0,,,0,0,0,0,,,0,0,0,0,,,0,0,0,0,,,0,0,0,0,AAPL
2024-10-22 13:24:38.218327287+00:00,10,41,38,A,B,0,234.25,200,194,55637,323423,,234.25,0,200,0,0,,,0,0,0,0,,,0,0,0,0,,,0,0,0,0,,,0,0,0,0,,,0,0,0,0,,,0,0,0,0,,,0,0,0,0,,,0,0,0,0,,,0,0,0,0,AAPL
2024-10-22 13:24:38.376357888+00:00,10,40,38,A,B,0,234.3,200,194,204290,127579,,234.3,0,200,0,0,,,0,0,0,0,,,0,0,0,0,,,0,0,0,0,,,0,0,0,0,,,0,0,0,0,,,0,0,0,0,,,0,0,0,0,,,0,0,0,0,,,0,0,0,0,AAPL
2024-10-22 13:24:40.360619411+00:00,10,40,38,A,B,0,234.3,200,194,204244,127598,233.65,234.3,200,200,0,0,,,0,0,0,0,,,0,0,0,0,,,0,0,0,0,,,0,0,0,0,,,0,0,0,0,,,0,0,0,0,,,0,0,0,0,,,0,0,0,0,,,0,0,0,0,AAPL
2024-10-22 13:24:40.390941645+00:00,10,41,38,A,B,0,234.25,200,194,55787,323579,233.7,234.25,200,200,0,0,,,0,0,0,0,,,0,0,0,0,,,0,0,0,0,,,0,0,0,0,,,0,0,0,0,,,0,0,0,0,,,0,0,0,0,,,0,0,0,0,,,0,0,0,0,AAPL
2024-10-22 13:24:40.465642175+00:00,10,41,38,A,B,0,234.25,200,194,55627,323594,,234.25,0,200,0,0,,,0,0,0,0,,,0,0,0,0,,,0,0,0,0,,,0,0,0,0,,,0,0,0,0,,,0,0,0,0,,,0,0,0,0,,,0,0,0,0,,,0,0,0,0,AAPL
2024-10-22 13:24:40.566905993+00:00,10,41,38,A,B,0,234.25,200,194,55124,323603,233.7,234.25,200,200,0,0,,,0,0,0,0,,,0,0,0,0,,,0,0,0,0,,,0,0,0,0,,,0,0,0,0,,,0,0,0,0,,,0,0,0,0,,,0,0,0,0,,,0,0,0,0,AAPL
2024-10-22 13:24:40.595760826+00:00,10,41,38,A,B,0,234.25,200,194,55384,323605,,234.25,0,200,0,0,,,0,0,0,0,,,0,0,0,0,,,0,0,0,0,,,0,0,0,0,,,0,0,0,0,,,0,0,0,0,,,0,0,0,0,,,0,0,0,0,,,0,0,0,0,AAPL
2024-10-22 13:24:41.391671515+00:00,10,41,38,A,B,0,234.25,200,194,55234,323652,233.7,234.25,200,200,0,0,,,0,0,0,0,,,0,0,0,0,,,0,0,0,0,,,0,0,0,0,,,0,0,0,0,,,0,0,0,0,,,0,0,0,0,,,0,0,0,0,,,0,0,0,0,AAPL
2024-10-22 13:24:41.506940306+00:00,10,41,38,A,B,0,234.25,200,194,55387,323654,,234.25,0,200,0,0,,,0,0,0,0,,,0,0,0,0,,,0,0,0,0,,,0,0,0,0,,,0,0,0,0,,,0,0,0,0,,,0,0,0,0,,,0,0,0,0,,,0,0,0,0,AAPL
2024-10-22 13:24:41.850622674+00:00,10,40,38,A,B,0,234.3,200,194,203225,127618,,234.3,0,200,0,0,,,0,0,0,0,,,0,0,0,0,,,0,0,0,0,,,0,0,0,0,,,0,0,0,0,,,0,0,0,0,,,0,0,0,0,,,0,0,0,0,,,0,0,0,0,AAPL
2024-10-22 13:24:43.224489514+00:00,10,40,38,A,B,0,234.3,200,194,203320,127637,233.65,234.3,200,200,0,0,,,0,0,0,0,,,0,0,0,0,,,0,0,0,0,,,0,0,0,0,,,0,0,0,0,,,0,0,0,0,,,0,0,0,0,,,0,0,0,0,,,0,0,0,0,AAPL
2024-10-22 13:24:43.224729449+00:00,10,41,38,A,B,0,234.25,200,194,55824,323758,233.7,234.25,200,200,0,0,,,0,0,0,0,,,0,0,0,0,,,0,0,0,0,,,0,0,0,0,,,0,0,0,0,,,0,0,0,0,,,0,0,0,0,,,0,0,0,0,,,0,0,0,0,AAPL
2024-10-22 13:24:43.428552683+00:00,10,40,38,A,B,0,234.3,200,194,203303,127641,,234.3,0,200,0,0,,,0,0,0,0,,,0,0,0,0,,,0,0,0,0,,,0,0,0,0,,,0,0,0,0,,,0,0,0,0,,,0,0,0,0,,,0,0,0,0,,,0,0,0,0,AAPL
2024-10-22 13:24:43.428792015+00:00,10,41,38,A,B,0,234.25,200,194,60435,323763,,234.25,0,200,0,0,,,0,0,0,0,,,0,0,0,0,,,0,0,0,0,,,0,0,0,0,,,0,0,0,0,,,0,0,0,0,,,0,0,0,0,,,0,0,0,0,,,0,0,0,0,AAPL
2024-10-22 13:24:43.918969072+00:00,10,39,10888,C,A,0,420.4,2000,130,204061,107205,419.2,421.2,2000,2000,1,1,418.8,422.0,2000,2000,1,1,418.4,422.4,2000,2000,1,1,418.0,,2000,0,1,0,417.6,,2000,0,1,0,417.2,,2000,0,1,0,,,0,0,0,0,,,0,0,0,0,,,0,0,0,0,,,0,0,0,0,MSFT
2024-10-22 13:24:43.955344863+00:00,10,39,10888,A,A,0,420.4,2000,130,203940,107206,419.2,420.4,2000,2000,1,1,418.8,421.2,2000,2000,1,1,418.4,422.0,2000,2000,1,1,418.0,422.4,2000,2000,1,1,417.6,,2000,0,1,0,417.2,,2000,0,1,0,,,0,0,0,0,,,0,0,0,0,,,0,0,0,0,,,0,0,0,0,MSFT
2024-10-22 13:24:43.966562438+00:00,10,39,10888,A,A,1,420.8,2000,130,203869,107207,419.2,420.4,2000,2000,1,1,418.8,420.8,2000,2000,1,1,418.4,421.2,2000,2000,1,1,418.0,422.0,2000,2000,1,1,417.6,422.4,2000,2000,1,1,417.2,,2000,0,1,0,,,0,0,0,0,,,0,0,0,0,,,0,0,0,0,,,0,0,0,0,MSFT
2024-10-22 13:24:43.967284837+00:00,10,39,10888,C,A,2,421.2,2000,130,203800,107208,419.2,420.4,2000,2000,1,1,418.8,420.8,2000,2000,1,1,418.4,422.0,2000,2000,1,1,418.0,422.4,2000,2000,1,1,417.6,,2000,0,1,0,417.2,,2000,0,1,0,,,0,0,0,0,,,0,0,0,0,,,0,0,0,0,,,0,0,0,0,MSFT
2024-10-22 13:24:43.978038373+00:00,10,39,10888,A,A,2,421.6,2000,130,203769,107209,419.2,420.4,2000,2000,1,1,418.8,420.8,2000,2000,1,1,418.4,421.6,2000,2000,1,1,418.0,422.0,2000,2000,1,1,417.6,422.4,2000,2000,1,1,417.2,,2000,0,1,0,,,0,0,0,0,,,0,0,0,0,,,0,0,0,0,,,0,0,0,0,MSFT
2024-10-22 13:24:44.745236115+00:00,10,40,38,A,B,0,234.3,200,194,203343,127658,233.65,234.3,200,200,0,0,,,0,0,0,0,,,0,0,0,0,,,0,0,0,0,,,0,0,0,0,,,0,0,0,0,,,0,0,0,0,,,0,0,0,0,,,0,0,0,0,,,0,0,0,0,AAPL
2024-10-22 13:24:44.745720220+00:00,10,41,38,A,B,0,234.25,200,194,56035,323853,233.7,234.25,200,200,0,0,,,0,0,0,0,,,0,0,0,0,,,0,0,0,0,,,0,0,0,0,,,0,0,0,0,,,0,0,0,0,,,0,0,0,0,,,0,0,0,0,,,0,0,0,0,AAPL
2024-10-22 13:24:44.934438752+00:00,10,41,38,A,B,0,234.25,200,194,60863,323866,,234.25,0,200,0,0,,,0,0,0,0,,,0,0,0,0,,,0,0,0,0,,,0,0,0,0,,,0,0,0,0,,,0,0,0,0,,,0,0,0,0,,,0,0,0,0,,,0,0,0,0,AAPL
2024-10-22 13:24:45.300890939+00:00,10,39,10888,C,A,1,420.8,2000,130,204432,107218,419.2,420.4,2000,2000,1,1,418.8,421.6,2000,2000,1,1,418.4,422.0,2000,2000,1,1,418.0,422.4,2000,2000,1,1,417.6,,2000,0,1,0,417.2,,2000,0,1,0,,,0,0,0,0,,,0,0,0,0,,,0,0,0,0,,,0,0,0,0,MSFT
2024-10-22 13:24:45.301120042+00:00,10,39,10888,C,A,0,420.4,2000,130,203655,107219,419.2,421.6,2000,2000,1,1,418.8,422.0,2000,2000,1,1,418.4,422.4,2000,2000,1,1,418.0,,2000,0,1,0,417.6,,2000,0,1,0,417.2,,2000,0,1,0,,,0,0,0,0,,,0,0,0,0,,,0,0,0,0,,,0,0,0,0,MSFT
2024-10-22 13:24:45.338436748+00:00,10,39,10888,A,A,0,420.8,2000,130,203699,107222,419.2,420.8,2000,2000,1,1,418.8,421.6,2000,2000,1,1,418.4,422.0,2000,2000,1,1,418.0,422.4,2000,2000,1,1,417.6,,2000,0,1,0,417.2,,2000,0,1,0,,,0,0,0,0,,,0,0,0,0,,,0,0,0,0,,,0,0,0,0,MSFT
2024-10-22 13:24:45.338688229+00:00,10,39,10888,C,A,1,421.6,2000,130,203570,107223,419.2,420.8,2000,2000,1,1,418.8,422.0,2000,2000,1,1,418.4,422.4,2000,2000,1,1,418.0,,2000,0,1,0,417.6,,2000,0,1,0,417.2,,2000,0,1,0,,,0,0,0,0,,,0,0,0,0,,,0,0,0,0,,,0,0,0,0,MSFT
2024-10-22 13:24:46.042383729+00:00,10,39,10888,A,A,1,421.6,2000,130,203840,107230,419.2,420.8,2000,2000,1,1,418.8,421.6,2000,2000,1,1,418.4,422.0,2000,2000,1,1,418.0,422.4,2000,2000,1,1,417.6,,2000,0,1,0,417.2,,2000,0,1,0,,,0,0,0,0,,,0,0,0,0,,,0,0,0,0,,,0,0,0,0,MSFT
2024-10-22 13:24:46.319252579+00:00,10,40,38,A,B,0,234.3,200,194,203284,127688,,234.3,0,200,0,0,,,0,0,0,0,,,0,0,0,0,,,0,0,0,0,,,0,0,0,0,,,0,0,0,0,,,0,0,0,0,,,0,0,0,0,,,0,0,0,0,,,0,0,0,0,AAPL
2024-10-22 13:24:47.353353102+00:00,10,40,38,A,B,0,234.3,200,194,203319,127703,233.63,234.3,200,200,0,0,,,0,0,0,0,,,0,0,0,0,,,0,0,0,0,,,0,0,0,0,,,0,0,0,0,,,0,0,0,0,,,0,0,0,0,,,0,0,0,0,,,0,0,0,0,AAPL
2024-10-22 13:24:47.353598225+00:00,10,41,38,A,B,0,234.25,200,194,55739,324014,233.68,234.25,200,200,0,0,,,0,0,0,0,,,0,0,0,0,,,0,0,0,0,,,0,0,0,0,,,0,0,0,0,,,0,0,0,0,,,0,0,0,0,,,0,0,0,0,,,0,0,0,0,AAPL
2024-10-22 13:24:47.526907005+00:00,10,41,38,A,B,0,234.25,200,194,55580,324031,,234.25,0,200,0,0,,,0,0,0,0,,,0,0,0,0,,,0,0,0,0,,,0,0,0,0,,,0,0,0,0,,,0,0,0,0,,,0,0,0,0,,,0,0,0,0,,,0,0,0,0,AAPL
2024-10-22 13:24:49.311329839+00:00,10,40,38,A,B,0,234.3,200,194,202979,127725,,234.3,0,200,0,0,,,0,0,0,0,,,0,0,0,0,,,0,0,0,0,,,0,0,0,0,,,0,0,0,0,,,0,0,0,0,,,0,0,0,0,,,0,0,0,0,,,0,0,0,0,AAPL
2024-10-22 13:24:49.311350655+00:00,10,40,38,A,B,0,234.3,200,194,203013,127726,233.62,234.3,200,200,0,0,,,0,0,0,0,,,0,0,0,0,,,0,0,0,0,,,0,0,0,0,,,0,0,0,0,,,0,0,0,0,,,0,0,0,0,,,0,0,0,0,,,0,0,0,0,AAPL
2024-10-22 13:24:49.347940773+00:00,10,40,38,A,B,0,234.3,200,194,203004,127728,,234.3,0,200,0,0,,,0,0,0,0,,,0,0,0,0,,,0,0,0,0,,,0,0,0,0,,,0,0,0,0,,,0,0,0,0,,,0,0,0,0,,,0,0,0,0,,,0,0,0,0,AAPL
2024-10-22 13:24:55.690362611+00:00,10,40,38,A,B,0,234.3,200,194,203124,127816,233.61,234.3,200,200,0,0,,,0,0,0,0,,,0,0,0,0,,,0,0,0,0,,,0,0,0,0,,,0,0,0,0,,,0,0,0,0,,,0,0,0,0,,,0,0,0,0,,,0,0,0,0,AAPL
2024-10-22 13:24:55.690779335+00:00,10,40,38,A,B,0,234.3,200,194,203124,127817,,234.3,0,200,0,0,,,0,0,0,0,,,0,0,0,0,,,0,0,0,0,,,0,0,0,0,,,0,0,0,0,,,0,0,0,0,,,0,0,0,0,,,0,0,0,0,,,0,0,0,0,AAPL
2024-10-22 13:24:55.691091423+00:00,10,39,38,C,B,0,233.6,2000,130,203592,72973,233.4,234.4,2000,2000,1,1,233.2,234.6,2000,2000,1,1,233.0,234.8,2000,2000,1,1,,,0,0,0,0,,,0,0,0,0,,,0,0,0,0,,,0,0,0,0,,,0,0,0,0,,,0,0,0,0,,,0,0,0,0,AAPL
2024-10-22 13:24:55.694400436+00:00,10,41,38,A,B,0,234.25,200,194,55420,324635,233.64,234.25,200,200,0,0,,,0,0,0,0,,,0,0,0,0,,,0,0,0,0,,,0,0,0,0,,,0,0,0,0,,,0,0,0,0,,,0,0,0,0,,,0,0,0,0,,,0,0,0,0,AAPL
2024-10-22 13:24:55.697208780+00:00,10,41,38,A,B,0,234.25,200,194,54424,324637,,234.25,0,200,0,0,,,0,0,0,0,,,0,0,0,0,,,0,0,0,0,,,0,0,0,0,,,0,0,0,0,,,0,0,0,0,,,0,0,0,0,,,0,0,0,0,,,0,0,0,0,AAPL
2024-10-22 13:24:55.998829921+00:00,10,40,38,A,A,0,,0,194,203088,127821,,,0,0,0,0,,,0,0,0,0,,,0,0,0,0,,,0,0,0,0,,,0,0,0,0,,,0,0,0,0,,,0,0,0,0,,,0,0,0,0,,,0,0,0,0,,,0,0,0,0,AAPL
2024-10-22 13:24:55.998852599+00:00,10,40,38,A,A,0,234.15,200,194,203047,127822,,234.15,0,200,0,0,,,0,0,0,0,,,0,0,0,0,,,0,0,0,0,,,0,0,0,0,,,0,0,0,0,,,0,0,0,0,,,0,0,0,0,,,0,0,0,0,,,0,0,0,0,AAPL
2024-10-22 13:24:55.998983395+00:00,10,41,38,A,A,0,,0,194,55298,324662,,,0,0,0,0,,,0,0,0,0,,,0,0,0,0,,,0,0,0,0,,,0,0,0,0,,,0,0,0,0,,,0,0,0,0,,,0,0,0,0,,,0,0,0,0,,,0,0,0,0,AAPL
2024-10-22 13:24:55.998997975+00:00,10,41,38,A,A,0,234.1,200,194,54296,324663,,234.1,0,200,0,0,,,0,0,0,0,,,0,0,0,0,,,0,0,0,0,,,0,0,0,0,,,0,0,0,0,,,0,0,0,0,,,0,0,0,0,,,0,0,0,0,,,0,0,0,0,AAPL
2024-10-22 13:24:56.001969362+00:00,10,39,38,C,B,0,233.4,2000,130,203568,72985,233.2,234.4,2000,2000,1,1,233.0,234.6,2000,2000,1,1,,234.8,0,2000,0,1,,,0,0,0,0,,,0,0,0,0,,,0,0,0,0,,,0,0,0,0,,,0,0,0,0,,,0,0,0,0,,,0,0,0,0,AAPL
2024-10-22 13:24:56.001977339+00:00,10,39,38,C,A,0,234.6,2000,130,203785,72988,233.2,234.8,2000,2000,1,1,233.0,,2000,0,1,0,,,0,0,0,0,,,0,0,0,0,,,0,0,0,0,,,0,0,0,0,,,0,0,0,0,,,0,0,0,0,,,0,0,0,0,,,0,0,0,0,AAPL
2024-10-22 13:24:56.002003243+00:00,10,39,38,C,B,0,233.2,2000,130,203554,72989,233.0,234.8,2000,2000,1,1,,,0,0,0,0,,,0,0,0,0,,,0,0,0,0,,,0,0,0,0,,,0,0,0,0,,,0,0,0,0,,,0,0,0,0,,,0,0,0,0,,,0,0,0,0,AAPL
2024-10-22 13:24:56.002010604+00:00,10,39,38,C,N,0,234.8,2000,130,203678,72991,,,0,0,0,0,,,0,0,0,0,,,0,0,0,0,,,0,0,0,0,,,0,0,0,0,,,0,0,0,0,,,0,0,0,0,,,0,0,0,0,,,0,0,0,0,,,0,0,0,0,AAPL
2024-10-22 13:24:56.002288613+00:00,10,39,10888,C,A,2,422.0,2000,130,203971,107345,419.2,420.8,2000,2000,1,1,418.8,421.6,2000,2000,1,1,418.4,422.4,2000,2000,1,1,418.0,,2000,0,1,0,417.6,,2000,0,1,0,417.2,,2000,0,1,0,,,0,0,0,0,,,0,0,0,0,,,0,0,0,0,,,0,0,0,0,MSFT
2024-10-22 13:24:56.002291262+00:00,10,39,10888,C,N,0,420.8,2000,130,204225,107348,418.4,421.6,2000,2000,1,1,418.0,422.4,2000,2000,1,1,417.6,,2000,0,1,0,417.2,,2000,0,1,0,,,0,0,0,0,,,0,0,0,0,,,0,0,0,0,,,0,0,0,0,,,0,0,0,0,,,0,0,0,0,MSFT
2024-10-22 13:24:56.012932441+00:00,10,39,38,A,B,0,232.8,2000,130,203499,73023,232.8,,2000,0,1,0,,,0,0,0,0,,,0,0,0,0,,,0,0,0,0,,,0,0,0,0,,,0,0,0,0,,,0,0,0,0,,,0,0,0,0,,,0,0,0,0,,,0,0,0,0,AAPL
2024-10-22 13:24:56.012937395+00:00,10,39,38,A,A,0,235.0,2000,130,203616,73024,232.8,235.0,2000,2000,1,1,,,0,0,0,0,,,0,0,0,0,,,0,0,0,0,,,0,0,0,0,,,0,0,0,0,,,0,0,0,0,,,0,0,0,0,,,0,0,0,0,,,0,0,0,0,AAPL
2024-10-22 13:24:56.013145045+00:00,10,39,10888,A,A,2,422.8,2000,128,204261,107360,418.4,421.6,2000,2000,1,1,418.0,422.4,2000,2000,1,1,417.6,422.8,2000,2000,1,1,417.2,,2000,0,1,0,,,0,0,0,0,,,0,0,0,0,,,0,0,0,0,,,0,0,0,0,,,0,0,0,0,,,0,0,0,0,MSFT
2024-10-22 13:24:56.023857169+00:00,10,39,38,A,B,1,232.6,2000,130,203634,73040,232.8,235.0,2000,2000,1,1,232.6,,2000,0,1,0,,,0,0,0,0,,,0,0,0,0,,,0,0,0,0,,,0,0,0,0,,,0,0,0,0,,,0,0,0,0,,,0,0,0,0,,,0,0,0,0,AAPL
2024-10-22 13:24:56.023860584+00:00,10,39,38,A,A,1,235.2,2000,130,203631,73041,232.8,235.0,2000,2000,1,1,232.6,235.2,2000,2000,1,1,,,0,0,0,0,,,0,0,0,0,,,0,0,0,0,,,0,0,0,0,,,0,0,0,0,,,0,0,0,0,,,0,0,0,0,,,0,0,0,0,AAPL
2024-10-22 13:24:56.034794300+00:00,10,39,38,A,N,2,235.4,2000,130,203705,73052,232.8,235.0,2000,2000,1,1,232.6,235.2,2000,2000,1,1,232.4,235.4,2000,2000,1,1,,,0,0,0,0,,,0,0,0,0,,,0,0,0,0,,,0,0,0,0,,,0,0,0,0,,,0,0,0,0,,,0,0,0,0,AAPL
2024-10-22 13:24:56.711384014+00:00,10,39,10888,A,A,1,422.0,2000,130,204393,107386,418.4,421.6,2000,2000,1,1,418.0,422.0,2000,2000,1,1,417.6,422.4,2000,2000,1,1,417.2,422.8,2000,2000,1,1,,,0,0,0,0,,,0,0,0,0,,,0,0,0,0,,,0,0,0,0,,,0,0,0,0,,,0,0,0,0,MSFT
2024-10-22 13:24:56.711574385+00:00,10,39,10888,C,A,2,422.4,2000,130,204343,107387,418.4,421.6,2000,2000,1,1,418.0,422.0,2000,2000,1,1,417.6,422.8,2000,2000,1,1,417.2,,2000,0,1,0,,,0,0,0,0,,,0,0,0,0,,,0,0,0,0,,,0,0,0,0,,,0,0,0,0,,,0,0,0,0,MSFT
2024-10-22 13:24:56.732891178+00:00,10,39,10888,C,A,1,422.0,2000,130,204194,107388,418.4,421.6,2000,2000,1,1,418.0,422.8,2000,2000,1,1,417.6,,2000,0,1,0,417.2,,2000,0,1,0,,,0,0,0,0,,,0,0,0,0,,,0,0,0,0,,,0,0,0,0,,,0,0,0,0,,,0,0,0,0,MSFT
2024-10-22 13:24:56.744281962+00:00,10,39,10888,A,A,1,422.0,2000,130,204198,107389,418.4,421.6,2000,2000,1,1,418.0,422.0,2000,2000,1,1,417.6,422.8,2000,2000,1,1,417.2,,2000,0,1,0,,,0,0,0,0,,,0,0,0,0,,,0,0,0,0,,,0,0,0,0,,,0,0,0,0,,,0,0,0,0,MSFT
2024-10-22 13:24:57.032016015+00:00,10,39,10888,C,B,3,417.2,2000,130,204137,107404,418.4,421.6,2000,2000,1,1,418.0,422.0,2000,2000,1,1,417.6,422.8,2000,2000,1,1,,,0,0,0,0,,,0,0,0,0,,,0,0,0,0,,,0,0,0,0,,,0,0,0,0,,,0,0,0,0,,,0,0,0,0,MSFT
2024-10-22 13:24:57.032018381+00:00,10,39,10888,C,A,1,422.0,2000,130,204112,107405,418.4,421.6,2000,2000,1,1,418.0,422.8,2000,2000,1,1,417.6,,2000,0,1,0,,,0,0,0,0,,,0,0,0,0,,,0,0,0,0,,,0,0,0,0,,,0,0,0,0,,,0,0,0,0,,,0,0,0,0,MSFT
2024-10-22 13:24:57.034756631+00:00,10,39,10888,C,B,2,417.6,2000,130,204118,107406,418.4,421.6,2000,2000,1,1,418.0,422.8,2000,2000,1,1,,,0,0,0,0,,,0,0,0,0,,,0,0,0,0,,,0,0,0,0,,,0,0,0,0,,,0,0,0,0,,,0,0,0,0,,,0,0,0,0,MSFT
2024-10-22 13:24:57.035128966+00:00,10,39,10888,C,B,1,418.0,2000,130,204072,107407,418.4,421.6,2000,2000,1,1,,422.8,0,2000,0,1,,,0,0,0,0,,,0,0,0,0,,,0,0,0,0,,,0,0,0,0,,,0,0,0,0,,,0,0,0,0,,,0,0,0,0,,,0,0,0,0,MSFT
2024-10-22 13:24:57.035134084+00:00,10,39,10888,C,A,0,421.6,2000,130,204113,107408,418.4,422.8,2000,2000,1,1,,,0,0,0,0,,,0,0,0,0,,,0,0,0,0,,,0,0,0,0,,,0,0,0,0,,,0,0,0,0,,,0,0,0,0,,,0,0,0,0,,,0,0,0,0,MSFT
2024-10-22 13:24:57.046427186+00:00,10,39,10888,A,B,1,417.6,2000,130,204165,107415,418.4,422.8,2000,2000,1,1,417.6,,2000,0,1,0,,,0,0,0,0,,,0,0,0,0,,,0,0,0,0,,,0,0,0,0,,,0,0,0,0,,,0,0,0,0,,,0,0,0,0,,,0,0,0,0,MSFT
2024-10-22 13:24:57.046433569+00:00,10,39,10888,A,A,0,422.0,2000,130,204142,107416,418.4,422.0,2000,2000,1,1,417.6,422.8,2000,2000,1,1,,,0,0,0,0,,,0,0,0,0,,,0,0,0,0,,,0,0,0,0,,,0,0,0,0,,,0,0,0,0,,,0,0,0,0,,,0,0,0,0,MSFT
2024-10-22 13:24:57.049740884+00:00,10,39,10888,C,B,1,417.6,2000,130,204115,107419,418.4,422.0,2000,2000,1,1,,422.8,0,2000,0,1,,,0,0,0,0,,,0,0,0,0,,,0,0,0,0,,,0,0,0,0,,,0,0,0,0,,,0,0,0,0,,,0,0,0,0,,,0,0,0,0,MSFT
2024-10-22 13:24:57.049743313+00:00,10,39,10888,C,A,0,422.0,2000,130,204183,107420,418.4,422.8,2000,2000,1,1,,,0,0,0,0,,,0,0,0,0,,,0,0,0,0,,,0,0,0,0,,,0,0,0,0,,,0,0,0,0,,,0,0,0,0,,,0,0,0,0,,,0,0,0,0,MSFT
2024-10-22 13:24:57.050105325+00:00,10,39,10888,C,B,0,418.4,2000,130,204103,107421,,422.8,0,2000,0,1,,,0,0,0,0,,,0,0,0,0,,,0,0,0,0,,,0,0,0,0,,,0,0,0,0,,,0,0,0,0,,,0,0,0,0,,,0,0,0,0,,,0,0,0,0,MSFT
2024-10-22 13:24:57.053717069+00:00,10,39,38,C,A,1,235.2,2000,130,203585,73085,232.8,235.0,2000,2000,1,1,232.6,235.4,2000,2000,1,1,232.4,,2000,0,1,0,,,0,0,0,0,,,0,0,0,0,,,0,0,0,0,,,0,0,0,0,,,0,0,0,0,,,0,0,0,0,,,0,0,0,0,AAPL
2024-10-22 13:24:57.060558869+00:00,10,39,38,C,N,1,235.4,2000,130,203776,73088,232.8,235.0,2000,2000,1,1,232.4,,2000,0,1,0,,,0,0,0,0,,,0,0,0,0,,,0,0,0,0,,,0,0,0,0,,,0,0,0,0,,,0,0,0,0,,,0,0,0,0,,,0,0,0,0,AAPL
2024-10-22 13:24:57.061159821+00:00,10,39,38,C,B,0,232.8,2000,130,203572,73090,232.4,235.0,2000,2000,1,1,,,0,0,0,0,,,0,0,0,0,,,0,0,0,0,,,0,0,0,0,,,0,0,0,0,,,0,0,0,0,,,0,0,0,0,,,0,0,0,0,,,0,0,0,0,AAPL
2024-10-22 13:24:57.061160445+00:00,10,39,38,C,N,0,235.0,2000,130,203719,73092,,,0,0,0,0,,,0,0,0,0,,,0,0,0,0,,,0,0,0,0,,,0,0,0,0,,,0,0,0,0,,,0,0,0,0,,,0,0,0,0,,,0,0,0,0,,,0,0,0,0,AAPL
2024-10-22 13:24:57.061197661+00:00,10,39,10888,A,A,0,422.4,2000,130,204246,107428,,422.4,0,2000,0,1,,422.8,0,2000,0,1,,,0,0,0,0,,,0,0,0,0,,,0,0,0,0,,,0,0,0,0,,,0,0,0,0,,,0,0,0,0,,,0,0,0,0,,,0,0,0,0,MSFT
2024-10-22 13:24:57.061383679+00:00,10,39,10888,C,A,1,422.8,2000,130,204109,107429,,422.4,0,2000,0,1,,,0,0,0,0,,,0,0,0,0,,,0,0,0,0,,,0,0,0,0,,,0,0,0,0,,,0,0,0,0,,,0,0,0,0,,,0,0,0,0,,,0,0,0,0,MSFT
2024-10-22 13:24:57.072759886+00:00,10,39,38,A,B,0,231.6,2000,130,203630,73098,231.6,,2000,0,1,0,,,0,0,0,0,,,0,0,0,0,,,0,0,0,0,,,0,0,0,0,,,0,0,0,0,,,0,0,0,0,,,0,0,0,0,,,0,0,0,0,,,0,0,0,0,AAPL
2024-10-22 13:24:59.500112435+00:00,10,40,38,A,A,0,,0,194,203097,127998,,,0,0,0,0,,,0,0,0,0,,,0,0,0,0,,,0,0,0,0,,,0,0,0,0,,,0,0,0,0,,,0,0,0,0,,,0,0,0,0,,,0,0,0,0,,,0,0,0,0,AAPL
2024-10-22 13:24:59.500618820+00:00,10,41,38,A,A,0,,0,192,101537,325618,,,0,0,0,0,,,0,0,0,0,,,0,0,0,0,,,0,0,0,0,,,0,0,0,0,,,0,0,0,0,,,0,0,0,0,,,0,0,0,0,,,0,0,0,0,,,0,0,0,0,AAPL
2024-10-22 13:24:59.669851348+00:00,10,39,10888,C,A,0,422.4,2000,130,204112,107456,,,0,0,0,0,,,0,0,0,0,,,0,0,0,0,,,0,0,0,0,,,0,0,0,0,,,0,0,0,0,,,0,0,0,0,,,0,0,0,0,,,0,0,0,0,,,0,0,0,0,MSFT
2024-10-22 13:24:59.706344130+00:00,10,39,10888,A,A,0,422.8,2000,130,204194,107457,,422.8,0,2000,0,1,,,0,0,0,0,,,0,0,0,0,,,0,0,0,0,,,0,0,0,0,,,0,0,0,0,,,0,0,0,0,,,0,0,0,0,,,0,0,0,0,,,0,0,0,0,MSFT
2024-10-22 13:25:00.074831333+00:00,10,39,38,C,B,0,231.6,2000,130,203599,73148,,,0,0,0,0,,,0,0,0,0,,,0,0,0,0,,,0,0,0,0,,,0,0,0,0,,,0,0,0,0,,,0,0,0,0,,,0,0,0,0,,,0,0,0,0,,,0,0,0,0,AAPL
2024-10-22 13:25:00.119493194+00:00,10,39,38,A,B,0,231.2,2000,130,203646,73154,231.2,,2000,0,1,0,,,0,0,0,0,,,0,0,0,0,,,0,0,0,0,,,0,0,0,0,,,0,0,0,0,,,0,0,0,0,,,0,0,0,0,,,0,0,0,0,,,0,0,0,0,AAPL
2024-10-22 13:25:00.129304555+00:00,10,39,10888,A,A,0,422.0,2000,130,204152,107519,,422.0,0,2000,0,1,,422.8,0,2000,0,1,,,0,0,0,0,,,0,0,0,0,,,0,0,0,0,,,0,0,0,0,,,0,0,0,0,,,0,0,0,0,,,0,0,0,0,,,0,0,0,0,MSFT
2024-10-22 13:25:00.129489171+00:00,10,39,10888,C,A,1,422.8,2000,130,204095,107520,,422.0,0,2000,0,1,,,0,0,0,0,,,0,0,0,0,,,0,0,0,0,,,0,0,0,0,,,0,0,0,0,,,0,0,0,0,,,0,0,0,0,,,0,0,0,0,,,0,0,0,0,MSFT
2024-10-22 13:25:00.138543639+00:00,10,39,10888,C,A,0,422.0,2000,130,204071,107523,,,0,0,0,0,,,0,0,0,0,,,0,0,0,0,,,0,0,0,0,,,0,0,0,0,,,0,0,0,0,,,0,0,0,0,,,0,0,0,0,,,0,0,0,0,,,0,0,0,0,MSFT
2024-10-22 13:25:00.174324377+00:00,10,39,38,C,B,0,231.2,2000,130,203537,73156,,,0,0,0,0,,,0,0,0,0,,,0,0,0,0,,,0,0,0,0,,,0,0,0,0,,,0,0,0,0,,,0,0,0,0,,,0,0,0,0,,,0,0,0,0,,,0,0,0,0,AAPL
2024-10-22 13:25:00.397314066+00:00,10,39,10888,A,A,0,422.0,2000,130,204320,107533,,422.0,0,2000,0,1,,,0,0,0,0,,,0,0,0,0,,,0,0,0,0,,,0,0,0,0,,,0,0,0,0,,,0,0,0,0,,,0,0,0,0,,,0,0,0,0,,,0,0,0,0,MSFT
2024-10-22 13:25:01.041418377+00:00,10,39,10888,C,A,0,422.0,2000,130,204687,107540,,,0,0,0,0,,,0,0,0,0,,,0,0,0,0,,,0,0,0,0,,,0,0,0,0,,,0,0,0,0,,,0,0,0,0,,,0,0,0,0,,,0,0,0,0,,,0,0,0,0,MSFT
2024-10-22 13:25:01.344854294+00:00,10,39,10888,A,A,0,422.4,2000,130,204248,107550,,422.4,0,2000,0,1,,,0,0,0,0,,,0,0,0,0,,,0,0,0,0,,,0,0,0,0,,,0,0,0,0,,,0,0,0,0,,,0,0,0,0,,,0,0,0,0,,,0,0,0,0,MSFT
2024-10-22 13:25:01.713989172+00:00,10,39,10888,C,A,0,422.4,2000,130,204194,107560,,,0,0,0,0,,,0,0,0,0,,,0,0,0,0,,,0,0,0,0,,,0,0,0,0,,,0,0,0,0,,,0,0,0,0,,,0,0,0,0,,,0,0,0,0,,,0,0,0,0,MSFT
2024-10-22 13:25:02.357441306+00:00,10,40,38,A,B,0,,0,194,202554,128960,233.23,,200,0,0,0,,,0,0,0,0,,,0,0,0,0,,,0,0,0,0,,,0,0,0,0,,,0,0,0,0,,,0,0,0,0,,,0,0,0,0,,,0,0,0,0,,,0,0,0,0,AAPL
2024-10-22 13:25:02.377013826+00:00,10,40,38,A,B,0,,0,194,202625,128961,,,0,0,0,0,,,0,0,0,0,,,0,0,0,0,,,0,0,0,0,,,0,0,0,0,,,0,0,0,0,,,0,0,0,0,,,0,0,0,0,,,0,0,0,0,,,0,0,0,0,AAPL
2024-10-22 13:25:03.205917788+00:00,10,40,10888,A,A,0,420.02,100,194,202623,128985,,420.02,0,100,0,0,,,0,0,0,0,,,0,0,0,0,,,0,0,0,0,,,0,0,0,0,,,0,0,0,0,,,0,0,0,0,,,0,0,0,0,,,0,0,0,0,,,0,0,0,0,MSFT
2024-10-22 13:25:04.718114589+00:00,10,40,10888,A,A,0,,0,194,202523,129047,,,0,0,0,0,,,0,0,0,0,,,0,0,0,0,,,0,0,0,0,,,0,0,0,0,,,0,0,0,0,,,0,0,0,0,,,0,0,0,0,,,0,0,0,0,,,0,0,0,0,MSFT
2024-10-22 13:25:04.969716424+00:00,10,40,10888,A,A,0,419.99,100,194,202611,129058,,419.99,0,100,0,0,,,0,0,0,0,,,0,0,0,0,,,0,0,0,0,,,0,0,0,0,,,0,0,0,0,,,0,0,0,0,,,0,0,0,0,,,0,0,0,0,,,0,0,0,0,MSFT
2024-10-22 13:25:05.066208875+00:00,10,40,38,A,B,0,,0,194,202572,129069,233.23,,200,0,0,0,,,0,0,0,0,,,0,0,0,0,,,0,0,0,0,,,0,0,0,0,,,0,0,0,0,,,0,0,0,0,,,0,0,0,0,,,0,0,0,0,,,0,0,0,0,AAPL
2024-10-22 13:25:05.066652617+00:00,10,41,38,A,B,0,,0,194,55640,329374,233.28,,200,0,0,0,,,0,0,0,0,,,0,0,0,0,,,0,0,0,0,,,0,0,0,0,,,0,0,0,0,,,0,0,0,0,,,0,0,0,0,,,0,0,0,0,,,0,0,0,0,AAPL
2024-10-22 13:25:05.079324148+00:00,10,39,38,A,B,0,231.2,2000,130,203958,73188,231.2,,2000,0,1,0,,,0,0,0,0,,,0,0,0,0,,,0,0,0,0,,,0,0,0,0,,,0,0,0,0,,,0,0,0,0,,,0,0,0,0,,,0,0,0,0,,,0,0,0,0,AAPL
2024-10-22 13:25:05.170813433+00:00,10,40,38,A,B,0,,0,194,202639,129074,,,0,0,0,0,,,0,0,0,0,,,0,0,0,0,,,0,0,0,0,,,0,0,0,0,,,0,0,0,0,,,0,0,0,0,,,0,0,0,0,,,0,0,0,0,,,0,0,0,0,AAPL
2024-10-22 13:25:05.170997663+00:00,10,41,38,A,B,0,,0,194,55366,329380,,,0,0,0,0,,,0,0,0,0,,,0,0,0,0,,,0,0,0,0,,,0,0,0,0,,,0,0,0,0,,,0,0,0,0,,,0,0,0,0,,,0,0,0,0,,,0,0,0,0,AAPL
2024-10-22 13:25:05.399477062+00:00,10,40,38,A,B,0,,0,194,202615,129082,233.23,,200,0,0,0,,,0,0,0,0,,,0,0,0,0,,,0,0,0,0,,,0,0,0,0,,,0,0,0,0,,,0,0,0,0,,,0,0,0,0,,,0,0,0,0,,,0,0,0,0,AAPL
2024-10-22 13:25:05.399716638+00:00,10,41,38,A,B,0,,0,194,55261,329442,233.28,,200,0,0,0,,,0,0,0,0,,,0,0,0,0,,,0,0,0,0,,,0,0,0,0,,,0,0,0,0,,,0,0,0,0,,,0,0,0,0,,,0,0,0,0,,,0,0,0,0,AAPL
2024-10-22 13:25:05.440093721+00:00,10,40,38,A,B,0,,0,194,202667,129088,,,0,0,0,0,,,0,0,0,0,,,0,0,0,0,,,0,0,0,0,,,0,0,0,0,,,0,0,0,0,,,0,0,0,0,,,0,0,0,0,,,0,0,0,0,,,0,0,0,0,AAPL
2024-10-22 13:25:05.440325914+00:00,10,41,38,A,B,0,,0,194,55279,329459,,,0,0,0,0,,,0,0,0,0,,,0,0,0,0,,,0,0,0,0,,,0,0,0,0,,,0,0,0,0,,,0,0,0,0,,,0,0,0,0,,,0,0,0,0,,,0,0,0,0,AAPL
2024-10-22 13:25:05.797410839+00:00,10,40,10888,A,A,0,,0,194,202751,129100,,,0,0,0,0,,,0,0,0,0,,,0,0,0,0,,,0,0,0,0,,,0,0,0,0,,,0,0,0,0,,,0,0,0,0,,,0,0,0,0,,,0,0,0,0,,,0,0,0,0,MSFT
2024-10-22 13:25:06.045419485+00:00,10,40,10888,A,A,0,419.87,100,194,203093,129107,,419.87,0,100,0,0,,,0,0,0,0,,,0,0,0,0,,,0,0,0,0,,,0,0,0,0,,,0,0,0,0,,,0,0,0,0,,,0,0,0,0,,,0,0,0,0,,,0,0,0,0,MSFT
2024-10-22 13:25:06.202526166+00:00,10,40,38,A,B,0,,0,194,202827,129109,233.23,,200,0,0,0,,,0,0,0,0,,,0,0,0,0,,,0,0,0,0,,,0,0,0,0,,,0,0,0,0,,,0,0,0,0,,,0,0,0,0,,,0,0,0,0,,,0,0,0,0,AAPL
2024-10-22 13:25:06.202988642+00:00,10,41,38,A,B,0,,0,194,55445,329603,233.28,,200,0,0,0,,,0,0,0,0,,,0,0,0,0,,,0,0,0,0,,,0,0,0,0,,,0,0,0,0,,,0,0,0,0,,,0,0,0,0,,,0,0,0,0,,,0,0,0,0,AAPL
2024-10-22 13:25:06.203601047+00:00,10,39,38,C,B,0,231.2,2000,130,203678,73195,,,0,0,0,0,,,0,0,0,0,,,0,0,0,0,,,0,0,0,0,,,0,0,0,0,,,0,0,0,0,,,0,0,0,0,,,0,0,0,0,,,0,0,0,0,,,0,0,0,0,AAPL
2024-10-22 13:25:06.240474240+00:00,10,39,38,A,B,0,231.2,2000,130,203674,73196,231.2,,2000,0,1,0,,,0,0,0,0,,,0,0,0,0,,,0,0,0,0,,,0,0,0,0,,,0,0,0,0,,,0,0,0,0,,,0,0,0,0,,,0,0,0,0,,,0,0,0,0,AAPL
2024-10-22 13:25:06.411492010+00:00,10,41,38,A,B,0,,0,194,55152,329635,,,0,0,0,0,,,0,0,0,0,,,0,0,0,0,,,0,0,0,0,,,0,0,0,0,,,0,0,0,0,,,0,0,0,0,,,0,0,0,0,,,0,0,0,0,,,0,0,0,0,AAPL
2024-10-22 13:25:06.411914223+00:00,10,40,38,A,B,0,,0,194,203059,129110,,,0,0,0,0,,,0,0,0,0,,,0,0,0,0,,,0,0,0,0,,,0,0,0,0,,,0,0,0,0,,,0,0,0,0,,,0,0,0,0,,,0,0,0,0,,,0,0,0,0,AAPL
2024-10-22 13:25:06.901129805+00:00,10,40,38,A,B,0,,0,194,202805,129129,233.22,,200,0,0,0,,,0,0,0,0,,,0,0,0,0,,,0,0,0,0,,,0,0,0,0,,,0,0,0,0,,,0,0,0,0,,,0,0,0,0,,,0,0,0,0,,,0,0,0,0,AAPL
2024-10-22 13:25:06.901420244+00:00,10,41,38,A,B,0,,0,194,55403,329745,233.27,,200,0,0,0,,,0,0,0,0,,,0,0,0,0,,,0,0,0,0,,,0,0,0,0,,,0,0,0,0,,,0,0,0,0,,,0,0,0,0,,,0,0,0,0,,,0,0,0,0,AAPL
2024-10-22 13:25:06.912487839+00:00,10,39,38,A,B,0,231.4,2000,130,203965,73206,231.4,,2000,0,1,0,231.2,,2000,0,1,0,,,0,0,0,0,,,0,0,0,0,,,0,0,0,0,,,0,0,0,0,,,0,0,0,0,,,0,0,0,0,,,0,0,0,0,,,0,0,0,0,AAPL
2024-10-22 13:25:06.912669604+00:00,10,39,38,C,B,1,231.2,2000,130,203633,73207,231.4,,2000,0,1,0,,,0,0,0,0,,,0,0,0,0,,,0,0,0,0,,,0,0,0,0,,,0,0,0,0,,,0,0,0,0,,,0,0,0,0,,,0,0,0,0,,,0,0,0,0,AAPL
2024-10-22 13:25:06.938353851+00:00,10,40,38,A,A,0,233.9,200,194,202791,129130,233.22,233.9,200,200,0,0,,,0,0,0,0,,,0,0,0,0,,,0,0,0,0,,,0,0,0,0,,,0,0,0,0,,,0,0,0,0,,,0,0,0,0,,,0,0,0,0,,,0,0,0,0,AAPL
2024-10-22 13:25:07.047408228+00:00,10,41,38,A,B,0,,0,194,62078,329779,,,0,0,0,0,,,0,0,0,0,,,0,0,0,0,,,0,0,0,0,,,0,0,0,0,,,0,0,0,0,,,0,0,0,0,,,0,0,0,0,,,0,0,0,0,,,0,0,0,0,AAPL
2024-10-22 13:25:08.358965086+00:00,10,40,38,A,B,0,233.9,200,194,202948,129173,,233.9,0,200,0,0,,,0,0,0,0,,,0,0,0,0,,,0,0,0,0,,,0,0,0,0,,,0,0,0,0,,,0,0,0,0,,,0,0,0,0,,,0,0,0,0,,,0,0,0,0,AAPL
2024-10-22 13:25:08.811487974+00:00,10,39,10888,A,A,0,422.4,2000,130,204071,107645,,422.4,0,2000,0,1,,,0,0,0,0,,,0,0,0,0,,,0,0,0,0,,,0,0,0,0,,,0,0,0,0,,,0,0,0,0,,,0,0,0,0,,,0,0,0,0,,,0,0,0,0,MSFT
2024-10-22 13:25:08.864616616+00:00,10,39,10888,C,A,0,422.4,2000,130,203906,107646,,,0,0,0,0,,,0,0,0,0,,,0,0,0,0,,,0,0,0,0,,,0,0,0,0,,,0,0,0,0,,,0,0,0,0,,,0,0,0,0,,,0,0,0,0,,,0,0,0,0,MSFT
2024-10-22 13:25:08.941172022+00:00,10,40,10888,A,A,0,,0,194,203124,129186,,,0,0,0,0,,,0,0,0,0,,,0,0,0,0,,,0,0,0,0,,,0,0,0,0,,,0,0,0,0,,,0,0,0,0,,,0,0,0,0,,,0,0,0,0,,,0,0,0,0,MSFT
2024-10-22 13:25:09.073011023+00:00,10,40,38,A,B,0,233.9,200,194,203056,129190,233.25,233.9,200,200,0,0,,,0,0,0,0,,,0,0,0,0,,,0,0,0,0,,,0,0,0,0,,,0,0,0,0,,,0,0,0,0,,,0,0,0,0,,,0,0,0,0,,,0,0,0,0,AAPL
2024-10-22 13:25:09.073260821+00:00,10,41,38,A,B,0,,0,194,55537,330049,233.3,,200,0,0,0,,,0,0,0,0,,,0,0,0,0,,,0,0,0,0,,,0,0,0,0,,,0,0,0,0,,,0,0,0,0,,,0,0,0,0,,,0,0,0,0,,,0,0,0,0,AAPL
2024-10-22 13:25:09.275961545+00:00,10,41,38,A,B,0,,0,194,55678,330066,,,0,0,0,0,,,0,0,0,0,,,0,0,0,0,,,0,0,0,0,,,0,0,0,0,,,0,0,0,0,,,0,0,0,0,,,0,0,0,0,,,0,0,0,0,,,0,0,0,0,AAPL
2024-10-22 13:25:09.275858770+00:00,10,40,38,A,B,0,233.9,200,194,203085,129198,,233.9,0,200,0,0,,,0,0,0,0,,,0,0,0,0,,,0,0,0,0,,,0,0,0,0,,,0,0,0,0,,,0,0,0,0,,,0,0,0,0,,,0,0,0,0,,,0,0,0,0,AAPL
2024-10-22 13:25:09.902978843+00:00,10,40,38,A,B,0,233.9,200,194,203042,129226,233.29,233.9,200,200,0,0,,,0,0,0,0,,,0,0,0,0,,,0,0,0,0,,,0,0,0,0,,,0,0,0,0,,,0,0,0,0,,,0,0,0,0,,,0,0,0,0,,,0,0,0,0,AAPL
2024-10-22 13:25:09.903233637+00:00,10,41,38,A,B,0,,0,194,57240,330169,233.34,,200,0,0,0,,,0,0,0,0,,,0,0,0,0,,,0,0,0,0,,,0,0,0,0,,,0,0,0,0,,,0,0,0,0,,,0,0,0,0,,,0,0,0,0,,,0,0,0,0,AAPL
2024-10-22 13:25:09.940776143+00:00,10,39,38,C,B,0,231.4,2000,130,203696,73225,,,0,0,0,0,,,0,0,0,0,,,0,0,0,0,,,0,0,0,0,,,0,0,0,0,,,0,0,0,0,,,0,0,0,0,,,0,0,0,0,,,0,0,0,0,,,0,0,0,0,AAPL
2024-10-22 13:25:09.952303027+00:00,10,39,38,A,B,0,231.2,2000,130,203727,73226,231.2,,2000,0,1,0,,,0,0,0,0,,,0,0,0,0,,,0,0,0,0,,,0,0,0,0,,,0,0,0,0,,,0,0,0,0,,,0,0,0,0,,,0,0,0,0,,,0,0,0,0,AAPL
2024-10-22 13:25:09.968123506+00:00,10,39,38,C,B,0,231.2,2000,130,203621,73227,,,0,0,0,0,,,0,0,0,0,,,0,0,0,0,,,0,0,0,0,,,0,0,0,0,,,0,0,0,0,,,0,0,0,0,,,0,0,0,0,,,0,0,0,0,,,0,0,0,0,AAPL
2024-10-22 13:25:10.011415367+00:00,10,41,38,A,B,0,,0,194,55392,330198,,,0,0,0,0,,,0,0,0,0,,,0,0,0,0,,,0,0,0,0,,,0,0,0,0,,,0,0,0,0,,,0,0,0,0,,,0,0,0,0,,,0,0,0,0,,,0,0,0,0,AAPL
2024-10-22 13:25:10.011515399+00:00,10,41,38,A,A,0,234.1,200,194,56544,330199,,234.1,0,200,0,0,,,0,0,0,0,,,0,0,0,0,,,0,0,0,0,,,0,0,0,0,,,0,0,0,0,,,0,0,0,0,,,0,0,0,0,,,0,0,0,0,,,0,0,0,0,AAPL
2024-10-22 13:25:10.029352887+00:00,10,39,10888,A,A,0,422.8,2000,130,204244,107673,,422.8,0,2000,0,1,,,0,0,0,0,,,0,0,0,0,,,0,0,0,0,,,0,0,0,0,,,0,0,0,0,,,0,0,0,0,,,0,0,0,0,,,0,0,0,0,,,0,0,0,0,MSFT
2024-10-22 13:25:10.048319855+00:00,10,39,38,A,B,0,231.4,2000,130,204081,73229,231.4,,2000,0,1,0,,,0,0,0,0,,,0,0,0,0,,,0,0,0,0,,,0,0,0,0,,,0,0,0,0,,,0,0,0,0,,,0,0,0,0,,,0,0,0,0,,,0,0,0,0,AAPL
2024-10-22 13:25:10.050703356+00:00,10,39,10888,C,A,0,422.8,2000,130,204045,107677,,,0,0,0,0,,,0,0,0,0,,,0,0,0,0,,,0,0,0,0,,,0,0,0,0,,,0,0,0,0,,,0,0,0,0,,,0,0,0,0,,,0,0,0,0,,,0,0,0,0,MSFT
2024-10-22 13:25:10.053606086+00:00,10,41,38,A,B,0,234.1,200,194,55447,330232,233.3,234.1,200,200,0,0,,,0,0,0,0,,,0,0,0,0,,,0,0,0,0,,,0,0,0,0,,,0,0,0,0,,,0,0,0,0,,,0,0,0,0,,,0,0,0,0,,,0,0,0,0,AAPL
2024-10-22 13:25:10.070323090+00:00,10,39,10888,A,A,0,422.8,2000,130,204090,107685,,422.8,0,2000,0,1,,,0,0,0,0,,,0,0,0,0,,,0,0,0,0,,,0,0,0,0,,,0,0,0,0,,,0,0,0,0,,,0,0,0,0,,,0,0,0,0,,,0,0,0,0,MSFT
2024-10-22 13:25:10.196967520+00:00,10,41,38,A,B,0,234.1,200,194,55786,330297,,234.1,0,200,0,0,,,0,0,0,0,,,0,0,0,0,,,0,0,0,0,,,0,0,0,0,,,0,0,0,0,,,0,0,0,0,,,0,0,0,0,,,0,0,0,0,,,0,0,0,0,AAPL
2024-10-22 13:25:10.221766775+00:00,10,39,10888,A,A,0,422.4,2000,130,204082,107710,,422.4,0,2000,0,1,,422.8,0,2000,0,1,,,0,0,0,0,,,0,0,0,0,,,0,0,0,0,,,0,0,0,0,,,0,0,0,0,,,0,0,0,0,,,0,0,0,0,,,0,0,0,0,MSFT
2024-10-22 13:25:10.221963999+00:00,10,39,10888,C,A,1,422.8,2000,130,204081,107711,,422.4,0,2000,0,1,,,0,0,0,0,,,0,0,0,0,,,0,0,0,0,,,0,0,0,0,,,0,0,0,0,,,0,0,0,0,,,0,0,0,0,,,0,0,0,0,,,0,0,0,0,MSFT
2024-10-22 13:25:10.272241477+00:00,10,40,38,A,B,0,233.9,200,194,203093,129279,,233.9,0,200,0,0,,,0,0,0,0,,,0,0,0,0,,,0,0,0,0,,,0,0,0,0,,,0,0,0,0,,,0,0,0,0,,,0,0,0,0,,,0,0,0,0,,,0,0,0,0,AAPL
2024-10-22 13:25:10.272255671+00:00,10,40,38,A,B,0,233.9,200,194,202947,129280,233.25,233.9,200,200,0,0,,,0,0,0,0,,,0,0,0,0,,,0,0,0,0,,,0,0,0,0,,,0,0,0,0,,,0,0,0,0,,,0,0,0,0,,,0,0,0,0,,,0,0,0,0,AAPL
2024-10-22 13:25:10.309299857+00:00,10,40,38,A,B,0,233.9,200,194,203007,129282,,233.9,0,200,0,0,,,0,0,0,0,,,0,0,0,0,,,0,0,0,0,,,0,0,0,0,,,0,0,0,0,,,0,0,0,0,,,0,0,0,0,,,0,0,0,0,,,0,0,0,0,AAPL
2024-10-22 13:25:10.309309150+00:00,10,40,38,A,A,0,,0,194,202952,129283,,,0,0,0,0,,,0,0,0,0,,,0,0,0,0,,,0,0,0,0,,,0,0,0,0,,,0,0,0,0,,,0,0,0,0,,,0,0,0,0,,,0,0,0,0,,,0,0,0,0,AAPL
2024-10-22 13:25:10.309329736+00:00,10,40,38,A,A,0,234.04,200,194,202962,129284,,234.04,0,200,0,0,,,0,0,0,0,,,0,0,0,0,,,0,0,0,0,,,0,0,0,0,,,0,0,0,0,,,0,0,0,0,,,0,0,0,0,,,0,0,0,0,,,0,0,0,0,AAPL
2024-10-22 13:25:10.428192689+00:00,10,40,38,A,B,0,234.04,200,194,203140,129289,233.25,234.04,200,200,0,0,,,0,0,0,0,,,0,0,0,0,,,0,0,0,0,,,0,0,0,0,,,0,0,0,0,,,0,0,0,0,,,0,0,0,0,,,0,0,0,0,,,0,0,0,0,AAPL
2024-10-22 13:25:10.531015439+00:00,10,40,38,A,B,0,234.04,200,194,202965,129291,,234.04,0,200,0,0,,,0,0,0,0,,,0,0,0,0,,,0,0,0,0,,,0,0,0,0,,,0,0,0,0,,,0,0,0,0,,,0,0,0,0,,,0,0,0,0,,,0,0,0,0,AAPL
2024-10-22 13:25:10.613203926+00:00,10,40,38,A,B,0,234.04,200,194,202978,129293,233.25,234.04,200,200,0,0,,,0,0,0,0,,,0,0,0,0,,,0,0,0,0,,,0,0,0,0,,,0,0,0,0,,,0,0,0,0,,,0,0,0,0,,,0,0,0,0,,,0,0,0,0,AAPL
2024-10-22 13:25:10.613447415+00:00,10,41,38,A,B,0,234.1,200,194,55592,330361,233.3,234.1,200,200,0,0,,,0,0,0,0,,,0,0,0,0,,,0,0,0,0,,,0,0,0,0,,,0,0,0,0,,,0,0,0,0,,,0,0,0,0,,,0,0,0,0,,,0,0,0,0,AAPL
2024-10-22 13:25:10.613451208+00:00,10,41,38,A,A,0,,0,194,60372,330362,233.3,,200,0,0,0,,,0,0,0,0,,,0,0,0,0,,,0,0,0,0,,,0,0,0,0,,,0,0,0,0,,,0,0,0,0,,,0,0,0,0,,,0,0,0,0,,,0,0,0,0,AAPL
2024-10-22 13:25:10.613465580+00:00,10,41,38,A,A,0,233.99,200,194,54423,330363,233.3,233.99,200,200,0,0,,,0,0,0,0,,,0,0,0,0,,,0,0,0,0,,,0,0,0,0,,,0,0,0,0,,,0,0,0,0,,,0,0,0,0,,,0,0,0,0,,,0,0,0,0,AAPL
2024-10-22 13:25:10.613665151+00:00,10,39,38,C,B,0,231.4,2000,130,203576,73243,,,0,0,0,0,,,0,0,0,0,,,0,0,0,0,,,0,0,0,0,,,0,0,0,0,,,0,0,0,0,,,0,0,0,0,,,0,0,0,0,,,0,0,0,0,,,0,0,0,0,AAPL
2024-10-22 13:25:10.651300390+00:00,10,39,38,A,B,0,231.4,2000,130,203670,73244,231.4,,2000,0,1,0,,,0,0,0,0,,,0,0,0,0,,,0,0,0,0,,,0,0,0,0,,,0,0,0,0,,,0,0,0,0,,,0,0,0,0,,,0,0,0,0,,,0,0,0,0,AAPL
2024-10-22 13:25:10.741845101+00:00,10,41,38,A,B,0,233.99,200,194,55589,330381,,233.99,0,200,0,0,,,0,0,0,0,,,0,0,0,0,,,0,0,0,0,,,0,0,0,0,,,0,0,0,0,,,0,0,0,0,,,0,0,0,0,,,0,0,0,0,,,0,0,0,0,AAPL
2024-10-22 13:25:10.942990929+00:00,10,40,38,A,A,0,,0,194,202707,129302,233.25,,200,0,0,0,,,0,0,0,0,,,0,0,0,0,,,0,0,0,0,,,0,0,0,0,,,0,0,0,0,,,0,0,0,0,,,0,0,0,0,,,0,0,0,0,,,0,0,0,0,AAPL
2024-10-22 13:25:10.943012835+00:00,10,40,38,A,A,0,233.93,200,194,202764,129303,233.25,233.93,200,200,0,0,,,0,0,0,0,,,0,0,0,0,,,0,0,0,0,,,0,0,0,0,,,0,0,0,0,,,0,0,0,0,,,0,0,0,0,,,0,0,0,0,,,0,0,0,0,AAPL
2024-10-22 13:25:10.943572393+00:00,10,41,38,A,A,0,,0,194,55840,330410,,,0,0,0,0,,,0,0,0,0,,,0,0,0,0,,,0,0,0,0,,,0,0,0,0,,,0,0,0,0,,,0,0,0,0,,,0,0,0,0,,,0,0,0,0,,,0,0,0,0,AAPL
2024-10-22 13:25:10.943583840+00:00,10,41,38,A,A,0,233.88,200,194,56559,330411,,233.88,0,200,0,0,,,0,0,0,0,,,0,0,0,0,,,0,0,0,0,,,0,0,0,0,,,0,0,0,0,,,0,0,0,0,,,0,0,0,0,,,0,0,0,0,,,0,0,0,0,AAPL
2024-10-22 13:25:12.044570358+00:00,10,41,38,A,B,0,233.88,200,194,55399,330492,233.28,233.88,200,200,0,0,,,0,0,0,0,,,0,0,0,0,,,0,0,0,0,,,0,0,0,0,,,0,0,0,0,,,0,0,0,0,,,0,0,0,0,,,0,0,0,0,,,0,0,0,0,AAPL
2024-10-22 13:25:12.246898477+00:00,10,41,38,A,B,0,233.88,200,194,55420,330513,,233.88,0,200,0,0,,,0,0,0,0,,,0,0,0,0,,,0,0,0,0,,,0,0,0,0,,,0,0,0,0,,,0,0,0,0,,,0,0,0,0,,,0,0,0,0,,,0,0,0,0,AAPL
