ts_event,rtype,publisher_id,instrument_id,action,side,depth,price,size,flags,ts_in_delta,sequence,bid_px_00,ask_px_00,bid_sz_00,ask_sz_00,bid_ct_00,ask_ct_00,bid_px_01,ask_px_01,bid_sz_01,ask_sz_01,bid_ct_01,ask_ct_01,bid_px_02,ask_px_02,bid_sz_02,ask_sz_02,bid_ct_02,ask_ct_02,bid_px_03,ask_px_03,bid_sz_03,ask_sz_03,bid_ct_03,ask_ct_03,bid_px_04,ask_px_04,bid_sz_04,ask_sz_04,bid_ct_04,ask_ct_04,bid_px_05,ask_px_05,bid_sz_05,ask_sz_05,bid_ct_05,ask_ct_05,bid_px_06,ask_px_06,bid_sz_06,ask_sz_06,bid_ct_06,ask_ct_06,bid_px_07,ask_px_07,bid_sz_07,ask_sz_07,bid_ct_07,ask_ct_07,bid_px_08,ask_px_08,bid_sz_08,ask_sz_08,bid_ct_08,ask_ct_08,bid_px_09,ask_px_09,bid_sz_09,ask_sz_09,bid_ct_09,ask_ct_09,symbol
2024-10-22 12:01:45.293275801+00:00,10,41,38,A,B,0,235.06,200,194,60596,63924,,235.06,0,200,0,0,,,0,0,0,0,,,0,0,0,0,,,0,0,0,0,,,0,0,0,0,,,0,0,0,0,,,0,0,0,0,,,0,0,0,0,,,0,0,0,0,,,0,0,0,0,AAPL
2024-10-22 12:01:45.374905210+00:00,10,40,38,A,B,0,235.13,200,194,203659,57870,234.18,235.13,200,200,0,0,,,0,0,0,0,,,0,0,0,0,,,0,0,0,0,,,0,0,0,0,,,0,0,0,0,,,0,0,0,0,,,0,0,0,0,,,0,0,0,0,,,0,0,0,0,AAPL
2024-10-22 12:01:45.375481400+00:00,10,41,38,A,B,0,235.06,200,194,56119,63926,234.25,235.06,200,200,0,0,,,0,0,0,0,,,0,0,0,0,,,0,0,0,0,,,0,0,0,0,,,0,0,0,0,,,0,0,0,0,,,0,0,0,0,,,0,0,0,0,,,0,0,0,0,AAPL
2024-10-22 12:01:45.538796645+00:00,10,40,38,A,B,0,235.13,200,194,203649,57875,,235.13,0,200,0,0,,,0,0,0,0,,,0,0,0,0,,,0,0,0,0,,,0,0,0,0,,,0,0,0,0,,,0,0,0,0,,,0,0,0,0,,,0,0,0,0,,,0,0,0,0,AAPL
2024-10-22 12:01:45.539316989+00:00,10,41,38,A,B,0,235.06,200,194,55982,63933,,235.06,0,200,0,0,,,0,0,0,0,,,0,0,0,0,,,0,0,0,0,,,0,0,0,0,,,0,0,0,0,,,0,0,0,0,,,0,0,0,0,,,0,0,0,0,,,0,0,0,0,AAPL
2024-10-22 12:01:46.845309036+00:00,10,40,38,A,B,0,235.13,200,194,203745,57919,234.18,235.13,200,200,0,0,,,0,0,0,0,,,0,0,0,0,,,0,0,0,0,,,0,0,0,0,,,0,0,0,0,,,0,0,0,0,,,0,0,0,0,,,0,0,0,0,,,0,0,0,0,AAPL
2024-10-22 12:01:50.474843678+00:00,10,41,38,A,B,0,235.06,200,194,60761,64102,234.3,235.06,200,200,0,0,,,0,0,0,0,,,0,0,0,0,,,0,0,0,0,,,0,0,0,0,,,0,0,0,0,,,0,0,0,0,,,0,0,0,0,,,0,0,0,0,,,0,0,0,0,AAPL
2024-10-22 12:01:50.505987071+00:00,10,39,38,C,B,0,232.6,2000,130,204044,37525,,237.0,0,2000,0,1,,,0,0,0,0,,,0,0,0,0,,,0,0,0,0,,,0,0,0,0,,,0,0,0,0,,,0,0,0,0,,,0,0,0,0,,,0,0,0,0,,,0,0,0,0,AAPL
2024-10-22 12:01:50.517766141+00:00,10,39,38,A,B,0,232.4,2000,130,203617,37526,232.4,237.0,2000,2000,1,1,,,0,0,0,0,,,0,0,0,0,,,0,0,0,0,,,0,0,0,0,,,0,0,0,0,,,0,0,0,0,,,0,0,0,0,,,0,0,0,0,,,0,0,0,0,AAPL
2024-10-22 12:01:56.040972556+00:00,10,39,38,C,B,0,232.4,2000,130,203983,37565,,237.0,0,2000,0,1,,,0,0,0,0,,,0,0,0,0,,,0,0,0,0,,,0,0,0,0,,,0,0,0,0,,,0,0,0,0,,,0,0,0,0,,,0,0,0,0,,,0,0,0,0,AAPL
2024-10-22 12:01:56.062490731+00:00,10,39,38,A,B,0,232.6,2000,130,203695,37566,232.6,237.0,2000,2000,1,1,,,0,0,0,0,,,0,0,0,0,,,0,0,0,0,,,0,0,0,0,,,0,0,0,0,,,0,0,0,0,,,0,0,0,0,,,0,0,0,0,,,0,0,0,0,AAPL
2024-10-22 12:01:56.080179064+00:00,10,39,38,C,A,0,237.0,2000,130,203490,37568,232.6,,2000,0,1,0,,,0,0,0,0,,,0,0,0,0,,,0,0,0,0,,,0,0,0,0,,,0,0,0,0,,,0,0,0,0,,,0,0,0,0,,,0,0,0,0,,,0,0,0,0,AAPL
2024-10-22 12:01:56.188248507+00:00,10,41,38,A,B,0,235.06,200,194,60392,64253,,235.06,0,200,0,0,,,0,0,0,0,,,0,0,0,0,,,0,0,0,0,,,0,0,0,0,,,0,0,0,0,,,0,0,0,0,,,0,0,0,0,,,0,0,0,0,,,0,0,0,0,AAPL
2024-10-22 12:01:56.490963363+00:00,10,41,38,A,B,0,235.06,200,194,55333,64262,234.25,235.06,200,200,0,0,,,0,0,0,0,,,0,0,0,0,,,0,0,0,0,,,0,0,0,0,,,0,0,0,0,,,0,0,0,0,,,0,0,0,0,,,0,0,0,0,,,0,0,0,0,AAPL
2024-10-22 12:01:56.936358529+00:00,10,40,38,A,B,0,235.13,200,194,203219,58129,,235.13,0,200,0,0,,,0,0,0,0,,,0,0,0,0,,,0,0,0,0,,,0,0,0,0,,,0,0,0,0,,,0,0,0,0,,,0,0,0,0,,,0,0,0,0,,,0,0,0,0,AAPL
2024-10-22 12:01:56.936595194+00:00,10,41,38,A,B,0,235.06,200,194,55330,64277,,235.06,0,200,0,0,,,0,0,0,0,,,0,0,0,0,,,0,0,0,0,,,0,0,0,0,,,0,0,0,0,,,0,0,0,0,,,0,0,0,0,,,0,0,0,0,,,0,0,0,0,AAPL
2024-10-22 12:01:57.694318550+00:00,10,40,38,A,B,0,235.13,200,194,203369,58155,234.18,235.13,200,200,0,0,,,0,0,0,0,,,0,0,0,0,,,0,0,0,0,,,0,0,0,0,,,0,0,0,0,,,0,0,0,0,,,0,0,0,0,,,0,0,0,0,,,0,0,0,0,AAPL
2024-10-22 12:01:57.694922035+00:00,10,41,38,A,B,0,235.06,200,194,56126,64315,234.25,235.06,200,200,0,0,,,0,0,0,0,,,0,0,0,0,,,0,0,0,0,,,0,0,0,0,,,0,0,0,0,,,0,0,0,0,,,0,0,0,0,,,0,0,0,0,,,0,0,0,0,AAPL
2024-10-22 12:01:57.695477542+00:00,10,39,38,C,B,0,232.6,2000,130,203850,37583,,,0,0,0,0,,,0,0,0,0,,,0,0,0,0,,,0,0,0,0,,,0,0,0,0,,,0,0,0,0,,,0,0,0,0,,,0,0,0,0,,,0,0,0,0,,,0,0,0,0,AAPL
2024-10-22 12:01:57.706014748+00:00,10,39,38,A,A,0,237.0,2000,130,203693,37584,,237.0,0,2000,0,1,,,0,0,0,0,,,0,0,0,0,,,0,0,0,0,,,0,0,0,0,,,0,0,0,0,,,0,0,0,0,,,0,0,0,0,,,0,0,0,0,,,0,0,0,0,AAPL
2024-10-22 12:01:57.730390394+00:00,10,39,38,A,B,0,232.2,2000,130,203586,37585,232.2,237.0,2000,2000,1,1,,,0,0,0,0,,,0,0,0,0,,,0,0,0,0,,,0,0,0,0,,,0,0,0,0,,,0,0,0,0,,,0,0,0,0,,,0,0,0,0,,,0,0,0,0,AAPL
2024-10-22 12:01:57.779702655+00:00,10,39,38,C,B,0,232.2,2000,130,203545,37586,,237.0,0,2000,0,1,,,0,0,0,0,,,0,0,0,0,,,0,0,0,0,,,0,0,0,0,,,0,0,0,0,,,0,0,0,0,,,0,0,0,0,,,0,0,0,0,,,0,0,0,0,AAPL
2024-10-22 12:01:57.822266092+00:00,10,39,38,A,B,0,232.4,2000,130,203545,37587,232.4,237.0,2000,2000,1,1,,,0,0,0,0,,,0,0,0,0,,,0,0,0,0,,,0,0,0,0,,,0,0,0,0,,,0,0,0,0,,,0,0,0,0,,,0,0,0,0,,,0,0,0,0,AAPL
2024-10-22 12:01:58.700928434+00:00,10,39,38,C,A,0,237.0,2000,130,203854,37591,232.4,,2000,0,1,0,,,0,0,0,0,,,0,0,0,0,,,0,0,0,0,,,0,0,0,0,,,0,0,0,0,,,0,0,0,0,,,0,0,0,0,,,0,0,0,0,,,0,0,0,0,AAPL
2024-10-22 12:02:00.073611061+00:00,10,40,38,A,B,0,235.13,200,194,203303,58246,,235.13,0,200,0,0,,,0,0,0,0,,,0,0,0,0,,,0,0,0,0,,,0,0,0,0,,,0,0,0,0,,,0,0,0,0,,,0,0,0,0,,,0,0,0,0,,,0,0,0,0,AAPL
2024-10-22 12:02:00.073812248+00:00,10,41,38,A,B,0,235.06,200,194,66907,64855,,235.06,0,200,0,0,,,0,0,0,0,,,0,0,0,0,,,0,0,0,0,,,0,0,0,0,,,0,0,0,0,,,0,0,0,0,,,0,0,0,0,,,0,0,0,0,,,0,0,0,0,AAPL
2024-10-22 12:02:00.276379035+00:00,10,41,38,A,B,0,235.06,200,194,55271,65127,234.26,235.06,200,200,0,0,,,0,0,0,0,,,0,0,0,0,,,0,0,0,0,,,0,0,0,0,,,0,0,0,0,,,0,0,0,0,,,0,0,0,0,,,0,0,0,0,,,0,0,0,0,AAPL
2024-10-22 12:02:00.544891468+00:00,10,39,38,C,B,0,232.4,2000,130,203717,37604,,,0,0,0,0,,,0,0,0,0,,,0,0,0,0,,,0,0,0,0,,,0,0,0,0,,,0,0,0,0,,,0,0,0,0,,,0,0,0,0,,,0,0,0,0,,,0,0,0,0,AAPL
2024-10-22 12:02:00.778455024+00:00,10,41,38,A,B,0,235.06,200,194,55276,65229,,235.06,0,200,0,0,,,0,0,0,0,,,0,0,0,0,,,0,0,0,0,,,0,0,0,0,,,0,0,0,0,,,0,0,0,0,,,0,0,0,0,,,0,0,0,0,,,0,0,0,0,AAPL
2024-10-22 12:02:01.903115799+00:00,10,40,38,A,B,0,235.13,200,194,203278,58353,234.22,235.13,200,200,0,0,,,0,0,0,0,,,0,0,0,0,,,0,0,0,0,,,0,0,0,0,,,0,0,0,0,,,0,0,0,0,,,0,0,0,0,,,0,0,0,0,,,0,0,0,0,AAPL
2024-10-22 12:02:01.903496179+00:00,10,41,38,A,B,0,235.06,200,194,55233,65311,234.29,235.06,200,200,0,0,,,0,0,0,0,,,0,0,0,0,,,0,0,0,0,,,0,0,0,0,,,0,0,0,0,,,0,0,0,0,,,0,0,0,0,,,0,0,0,0,,,0,0,0,0,AAPL
2024-10-22 12:02:02.019854625+00:00,10,40,38,A,B,0,235.13,200,194,203355,58355,,235.13,0,200,0,0,,,0,0,0,0,,,0,0,0,0,,,0,0,0,0,,,0,0,0,0,,,0,0,0,0,,,0,0,0,0,,,0,0,0,0,,,0,0,0,0,,,0,0,0,0,AAPL
2024-10-22 12:02:02.020310188+00:00,10,41,38,A,B,0,235.06,200,194,55410,65313,,235.06,0,200,0,0,,,0,0,0,0,,,0,0,0,0,,,0,0,0,0,,,0,0,0,0,,,0,0,0,0,,,0,0,0,0,,,0,0,0,0,,,0,0,0,0,,,0,0,0,0,AAPL
2024-10-22 12:02:05.750996933+00:00,10,41,38,A,B,0,235.06,200,194,55828,65427,234.29,235.06,200,200,0,0,,,0,0,0,0,,,0,0,0,0,,,0,0,0,0,,,0,0,0,0,,,0,0,0,0,,,0,0,0,0,,,0,0,0,0,,,0,0,0,0,,,0,0,0,0,AAPL
2024-10-22 12:02:06.581655234+00:00,10,40,38,A,B,0,235.13,200,194,203178,58413,234.22,235.13,200,200,0,0,,,0,0,0,0,,,0,0,0,0,,,0,0,0,0,,,0,0,0,0,,,0,0,0,0,,,0,0,0,0,,,0,0,0,0,,,0,0,0,0,,,0,0,0,0,AAPL
2024-10-22 12:02:06.668424504+00:00,10,40,38,A,B,0,235.13,200,194,202833,58416,,235.13,0,200,0,0,,,0,0,0,0,,,0,0,0,0,,,0,0,0,0,,,0,0,0,0,,,0,0,0,0,,,0,0,0,0,,,0,0,0,0,,,0,0,0,0,,,0,0,0,0,AAPL
2024-10-22 12:02:06.711906328+00:00,10,41,38,A,B,0,235.06,200,194,55361,65464,,235.06,0,200,0,0,,,0,0,0,0,,,0,0,0,0,,,0,0,0,0,,,0,0,0,0,,,0,0,0,0,,,0,0,0,0,,,0,0,0,0,,,0,0,0,0,,,0,0,0,0,AAPL
2024-10-22 12:02:06.745604822+00:00,10,41,38,A,B,0,235.06,200,194,55647,65465,234.24,235.06,200,200,0,0,,,0,0,0,0,,,0,0,0,0,,,0,0,0,0,,,0,0,0,0,,,0,0,0,0,,,0,0,0,0,,,0,0,0,0,,,0,0,0,0,,,0,0,0,0,AAPL
2024-10-22 12:02:06.756938587+00:00,10,39,38,A,B,0,232.4,2000,130,203766,37640,232.4,,2000,0,1,0,,,0,0,0,0,,,0,0,0,0,,,0,0,0,0,,,0,0,0,0,,,0,0,0,0,,,0,0,0,0,,,0,0,0,0,,,0,0,0,0,,,0,0,0,0,AAPL
2024-10-22 12:02:06.783391813+00:00,10,39,38,C,B,0,232.4,2000,130,203576,37641,,,0,0,0,0,,,0,0,0,0,,,0,0,0,0,,,0,0,0,0,,,0,0,0,0,,,0,0,0,0,,,0,0,0,0,,,0,0,0,0,,,0,0,0,0,,,0,0,0,0,AAPL
2024-10-22 12:02:06.801644577+00:00,10,39,38,A,B,0,232.2,2000,130,203344,37642,232.2,,2000,0,1,0,,,0,0,0,0,,,0,0,0,0,,,0,0,0,0,,,0,0,0,0,,,0,0,0,0,,,0,0,0,0,,,0,0,0,0,,,0,0,0,0,,,0,0,0,0,AAPL
2024-10-22 12:02:06.817053738+00:00,10,39,38,A,B,0,232.4,2000,130,203482,37643,232.4,,2000,0,1,0,232.2,,2000,0,1,0,,,0,0,0,0,,,0,0,0,0,,,0,0,0,0,,,0,0,0,0,,,0,0,0,0,,,0,0,0,0,,,0,0,0,0,,,0,0,0,0,AAPL
2024-10-22 12:02:06.817786152+00:00,10,39,38,C,B,1,232.2,2000,130,203291,37644,232.4,,2000,0,1,0,,,0,0,0,0,,,0,0,0,0,,,0,0,0,0,,,0,0,0,0,,,0,0,0,0,,,0,0,0,0,,,0,0,0,0,,,0,0,0,0,,,0,0,0,0,AAPL
2024-10-22 12:02:06.819764198+00:00,10,41,38,A,B,0,235.06,200,194,55182,65466,,235.06,0,200,0,0,,,0,0,0,0,,,0,0,0,0,,,0,0,0,0,,,0,0,0,0,,,0,0,0,0,,,0,0,0,0,,,0,0,0,0,,,0,0,0,0,,,0,0,0,0,AAPL
2024-10-22 12:02:06.830100182+00:00,10,39,38,A,B,0,232.6,2000,130,203231,37645,232.6,,2000,0,1,0,232.4,,2000,0,1,0,,,0,0,0,0,,,0,0,0,0,,,0,0,0,0,,,0,0,0,0,,,0,0,0,0,,,0,0,0,0,,,0,0,0,0,,,0,0,0,0,AAPL
2024-10-22 12:02:06.830304005+00:00,10,39,38,C,B,1,232.4,2000,130,203231,37646,232.6,,2000,0,1,0,,,0,0,0,0,,,0,0,0,0,,,0,0,0,0,,,0,0,0,0,,,0,0,0,0,,,0,0,0,0,,,0,0,0,0,,,0,0,0,0,,,0,0,0,0,AAPL
2024-10-22 12:02:06.857311247+00:00,10,39,38,C,B,0,232.6,2000,130,203159,37648,,,0,0,0,0,,,0,0,0,0,,,0,0,0,0,,,0,0,0,0,,,0,0,0,0,,,0,0,0,0,,,0,0,0,0,,,0,0,0,0,,,0,0,0,0,,,0,0,0,0,AAPL
2024-10-22 12:02:06.869091788+00:00,10,39,38,A,B,0,232.6,2000,130,203264,37651,232.6,,2000,0,1,0,,,0,0,0,0,,,0,0,0,0,,,0,0,0,0,,,0,0,0,0,,,0,0,0,0,,,0,0,0,0,,,0,0,0,0,,,0,0,0,0,,,0,0,0,0,AAPL
2024-10-22 12:02:06.884601350+00:00,10,39,38,C,B,0,232.6,2000,130,203287,37652,,,0,0,0,0,,,0,0,0,0,,,0,0,0,0,,,0,0,0,0,,,0,0,0,0,,,0,0,0,0,,,0,0,0,0,,,0,0,0,0,,,0,0,0,0,,,0,0,0,0,AAPL
2024-10-22 12:02:07.162186182+00:00,10,40,38,A,B,0,235.13,200,194,202874,58423,234.2,235.13,200,200,0,0,,,0,0,0,0,,,0,0,0,0,,,0,0,0,0,,,0,0,0,0,,,0,0,0,0,,,0,0,0,0,,,0,0,0,0,,,0,0,0,0,,,0,0,0,0,AAPL
2024-10-22 12:02:07.162803955+00:00,10,41,38,A,B,0,235.06,200,194,56860,65482,234.27,235.06,200,200,0,0,,,0,0,0,0,,,0,0,0,0,,,0,0,0,0,,,0,0,0,0,,,0,0,0,0,,,0,0,0,0,,,0,0,0,0,,,0,0,0,0,,,0,0,0,0,AAPL
2024-10-22 12:02:07.179206563+00:00,10,40,38,A,B,0,235.13,200,194,202766,58424,,235.13,0,200,0,0,,,0,0,0,0,,,0,0,0,0,,,0,0,0,0,,,0,0,0,0,,,0,0,0,0,,,0,0,0,0,,,0,0,0,0,,,0,0,0,0,,,0,0,0,0,AAPL
2024-10-22 12:02:07.249126294+00:00,10,39,38,A,B,0,232.2,2000,130,203608,37654,232.2,,2000,0,1,0,,,0,0,0,0,,,0,0,0,0,,,0,0,0,0,,,0,0,0,0,,,0,0,0,0,,,0,0,0,0,,,0,0,0,0,,,0,0,0,0,,,0,0,0,0,AAPL
2024-10-22 12:02:07.273720756+00:00,10,39,38,A,B,0,232.4,2000,130,203328,37655,232.4,,2000,0,1,0,232.2,,2000,0,1,0,,,0,0,0,0,,,0,0,0,0,,,0,0,0,0,,,0,0,0,0,,,0,0,0,0,,,0,0,0,0,,,0,0,0,0,,,0,0,0,0,AAPL
2024-10-22 12:02:07.274452361+00:00,10,39,38,C,B,1,232.2,2000,130,203271,37656,232.4,,2000,0,1,0,,,0,0,0,0,,,0,0,0,0,,,0,0,0,0,,,0,0,0,0,,,0,0,0,0,,,0,0,0,0,,,0,0,0,0,,,0,0,0,0,,,0,0,0,0,AAPL
2024-10-22 12:02:07.615934980+00:00,10,41,38,A,B,0,235.06,200,194,55737,65491,,235.06,0,200,0,0,,,0,0,0,0,,,0,0,0,0,,,0,0,0,0,,,0,0,0,0,,,0,0,0,0,,,0,0,0,0,,,0,0,0,0,,,0,0,0,0,,,0,0,0,0,AAPL
2024-10-22 12:02:07.615978629+00:00,10,41,38,A,B,0,235.06,200,194,54877,65492,234.24,235.06,200,200,0,0,,,0,0,0,0,,,0,0,0,0,,,0,0,0,0,,,0,0,0,0,,,0,0,0,0,,,0,0,0,0,,,0,0,0,0,,,0,0,0,0,,,0,0,0,0,AAPL
2024-10-22 12:02:07.626641901+00:00,10,39,38,A,B,0,232.6,2000,130,203763,37657,232.6,,2000,0,1,0,232.4,,2000,0,1,0,,,0,0,0,0,,,0,0,0,0,,,0,0,0,0,,,0,0,0,0,,,0,0,0,0,,,0,0,0,0,,,0,0,0,0,,,0,0,0,0,AAPL
2024-10-22 12:02:07.626820168+00:00,10,39,38,C,B,1,232.4,2000,130,203421,37658,232.6,,2000,0,1,0,,,0,0,0,0,,,0,0,0,0,,,0,0,0,0,,,0,0,0,0,,,0,0,0,0,,,0,0,0,0,,,0,0,0,0,,,0,0,0,0,,,0,0,0,0,AAPL
2024-10-22 12:02:07.653045903+00:00,10,39,38,C,B,0,232.6,2000,130,203277,37659,,,0,0,0,0,,,0,0,0,0,,,0,0,0,0,,,0,0,0,0,,,0,0,0,0,,,0,0,0,0,,,0,0,0,0,,,0,0,0,0,,,0,0,0,0,,,0,0,0,0,AAPL
2024-10-22 12:02:07.665399871+00:00,10,39,38,A,B,0,232.6,2000,130,203351,37660,232.6,,2000,0,1,0,,,0,0,0,0,,,0,0,0,0,,,0,0,0,0,,,0,0,0,0,,,0,0,0,0,,,0,0,0,0,,,0,0,0,0,,,0,0,0,0,,,0,0,0,0,AAPL
2024-10-22 12:02:07.919503860+00:00,10,41,38,A,B,0,235.06,200,194,60609,65506,,235.06,0,200,0,0,,,0,0,0,0,,,0,0,0,0,,,0,0,0,0,,,0,0,0,0,,,0,0,0,0,,,0,0,0,0,,,0,0,0,0,,,0,0,0,0,,,0,0,0,0,AAPL
2024-10-22 12:02:11.993017003+00:00,10,40,38,A,B,0,235.13,200,194,203434,58472,234.17,235.13,200,200,0,0,,,0,0,0,0,,,0,0,0,0,,,0,0,0,0,,,0,0,0,0,,,0,0,0,0,,,0,0,0,0,,,0,0,0,0,,,0,0,0,0,,,0,0,0,0,AAPL
2024-10-22 12:02:11.993605350+00:00,10,41,38,A,B,0,235.06,200,194,55628,65682,234.24,235.06,200,200,0,0,,,0,0,0,0,,,0,0,0,0,,,0,0,0,0,,,0,0,0,0,,,0,0,0,0,,,0,0,0,0,,,0,0,0,0,,,0,0,0,0,,,0,0,0,0,AAPL
2024-10-22 12:02:24.437209204+00:00,10,39,38,C,B,0,232.6,2000,130,203648,37787,,,0,0,0,0,,,0,0,0,0,,,0,0,0,0,,,0,0,0,0,,,0,0,0,0,,,0,0,0,0,,,0,0,0,0,,,0,0,0,0,,,0,0,0,0,,,0,0,0,0,AAPL
2024-10-22 12:02:55.284653010+00:00,10,39,38,A,A,0,237.0,2000,130,203770,37948,,237.0,0,2000,0,1,,,0,0,0,0,,,0,0,0,0,,,0,0,0,0,,,0,0,0,0,,,0,0,0,0,,,0,0,0,0,,,0,0,0,0,,,0,0,0,0,,,0,0,0,0,AAPL
2024-10-22 12:02:56.904976811+00:00,10,39,38,A,A,0,236.8,2000,130,203528,37965,,236.8,0,2000,0,1,,237.0,0,2000,0,1,,,0,0,0,0,,,0,0,0,0,,,0,0,0,0,,,0,0,0,0,,,0,0,0,0,,,0,0,0,0,,,0,0,0,0,,,0,0,0,0,AAPL
2024-10-22 12:02:56.905232105+00:00,10,39,38,C,A,1,237.0,2000,130,203395,37966,,236.8,0,2000,0,1,,,0,0,0,0,,,0,0,0,0,,,0,0,0,0,,,0,0,0,0,,,0,0,0,0,,,0,0,0,0,,,0,0,0,0,,,0,0,0,0,,,0,0,0,0,AAPL
2024-10-22 12:03:00.037664076+00:00,10,40,38,A,B,0,235.13,200,194,202974,58977,,235.13,0,200,0,0,,,0,0,0,0,,,0,0,0,0,,,0,0,0,0,,,0,0,0,0,,,0,0,0,0,,,0,0,0,0,,,0,0,0,0,,,0,0,0,0,,,0,0,0,0,AAPL
2024-10-22 12:03:00.037957919+00:00,10,41,38,A,B,0,235.06,200,194,55774,67285,,235.06,0,200,0,0,,,0,0,0,0,,,0,0,0,0,,,0,0,0,0,,,0,0,0,0,,,0,0,0,0,,,0,0,0,0,,,0,0,0,0,,,0,0,0,0,,,0,0,0,0,AAPL
2024-10-22 12:03:00.038031771+00:00,10,41,38,A,B,0,235.06,200,194,56619,67292,234.29,235.06,200,200,0,0,,,0,0,0,0,,,0,0,0,0,,,0,0,0,0,,,0,0,0,0,,,0,0,0,0,,,0,0,0,0,,,0,0,0,0,,,0,0,0,0,,,0,0,0,0,AAPL
2024-10-22 12:03:00.137928159+00:00,10,40,38,A,B,0,235.13,200,194,202937,59036,234.22,235.13,200,200,0,0,,,0,0,0,0,,,0,0,0,0,,,0,0,0,0,,,0,0,0,0,,,0,0,0,0,,,0,0,0,0,,,0,0,0,0,,,0,0,0,0,,,0,0,0,0,AAPL
2024-10-22 12:03:07.000151366+00:00,10,39,38,C,A,0,236.8,2000,130,204200,38042,,,0,0,0,0,,,0,0,0,0,,,0,0,0,0,,,0,0,0,0,,,0,0,0,0,,,0,0,0,0,,,0,0,0,0,,,0,0,0,0,,,0,0,0,0,,,0,0,0,0,AAPL
2024-10-22 12:03:07.013057968+00:00,10,39,38,A,A,0,237.0,2000,130,203639,38043,,237.0,0,2000,0,1,,,0,0,0,0,,,0,0,0,0,,,0,0,0,0,,,0,0,0,0,,,0,0,0,0,,,0,0,0,0,,,0,0,0,0,,,0,0,0,0,,,0,0,0,0,AAPL
2024-10-22 12:03:07.029016220+00:00,10,39,38,C,A,0,237.0,2000,130,203550,38044,,,0,0,0,0,,,0,0,0,0,,,0,0,0,0,,,0,0,0,0,,,0,0,0,0,,,0,0,0,0,,,0,0,0,0,,,0,0,0,0,,,0,0,0,0,,,0,0,0,0,AAPL
2024-10-22 12:03:07.075705995+00:00,10,41,38,A,B,0,235.06,200,194,55841,68065,,235.06,0,200,0,0,,,0,0,0,0,,,0,0,0,0,,,0,0,0,0,,,0,0,0,0,,,0,0,0,0,,,0,0,0,0,,,0,0,0,0,,,0,0,0,0,,,0,0,0,0,AAPL
2024-10-22 12:03:07.075763109+00:00,10,41,38,A,B,0,235.06,200,194,54338,68066,234.27,235.06,200,200,0,0,,,0,0,0,0,,,0,0,0,0,,,0,0,0,0,,,0,0,0,0,,,0,0,0,0,,,0,0,0,0,,,0,0,0,0,,,0,0,0,0,,,0,0,0,0,AAPL
2024-10-22 12:03:15.360718458+00:00,10,39,38,A,B,0,232.2,2000,130,203672,38147,232.2,,2000,0,1,0,,,0,0,0,0,,,0,0,0,0,,,0,0,0,0,,,0,0,0,0,,,0,0,0,0,,,0,0,0,0,,,0,0,0,0,,,0,0,0,0,,,0,0,0,0,AAPL
2024-10-22 12:03:31.925310285+00:00,10,39,38,A,A,0,237.0,2000,130,204610,38284,232.2,237.0,2000,2000,1,1,,,0,0,0,0,,,0,0,0,0,,,0,0,0,0,,,0,0,0,0,,,0,0,0,0,,,0,0,0,0,,,0,0,0,0,,,0,0,0,0,,,0,0,0,0,AAPL
2024-10-22 12:03:32.039241236+00:00,10,39,38,C,A,0,237.0,2000,130,204015,38286,232.2,,2000,0,1,0,,,0,0,0,0,,,0,0,0,0,,,0,0,0,0,,,0,0,0,0,,,0,0,0,0,,,0,0,0,0,,,0,0,0,0,,,0,0,0,0,,,0,0,0,0,AAPL
2024-10-22 12:03:32.065514029+00:00,10,39,38,A,A,0,237.2,2000,130,204097,38287,232.2,237.2,2000,2000,1,1,,,0,0,0,0,,,0,0,0,0,,,0,0,0,0,,,0,0,0,0,,,0,0,0,0,,,0,0,0,0,,,0,0,0,0,,,0,0,0,0,,,0,0,0,0,AAPL
2024-10-22 12:03:37.868198437+00:00,10,40,38,A,N,0,,0,194,203427,59421,,,0,0,0,0,,,0,0,0,0,,,0,0,0,0,,,0,0,0,0,,,0,0,0,0,,,0,0,0,0,,,0,0,0,0,,,0,0,0,0,,,0,0,0,0,,,0,0,0,0,AAPL
2024-10-22 12:03:37.868221902+00:00,10,40,38,A,B,0,,0,194,203132,59422,234.19,,200,0,0,0,,,0,0,0,0,,,0,0,0,0,,,0,0,0,0,,,0,0,0,0,,,0,0,0,0,,,0,0,0,0,,,0,0,0,0,,,0,0,0,0,,,0,0,0,0,AAPL
2024-10-22 12:03:37.868229351+00:00,10,40,38,A,A,0,235.22,200,194,203129,59423,234.19,235.22,200,200,0,0,,,0,0,0,0,,,0,0,0,0,,,0,0,0,0,,,0,0,0,0,,,0,0,0,0,,,0,0,0,0,,,0,0,0,0,,,0,0,0,0,,,0,0,0,0,AAPL
2024-10-22 12:03:38.650159417+00:00,10,41,38,A,B,0,235.06,200,194,56778,69027,,235.06,0,200,0,0,,,0,0,0,0,,,0,0,0,0,,,0,0,0,0,,,0,0,0,0,,,0,0,0,0,,,0,0,0,0,,,0,0,0,0,,,0,0,0,0,,,0,0,0,0,AAPL
2024-10-22 12:03:38.650176143+00:00,10,41,38,A,A,0,,0,194,57629,69028,,,0,0,0,0,,,0,0,0,0,,,0,0,0,0,,,0,0,0,0,,,0,0,0,0,,,0,0,0,0,,,0,0,0,0,,,0,0,0,0,,,0,0,0,0,,,0,0,0,0,AAPL
2024-10-22 12:03:38.650229516+00:00,10,41,38,A,B,0,,0,194,55163,69029,234.26,,200,0,0,0,,,0,0,0,0,,,0,0,0,0,,,0,0,0,0,,,0,0,0,0,,,0,0,0,0,,,0,0,0,0,,,0,0,0,0,,,0,0,0,0,,,0,0,0,0,AAPL
2024-10-22 12:03:38.650246304+00:00,10,41,38,A,A,0,235.15,200,194,54390,69030,234.26,235.15,200,200,0,0,,,0,0,0,0,,,0,0,0,0,,,0,0,0,0,,,0,0,0,0,,,0,0,0,0,,,0,0,0,0,,,0,0,0,0,,,0,0,0,0,,,0,0,0,0,AAPL
2024-10-22 12:03:43.436328585+00:00,10,39,38,C,A,0,237.2,2000,130,203578,38358,232.2,,2000,0,1,0,,,0,0,0,0,,,0,0,0,0,,,0,0,0,0,,,0,0,0,0,,,0,0,0,0,,,0,0,0,0,,,0,0,0,0,,,0,0,0,0,,,0,0,0,0,AAPL
2024-10-22 12:03:43.448694262+00:00,10,39,38,A,B,0,232.6,2000,130,203588,38359,232.6,,2000,0,1,0,232.2,,2000,0,1,0,,,0,0,0,0,,,0,0,0,0,,,0,0,0,0,,,0,0,0,0,,,0,0,0,0,,,0,0,0,0,,,0,0,0,0,,,0,0,0,0,AAPL
2024-10-22 12:03:43.448882166+00:00,10,39,38,C,B,1,232.2,2000,130,203375,38360,232.6,,2000,0,1,0,,,0,0,0,0,,,0,0,0,0,,,0,0,0,0,,,0,0,0,0,,,0,0,0,0,,,0,0,0,0,,,0,0,0,0,,,0,0,0,0,,,0,0,0,0,AAPL
2024-10-22 12:03:43.467615024+00:00,10,39,38,C,B,0,232.6,2000,130,203380,38361,,,0,0,0,0,,,0,0,0,0,,,0,0,0,0,,,0,0,0,0,,,0,0,0,0,,,0,0,0,0,,,0,0,0,0,,,0,0,0,0,,,0,0,0,0,,,0,0,0,0,AAPL
2024-10-22 12:03:43.472031476+00:00,10,39,38,A,A,0,237.2,2000,130,203409,38362,,237.2,0,2000,0,1,,,0,0,0,0,,,0,0,0,0,,,0,0,0,0,,,0,0,0,0,,,0,0,0,0,,,0,0,0,0,,,0,0,0,0,,,0,0,0,0,,,0,0,0,0,AAPL
2024-10-22 12:03:43.478710556+00:00,10,39,38,A,B,0,232.4,2000,130,203401,38363,232.4,237.2,2000,2000,1,1,,,0,0,0,0,,,0,0,0,0,,,0,0,0,0,,,0,0,0,0,,,0,0,0,0,,,0,0,0,0,,,0,0,0,0,,,0,0,0,0,,,0,0,0,0,AAPL
2024-10-22 12:03:47.559744190+00:00,10,39,38,C,A,0,237.2,2000,130,203888,38373,232.4,,2000,0,1,0,,,0,0,0,0,,,0,0,0,0,,,0,0,0,0,,,0,0,0,0,,,0,0,0,0,,,0,0,0,0,,,0,0,0,0,,,0,0,0,0,,,0,0,0,0,AAPL
2024-10-22 12:03:47.588075932+00:00,10,39,38,A,B,0,232.6,2000,130,203705,38374,232.6,,2000,0,1,0,232.4,,2000,0,1,0,,,0,0,0,0,,,0,0,0,0,,,0,0,0,0,,,0,0,0,0,,,0,0,0,0,,,0,0,0,0,,,0,0,0,0,,,0,0,0,0,AAPL
2024-10-22 12:03:47.588250157+00:00,10,39,38,C,B,1,232.4,2000,130,203454,38375,232.6,,2000,0,1,0,,,0,0,0,0,,,0,0,0,0,,,0,0,0,0,,,0,0,0,0,,,0,0,0,0,,,0,0,0,0,,,0,0,0,0,,,0,0,0,0,,,0,0,0,0,AAPL
2024-10-22 12:03:47.596344223+00:00,10,39,38,A,A,0,237.2,2000,130,203545,38376,232.6,237.2,2000,2000,1,1,,,0,0,0,0,,,0,0,0,0,,,0,0,0,0,,,0,0,0,0,,,0,0,0,0,,,0,0,0,0,,,0,0,0,0,,,0,0,0,0,,,0,0,0,0,AAPL
2024-10-22 12:03:50.971127055+00:00,10,39,38,C,B,0,232.6,2000,130,203871,38387,,237.2,0,2000,0,1,,,0,0,0,0,,,0,0,0,0,,,0,0,0,0,,,0,0,0,0,,,0,0,0,0,,,0,0,0,0,,,0,0,0,0,,,0,0,0,0,,,0,0,0,0,AAPL
2024-10-22 12:03:50.982455344+00:00,10,39,38,A,B,0,232.6,2000,130,203693,38388,232.6,237.2,2000,2000,1,1,,,0,0,0,0,,,0,0,0,0,,,0,0,0,0,,,0,0,0,0,,,0,0,0,0,,,0,0,0,0,,,0,0,0,0,,,0,0,0,0,,,0,0,0,0,AAPL
2024-10-22 12:04:00.015672758+00:00,10,40,38,A,B,0,235.22,200,194,202919,60272,,235.22,0,200,0,0,,,0,0,0,0,,,0,0,0,0,,,0,0,0,0,,,0,0,0,0,,,0,0,0,0,,,0,0,0,0,,,0,0,0,0,,,0,0,0,0,,,0,0,0,0,AAPL
2024-10-22 12:04:00.016048925+00:00,10,41,38,A,B,0,235.15,200,194,60242,72133,,235.15,0,200,0,0,,,0,0,0,0,,,0,0,0,0,,,0,0,0,0,,,0,0,0,0,,,0,0,0,0,,,0,0,0,0,,,0,0,0,0,,,0,0,0,0,,,0,0,0,0,AAPL
2024-10-22 12:04:00.116381254+00:00,10,40,38,A,B,0,235.22,200,194,202935,60340,234.28,235.22,200,200,0,0,,,0,0,0,0,,,0,0,0,0,,,0,0,0,0,,,0,0,0,0,,,0,0,0,0,,,0,0,0,0,,,0,0,0,0,,,0,0,0,0,,,0,0,0,0,AAPL
2024-10-22 12:04:00.116971051+00:00,10,41,38,A,B,0,235.15,200,194,55404,72417,234.35,235.15,200,200,0,0,,,0,0,0,0,,,0,0,0,0,,,0,0,0,0,,,0,0,0,0,,,0,0,0,0,,,0,0,0,0,,,0,0,0,0,,,0,0,0,0,,,0,0,0,0,AAPL
2024-10-22 12:04:05.746379786+00:00,10,39,38,C,B,0,232.6,2000,130,203702,38482,,237.2,0,2000,0,1,,,0,0,0,0,,,0,0,0,0,,,0,0,0,0,,,0,0,0,0,,,0,0,0,0,,,0,0,0,0,,,0,0,0,0,,,0,0,0,0,,,0,0,0,0,AAPL
2024-10-22 12:04:05.757124489+00:00,10,39,38,A,B,0,232.4,2000,130,203713,38484,232.4,237.2,2000,2000,1,1,,,0,0,0,0,,,0,0,0,0,,,0,0,0,0,,,0,0,0,0,,,0,0,0,0,,,0,0,0,0,,,0,0,0,0,,,0,0,0,0,,,0,0,0,0,AAPL
2024-10-22 12:04:21.614169734+00:00,10,39,38,C,A,0,237.2,2000,130,204733,38587,232.4,,2000,0,1,0,,,0,0,0,0,,,0,0,0,0,,,0,0,0,0,,,0,0,0,0,,,0,0,0,0,,,0,0,0,0,,,0,0,0,0,,,0,0,0,0,,,0,0,0,0,AAPL
2024-10-22 12:04:21.665358164+00:00,10,39,38,A,B,0,232.6,2000,130,204630,38588,232.6,,2000,0,1,0,232.4,,2000,0,1,0,,,0,0,0,0,,,0,0,0,0,,,0,0,0,0,,,0,0,0,0,,,0,0,0,0,,,0,0,0,0,,,0,0,0,0,,,0,0,0,0,AAPL
2024-10-22 12:04:21.666086367+00:00,10,39,38,C,B,1,232.4,2000,130,204415,38589,232.6,,2000,0,1,0,,,0,0,0,0,,,0,0,0,0,,,0,0,0,0,,,0,0,0,0,,,0,0,0,0,,,0,0,0,0,,,0,0,0,0,,,0,0,0,0,,,0,0,0,0,AAPL
2024-10-22 12:04:35.510144095+00:00,10,39,38,C,B,0,232.6,2000,130,204369,38644,,,0,0,0,0,,,0,0,0,0,,,0,0,0,0,,,0,0,0,0,,,0,0,0,0,,,0,0,0,0,,,0,0,0,0,,,0,0,0,0,,,0,0,0,0,,,0,0,0,0,AAPL
2024-10-22 12:04:37.975979204+00:00,10,39,38,A,B,0,232.4,2000,130,204327,38665,232.4,,2000,0,1,0,,,0,0,0,0,,,0,0,0,0,,,0,0,0,0,,,0,0,0,0,,,0,0,0,0,,,0,0,0,0,,,0,0,0,0,,,0,0,0,0,,,0,0,0,0,AAPL
2024-10-22 12:04:47.965156560+00:00,10,39,38,C,B,0,232.4,2000,130,203424,38738,,,0,0,0,0,,,0,0,0,0,,,0,0,0,0,,,0,0,0,0,,,0,0,0,0,,,0,0,0,0,,,0,0,0,0,,,0,0,0,0,,,0,0,0,0,,,0,0,0,0,AAPL
2024-10-22 12:04:48.026832560+00:00,10,39,38,A,B,0,232.4,2000,130,203575,38740,232.4,,2000,0,1,0,,,0,0,0,0,,,0,0,0,0,,,0,0,0,0,,,0,0,0,0,,,0,0,0,0,,,0,0,0,0,,,0,0,0,0,,,0,0,0,0,,,0,0,0,0,AAPL
2024-10-22 12:04:50.980935972+00:00,10,39,38,C,B,0,232.4,2000,130,203337,38779,,,0,0,0,0,,,0,0,0,0,,,0,0,0,0,,,0,0,0,0,,,0,0,0,0,,,0,0,0,0,,,0,0,0,0,,,0,0,0,0,,,0,0,0,0,,,0,0,0,0,AAPL
2024-10-22 12:04:52.000341682+00:00,10,39,38,A,B,0,232.4,2000,130,204059,38787,232.4,,2000,0,1,0,,,0,0,0,0,,,0,0,0,0,,,0,0,0,0,,,0,0,0,0,,,0,0,0,0,,,0,0,0,0,,,0,0,0,0,,,0,0,0,0,,,0,0,0,0,AAPL
2024-10-22 12:04:52.023309770+00:00,10,39,38,C,B,0,232.4,2000,130,203373,38788,,,0,0,0,0,,,0,0,0,0,,,0,0,0,0,,,0,0,0,0,,,0,0,0,0,,,0,0,0,0,,,0,0,0,0,,,0,0,0,0,,,0,0,0,0,,,0,0,0,0,AAPL
2024-10-22 12:04:52.034069163+00:00,10,39,38,A,B,0,232.4,2000,130,203364,38789,232.4,,2000,0,1,0,,,0,0,0,0,,,0,0,0,0,,,0,0,0,0,,,0,0,0,0,,,0,0,0,0,,,0,0,0,0,,,0,0,0,0,,,0,0,0,0,,,0,0,0,0,AAPL
2024-10-22 12:05:00.033857587+00:00,10,40,38,A,B,0,235.22,200,194,203130,61108,,235.22,0,200,0,0,,,0,0,0,0,,,0,0,0,0,,,0,0,0,0,,,0,0,0,0,,,0,0,0,0,,,0,0,0,0,,,0,0,0,0,,,0,0,0,0,,,0,0,0,0,AAPL
2024-10-22 12:05:00.033983169+00:00,10,40,38,A,A,0,,0,194,203118,61109,,,0,0,0,0,,,0,0,0,0,,,0,0,0,0,,,0,0,0,0,,,0,0,0,0,,,0,0,0,0,,,0,0,0,0,,,0,0,0,0,,,0,0,0,0,,,0,0,0,0,AAPL
2024-10-22 12:05:00.034277817+00:00,10,41,38,A,B,0,235.15,200,194,62060,74540,,235.15,0,200,0,0,,,0,0,0,0,,,0,0,0,0,,,0,0,0,0,,,0,0,0,0,,,0,0,0,0,,,0,0,0,0,,,0,0,0,0,,,0,0,0,0,,,0,0,0,0,AAPL
2024-10-22 12:05:00.088883146+00:00,10,40,38,A,A,0,235.22,200,194,203139,61207,,235.22,0,200,0,0,,,0,0,0,0,,,0,0,0,0,,,0,0,0,0,,,0,0,0,0,,,0,0,0,0,,,0,0,0,0,,,0,0,0,0,,,0,0,0,0,,,0,0,0,0,AAPL
2024-10-22 12:05:00.548256389+00:00,10,40,38,A,B,0,235.22,200,194,203063,61341,234.33,235.22,200,200,0,0,,,0,0,0,0,,,0,0,0,0,,,0,0,0,0,,,0,0,0,0,,,0,0,0,0,,,0,0,0,0,,,0,0,0,0,,,0,0,0,0,,,0,0,0,0,AAPL
2024-10-22 12:05:00.548524224+00:00,10,41,38,A,B,0,235.15,200,194,55707,75394,234.4,235.15,200,200,0,0,,,0,0,0,0,,,0,0,0,0,,,0,0,0,0,,,0,0,0,0,,,0,0,0,0,,,0,0,0,0,,,0,0,0,0,,,0,0,0,0,,,0,0,0,0,AAPL
2024-10-22 12:05:00.851993891+00:00,10,40,38,A,B,0,235.22,200,194,203112,61346,,235.22,0,200,0,0,,,0,0,0,0,,,0,0,0,0,,,0,0,0,0,,,0,0,0,0,,,0,0,0,0,,,0,0,0,0,,,0,0,0,0,,,0,0,0,0,,,0,0,0,0,AAPL
2024-10-22 12:05:01.959684701+00:00,10,41,38,A,B,0,235.15,200,194,55668,75486,,235.15,0,200,0,0,,,0,0,0,0,,,0,0,0,0,,,0,0,0,0,,,0,0,0,0,,,0,0,0,0,,,0,0,0,0,,,0,0,0,0,,,0,0,0,0,,,0,0,0,0,AAPL
2024-10-22 12:05:02.766966958+00:00,10,41,38,A,B,0,235.15,200,194,56142,75511,234.4,235.15,200,200,0,0,,,0,0,0,0,,,0,0,0,0,,,0,0,0,0,,,0,0,0,0,,,0,0,0,0,,,0,0,0,0,,,0,0,0,0,,,0,0,0,0,,,0,0,0,0,AAPL
2024-10-22 12:05:02.874944321+00:00,10,41,38,A,B,0,235.15,200,194,55072,75515,,235.15,0,200,0,0,,,0,0,0,0,,,0,0,0,0,,,0,0,0,0,,,0,0,0,0,,,0,0,0,0,,,0,0,0,0,,,0,0,0,0,,,0,0,0,0,,,0,0,0,0,AAPL
2024-10-22 12:05:03.433168403+00:00,10,40,38,A,B,0,235.22,200,194,202801,61388,234.33,235.22,200,200,0,0,,,0,0,0,0,,,0,0,0,0,,,0,0,0,0,,,0,0,0,0,,,0,0,0,0,,,0,0,0,0,,,0,0,0,0,,,0,0,0,0,,,0,0,0,0,AAPL
2024-10-22 12:05:03.433478148+00:00,10,41,38,A,B,0,235.15,200,194,60548,75540,234.4,235.15,200,200,0,0,,,0,0,0,0,,,0,0,0,0,,,0,0,0,0,,,0,0,0,0,,,0,0,0,0,,,0,0,0,0,,,0,0,0,0,,,0,0,0,0,,,0,0,0,0,AAPL
2024-10-22 12:05:10.643685750+00:00,10,39,38,C,B,0,232.4,2000,130,203728,38902,,,0,0,0,0,,,0,0,0,0,,,0,0,0,0,,,0,0,0,0,,,0,0,0,0,,,0,0,0,0,,,0,0,0,0,,,0,0,0,0,,,0,0,0,0,,,0,0,0,0,AAPL
2024-10-22 12:05:12.553071116+00:00,10,39,38,A,A,0,237.0,2000,130,203293,38911,,237.0,0,2000,0,1,,,0,0,0,0,,,0,0,0,0,,,0,0,0,0,,,0,0,0,0,,,0,0,0,0,,,0,0,0,0,,,0,0,0,0,,,0,0,0,0,,,0,0,0,0,AAPL
2024-10-22 12:05:19.297626412+00:00,10,39,38,C,A,0,237.0,2000,130,203788,38961,,,0,0,0,0,,,0,0,0,0,,,0,0,0,0,,,0,0,0,0,,,0,0,0,0,,,0,0,0,0,,,0,0,0,0,,,0,0,0,0,,,0,0,0,0,,,0,0,0,0,AAPL
2024-10-22 12:05:19.334165308+00:00,10,39,38,A,A,0,237.0,2000,130,203347,38962,,237.0,0,2000,0,1,,,0,0,0,0,,,0,0,0,0,,,0,0,0,0,,,0,0,0,0,,,0,0,0,0,,,0,0,0,0,,,0,0,0,0,,,0,0,0,0,,,0,0,0,0,AAPL
2024-10-22 12:05:19.748922226+00:00,10,39,38,A,B,0,232.4,2000,130,203666,38963,232.4,237.0,2000,2000,1,1,,,0,0,0,0,,,0,0,0,0,,,0,0,0,0,,,0,0,0,0,,,0,0,0,0,,,0,0,0,0,,,0,0,0,0,,,0,0,0,0,,,0,0,0,0,AAPL
2024-10-22 12:05:19.762652723+00:00,10,39,38,C,B,0,232.4,2000,130,203351,38964,,237.0,0,2000,0,1,,,0,0,0,0,,,0,0,0,0,,,0,0,0,0,,,0,0,0,0,,,0,0,0,0,,,0,0,0,0,,,0,0,0,0,,,0,0,0,0,,,0,0,0,0,AAPL
2024-10-22 12:05:19.781161719+00:00,10,39,38,A,B,0,232.4,2000,130,203282,38965,232.4,237.0,2000,2000,1,1,,,0,0,0,0,,,0,0,0,0,,,0,0,0,0,,,0,0,0,0,,,0,0,0,0,,,0,0,0,0,,,0,0,0,0,,,0,0,0,0,,,0,0,0,0,AAPL
2024-10-22 12:05:23.148757688+00:00,10,39,38,A,B,0,232.6,2000,130,203143,38998,232.6,237.0,2000,2000,1,1,232.4,,2000,0,1,0,,,0,0,0,0,,,0,0,0,0,,,0,0,0,0,,,0,0,0,0,,,0,0,0,0,,,0,0,0,0,,,0,0,0,0,,,0,0,0,0,AAPL
2024-10-22 12:05:23.149487109+00:00,10,39,38,C,B,1,232.4,2000,130,203120,38999,232.6,237.0,2000,2000,1,1,,,0,0,0,0,,,0,0,0,0,,,0,0,0,0,,,0,0,0,0,,,0,0,0,0,,,0,0,0,0,,,0,0,0,0,,,0,0,0,0,,,0,0,0,0,AAPL
2024-10-22 12:05:32.020956092+00:00,10,40,38,A,B,0,235.22,200,194,202775,61720,,235.22,0,200,0,0,,,0,0,0,0,,,0,0,0,0,,,0,0,0,0,,,0,0,0,0,,,0,0,0,0,,,0,0,0,0,,,0,0,0,0,,,0,0,0,0,,,0,0,0,0,AAPL
2024-10-22 12:05:32.021217787+00:00,10,41,38,A,B,0,235.15,200,194,56068,77167,,235.15,0,200,0,0,,,0,0,0,0,,,0,0,0,0,,,0,0,0,0,,,0,0,0,0,,,0,0,0,0,,,0,0,0,0,,,0,0,0,0,,,0,0,0,0,,,0,0,0,0,AAPL
2024-10-22 12:05:32.570894610+00:00,10,41,38,A,B,0,235.15,200,194,60640,77177,234.35,235.15,200,200,0,0,,,0,0,0,0,,,0,0,0,0,,,0,0,0,0,,,0,0,0,0,,,0,0,0,0,,,0,0,0,0,,,0,0,0,0,,,0,0,0,0,,,0,0,0,0,AAPL
2024-10-22 12:05:32.571302509+00:00,10,40,38,A,B,0,235.22,200,194,202471,61723,234.28,235.22,200,200,0,0,,,0,0,0,0,,,0,0,0,0,,,0,0,0,0,,,0,0,0,0,,,0,0,0,0,,,0,0,0,0,,,0,0,0,0,,,0,0,0,0,,,0,0,0,0,AAPL
2024-10-22 12:05:33.271987973+00:00,10,40,38,A,B,0,235.22,200,194,202407,61728,,235.22,0,200,0,0,,,0,0,0,0,,,0,0,0,0,,,0,0,0,0,,,0,0,0,0,,,0,0,0,0,,,0,0,0,0,,,0,0,0,0,,,0,0,0,0,,,0,0,0,0,AAPL
2024-10-22 12:05:33.272699895+00:00,10,41,38,A,B,0,235.15,200,194,55468,77194,,235.15,0,200,0,0,,,0,0,0,0,,,0,0,0,0,,,0,0,0,0,,,0,0,0,0,,,0,0,0,0,,,0,0,0,0,,,0,0,0,0,,,0,0,0,0,,,0,0,0,0,AAPL
2024-10-22 12:05:33.776368776+00:00,10,40,38,A,B,0,235.22,200,194,202501,61730,234.28,235.22,200,200,0,0,,,0,0,0,0,,,0,0,0,0,,,0,0,0,0,,,0,0,0,0,,,0,0,0,0,,,0,0,0,0,,,0,0,0,0,,,0,0,0,0,,,0,0,0,0,AAPL
2024-10-22 12:05:35.026969377+00:00,10,41,38,A,B,0,235.15,200,194,55638,77285,234.35,235.15,200,200,0,0,,,0,0,0,0,,,0,0,0,0,,,0,0,0,0,,,0,0,0,0,,,0,0,0,0,,,0,0,0,0,,,0,0,0,0,,,0,0,0,0,,,0,0,0,0,AAPL
2024-10-22 12:05:35.831110516+00:00,10,40,38,A,B,0,235.22,200,194,202500,61758,,235.22,0,200,0,0,,,0,0,0,0,,,0,0,0,0,,,0,0,0,0,,,0,0,0,0,,,0,0,0,0,,,0,0,0,0,,,0,0,0,0,,,0,0,0,0,,,0,0,0,0,AAPL
2024-10-22 12:05:38.445929514+00:00,10,41,38,A,B,0,235.15,200,194,61073,77357,,235.15,0,200,0,0,,,0,0,0,0,,,0,0,0,0,,,0,0,0,0,,,0,0,0,0,,,0,0,0,0,,,0,0,0,0,,,0,0,0,0,,,0,0,0,0,,,0,0,0,0,AAPL
2024-10-22 12:05:38.713523437+00:00,10,40,38,A,B,0,235.22,200,194,202678,61781,234.28,235.22,200,200,0,0,,,0,0,0,0,,,0,0,0,0,,,0,0,0,0,,,0,0,0,0,,,0,0,0,0,,,0,0,0,0,,,0,0,0,0,,,0,0,0,0,,,0,0,0,0,AAPL
2024-10-22 12:05:38.713574892+00:00,10,40,38,A,B,0,235.22,200,194,202790,61782,,235.22,0,200,0,0,,,0,0,0,0,,,0,0,0,0,,,0,0,0,0,,,0,0,0,0,,,0,0,0,0,,,0,0,0,0,,,0,0,0,0,,,0,0,0,0,,,0,0,0,0,AAPL
2024-10-22 12:05:38.713826910+00:00,10,41,38,A,B,0,235.15,200,194,60637,77360,234.35,235.15,200,200,0,0,,,0,0,0,0,,,0,0,0,0,,,0,0,0,0,,,0,0,0,0,,,0,0,0,0,,,0,0,0,0,,,0,0,0,0,,,0,0,0,0,,,0,0,0,0,AAPL
2024-10-22 12:05:38.714154802+00:00,10,39,38,C,B,0,232.6,2000,130,204188,39104,,237.0,0,2000,0,1,,,0,0,0,0,,,0,0,0,0,,,0,0,0,0,,,0,0,0,0,,,0,0,0,0,,,0,0,0,0,,,0,0,0,0,,,0,0,0,0,,,0,0,0,0,AAPL
2024-10-22 12:05:38.728307283+00:00,10,39,38,A,B,0,232.4,2000,130,203394,39105,232.4,237.0,2000,2000,1,1,,,0,0,0,0,,,0,0,0,0,,,0,0,0,0,,,0,0,0,0,,,0,0,0,0,,,0,0,0,0,,,0,0,0,0,,,0,0,0,0,,,0,0,0,0,AAPL
2024-10-22 12:05:38.931614570+00:00,10,40,38,A,B,0,235.22,200,194,202590,61785,234.27,235.22,200,200,0,0,,,0,0,0,0,,,0,0,0,0,,,0,0,0,0,,,0,0,0,0,,,0,0,0,0,,,0,0,0,0,,,0,0,0,0,,,0,0,0,0,,,0,0,0,0,AAPL
2024-10-22 12:05:39.970400986+00:00,10,40,38,A,B,0,235.22,200,194,202650,61790,,235.22,0,200,0,0,,,0,0,0,0,,,0,0,0,0,,,0,0,0,0,,,0,0,0,0,,,0,0,0,0,,,0,0,0,0,,,0,0,0,0,,,0,0,0,0,,,0,0,0,0,AAPL
2024-10-22 12:05:44.293043108+00:00,10,40,38,A,B,0,235.22,200,194,202253,61823,234.27,235.22,200,200,0,0,,,0,0,0,0,,,0,0,0,0,,,0,0,0,0,,,0,0,0,0,,,0,0,0,0,,,0,0,0,0,,,0,0,0,0,,,0,0,0,0,,,0,0,0,0,AAPL
2024-10-22 12:05:55.939403582+00:00,10,39,38,C,B,0,232.4,2000,130,204438,39163,,237.0,0,2000,0,1,,,0,0,0,0,,,0,0,0,0,,,0,0,0,0,,,0,0,0,0,,,0,0,0,0,,,0,0,0,0,,,0,0,0,0,,,0,0,0,0,,,0,0,0,0,AAPL
2024-10-22 12:05:55.976346499+00:00,10,39,38,A,B,0,232.6,2000,130,204006,39164,232.6,237.0,2000,2000,1,1,,,0,0,0,0,,,0,0,0,0,,,0,0,0,0,,,0,0,0,0,,,0,0,0,0,,,0,0,0,0,,,0,0,0,0,,,0,0,0,0,,,0,0,0,0,AAPL
2024-10-22 12:06:00.048603708+00:00,10,40,38,A,B,0,235.22,200,194,202964,61977,,235.22,0,200,0,0,,,0,0,0,0,,,0,0,0,0,,,0,0,0,0,,,0,0,0,0,,,0,0,0,0,,,0,0,0,0,,,0,0,0,0,,,0,0,0,0,,,0,0,0,0,AAPL
2024-10-22 12:06:00.048714211+00:00,10,40,38,A,A,0,,0,194,202899,61978,,,0,0,0,0,,,0,0,0,0,,,0,0,0,0,,,0,0,0,0,,,0,0,0,0,,,0,0,0,0,,,0,0,0,0,,,0,0,0,0,,,0,0,0,0,,,0,0,0,0,AAPL
2024-10-22 12:06:00.048734441+00:00,10,40,38,A,A,0,235.17,200,194,202924,61979,,235.17,0,200,0,0,,,0,0,0,0,,,0,0,0,0,,,0,0,0,0,,,0,0,0,0,,,0,0,0,0,,,0,0,0,0,,,0,0,0,0,,,0,0,0,0,,,0,0,0,0,AAPL
2024-10-22 12:06:00.049094070+00:00,10,41,38,A,B,0,235.15,200,194,55306,78156,,235.15,0,200,0,0,,,0,0,0,0,,,0,0,0,0,,,0,0,0,0,,,0,0,0,0,,,0,0,0,0,,,0,0,0,0,,,0,0,0,0,,,0,0,0,0,,,0,0,0,0,AAPL
2024-10-22 12:06:00.089853867+00:00,10,40,38,A,A,0,,0,194,202915,62005,,,0,0,0,0,,,0,0,0,0,,,0,0,0,0,,,0,0,0,0,,,0,0,0,0,,,0,0,0,0,,,0,0,0,0,,,0,0,0,0,,,0,0,0,0,,,0,0,0,0,AAPL
2024-10-22 12:06:00.090101867+00:00,10,41,38,A,A,0,,0,194,55665,78254,,,0,0,0,0,,,0,0,0,0,,,0,0,0,0,,,0,0,0,0,,,0,0,0,0,,,0,0,0,0,,,0,0,0,0,,,0,0,0,0,,,0,0,0,0,,,0,0,0,0,AAPL
2024-10-22 12:06:00.350552929+00:00,10,40,38,A,A,0,235.17,200,194,202911,62048,,235.17,0,200,0,0,,,0,0,0,0,,,0,0,0,0,,,0,0,0,0,,,0,0,0,0,,,0,0,0,0,,,0,0,0,0,,,0,0,0,0,,,0,0,0,0,,,0,0,0,0,AAPL
2024-10-22 12:06:00.350838755+00:00,10,41,38,A,A,0,235.1,200,194,55422,78453,,235.1,0,200,0,0,,,0,0,0,0,,,0,0,0,0,,,0,0,0,0,,,0,0,0,0,,,0,0,0,0,,,0,0,0,0,,,0,0,0,0,,,0,0,0,0,,,0,0,0,0,AAPL
2024-10-22 12:06:00.954638080+00:00,10,40,38,A,B,0,235.17,200,194,203047,62073,234.21,235.17,200,200,0,0,,,0,0,0,0,,,0,0,0,0,,,0,0,0,0,,,0,0,0,0,,,0,0,0,0,,,0,0,0,0,,,0,0,0,0,,,0,0,0,0,,,0,0,0,0,AAPL
2024-10-22 12:06:00.954851102+00:00,10,41,38,A,B,0,235.1,200,194,55479,78512,234.28,235.1,200,200,0,0,,,0,0,0,0,,,0,0,0,0,,,0,0,0,0,,,0,0,0,0,,,0,0,0,0,,,0,0,0,0,,,0,0,0,0,,,0,0,0,0,,,0,0,0,0,AAPL
2024-10-22 12:06:11.077748089+00:00,10,39,38,C,A,0,237.0,2000,130,204035,39224,232.6,,2000,0,1,0,,,0,0,0,0,,,0,0,0,0,,,0,0,0,0,,,0,0,0,0,,,0,0,0,0,,,0,0,0,0,,,0,0,0,0,,,0,0,0,0,,,0,0,0,0,AAPL
2024-10-22 12:06:11.089157223+00:00,10,39,38,A,A,0,237.0,2000,130,203950,39225,232.6,237.0,2000,2000,1,1,,,0,0,0,0,,,0,0,0,0,,,0,0,0,0,,,0,0,0,0,,,0,0,0,0,,,0,0,0,0,,,0,0,0,0,,,0,0,0,0,,,0,0,0,0,AAPL
2024-10-22 12:06:13.396073547+00:00,10,39,38,C,A,0,237.0,2000,130,204275,39242,232.6,,2000,0,1,0,,,0,0,0,0,,,0,0,0,0,,,0,0,0,0,,,0,0,0,0,,,0,0,0,0,,,0,0,0,0,,,0,0,0,0,,,0,0,0,0,,,0,0,0,0,AAPL
2024-10-22 12:06:13.483698055+00:00,10,39,38,A,A,0,237.0,2000,130,204055,39243,232.6,237.0,2000,2000,1,1,,,0,0,0,0,,,0,0,0,0,,,0,0,0,0,,,0,0,0,0,,,0,0,0,0,,,0,0,0,0,,,0,0,0,0,,,0,0,0,0,,,0,0,0,0,AAPL
2024-10-22 12:06:13.501177933+00:00,10,39,38,C,A,0,237.0,2000,130,203922,39244,232.6,,2000,0,1,0,,,0,0,0,0,,,0,0,0,0,,,0,0,0,0,,,0,0,0,0,,,0,0,0,0,,,0,0,0,0,,,0,0,0,0,,,0,0,0,0,,,0,0,0,0,AAPL
2024-10-22 12:06:13.524884359+00:00,10,39,38,A,A,0,237.0,2000,130,203951,39245,232.6,237.0,2000,2000,1,1,,,0,0,0,0,,,0,0,0,0,,,0,0,0,0,,,0,0,0,0,,,0,0,0,0,,,0,0,0,0,,,0,0,0,0,,,0,0,0,0,,,0,0,0,0,AAPL
2024-10-22 12:06:36.093055597+00:00,10,39,38,C,A,0,237.0,2000,130,204574,39430,232.6,,2000,0,1,0,,,0,0,0,0,,,0,0,0,0,,,0,0,0,0,,,0,0,0,0,,,0,0,0,0,,,0,0,0,0,,,0,0,0,0,,,0,0,0,0,,,0,0,0,0,AAPL
2024-10-22 12:06:36.128727096+00:00,10,39,38,A,A,0,237.0,2000,130,204571,39431,232.6,237.0,2000,2000,1,1,,,0,0,0,0,,,0,0,0,0,,,0,0,0,0,,,0,0,0,0,,,0,0,0,0,,,0,0,0,0,,,0,0,0,0,,,0,0,0,0,,,0,0,0,0,AAPL
2024-10-22 12:06:40.455881370+00:00,10,39,38,C,B,0,232.6,2000,130,204338,39469,,237.0,0,2000,0,1,,,0,0,0,0,,,0,0,0,0,,,0,0,0,0,,,0,0,0,0,,,0,0,0,0,,,0,0,0,0,,,0,0,0,0,,,0,0,0,0,,,0,0,0,0,AAPL
2024-10-22 12:06:40.466962163+00:00,10,39,38,A,B,0,232.4,2000,130,204198,39470,232.4,237.0,2000,2000,1,1,,,0,0,0,0,,,0,0,0,0,,,0,0,0,0,,,0,0,0,0,,,0,0,0,0,,,0,0,0,0,,,0,0,0,0,,,0,0,0,0,,,0,0,0,0,AAPL
2024-10-22 12:06:54.981623060+00:00,10,39,38,C,A,0,237.0,2000,130,204892,39582,232.4,,2000,0,1,0,,,0,0,0,0,,,0,0,0,0,,,0,0,0,0,,,0,0,0,0,,,0,0,0,0,,,0,0,0,0,,,0,0,0,0,,,0,0,0,0,,,0,0,0,0,AAPL
2024-10-22 12:06:54.982930295+00:00,10,39,38,C,B,0,232.4,2000,130,204388,39583,,,0,0,0,0,,,0,0,0,0,,,0,0,0,0,,,0,0,0,0,,,0,0,0,0,,,0,0,0,0,,,0,0,0,0,,,0,0,0,0,,,0,0,0,0,,,0,0,0,0,AAPL
2024-10-22 12:06:55.004333613+00:00,10,39,38,A,B,0,232.4,2000,130,204584,39585,232.4,,2000,0,1,0,,,0,0,0,0,,,0,0,0,0,,,0,0,0,0,,,0,0,0,0,,,0,0,0,0,,,0,0,0,0,,,0,0,0,0,,,0,0,0,0,,,0,0,0,0,AAPL
2024-10-22 12:06:55.017886911+00:00,10,39,38,A,A,0,237.0,2000,130,204440,39587,232.4,237.0,2000,2000,1,1,,,0,0,0,0,,,0,0,0,0,,,0,0,0,0,,,0,0,0,0,,,0,0,0,0,,,0,0,0,0,,,0,0,0,0,,,0,0,0,0,,,0,0,0,0,AAPL
2024-10-22 12:06:55.020655526+00:00,10,39,38,A,B,0,232.6,2000,130,204391,39588,232.6,237.0,2000,2000,1,1,232.4,,2000,0,1,0,,,0,0,0,0,,,0,0,0,0,,,0,0,0,0,,,0,0,0,0,,,0,0,0,0,,,0,0,0,0,,,0,0,0,0,,,0,0,0,0,AAPL
2024-10-22 12:06:55.021109061+00:00,10,39,38,C,B,1,232.4,2000,130,204362,39589,232.6,237.0,2000,2000,1,1,,,0,0,0,0,,,0,0,0,0,,,0,0,0,0,,,0,0,0,0,,,0,0,0,0,,,0,0,0,0,,,0,0,0,0,,,0,0,0,0,,,0,0,0,0,AAPL
2024-10-22 12:06:56.566794377+00:00,10,39,38,C,A,0,237.0,2000,130,204561,39597,232.6,,2000,0,1,0,,,0,0,0,0,,,0,0,0,0,,,0,0,0,0,,,0,0,0,0,,,0,0,0,0,,,0,0,0,0,,,0,0,0,0,,,0,0,0,0,,,0,0,0,0,AAPL
2024-10-22 12:06:56.567743025+00:00,10,39,38,C,B,0,232.6,2000,130,204543,39598,,,0,0,0,0,,,0,0,0,0,,,0,0,0,0,,,0,0,0,0,,,0,0,0,0,,,0,0,0,0,,,0,0,0,0,,,0,0,0,0,,,0,0,0,0,,,0,0,0,0,AAPL
2024-10-22 12:06:56.578614241+00:00,10,39,38,A,B,0,232.4,2000,130,204600,39599,232.4,,2000,0,1,0,,,0,0,0,0,,,0,0,0,0,,,0,0,0,0,,,0,0,0,0,,,0,0,0,0,,,0,0,0,0,,,0,0,0,0,,,0,0,0,0,,,0,0,0,0,AAPL
2024-10-22 12:06:56.603349788+00:00,10,39,38,A,A,0,237.0,2000,130,204626,39600,232.4,237.0,2000,2000,1,1,,,0,0,0,0,,,0,0,0,0,,,0,0,0,0,,,0,0,0,0,,,0,0,0,0,,,0,0,0,0,,,0,0,0,0,,,0,0,0,0,,,0,0,0,0,AAPL
2024-10-22 12:06:56.611827317+00:00,10,39,38,A,B,0,232.6,2000,130,204468,39601,232.6,237.0,2000,2000,1,1,232.4,,2000,0,1,0,,,0,0,0,0,,,0,0,0,0,,,0,0,0,0,,,0,0,0,0,,,0,0,0,0,,,0,0,0,0,,,0,0,0,0,,,0,0,0,0,AAPL
2024-10-22 12:06:56.612481066+00:00,10,39,38,C,B,1,232.4,2000,130,204461,39602,232.6,237.0,2000,2000,1,1,,,0,0,0,0,,,0,0,0,0,,,0,0,0,0,,,0,0,0,0,,,0,0,0,0,,,0,0,0,0,,,0,0,0,0,,,0,0,0,0,,,0,0,0,0,AAPL
2024-10-22 12:06:57.954646976+00:00,10,39,38,C,A,0,237.0,2000,130,204460,39612,232.6,,2000,0,1,0,,,0,0,0,0,,,0,0,0,0,,,0,0,0,0,,,0,0,0,0,,,0,0,0,0,,,0,0,0,0,,,0,0,0,0,,,0,0,0,0,,,0,0,0,0,AAPL
2024-10-22 12:06:57.990495646+00:00,10,39,38,A,A,0,237.0,2000,130,204539,39619,232.6,237.0,2000,2000,1,1,,,0,0,0,0,,,0,0,0,0,,,0,0,0,0,,,0,0,0,0,,,0,0,0,0,,,0,0,0,0,,,0,0,0,0,,,0,0,0,0,,,0,0,0,0,AAPL
2024-10-22 12:06:58.014844693+00:00,10,39,38,C,B,0,232.6,2000,130,204545,39621,,237.0,0,2000,0,1,,,0,0,0,0,,,0,0,0,0,,,0,0,0,0,,,0,0,0,0,,,0,0,0,0,,,0,0,0,0,,,0,0,0,0,,,0,0,0,0,,,0,0,0,0,AAPL
2024-10-22 12:07:00.058922683+00:00,10,40,38,A,A,0,,0,194,203139,62816,234.21,,200,0,0,0,,,0,0,0,0,,,0,0,0,0,,,0,0,0,0,,,0,0,0,0,,,0,0,0,0,,,0,0,0,0,,,0,0,0,0,,,0,0,0,0,,,0,0,0,0,AAPL
2024-10-22 12:07:00.059168863+00:00,10,41,38,A,A,0,,0,194,56737,81013,234.28,,200,0,0,0,,,0,0,0,0,,,0,0,0,0,,,0,0,0,0,,,0,0,0,0,,,0,0,0,0,,,0,0,0,0,,,0,0,0,0,,,0,0,0,0,,,0,0,0,0,AAPL
2024-10-22 12:07:00.450076285+00:00,10,40,38,A,A,0,235.12,200,194,202961,62869,234.21,235.12,200,200,0,0,,,0,0,0,0,,,0,0,0,0,,,0,0,0,0,,,0,0,0,0,,,0,0,0,0,,,0,0,0,0,,,0,0,0,0,,,0,0,0,0,,,0,0,0,0,AAPL
2024-10-22 12:07:00.941930072+00:00,10,41,38,A,A,0,235.05,200,194,55935,81462,234.28,235.05,200,200,0,0,,,0,0,0,0,,,0,0,0,0,,,0,0,0,0,,,0,0,0,0,,,0,0,0,0,,,0,0,0,0,,,0,0,0,0,,,0,0,0,0,,,0,0,0,0,AAPL
2024-10-22 12:07:07.863549907+00:00,10,39,38,C,A,0,237.0,2000,130,203801,39738,,,0,0,0,0,,,0,0,0,0,,,0,0,0,0,,,0,0,0,0,,,0,0,0,0,,,0,0,0,0,,,0,0,0,0,,,0,0,0,0,,,0,0,0,0,,,0,0,0,0,AAPL
2024-10-22 12:07:07.873741865+00:00,10,39,38,A,B,0,232.6,2000,130,203669,39739,232.6,,2000,0,1,0,,,0,0,0,0,,,0,0,0,0,,,0,0,0,0,,,0,0,0,0,,,0,0,0,0,,,0,0,0,0,,,0,0,0,0,,,0,0,0,0,,,0,0,0,0,AAPL
2024-10-22 12:07:07.900543667+00:00,10,39,38,A,A,0,237.0,2000,130,203735,39740,232.6,237.0,2000,2000,1,1,,,0,0,0,0,,,0,0,0,0,,,0,0,0,0,,,0,0,0,0,,,0,0,0,0,,,0,0,0,0,,,0,0,0,0,,,0,0,0,0,,,0,0,0,0,AAPL
2024-10-22 12:07:08.318852984+00:00,10,39,38,C,A,0,237.0,2000,130,203797,39744,232.6,,2000,0,1,0,,,0,0,0,0,,,0,0,0,0,,,0,0,0,0,,,0,0,0,0,,,0,0,0,0,,,0,0,0,0,,,0,0,0,0,,,0,0,0,0,,,0,0,0,0,AAPL
2024-10-22 12:07:08.355041508+00:00,10,39,38,A,A,0,237.0,2000,130,203642,39745,232.6,237.0,2000,2000,1,1,,,0,0,0,0,,,0,0,0,0,,,0,0,0,0,,,0,0,0,0,,,0,0,0,0,,,0,0,0,0,,,0,0,0,0,,,0,0,0,0,,,0,0,0,0,AAPL
2024-10-22 12:07:10.720847041+00:00,10,39,38,C,A,0,237.0,2000,130,203570,39753,232.6,,2000,0,1,0,,,0,0,0,0,,,0,0,0,0,,,0,0,0,0,,,0,0,0,0,,,0,0,0,0,,,0,0,0,0,,,0,0,0,0,,,0,0,0,0,,,0,0,0,0,AAPL
2024-10-22 12:07:10.756819236+00:00,10,39,38,A,A,0,237.0,2000,130,203636,39755,232.6,237.0,2000,2000,1,1,,,0,0,0,0,,,0,0,0,0,,,0,0,0,0,,,0,0,0,0,,,0,0,0,0,,,0,0,0,0,,,0,0,0,0,,,0,0,0,0,,,0,0,0,0,AAPL
2024-10-22 12:07:14.928064733+00:00,10,40,38,A,N,0,,0,194,202941,63160,,,0,0,0,0,,,0,0,0,0,,,0,0,0,0,,,0,0,0,0,,,0,0,0,0,,,0,0,0,0,,,0,0,0,0,,,0,0,0,0,,,0,0,0,0,,,0,0,0,0,AAPL
2024-10-22 12:07:14.930014315+00:00,10,41,38,A,A,0,,0,194,54907,82369,234.28,,200,0,0,0,,,0,0,0,0,,,0,0,0,0,,,0,0,0,0,,,0,0,0,0,,,0,0,0,0,,,0,0,0,0,,,0,0,0,0,,,0,0,0,0,,,0,0,0,0,AAPL
2024-10-22 12:07:14.930015960+00:00,10,41,38,A,B,0,,0,194,54307,82370,,,0,0,0,0,,,0,0,0,0,,,0,0,0,0,,,0,0,0,0,,,0,0,0,0,,,0,0,0,0,,,0,0,0,0,,,0,0,0,0,,,0,0,0,0,,,0,0,0,0,AAPL
2024-10-22 12:07:19.953393235+00:00,10,40,38,A,B,0,,0,194,203271,63230,234.27,,200,0,0,0,,,0,0,0,0,,,0,0,0,0,,,0,0,0,0,,,0,0,0,0,,,0,0,0,0,,,0,0,0,0,,,0,0,0,0,,,0,0,0,0,,,0,0,0,0,AAPL
2024-10-22 12:07:19.953400144+00:00,10,40,38,A,A,0,235.12,200,194,203100,63231,234.27,235.12,200,200,0,0,,,0,0,0,0,,,0,0,0,0,,,0,0,0,0,,,0,0,0,0,,,0,0,0,0,,,0,0,0,0,,,0,0,0,0,,,0,0,0,0,,,0,0,0,0,AAPL
2024-10-22 12:07:19.953748442+00:00,10,41,38,A,B,0,,0,194,55806,82811,234.34,,200,0,0,0,,,0,0,0,0,,,0,0,0,0,,,0,0,0,0,,,0,0,0,0,,,0,0,0,0,,,0,0,0,0,,,0,0,0,0,,,0,0,0,0,,,0,0,0,0,AAPL
2024-10-22 12:07:19.953755935+00:00,10,41,38,A,A,0,235.05,200,194,54545,82812,234.34,235.05,200,200,0,0,,,0,0,0,0,,,0,0,0,0,,,0,0,0,0,,,0,0,0,0,,,0,0,0,0,,,0,0,0,0,,,0,0,0,0,,,0,0,0,0,,,0,0,0,0,AAPL
2024-10-22 12:07:20.055813068+00:00,10,39,38,C,B,0,232.6,2000,130,204314,39842,,237.0,0,2000,0,1,,,0,0,0,0,,,0,0,0,0,,,0,0,0,0,,,0,0,0,0,,,0,0,0,0,,,0,0,0,0,,,0,0,0,0,,,0,0,0,0,,,0,0,0,0,AAPL
2024-10-22 12:07:20.066669474+00:00,10,39,38,A,B,0,232.6,2000,130,203867,39843,232.6,237.0,2000,2000,1,1,,,0,0,0,0,,,0,0,0,0,,,0,0,0,0,,,0,0,0,0,,,0,0,0,0,,,0,0,0,0,,,0,0,0,0,,,0,0,0,0,,,0,0,0,0,AAPL
2024-10-22 12:07:34.028410178+00:00,10,39,38,C,B,0,232.6,2000,130,204068,39958,,237.0,0,2000,0,1,,,0,0,0,0,,,0,0,0,0,,,0,0,0,0,,,0,0,0,0,,,0,0,0,0,,,0,0,0,0,,,0,0,0,0,,,0,0,0,0,,,0,0,0,0,AAPL
2024-10-22 12:07:34.070323788+00:00,10,39,38,A,B,0,232.6,2000,130,203782,39959,232.6,237.0,2000,2000,1,1,,,0,0,0,0,,,0,0,0,0,,,0,0,0,0,,,0,0,0,0,,,0,0,0,0,,,0,0,0,0,,,0,0,0,0,,,0,0,0,0,,,0,0,0,0,AAPL
2024-10-22 12:07:34.217763698+00:00,10,39,38,C,B,0,232.6,2000,130,203843,39960,,237.0,0,2000,0,1,,,0,0,0,0,,,0,0,0,0,,,0,0,0,0,,,0,0,0,0,,,0,0,0,0,,,0,0,0,0,,,0,0,0,0,,,0,0,0,0,,,0,0,0,0,AAPL
2024-10-22 12:07:34.232713827+00:00,10,39,38,A,B,0,232.6,2000,130,203724,39961,232.6,237.0,2000,2000,1,1,,,0,0,0,0,,,0,0,0,0,,,0,0,0,0,,,0,0,0,0,,,0,0,0,0,,,0,0,0,0,,,0,0,0,0,,,0,0,0,0,,,0,0,0,0,AAPL
2024-10-22 12:07:43.172131867+00:00,10,39,38,C,B,0,232.6,2000,130,203860,40037,,237.0,0,2000,0,1,,,0,0,0,0,,,0,0,0,0,,,0,0,0,0,,,0,0,0,0,,,0,0,0,0,,,0,0,0,0,,,0,0,0,0,,,0,0,0,0,,,0,0,0,0,AAPL
2024-10-22 12:07:43.183339195+00:00,10,39,38,A,B,0,232.6,2000,130,203368,40038,232.6,237.0,2000,2000,1,1,,,0,0,0,0,,,0,0,0,0,,,0,0,0,0,,,0,0,0,0,,,0,0,0,0,,,0,0,0,0,,,0,0,0,0,,,0,0,0,0,,,0,0,0,0,AAPL
2024-10-22 12:07:54.767541439+00:00,10,39,38,C,B,0,232.6,2000,130,202724,40173,,237.0,0,2000,0,1,,,0,0,0,0,,,0,0,0,0,,,0,0,0,0,,,0,0,0,0,,,0,0,0,0,,,0,0,0,0,,,0,0,0,0,,,0,0,0,0,,,0,0,0,0,AAPL
2024-10-22 12:07:54.812643957+00:00,10,39,38,A,B,0,232.4,2000,130,202759,40174,232.4,237.0,2000,2000,1,1,,,0,0,0,0,,,0,0,0,0,,,0,0,0,0,,,0,0,0,0,,,0,0,0,0,,,0,0,0,0,,,0,0,0,0,,,0,0,0,0,,,0,0,0,0,AAPL
2024-10-22 12:07:54.835829799+00:00,10,39,38,C,B,0,232.4,2000,130,202730,40175,,237.0,0,2000,0,1,,,0,0,0,0,,,0,0,0,0,,,0,0,0,0,,,0,0,0,0,,,0,0,0,0,,,0,0,0,0,,,0,0,0,0,,,0,0,0,0,,,0,0,0,0,AAPL
2024-10-22 12:07:54.867797366+00:00,10,39,38,A,B,0,232.4,2000,130,202832,40176,232.4,237.0,2000,2000,1,1,,,0,0,0,0,,,0,0,0,0,,,0,0,0,0,,,0,0,0,0,,,0,0,0,0,,,0,0,0,0,,,0,0,0,0,,,0,0,0,0,,,0,0,0,0,AAPL
2024-10-22 12:07:55.933801609+00:00,10,39,38,A,B,0,232.6,2000,130,203507,40178,232.6,237.0,2000,2000,1,1,232.4,,2000,0,1,0,,,0,0,0,0,,,0,0,0,0,,,0,0,0,0,,,0,0,0,0,,,0,0,0,0,,,0,0,0,0,,,0,0,0,0,,,0,0,0,0,AAPL
2024-10-22 12:07:55.934000596+00:00,10,39,38,C,B,1,232.4,2000,130,202806,40179,232.6,237.0,2000,2000,1,1,,,0,0,0,0,,,0,0,0,0,,,0,0,0,0,,,0,0,0,0,,,0,0,0,0,,,0,0,0,0,,,0,0,0,0,,,0,0,0,0,,,0,0,0,0,AAPL
2024-10-22 12:07:55.960305247+00:00,10,39,38,C,B,0,232.6,2000,130,202729,40180,,237.0,0,2000,0,1,,,0,0,0,0,,,0,0,0,0,,,0,0,0,0,,,0,0,0,0,,,0,0,0,0,,,0,0,0,0,,,0,0,0,0,,,0,0,0,0,,,0,0,0,0,AAPL
2024-10-22 12:07:55.973481910+00:00,10,39,38,A,B,0,232.6,2000,130,202777,40181,232.6,237.0,2000,2000,1,1,,,0,0,0,0,,,0,0,0,0,,,0,0,0,0,,,0,0,0,0,,,0,0,0,0,,,0,0,0,0,,,0,0,0,0,,,0,0,0,0,,,0,0,0,0,AAPL
2024-10-22 12:07:55.986901242+00:00,10,39,38,C,B,0,232.6,2000,130,202786,40182,,237.0,0,2000,0,1,,,0,0,0,0,,,0,0,0,0,,,0,0,0,0,,,0,0,0,0,,,0,0,0,0,,,0,0,0,0,,,0,0,0,0,,,0,0,0,0,,,0,0,0,0,AAPL
2024-10-22 12:08:00.083073382+00:00,10,40,38,A,B,0,235.12,200,194,202208,63763,,235.12,0,200,0,0,,,0,0,0,0,,,0,0,0,0,,,0,0,0,0,,,0,0,0,0,,,0,0,0,0,,,0,0,0,0,,,0,0,0,0,,,0,0,0,0,,,0,0,0,0,AAPL
2024-10-22 12:08:00.083389658+00:00,10,41,38,A,B,0,235.05,200,194,57138,84589,,235.05,0,200,0,0,,,0,0,0,0,,,0,0,0,0,,,0,0,0,0,,,0,0,0,0,,,0,0,0,0,,,0,0,0,0,,,0,0,0,0,,,0,0,0,0,,,0,0,0,0,AAPL
2024-10-22 12:08:00.850080094+00:00,10,40,38,A,B,0,235.12,200,194,202217,63804,234.27,235.12,200,200,0,0,,,0,0,0,0,,,0,0,0,0,,,0,0,0,0,,,0,0,0,0,,,0,0,0,0,,,0,0,0,0,,,0,0,0,0,,,0,0,0,0,,,0,0,0,0,AAPL
2024-10-22 12:08:00.850612877+00:00,10,41,38,A,B,0,235.05,200,194,55911,84827,234.34,235.05,200,200,0,0,,,0,0,0,0,,,0,0,0,0,,,0,0,0,0,,,0,0,0,0,,,0,0,0,0,,,0,0,0,0,,,0,0,0,0,,,0,0,0,0,,,0,0,0,0,AAPL
2024-10-22 12:08:00.850625619+00:00,10,41,38,A,B,0,235.05,200,194,59119,84828,,235.05,0,200,0,0,,,0,0,0,0,,,0,0,0,0,,,0,0,0,0,,,0,0,0,0,,,0,0,0,0,,,0,0,0,0,,,0,0,0,0,,,0,0,0,0,,,0,0,0,0,AAPL
2024-10-22 12:08:00.923023683+00:00,10,40,38,A,B,0,235.12,200,194,202202,63806,,235.12,0,200,0,0,,,0,0,0,0,,,0,0,0,0,,,0,0,0,0,,,0,0,0,0,,,0,0,0,0,,,0,0,0,0,,,0,0,0,0,,,0,0,0,0,,,0,0,0,0,AAPL
2024-10-22 12:08:01.596362304+00:00,10,40,38,A,B,0,235.12,200,194,202325,63809,234.27,235.12,200,200,0,0,,,0,0,0,0,,,0,0,0,0,,,0,0,0,0,,,0,0,0,0,,,0,0,0,0,,,0,0,0,0,,,0,0,0,0,,,0,0,0,0,,,0,0,0,0,AAPL
2024-10-22 12:08:02.699039539+00:00,10,41,38,A,B,0,235.05,200,194,55625,84927,234.34,235.05,200,200,0,0,,,0,0,0,0,,,0,0,0,0,,,0,0,0,0,,,0,0,0,0,,,0,0,0,0,,,0,0,0,0,,,0,0,0,0,,,0,0,0,0,,,0,0,0,0,AAPL
2024-10-22 12:08:03.871495147+00:00,10,39,38,C,A,0,237.0,2000,130,203374,40233,,,0,0,0,0,,,0,0,0,0,,,0,0,0,0,,,0,0,0,0,,,0,0,0,0,,,0,0,0,0,,,0,0,0,0,,,0,0,0,0,,,0,0,0,0,,,0,0,0,0,AAPL
2024-10-22 12:08:03.908073696+00:00,10,39,38,A,A,0,237.0,2000,130,203415,40234,,237.0,0,2000,0,1,,,0,0,0,0,,,0,0,0,0,,,0,0,0,0,,,0,0,0,0,,,0,0,0,0,,,0,0,0,0,,,0,0,0,0,,,0,0,0,0,,,0,0,0,0,AAPL
2024-10-22 12:08:04.702026905+00:00,10,39,38,C,A,0,237.0,2000,130,203433,40237,,,0,0,0,0,,,0,0,0,0,,,0,0,0,0,,,0,0,0,0,,,0,0,0,0,,,0,0,0,0,,,0,0,0,0,,,0,0,0,0,,,0,0,0,0,,,0,0,0,0,AAPL
2024-10-22 12:08:04.737871042+00:00,10,39,38,A,A,0,237.0,2000,130,203209,40238,,237.0,0,2000,0,1,,,0,0,0,0,,,0,0,0,0,,,0,0,0,0,,,0,0,0,0,,,0,0,0,0,,,0,0,0,0,,,0,0,0,0,,,0,0,0,0,,,0,0,0,0,AAPL
2024-10-22 12:08:05.340252690+00:00,10,39,38,A,B,0,232.4,2000,130,202984,40247,232.4,237.0,2000,2000,1,1,,,0,0,0,0,,,0,0,0,0,,,0,0,0,0,,,0,0,0,0,,,0,0,0,0,,,0,0,0,0,,,0,0,0,0,,,0,0,0,0,,,0,0,0,0,AAPL
2024-10-22 12:08:07.495058731+00:00,10,39,38,A,B,0,232.6,2000,130,203564,40264,232.6,237.0,2000,2000,1,1,232.4,,2000,0,1,0,,,0,0,0,0,,,0,0,0,0,,,0,0,0,0,,,0,0,0,0,,,0,0,0,0,,,0,0,0,0,,,0,0,0,0,,,0,0,0,0,AAPL
2024-10-22 12:08:07.495239380+00:00,10,39,38,C,B,1,232.4,2000,130,203133,40265,232.6,237.0,2000,2000,1,1,,,0,0,0,0,,,0,0,0,0,,,0,0,0,0,,,0,0,0,0,,,0,0,0,0,,,0,0,0,0,,,0,0,0,0,,,0,0,0,0,,,0,0,0,0,AAPL
2024-10-22 12:08:07.521504349+00:00,10,39,38,C,B,0,232.6,2000,130,203098,40266,,237.0,0,2000,0,1,,,0,0,0,0,,,0,0,0,0,,,0,0,0,0,,,0,0,0,0,,,0,0,0,0,,,0,0,0,0,,,0,0,0,0,,,0,0,0,0,,,0,0,0,0,AAPL
2024-10-22 12:08:07.532617019+00:00,10,39,38,A,B,0,232.4,2000,130,203162,40267,232.4,237.0,2000,2000,1,1,,,0,0,0,0,,,0,0,0,0,,,0,0,0,0,,,0,0,0,0,,,0,0,0,0,,,0,0,0,0,,,0,0,0,0,,,0,0,0,0,,,0,0,0,0,AAPL
2024-10-22 12:08:07.548773198+00:00,10,39,38,C,B,0,232.4,2000,130,203113,40268,,237.0,0,2000,0,1,,,0,0,0,0,,,0,0,0,0,,,0,0,0,0,,,0,0,0,0,,,0,0,0,0,,,0,0,0,0,,,0,0,0,0,,,0,0,0,0,,,0,0,0,0,AAPL
2024-10-22 12:08:15.721963188+00:00,10,39,38,C,A,0,237.0,2000,130,203820,40295,,,0,0,0,0,,,0,0,0,0,,,0,0,0,0,,,0,0,0,0,,,0,0,0,0,,,0,0,0,0,,,0,0,0,0,,,0,0,0,0,,,0,0,0,0,,,0,0,0,0,AAPL
2024-10-22 12:08:15.757511823+00:00,10,39,38,A,A,0,237.0,2000,130,203407,40298,,237.0,0,2000,0,1,,,0,0,0,0,,,0,0,0,0,,,0,0,0,0,,,0,0,0,0,,,0,0,0,0,,,0,0,0,0,,,0,0,0,0,,,0,0,0,0,,,0,0,0,0,AAPL
2024-10-22 12:08:21.223070773+00:00,10,39,38,C,A,0,237.0,2000,130,203337,40342,,,0,0,0,0,,,0,0,0,0,,,0,0,0,0,,,0,0,0,0,,,0,0,0,0,,,0,0,0,0,,,0,0,0,0,,,0,0,0,0,,,0,0,0,0,,,0,0,0,0,AAPL
2024-10-22 12:08:21.259536066+00:00,10,39,38,A,A,0,237.0,2000,130,203222,40343,,237.0,0,2000,0,1,,,0,0,0,0,,,0,0,0,0,,,0,0,0,0,,,0,0,0,0,,,0,0,0,0,,,0,0,0,0,,,0,0,0,0,,,0,0,0,0,,,0,0,0,0,AAPL
2024-10-22 12:08:29.065587282+00:00,10,39,38,A,B,0,232.4,2000,130,203565,40441,232.4,237.0,2000,2000,1,1,,,0,0,0,0,,,0,0,0,0,,,0,0,0,0,,,0,0,0,0,,,0,0,0,0,,,0,0,0,0,,,0,0,0,0,,,0,0,0,0,,,0,0,0,0,AAPL
2024-10-22 12:08:29.080616538+00:00,10,39,38,A,B,0,232.6,2000,130,203130,40442,232.6,237.0,2000,2000,1,1,232.4,,2000,0,1,0,,,0,0,0,0,,,0,0,0,0,,,0,0,0,0,,,0,0,0,0,,,0,0,0,0,,,0,0,0,0,,,0,0,0,0,,,0,0,0,0,AAPL
2024-10-22 12:08:29.080801919+00:00,10,39,38,C,B,1,232.4,2000,130,203164,40443,232.6,237.0,2000,2000,1,1,,,0,0,0,0,,,0,0,0,0,,,0,0,0,0,,,0,0,0,0,,,0,0,0,0,,,0,0,0,0,,,0,0,0,0,,,0,0,0,0,,,0,0,0,0,AAPL
2024-10-22 12:08:29.132603844+00:00,10,39,38,C,B,0,232.6,2000,130,203091,40444,,237.0,0,2000,0,1,,,0,0,0,0,,,0,0,0,0,,,0,0,0,0,,,0,0,0,0,,,0,0,0,0,,,0,0,0,0,,,0,0,0,0,,,0,0,0,0,,,0,0,0,0,AAPL
2024-10-22 12:08:36.206771788+00:00,10,39,38,C,A,0,237.0,2000,130,203433,40510,,,0,0,0,0,,,0,0,0,0,,,0,0,0,0,,,0,0,0,0,,,0,0,0,0,,,0,0,0,0,,,0,0,0,0,,,0,0,0,0,,,0,0,0,0,,,0,0,0,0,AAPL
2024-10-22 12:08:36.216880546+00:00,10,39,38,A,B,0,232.6,2000,130,203252,40511,232.6,,2000,0,1,0,,,0,0,0,0,,,0,0,0,0,,,0,0,0,0,,,0,0,0,0,,,0,0,0,0,,,0,0,0,0,,,0,0,0,0,,,0,0,0,0,,,0,0,0,0,AAPL
2024-10-22 12:08:36.242870306+00:00,10,39,38,A,A,0,237.0,2000,130,203466,40512,232.6,237.0,2000,2000,1,1,,,0,0,0,0,,,0,0,0,0,,,0,0,0,0,,,0,0,0,0,,,0,0,0,0,,,0,0,0,0,,,0,0,0,0,,,0,0,0,0,,,0,0,0,0,AAPL
2024-10-22 12:09:00.093051307+00:00,10,40,38,A,B,0,235.12,200,194,201910,64328,,235.12,0,200,0,0,,,0,0,0,0,,,0,0,0,0,,,0,0,0,0,,,0,0,0,0,,,0,0,0,0,,,0,0,0,0,,,0,0,0,0,,,0,0,0,0,,,0,0,0,0,AAPL
2024-10-22 12:09:00.093687088+00:00,10,41,38,A,B,0,235.05,200,194,54854,86908,,235.05,0,200,0,0,,,0,0,0,0,,,0,0,0,0,,,0,0,0,0,,,0,0,0,0,,,0,0,0,0,,,0,0,0,0,,,0,0,0,0,,,0,0,0,0,,,0,0,0,0,AAPL
2024-10-22 12:09:00.934597468+00:00,10,40,38,A,B,0,235.12,200,194,201936,64370,234.23,235.12,200,200,0,0,,,0,0,0,0,,,0,0,0,0,,,0,0,0,0,,,0,0,0,0,,,0,0,0,0,,,0,0,0,0,,,0,0,0,0,,,0,0,0,0,,,0,0,0,0,AAPL
2024-10-22 12:09:00.934891765+00:00,10,41,38,A,B,0,235.05,200,194,55482,87111,234.3,235.05,200,200,0,0,,,0,0,0,0,,,0,0,0,0,,,0,0,0,0,,,0,0,0,0,,,0,0,0,0,,,0,0,0,0,,,0,0,0,0,,,0,0,0,0,,,0,0,0,0,AAPL
2024-10-22 12:09:02.365341901+00:00,10,40,38,A,B,0,235.12,200,194,201968,64382,,235.12,0,200,0,0,,,0,0,0,0,,,0,0,0,0,,,0,0,0,0,,,0,0,0,0,,,0,0,0,0,,,0,0,0,0,,,0,0,0,0,,,0,0,0,0,,,0,0,0,0,AAPL
2024-10-22 12:09:02.365528094+00:00,10,41,38,A,B,0,235.05,200,194,56422,87227,,235.05,0,200,0,0,,,0,0,0,0,,,0,0,0,0,,,0,0,0,0,,,0,0,0,0,,,0,0,0,0,,,0,0,0,0,,,0,0,0,0,,,0,0,0,0,,,0,0,0,0,AAPL
2024-10-22 12:09:02.769231922+00:00,10,40,38,A,B,0,235.12,200,194,202143,64383,234.23,235.12,200,200,0,0,,,0,0,0,0,,,0,0,0,0,,,0,0,0,0,,,0,0,0,0,,,0,0,0,0,,,0,0,0,0,,,0,0,0,0,,,0,0,0,0,,,0,0,0,0,AAPL
2024-10-22 12:09:02.769739084+00:00,10,41,38,A,B,0,235.05,200,194,55419,87271,234.3,235.05,200,200,0,0,,,0,0,0,0,,,0,0,0,0,,,0,0,0,0,,,0,0,0,0,,,0,0,0,0,,,0,0,0,0,,,0,0,0,0,,,0,0,0,0,,,0,0,0,0,AAPL
2024-10-22 12:09:14.083533548+00:00,10,39,38,C,B,0,232.6,2000,130,204157,40730,,237.0,0,2000,0,1,,,0,0,0,0,,,0,0,0,0,,,0,0,0,0,,,0,0,0,0,,,0,0,0,0,,,0,0,0,0,,,0,0,0,0,,,0,0,0,0,,,0,0,0,0,AAPL
2024-10-22 12:09:14.094288578+00:00,10,39,38,A,B,0,232.4,2000,130,204072,40731,232.4,237.0,2000,2000,1,1,,,0,0,0,0,,,0,0,0,0,,,0,0,0,0,,,0,0,0,0,,,0,0,0,0,,,0,0,0,0,,,0,0,0,0,,,0,0,0,0,,,0,0,0,0,AAPL
2024-10-22 12:09:37.398998719+00:00,10,39,38,C,B,0,232.4,2000,130,203787,40826,,237.0,0,2000,0,1,,,0,0,0,0,,,0,0,0,0,,,0,0,0,0,,,0,0,0,0,,,0,0,0,0,,,0,0,0,0,,,0,0,0,0,,,0,0,0,0,,,0,0,0,0,AAPL
2024-10-22 12:09:37.416201810+00:00,10,39,38,A,B,0,232.4,2000,130,203796,40827,232.4,237.0,2000,2000,1,1,,,0,0,0,0,,,0,0,0,0,,,0,0,0,0,,,0,0,0,0,,,0,0,0,0,,,0,0,0,0,,,0,0,0,0,,,0,0,0,0,,,0,0,0,0,AAPL
2024-10-22 12:09:38.518073274+00:00,10,39,38,C,A,0,237.0,2000,130,203823,40833,232.4,,2000,0,1,0,,,0,0,0,0,,,0,0,0,0,,,0,0,0,0,,,0,0,0,0,,,0,0,0,0,,,0,0,0,0,,,0,0,0,0,,,0,0,0,0,,,0,0,0,0,AAPL
2024-10-22 12:09:38.528513557+00:00,10,39,38,A,B,0,232.6,2000,130,203808,40834,232.6,,2000,0,1,0,232.4,,2000,0,1,0,,,0,0,0,0,,,0,0,0,0,,,0,0,0,0,,,0,0,0,0,,,0,0,0,0,,,0,0,0,0,,,0,0,0,0,,,0,0,0,0,AAPL
2024-10-22 12:09:38.528695868+00:00,10,39,38,C,B,1,232.4,2000,130,203718,40835,232.6,,2000,0,1,0,,,0,0,0,0,,,0,0,0,0,,,0,0,0,0,,,0,0,0,0,,,0,0,0,0,,,0,0,0,0,,,0,0,0,0,,,0,0,0,0,,,0,0,0,0,AAPL
2024-10-22 12:09:38.555163329+00:00,10,39,38,A,A,0,237.0,2000,130,203777,40836,232.6,237.0,2000,2000,1,1,,,0,0,0,0,,,0,0,0,0,,,0,0,0,0,,,0,0,0,0,,,0,0,0,0,,,0,0,0,0,,,0,0,0,0,,,0,0,0,0,,,0,0,0,0,AAPL
2024-10-22 12:09:57.539703052+00:00,10,39,38,C,A,0,237.0,2000,130,203368,40917,232.6,,2000,0,1,0,,,0,0,0,0,,,0,0,0,0,,,0,0,0,0,,,0,0,0,0,,,0,0,0,0,,,0,0,0,0,,,0,0,0,0,,,0,0,0,0,,,0,0,0,0,AAPL
2024-10-22 12:09:57.576516443+00:00,10,39,38,A,A,0,237.0,2000,130,203399,40918,232.6,237.0,2000,2000,1,1,,,0,0,0,0,,,0,0,0,0,,,0,0,0,0,,,0,0,0,0,,,0,0,0,0,,,0,0,0,0,,,0,0,0,0,,,0,0,0,0,,,0,0,0,0,AAPL
2024-10-22 12:10:00.044721212+00:00,10,40,38,A,B,0,235.12,200,194,203719,64803,,235.12,0,200,0,0,,,0,0,0,0,,,0,0,0,0,,,0,0,0,0,,,0,0,0,0,,,0,0,0,0,,,0,0,0,0,,,0,0,0,0,,,0,0,0,0,,,0,0,0,0,AAPL
2024-10-22 12:10:00.044727157+00:00,10,40,38,A,A,0,,0,194,203644,64804,,,0,0,0,0,,,0,0,0,0,,,0,0,0,0,,,0,0,0,0,,,0,0,0,0,,,0,0,0,0,,,0,0,0,0,,,0,0,0,0,,,0,0,0,0,,,0,0,0,0,AAPL
2024-10-22 12:10:00.045206193+00:00,10,41,38,A,A,0,,0,194,55055,89461,234.3,,200,0,0,0,,,0,0,0,0,,,0,0,0,0,,,0,0,0,0,,,0,0,0,0,,,0,0,0,0,,,0,0,0,0,,,0,0,0,0,,,0,0,0,0,,,0,0,0,0,AAPL
2024-10-22 12:10:00.145517670+00:00,10,41,38,A,A,0,235.05,200,194,55700,89809,234.3,235.05,200,200,0,0,,,0,0,0,0,,,0,0,0,0,,,0,0,0,0,,,0,0,0,0,,,0,0,0,0,,,0,0,0,0,,,0,0,0,0,,,0,0,0,0,,,0,0,0,0,AAPL
2024-10-22 12:10:00.650322803+00:00,10,40,38,A,B,0,,0,194,203885,64970,234.24,,200,0,0,0,,,0,0,0,0,,,0,0,0,0,,,0,0,0,0,,,0,0,0,0,,,0,0,0,0,,,0,0,0,0,,,0,0,0,0,,,0,0,0,0,,,0,0,0,0,AAPL
2024-10-22 12:10:00.650329198+00:00,10,40,38,A,A,0,235.11,200,194,203705,64971,234.24,235.11,200,200,0,0,,,0,0,0,0,,,0,0,0,0,,,0,0,0,0,,,0,0,0,0,,,0,0,0,0,,,0,0,0,0,,,0,0,0,0,,,0,0,0,0,,,0,0,0,0,AAPL
2024-10-22 12:10:00.650791454+00:00,10,39,38,C,A,0,237.0,2000,130,203640,40931,232.6,,2000,0,1,0,,,0,0,0,0,,,0,0,0,0,,,0,0,0,0,,,0,0,0,0,,,0,0,0,0,,,0,0,0,0,,,0,0,0,0,,,0,0,0,0,,,0,0,0,0,AAPL
2024-10-22 12:10:00.688005501+00:00,10,39,38,A,A,0,237.0,2000,130,203424,40932,232.6,237.0,2000,2000,1,1,,,0,0,0,0,,,0,0,0,0,,,0,0,0,0,,,0,0,0,0,,,0,0,0,0,,,0,0,0,0,,,0,0,0,0,,,0,0,0,0,,,0,0,0,0,AAPL
2024-10-22 12:10:00.757578986+00:00,10,41,38,A,B,0,235.05,200,194,56312,90086,,235.05,0,200,0,0,,,0,0,0,0,,,0,0,0,0,,,0,0,0,0,,,0,0,0,0,,,0,0,0,0,,,0,0,0,0,,,0,0,0,0,,,0,0,0,0,,,0,0,0,0,AAPL
2024-10-22 12:10:00.757613520+00:00,10,41,38,A,B,0,235.05,200,194,63441,90087,234.34,235.05,200,200,0,0,,,0,0,0,0,,,0,0,0,0,,,0,0,0,0,,,0,0,0,0,,,0,0,0,0,,,0,0,0,0,,,0,0,0,0,,,0,0,0,0,,,0,0,0,0,AAPL
2024-10-22 12:10:00.808621236+00:00,10,39,38,C,A,0,237.0,2000,130,203671,40933,232.6,,2000,0,1,0,,,0,0,0,0,,,0,0,0,0,,,0,0,0,0,,,0,0,0,0,,,0,0,0,0,,,0,0,0,0,,,0,0,0,0,,,0,0,0,0,,,0,0,0,0,AAPL
2024-10-22 12:10:00.845547030+00:00,10,39,38,A,A,0,237.0,2000,130,203387,40934,232.6,237.0,2000,2000,1,1,,,0,0,0,0,,,0,0,0,0,,,0,0,0,0,,,0,0,0,0,,,0,0,0,0,,,0,0,0,0,,,0,0,0,0,,,0,0,0,0,,,0,0,0,0,AAPL
2024-10-22 12:10:00.845580378+00:00,10,40,38,A,B,0,235.11,200,194,204040,64978,,235.11,0,200,0,0,,,0,0,0,0,,,0,0,0,0,,,0,0,0,0,,,0,0,0,0,,,0,0,0,0,,,0,0,0,0,,,0,0,0,0,,,0,0,0,0,,,0,0,0,0,AAPL
2024-10-22 12:10:00.862630697+00:00,10,39,38,C,B,0,232.6,2000,130,203429,40935,,237.0,0,2000,0,1,,,0,0,0,0,,,0,0,0,0,,,0,0,0,0,,,0,0,0,0,,,0,0,0,0,,,0,0,0,0,,,0,0,0,0,,,0,0,0,0,,,0,0,0,0,AAPL
2024-10-22 12:10:00.876456696+00:00,10,39,38,A,B,0,232.6,2000,130,203479,40936,232.6,237.0,2000,2000,1,1,,,0,0,0,0,,,0,0,0,0,,,0,0,0,0,,,0,0,0,0,,,0,0,0,0,,,0,0,0,0,,,0,0,0,0,,,0,0,0,0,,,0,0,0,0,AAPL
2024-10-22 12:10:00.877113867+00:00,10,41,38,A,B,0,235.05,200,194,55026,90099,,235.05,0,200,0,0,,,0,0,0,0,,,0,0,0,0,,,0,0,0,0,,,0,0,0,0,,,0,0,0,0,,,0,0,0,0,,,0,0,0,0,,,0,0,0,0,,,0,0,0,0,AAPL
2024-10-22 12:10:00.958240113+00:00,10,40,38,A,A,0,,0,194,203779,64980,,,0,0,0,0,,,0,0,0,0,,,0,0,0,0,,,0,0,0,0,,,0,0,0,0,,,0,0,0,0,,,0,0,0,0,,,0,0,0,0,,,0,0,0,0,,,0,0,0,0,AAPL
2024-10-22 12:10:00.958497189+00:00,10,41,38,A,A,0,,0,194,55276,90114,,,0,0,0,0,,,0,0,0,0,,,0,0,0,0,,,0,0,0,0,,,0,0,0,0,,,0,0,0,0,,,0,0,0,0,,,0,0,0,0,,,0,0,0,0,,,0,0,0,0,AAPL
2024-10-22 12:10:01.703771281+00:00,10,41,38,A,B,0,,0,194,55521,90179,234.3,,200,0,0,0,,,0,0,0,0,,,0,0,0,0,,,0,0,0,0,,,0,0,0,0,,,0,0,0,0,,,0,0,0,0,,,0,0,0,0,,,0,0,0,0,,,0,0,0,0,AAPL
2024-10-22 12:10:02.026942172+00:00,10,41,38,A,B,0,,0,194,55748,90198,,,0,0,0,0,,,0,0,0,0,,,0,0,0,0,,,0,0,0,0,,,0,0,0,0,,,0,0,0,0,,,0,0,0,0,,,0,0,0,0,,,0,0,0,0,,,0,0,0,0,AAPL
2024-10-22 12:10:02.316074550+00:00,10,40,38,A,A,0,235.11,200,194,203853,64991,,235.11,0,200,0,0,,,0,0,0,0,,,0,0,0,0,,,0,0,0,0,,,0,0,0,0,,,0,0,0,0,,,0,0,0,0,,,0,0,0,0,,,0,0,0,0,,,0,0,0,0,AAPL
2024-10-22 12:10:02.316194921+00:00,10,40,38,A,B,0,235.11,200,194,203821,64992,234.24,235.11,200,200,0,0,,,0,0,0,0,,,0,0,0,0,,,0,0,0,0,,,0,0,0,0,,,0,0,0,0,,,0,0,0,0,,,0,0,0,0,,,0,0,0,0,,,0,0,0,0,AAPL
2024-10-22 12:10:02.316583589+00:00,10,41,38,A,B,0,,0,194,55421,90217,234.3,,200,0,0,0,,,0,0,0,0,,,0,0,0,0,,,0,0,0,0,,,0,0,0,0,,,0,0,0,0,,,0,0,0,0,,,0,0,0,0,,,0,0,0,0,,,0,0,0,0,AAPL
2024-10-22 12:10:02.316592520+00:00,10,41,38,A,A,0,235.05,200,194,54457,90218,234.3,235.05,200,200,0,0,,,0,0,0,0,,,0,0,0,0,,,0,0,0,0,,,0,0,0,0,,,0,0,0,0,,,0,0,0,0,,,0,0,0,0,,,0,0,0,0,,,0,0,0,0,AAPL
2024-10-22 12:10:02.731714419+00:00,10,40,38,A,A,0,,0,194,203828,64999,234.24,,200,0,0,0,,,0,0,0,0,,,0,0,0,0,,,0,0,0,0,,,0,0,0,0,,,0,0,0,0,,,0,0,0,0,,,0,0,0,0,,,0,0,0,0,,,0,0,0,0,AAPL
2024-10-22 12:10:02.731845332+00:00,10,40,38,A,B,0,,0,194,203786,65000,,,0,0,0,0,,,0,0,0,0,,,0,0,0,0,,,0,0,0,0,,,0,0,0,0,,,0,0,0,0,,,0,0,0,0,,,0,0,0,0,,,0,0,0,0,,,0,0,0,0,AAPL
2024-10-22 12:10:03.837040915+00:00,10,41,38,A,B,0,235.05,200,194,55739,90343,,235.05,0,200,0,0,,,0,0,0,0,,,0,0,0,0,,,0,0,0,0,,,0,0,0,0,,,0,0,0,0,,,0,0,0,0,,,0,0,0,0,,,0,0,0,0,,,0,0,0,0,AAPL
2024-10-22 12:10:04.095748651+00:00,10,40,38,A,A,0,235.11,200,194,203976,65025,,235.11,0,200,0,0,,,0,0,0,0,,,0,0,0,0,,,0,0,0,0,,,0,0,0,0,,,0,0,0,0,,,0,0,0,0,,,0,0,0,0,,,0,0,0,0,,,0,0,0,0,AAPL
2024-10-22 12:10:04.096023013+00:00,10,41,38,A,B,0,235.05,200,194,56156,90361,234.3,235.05,200,200,0,0,,,0,0,0,0,,,0,0,0,0,,,0,0,0,0,,,0,0,0,0,,,0,0,0,0,,,0,0,0,0,,,0,0,0,0,,,0,0,0,0,,,0,0,0,0,AAPL
2024-10-22 12:10:04.095919202+00:00,10,40,38,A,B,0,235.11,200,194,203943,65026,234.24,235.11,200,200,0,0,,,0,0,0,0,,,0,0,0,0,,,0,0,0,0,,,0,0,0,0,,,0,0,0,0,,,0,0,0,0,,,0,0,0,0,,,0,0,0,0,,,0,0,0,0,AAPL
2024-10-22 12:10:04.168054662+00:00,10,41,38,A,B,0,235.05,200,194,60963,90366,,235.05,0,200,0,0,,,0,0,0,0,,,0,0,0,0,,,0,0,0,0,,,0,0,0,0,,,0,0,0,0,,,0,0,0,0,,,0,0,0,0,,,0,0,0,0,,,0,0,0,0,AAPL
2024-10-22 12:10:04.298612214+00:00,10,41,38,A,B,0,235.05,200,194,55875,90370,234.3,235.05,200,200,0,0,,,0,0,0,0,,,0,0,0,0,,,0,0,0,0,,,0,0,0,0,,,0,0,0,0,,,0,0,0,0,,,0,0,0,0,,,0,0,0,0,,,0,0,0,0,AAPL
2024-10-22 12:10:04.731708019+00:00,10,40,38,A,B,0,235.11,200,194,204015,65030,,235.11,0,200,0,0,,,0,0,0,0,,,0,0,0,0,,,0,0,0,0,,,0,0,0,0,,,0,0,0,0,,,0,0,0,0,,,0,0,0,0,,,0,0,0,0,,,0,0,0,0,AAPL
2024-10-22 12:10:04.731715082+00:00,10,40,38,A,A,0,,0,194,204135,65031,,,0,0,0,0,,,0,0,0,0,,,0,0,0,0,,,0,0,0,0,,,0,0,0,0,,,0,0,0,0,,,0,0,0,0,,,0,0,0,0,,,0,0,0,0,,,0,0,0,0,AAPL
2024-10-22 12:10:04.731872435+00:00,10,41,38,A,B,0,235.05,200,194,55518,90384,,235.05,0,200,0,0,,,0,0,0,0,,,0,0,0,0,,,0,0,0,0,,,0,0,0,0,,,0,0,0,0,,,0,0,0,0,,,0,0,0,0,,,0,0,0,0,,,0,0,0,0,AAPL
2024-10-22 12:10:05.033946038+00:00,10,41,38,A,B,0,235.05,200,194,55370,90399,234.3,235.05,200,200,0,0,,,0,0,0,0,,,0,0,0,0,,,0,0,0,0,,,0,0,0,0,,,0,0,0,0,,,0,0,0,0,,,0,0,0,0,,,0,0,0,0,,,0,0,0,0,AAPL
2024-10-22 12:10:05.071114724+00:00,10,40,38,A,A,0,235.11,200,194,204466,65033,,235.11,0,200,0,0,,,0,0,0,0,,,0,0,0,0,,,0,0,0,0,,,0,0,0,0,,,0,0,0,0,,,0,0,0,0,,,0,0,0,0,,,0,0,0,0,,,0,0,0,0,AAPL
2024-10-22 12:10:05.071274589+00:00,10,40,38,A,B,0,235.11,200,194,204156,65034,234.24,235.11,200,200,0,0,,,0,0,0,0,,,0,0,0,0,,,0,0,0,0,,,0,0,0,0,,,0,0,0,0,,,0,0,0,0,,,0,0,0,0,,,0,0,0,0,,,0,0,0,0,AAPL
2024-10-22 12:10:05.658854381+00:00,10,40,38,A,B,0,235.11,200,194,203870,65042,,235.11,0,200,0,0,,,0,0,0,0,,,0,0,0,0,,,0,0,0,0,,,0,0,0,0,,,0,0,0,0,,,0,0,0,0,,,0,0,0,0,,,0,0,0,0,,,0,0,0,0,AAPL
2024-10-22 12:10:05.776380773+00:00,10,40,38,A,A,0,,0,194,203862,65045,,,0,0,0,0,,,0,0,0,0,,,0,0,0,0,,,0,0,0,0,,,0,0,0,0,,,0,0,0,0,,,0,0,0,0,,,0,0,0,0,,,0,0,0,0,,,0,0,0,0,AAPL
2024-10-22 12:10:06.237558686+00:00,10,41,38,A,B,0,235.05,200,194,55351,90473,,235.05,0,200,0,0,,,0,0,0,0,,,0,0,0,0,,,0,0,0,0,,,0,0,0,0,,,0,0,0,0,,,0,0,0,0,,,0,0,0,0,,,0,0,0,0,,,0,0,0,0,AAPL
2024-10-22 12:10:07.363197474+00:00,10,40,38,A,A,0,235.11,200,194,203902,65086,,235.11,0,200,0,0,,,0,0,0,0,,,0,0,0,0,,,0,0,0,0,,,0,0,0,0,,,0,0,0,0,,,0,0,0,0,,,0,0,0,0,,,0,0,0,0,,,0,0,0,0,AAPL
2024-10-22 12:10:07.363360880+00:00,10,40,38,A,B,0,235.11,200,194,203857,65087,234.24,235.11,200,200,0,0,,,0,0,0,0,,,0,0,0,0,,,0,0,0,0,,,0,0,0,0,,,0,0,0,0,,,0,0,0,0,,,0,0,0,0,,,0,0,0,0,,,0,0,0,0,AAPL
2024-10-22 12:10:07.363505831+00:00,10,41,38,A,B,0,235.05,200,194,56000,90602,234.3,235.05,200,200,0,0,,,0,0,0,0,,,0,0,0,0,,,0,0,0,0,,,0,0,0,0,,,0,0,0,0,,,0,0,0,0,,,0,0,0,0,,,0,0,0,0,,,0,0,0,0,AAPL
2024-10-22 12:10:07.464140927+00:00,10,41,38,A,B,0,235.05,200,194,60309,90604,,235.05,0,200,0,0,,,0,0,0,0,,,0,0,0,0,,,0,0,0,0,,,0,0,0,0,,,0,0,0,0,,,0,0,0,0,,,0,0,0,0,,,0,0,0,0,,,0,0,0,0,AAPL
2024-10-22 12:10:07.926138801+00:00,10,41,38,A,B,0,235.05,200,194,54643,90637,234.3,235.05,200,200,0,0,,,0,0,0,0,,,0,0,0,0,,,0,0,0,0,,,0,0,0,0,,,0,0,0,0,,,0,0,0,0,,,0,0,0,0,,,0,0,0,0,,,0,0,0,0,AAPL
2024-10-22 12:10:08.026352416+00:00,10,40,38,A,B,0,235.11,200,194,204159,65092,,235.11,0,200,0,0,,,0,0,0,0,,,0,0,0,0,,,0,0,0,0,,,0,0,0,0,,,0,0,0,0,,,0,0,0,0,,,0,0,0,0,,,0,0,0,0,,,0,0,0,0,AAPL
2024-10-22 12:10:08.026940035+00:00,10,41,38,A,B,0,235.05,200,194,55701,90640,,235.05,0,200,0,0,,,0,0,0,0,,,0,0,0,0,,,0,0,0,0,,,0,0,0,0,,,0,0,0,0,,,0,0,0,0,,,0,0,0,0,,,0,0,0,0,,,0,0,0,0,AAPL
2024-10-22 12:10:08.128367397+00:00,10,40,38,A,B,0,235.11,200,194,204066,65093,234.24,235.11,200,200,0,0,,,0,0,0,0,,,0,0,0,0,,,0,0,0,0,,,0,0,0,0,,,0,0,0,0,,,0,0,0,0,,,0,0,0,0,,,0,0,0,0,,,0,0,0,0,AAPL
2024-10-22 12:10:08.630175529+00:00,10,40,38,A,A,0,,0,194,204091,65100,234.24,,200,0,0,0,,,0,0,0,0,,,0,0,0,0,,,0,0,0,0,,,0,0,0,0,,,0,0,0,0,,,0,0,0,0,,,0,0,0,0,,,0,0,0,0,,,0,0,0,0,AAPL
2024-10-22 12:10:08.630290008+00:00,10,40,38,A,B,0,,0,194,204081,65101,,,0,0,0,0,,,0,0,0,0,,,0,0,0,0,,,0,0,0,0,,,0,0,0,0,,,0,0,0,0,,,0,0,0,0,,,0,0,0,0,,,0,0,0,0,,,0,0,0,0,AAPL
2024-10-22 12:10:10.400017156+00:00,10,40,38,A,A,0,235.11,200,194,204290,65112,,235.11,0,200,0,0,,,0,0,0,0,,,0,0,0,0,,,0,0,0,0,,,0,0,0,0,,,0,0,0,0,,,0,0,0,0,,,0,0,0,0,,,0,0,0,0,,,0,0,0,0,AAPL
2024-10-22 12:10:10.400173281+00:00,10,40,38,A,B,0,235.11,200,194,204241,65113,234.24,235.11,200,200,0,0,,,0,0,0,0,,,0,0,0,0,,,0,0,0,0,,,0,0,0,0,,,0,0,0,0,,,0,0,0,0,,,0,0,0,0,,,0,0,0,0,,,0,0,0,0,AAPL
2024-10-22 12:10:10.400312396+00:00,10,41,38,A,B,0,235.05,200,194,55719,90733,234.3,235.05,200,200,0,0,,,0,0,0,0,,,0,0,0,0,,,0,0,0,0,,,0,0,0,0,,,0,0,0,0,,,0,0,0,0,,,0,0,0,0,,,0,0,0,0,,,0,0,0,0,AAPL
2024-10-22 12:10:13.808988601+00:00,10,41,38,A,B,0,235.05,200,194,56208,90828,,235.05,0,200,0,0,,,0,0,0,0,,,0,0,0,0,,,0,0,0,0,,,0,0,0,0,,,0,0,0,0,,,0,0,0,0,,,0,0,0,0,,,0,0,0,0,,,0,0,0,0,AAPL
2024-10-22 12:10:16.733851041+00:00,10,39,38,A,N,0,233.0,2000,130,204010,41052,233.0,236.6,2000,2000,1,1,232.6,237.0,2000,2000,1,1,,,0,0,0,0,,,0,0,0,0,,,0,0,0,0,,,0,0,0,0,,,0,0,0,0,,,0,0,0,0,,,0,0,0,0,,,0,0,0,0,AAPL
2024-10-22 12:10:16.733898198+00:00,10,39,38,C,B,1,232.6,2000,130,203405,41053,233.0,236.6,2000,2000,1,1,,237.0,0,2000,0,1,,,0,0,0,0,,,0,0,0,0,,,0,0,0,0,,,0,0,0,0,,,0,0,0,0,,,0,0,0,0,,,0,0,0,0,,,0,0,0,0,AAPL
2024-10-22 12:10:16.733900242+00:00,10,39,38,C,A,1,237.0,2000,130,203388,41054,233.0,236.6,2000,2000,1,1,,,0,0,0,0,,,0,0,0,0,,,0,0,0,0,,,0,0,0,0,,,0,0,0,0,,,0,0,0,0,,,0,0,0,0,,,0,0,0,0,,,0,0,0,0,AAPL
2024-10-22 12:10:17.094034376+00:00,10,41,38,A,B,0,235.05,200,194,56091,90874,234.31,235.05,200,200,0,0,,,0,0,0,0,,,0,0,0,0,,,0,0,0,0,,,0,0,0,0,,,0,0,0,0,,,0,0,0,0,,,0,0,0,0,,,0,0,0,0,,,0,0,0,0,AAPL
2024-10-22 12:10:19.756153599+00:00,10,39,38,C,A,0,236.6,2000,130,203772,41078,233.0,,2000,0,1,0,,,0,0,0,0,,,0,0,0,0,,,0,0,0,0,,,0,0,0,0,,,0,0,0,0,,,0,0,0,0,,,0,0,0,0,,,0,0,0,0,,,0,0,0,0,AAPL
2024-10-22 12:10:19.792833450+00:00,10,39,38,A,A,0,236.6,2000,130,203542,41081,233.0,236.6,2000,2000,1,1,,,0,0,0,0,,,0,0,0,0,,,0,0,0,0,,,0,0,0,0,,,0,0,0,0,,,0,0,0,0,,,0,0,0,0,,,0,0,0,0,,,0,0,0,0,AAPL
2024-10-22 12:10:36.637218062+00:00,10,39,38,C,B,0,233.0,2000,130,203203,41152,,236.6,0,2000,0,1,,,0,0,0,0,,,0,0,0,0,,,0,0,0,0,,,0,0,0,0,,,0,0,0,0,,,0,0,0,0,,,0,0,0,0,,,0,0,0,0,,,0,0,0,0,AAPL
2024-10-22 12:10:36.650933144+00:00,10,39,38,A,B,0,232.8,2000,130,202840,41155,232.8,236.6,2000,2000,1,1,,,0,0,0,0,,,0,0,0,0,,,0,0,0,0,,,0,0,0,0,,,0,0,0,0,,,0,0,0,0,,,0,0,0,0,,,0,0,0,0,,,0,0,0,0,AAPL
2024-10-22 12:10:38.983381211+00:00,10,39,38,C,A,0,236.6,2000,130,203110,41166,232.8,,2000,0,1,0,,,0,0,0,0,,,0,0,0,0,,,0,0,0,0,,,0,0,0,0,,,0,0,0,0,,,0,0,0,0,,,0,0,0,0,,,0,0,0,0,,,0,0,0,0,AAPL
2024-10-22 12:10:39.020616641+00:00,10,39,38,A,A,0,236.6,2000,130,202786,41170,232.8,236.6,2000,2000,1,1,,,0,0,0,0,,,0,0,0,0,,,0,0,0,0,,,0,0,0,0,,,0,0,0,0,,,0,0,0,0,,,0,0,0,0,,,0,0,0,0,,,0,0,0,0,AAPL
2024-10-22 12:10:45.213112603+00:00,10,39,38,C,A,0,236.6,2000,130,203331,41187,232.8,,2000,0,1,0,,,0,0,0,0,,,0,0,0,0,,,0,0,0,0,,,0,0,0,0,,,0,0,0,0,,,0,0,0,0,,,0,0,0,0,,,0,0,0,0,,,0,0,0,0,AAPL
2024-10-22 12:10:45.223775376+00:00,10,39,38,A,B,0,233.0,2000,130,202740,41188,233.0,,2000,0,1,0,232.8,,2000,0,1,0,,,0,0,0,0,,,0,0,0,0,,,0,0,0,0,,,0,0,0,0,,,0,0,0,0,,,0,0,0,0,,,0,0,0,0,,,0,0,0,0,AAPL
2024-10-22 12:10:45.223950345+00:00,10,39,38,C,B,1,232.8,2000,130,202687,41189,233.0,,2000,0,1,0,,,0,0,0,0,,,0,0,0,0,,,0,0,0,0,,,0,0,0,0,,,0,0,0,0,,,0,0,0,0,,,0,0,0,0,,,0,0,0,0,,,0,0,0,0,AAPL
2024-10-22 12:10:45.236519562+00:00,10,39,38,A,A,0,236.6,2000,130,202686,41190,233.0,236.6,2000,2000,1,1,,,0,0,0,0,,,0,0,0,0,,,0,0,0,0,,,0,0,0,0,,,0,0,0,0,,,0,0,0,0,,,0,0,0,0,,,0,0,0,0,,,0,0,0,0,AAPL
2024-10-22 12:10:49.803116723+00:00,10,39,38,C,A,0,236.6,2000,130,203018,41217,233.0,,2000,0,1,0,,,0,0,0,0,,,0,0,0,0,,,0,0,0,0,,,0,0,0,0,,,0,0,0,0,,,0,0,0,0,,,0,0,0,0,,,0,0,0,0,,,0,0,0,0,AAPL
2024-10-22 12:10:49.839970077+00:00,10,39,38,A,A,0,236.6,2000,130,203006,41218,233.0,236.6,2000,2000,1,1,,,0,0,0,0,,,0,0,0,0,,,0,0,0,0,,,0,0,0,0,,,0,0,0,0,,,0,0,0,0,,,0,0,0,0,,,0,0,0,0,,,0,0,0,0,AAPL
2024-10-22 12:10:51.412110778+00:00,10,39,38,C,A,0,236.6,2000,130,202900,41225,233.0,,2000,0,1,0,,,0,0,0,0,,,0,0,0,0,,,0,0,0,0,,,0,0,0,0,,,0,0,0,0,,,0,0,0,0,,,0,0,0,0,,,0,0,0,0,,,0,0,0,0,AAPL
2024-10-22 12:10:51.449531211+00:00,10,39,38,A,A,0,236.6,2000,130,203032,41226,233.0,236.6,2000,2000,1,1,,,0,0,0,0,,,0,0,0,0,,,0,0,0,0,,,0,0,0,0,,,0,0,0,0,,,0,0,0,0,,,0,0,0,0,,,0,0,0,0,,,0,0,0,0,AAPL
2024-10-22 12:10:56.857196236+00:00,10,39,38,C,B,0,233.0,2000,130,203186,41253,,236.6,0,2000,0,1,,,0,0,0,0,,,0,0,0,0,,,0,0,0,0,,,0,0,0,0,,,0,0,0,0,,,0,0,0,0,,,0,0,0,0,,,0,0,0,0,,,0,0,0,0,AAPL
2024-10-22 12:10:56.894286280+00:00,10,39,38,A,B,0,233.0,2000,130,203068,41262,233.0,236.6,2000,2000,1,1,,,0,0,0,0,,,0,0,0,0,,,0,0,0,0,,,0,0,0,0,,,0,0,0,0,,,0,0,0,0,,,0,0,0,0,,,0,0,0,0,,,0,0,0,0,AAPL
2024-10-22 12:11:00.960191020+00:00,10,40,38,A,B,0,235.11,200,194,204221,65612,,235.11,0,200,0,0,,,0,0,0,0,,,0,0,0,0,,,0,0,0,0,,,0,0,0,0,,,0,0,0,0,,,0,0,0,0,,,0,0,0,0,,,0,0,0,0,,,0,0,0,0,AAPL
2024-10-22 12:11:00.960437319+00:00,10,41,38,A,B,0,235.05,200,194,55833,92483,,235.05,0,200,0,0,,,0,0,0,0,,,0,0,0,0,,,0,0,0,0,,,0,0,0,0,,,0,0,0,0,,,0,0,0,0,,,0,0,0,0,,,0,0,0,0,,,0,0,0,0,AAPL
2024-10-22 12:11:02.417969712+00:00,10,40,38,A,B,0,235.11,200,194,204265,65631,234.27,235.11,200,200,0,0,,,0,0,0,0,,,0,0,0,0,,,0,0,0,0,,,0,0,0,0,,,0,0,0,0,,,0,0,0,0,,,0,0,0,0,,,0,0,0,0,,,0,0,0,0,AAPL
2024-10-22 12:11:02.418262664+00:00,10,41,38,A,B,0,235.05,200,194,60915,92543,234.34,235.05,200,200,0,0,,,0,0,0,0,,,0,0,0,0,,,0,0,0,0,,,0,0,0,0,,,0,0,0,0,,,0,0,0,0,,,0,0,0,0,,,0,0,0,0,,,0,0,0,0,AAPL
2024-10-22 12:11:16.077802431+00:00,10,39,38,C,B,0,233.0,2000,130,203508,41362,,236.6,0,2000,0,1,,,0,0,0,0,,,0,0,0,0,,,0,0,0,0,,,0,0,0,0,,,0,0,0,0,,,0,0,0,0,,,0,0,0,0,,,0,0,0,0,,,0,0,0,0,AAPL
2024-10-22 12:11:16.090995235+00:00,10,39,38,A,B,0,232.8,2000,130,203449,41363,232.8,236.6,2000,2000,1,1,,,0,0,0,0,,,0,0,0,0,,,0,0,0,0,,,0,0,0,0,,,0,0,0,0,,,0,0,0,0,,,0,0,0,0,,,0,0,0,0,,,0,0,0,0,AAPL
2024-10-22 12:11:39.846411308+00:00,10,39,38,C,B,0,232.8,2000,130,204309,41507,,236.6,0,2000,0,1,,,0,0,0,0,,,0,0,0,0,,,0,0,0,0,,,0,0,0,0,,,0,0,0,0,,,0,0,0,0,,,0,0,0,0,,,0,0,0,0,,,0,0,0,0,AAPL
2024-10-22 12:11:39.882994713+00:00,10,39,38,A,B,0,233.0,2000,130,204041,41508,233.0,236.6,2000,2000,1,1,,,0,0,0,0,,,0,0,0,0,,,0,0,0,0,,,0,0,0,0,,,0,0,0,0,,,0,0,0,0,,,0,0,0,0,,,0,0,0,0,,,0,0,0,0,AAPL
2024-10-22 12:11:46.881940494+00:00,10,39,38,C,B,0,233.0,2000,130,204464,41579,,236.6,0,2000,0,1,,,0,0,0,0,,,0,0,0,0,,,0,0,0,0,,,0,0,0,0,,,0,0,0,0,,,0,0,0,0,,,0,0,0,0,,,0,0,0,0,,,0,0,0,0,AAPL
2024-10-22 12:11:46.894907119+00:00,10,39,38,A,B,0,232.8,2000,130,204056,41580,232.8,236.6,2000,2000,1,1,,,0,0,0,0,,,0,0,0,0,,,0,0,0,0,,,0,0,0,0,,,0,0,0,0,,,0,0,0,0,,,0,0,0,0,,,0,0,0,0,,,0,0,0,0,AAPL
2024-10-22 12:11:48.295436756+00:00,10,39,38,C,B,0,232.8,2000,130,204114,41594,,236.6,0,2000,0,1,,,0,0,0,0,,,0,0,0,0,,,0,0,0,0,,,0,0,0,0,,,0,0,0,0,,,0,0,0,0,,,0,0,0,0,,,0,0,0,0,,,0,0,0,0,AAPL
2024-10-22 12:11:48.331722016+00:00,10,39,38,A,B,0,233.0,2000,130,204083,41599,233.0,236.6,2000,2000,1,1,,,0,0,0,0,,,0,0,0,0,,,0,0,0,0,,,0,0,0,0,,,0,0,0,0,,,0,0,0,0,,,0,0,0,0,,,0,0,0,0,,,0,0,0,0,AAPL
2024-10-22 12:11:56.128319095+00:00,10,39,10888,A,A,0,418.69,100,130,203925,63270,,418.69,0,100,0,1,,,0,0,0,0,,,0,0,0,0,,,0,0,0,0,,,0,0,0,0,,,0,0,0,0,,,0,0,0,0,,,0,0,0,0,,,0,0,0,0,,,0,0,0,0,MSFT
2024-10-22 12:11:58.737083835+00:00,10,39,10888,C,A,0,418.69,100,130,204028,63320,,,0,0,0,0,,,0,0,0,0,,,0,0,0,0,,,0,0,0,0,,,0,0,0,0,,,0,0,0,0,,,0,0,0,0,,,0,0,0,0,,,0,0,0,0,,,0,0,0,0,MSFT
2024-10-22 12:12:00.012017433+00:00,10,40,38,A,B,0,235.11,200,194,202637,66131,,235.11,0,200,0,0,,,0,0,0,0,,,0,0,0,0,,,0,0,0,0,,,0,0,0,0,,,0,0,0,0,,,0,0,0,0,,,0,0,0,0,,,0,0,0,0,,,0,0,0,0,AAPL
2024-10-22 12:12:00.012027851+00:00,10,40,38,A,A,0,,0,194,202647,66132,,,0,0,0,0,,,0,0,0,0,,,0,0,0,0,,,0,0,0,0,,,0,0,0,0,,,0,0,0,0,,,0,0,0,0,,,0,0,0,0,,,0,0,0,0,,,0,0,0,0,AAPL
2024-10-22 12:12:00.012203561+00:00,10,41,38,A,B,0,235.05,200,194,57273,94730,,235.05,0,200,0,0,,,0,0,0,0,,,0,0,0,0,,,0,0,0,0,,,0,0,0,0,,,0,0,0,0,,,0,0,0,0,,,0,0,0,0,,,0,0,0,0,,,0,0,0,0,AAPL
2024-10-22 12:12:00.012215724+00:00,10,41,38,A,A,0,,0,194,54232,94732,,,0,0,0,0,,,0,0,0,0,,,0,0,0,0,,,0,0,0,0,,,0,0,0,0,,,0,0,0,0,,,0,0,0,0,,,0,0,0,0,,,0,0,0,0,,,0,0,0,0,AAPL
2024-10-22 12:12:00.219639549+00:00,10,40,38,A,A,0,235.11,200,194,202649,66202,,235.11,0,200,0,0,,,0,0,0,0,,,0,0,0,0,,,0,0,0,0,,,0,0,0,0,,,0,0,0,0,,,0,0,0,0,,,0,0,0,0,,,0,0,0,0,,,0,0,0,0,AAPL
2024-10-22 12:12:00.219767504+00:00,10,40,38,A,B,0,235.11,200,194,202622,66203,234.24,235.11,200,200,0,0,,,0,0,0,0,,,0,0,0,0,,,0,0,0,0,,,0,0,0,0,,,0,0,0,0,,,0,0,0,0,,,0,0,0,0,,,0,0,0,0,,,0,0,0,0,AAPL
2024-10-22 12:12:00.219905457+00:00,10,41,38,A,A,0,235.04,200,194,55816,94967,,235.04,0,200,0,0,,,0,0,0,0,,,0,0,0,0,,,0,0,0,0,,,0,0,0,0,,,0,0,0,0,,,0,0,0,0,,,0,0,0,0,,,0,0,0,0,,,0,0,0,0,AAPL
2024-10-22 12:12:00.220480032+00:00,10,41,38,A,B,0,235.04,200,194,55565,94969,234.31,235.04,200,200,0,0,,,0,0,0,0,,,0,0,0,0,,,0,0,0,0,,,0,0,0,0,,,0,0,0,0,,,0,0,0,0,,,0,0,0,0,,,0,0,0,0,,,0,0,0,0,AAPL
2024-10-22 12:12:00.535345038+00:00,10,41,38,A,B,0,235.04,200,194,56108,95018,,235.04,0,200,0,0,,,0,0,0,0,,,0,0,0,0,,,0,0,0,0,,,0,0,0,0,,,0,0,0,0,,,0,0,0,0,,,0,0,0,0,,,0,0,0,0,,,0,0,0,0,AAPL
2024-10-22 12:12:00.671636342+00:00,10,41,38,A,B,0,235.04,200,194,60396,95027,234.33,235.04,200,200,0,0,,,0,0,0,0,,,0,0,0,0,,,0,0,0,0,,,0,0,0,0,,,0,0,0,0,,,0,0,0,0,,,0,0,0,0,,,0,0,0,0,,,0,0,0,0,AAPL
2024-10-22 12:12:00.937078722+00:00,10,40,38,A,B,0,235.11,200,194,202653,66229,,235.11,0,200,0,0,,,0,0,0,0,,,0,0,0,0,,,0,0,0,0,,,0,0,0,0,,,0,0,0,0,,,0,0,0,0,,,0,0,0,0,,,0,0,0,0,,,0,0,0,0,AAPL
2024-10-22 12:12:00.937289134+00:00,10,41,38,A,B,0,235.04,200,194,55286,95041,,235.04,0,200,0,0,,,0,0,0,0,,,0,0,0,0,,,0,0,0,0,,,0,0,0,0,,,0,0,0,0,,,0,0,0,0,,,0,0,0,0,,,0,0,0,0,,,0,0,0,0,AAPL
2024-10-22 12:12:02.659284871+00:00,10,40,38,A,B,0,235.11,200,194,202491,66251,234.26,235.11,200,200,0,0,,,0,0,0,0,,,0,0,0,0,,,0,0,0,0,,,0,0,0,0,,,0,0,0,0,,,0,0,0,0,,,0,0,0,0,,,0,0,0,0,,,0,0,0,0,AAPL
2024-10-22 12:12:02.659794001+00:00,10,41,38,A,B,0,235.04,200,194,55203,95100,234.33,235.04,200,200,0,0,,,0,0,0,0,,,0,0,0,0,,,0,0,0,0,,,0,0,0,0,,,0,0,0,0,,,0,0,0,0,,,0,0,0,0,,,0,0,0,0,,,0,0,0,0,AAPL
2024-10-22 12:12:07.297000253+00:00,10,39,38,C,A,0,236.6,2000,130,204772,41743,233.0,,2000,0,1,0,,,0,0,0,0,,,0,0,0,0,,,0,0,0,0,,,0,0,0,0,,,0,0,0,0,,,0,0,0,0,,,0,0,0,0,,,0,0,0,0,,,0,0,0,0,AAPL
2024-10-22 12:12:07.307879079+00:00,10,39,38,A,A,0,237.0,2000,130,204171,41744,233.0,237.0,2000,2000,1,1,,,0,0,0,0,,,0,0,0,0,,,0,0,0,0,,,0,0,0,0,,,0,0,0,0,,,0,0,0,0,,,0,0,0,0,,,0,0,0,0,,,0,0,0,0,AAPL
2024-10-22 12:12:07.324717205+00:00,10,39,38,C,A,0,237.0,2000,130,204089,41745,233.0,,2000,0,1,0,,,0,0,0,0,,,0,0,0,0,,,0,0,0,0,,,0,0,0,0,,,0,0,0,0,,,0,0,0,0,,,0,0,0,0,,,0,0,0,0,,,0,0,0,0,AAPL
2024-10-22 12:12:07.614075870+00:00,10,39,38,A,A,0,237.0,2000,130,204225,41746,233.0,237.0,2000,2000,1,1,,,0,0,0,0,,,0,0,0,0,,,0,0,0,0,,,0,0,0,0,,,0,0,0,0,,,0,0,0,0,,,0,0,0,0,,,0,0,0,0,,,0,0,0,0,AAPL
2024-10-22 12:12:09.608863131+00:00,10,39,38,A,A,0,236.8,2000,130,204448,41757,233.0,236.8,2000,2000,1,1,,237.0,0,2000,0,1,,,0,0,0,0,,,0,0,0,0,,,0,0,0,0,,,0,0,0,0,,,0,0,0,0,,,0,0,0,0,,,0,0,0,0,,,0,0,0,0,AAPL
2024-10-22 12:12:09.609057217+00:00,10,39,38,C,A,1,237.0,2000,130,204014,41758,233.0,236.8,2000,2000,1,1,,,0,0,0,0,,,0,0,0,0,,,0,0,0,0,,,0,0,0,0,,,0,0,0,0,,,0,0,0,0,,,0,0,0,0,,,0,0,0,0,,,0,0,0,0,AAPL
2024-10-22 12:12:49.065295762+00:00,10,40,38,A,B,0,235.11,200,194,203903,66577,,235.11,0,200,0,0,,,0,0,0,0,,,0,0,0,0,,,0,0,0,0,,,0,0,0,0,,,0,0,0,0,,,0,0,0,0,,,0,0,0,0,,,0,0,0,0,,,0,0,0,0,AAPL
2024-10-22 12:12:49.166383350+00:00,10,40,38,A,B,0,235.11,200,194,203665,66578,234.26,235.11,200,200,0,0,,,0,0,0,0,,,0,0,0,0,,,0,0,0,0,,,0,0,0,0,,,0,0,0,0,,,0,0,0,0,,,0,0,0,0,,,0,0,0,0,,,0,0,0,0,AAPL
2024-10-22 12:13:00.099769705+00:00,10,40,38,A,B,0,235.11,200,194,203713,66705,,235.11,0,200,0,0,,,0,0,0,0,,,0,0,0,0,,,0,0,0,0,,,0,0,0,0,,,0,0,0,0,,,0,0,0,0,,,0,0,0,0,,,0,0,0,0,,,0,0,0,0,AAPL
2024-10-22 12:13:00.100164105+00:00,10,41,38,A,B,0,235.04,200,194,57466,96725,,235.04,0,200,0,0,,,0,0,0,0,,,0,0,0,0,,,0,0,0,0,,,0,0,0,0,,,0,0,0,0,,,0,0,0,0,,,0,0,0,0,,,0,0,0,0,,,0,0,0,0,AAPL
2024-10-22 12:13:02.691627897+00:00,10,40,38,A,B,0,235.11,200,194,203673,66764,234.26,235.11,200,200,0,0,,,0,0,0,0,,,0,0,0,0,,,0,0,0,0,,,0,0,0,0,,,0,0,0,0,,,0,0,0,0,,,0,0,0,0,,,0,0,0,0,,,0,0,0,0,AAPL
2024-10-22 12:13:02.692325566+00:00,10,41,38,A,B,0,235.04,200,194,56106,96955,234.33,235.04,200,200,0,0,,,0,0,0,0,,,0,0,0,0,,,0,0,0,0,,,0,0,0,0,,,0,0,0,0,,,0,0,0,0,,,0,0,0,0,,,0,0,0,0,,,0,0,0,0,AAPL
2024-10-22 12:13:40.813775710+00:00,10,39,38,C,A,0,236.8,2000,130,203572,42196,233.0,,2000,0,1,0,,,0,0,0,0,,,0,0,0,0,,,0,0,0,0,,,0,0,0,0,,,0,0,0,0,,,0,0,0,0,,,0,0,0,0,,,0,0,0,0,,,0,0,0,0,AAPL
2024-10-22 12:13:40.850619384+00:00,10,39,38,A,A,0,236.6,2000,130,203280,42197,233.0,236.6,2000,2000,1,1,,,0,0,0,0,,,0,0,0,0,,,0,0,0,0,,,0,0,0,0,,,0,0,0,0,,,0,0,0,0,,,0,0,0,0,,,0,0,0,0,,,0,0,0,0,AAPL
2024-10-22 12:13:50.379030397+00:00,10,39,38,C,B,0,233.0,2000,130,203996,42223,,236.6,0,2000,0,1,,,0,0,0,0,,,0,0,0,0,,,0,0,0,0,,,0,0,0,0,,,0,0,0,0,,,0,0,0,0,,,0,0,0,0,,,0,0,0,0,,,0,0,0,0,AAPL
2024-10-22 12:13:50.390202514+00:00,10,39,38,A,B,0,232.6,2000,130,203677,42224,232.6,236.6,2000,2000,1,1,,,0,0,0,0,,,0,0,0,0,,,0,0,0,0,,,0,0,0,0,,,0,0,0,0,,,0,0,0,0,,,0,0,0,0,,,0,0,0,0,,,0,0,0,0,AAPL
2024-10-22 12:13:50.405775880+00:00,10,39,38,A,B,0,233.0,2000,130,203595,42225,233.0,236.6,2000,2000,1,1,232.6,,2000,0,1,0,,,0,0,0,0,,,0,0,0,0,,,0,0,0,0,,,0,0,0,0,,,0,0,0,0,,,0,0,0,0,,,0,0,0,0,,,0,0,0,0,AAPL
2024-10-22 12:13:50.406501702+00:00,10,39,38,C,B,1,232.6,2000,130,203543,42226,233.0,236.6,2000,2000,1,1,,,0,0,0,0,,,0,0,0,0,,,0,0,0,0,,,0,0,0,0,,,0,0,0,0,,,0,0,0,0,,,0,0,0,0,,,0,0,0,0,,,0,0,0,0,AAPL
2024-10-22 12:14:00.066351548+00:00,10,40,38,A,B,0,235.11,200,194,202691,67207,,235.11,0,200,0,0,,,0,0,0,0,,,0,0,0,0,,,0,0,0,0,,,0,0,0,0,,,0,0,0,0,,,0,0,0,0,,,0,0,0,0,,,0,0,0,0,,,0,0,0,0,AAPL
2024-10-22 12:14:00.066512385+00:00,10,41,38,A,B,0,235.04,200,194,56377,98433,,235.04,0,200,0,0,,,0,0,0,0,,,0,0,0,0,,,0,0,0,0,,,0,0,0,0,,,0,0,0,0,,,0,0,0,0,,,0,0,0,0,,,0,0,0,0,,,0,0,0,0,AAPL
2024-10-22 12:14:02.733026976+00:00,10,40,38,A,B,0,235.11,200,194,202473,67262,234.25,235.11,200,200,0,0,,,0,0,0,0,,,0,0,0,0,,,0,0,0,0,,,0,0,0,0,,,0,0,0,0,,,0,0,0,0,,,0,0,0,0,,,0,0,0,0,,,0,0,0,0,AAPL
2024-10-22 12:14:02.733602189+00:00,10,41,38,A,B,0,235.04,200,194,56109,98706,234.32,235.04,200,200,0,0,,,0,0,0,0,,,0,0,0,0,,,0,0,0,0,,,0,0,0,0,,,0,0,0,0,,,0,0,0,0,,,0,0,0,0,,,0,0,0,0,,,0,0,0,0,AAPL
2024-10-22 12:14:12.367848471+00:00,10,40,38,A,B,0,235.11,200,194,202417,67318,,235.11,0,200,0,0,,,0,0,0,0,,,0,0,0,0,,,0,0,0,0,,,0,0,0,0,,,0,0,0,0,,,0,0,0,0,,,0,0,0,0,,,0,0,0,0,,,0,0,0,0,AAPL
2024-10-22 12:14:14.105249875+00:00,10,39,38,C,B,0,233.0,2000,130,203318,42296,,236.6,0,2000,0,1,,,0,0,0,0,,,0,0,0,0,,,0,0,0,0,,,0,0,0,0,,,0,0,0,0,,,0,0,0,0,,,0,0,0,0,,,0,0,0,0,,,0,0,0,0,AAPL
2024-10-22 12:14:14.142574456+00:00,10,39,38,A,B,0,232.8,2000,130,203174,42297,232.8,236.6,2000,2000,1,1,,,0,0,0,0,,,0,0,0,0,,,0,0,0,0,,,0,0,0,0,,,0,0,0,0,,,0,0,0,0,,,0,0,0,0,,,0,0,0,0,,,0,0,0,0,AAPL
2024-10-22 12:14:16.815921581+00:00,10,39,38,C,B,0,232.8,2000,130,203540,42305,,236.6,0,2000,0,1,,,0,0,0,0,,,0,0,0,0,,,0,0,0,0,,,0,0,0,0,,,0,0,0,0,,,0,0,0,0,,,0,0,0,0,,,0,0,0,0,,,0,0,0,0,AAPL
2024-10-22 12:14:16.852471020+00:00,10,39,38,A,B,0,232.8,2000,130,203017,42306,232.8,236.6,2000,2000,1,1,,,0,0,0,0,,,0,0,0,0,,,0,0,0,0,,,0,0,0,0,,,0,0,0,0,,,0,0,0,0,,,0,0,0,0,,,0,0,0,0,,,0,0,0,0,AAPL
2024-10-22 12:14:22.969139850+00:00,10,40,38,A,B,0,235.11,200,194,202230,67408,234.26,235.11,200,200,0,0,,,0,0,0,0,,,0,0,0,0,,,0,0,0,0,,,0,0,0,0,,,0,0,0,0,,,0,0,0,0,,,0,0,0,0,,,0,0,0,0,,,0,0,0,0,AAPL
2024-10-22 12:14:23.070404417+00:00,10,40,38,A,B,0,235.11,200,194,201988,67410,,235.11,0,200,0,0,,,0,0,0,0,,,0,0,0,0,,,0,0,0,0,,,0,0,0,0,,,0,0,0,0,,,0,0,0,0,,,0,0,0,0,,,0,0,0,0,,,0,0,0,0,AAPL
2024-10-22 12:14:34.341203955+00:00,10,39,38,C,A,0,236.6,2000,130,203653,42347,232.8,,2000,0,1,0,,,0,0,0,0,,,0,0,0,0,,,0,0,0,0,,,0,0,0,0,,,0,0,0,0,,,0,0,0,0,,,0,0,0,0,,,0,0,0,0,,,0,0,0,0,AAPL
2024-10-22 12:14:34.377844922+00:00,10,39,38,A,A,0,236.6,2000,130,203519,42348,232.8,236.6,2000,2000,1,1,,,0,0,0,0,,,0,0,0,0,,,0,0,0,0,,,0,0,0,0,,,0,0,0,0,,,0,0,0,0,,,0,0,0,0,,,0,0,0,0,,,0,0,0,0,AAPL
2024-10-22 12:14:34.383524807+00:00,10,39,38,C,A,0,236.6,2000,130,203388,42349,232.8,,2000,0,1,0,,,0,0,0,0,,,0,0,0,0,,,0,0,0,0,,,0,0,0,0,,,0,0,0,0,,,0,0,0,0,,,0,0,0,0,,,0,0,0,0,,,0,0,0,0,AAPL
2024-10-22 12:14:34.395204652+00:00,10,39,38,A,A,0,237.0,2000,130,203414,42350,232.8,237.0,2000,2000,1,1,,,0,0,0,0,,,0,0,0,0,,,0,0,0,0,,,0,0,0,0,,,0,0,0,0,,,0,0,0,0,,,0,0,0,0,,,0,0,0,0,,,0,0,0,0,AAPL
2024-10-22 12:14:34.408429786+00:00,10,39,38,C,A,0,237.0,2000,130,203337,42351,232.8,,2000,0,1,0,,,0,0,0,0,,,0,0,0,0,,,0,0,0,0,,,0,0,0,0,,,0,0,0,0,,,0,0,0,0,,,0,0,0,0,,,0,0,0,0,,,0,0,0,0,AAPL
2024-10-22 12:14:34.423364360+00:00,10,39,38,C,B,0,232.8,2000,130,203309,42352,,,0,0,0,0,,,0,0,0,0,,,0,0,0,0,,,0,0,0,0,,,0,0,0,0,,,0,0,0,0,,,0,0,0,0,,,0,0,0,0,,,0,0,0,0,,,0,0,0,0,AAPL
2024-10-22 12:14:34.433508797+00:00,10,39,38,A,A,0,237.0,2000,130,203427,42353,,237.0,0,2000,0,1,,,0,0,0,0,,,0,0,0,0,,,0,0,0,0,,,0,0,0,0,,,0,0,0,0,,,0,0,0,0,,,0,0,0,0,,,0,0,0,0,,,0,0,0,0,AAPL
2024-10-22 12:14:34.459506944+00:00,10,39,38,A,B,0,233.0,2000,130,203345,42354,233.0,237.0,2000,2000,1,1,,,0,0,0,0,,,0,0,0,0,,,0,0,0,0,,,0,0,0,0,,,0,0,0,0,,,0,0,0,0,,,0,0,0,0,,,0,0,0,0,,,0,0,0,0,AAPL
2024-10-22 12:14:34.490791297+00:00,10,39,38,C,B,0,233.0,2000,130,203393,42355,,237.0,0,2000,0,1,,,0,0,0,0,,,0,0,0,0,,,0,0,0,0,,,0,0,0,0,,,0,0,0,0,,,0,0,0,0,,,0,0,0,0,,,0,0,0,0,,,0,0,0,0,AAPL
2024-10-22 12:14:34.502762560+00:00,10,39,38,A,B,0,232.8,2000,130,203410,42356,232.8,237.0,2000,2000,1,1,,,0,0,0,0,,,0,0,0,0,,,0,0,0,0,,,0,0,0,0,,,0,0,0,0,,,0,0,0,0,,,0,0,0,0,,,0,0,0,0,,,0,0,0,0,AAPL
2024-10-22 12:14:34.700437360+00:00,10,39,38,A,A,0,236.6,2000,130,203355,42357,232.8,236.6,2000,2000,1,1,,237.0,0,2000,0,1,,,0,0,0,0,,,0,0,0,0,,,0,0,0,0,,,0,0,0,0,,,0,0,0,0,,,0,0,0,0,,,0,0,0,0,,,0,0,0,0,AAPL
2024-10-22 12:14:34.700619416+00:00,10,39,38,C,A,1,237.0,2000,130,203396,42358,232.8,236.6,2000,2000,1,1,,,0,0,0,0,,,0,0,0,0,,,0,0,0,0,,,0,0,0,0,,,0,0,0,0,,,0,0,0,0,,,0,0,0,0,,,0,0,0,0,,,0,0,0,0,AAPL
2024-10-22 12:14:46.159691107+00:00,10,40,38,A,B,0,235.11,200,194,202394,67557,234.25,235.11,200,200,0,0,,,0,0,0,0,,,0,0,0,0,,,0,0,0,0,,,0,0,0,0,,,0,0,0,0,,,0,0,0,0,,,0,0,0,0,,,0,0,0,0,,,0,0,0,0,AAPL
2024-10-22 12:14:46.251365599+00:00,10,40,38,A,B,0,235.11,200,194,202041,67558,,235.11,0,200,0,0,,,0,0,0,0,,,0,0,0,0,,,0,0,0,0,,,0,0,0,0,,,0,0,0,0,,,0,0,0,0,,,0,0,0,0,,,0,0,0,0,,,0,0,0,0,AAPL
2024-10-22 12:14:58.165041219+00:00,10,39,38,A,B,0,233.0,2000,130,203871,42504,233.0,236.6,2000,2000,1,1,232.8,,2000,0,1,0,,,0,0,0,0,,,0,0,0,0,,,0,0,0,0,,,0,0,0,0,,,0,0,0,0,,,0,0,0,0,,,0,0,0,0,,,0,0,0,0,AAPL
2024-10-22 12:14:58.165226386+00:00,10,39,38,C,B,1,232.8,2000,130,203723,42505,233.0,236.6,2000,2000,1,1,,,0,0,0,0,,,0,0,0,0,,,0,0,0,0,,,0,0,0,0,,,0,0,0,0,,,0,0,0,0,,,0,0,0,0,,,0,0,0,0,,,0,0,0,0,AAPL
2024-10-22 12:15:00.058823714+00:00,10,40,38,A,A,0,,0,194,202923,67775,,,0,0,0,0,,,0,0,0,0,,,0,0,0,0,,,0,0,0,0,,,0,0,0,0,,,0,0,0,0,,,0,0,0,0,,,0,0,0,0,,,0,0,0,0,,,0,0,0,0,AAPL
2024-10-22 12:15:00.059180555+00:00,10,41,38,A,B,0,235.04,200,194,55135,101549,,235.04,0,200,0,0,,,0,0,0,0,,,0,0,0,0,,,0,0,0,0,,,0,0,0,0,,,0,0,0,0,,,0,0,0,0,,,0,0,0,0,,,0,0,0,0,,,0,0,0,0,AAPL
2024-10-22 12:15:00.059200766+00:00,10,41,38,A,A,0,,0,194,55022,101552,,,0,0,0,0,,,0,0,0,0,,,0,0,0,0,,,0,0,0,0,,,0,0,0,0,,,0,0,0,0,,,0,0,0,0,,,0,0,0,0,,,0,0,0,0,,,0,0,0,0,AAPL
2024-10-22 12:15:01.651557489+00:00,10,40,38,A,A,0,235.08,200,194,202937,67945,,235.08,0,200,0,0,,,0,0,0,0,,,0,0,0,0,,,0,0,0,0,,,0,0,0,0,,,0,0,0,0,,,0,0,0,0,,,0,0,0,0,,,0,0,0,0,,,0,0,0,0,AAPL
2024-10-22 12:15:01.651805526+00:00,10,41,38,A,B,0,,0,194,63980,102268,234.32,,200,0,0,0,,,0,0,0,0,,,0,0,0,0,,,0,0,0,0,,,0,0,0,0,,,0,0,0,0,,,0,0,0,0,,,0,0,0,0,,,0,0,0,0,,,0,0,0,0,AAPL
2024-10-22 12:15:01.651818235+00:00,10,41,38,A,A,0,235.01,200,194,54429,102269,234.32,235.01,200,200,0,0,,,0,0,0,0,,,0,0,0,0,,,0,0,0,0,,,0,0,0,0,,,0,0,0,0,,,0,0,0,0,,,0,0,0,0,,,0,0,0,0,,,0,0,0,0,AAPL
2024-10-22 12:15:01.651767304+00:00,10,40,38,A,B,0,235.08,200,194,203125,67946,234.25,235.08,200,200,0,0,,,0,0,0,0,,,0,0,0,0,,,0,0,0,0,,,0,0,0,0,,,0,0,0,0,,,0,0,0,0,,,0,0,0,0,,,0,0,0,0,,,0,0,0,0,AAPL
2024-10-22 12:15:01.755929116+00:00,10,40,38,A,B,0,235.08,200,194,202912,67951,,235.08,0,200,0,0,,,0,0,0,0,,,0,0,0,0,,,0,0,0,0,,,0,0,0,0,,,0,0,0,0,,,0,0,0,0,,,0,0,0,0,,,0,0,0,0,,,0,0,0,0,AAPL
2024-10-22 12:15:01.854398119+00:00,10,41,38,A,B,0,235.01,200,194,55674,102311,,235.01,0,200,0,0,,,0,0,0,0,,,0,0,0,0,,,0,0,0,0,,,0,0,0,0,,,0,0,0,0,,,0,0,0,0,,,0,0,0,0,,,0,0,0,0,,,0,0,0,0,AAPL
2024-10-22 12:15:01.927197995+00:00,10,40,38,A,B,0,235.08,200,194,202900,67955,234.25,235.08,200,200,0,0,,,0,0,0,0,,,0,0,0,0,,,0,0,0,0,,,0,0,0,0,,,0,0,0,0,,,0,0,0,0,,,0,0,0,0,,,0,0,0,0,,,0,0,0,0,AAPL
2024-10-22 12:15:01.927469242+00:00,10,41,38,A,B,0,235.01,200,194,57108,102322,234.32,235.01,200,200,0,0,,,0,0,0,0,,,0,0,0,0,,,0,0,0,0,,,0,0,0,0,,,0,0,0,0,,,0,0,0,0,,,0,0,0,0,,,0,0,0,0,,,0,0,0,0,AAPL
2024-10-22 12:15:02.028248941+00:00,10,40,38,A,B,0,235.08,200,194,203031,67963,,235.08,0,200,0,0,,,0,0,0,0,,,0,0,0,0,,,0,0,0,0,,,0,0,0,0,,,0,0,0,0,,,0,0,0,0,,,0,0,0,0,,,0,0,0,0,,,0,0,0,0,AAPL
2024-10-22 12:15:02.028487022+00:00,10,41,38,A,B,0,235.01,200,194,55185,102344,,235.01,0,200,0,0,,,0,0,0,0,,,0,0,0,0,,,0,0,0,0,,,0,0,0,0,,,0,0,0,0,,,0,0,0,0,,,0,0,0,0,,,0,0,0,0,,,0,0,0,0,AAPL
2024-10-22 12:15:02.632016327+00:00,10,40,38,A,A,0,,0,194,202969,67979,,,0,0,0,0,,,0,0,0,0,,,0,0,0,0,,,0,0,0,0,,,0,0,0,0,,,0,0,0,0,,,0,0,0,0,,,0,0,0,0,,,0,0,0,0,,,0,0,0,0,AAPL
2024-10-22 12:15:02.897037163+00:00,10,40,38,A,A,0,235.09,200,194,202783,67991,,235.09,0,200,0,0,,,0,0,0,0,,,0,0,0,0,,,0,0,0,0,,,0,0,0,0,,,0,0,0,0,,,0,0,0,0,,,0,0,0,0,,,0,0,0,0,,,0,0,0,0,AAPL
2024-10-22 12:15:02.897178857+00:00,10,40,38,A,B,0,235.09,200,194,202847,67992,234.25,235.09,200,200,0,0,,,0,0,0,0,,,0,0,0,0,,,0,0,0,0,,,0,0,0,0,,,0,0,0,0,,,0,0,0,0,,,0,0,0,0,,,0,0,0,0,,,0,0,0,0,AAPL
2024-10-22 12:15:02.897305519+00:00,10,41,38,A,B,0,235.01,200,194,55726,102452,234.32,235.01,200,200,0,0,,,0,0,0,0,,,0,0,0,0,,,0,0,0,0,,,0,0,0,0,,,0,0,0,0,,,0,0,0,0,,,0,0,0,0,,,0,0,0,0,,,0,0,0,0,AAPL
2024-10-22 12:15:02.996742160+00:00,10,40,38,A,B,0,235.09,200,194,202887,67997,,235.09,0,200,0,0,,,0,0,0,0,,,0,0,0,0,,,0,0,0,0,,,0,0,0,0,,,0,0,0,0,,,0,0,0,0,,,0,0,0,0,,,0,0,0,0,,,0,0,0,0,AAPL
2024-10-22 12:15:02.997273981+00:00,10,41,38,A,B,0,235.01,200,194,55869,102459,,235.01,0,200,0,0,,,0,0,0,0,,,0,0,0,0,,,0,0,0,0,,,0,0,0,0,,,0,0,0,0,,,0,0,0,0,,,0,0,0,0,,,0,0,0,0,,,0,0,0,0,AAPL
2024-10-22 12:15:03.601710069+00:00,10,40,38,A,A,0,,0,194,202878,68010,,,0,0,0,0,,,0,0,0,0,,,0,0,0,0,,,0,0,0,0,,,0,0,0,0,,,0,0,0,0,,,0,0,0,0,,,0,0,0,0,,,0,0,0,0,,,0,0,0,0,AAPL
2024-10-22 12:15:04.003803502+00:00,10,41,38,A,A,0,,0,194,55547,102793,,,0,0,0,0,,,0,0,0,0,,,0,0,0,0,,,0,0,0,0,,,0,0,0,0,,,0,0,0,0,,,0,0,0,0,,,0,0,0,0,,,0,0,0,0,,,0,0,0,0,AAPL
2024-10-22 12:15:04.077901281+00:00,10,41,38,A,B,0,,0,194,55342,102798,234.32,,200,0,0,0,,,0,0,0,0,,,0,0,0,0,,,0,0,0,0,,,0,0,0,0,,,0,0,0,0,,,0,0,0,0,,,0,0,0,0,,,0,0,0,0,,,0,0,0,0,AAPL
2024-10-22 12:15:07.056535490+00:00,10,40,38,A,A,0,235.08,200,194,202885,68084,,235.08,0,200,0,0,,,0,0,0,0,,,0,0,0,0,,,0,0,0,0,,,0,0,0,0,,,0,0,0,0,,,0,0,0,0,,,0,0,0,0,,,0,0,0,0,,,0,0,0,0,AAPL
2024-10-22 12:15:07.057052710+00:00,10,41,38,A,A,0,235.02,200,194,56341,102906,234.32,235.02,200,200,0,0,,,0,0,0,0,,,0,0,0,0,,,0,0,0,0,,,0,0,0,0,,,0,0,0,0,,,0,0,0,0,,,0,0,0,0,,,0,0,0,0,,,0,0,0,0,AAPL
2024-10-22 12:15:07.057542124+00:00,10,39,38,C,A,0,236.6,2000,130,204933,42687,233.0,,2000,0,1,0,,,0,0,0,0,,,0,0,0,0,,,0,0,0,0,,,0,0,0,0,,,0,0,0,0,,,0,0,0,0,,,0,0,0,0,,,0,0,0,0,,,0,0,0,0,AAPL
2024-10-22 12:15:07.093684760+00:00,10,39,38,A,A,0,236.6,2000,130,203936,42688,233.0,236.6,2000,2000,1,1,,,0,0,0,0,,,0,0,0,0,,,0,0,0,0,,,0,0,0,0,,,0,0,0,0,,,0,0,0,0,,,0,0,0,0,,,0,0,0,0,,,0,0,0,0,AAPL
2024-10-22 12:15:07.731714456+00:00,10,40,38,A,A,0,,0,194,202712,68109,,,0,0,0,0,,,0,0,0,0,,,0,0,0,0,,,0,0,0,0,,,0,0,0,0,,,0,0,0,0,,,0,0,0,0,,,0,0,0,0,,,0,0,0,0,,,0,0,0,0,AAPL
2024-10-22 12:15:08.298964521+00:00,10,41,38,A,A,0,,0,194,55420,102994,234.32,,200,0,0,0,,,0,0,0,0,,,0,0,0,0,,,0,0,0,0,,,0,0,0,0,,,0,0,0,0,,,0,0,0,0,,,0,0,0,0,,,0,0,0,0,,,0,0,0,0,AAPL
2024-10-22 12:15:09.310342270+00:00,10,40,38,A,A,0,235.07,200,194,202765,68120,,235.07,0,200,0,0,,,0,0,0,0,,,0,0,0,0,,,0,0,0,0,,,0,0,0,0,,,0,0,0,0,,,0,0,0,0,,,0,0,0,0,,,0,0,0,0,,,0,0,0,0,AAPL
2024-10-22 12:15:09.310655111+00:00,10,41,38,A,A,0,235.01,200,194,55417,103044,234.32,235.01,200,200,0,0,,,0,0,0,0,,,0,0,0,0,,,0,0,0,0,,,0,0,0,0,,,0,0,0,0,,,0,0,0,0,,,0,0,0,0,,,0,0,0,0,,,0,0,0,0,AAPL
2024-10-22 12:15:09.747464257+00:00,10,39,38,A,B,0,234.4,2000,130,203974,42699,234.4,236.6,2000,2000,1,1,233.0,,2000,0,1,0,,,0,0,0,0,,,0,0,0,0,,,0,0,0,0,,,0,0,0,0,,,0,0,0,0,,,0,0,0,0,,,0,0,0,0,,,0,0,0,0,AAPL
2024-10-22 12:15:09.747662791+00:00,10,39,38,C,B,1,233.0,2000,130,203733,42700,234.4,236.6,2000,2000,1,1,,,0,0,0,0,,,0,0,0,0,,,0,0,0,0,,,0,0,0,0,,,0,0,0,0,,,0,0,0,0,,,0,0,0,0,,,0,0,0,0,,,0,0,0,0,AAPL
2024-10-22 12:15:11.044241265+00:00,10,41,38,A,B,0,235.01,200,194,55794,103119,,235.01,0,200,0,0,,,0,0,0,0,,,0,0,0,0,,,0,0,0,0,,,0,0,0,0,,,0,0,0,0,,,0,0,0,0,,,0,0,0,0,,,0,0,0,0,,,0,0,0,0,AAPL
2024-10-22 12:15:11.044346556+00:00,10,41,38,A,B,0,235.01,200,194,54131,103121,234.32,235.01,200,200,0,0,,,0,0,0,0,,,0,0,0,0,,,0,0,0,0,,,0,0,0,0,,,0,0,0,0,,,0,0,0,0,,,0,0,0,0,,,0,0,0,0,,,0,0,0,0,AAPL
2024-10-22 12:15:12.329580938+00:00,10,40,38,A,A,0,,0,194,202964,68172,,,0,0,0,0,,,0,0,0,0,,,0,0,0,0,,,0,0,0,0,,,0,0,0,0,,,0,0,0,0,,,0,0,0,0,,,0,0,0,0,,,0,0,0,0,,,0,0,0,0,AAPL
2024-10-22 12:15:12.500294609+00:00,10,40,38,A,A,0,235.08,200,194,202904,68178,,235.08,0,200,0,0,,,0,0,0,0,,,0,0,0,0,,,0,0,0,0,,,0,0,0,0,,,0,0,0,0,,,0,0,0,0,,,0,0,0,0,,,0,0,0,0,,,0,0,0,0,AAPL
2024-10-22 12:15:14.694076024+00:00,10,40,38,A,B,0,235.08,200,194,203003,68200,234.26,235.08,200,200,0,0,,,0,0,0,0,,,0,0,0,0,,,0,0,0,0,,,0,0,0,0,,,0,0,0,0,,,0,0,0,0,,,0,0,0,0,,,0,0,0,0,,,0,0,0,0,AAPL
2024-10-22 12:15:15.967609959+00:00,10,39,10888,A,B,0,418.27,100,130,203724,65421,418.27,,100,0,1,0,,,0,0,0,0,,,0,0,0,0,,,0,0,0,0,,,0,0,0,0,,,0,0,0,0,,,0,0,0,0,,,0,0,0,0,,,0,0,0,0,,,0,0,0,0,MSFT
2024-10-22 12:15:37.712960130+00:00,10,39,38,C,B,0,234.4,2000,130,203985,42772,,236.6,0,2000,0,1,,,0,0,0,0,,,0,0,0,0,,,0,0,0,0,,,0,0,0,0,,,0,0,0,0,,,0,0,0,0,,,0,0,0,0,,,0,0,0,0,,,0,0,0,0,AAPL
2024-10-22 12:15:37.724050566+00:00,10,39,38,A,B,0,232.8,2000,130,203459,42773,232.8,236.6,2000,2000,1,1,,,0,0,0,0,,,0,0,0,0,,,0,0,0,0,,,0,0,0,0,,,0,0,0,0,,,0,0,0,0,,,0,0,0,0,,,0,0,0,0,,,0,0,0,0,AAPL
2024-10-22 12:15:51.503642137+00:00,10,39,10888,C,B,0,418.27,100,130,203252,65716,,,0,0,0,0,,,0,0,0,0,,,0,0,0,0,,,0,0,0,0,,,0,0,0,0,,,0,0,0,0,,,0,0,0,0,,,0,0,0,0,,,0,0,0,0,,,0,0,0,0,MSFT
2024-10-22 12:16:00.011374331+00:00,10,40,38,A,B,0,235.08,200,194,203342,68540,,235.08,0,200,0,0,,,0,0,0,0,,,0,0,0,0,,,0,0,0,0,,,0,0,0,0,,,0,0,0,0,,,0,0,0,0,,,0,0,0,0,,,0,0,0,0,,,0,0,0,0,AAPL
2024-10-22 12:16:00.011979481+00:00,10,41,38,A,B,0,235.01,200,194,56405,104444,,235.01,0,200,0,0,,,0,0,0,0,,,0,0,0,0,,,0,0,0,0,,,0,0,0,0,,,0,0,0,0,,,0,0,0,0,,,0,0,0,0,,,0,0,0,0,,,0,0,0,0,AAPL
2024-10-22 12:16:00.916358701+00:00,10,40,38,A,A,0,,0,194,203171,68614,,,0,0,0,0,,,0,0,0,0,,,0,0,0,0,,,0,0,0,0,,,0,0,0,0,,,0,0,0,0,,,0,0,0,0,,,0,0,0,0,,,0,0,0,0,,,0,0,0,0,AAPL
2024-10-22 12:16:02.769247162+00:00,10,40,38,A,B,0,,0,194,203203,68632,234.27,,200,0,0,0,,,0,0,0,0,,,0,0,0,0,,,0,0,0,0,,,0,0,0,0,,,0,0,0,0,,,0,0,0,0,,,0,0,0,0,,,0,0,0,0,,,0,0,0,0,AAPL
2024-10-22 12:16:02.769385720+00:00,10,40,38,A,A,0,235.08,200,194,203083,68633,234.27,235.08,200,200,0,0,,,0,0,0,0,,,0,0,0,0,,,0,0,0,0,,,0,0,0,0,,,0,0,0,0,,,0,0,0,0,,,0,0,0,0,,,0,0,0,0,,,0,0,0,0,AAPL
2024-10-22 12:16:02.769727487+00:00,10,41,38,A,B,0,235.01,200,194,56350,104820,234.33,235.01,200,200,0,0,,,0,0,0,0,,,0,0,0,0,,,0,0,0,0,,,0,0,0,0,,,0,0,0,0,,,0,0,0,0,,,0,0,0,0,,,0,0,0,0,,,0,0,0,0,AAPL
2024-10-22 12:16:09.165001554+00:00,10,41,38,A,B,0,235.01,200,194,60824,105054,,235.01,0,200,0,0,,,0,0,0,0,,,0,0,0,0,,,0,0,0,0,,,0,0,0,0,,,0,0,0,0,,,0,0,0,0,,,0,0,0,0,,,0,0,0,0,,,0,0,0,0,AAPL
2024-10-22 12:16:09.165164374+00:00,10,41,38,A,B,0,235.01,200,194,55132,105055,234.33,235.01,200,200,0,0,,,0,0,0,0,,,0,0,0,0,,,0,0,0,0,,,0,0,0,0,,,0,0,0,0,,,0,0,0,0,,,0,0,0,0,,,0,0,0,0,,,0,0,0,0,AAPL
2024-10-22 12:16:28.552568149+00:00,10,39,38,A,B,0,233.0,2000,130,203114,42892,233.0,236.6,2000,2000,1,1,232.8,,2000,0,1,0,,,0,0,0,0,,,0,0,0,0,,,0,0,0,0,,,0,0,0,0,,,0,0,0,0,,,0,0,0,0,,,0,0,0,0,,,0,0,0,0,AAPL
2024-10-22 12:16:28.552776156+00:00,10,39,38,C,B,1,232.8,2000,130,202947,42893,233.0,236.6,2000,2000,1,1,,,0,0,0,0,,,0,0,0,0,,,0,0,0,0,,,0,0,0,0,,,0,0,0,0,,,0,0,0,0,,,0,0,0,0,,,0,0,0,0,,,0,0,0,0,AAPL
2024-10-22 12:16:31.778012154+00:00,10,40,38,A,N,0,,0,194,203931,68859,,,0,0,0,0,,,0,0,0,0,,,0,0,0,0,,,0,0,0,0,,,0,0,0,0,,,0,0,0,0,,,0,0,0,0,,,0,0,0,0,,,0,0,0,0,,,0,0,0,0,AAPL
2024-10-22 12:16:31.780079363+00:00,10,41,38,A,B,0,235.01,200,194,55455,105548,,235.01,0,200,0,0,,,0,0,0,0,,,0,0,0,0,,,0,0,0,0,,,0,0,0,0,,,0,0,0,0,,,0,0,0,0,,,0,0,0,0,,,0,0,0,0,,,0,0,0,0,AAPL
2024-10-22 12:16:31.780131906+00:00,10,41,38,A,A,0,,0,194,54015,105549,,,0,0,0,0,,,0,0,0,0,,,0,0,0,0,,,0,0,0,0,,,0,0,0,0,,,0,0,0,0,,,0,0,0,0,,,0,0,0,0,,,0,0,0,0,,,0,0,0,0,AAPL
2024-10-22 12:16:36.106063864+00:00,10,39,38,C,B,0,233.0,2000,130,203026,42938,,236.6,0,2000,0,1,,,0,0,0,0,,,0,0,0,0,,,0,0,0,0,,,0,0,0,0,,,0,0,0,0,,,0,0,0,0,,,0,0,0,0,,,0,0,0,0,,,0,0,0,0,AAPL
2024-10-22 12:16:36.119586355+00:00,10,39,38,A,B,0,232.8,2000,130,203110,42941,232.8,236.6,2000,2000,1,1,,,0,0,0,0,,,0,0,0,0,,,0,0,0,0,,,0,0,0,0,,,0,0,0,0,,,0,0,0,0,,,0,0,0,0,,,0,0,0,0,,,0,0,0,0,AAPL
2024-10-22 12:16:36.813845176+00:00,10,40,38,A,N,0,235.08,200,194,204087,68884,234.27,235.08,200,200,0,0,,,0,0,0,0,,,0,0,0,0,,,0,0,0,0,,,0,0,0,0,,,0,0,0,0,,,0,0,0,0,,,0,0,0,0,,,0,0,0,0,,,0,0,0,0,AAPL
2024-10-22 12:16:36.814410477+00:00,10,41,38,A,A,0,235.02,200,194,56630,105716,,235.02,0,200,0,0,,,0,0,0,0,,,0,0,0,0,,,0,0,0,0,,,0,0,0,0,,,0,0,0,0,,,0,0,0,0,,,0,0,0,0,,,0,0,0,0,,,0,0,0,0,AAPL
2024-10-22 12:16:36.814414544+00:00,10,41,38,A,B,0,235.02,200,194,56288,105717,234.33,235.02,200,200,0,0,,,0,0,0,0,,,0,0,0,0,,,0,0,0,0,,,0,0,0,0,,,0,0,0,0,,,0,0,0,0,,,0,0,0,0,,,0,0,0,0,,,0,0,0,0,AAPL
2024-10-22 12:17:00.047791211+00:00,10,40,38,A,B,0,235.08,200,194,204628,69117,,235.08,0,200,0,0,,,0,0,0,0,,,0,0,0,0,,,0,0,0,0,,,0,0,0,0,,,0,0,0,0,,,0,0,0,0,,,0,0,0,0,,,0,0,0,0,,,0,0,0,0,AAPL
2024-10-22 12:17:00.048186308+00:00,10,41,38,A,B,0,235.02,200,194,60342,106407,,235.02,0,200,0,0,,,0,0,0,0,,,0,0,0,0,,,0,0,0,0,,,0,0,0,0,,,0,0,0,0,,,0,0,0,0,,,0,0,0,0,,,0,0,0,0,,,0,0,0,0,AAPL
2024-10-22 12:17:00.917547869+00:00,10,40,38,A,A,0,,0,194,204719,69176,,,0,0,0,0,,,0,0,0,0,,,0,0,0,0,,,0,0,0,0,,,0,0,0,0,,,0,0,0,0,,,0,0,0,0,,,0,0,0,0,,,0,0,0,0,,,0,0,0,0,AAPL
2024-10-22 12:17:00.918051521+00:00,10,41,38,A,A,0,,0,194,56275,106634,,,0,0,0,0,,,0,0,0,0,,,0,0,0,0,,,0,0,0,0,,,0,0,0,0,,,0,0,0,0,,,0,0,0,0,,,0,0,0,0,,,0,0,0,0,,,0,0,0,0,AAPL
2024-10-22 12:17:02.396236093+00:00,10,40,38,A,B,0,,0,194,204799,69201,234.27,,200,0,0,0,,,0,0,0,0,,,0,0,0,0,,,0,0,0,0,,,0,0,0,0,,,0,0,0,0,,,0,0,0,0,,,0,0,0,0,,,0,0,0,0,,,0,0,0,0,AAPL
2024-10-22 12:17:02.396242689+00:00,10,40,38,A,A,0,235.08,200,194,204651,69202,234.27,235.08,200,200,0,0,,,0,0,0,0,,,0,0,0,0,,,0,0,0,0,,,0,0,0,0,,,0,0,0,0,,,0,0,0,0,,,0,0,0,0,,,0,0,0,0,,,0,0,0,0,AAPL
2024-10-22 12:17:02.396759361+00:00,10,41,38,A,B,0,,0,194,55625,106708,234.33,,200,0,0,0,,,0,0,0,0,,,0,0,0,0,,,0,0,0,0,,,0,0,0,0,,,0,0,0,0,,,0,0,0,0,,,0,0,0,0,,,0,0,0,0,,,0,0,0,0,AAPL
2024-10-22 12:17:02.396817958+00:00,10,41,38,A,A,0,235.02,200,194,54235,106709,234.33,235.02,200,200,0,0,,,0,0,0,0,,,0,0,0,0,,,0,0,0,0,,,0,0,0,0,,,0,0,0,0,,,0,0,0,0,,,0,0,0,0,,,0,0,0,0,,,0,0,0,0,AAPL
2024-10-22 12:17:02.397117482+00:00,10,39,38,C,A,0,236.6,2000,130,204098,43072,232.8,,2000,0,1,0,,,0,0,0,0,,,0,0,0,0,,,0,0,0,0,,,0,0,0,0,,,0,0,0,0,,,0,0,0,0,,,0,0,0,0,,,0,0,0,0,,,0,0,0,0,AAPL
2024-10-22 12:17:02.432551134+00:00,10,39,38,A,A,0,236.6,2000,130,203993,43073,232.8,236.6,2000,2000,1,1,,,0,0,0,0,,,0,0,0,0,,,0,0,0,0,,,0,0,0,0,,,0,0,0,0,,,0,0,0,0,,,0,0,0,0,,,0,0,0,0,,,0,0,0,0,AAPL
2024-10-22 12:17:02.698373447+00:00,10,41,38,A,B,0,235.02,200,194,56732,106718,,235.02,0,200,0,0,,,0,0,0,0,,,0,0,0,0,,,0,0,0,0,,,0,0,0,0,,,0,0,0,0,,,0,0,0,0,,,0,0,0,0,,,0,0,0,0,,,0,0,0,0,AAPL
2024-10-22 12:17:02.698740724+00:00,10,40,38,A,B,0,235.08,200,194,204615,69206,,235.08,0,200,0,0,,,0,0,0,0,,,0,0,0,0,,,0,0,0,0,,,0,0,0,0,,,0,0,0,0,,,0,0,0,0,,,0,0,0,0,,,0,0,0,0,,,0,0,0,0,AAPL
2024-10-22 12:17:04.043725038+00:00,10,40,38,A,B,0,235.08,200,194,204841,69214,234.27,235.08,200,200,0,0,,,0,0,0,0,,,0,0,0,0,,,0,0,0,0,,,0,0,0,0,,,0,0,0,0,,,0,0,0,0,,,0,0,0,0,,,0,0,0,0,,,0,0,0,0,AAPL
2024-10-22 12:17:04.044239223+00:00,10,41,38,A,B,0,235.02,200,194,55632,106775,234.33,235.02,200,200,0,0,,,0,0,0,0,,,0,0,0,0,,,0,0,0,0,,,0,0,0,0,,,0,0,0,0,,,0,0,0,0,,,0,0,0,0,,,0,0,0,0,,,0,0,0,0,AAPL
2024-10-22 12:17:04.077684202+00:00,10,40,38,A,B,0,235.08,200,194,204693,69215,,235.08,0,200,0,0,,,0,0,0,0,,,0,0,0,0,,,0,0,0,0,,,0,0,0,0,,,0,0,0,0,,,0,0,0,0,,,0,0,0,0,,,0,0,0,0,,,0,0,0,0,AAPL
2024-10-22 12:17:04.077884013+00:00,10,41,38,A,B,0,235.02,200,194,55317,106776,,235.02,0,200,0,0,,,0,0,0,0,,,0,0,0,0,,,0,0,0,0,,,0,0,0,0,,,0,0,0,0,,,0,0,0,0,,,0,0,0,0,,,0,0,0,0,,,0,0,0,0,AAPL
2024-10-22 12:17:04.391695766+00:00,10,41,38,A,B,0,235.02,200,194,56362,106787,234.33,235.02,200,200,0,0,,,0,0,0,0,,,0,0,0,0,,,0,0,0,0,,,0,0,0,0,,,0,0,0,0,,,0,0,0,0,,,0,0,0,0,,,0,0,0,0,,,0,0,0,0,AAPL
2024-10-22 12:17:04.490241121+00:00,10,40,38,A,B,0,235.08,200,194,205076,69216,234.27,235.08,200,200,0,0,,,0,0,0,0,,,0,0,0,0,,,0,0,0,0,,,0,0,0,0,,,0,0,0,0,,,0,0,0,0,,,0,0,0,0,,,0,0,0,0,,,0,0,0,0,AAPL
2024-10-22 12:17:04.691694614+00:00,10,40,38,A,B,0,235.08,200,194,204760,69217,,235.08,0,200,0,0,,,0,0,0,0,,,0,0,0,0,,,0,0,0,0,,,0,0,0,0,,,0,0,0,0,,,0,0,0,0,,,0,0,0,0,,,0,0,0,0,,,0,0,0,0,AAPL
2024-10-22 12:17:05.697888322+00:00,10,40,38,A,B,0,235.08,200,194,204801,69225,234.27,235.08,200,200,0,0,,,0,0,0,0,,,0,0,0,0,,,0,0,0,0,,,0,0,0,0,,,0,0,0,0,,,0,0,0,0,,,0,0,0,0,,,0,0,0,0,,,0,0,0,0,AAPL
2024-10-22 12:17:06.674529434+00:00,10,41,38,A,B,0,235.02,200,194,60904,106855,,235.02,0,200,0,0,,,0,0,0,0,,,0,0,0,0,,,0,0,0,0,,,0,0,0,0,,,0,0,0,0,,,0,0,0,0,,,0,0,0,0,,,0,0,0,0,,,0,0,0,0,AAPL
2024-10-22 12:17:08.646391704+00:00,10,40,38,A,B,0,235.08,200,194,204505,69257,,235.08,0,200,0,0,,,0,0,0,0,,,0,0,0,0,,,0,0,0,0,,,0,0,0,0,,,0,0,0,0,,,0,0,0,0,,,0,0,0,0,,,0,0,0,0,,,0,0,0,0,AAPL
2024-10-22 12:17:09.795729156+00:00,10,41,38,A,B,0,235.02,200,194,61200,106911,234.33,235.02,200,200,0,0,,,0,0,0,0,,,0,0,0,0,,,0,0,0,0,,,0,0,0,0,,,0,0,0,0,,,0,0,0,0,,,0,0,0,0,,,0,0,0,0,,,0,0,0,0,AAPL
2024-10-22 12:17:10.117926671+00:00,10,40,38,A,B,0,235.08,200,194,204876,69264,234.27,235.08,200,200,0,0,,,0,0,0,0,,,0,0,0,0,,,0,0,0,0,,,0,0,0,0,,,0,0,0,0,,,0,0,0,0,,,0,0,0,0,,,0,0,0,0,,,0,0,0,0,AAPL
2024-10-22 12:17:11.288106098+00:00,10,40,38,A,B,0,235.08,200,194,204916,69269,,235.08,0,200,0,0,,,0,0,0,0,,,0,0,0,0,,,0,0,0,0,,,0,0,0,0,,,0,0,0,0,,,0,0,0,0,,,0,0,0,0,,,0,0,0,0,,,0,0,0,0,AAPL
2024-10-22 12:17:11.446580654+00:00,10,41,38,A,B,0,235.02,200,194,60146,106960,,235.02,0,200,0,0,,,0,0,0,0,,,0,0,0,0,,,0,0,0,0,,,0,0,0,0,,,0,0,0,0,,,0,0,0,0,,,0,0,0,0,,,0,0,0,0,,,0,0,0,0,AAPL
2024-10-22 12:17:13.379048527+00:00,10,40,38,A,B,0,235.08,200,194,204975,69289,234.27,235.08,200,200,0,0,,,0,0,0,0,,,0,0,0,0,,,0,0,0,0,,,0,0,0,0,,,0,0,0,0,,,0,0,0,0,,,0,0,0,0,,,0,0,0,0,,,0,0,0,0,AAPL
2024-10-22 12:17:13.379571702+00:00,10,41,38,A,B,0,235.02,200,194,55591,106997,234.33,235.02,200,200,0,0,,,0,0,0,0,,,0,0,0,0,,,0,0,0,0,,,0,0,0,0,,,0,0,0,0,,,0,0,0,0,,,0,0,0,0,,,0,0,0,0,,,0,0,0,0,AAPL
2024-10-22 12:17:13.479992330+00:00,10,40,38,A,B,0,235.08,200,194,204763,69290,,235.08,0,200,0,0,,,0,0,0,0,,,0,0,0,0,,,0,0,0,0,,,0,0,0,0,,,0,0,0,0,,,0,0,0,0,,,0,0,0,0,,,0,0,0,0,,,0,0,0,0,AAPL
2024-10-22 12:17:13.480264226+00:00,10,41,38,A,B,0,235.02,200,194,61425,106998,,235.02,0,200,0,0,,,0,0,0,0,,,0,0,0,0,,,0,0,0,0,,,0,0,0,0,,,0,0,0,0,,,0,0,0,0,,,0,0,0,0,,,0,0,0,0,,,0,0,0,0,AAPL
2024-10-22 12:17:13.581952820+00:00,10,41,38,A,B,0,235.02,200,194,55361,106999,234.33,235.02,200,200,0,0,,,0,0,0,0,,,0,0,0,0,,,0,0,0,0,,,0,0,0,0,,,0,0,0,0,,,0,0,0,0,,,0,0,0,0,,,0,0,0,0,,,0,0,0,0,AAPL
2024-10-22 12:17:13.984922686+00:00,10,40,38,A,B,0,235.08,200,194,204635,69297,234.27,235.08,200,200,0,0,,,0,0,0,0,,,0,0,0,0,,,0,0,0,0,,,0,0,0,0,,,0,0,0,0,,,0,0,0,0,,,0,0,0,0,,,0,0,0,0,,,0,0,0,0,AAPL
2024-10-22 12:17:14.588807784+00:00,10,40,38,A,B,0,235.08,200,194,204802,69302,,235.08,0,200,0,0,,,0,0,0,0,,,0,0,0,0,,,0,0,0,0,,,0,0,0,0,,,0,0,0,0,,,0,0,0,0,,,0,0,0,0,,,0,0,0,0,,,0,0,0,0,AAPL
2024-10-22 12:17:15.776849238+00:00,10,40,38,A,B,0,235.08,200,194,204618,69312,234.27,235.08,200,200,0,0,,,0,0,0,0,,,0,0,0,0,,,0,0,0,0,,,0,0,0,0,,,0,0,0,0,,,0,0,0,0,,,0,0,0,0,,,0,0,0,0,,,0,0,0,0,AAPL
2024-10-22 12:17:27.349732389+00:00,10,39,38,C,A,0,236.6,2000,130,204160,43221,232.8,,2000,0,1,0,,,0,0,0,0,,,0,0,0,0,,,0,0,0,0,,,0,0,0,0,,,0,0,0,0,,,0,0,0,0,,,0,0,0,0,,,0,0,0,0,,,0,0,0,0,AAPL
2024-10-22 12:17:27.386534462+00:00,10,39,38,A,A,0,236.8,2000,130,204314,43222,232.8,236.8,2000,2000,1,1,,,0,0,0,0,,,0,0,0,0,,,0,0,0,0,,,0,0,0,0,,,0,0,0,0,,,0,0,0,0,,,0,0,0,0,,,0,0,0,0,,,0,0,0,0,AAPL
2024-10-22 12:17:36.759350956+00:00,10,39,38,C,B,0,232.8,2000,130,204343,43276,,236.8,0,2000,0,1,,,0,0,0,0,,,0,0,0,0,,,0,0,0,0,,,0,0,0,0,,,0,0,0,0,,,0,0,0,0,,,0,0,0,0,,,0,0,0,0,,,0,0,0,0,AAPL
2024-10-22 12:17:36.768700077+00:00,10,39,38,A,A,0,236.6,2000,130,204221,43277,,236.6,0,2000,0,1,,236.8,0,2000,0,1,,,0,0,0,0,,,0,0,0,0,,,0,0,0,0,,,0,0,0,0,,,0,0,0,0,,,0,0,0,0,,,0,0,0,0,,,0,0,0,0,AAPL
2024-10-22 12:17:36.768897463+00:00,10,39,38,C,A,1,236.8,2000,130,204094,43278,,236.6,0,2000,0,1,,,0,0,0,0,,,0,0,0,0,,,0,0,0,0,,,0,0,0,0,,,0,0,0,0,,,0,0,0,0,,,0,0,0,0,,,0,0,0,0,,,0,0,0,0,AAPL
2024-10-22 12:17:36.794688210+00:00,10,39,38,A,B,0,232.8,2000,130,204201,43279,232.8,236.6,2000,2000,1,1,,,0,0,0,0,,,0,0,0,0,,,0,0,0,0,,,0,0,0,0,,,0,0,0,0,,,0,0,0,0,,,0,0,0,0,,,0,0,0,0,,,0,0,0,0,AAPL
2024-10-22 12:17:41.856020294+00:00,10,39,38,C,B,0,232.8,2000,130,204079,43290,,236.6,0,2000,0,1,,,0,0,0,0,,,0,0,0,0,,,0,0,0,0,,,0,0,0,0,,,0,0,0,0,,,0,0,0,0,,,0,0,0,0,,,0,0,0,0,,,0,0,0,0,AAPL
2024-10-22 12:17:41.891770268+00:00,10,39,38,A,B,0,232.8,2000,130,204172,43294,232.8,236.6,2000,2000,1,1,,,0,0,0,0,,,0,0,0,0,,,0,0,0,0,,,0,0,0,0,,,0,0,0,0,,,0,0,0,0,,,0,0,0,0,,,0,0,0,0,,,0,0,0,0,AAPL
2024-10-22 12:17:42.046667168+00:00,10,39,38,C,B,0,232.8,2000,130,204397,43296,,236.6,0,2000,0,1,,,0,0,0,0,,,0,0,0,0,,,0,0,0,0,,,0,0,0,0,,,0,0,0,0,,,0,0,0,0,,,0,0,0,0,,,0,0,0,0,,,0,0,0,0,AAPL
2024-10-22 12:17:42.082771770+00:00,10,39,38,A,B,0,232.8,2000,130,204134,43297,232.8,236.6,2000,2000,1,1,,,0,0,0,0,,,0,0,0,0,,,0,0,0,0,,,0,0,0,0,,,0,0,0,0,,,0,0,0,0,,,0,0,0,0,,,0,0,0,0,,,0,0,0,0,AAPL
2024-10-22 12:17:42.103273724+00:00,10,39,38,C,B,0,232.8,2000,130,204088,43298,,236.6,0,2000,0,1,,,0,0,0,0,,,0,0,0,0,,,0,0,0,0,,,0,0,0,0,,,0,0,0,0,,,0,0,0,0,,,0,0,0,0,,,0,0,0,0,,,0,0,0,0,AAPL
2024-10-22 12:17:42.139723497+00:00,10,39,38,A,B,0,232.8,2000,130,204151,43301,232.8,236.6,2000,2000,1,1,,,0,0,0,0,,,0,0,0,0,,,0,0,0,0,,,0,0,0,0,,,0,0,0,0,,,0,0,0,0,,,0,0,0,0,,,0,0,0,0,,,0,0,0,0,AAPL
2024-10-22 12:17:43.867370041+00:00,10,39,38,A,B,0,233.0,2000,130,204695,43309,233.0,236.6,2000,2000,1,1,232.8,,2000,0,1,0,,,0,0,0,0,,,0,0,0,0,,,0,0,0,0,,,0,0,0,0,,,0,0,0,0,,,0,0,0,0,,,0,0,0,0,,,0,0,0,0,AAPL
2024-10-22 12:17:43.868094586+00:00,10,39,38,C,B,1,232.8,2000,130,204043,43310,233.0,236.6,2000,2000,1,1,,,0,0,0,0,,,0,0,0,0,,,0,0,0,0,,,0,0,0,0,,,0,0,0,0,,,0,0,0,0,,,0,0,0,0,,,0,0,0,0,,,0,0,0,0,AAPL
2024-10-22 12:17:49.201260898+00:00,10,39,38,C,B,0,233.0,2000,130,203862,43337,,236.6,0,2000,0,1,,,0,0,0,0,,,0,0,0,0,,,0,0,0,0,,,0,0,0,0,,,0,0,0,0,,,0,0,0,0,,,0,0,0,0,,,0,0,0,0,,,0,0,0,0,AAPL
2024-10-22 12:17:49.236539580+00:00,10,39,38,A,B,0,233.0,2000,130,203957,43338,233.0,236.6,2000,2000,1,1,,,0,0,0,0,,,0,0,0,0,,,0,0,0,0,,,0,0,0,0,,,0,0,0,0,,,0,0,0,0,,,0,0,0,0,,,0,0,0,0,,,0,0,0,0,AAPL
2024-10-22 12:17:56.074902715+00:00,10,39,38,C,B,0,233.0,2000,130,204053,43359,,236.6,0,2000,0,1,,,0,0,0,0,,,0,0,0,0,,,0,0,0,0,,,0,0,0,0,,,0,0,0,0,,,0,0,0,0,,,0,0,0,0,,,0,0,0,0,,,0,0,0,0,AAPL
2024-10-22 12:17:56.112382296+00:00,10,39,38,A,B,0,232.8,2000,130,203899,43360,232.8,236.6,2000,2000,1,1,,,0,0,0,0,,,0,0,0,0,,,0,0,0,0,,,0,0,0,0,,,0,0,0,0,,,0,0,0,0,,,0,0,0,0,,,0,0,0,0,,,0,0,0,0,AAPL
2024-10-22 12:17:57.390149963+00:00,10,39,10888,A,A,0,419.08,100,130,204083,67070,,419.08,0,100,0,1,,,0,0,0,0,,,0,0,0,0,,,0,0,0,0,,,0,0,0,0,,,0,0,0,0,,,0,0,0,0,,,0,0,0,0,,,0,0,0,0,,,0,0,0,0,MSFT
2024-10-22 12:17:59.309360537+00:00,10,39,10888,C,A,0,419.08,100,130,203613,67087,,,0,0,0,0,,,0,0,0,0,,,0,0,0,0,,,0,0,0,0,,,0,0,0,0,,,0,0,0,0,,,0,0,0,0,,,0,0,0,0,,,0,0,0,0,,,0,0,0,0,MSFT
2024-10-22 12:18:01.311880186+00:00,10,41,38,A,B,0,235.02,200,194,56444,108695,,235.02,0,200,0,0,,,0,0,0,0,,,0,0,0,0,,,0,0,0,0,,,0,0,0,0,,,0,0,0,0,,,0,0,0,0,,,0,0,0,0,,,0,0,0,0,,,0,0,0,0,AAPL
2024-10-22 12:18:02.400261426+00:00,10,39,38,C,A,0,236.6,2000,130,203678,43419,232.8,,2000,0,1,0,,,0,0,0,0,,,0,0,0,0,,,0,0,0,0,,,0,0,0,0,,,0,0,0,0,,,0,0,0,0,,,0,0,0,0,,,0,0,0,0,,,0,0,0,0,AAPL
2024-10-22 12:18:02.410972345+00:00,10,39,38,A,A,0,237.0,2000,130,203684,43420,232.8,237.0,2000,2000,1,1,,,0,0,0,0,,,0,0,0,0,,,0,0,0,0,,,0,0,0,0,,,0,0,0,0,,,0,0,0,0,,,0,0,0,0,,,0,0,0,0,,,0,0,0,0,AAPL
2024-10-22 12:18:02.427917176+00:00,10,39,38,C,A,0,237.0,2000,130,203605,43421,232.8,,2000,0,1,0,,,0,0,0,0,,,0,0,0,0,,,0,0,0,0,,,0,0,0,0,,,0,0,0,0,,,0,0,0,0,,,0,0,0,0,,,0,0,0,0,,,0,0,0,0,AAPL
2024-10-22 12:18:02.710840084+00:00,10,39,38,A,A,0,236.8,2000,130,203519,43430,232.8,236.8,2000,2000,1,1,,,0,0,0,0,,,0,0,0,0,,,0,0,0,0,,,0,0,0,0,,,0,0,0,0,,,0,0,0,0,,,0,0,0,0,,,0,0,0,0,,,0,0,0,0,AAPL
2024-10-22 12:18:04.345935912+00:00,10,40,38,A,B,0,235.08,200,194,203475,69909,,235.08,0,200,0,0,,,0,0,0,0,,,0,0,0,0,,,0,0,0,0,,,0,0,0,0,,,0,0,0,0,,,0,0,0,0,,,0,0,0,0,,,0,0,0,0,,,0,0,0,0,AAPL
2024-10-22 12:18:04.748381294+00:00,10,40,38,A,B,0,235.08,200,194,203556,69912,234.26,235.08,200,200,0,0,,,0,0,0,0,,,0,0,0,0,,,0,0,0,0,,,0,0,0,0,,,0,0,0,0,,,0,0,0,0,,,0,0,0,0,,,0,0,0,0,,,0,0,0,0,AAPL
2024-10-22 12:18:04.748920166+00:00,10,41,38,A,B,0,235.02,200,194,56145,108810,234.33,235.02,200,200,0,0,,,0,0,0,0,,,0,0,0,0,,,0,0,0,0,,,0,0,0,0,,,0,0,0,0,,,0,0,0,0,,,0,0,0,0,,,0,0,0,0,,,0,0,0,0,AAPL
2024-10-22 12:18:05.802012118+00:00,10,39,38,C,B,0,232.8,2000,130,203636,43488,,236.8,0,2000,0,1,,,0,0,0,0,,,0,0,0,0,,,0,0,0,0,,,0,0,0,0,,,0,0,0,0,,,0,0,0,0,,,0,0,0,0,,,0,0,0,0,,,0,0,0,0,AAPL
2024-10-22 12:18:05.838883898+00:00,10,39,38,A,B,0,233.0,2000,130,203491,43489,233.0,236.8,2000,2000,1,1,,,0,0,0,0,,,0,0,0,0,,,0,0,0,0,,,0,0,0,0,,,0,0,0,0,,,0,0,0,0,,,0,0,0,0,,,0,0,0,0,,,0,0,0,0,AAPL
2024-10-22 12:18:07.665133061+00:00,10,41,38,A,B,0,235.02,200,194,60849,108941,,235.02,0,200,0,0,,,0,0,0,0,,,0,0,0,0,,,0,0,0,0,,,0,0,0,0,,,0,0,0,0,,,0,0,0,0,,,0,0,0,0,,,0,0,0,0,,,0,0,0,0,AAPL
2024-10-22 12:18:10.921274942+00:00,10,39,10888,A,A,0,419.07,100,130,203217,67360,,419.07,0,100,0,1,,,0,0,0,0,,,0,0,0,0,,,0,0,0,0,,,0,0,0,0,,,0,0,0,0,,,0,0,0,0,,,0,0,0,0,,,0,0,0,0,,,0,0,0,0,MSFT
2024-10-22 12:18:12.968882565+00:00,10,39,10888,C,A,0,419.07,100,130,203409,67378,,,0,0,0,0,,,0,0,0,0,,,0,0,0,0,,,0,0,0,0,,,0,0,0,0,,,0,0,0,0,,,0,0,0,0,,,0,0,0,0,,,0,0,0,0,,,0,0,0,0,MSFT
2024-10-22 12:18:13.956972822+00:00,10,41,38,A,B,0,235.02,200,194,61077,109141,234.33,235.02,200,200,0,0,,,0,0,0,0,,,0,0,0,0,,,0,0,0,0,,,0,0,0,0,,,0,0,0,0,,,0,0,0,0,,,0,0,0,0,,,0,0,0,0,,,0,0,0,0,AAPL
2024-10-22 12:18:31.217260015+00:00,10,41,38,A,B,0,235.02,200,194,61148,109558,,235.02,0,200,0,0,,,0,0,0,0,,,0,0,0,0,,,0,0,0,0,,,0,0,0,0,,,0,0,0,0,,,0,0,0,0,,,0,0,0,0,,,0,0,0,0,,,0,0,0,0,AAPL
2024-10-22 12:18:31.318145336+00:00,10,41,38,A,B,0,235.02,200,194,56092,109562,234.32,235.02,200,200,0,0,,,0,0,0,0,,,0,0,0,0,,,0,0,0,0,,,0,0,0,0,,,0,0,0,0,,,0,0,0,0,,,0,0,0,0,,,0,0,0,0,,,0,0,0,0,AAPL
2024-10-22 12:18:34.475895570+00:00,10,39,38,C,B,0,233.0,2000,130,205088,43807,,236.8,0,2000,0,1,,,0,0,0,0,,,0,0,0,0,,,0,0,0,0,,,0,0,0,0,,,0,0,0,0,,,0,0,0,0,,,0,0,0,0,,,0,0,0,0,,,0,0,0,0,AAPL
2024-10-22 12:18:34.485883544+00:00,10,39,38,A,A,0,236.6,2000,130,204693,43808,,236.6,0,2000,0,1,,236.8,0,2000,0,1,,,0,0,0,0,,,0,0,0,0,,,0,0,0,0,,,0,0,0,0,,,0,0,0,0,,,0,0,0,0,,,0,0,0,0,,,0,0,0,0,AAPL
2024-10-22 12:18:34.486071505+00:00,10,39,38,C,A,1,236.8,2000,130,204661,43809,,236.6,0,2000,0,1,,,0,0,0,0,,,0,0,0,0,,,0,0,0,0,,,0,0,0,0,,,0,0,0,0,,,0,0,0,0,,,0,0,0,0,,,0,0,0,0,,,0,0,0,0,AAPL
2024-10-22 12:18:34.512521808+00:00,10,39,38,A,B,0,233.0,2000,130,204733,43810,233.0,236.6,2000,2000,1,1,,,0,0,0,0,,,0,0,0,0,,,0,0,0,0,,,0,0,0,0,,,0,0,0,0,,,0,0,0,0,,,0,0,0,0,,,0,0,0,0,,,0,0,0,0,AAPL
2024-10-22 12:18:56.733767975+00:00,10,39,10888,A,A,0,419.07,100,130,203354,67931,,419.07,0,100,0,1,,,0,0,0,0,,,0,0,0,0,,,0,0,0,0,,,0,0,0,0,,,0,0,0,0,,,0,0,0,0,,,0,0,0,0,,,0,0,0,0,,,0,0,0,0,MSFT
2024-10-22 12:18:59.263940434+00:00,10,39,38,C,A,0,236.6,2000,130,203032,43976,233.0,,2000,0,1,0,,,0,0,0,0,,,0,0,0,0,,,0,0,0,0,,,0,0,0,0,,,0,0,0,0,,,0,0,0,0,,,0,0,0,0,,,0,0,0,0,,,0,0,0,0,AAPL
2024-10-22 12:18:59.292490206+00:00,10,39,38,A,A,0,236.6,2000,130,203087,43977,233.0,236.6,2000,2000,1,1,,,0,0,0,0,,,0,0,0,0,,,0,0,0,0,,,0,0,0,0,,,0,0,0,0,,,0,0,0,0,,,0,0,0,0,,,0,0,0,0,,,0,0,0,0,AAPL
2024-10-22 12:18:59.295151359+00:00,10,39,38,C,A,0,236.6,2000,130,202979,43978,233.0,,2000,0,1,0,,,0,0,0,0,,,0,0,0,0,,,0,0,0,0,,,0,0,0,0,,,0,0,0,0,,,0,0,0,0,,,0,0,0,0,,,0,0,0,0,,,0,0,0,0,AAPL
2024-10-22 12:18:59.305850457+00:00,10,39,38,A,A,0,237.0,2000,130,202979,43979,233.0,237.0,2000,2000,1,1,,,0,0,0,0,,,0,0,0,0,,,0,0,0,0,,,0,0,0,0,,,0,0,0,0,,,0,0,0,0,,,0,0,0,0,,,0,0,0,0,,,0,0,0,0,AAPL
2024-10-22 12:18:59.331324898+00:00,10,39,38,C,A,0,237.0,2000,130,202987,43980,233.0,,2000,0,1,0,,,0,0,0,0,,,0,0,0,0,,,0,0,0,0,,,0,0,0,0,,,0,0,0,0,,,0,0,0,0,,,0,0,0,0,,,0,0,0,0,,,0,0,0,0,AAPL
2024-10-22 12:18:59.608952073+00:00,10,39,38,A,A,0,236.8,2000,130,203209,43981,233.0,236.8,2000,2000,1,1,,,0,0,0,0,,,0,0,0,0,,,0,0,0,0,,,0,0,0,0,,,0,0,0,0,,,0,0,0,0,,,0,0,0,0,,,0,0,0,0,,,0,0,0,0,AAPL
2024-10-22 12:19:02.174136215+00:00,10,39,10888,C,A,0,419.07,100,130,203068,67998,,,0,0,0,0,,,0,0,0,0,,,0,0,0,0,,,0,0,0,0,,,0,0,0,0,,,0,0,0,0,,,0,0,0,0,,,0,0,0,0,,,0,0,0,0,,,0,0,0,0,MSFT
2024-10-22 12:19:02.925955231+00:00,10,39,38,C,B,0,233.0,2000,130,202733,44005,,236.8,0,2000,0,1,,,0,0,0,0,,,0,0,0,0,,,0,0,0,0,,,0,0,0,0,,,0,0,0,0,,,0,0,0,0,,,0,0,0,0,,,0,0,0,0,,,0,0,0,0,AAPL
2024-10-22 12:19:02.962121220+00:00,10,39,38,A,B,0,233.0,2000,130,202780,44006,233.0,236.8,2000,2000,1,1,,,0,0,0,0,,,0,0,0,0,,,0,0,0,0,,,0,0,0,0,,,0,0,0,0,,,0,0,0,0,,,0,0,0,0,,,0,0,0,0,,,0,0,0,0,AAPL
2024-10-22 12:19:11.614942985+00:00,10,40,38,A,A,0,,0,194,203481,70627,234.26,,200,0,0,0,,,0,0,0,0,,,0,0,0,0,,,0,0,0,0,,,0,0,0,0,,,0,0,0,0,,,0,0,0,0,,,0,0,0,0,,,0,0,0,0,,,0,0,0,0,AAPL
2024-10-22 12:19:11.614959411+00:00,10,40,38,A,A,0,235.04,200,194,203273,70628,234.26,235.04,200,200,0,0,,,0,0,0,0,,,0,0,0,0,,,0,0,0,0,,,0,0,0,0,,,0,0,0,0,,,0,0,0,0,,,0,0,0,0,,,0,0,0,0,,,0,0,0,0,AAPL
2024-10-22 12:19:33.902272702+00:00,10,39,38,C,A,0,236.8,2000,130,203735,44187,233.0,,2000,0,1,0,,,0,0,0,0,,,0,0,0,0,,,0,0,0,0,,,0,0,0,0,,,0,0,0,0,,,0,0,0,0,,,0,0,0,0,,,0,0,0,0,,,0,0,0,0,AAPL
2024-10-22 12:19:33.938795437+00:00,10,39,38,A,A,0,237.0,2000,130,203243,44188,233.0,237.0,2000,2000,1,1,,,0,0,0,0,,,0,0,0,0,,,0,0,0,0,,,0,0,0,0,,,0,0,0,0,,,0,0,0,0,,,0,0,0,0,,,0,0,0,0,,,0,0,0,0,AAPL
2024-10-22 12:19:41.543723212+00:00,10,39,38,A,A,0,236.6,2000,130,203515,44233,233.0,236.6,2000,2000,1,1,,237.0,0,2000,0,1,,,0,0,0,0,,,0,0,0,0,,,0,0,0,0,,,0,0,0,0,,,0,0,0,0,,,0,0,0,0,,,0,0,0,0,,,0,0,0,0,AAPL
2024-10-22 12:19:41.543925903+00:00,10,39,38,C,A,1,237.0,2000,130,203313,44234,233.0,236.6,2000,2000,1,1,,,0,0,0,0,,,0,0,0,0,,,0,0,0,0,,,0,0,0,0,,,0,0,0,0,,,0,0,0,0,,,0,0,0,0,,,0,0,0,0,,,0,0,0,0,AAPL
2024-10-22 12:19:41.597097799+00:00,10,39,38,C,A,0,236.6,2000,130,203298,44235,233.0,,2000,0,1,0,,,0,0,0,0,,,0,0,0,0,,,0,0,0,0,,,0,0,0,0,,,0,0,0,0,,,0,0,0,0,,,0,0,0,0,,,0,0,0,0,,,0,0,0,0,AAPL
2024-10-22 12:19:41.610726910+00:00,10,39,38,A,A,0,236.8,2000,130,203227,44238,233.0,236.8,2000,2000,1,1,,,0,0,0,0,,,0,0,0,0,,,0,0,0,0,,,0,0,0,0,,,0,0,0,0,,,0,0,0,0,,,0,0,0,0,,,0,0,0,0,,,0,0,0,0,AAPL
2024-10-22 12:19:58.302575709+00:00,10,39,38,C,B,0,233.0,2000,130,203989,44361,,236.8,0,2000,0,1,,,0,0,0,0,,,0,0,0,0,,,0,0,0,0,,,0,0,0,0,,,0,0,0,0,,,0,0,0,0,,,0,0,0,0,,,0,0,0,0,,,0,0,0,0,AAPL
2024-10-22 12:19:58.313444092+00:00,10,39,38,A,B,0,232.8,2000,130,203948,44362,232.8,236.8,2000,2000,1,1,,,0,0,0,0,,,0,0,0,0,,,0,0,0,0,,,0,0,0,0,,,0,0,0,0,,,0,0,0,0,,,0,0,0,0,,,0,0,0,0,,,0,0,0,0,AAPL
2024-10-22 12:20:00.067037625+00:00,10,40,38,A,N,0,,0,194,202858,71063,,,0,0,0,0,,,0,0,0,0,,,0,0,0,0,,,0,0,0,0,,,0,0,0,0,,,0,0,0,0,,,0,0,0,0,,,0,0,0,0,,,0,0,0,0,,,0,0,0,0,AAPL
2024-10-22 12:20:00.067258781+00:00,10,41,38,A,B,0,235.02,200,194,54743,112425,,235.02,0,200,0,0,,,0,0,0,0,,,0,0,0,0,,,0,0,0,0,,,0,0,0,0,,,0,0,0,0,,,0,0,0,0,,,0,0,0,0,,,0,0,0,0,,,0,0,0,0,AAPL
2024-10-22 12:20:00.067309132+00:00,10,41,38,A,A,0,,0,194,55783,112426,,,0,0,0,0,,,0,0,0,0,,,0,0,0,0,,,0,0,0,0,,,0,0,0,0,,,0,0,0,0,,,0,0,0,0,,,0,0,0,0,,,0,0,0,0,,,0,0,0,0,AAPL
2024-10-22 12:20:00.530068257+00:00,10,41,38,A,B,0,,0,194,55691,112794,234.3,,200,0,0,0,,,0,0,0,0,,,0,0,0,0,,,0,0,0,0,,,0,0,0,0,,,0,0,0,0,,,0,0,0,0,,,0,0,0,0,,,0,0,0,0,,,0,0,0,0,AAPL
2024-10-22 12:20:00.671867466+00:00,10,41,38,A,B,0,,0,194,60707,112800,,,0,0,0,0,,,0,0,0,0,,,0,0,0,0,,,0,0,0,0,,,0,0,0,0,,,0,0,0,0,,,0,0,0,0,,,0,0,0,0,,,0,0,0,0,,,0,0,0,0,AAPL
2024-10-22 12:20:05.631895148+00:00,10,41,38,A,B,0,,0,194,56049,113020,234.3,,200,0,0,0,,,0,0,0,0,,,0,0,0,0,,,0,0,0,0,,,0,0,0,0,,,0,0,0,0,,,0,0,0,0,,,0,0,0,0,,,0,0,0,0,,,0,0,0,0,AAPL
2024-10-22 12:20:05.631908597+00:00,10,41,38,A,A,0,234.97,200,194,54375,113021,234.3,234.97,200,200,0,0,,,0,0,0,0,,,0,0,0,0,,,0,0,0,0,,,0,0,0,0,,,0,0,0,0,,,0,0,0,0,,,0,0,0,0,,,0,0,0,0,,,0,0,0,0,AAPL
2024-10-22 12:20:05.935503607+00:00,10,41,38,A,B,0,234.97,200,194,61115,113034,,234.97,0,200,0,0,,,0,0,0,0,,,0,0,0,0,,,0,0,0,0,,,0,0,0,0,,,0,0,0,0,,,0,0,0,0,,,0,0,0,0,,,0,0,0,0,,,0,0,0,0,AAPL
2024-10-22 12:20:07.101333565+00:00,10,41,38,A,B,0,234.97,200,194,55607,113091,234.3,234.97,200,200,0,0,,,0,0,0,0,,,0,0,0,0,,,0,0,0,0,,,0,0,0,0,,,0,0,0,0,,,0,0,0,0,,,0,0,0,0,,,0,0,0,0,,,0,0,0,0,AAPL
2024-10-22 12:20:07.503813108+00:00,10,41,38,A,B,0,234.97,200,194,55679,113109,,234.97,0,200,0,0,,,0,0,0,0,,,0,0,0,0,,,0,0,0,0,,,0,0,0,0,,,0,0,0,0,,,0,0,0,0,,,0,0,0,0,,,0,0,0,0,,,0,0,0,0,AAPL
2024-10-22 12:20:08.309979067+00:00,10,41,38,A,A,0,,0,194,55245,113145,,,0,0,0,0,,,0,0,0,0,,,0,0,0,0,,,0,0,0,0,,,0,0,0,0,,,0,0,0,0,,,0,0,0,0,,,0,0,0,0,,,0,0,0,0,,,0,0,0,0,AAPL
2024-10-22 12:20:10.495698383+00:00,10,40,38,A,B,0,,0,194,203124,71277,234.23,,200,0,0,0,,,0,0,0,0,,,0,0,0,0,,,0,0,0,0,,,0,0,0,0,,,0,0,0,0,,,0,0,0,0,,,0,0,0,0,,,0,0,0,0,,,0,0,0,0,AAPL
2024-10-22 12:20:10.495991256+00:00,10,41,38,A,B,0,,0,194,56079,113214,234.3,,200,0,0,0,,,0,0,0,0,,,0,0,0,0,,,0,0,0,0,,,0,0,0,0,,,0,0,0,0,,,0,0,0,0,,,0,0,0,0,,,0,0,0,0,,,0,0,0,0,AAPL
2024-10-22 12:20:10.495904513+00:00,10,40,38,A,A,0,235.04,200,194,203163,71278,234.23,235.04,200,200,0,0,,,0,0,0,0,,,0,0,0,0,,,0,0,0,0,,,0,0,0,0,,,0,0,0,0,,,0,0,0,0,,,0,0,0,0,,,0,0,0,0,,,0,0,0,0,AAPL
2024-10-22 12:20:10.496298276+00:00,10,41,38,A,A,0,234.97,200,194,54966,113215,234.3,234.97,200,200,0,0,,,0,0,0,0,,,0,0,0,0,,,0,0,0,0,,,0,0,0,0,,,0,0,0,0,,,0,0,0,0,,,0,0,0,0,,,0,0,0,0,,,0,0,0,0,AAPL
2024-10-22 12:20:10.496385338+00:00,10,39,38,C,B,0,232.8,2000,130,203949,44546,,236.8,0,2000,0,1,,,0,0,0,0,,,0,0,0,0,,,0,0,0,0,,,0,0,0,0,,,0,0,0,0,,,0,0,0,0,,,0,0,0,0,,,0,0,0,0,,,0,0,0,0,AAPL
2024-10-22 12:20:10.533525944+00:00,10,39,38,A,B,0,233.0,2000,130,203837,44547,233.0,236.8,2000,2000,1,1,,,0,0,0,0,,,0,0,0,0,,,0,0,0,0,,,0,0,0,0,,,0,0,0,0,,,0,0,0,0,,,0,0,0,0,,,0,0,0,0,,,0,0,0,0,AAPL
2024-10-22 12:20:10.606946900+00:00,10,41,38,A,B,0,234.97,200,194,54926,113222,,234.97,0,200,0,0,,,0,0,0,0,,,0,0,0,0,,,0,0,0,0,,,0,0,0,0,,,0,0,0,0,,,0,0,0,0,,,0,0,0,0,,,0,0,0,0,,,0,0,0,0,AAPL
2024-10-22 12:20:10.697976098+00:00,10,40,38,A,B,0,235.04,200,194,202958,71281,,235.04,0,200,0,0,,,0,0,0,0,,,0,0,0,0,,,0,0,0,0,,,0,0,0,0,,,0,0,0,0,,,0,0,0,0,,,0,0,0,0,,,0,0,0,0,,,0,0,0,0,AAPL
2024-10-22 12:20:10.698000819+00:00,10,40,38,A,B,0,235.04,200,194,202986,71282,234.22,235.04,200,200,0,0,,,0,0,0,0,,,0,0,0,0,,,0,0,0,0,,,0,0,0,0,,,0,0,0,0,,,0,0,0,0,,,0,0,0,0,,,0,0,0,0,,,0,0,0,0,AAPL
2024-10-22 12:20:10.698058915+00:00,10,40,38,A,A,0,,0,194,203001,71283,234.22,,200,0,0,0,,,0,0,0,0,,,0,0,0,0,,,0,0,0,0,,,0,0,0,0,,,0,0,0,0,,,0,0,0,0,,,0,0,0,0,,,0,0,0,0,,,0,0,0,0,AAPL
2024-10-22 12:20:10.698129341+00:00,10,40,38,A,A,0,235.04,200,194,202944,71284,234.22,235.04,200,200,0,0,,,0,0,0,0,,,0,0,0,0,,,0,0,0,0,,,0,0,0,0,,,0,0,0,0,,,0,0,0,0,,,0,0,0,0,,,0,0,0,0,,,0,0,0,0,AAPL
2024-10-22 12:20:10.698163626+00:00,10,40,38,A,B,0,235.04,200,194,202925,71285,,235.04,0,200,0,0,,,0,0,0,0,,,0,0,0,0,,,0,0,0,0,,,0,0,0,0,,,0,0,0,0,,,0,0,0,0,,,0,0,0,0,,,0,0,0,0,,,0,0,0,0,AAPL
2024-10-22 12:20:10.698265956+00:00,10,40,38,A,A,0,,0,194,203046,71286,,,0,0,0,0,,,0,0,0,0,,,0,0,0,0,,,0,0,0,0,,,0,0,0,0,,,0,0,0,0,,,0,0,0,0,,,0,0,0,0,,,0,0,0,0,,,0,0,0,0,AAPL
2024-10-22 12:20:11.098813264+00:00,10,40,38,A,B,0,,0,194,202994,71292,234.22,,200,0,0,0,,,0,0,0,0,,,0,0,0,0,,,0,0,0,0,,,0,0,0,0,,,0,0,0,0,,,0,0,0,0,,,0,0,0,0,,,0,0,0,0,,,0,0,0,0,AAPL
2024-10-22 12:20:11.098819281+00:00,10,40,38,A,A,0,235.04,200,194,202980,71293,234.22,235.04,200,200,0,0,,,0,0,0,0,,,0,0,0,0,,,0,0,0,0,,,0,0,0,0,,,0,0,0,0,,,0,0,0,0,,,0,0,0,0,,,0,0,0,0,,,0,0,0,0,AAPL
2024-10-22 12:20:11.099359496+00:00,10,41,38,A,B,0,234.97,200,194,56260,113230,234.29,234.97,200,200,0,0,,,0,0,0,0,,,0,0,0,0,,,0,0,0,0,,,0,0,0,0,,,0,0,0,0,,,0,0,0,0,,,0,0,0,0,,,0,0,0,0,,,0,0,0,0,AAPL
2024-10-22 12:20:12.310325389+00:00,10,41,38,A,B,0,234.97,200,194,55618,113267,,234.97,0,200,0,0,,,0,0,0,0,,,0,0,0,0,,,0,0,0,0,,,0,0,0,0,,,0,0,0,0,,,0,0,0,0,,,0,0,0,0,,,0,0,0,0,,,0,0,0,0,AAPL
2024-10-22 12:20:15.960860372+00:00,10,41,38,A,B,0,234.97,200,194,61084,113354,234.29,234.97,200,200,0,0,,,0,0,0,0,,,0,0,0,0,,,0,0,0,0,,,0,0,0,0,,,0,0,0,0,,,0,0,0,0,,,0,0,0,0,,,0,0,0,0,,,0,0,0,0,AAPL
2024-10-22 12:20:18.274950632+00:00,10,41,38,A,B,0,234.97,200,194,56018,113430,,234.97,0,200,0,0,,,0,0,0,0,,,0,0,0,0,,,0,0,0,0,,,0,0,0,0,,,0,0,0,0,,,0,0,0,0,,,0,0,0,0,,,0,0,0,0,,,0,0,0,0,AAPL
2024-10-22 12:20:18.636964603+00:00,10,41,38,A,B,0,234.97,200,194,55888,113455,234.3,234.97,200,200,0,0,,,0,0,0,0,,,0,0,0,0,,,0,0,0,0,,,0,0,0,0,,,0,0,0,0,,,0,0,0,0,,,0,0,0,0,,,0,0,0,0,,,0,0,0,0,AAPL
2024-10-22 12:20:18.637522715+00:00,10,41,38,A,B,0,234.97,200,194,56038,113456,,234.97,0,200,0,0,,,0,0,0,0,,,0,0,0,0,,,0,0,0,0,,,0,0,0,0,,,0,0,0,0,,,0,0,0,0,,,0,0,0,0,,,0,0,0,0,,,0,0,0,0,AAPL
2024-10-22 12:20:19.118187840+00:00,10,41,38,A,B,0,234.97,200,194,56027,113473,234.29,234.97,200,200,0,0,,,0,0,0,0,,,0,0,0,0,,,0,0,0,0,,,0,0,0,0,,,0,0,0,0,,,0,0,0,0,,,0,0,0,0,,,0,0,0,0,,,0,0,0,0,AAPL
2024-10-22 12:20:21.699597340+00:00,10,41,38,A,B,0,234.97,200,194,62786,113551,,234.97,0,200,0,0,,,0,0,0,0,,,0,0,0,0,,,0,0,0,0,,,0,0,0,0,,,0,0,0,0,,,0,0,0,0,,,0,0,0,0,,,0,0,0,0,,,0,0,0,0,AAPL
2024-10-22 12:20:21.802953533+00:00,10,40,38,A,A,0,,0,194,203270,71401,234.22,,200,0,0,0,,,0,0,0,0,,,0,0,0,0,,,0,0,0,0,,,0,0,0,0,,,0,0,0,0,,,0,0,0,0,,,0,0,0,0,,,0,0,0,0,,,0,0,0,0,AAPL
2024-10-22 12:20:21.803437633+00:00,10,41,38,A,A,0,,0,194,55351,113556,,,0,0,0,0,,,0,0,0,0,,,0,0,0,0,,,0,0,0,0,,,0,0,0,0,,,0,0,0,0,,,0,0,0,0,,,0,0,0,0,,,0,0,0,0,,,0,0,0,0,AAPL
2024-10-22 12:20:21.803994377+00:00,10,41,38,A,B,0,,0,194,54879,113557,234.3,,200,0,0,0,,,0,0,0,0,,,0,0,0,0,,,0,0,0,0,,,0,0,0,0,,,0,0,0,0,,,0,0,0,0,,,0,0,0,0,,,0,0,0,0,,,0,0,0,0,AAPL
2024-10-22 12:20:21.810652103+00:00,10,40,38,A,A,0,235.04,200,194,202969,71402,234.22,235.04,200,200,0,0,,,0,0,0,0,,,0,0,0,0,,,0,0,0,0,,,0,0,0,0,,,0,0,0,0,,,0,0,0,0,,,0,0,0,0,,,0,0,0,0,,,0,0,0,0,AAPL
2024-10-22 12:20:21.811158910+00:00,10,41,38,A,A,0,234.97,200,194,55242,113558,234.3,234.97,200,200,0,0,,,0,0,0,0,,,0,0,0,0,,,0,0,0,0,,,0,0,0,0,,,0,0,0,0,,,0,0,0,0,,,0,0,0,0,,,0,0,0,0,,,0,0,0,0,AAPL
2024-10-22 12:20:22.113318606+00:00,10,41,38,A,B,0,234.97,200,194,56249,113566,,234.97,0,200,0,0,,,0,0,0,0,,,0,0,0,0,,,0,0,0,0,,,0,0,0,0,,,0,0,0,0,,,0,0,0,0,,,0,0,0,0,,,0,0,0,0,,,0,0,0,0,AAPL
2024-10-22 12:20:23.826164863+00:00,10,40,38,A,B,0,235.04,200,194,203173,71433,,235.04,0,200,0,0,,,0,0,0,0,,,0,0,0,0,,,0,0,0,0,,,0,0,0,0,,,0,0,0,0,,,0,0,0,0,,,0,0,0,0,,,0,0,0,0,,,0,0,0,0,AAPL
2024-10-22 12:20:24.669475885+00:00,10,40,38,A,B,0,235.04,200,194,203177,71436,234.22,235.04,200,200,0,0,,,0,0,0,0,,,0,0,0,0,,,0,0,0,0,,,0,0,0,0,,,0,0,0,0,,,0,0,0,0,,,0,0,0,0,,,0,0,0,0,,,0,0,0,0,AAPL
2024-10-22 12:20:24.669771174+00:00,10,41,38,A,B,0,234.97,200,194,60299,113705,234.29,234.97,200,200,0,0,,,0,0,0,0,,,0,0,0,0,,,0,0,0,0,,,0,0,0,0,,,0,0,0,0,,,0,0,0,0,,,0,0,0,0,,,0,0,0,0,,,0,0,0,0,AAPL
2024-10-22 12:20:24.876913660+00:00,10,41,38,A,B,0,234.97,200,194,55138,113710,,234.97,0,200,0,0,,,0,0,0,0,,,0,0,0,0,,,0,0,0,0,,,0,0,0,0,,,0,0,0,0,,,0,0,0,0,,,0,0,0,0,,,0,0,0,0,,,0,0,0,0,AAPL
2024-10-22 12:20:29.329895798+00:00,10,41,38,A,B,0,234.97,200,194,55456,113882,234.29,234.97,200,200,0,0,,,0,0,0,0,,,0,0,0,0,,,0,0,0,0,,,0,0,0,0,,,0,0,0,0,,,0,0,0,0,,,0,0,0,0,,,0,0,0,0,,,0,0,0,0,AAPL
2024-10-22 12:20:31.918966120+00:00,10,39,38,C,A,0,236.8,2000,130,204104,44713,233.0,,2000,0,1,0,,,0,0,0,0,,,0,0,0,0,,,0,0,0,0,,,0,0,0,0,,,0,0,0,0,,,0,0,0,0,,,0,0,0,0,,,0,0,0,0,,,0,0,0,0,AAPL
2024-10-22 12:20:31.955325326+00:00,10,39,38,A,A,0,236.8,2000,130,203718,44715,233.0,236.8,2000,2000,1,1,,,0,0,0,0,,,0,0,0,0,,,0,0,0,0,,,0,0,0,0,,,0,0,0,0,,,0,0,0,0,,,0,0,0,0,,,0,0,0,0,,,0,0,0,0,AAPL
2024-10-22 12:20:33.477360667+00:00,10,39,38,C,A,0,236.8,2000,130,204076,44729,233.0,,2000,0,1,0,,,0,0,0,0,,,0,0,0,0,,,0,0,0,0,,,0,0,0,0,,,0,0,0,0,,,0,0,0,0,,,0,0,0,0,,,0,0,0,0,,,0,0,0,0,AAPL
2024-10-22 12:20:33.792088019+00:00,10,39,38,A,A,0,237.0,2000,130,203989,44730,233.0,237.0,2000,2000,1,1,,,0,0,0,0,,,0,0,0,0,,,0,0,0,0,,,0,0,0,0,,,0,0,0,0,,,0,0,0,0,,,0,0,0,0,,,0,0,0,0,,,0,0,0,0,AAPL
2024-10-22 12:20:37.654933931+00:00,10,41,38,A,B,0,234.97,200,194,57577,114083,,234.97,0,200,0,0,,,0,0,0,0,,,0,0,0,0,,,0,0,0,0,,,0,0,0,0,,,0,0,0,0,,,0,0,0,0,,,0,0,0,0,,,0,0,0,0,,,0,0,0,0,AAPL
2024-10-22 12:20:37.956666708+00:00,10,41,38,A,B,0,234.97,200,194,55586,114087,234.29,234.97,200,200,0,0,,,0,0,0,0,,,0,0,0,0,,,0,0,0,0,,,0,0,0,0,,,0,0,0,0,,,0,0,0,0,,,0,0,0,0,,,0,0,0,0,,,0,0,0,0,AAPL
2024-10-22 12:20:38.650132192+00:00,10,41,38,A,B,0,234.97,200,194,60007,114111,,234.97,0,200,0,0,,,0,0,0,0,,,0,0,0,0,,,0,0,0,0,,,0,0,0,0,,,0,0,0,0,,,0,0,0,0,,,0,0,0,0,,,0,0,0,0,,,0,0,0,0,AAPL
2024-10-22 12:20:39.481913617+00:00,10,41,38,A,B,0,234.97,200,194,60422,114140,234.3,234.97,200,200,0,0,,,0,0,0,0,,,0,0,0,0,,,0,0,0,0,,,0,0,0,0,,,0,0,0,0,,,0,0,0,0,,,0,0,0,0,,,0,0,0,0,,,0,0,0,0,AAPL
2024-10-22 12:20:59.564768541+00:00,10,39,38,A,A,0,236.8,2000,130,204025,44913,233.0,236.8,2000,2000,1,1,,237.0,0,2000,0,1,,,0,0,0,0,,,0,0,0,0,,,0,0,0,0,,,0,0,0,0,,,0,0,0,0,,,0,0,0,0,,,0,0,0,0,,,0,0,0,0,AAPL
2024-10-22 12:20:59.565228240+00:00,10,39,38,C,A,1,237.0,2000,130,203817,44914,233.0,236.8,2000,2000,1,1,,,0,0,0,0,,,0,0,0,0,,,0,0,0,0,,,0,0,0,0,,,0,0,0,0,,,0,0,0,0,,,0,0,0,0,,,0,0,0,0,,,0,0,0,0,AAPL
2024-10-22 12:20:59.638210204+00:00,10,39,38,C,B,0,233.0,2000,130,203822,44915,,236.8,0,2000,0,1,,,0,0,0,0,,,0,0,0,0,,,0,0,0,0,,,0,0,0,0,,,0,0,0,0,,,0,0,0,0,,,0,0,0,0,,,0,0,0,0,,,0,0,0,0,AAPL
2024-10-22 12:20:59.662589190+00:00,10,41,38,A,B,0,234.97,200,194,58378,114749,,234.97,0,200,0,0,,,0,0,0,0,,,0,0,0,0,,,0,0,0,0,,,0,0,0,0,,,0,0,0,0,,,0,0,0,0,,,0,0,0,0,,,0,0,0,0,,,0,0,0,0,AAPL
2024-10-22 12:20:59.662630644+00:00,10,41,38,A,B,0,234.97,200,194,64338,114750,234.12,234.97,200,200,0,0,,,0,0,0,0,,,0,0,0,0,,,0,0,0,0,,,0,0,0,0,,,0,0,0,0,,,0,0,0,0,,,0,0,0,0,,,0,0,0,0,,,0,0,0,0,AAPL
2024-10-22 12:20:59.677096629+00:00,10,39,38,C,A,0,236.8,2000,130,203889,44916,,,0,0,0,0,,,0,0,0,0,,,0,0,0,0,,,0,0,0,0,,,0,0,0,0,,,0,0,0,0,,,0,0,0,0,,,0,0,0,0,,,0,0,0,0,,,0,0,0,0,AAPL
2024-10-22 12:20:59.686393319+00:00,10,39,38,A,B,0,232.8,2000,130,203821,44917,232.8,,2000,0,1,0,,,0,0,0,0,,,0,0,0,0,,,0,0,0,0,,,0,0,0,0,,,0,0,0,0,,,0,0,0,0,,,0,0,0,0,,,0,0,0,0,,,0,0,0,0,AAPL
2024-10-22 12:20:59.726174945+00:00,10,39,38,C,B,0,232.8,2000,130,203894,44919,,,0,0,0,0,,,0,0,0,0,,,0,0,0,0,,,0,0,0,0,,,0,0,0,0,,,0,0,0,0,,,0,0,0,0,,,0,0,0,0,,,0,0,0,0,,,0,0,0,0,AAPL
2024-10-22 12:20:59.737358528+00:00,10,39,38,A,B,0,232.6,2000,130,203955,44920,232.6,,2000,0,1,0,,,0,0,0,0,,,0,0,0,0,,,0,0,0,0,,,0,0,0,0,,,0,0,0,0,,,0,0,0,0,,,0,0,0,0,,,0,0,0,0,,,0,0,0,0,AAPL
2024-10-22 12:20:59.784423864+00:00,10,41,38,A,B,0,234.97,200,194,55580,114760,,234.97,0,200,0,0,,,0,0,0,0,,,0,0,0,0,,,0,0,0,0,,,0,0,0,0,,,0,0,0,0,,,0,0,0,0,,,0,0,0,0,,,0,0,0,0,,,0,0,0,0,AAPL
2024-10-22 12:20:59.847310871+00:00,10,39,38,A,B,0,232.8,2000,130,203835,44921,232.8,,2000,0,1,0,232.6,,2000,0,1,0,,,0,0,0,0,,,0,0,0,0,,,0,0,0,0,,,0,0,0,0,,,0,0,0,0,,,0,0,0,0,,,0,0,0,0,,,0,0,0,0,AAPL
2024-10-22 12:20:59.847397504+00:00,10,40,38,A,B,0,235.04,200,194,203294,71832,,235.04,0,200,0,0,,,0,0,0,0,,,0,0,0,0,,,0,0,0,0,,,0,0,0,0,,,0,0,0,0,,,0,0,0,0,,,0,0,0,0,,,0,0,0,0,,,0,0,0,0,AAPL
2024-10-22 12:20:59.847417028+00:00,10,40,38,A,B,0,235.04,200,194,203264,71833,234.06,235.04,200,200,0,0,,,0,0,0,0,,,0,0,0,0,,,0,0,0,0,,,0,0,0,0,,,0,0,0,0,,,0,0,0,0,,,0,0,0,0,,,0,0,0,0,,,0,0,0,0,AAPL
2024-10-22 12:20:59.847499105+00:00,10,39,38,C,B,1,232.6,2000,130,203822,44922,232.8,,2000,0,1,0,,,0,0,0,0,,,0,0,0,0,,,0,0,0,0,,,0,0,0,0,,,0,0,0,0,,,0,0,0,0,,,0,0,0,0,,,0,0,0,0,,,0,0,0,0,AAPL
2024-10-22 12:20:59.945420474+00:00,10,40,38,A,A,0,,0,194,203373,71839,234.06,,200,0,0,0,,,0,0,0,0,,,0,0,0,0,,,0,0,0,0,,,0,0,0,0,,,0,0,0,0,,,0,0,0,0,,,0,0,0,0,,,0,0,0,0,,,0,0,0,0,AAPL
2024-10-22 12:20:59.945440244+00:00,10,40,38,A,A,0,234.89,200,194,203231,71840,234.06,234.89,200,200,0,0,,,0,0,0,0,,,0,0,0,0,,,0,0,0,0,,,0,0,0,0,,,0,0,0,0,,,0,0,0,0,,,0,0,0,0,,,0,0,0,0,,,0,0,0,0,AAPL
2024-10-22 12:20:59.945676928+00:00,10,41,38,A,A,0,,0,194,55266,114770,,,0,0,0,0,,,0,0,0,0,,,0,0,0,0,,,0,0,0,0,,,0,0,0,0,,,0,0,0,0,,,0,0,0,0,,,0,0,0,0,,,0,0,0,0,,,0,0,0,0,AAPL
2024-10-22 12:20:59.945770807+00:00,10,41,38,A,A,0,234.83,200,194,54587,114771,,234.83,0,200,0,0,,,0,0,0,0,,,0,0,0,0,,,0,0,0,0,,,0,0,0,0,,,0,0,0,0,,,0,0,0,0,,,0,0,0,0,,,0,0,0,0,,,0,0,0,0,AAPL
2024-10-22 12:20:59.993967255+00:00,10,39,38,A,A,0,236.6,2000,130,203855,44928,232.8,236.6,2000,2000,1,1,,,0,0,0,0,,,0,0,0,0,,,0,0,0,0,,,0,0,0,0,,,0,0,0,0,,,0,0,0,0,,,0,0,0,0,,,0,0,0,0,,,0,0,0,0,AAPL
2024-10-22 12:21:00.002929121+00:00,10,40,38,A,B,0,234.89,200,194,203310,71843,,234.89,0,200,0,0,,,0,0,0,0,,,0,0,0,0,,,0,0,0,0,,,0,0,0,0,,,0,0,0,0,,,0,0,0,0,,,0,0,0,0,,,0,0,0,0,,,0,0,0,0,AAPL
2024-10-22 12:21:00.049031752+00:00,10,40,38,A,B,0,234.89,200,194,203450,71862,234.06,234.89,200,200,0,0,,,0,0,0,0,,,0,0,0,0,,,0,0,0,0,,,0,0,0,0,,,0,0,0,0,,,0,0,0,0,,,0,0,0,0,,,0,0,0,0,,,0,0,0,0,AAPL
2024-10-22 12:21:02.663646625+00:00,10,41,38,A,B,0,234.83,200,194,412981,115095,234.12,234.83,200,200,0,0,,,0,0,0,0,,,0,0,0,0,,,0,0,0,0,,,0,0,0,0,,,0,0,0,0,,,0,0,0,0,,,0,0,0,0,,,0,0,0,0,,,0,0,0,0,AAPL
2024-10-22 12:21:02.701110878+00:00,10,39,38,C,A,0,236.6,2000,130,203783,44986,232.8,,2000,0,1,0,,,0,0,0,0,,,0,0,0,0,,,0,0,0,0,,,0,0,0,0,,,0,0,0,0,,,0,0,0,0,,,0,0,0,0,,,0,0,0,0,,,0,0,0,0,AAPL
2024-10-22 12:21:03.015744332+00:00,10,39,38,A,A,0,236.8,2000,130,203909,44998,232.8,236.8,2000,2000,1,1,,,0,0,0,0,,,0,0,0,0,,,0,0,0,0,,,0,0,0,0,,,0,0,0,0,,,0,0,0,0,,,0,0,0,0,,,0,0,0,0,,,0,0,0,0,AAPL
2024-10-22 12:21:04.685270304+00:00,10,41,38,A,B,0,234.83,200,194,60592,115145,,234.83,0,200,0,0,,,0,0,0,0,,,0,0,0,0,,,0,0,0,0,,,0,0,0,0,,,0,0,0,0,,,0,0,0,0,,,0,0,0,0,,,0,0,0,0,,,0,0,0,0,AAPL
2024-10-22 12:21:06.455099557+00:00,10,41,38,A,B,0,234.83,200,194,60606,115209,234.12,234.83,200,200,0,0,,,0,0,0,0,,,0,0,0,0,,,0,0,0,0,,,0,0,0,0,,,0,0,0,0,,,0,0,0,0,,,0,0,0,0,,,0,0,0,0,,,0,0,0,0,AAPL
2024-10-22 12:21:14.897424578+00:00,10,39,38,C,B,0,232.8,2000,130,203762,45097,,236.8,0,2000,0,1,,,0,0,0,0,,,0,0,0,0,,,0,0,0,0,,,0,0,0,0,,,0,0,0,0,,,0,0,0,0,,,0,0,0,0,,,0,0,0,0,,,0,0,0,0,AAPL
2024-10-22 12:21:14.907396214+00:00,10,39,38,A,A,0,236.6,2000,130,203715,45098,,236.6,0,2000,0,1,,236.8,0,2000,0,1,,,0,0,0,0,,,0,0,0,0,,,0,0,0,0,,,0,0,0,0,,,0,0,0,0,,,0,0,0,0,,,0,0,0,0,,,0,0,0,0,AAPL
2024-10-22 12:21:14.907596610+00:00,10,39,38,C,A,1,236.8,2000,130,203705,45099,,236.6,0,2000,0,1,,,0,0,0,0,,,0,0,0,0,,,0,0,0,0,,,0,0,0,0,,,0,0,0,0,,,0,0,0,0,,,0,0,0,0,,,0,0,0,0,,,0,0,0,0,AAPL
2024-10-22 12:21:14.935058862+00:00,10,39,38,A,B,0,232.8,2000,130,203763,45100,232.8,236.6,2000,2000,1,1,,,0,0,0,0,,,0,0,0,0,,,0,0,0,0,,,0,0,0,0,,,0,0,0,0,,,0,0,0,0,,,0,0,0,0,,,0,0,0,0,,,0,0,0,0,AAPL
2024-10-22 12:21:15.240840325+00:00,10,39,38,C,A,0,236.6,2000,130,204135,45102,232.8,,2000,0,1,0,,,0,0,0,0,,,0,0,0,0,,,0,0,0,0,,,0,0,0,0,,,0,0,0,0,,,0,0,0,0,,,0,0,0,0,,,0,0,0,0,,,0,0,0,0,AAPL
2024-10-22 12:21:15.559288686+00:00,10,39,38,A,A,0,236.8,2000,130,203919,45105,232.8,236.8,2000,2000,1,1,,,0,0,0,0,,,0,0,0,0,,,0,0,0,0,,,0,0,0,0,,,0,0,0,0,,,0,0,0,0,,,0,0,0,0,,,0,0,0,0,,,0,0,0,0,AAPL
2024-10-22 12:21:28.117301567+00:00,10,40,38,A,A,0,,0,194,204877,72238,234.06,,200,0,0,0,,,0,0,0,0,,,0,0,0,0,,,0,0,0,0,,,0,0,0,0,,,0,0,0,0,,,0,0,0,0,,,0,0,0,0,,,0,0,0,0,,,0,0,0,0,AAPL
2024-10-22 12:21:28.117330266+00:00,10,40,38,A,A,0,234.83,200,194,204630,72239,234.06,234.83,200,200,0,0,,,0,0,0,0,,,0,0,0,0,,,0,0,0,0,,,0,0,0,0,,,0,0,0,0,,,0,0,0,0,,,0,0,0,0,,,0,0,0,0,,,0,0,0,0,AAPL
2024-10-22 12:21:28.117986383+00:00,10,39,38,C,A,0,236.8,2000,130,203765,45203,232.8,,2000,0,1,0,,,0,0,0,0,,,0,0,0,0,,,0,0,0,0,,,0,0,0,0,,,0,0,0,0,,,0,0,0,0,,,0,0,0,0,,,0,0,0,0,,,0,0,0,0,AAPL
2024-10-22 12:21:28.129966222+00:00,10,39,38,A,B,0,233.0,2000,130,203549,45204,233.0,,2000,0,1,0,232.8,,2000,0,1,0,,,0,0,0,0,,,0,0,0,0,,,0,0,0,0,,,0,0,0,0,,,0,0,0,0,,,0,0,0,0,,,0,0,0,0,,,0,0,0,0,AAPL
2024-10-22 12:21:28.130165113+00:00,10,39,38,C,B,1,232.8,2000,130,203475,45205,233.0,,2000,0,1,0,,,0,0,0,0,,,0,0,0,0,,,0,0,0,0,,,0,0,0,0,,,0,0,0,0,,,0,0,0,0,,,0,0,0,0,,,0,0,0,0,,,0,0,0,0,AAPL
2024-10-22 12:21:31.614407347+00:00,10,39,38,C,B,0,233.0,2000,130,203917,45231,,,0,0,0,0,,,0,0,0,0,,,0,0,0,0,,,0,0,0,0,,,0,0,0,0,,,0,0,0,0,,,0,0,0,0,,,0,0,0,0,,,0,0,0,0,,,0,0,0,0,AAPL
2024-10-22 12:21:31.652187792+00:00,10,39,38,A,B,0,232.4,2000,130,203753,45232,232.4,,2000,0,1,0,,,0,0,0,0,,,0,0,0,0,,,0,0,0,0,,,0,0,0,0,,,0,0,0,0,,,0,0,0,0,,,0,0,0,0,,,0,0,0,0,,,0,0,0,0,AAPL
2024-10-22 12:21:31.962080460+00:00,10,39,38,A,A,0,236.8,2000,130,203613,45237,232.4,236.8,2000,2000,1,1,,,0,0,0,0,,,0,0,0,0,,,0,0,0,0,,,0,0,0,0,,,0,0,0,0,,,0,0,0,0,,,0,0,0,0,,,0,0,0,0,,,0,0,0,0,AAPL
2024-10-22 12:21:33.136260756+00:00,10,39,38,A,B,0,232.8,2000,130,203987,45248,232.8,236.8,2000,2000,1,1,232.4,,2000,0,1,0,,,0,0,0,0,,,0,0,0,0,,,0,0,0,0,,,0,0,0,0,,,0,0,0,0,,,0,0,0,0,,,0,0,0,0,,,0,0,0,0,AAPL
2024-10-22 12:21:33.136500994+00:00,10,39,38,C,B,1,232.4,2000,130,203545,45249,232.8,236.8,2000,2000,1,1,,,0,0,0,0,,,0,0,0,0,,,0,0,0,0,,,0,0,0,0,,,0,0,0,0,,,0,0,0,0,,,0,0,0,0,,,0,0,0,0,,,0,0,0,0,AAPL
2024-10-22 12:21:33.772046955+00:00,10,39,38,C,A,0,236.8,2000,130,204008,45254,232.8,,2000,0,1,0,,,0,0,0,0,,,0,0,0,0,,,0,0,0,0,,,0,0,0,0,,,0,0,0,0,,,0,0,0,0,,,0,0,0,0,,,0,0,0,0,,,0,0,0,0,AAPL
2024-10-22 12:21:33.808149045+00:00,10,39,38,A,A,0,236.8,2000,130,203661,45255,232.8,236.8,2000,2000,1,1,,,0,0,0,0,,,0,0,0,0,,,0,0,0,0,,,0,0,0,0,,,0,0,0,0,,,0,0,0,0,,,0,0,0,0,,,0,0,0,0,,,0,0,0,0,AAPL
2024-10-22 12:21:33.834122382+00:00,10,39,38,A,A,0,236.6,2000,130,203724,45256,232.8,236.6,2000,2000,1,1,,236.8,0,2000,0,1,,,0,0,0,0,,,0,0,0,0,,,0,0,0,0,,,0,0,0,0,,,0,0,0,0,,,0,0,0,0,,,0,0,0,0,,,0,0,0,0,AAPL
2024-10-22 12:21:33.834314556+00:00,10,39,38,C,A,1,236.8,2000,130,203683,45257,232.8,236.6,2000,2000,1,1,,,0,0,0,0,,,0,0,0,0,,,0,0,0,0,,,0,0,0,0,,,0,0,0,0,,,0,0,0,0,,,0,0,0,0,,,0,0,0,0,,,0,0,0,0,AAPL
2024-10-22 12:21:35.553824204+00:00,10,39,38,C,A,0,236.6,2000,130,203983,45268,232.8,,2000,0,1,0,,,0,0,0,0,,,0,0,0,0,,,0,0,0,0,,,0,0,0,0,,,0,0,0,0,,,0,0,0,0,,,0,0,0,0,,,0,0,0,0,,,0,0,0,0,AAPL
2024-10-22 12:21:35.565489732+00:00,10,39,38,A,A,0,236.6,2000,130,203617,45269,232.8,236.6,2000,2000,1,1,,,0,0,0,0,,,0,0,0,0,,,0,0,0,0,,,0,0,0,0,,,0,0,0,0,,,0,0,0,0,,,0,0,0,0,,,0,0,0,0,,,0,0,0,0,AAPL
2024-10-22 12:21:37.066958447+00:00,10,39,38,A,A,0,234.53,100,130,204300,45275,232.8,234.53,2000,100,1,1,,236.6,0,2000,0,1,,,0,0,0,0,,,0,0,0,0,,,0,0,0,0,,,0,0,0,0,,,0,0,0,0,,,0,0,0,0,,,0,0,0,0,,,0,0,0,0,AAPL
2024-10-22 12:21:40.734705509+00:00,10,39,38,C,B,0,232.8,2000,130,203782,45281,,234.53,0,100,0,1,,236.6,0,2000,0,1,,,0,0,0,0,,,0,0,0,0,,,0,0,0,0,,,0,0,0,0,,,0,0,0,0,,,0,0,0,0,,,0,0,0,0,,,0,0,0,0,AAPL
2024-10-22 12:21:40.752567643+00:00,10,39,38,A,B,0,232.4,2000,130,203872,45282,232.4,234.53,2000,100,1,1,,236.6,0,2000,0,1,,,0,0,0,0,,,0,0,0,0,,,0,0,0,0,,,0,0,0,0,,,0,0,0,0,,,0,0,0,0,,,0,0,0,0,,,0,0,0,0,AAPL
2024-10-22 12:21:42.036751981+00:00,10,39,38,A,B,0,232.8,2000,130,204162,45288,232.8,234.53,2000,100,1,1,232.4,236.6,2000,2000,1,1,,,0,0,0,0,,,0,0,0,0,,,0,0,0,0,,,0,0,0,0,,,0,0,0,0,,,0,0,0,0,,,0,0,0,0,,,0,0,0,0,AAPL
2024-10-22 12:21:42.037260861+00:00,10,39,38,C,B,1,232.4,2000,130,203748,45289,232.8,234.53,2000,100,1,1,,236.6,0,2000,0,1,,,0,0,0,0,,,0,0,0,0,,,0,0,0,0,,,0,0,0,0,,,0,0,0,0,,,0,0,0,0,,,0,0,0,0,,,0,0,0,0,AAPL
2024-10-22 12:21:42.062804495+00:00,10,39,38,C,B,0,232.8,2000,130,203713,45290,,234.53,0,100,0,1,,236.6,0,2000,0,1,,,0,0,0,0,,,0,0,0,0,,,0,0,0,0,,,0,0,0,0,,,0,0,0,0,,,0,0,0,0,,,0,0,0,0,,,0,0,0,0,AAPL
2024-10-22 12:21:42.074364062+00:00,10,39,38,A,B,0,232.8,2000,130,203703,45291,232.8,234.53,2000,100,1,1,,236.6,0,2000,0,1,,,0,0,0,0,,,0,0,0,0,,,0,0,0,0,,,0,0,0,0,,,0,0,0,0,,,0,0,0,0,,,0,0,0,0,,,0,0,0,0,AAPL
2024-10-22 12:21:42.095382204+00:00,10,39,38,C,B,0,232.8,2000,130,203700,45292,,234.53,0,100,0,1,,236.6,0,2000,0,1,,,0,0,0,0,,,0,0,0,0,,,0,0,0,0,,,0,0,0,0,,,0,0,0,0,,,0,0,0,0,,,0,0,0,0,,,0,0,0,0,AAPL
2024-10-22 12:21:42.106963289+00:00,10,39,38,A,B,0,232.6,2000,130,203793,45293,232.6,234.53,2000,100,1,1,,236.6,0,2000,0,1,,,0,0,0,0,,,0,0,0,0,,,0,0,0,0,,,0,0,0,0,,,0,0,0,0,,,0,0,0,0,,,0,0,0,0,,,0,0,0,0,AAPL
2024-10-22 12:21:43.148760693+00:00,10,39,38,A,B,0,232.8,2000,130,204142,45297,232.8,234.53,2000,100,1,1,232.6,236.6,2000,2000,1,1,,,0,0,0,0,,,0,0,0,0,,,0,0,0,0,,,0,0,0,0,,,0,0,0,0,,,0,0,0,0,,,0,0,0,0,,,0,0,0,0,AAPL
2024-10-22 12:21:43.149488759+00:00,10,39,38,C,B,1,232.6,2000,130,203798,45298,232.8,234.53,2000,100,1,1,,236.6,0,2000,0,1,,,0,0,0,0,,,0,0,0,0,,,0,0,0,0,,,0,0,0,0,,,0,0,0,0,,,0,0,0,0,,,0,0,0,0,,,0,0,0,0,AAPL
2024-10-22 12:21:49.987190094+00:00,10,39,38,A,B,0,233.0,2000,130,204462,45322,233.0,234.53,2000,100,1,1,232.8,236.6,2000,2000,1,1,,,0,0,0,0,,,0,0,0,0,,,0,0,0,0,,,0,0,0,0,,,0,0,0,0,,,0,0,0,0,,,0,0,0,0,,,0,0,0,0,AAPL
2024-10-22 12:21:49.987932831+00:00,10,39,38,C,B,1,232.8,2000,130,203560,45323,233.0,234.53,2000,100,1,1,,236.6,0,2000,0,1,,,0,0,0,0,,,0,0,0,0,,,0,0,0,0,,,0,0,0,0,,,0,0,0,0,,,0,0,0,0,,,0,0,0,0,,,0,0,0,0,AAPL
2024-10-22 12:21:50.037729733+00:00,10,39,38,C,B,0,233.0,2000,130,203673,45325,,234.53,0,100,0,1,,236.6,0,2000,0,1,,,0,0,0,0,,,0,0,0,0,,,0,0,0,0,,,0,0,0,0,,,0,0,0,0,,,0,0,0,0,,,0,0,0,0,,,0,0,0,0,AAPL
2024-10-22 12:21:50.048826985+00:00,10,39,38,A,B,0,233.0,2000,130,203667,45326,233.0,234.53,2000,100,1,1,,236.6,0,2000,0,1,,,0,0,0,0,,,0,0,0,0,,,0,0,0,0,,,0,0,0,0,,,0,0,0,0,,,0,0,0,0,,,0,0,0,0,,,0,0,0,0,AAPL
2024-10-22 12:21:50.275420472+00:00,10,39,38,T,B,0,234.53,50,130,204088,45327,233.0,234.53,2000,100,1,1,,236.6,0,2000,0,1,,,0,0,0,0,,,0,0,0,0,,,0,0,0,0,,,0,0,0,0,,,0,0,0,0,,,0,0,0,0,,,0,0,0,0,,,0,0,0,0,AAPL
2024-10-22 12:21:50.275420472+00:00,10,39,38,C,A,0,234.53,50,130,204088,45327,233.0,234.53,2000,50,1,1,,236.6,0,2000,0,1,,,0,0,0,0,,,0,0,0,0,,,0,0,0,0,,,0,0,0,0,,,0,0,0,0,,,0,0,0,0,,,0,0,0,0,,,0,0,0,0,AAPL
2024-10-22 12:21:50.968572927+00:00,10,39,38,C,A,1,236.6,2000,130,203626,45338,233.0,234.53,2000,50,1,1,,,0,0,0,0,,,0,0,0,0,,,0,0,0,0,,,0,0,0,0,,,0,0,0,0,,,0,0,0,0,,,0,0,0,0,,,0,0,0,0,,,0,0,0,0,AAPL
2024-10-22 12:21:51.010889576+00:00,10,39,38,A,A,1,236.6,2000,130,203814,45341,233.0,234.53,2000,50,1,1,,236.6,0,2000,0,1,,,0,0,0,0,,,0,0,0,0,,,0,0,0,0,,,0,0,0,0,,,0,0,0,0,,,0,0,0,0,,,0,0,0,0,,,0,0,0,0,AAPL
2024-10-22 12:21:51.012297168+00:00,10,39,38,C,A,1,236.6,2000,130,203549,45342,233.0,234.53,2000,50,1,1,,,0,0,0,0,,,0,0,0,0,,,0,0,0,0,,,0,0,0,0,,,0,0,0,0,,,0,0,0,0,,,0,0,0,0,,,0,0,0,0,,,0,0,0,0,AAPL
2024-10-22 12:21:51.324712220+00:00,10,39,38,A,A,1,236.8,2000,130,203918,45343,233.0,234.53,2000,50,1,1,,236.8,0,2000,0,1,,,0,0,0,0,,,0,0,0,0,,,0,0,0,0,,,0,0,0,0,,,0,0,0,0,,,0,0,0,0,,,0,0,0,0,,,0,0,0,0,AAPL
2024-10-22 12:21:51.467545825+00:00,10,39,38,C,A,0,234.53,50,130,203658,45344,233.0,236.8,2000,2000,1,1,,,0,0,0,0,,,0,0,0,0,,,0,0,0,0,,,0,0,0,0,,,0,0,0,0,,,0,0,0,0,,,0,0,0,0,,,0,0,0,0,,,0,0,0,0,AAPL
2024-10-22 12:21:51.557785669+00:00,10,39,38,A,A,0,236.6,2000,130,203674,45345,233.0,236.6,2000,2000,1,1,,236.8,0,2000,0,1,,,0,0,0,0,,,0,0,0,0,,,0,0,0,0,,,0,0,0,0,,,0,0,0,0,,,0,0,0,0,,,0,0,0,0,,,0,0,0,0,AAPL
2024-10-22 12:21:51.557968105+00:00,10,39,38,C,A,1,236.8,2000,130,203556,45346,233.0,236.6,2000,2000,1,1,,,0,0,0,0,,,0,0,0,0,,,0,0,0,0,,,0,0,0,0,,,0,0,0,0,,,0,0,0,0,,,0,0,0,0,,,0,0,0,0,,,0,0,0,0,AAPL
2024-10-22 12:22:00.051907515+00:00,10,40,38,A,B,0,234.83,200,194,203443,72588,,234.83,0,200,0,0,,,0,0,0,0,,,0,0,0,0,,,0,0,0,0,,,0,0,0,0,,,0,0,0,0,,,0,0,0,0,,,0,0,0,0,,,0,0,0,0,,,0,0,0,0,AAPL
2024-10-22 12:22:00.064045389+00:00,10,41,38,A,B,0,234.83,200,194,55667,116535,,234.83,0,200,0,0,,,0,0,0,0,,,0,0,0,0,,,0,0,0,0,,,0,0,0,0,,,0,0,0,0,,,0,0,0,0,,,0,0,0,0,,,0,0,0,0,,,0,0,0,0,AAPL
2024-10-22 12:22:00.093917112+00:00,10,41,38,A,B,0,234.83,200,194,55116,116568,234.17,234.83,200,200,0,0,,,0,0,0,0,,,0,0,0,0,,,0,0,0,0,,,0,0,0,0,,,0,0,0,0,,,0,0,0,0,,,0,0,0,0,,,0,0,0,0,,,0,0,0,0,AAPL
2024-10-22 12:22:00.366355762+00:00,10,40,38,A,B,0,234.83,200,194,203539,72616,234.11,234.83,200,200,0,0,,,0,0,0,0,,,0,0,0,0,,,0,0,0,0,,,0,0,0,0,,,0,0,0,0,,,0,0,0,0,,,0,0,0,0,,,0,0,0,0,,,0,0,0,0,AAPL
2024-10-22 12:22:00.571752484+00:00,10,40,38,A,B,0,234.83,200,194,203415,72623,,234.83,0,200,0,0,,,0,0,0,0,,,0,0,0,0,,,0,0,0,0,,,0,0,0,0,,,0,0,0,0,,,0,0,0,0,,,0,0,0,0,,,0,0,0,0,,,0,0,0,0,AAPL
2024-10-22 12:22:01.376362795+00:00,10,40,38,A,B,0,234.83,200,194,203567,72627,234.11,234.83,200,200,0,0,,,0,0,0,0,,,0,0,0,0,,,0,0,0,0,,,0,0,0,0,,,0,0,0,0,,,0,0,0,0,,,0,0,0,0,,,0,0,0,0,,,0,0,0,0,AAPL
2024-10-22 12:22:09.960587709+00:00,10,39,38,C,A,0,236.6,2000,130,203670,45427,233.0,,2000,0,1,0,,,0,0,0,0,,,0,0,0,0,,,0,0,0,0,,,0,0,0,0,,,0,0,0,0,,,0,0,0,0,,,0,0,0,0,,,0,0,0,0,,,0,0,0,0,AAPL
2024-10-22 12:22:10.306870108+00:00,10,39,38,A,A,0,236.8,2000,130,203292,45432,233.0,236.8,2000,2000,1,1,,,0,0,0,0,,,0,0,0,0,,,0,0,0,0,,,0,0,0,0,,,0,0,0,0,,,0,0,0,0,,,0,0,0,0,,,0,0,0,0,,,0,0,0,0,AAPL
2024-10-22 12:22:11.657811623+00:00,10,39,38,C,A,0,236.8,2000,130,203661,45446,233.0,,2000,0,1,0,,,0,0,0,0,,,0,0,0,0,,,0,0,0,0,,,0,0,0,0,,,0,0,0,0,,,0,0,0,0,,,0,0,0,0,,,0,0,0,0,,,0,0,0,0,AAPL
2024-10-22 12:22:11.694046803+00:00,10,39,38,A,A,0,236.8,2000,130,203346,45447,233.0,236.8,2000,2000,1,1,,,0,0,0,0,,,0,0,0,0,,,0,0,0,0,,,0,0,0,0,,,0,0,0,0,,,0,0,0,0,,,0,0,0,0,,,0,0,0,0,,,0,0,0,0,AAPL
2024-10-22 12:22:12.011702845+00:00,10,40,38,A,A,0,,0,194,203693,72730,234.11,,200,0,0,0,,,0,0,0,0,,,0,0,0,0,,,0,0,0,0,,,0,0,0,0,,,0,0,0,0,,,0,0,0,0,,,0,0,0,0,,,0,0,0,0,,,0,0,0,0,AAPL
2024-10-22 12:22:12.011726074+00:00,10,40,38,A,A,0,235.0,200,194,203610,72731,234.11,235.0,200,200,0,0,,,0,0,0,0,,,0,0,0,0,,,0,0,0,0,,,0,0,0,0,,,0,0,0,0,,,0,0,0,0,,,0,0,0,0,,,0,0,0,0,,,0,0,0,0,AAPL
2024-10-22 12:22:12.011883373+00:00,10,41,38,A,A,0,,0,194,61097,116968,234.17,,200,0,0,0,,,0,0,0,0,,,0,0,0,0,,,0,0,0,0,,,0,0,0,0,,,0,0,0,0,,,0,0,0,0,,,0,0,0,0,,,0,0,0,0,,,0,0,0,0,AAPL
2024-10-22 12:22:12.011939353+00:00,10,41,38,A,A,0,234.94,200,194,55777,116969,234.17,234.94,200,200,0,0,,,0,0,0,0,,,0,0,0,0,,,0,0,0,0,,,0,0,0,0,,,0,0,0,0,,,0,0,0,0,,,0,0,0,0,,,0,0,0,0,,,0,0,0,0,AAPL
2024-10-22 12:22:12.011979886+00:00,10,40,38,A,B,0,235.0,200,194,203599,72732,,235.0,0,200,0,0,,,0,0,0,0,,,0,0,0,0,,,0,0,0,0,,,0,0,0,0,,,0,0,0,0,,,0,0,0,0,,,0,0,0,0,,,0,0,0,0,,,0,0,0,0,AAPL
2024-10-22 12:22:12.011998671+00:00,10,40,38,A,B,0,235.0,200,194,203538,72733,234.16,235.0,200,200,0,0,,,0,0,0,0,,,0,0,0,0,,,0,0,0,0,,,0,0,0,0,,,0,0,0,0,,,0,0,0,0,,,0,0,0,0,,,0,0,0,0,,,0,0,0,0,AAPL
2024-10-22 12:22:12.014765728+00:00,10,39,38,C,A,0,236.8,2000,130,203743,45449,233.0,,2000,0,1,0,,,0,0,0,0,,,0,0,0,0,,,0,0,0,0,,,0,0,0,0,,,0,0,0,0,,,0,0,0,0,,,0,0,0,0,,,0,0,0,0,,,0,0,0,0,AAPL
2024-10-22 12:22:12.027939202+00:00,10,39,38,A,A,0,236.6,2000,130,203400,45450,233.0,236.6,2000,2000,1,1,,,0,0,0,0,,,0,0,0,0,,,0,0,0,0,,,0,0,0,0,,,0,0,0,0,,,0,0,0,0,,,0,0,0,0,,,0,0,0,0,,,0,0,0,0,AAPL
2024-10-22 12:22:12.083514657+00:00,10,39,38,C,A,0,236.6,2000,130,203250,45451,233.0,,2000,0,1,0,,,0,0,0,0,,,0,0,0,0,,,0,0,0,0,,,0,0,0,0,,,0,0,0,0,,,0,0,0,0,,,0,0,0,0,,,0,0,0,0,,,0,0,0,0,AAPL
2024-10-22 12:22:12.094299256+00:00,10,39,38,A,A,0,236.8,2000,130,203241,45452,233.0,236.8,2000,2000,1,1,,,0,0,0,0,,,0,0,0,0,,,0,0,0,0,,,0,0,0,0,,,0,0,0,0,,,0,0,0,0,,,0,0,0,0,,,0,0,0,0,,,0,0,0,0,AAPL
2024-10-22 12:22:25.491640408+00:00,10,39,38,C,B,0,233.0,2000,130,203142,45599,,236.8,0,2000,0,1,,,0,0,0,0,,,0,0,0,0,,,0,0,0,0,,,0,0,0,0,,,0,0,0,0,,,0,0,0,0,,,0,0,0,0,,,0,0,0,0,,,0,0,0,0,AAPL
2024-10-22 12:22:25.502765577+00:00,10,39,38,A,B,0,232.8,2000,130,202665,45600,232.8,236.8,2000,2000,1,1,,,0,0,0,0,,,0,0,0,0,,,0,0,0,0,,,0,0,0,0,,,0,0,0,0,,,0,0,0,0,,,0,0,0,0,,,0,0,0,0,,,0,0,0,0,AAPL
2024-10-22 12:22:25.521429144+00:00,10,39,38,C,B,0,232.8,2000,130,202899,45601,,236.8,0,2000,0,1,,,0,0,0,0,,,0,0,0,0,,,0,0,0,0,,,0,0,0,0,,,0,0,0,0,,,0,0,0,0,,,0,0,0,0,,,0,0,0,0,,,0,0,0,0,AAPL
2024-10-22 12:22:25.532140982+00:00,10,39,38,A,B,0,232.6,2000,130,202590,45602,232.6,236.8,2000,2000,1,1,,,0,0,0,0,,,0,0,0,0,,,0,0,0,0,,,0,0,0,0,,,0,0,0,0,,,0,0,0,0,,,0,0,0,0,,,0,0,0,0,,,0,0,0,0,AAPL
2024-10-22 12:22:28.625226473+00:00,10,41,38,A,B,0,234.94,200,194,55876,117502,,234.94,0,200,0,0,,,0,0,0,0,,,0,0,0,0,,,0,0,0,0,,,0,0,0,0,,,0,0,0,0,,,0,0,0,0,,,0,0,0,0,,,0,0,0,0,,,0,0,0,0,AAPL
2024-10-22 12:22:28.625290490+00:00,10,41,38,A,B,0,234.94,200,194,54415,117503,234.3,234.94,200,200,0,0,,,0,0,0,0,,,0,0,0,0,,,0,0,0,0,,,0,0,0,0,,,0,0,0,0,,,0,0,0,0,,,0,0,0,0,,,0,0,0,0,,,0,0,0,0,AAPL
2024-10-22 12:22:31.030548392+00:00,10,39,38,A,B,0,232.8,2000,130,203046,45654,232.8,236.8,2000,2000,1,1,232.6,,2000,0,1,0,,,0,0,0,0,,,0,0,0,0,,,0,0,0,0,,,0,0,0,0,,,0,0,0,0,,,0,0,0,0,,,0,0,0,0,,,0,0,0,0,AAPL
2024-10-22 12:22:31.030731582+00:00,10,39,38,C,B,1,232.6,2000,130,202666,45655,232.8,236.8,2000,2000,1,1,,,0,0,0,0,,,0,0,0,0,,,0,0,0,0,,,0,0,0,0,,,0,0,0,0,,,0,0,0,0,,,0,0,0,0,,,0,0,0,0,,,0,0,0,0,AAPL
2024-10-22 12:22:31.540558459+00:00,10,40,38,A,A,0,,0,194,203384,72873,234.16,,200,0,0,0,,,0,0,0,0,,,0,0,0,0,,,0,0,0,0,,,0,0,0,0,,,0,0,0,0,,,0,0,0,0,,,0,0,0,0,,,0,0,0,0,,,0,0,0,0,AAPL
2024-10-22 12:22:31.540582158+00:00,10,40,38,A,A,0,234.99,200,194,203331,72874,234.16,234.99,200,200,0,0,,,0,0,0,0,,,0,0,0,0,,,0,0,0,0,,,0,0,0,0,,,0,0,0,0,,,0,0,0,0,,,0,0,0,0,,,0,0,0,0,,,0,0,0,0,AAPL
2024-10-22 12:22:31.540644275+00:00,10,40,38,A,A,0,,0,194,203285,72875,234.16,,200,0,0,0,,,0,0,0,0,,,0,0,0,0,,,0,0,0,0,,,0,0,0,0,,,0,0,0,0,,,0,0,0,0,,,0,0,0,0,,,0,0,0,0,,,0,0,0,0,AAPL
2024-10-22 12:22:31.541360513+00:00,10,39,38,C,A,0,236.8,2000,130,202946,45667,232.8,,2000,0,1,0,,,0,0,0,0,,,0,0,0,0,,,0,0,0,0,,,0,0,0,0,,,0,0,0,0,,,0,0,0,0,,,0,0,0,0,,,0,0,0,0,,,0,0,0,0,AAPL
2024-10-22 12:22:31.576848566+00:00,10,39,38,A,A,0,236.8,2000,130,203014,45668,232.8,236.8,2000,2000,1,1,,,0,0,0,0,,,0,0,0,0,,,0,0,0,0,,,0,0,0,0,,,0,0,0,0,,,0,0,0,0,,,0,0,0,0,,,0,0,0,0,,,0,0,0,0,AAPL
2024-10-22 12:22:31.579864323+00:00,10,39,38,C,A,0,236.8,2000,130,202710,45669,232.8,,2000,0,1,0,,,0,0,0,0,,,0,0,0,0,,,0,0,0,0,,,0,0,0,0,,,0,0,0,0,,,0,0,0,0,,,0,0,0,0,,,0,0,0,0,,,0,0,0,0,AAPL
2024-10-22 12:22:31.894293807+00:00,10,39,38,A,A,0,236.6,2000,130,202693,45676,232.8,236.6,2000,2000,1,1,,,0,0,0,0,,,0,0,0,0,,,0,0,0,0,,,0,0,0,0,,,0,0,0,0,,,0,0,0,0,,,0,0,0,0,,,0,0,0,0,,,0,0,0,0,AAPL
2024-10-22 12:22:31.991347553+00:00,10,40,38,A,A,0,234.99,200,194,203307,72883,234.16,234.99,200,200,0,0,,,0,0,0,0,,,0,0,0,0,,,0,0,0,0,,,0,0,0,0,,,0,0,0,0,,,0,0,0,0,,,0,0,0,0,,,0,0,0,0,,,0,0,0,0,AAPL
2024-10-22 12:22:32.051697370+00:00,10,40,38,A,A,0,,0,194,203403,72885,234.16,,200,0,0,0,,,0,0,0,0,,,0,0,0,0,,,0,0,0,0,,,0,0,0,0,,,0,0,0,0,,,0,0,0,0,,,0,0,0,0,,,0,0,0,0,,,0,0,0,0,AAPL
2024-10-22 12:22:39.337099896+00:00,10,40,38,A,A,0,234.99,200,194,203177,72981,234.16,234.99,200,200,0,0,,,0,0,0,0,,,0,0,0,0,,,0,0,0,0,,,0,0,0,0,,,0,0,0,0,,,0,0,0,0,,,0,0,0,0,,,0,0,0,0,,,0,0,0,0,AAPL
2024-10-22 12:22:39.437776347+00:00,10,40,38,A,A,0,,0,194,203201,72984,234.16,,200,0,0,0,,,0,0,0,0,,,0,0,0,0,,,0,0,0,0,,,0,0,0,0,,,0,0,0,0,,,0,0,0,0,,,0,0,0,0,,,0,0,0,0,,,0,0,0,0,AAPL
2024-10-22 12:22:39.877712411+00:00,10,40,38,A,A,0,234.99,200,194,203241,72996,234.16,234.99,200,200,0,0,,,0,0,0,0,,,0,0,0,0,,,0,0,0,0,,,0,0,0,0,,,0,0,0,0,,,0,0,0,0,,,0,0,0,0,,,0,0,0,0,,,0,0,0,0,AAPL
2024-10-22 12:22:39.878983853+00:00,10,40,38,A,A,0,,0,194,203187,72997,234.16,,200,0,0,0,,,0,0,0,0,,,0,0,0,0,,,0,0,0,0,,,0,0,0,0,,,0,0,0,0,,,0,0,0,0,,,0,0,0,0,,,0,0,0,0,,,0,0,0,0,AAPL
2024-10-22 12:22:41.059995932+00:00,10,39,38,A,B,0,233.0,2000,130,203314,45772,233.0,236.6,2000,2000,1,1,232.8,,2000,0,1,0,,,0,0,0,0,,,0,0,0,0,,,0,0,0,0,,,0,0,0,0,,,0,0,0,0,,,0,0,0,0,,,0,0,0,0,,,0,0,0,0,AAPL
2024-10-22 12:22:41.060731298+00:00,10,39,38,C,B,1,232.8,2000,130,203051,45773,233.0,236.6,2000,2000,1,1,,,0,0,0,0,,,0,0,0,0,,,0,0,0,0,,,0,0,0,0,,,0,0,0,0,,,0,0,0,0,,,0,0,0,0,,,0,0,0,0,,,0,0,0,0,AAPL
2024-10-22 12:22:42.761515408+00:00,10,39,38,C,A,0,236.6,2000,130,203450,45797,233.0,,2000,0,1,0,,,0,0,0,0,,,0,0,0,0,,,0,0,0,0,,,0,0,0,0,,,0,0,0,0,,,0,0,0,0,,,0,0,0,0,,,0,0,0,0,,,0,0,0,0,AAPL
2024-10-22 12:22:42.797749554+00:00,10,39,38,A,A,0,236.6,2000,130,203208,45798,233.0,236.6,2000,2000,1,1,,,0,0,0,0,,,0,0,0,0,,,0,0,0,0,,,0,0,0,0,,,0,0,0,0,,,0,0,0,0,,,0,0,0,0,,,0,0,0,0,,,0,0,0,0,AAPL
2024-10-22 12:22:47.364804182+00:00,10,40,38,A,A,0,234.99,200,194,203145,73099,234.16,234.99,200,200,0,0,,,0,0,0,0,,,0,0,0,0,,,0,0,0,0,,,0,0,0,0,,,0,0,0,0,,,0,0,0,0,,,0,0,0,0,,,0,0,0,0,,,0,0,0,0,AAPL
2024-10-22 12:22:47.636197646+00:00,10,40,38,A,A,0,,0,194,203224,73100,234.16,,200,0,0,0,,,0,0,0,0,,,0,0,0,0,,,0,0,0,0,,,0,0,0,0,,,0,0,0,0,,,0,0,0,0,,,0,0,0,0,,,0,0,0,0,,,0,0,0,0,AAPL
2024-10-22 12:22:48.041726283+00:00,10,40,38,A,A,0,234.99,200,194,203220,73103,234.16,234.99,200,200,0,0,,,0,0,0,0,,,0,0,0,0,,,0,0,0,0,,,0,0,0,0,,,0,0,0,0,,,0,0,0,0,,,0,0,0,0,,,0,0,0,0,,,0,0,0,0,AAPL
2024-10-22 12:22:49.123716470+00:00,10,39,38,C,A,0,236.6,2000,130,203387,45845,233.0,,2000,0,1,0,,,0,0,0,0,,,0,0,0,0,,,0,0,0,0,,,0,0,0,0,,,0,0,0,0,,,0,0,0,0,,,0,0,0,0,,,0,0,0,0,,,0,0,0,0,AAPL
2024-10-22 12:22:49.160397032+00:00,10,39,38,A,A,0,236.6,2000,130,203208,45846,233.0,236.6,2000,2000,1,1,,,0,0,0,0,,,0,0,0,0,,,0,0,0,0,,,0,0,0,0,,,0,0,0,0,,,0,0,0,0,,,0,0,0,0,,,0,0,0,0,,,0,0,0,0,AAPL
2024-10-22 12:22:49.160446628+00:00,10,40,38,A,A,0,,0,194,203566,73112,234.16,,200,0,0,0,,,0,0,0,0,,,0,0,0,0,,,0,0,0,0,,,0,0,0,0,,,0,0,0,0,,,0,0,0,0,,,0,0,0,0,,,0,0,0,0,,,0,0,0,0,AAPL
2024-10-22 12:22:49.226003336+00:00,10,40,38,A,A,0,234.99,200,194,203244,73114,234.16,234.99,200,200,0,0,,,0,0,0,0,,,0,0,0,0,,,0,0,0,0,,,0,0,0,0,,,0,0,0,0,,,0,0,0,0,,,0,0,0,0,,,0,0,0,0,,,0,0,0,0,AAPL
2024-10-22 12:22:51.374336392+00:00,10,39,38,C,A,0,236.6,2000,130,203782,45869,233.0,,2000,0,1,0,,,0,0,0,0,,,0,0,0,0,,,0,0,0,0,,,0,0,0,0,,,0,0,0,0,,,0,0,0,0,,,0,0,0,0,,,0,0,0,0,,,0,0,0,0,AAPL
2024-10-22 12:22:51.410660863+00:00,10,39,38,A,A,0,236.6,2000,130,203334,45870,233.0,236.6,2000,2000,1,1,,,0,0,0,0,,,0,0,0,0,,,0,0,0,0,,,0,0,0,0,,,0,0,0,0,,,0,0,0,0,,,0,0,0,0,,,0,0,0,0,,,0,0,0,0,AAPL
2024-10-22 12:22:52.030969719+00:00,10,40,38,A,A,0,,0,194,203208,73134,234.16,,200,0,0,0,,,0,0,0,0,,,0,0,0,0,,,0,0,0,0,,,0,0,0,0,,,0,0,0,0,,,0,0,0,0,,,0,0,0,0,,,0,0,0,0,,,0,0,0,0,AAPL
2024-10-22 12:22:53.002295354+00:00,10,40,38,A,A,0,234.99,200,194,203865,73143,234.16,234.99,200,200,0,0,,,0,0,0,0,,,0,0,0,0,,,0,0,0,0,,,0,0,0,0,,,0,0,0,0,,,0,0,0,0,,,0,0,0,0,,,0,0,0,0,,,0,0,0,0,AAPL
2024-10-22 12:22:53.103063226+00:00,10,40,38,A,A,0,,0,194,203158,73148,234.16,,200,0,0,0,,,0,0,0,0,,,0,0,0,0,,,0,0,0,0,,,0,0,0,0,,,0,0,0,0,,,0,0,0,0,,,0,0,0,0,,,0,0,0,0,,,0,0,0,0,AAPL
2024-10-22 12:22:53.680219612+00:00,10,40,38,A,A,0,234.99,200,194,203234,73158,234.16,234.99,200,200,0,0,,,0,0,0,0,,,0,0,0,0,,,0,0,0,0,,,0,0,0,0,,,0,0,0,0,,,0,0,0,0,,,0,0,0,0,,,0,0,0,0,,,0,0,0,0,AAPL
2024-10-22 12:23:04.746748774+00:00,10,40,38,A,A,0,,0,194,203411,73321,234.16,,200,0,0,0,,,0,0,0,0,,,0,0,0,0,,,0,0,0,0,,,0,0,0,0,,,0,0,0,0,,,0,0,0,0,,,0,0,0,0,,,0,0,0,0,,,0,0,0,0,AAPL
2024-10-22 12:23:17.832973065+00:00,10,40,38,A,A,0,234.99,200,194,203257,73425,234.16,234.99,200,200,0,0,,,0,0,0,0,,,0,0,0,0,,,0,0,0,0,,,0,0,0,0,,,0,0,0,0,,,0,0,0,0,,,0,0,0,0,,,0,0,0,0,,,0,0,0,0,AAPL
2024-10-22 12:23:17.833588243+00:00,10,39,38,C,A,0,236.6,2000,130,203451,46152,233.0,,2000,0,1,0,,,0,0,0,0,,,0,0,0,0,,,0,0,0,0,,,0,0,0,0,,,0,0,0,0,,,0,0,0,0,,,0,0,0,0,,,0,0,0,0,,,0,0,0,0,AAPL
2024-10-22 12:23:17.858765012+00:00,10,39,38,A,A,0,236.6,2000,130,203320,46153,233.0,236.6,2000,2000,1,1,,,0,0,0,0,,,0,0,0,0,,,0,0,0,0,,,0,0,0,0,,,0,0,0,0,,,0,0,0,0,,,0,0,0,0,,,0,0,0,0,,,0,0,0,0,AAPL
2024-10-22 12:23:17.858809163+00:00,10,40,38,A,A,0,,0,194,203152,73426,234.16,,200,0,0,0,,,0,0,0,0,,,0,0,0,0,,,0,0,0,0,,,0,0,0,0,,,0,0,0,0,,,0,0,0,0,,,0,0,0,0,,,0,0,0,0,,,0,0,0,0,AAPL
2024-10-22 12:23:19.122486039+00:00,10,40,38,A,A,0,234.99,200,194,203400,73432,234.16,234.99,200,200,0,0,,,0,0,0,0,,,0,0,0,0,,,0,0,0,0,,,0,0,0,0,,,0,0,0,0,,,0,0,0,0,,,0,0,0,0,,,0,0,0,0,,,0,0,0,0,AAPL
2024-10-22 12:23:19.222455082+00:00,10,40,38,A,A,0,,0,194,203184,73434,234.16,,200,0,0,0,,,0,0,0,0,,,0,0,0,0,,,0,0,0,0,,,0,0,0,0,,,0,0,0,0,,,0,0,0,0,,,0,0,0,0,,,0,0,0,0,,,0,0,0,0,AAPL
2024-10-22 12:23:24.637542543+00:00,10,40,38,A,A,0,234.99,200,194,203384,73489,234.16,234.99,200,200,0,0,,,0,0,0,0,,,0,0,0,0,,,0,0,0,0,,,0,0,0,0,,,0,0,0,0,,,0,0,0,0,,,0,0,0,0,,,0,0,0,0,,,0,0,0,0,AAPL
2024-10-22 12:23:24.706369200+00:00,10,40,38,A,A,0,,0,194,203100,73493,234.16,,200,0,0,0,,,0,0,0,0,,,0,0,0,0,,,0,0,0,0,,,0,0,0,0,,,0,0,0,0,,,0,0,0,0,,,0,0,0,0,,,0,0,0,0,,,0,0,0,0,AAPL
2024-10-22 12:23:32.936992649+00:00,10,40,38,A,A,0,234.99,200,194,202804,73552,234.16,234.99,200,200,0,0,,,0,0,0,0,,,0,0,0,0,,,0,0,0,0,,,0,0,0,0,,,0,0,0,0,,,0,0,0,0,,,0,0,0,0,,,0,0,0,0,,,0,0,0,0,AAPL
2024-10-22 12:23:32.990283178+00:00,10,40,38,A,A,0,,0,194,202875,73555,234.16,,200,0,0,0,,,0,0,0,0,,,0,0,0,0,,,0,0,0,0,,,0,0,0,0,,,0,0,0,0,,,0,0,0,0,,,0,0,0,0,,,0,0,0,0,,,0,0,0,0,AAPL
2024-10-22 12:23:40.688699940+00:00,10,40,38,A,A,0,234.99,200,194,203165,73588,234.16,234.99,200,200,0,0,,,0,0,0,0,,,0,0,0,0,,,0,0,0,0,,,0,0,0,0,,,0,0,0,0,,,0,0,0,0,,,0,0,0,0,,,0,0,0,0,,,0,0,0,0,AAPL
2024-10-22 12:23:40.689372726+00:00,10,39,38,C,A,0,236.6,2000,130,204087,46383,233.0,,2000,0,1,0,,,0,0,0,0,,,0,0,0,0,,,0,0,0,0,,,0,0,0,0,,,0,0,0,0,,,0,0,0,0,,,0,0,0,0,,,0,0,0,0,,,0,0,0,0,AAPL
2024-10-22 12:23:40.725793323+00:00,10,39,38,A,A,0,236.6,2000,130,203861,46384,233.0,236.6,2000,2000,1,1,,,0,0,0,0,,,0,0,0,0,,,0,0,0,0,,,0,0,0,0,,,0,0,0,0,,,0,0,0,0,,,0,0,0,0,,,0,0,0,0,,,0,0,0,0,AAPL
2024-10-22 12:23:40.725847489+00:00,10,40,38,A,A,0,,0,194,203266,73589,234.16,,200,0,0,0,,,0,0,0,0,,,0,0,0,0,,,0,0,0,0,,,0,0,0,0,,,0,0,0,0,,,0,0,0,0,,,0,0,0,0,,,0,0,0,0,,,0,0,0,0,AAPL
2024-10-22 12:23:41.306375636+00:00,10,40,38,A,A,0,234.99,200,194,203265,73592,234.16,234.99,200,200,0,0,,,0,0,0,0,,,0,0,0,0,,,0,0,0,0,,,0,0,0,0,,,0,0,0,0,,,0,0,0,0,,,0,0,0,0,,,0,0,0,0,,,0,0,0,0,AAPL
2024-10-22 12:23:41.396353530+00:00,10,40,38,A,A,0,,0,194,203002,73593,234.16,,200,0,0,0,,,0,0,0,0,,,0,0,0,0,,,0,0,0,0,,,0,0,0,0,,,0,0,0,0,,,0,0,0,0,,,0,0,0,0,,,0,0,0,0,,,0,0,0,0,AAPL
2024-10-22 12:23:43.113942964+00:00,10,40,38,A,A,0,234.99,200,194,202964,73602,234.16,234.99,200,200,0,0,,,0,0,0,0,,,0,0,0,0,,,0,0,0,0,,,0,0,0,0,,,0,0,0,0,,,0,0,0,0,,,0,0,0,0,,,0,0,0,0,,,0,0,0,0,AAPL
2024-10-22 12:23:43.206360600+00:00,10,40,38,A,A,0,,0,194,202793,73603,234.16,,200,0,0,0,,,0,0,0,0,,,0,0,0,0,,,0,0,0,0,,,0,0,0,0,,,0,0,0,0,,,0,0,0,0,,,0,0,0,0,,,0,0,0,0,,,0,0,0,0,AAPL
2024-10-22 12:23:51.411640444+00:00,10,40,38,A,A,0,234.99,200,194,202665,73653,234.16,234.99,200,200,0,0,,,0,0,0,0,,,0,0,0,0,,,0,0,0,0,,,0,0,0,0,,,0,0,0,0,,,0,0,0,0,,,0,0,0,0,,,0,0,0,0,,,0,0,0,0,AAPL
2024-10-22 12:23:51.411666367+00:00,10,40,38,A,A,0,,0,194,202435,73654,234.16,,200,0,0,0,,,0,0,0,0,,,0,0,0,0,,,0,0,0,0,,,0,0,0,0,,,0,0,0,0,,,0,0,0,0,,,0,0,0,0,,,0,0,0,0,,,0,0,0,0,AAPL
2024-10-22 12:23:56.342555593+00:00,10,40,38,A,A,0,234.99,200,194,202481,73676,234.16,234.99,200,200,0,0,,,0,0,0,0,,,0,0,0,0,,,0,0,0,0,,,0,0,0,0,,,0,0,0,0,,,0,0,0,0,,,0,0,0,0,,,0,0,0,0,,,0,0,0,0,AAPL
2024-10-22 12:23:56.454139475+00:00,10,40,38,A,A,0,,0,194,202333,73678,234.16,,200,0,0,0,,,0,0,0,0,,,0,0,0,0,,,0,0,0,0,,,0,0,0,0,,,0,0,0,0,,,0,0,0,0,,,0,0,0,0,,,0,0,0,0,,,0,0,0,0,AAPL
2024-10-22 12:23:58.372368030+00:00,10,40,38,A,A,0,234.99,200,194,202205,73690,234.16,234.99,200,200,0,0,,,0,0,0,0,,,0,0,0,0,,,0,0,0,0,,,0,0,0,0,,,0,0,0,0,,,0,0,0,0,,,0,0,0,0,,,0,0,0,0,,,0,0,0,0,AAPL
2024-10-22 12:23:58.584915041+00:00,10,40,38,A,A,0,,0,194,202164,73695,234.16,,200,0,0,0,,,0,0,0,0,,,0,0,0,0,,,0,0,0,0,,,0,0,0,0,,,0,0,0,0,,,0,0,0,0,,,0,0,0,0,,,0,0,0,0,,,0,0,0,0,AAPL
2024-10-22 12:23:58.786373745+00:00,10,40,38,A,A,0,234.99,200,194,202205,73696,234.16,234.99,200,200,0,0,,,0,0,0,0,,,0,0,0,0,,,0,0,0,0,,,0,0,0,0,,,0,0,0,0,,,0,0,0,0,,,0,0,0,0,,,0,0,0,0,,,0,0,0,0,AAPL
2024-10-22 12:23:59.413152988+00:00,10,40,38,A,A,0,,0,194,202449,73703,234.16,,200,0,0,0,,,0,0,0,0,,,0,0,0,0,,,0,0,0,0,,,0,0,0,0,,,0,0,0,0,,,0,0,0,0,,,0,0,0,0,,,0,0,0,0,,,0,0,0,0,AAPL
2024-10-22 12:24:00.016724207+00:00,10,40,38,A,A,0,234.99,200,192,202335,73719,234.16,234.99,200,200,0,0,,,0,0,0,0,,,0,0,0,0,,,0,0,0,0,,,0,0,0,0,,,0,0,0,0,,,0,0,0,0,,,0,0,0,0,,,0,0,0,0,,,0,0,0,0,AAPL
2024-10-22 12:24:00.016867267+00:00,10,41,38,A,A,0,,0,194,57959,120164,234.3,,200,0,0,0,,,0,0,0,0,,,0,0,0,0,,,0,0,0,0,,,0,0,0,0,,,0,0,0,0,,,0,0,0,0,,,0,0,0,0,,,0,0,0,0,,,0,0,0,0,AAPL
2024-10-22 12:24:00.016878588+00:00,10,41,38,A,B,0,,0,194,55474,120166,,,0,0,0,0,,,0,0,0,0,,,0,0,0,0,,,0,0,0,0,,,0,0,0,0,,,0,0,0,0,,,0,0,0,0,,,0,0,0,0,,,0,0,0,0,,,0,0,0,0,AAPL
2024-10-22 12:24:00.120271999+00:00,10,41,38,A,A,0,234.93,200,194,54995,120288,,234.93,0,200,0,0,,,0,0,0,0,,,0,0,0,0,,,0,0,0,0,,,0,0,0,0,,,0,0,0,0,,,0,0,0,0,,,0,0,0,0,,,0,0,0,0,,,0,0,0,0,AAPL
2024-10-22 12:24:00.221659741+00:00,10,41,38,A,B,0,234.93,200,194,64608,120329,234.22,234.93,200,200,0,0,,,0,0,0,0,,,0,0,0,0,,,0,0,0,0,,,0,0,0,0,,,0,0,0,0,,,0,0,0,0,,,0,0,0,0,,,0,0,0,0,,,0,0,0,0,AAPL
2024-10-22 12:24:02.801709325+00:00,10,40,38,A,B,0,234.99,200,194,202181,73785,,234.99,0,200,0,0,,,0,0,0,0,,,0,0,0,0,,,0,0,0,0,,,0,0,0,0,,,0,0,0,0,,,0,0,0,0,,,0,0,0,0,,,0,0,0,0,,,0,0,0,0,AAPL
2024-10-22 12:24:03.738778981+00:00,10,41,38,A,B,0,234.93,200,194,60945,120445,,234.93,0,200,0,0,,,0,0,0,0,,,0,0,0,0,,,0,0,0,0,,,0,0,0,0,,,0,0,0,0,,,0,0,0,0,,,0,0,0,0,,,0,0,0,0,,,0,0,0,0,AAPL
2024-10-22 12:24:04.744105268+00:00,10,40,38,A,A,0,,0,194,202327,73829,,,0,0,0,0,,,0,0,0,0,,,0,0,0,0,,,0,0,0,0,,,0,0,0,0,,,0,0,0,0,,,0,0,0,0,,,0,0,0,0,,,0,0,0,0,,,0,0,0,0,AAPL
2024-10-22 12:24:26.094557707+00:00,10,39,38,A,B,0,233.4,2000,130,204045,46662,233.4,236.6,2000,2000,1,1,233.0,,2000,0,1,0,,,0,0,0,0,,,0,0,0,0,,,0,0,0,0,,,0,0,0,0,,,0,0,0,0,,,0,0,0,0,,,0,0,0,0,,,0,0,0,0,AAPL
2024-10-22 12:24:26.094744651+00:00,10,39,38,C,B,1,233.0,2000,130,203474,46663,233.4,236.6,2000,2000,1,1,,,0,0,0,0,,,0,0,0,0,,,0,0,0,0,,,0,0,0,0,,,0,0,0,0,,,0,0,0,0,,,0,0,0,0,,,0,0,0,0,,,0,0,0,0,AAPL
2024-10-22 12:24:31.438567117+00:00,10,39,38,C,B,0,233.4,2000,130,203959,46697,,236.6,0,2000,0,1,,,0,0,0,0,,,0,0,0,0,,,0,0,0,0,,,0,0,0,0,,,0,0,0,0,,,0,0,0,0,,,0,0,0,0,,,0,0,0,0,,,0,0,0,0,AAPL
2024-10-22 12:24:31.439889445+00:00,10,40,38,A,A,0,234.99,200,194,202423,74052,,234.99,0,200,0,0,,,0,0,0,0,,,0,0,0,0,,,0,0,0,0,,,0,0,0,0,,,0,0,0,0,,,0,0,0,0,,,0,0,0,0,,,0,0,0,0,,,0,0,0,0,AAPL
2024-10-22 12:24:31.440162360+00:00,10,40,38,A,B,0,234.99,200,194,202314,74053,234.16,234.99,200,200,0,0,,,0,0,0,0,,,0,0,0,0,,,0,0,0,0,,,0,0,0,0,,,0,0,0,0,,,0,0,0,0,,,0,0,0,0,,,0,0,0,0,,,0,0,0,0,AAPL
2024-10-22 12:24:31.443506435+00:00,10,41,38,A,B,0,234.93,200,194,61211,121117,234.21,234.93,200,200,0,0,,,0,0,0,0,,,0,0,0,0,,,0,0,0,0,,,0,0,0,0,,,0,0,0,0,,,0,0,0,0,,,0,0,0,0,,,0,0,0,0,,,0,0,0,0,AAPL
2024-10-22 12:24:31.450759348+00:00,10,40,38,A,B,0,234.99,200,194,202302,74054,,234.99,0,200,0,0,,,0,0,0,0,,,0,0,0,0,,,0,0,0,0,,,0,0,0,0,,,0,0,0,0,,,0,0,0,0,,,0,0,0,0,,,0,0,0,0,,,0,0,0,0,AAPL
2024-10-22 12:24:31.450963515+00:00,10,41,38,A,B,0,234.93,200,194,55761,121118,,234.93,0,200,0,0,,,0,0,0,0,,,0,0,0,0,,,0,0,0,0,,,0,0,0,0,,,0,0,0,0,,,0,0,0,0,,,0,0,0,0,,,0,0,0,0,,,0,0,0,0,AAPL
2024-10-22 12:24:31.455999930+00:00,10,39,38,C,A,0,236.6,2000,130,203623,46698,,,0,0,0,0,,,0,0,0,0,,,0,0,0,0,,,0,0,0,0,,,0,0,0,0,,,0,0,0,0,,,0,0,0,0,,,0,0,0,0,,,0,0,0,0,,,0,0,0,0,AAPL
2024-10-22 12:24:31.467657024+00:00,10,39,38,A,A,0,236.6,2000,130,203775,46699,,236.6,0,2000,0,1,,,0,0,0,0,,,0,0,0,0,,,0,0,0,0,,,0,0,0,0,,,0,0,0,0,,,0,0,0,0,,,0,0,0,0,,,0,0,0,0,,,0,0,0,0,AAPL
2024-10-22 12:24:31.480159367+00:00,10,39,38,A,B,0,233.0,2000,130,203678,46700,233.0,236.6,2000,2000,1,1,,,0,0,0,0,,,0,0,0,0,,,0,0,0,0,,,0,0,0,0,,,0,0,0,0,,,0,0,0,0,,,0,0,0,0,,,0,0,0,0,,,0,0,0,0,AAPL
2024-10-22 12:24:32.745999164+00:00,10,39,38,C,A,0,236.6,2000,130,203781,46717,233.0,,2000,0,1,0,,,0,0,0,0,,,0,0,0,0,,,0,0,0,0,,,0,0,0,0,,,0,0,0,0,,,0,0,0,0,,,0,0,0,0,,,0,0,0,0,,,0,0,0,0,AAPL
2024-10-22 12:24:33.059044232+00:00,10,39,38,A,A,0,236.8,2000,130,203993,46721,233.0,236.8,2000,2000,1,1,,,0,0,0,0,,,0,0,0,0,,,0,0,0,0,,,0,0,0,0,,,0,0,0,0,,,0,0,0,0,,,0,0,0,0,,,0,0,0,0,,,0,0,0,0,AAPL
2024-10-22 12:24:33.141775212+00:00,10,40,38,A,B,0,234.99,200,194,202273,74069,234.11,234.99,200,200,0,0,,,0,0,0,0,,,0,0,0,0,,,0,0,0,0,,,0,0,0,0,,,0,0,0,0,,,0,0,0,0,,,0,0,0,0,,,0,0,0,0,,,0,0,0,0,AAPL
2024-10-22 12:24:33.242015856+00:00,10,40,38,A,B,0,234.99,200,194,202283,74070,,234.99,0,200,0,0,,,0,0,0,0,,,0,0,0,0,,,0,0,0,0,,,0,0,0,0,,,0,0,0,0,,,0,0,0,0,,,0,0,0,0,,,0,0,0,0,,,0,0,0,0,AAPL
2024-10-22 12:24:33.851410134+00:00,10,40,38,A,B,0,234.99,200,194,202277,74075,234.11,234.99,200,200,0,0,,,0,0,0,0,,,0,0,0,0,,,0,0,0,0,,,0,0,0,0,,,0,0,0,0,,,0,0,0,0,,,0,0,0,0,,,0,0,0,0,,,0,0,0,0,AAPL
2024-10-22 12:24:33.851699597+00:00,10,41,38,A,B,0,234.93,200,194,56363,121156,234.18,234.93,200,200,0,0,,,0,0,0,0,,,0,0,0,0,,,0,0,0,0,,,0,0,0,0,,,0,0,0,0,,,0,0,0,0,,,0,0,0,0,,,0,0,0,0,,,0,0,0,0,AAPL
2024-10-22 12:24:33.952854255+00:00,10,40,38,A,B,0,234.99,200,194,202277,74078,,234.99,0,200,0,0,,,0,0,0,0,,,0,0,0,0,,,0,0,0,0,,,0,0,0,0,,,0,0,0,0,,,0,0,0,0,,,0,0,0,0,,,0,0,0,0,,,0,0,0,0,AAPL
2024-10-22 12:24:33.953447603+00:00,10,41,38,A,B,0,234.93,200,194,56110,121159,,234.93,0,200,0,0,,,0,0,0,0,,,0,0,0,0,,,0,0,0,0,,,0,0,0,0,,,0,0,0,0,,,0,0,0,0,,,0,0,0,0,,,0,0,0,0,,,0,0,0,0,AAPL
2024-10-22 12:24:42.953950796+00:00,10,40,38,A,B,0,234.99,200,194,202596,74152,234.11,234.99,200,200,0,0,,,0,0,0,0,,,0,0,0,0,,,0,0,0,0,,,0,0,0,0,,,0,0,0,0,,,0,0,0,0,,,0,0,0,0,,,0,0,0,0,,,0,0,0,0,AAPL
2024-10-22 12:24:42.975740591+00:00,10,39,38,A,A,0,236.6,2000,130,204168,46771,233.0,236.6,2000,2000,1,1,,236.8,0,2000,0,1,,,0,0,0,0,,,0,0,0,0,,,0,0,0,0,,,0,0,0,0,,,0,0,0,0,,,0,0,0,0,,,0,0,0,0,,,0,0,0,0,AAPL
2024-10-22 12:24:42.975940762+00:00,10,39,38,C,A,1,236.8,2000,130,203637,46772,233.0,236.6,2000,2000,1,1,,,0,0,0,0,,,0,0,0,0,,,0,0,0,0,,,0,0,0,0,,,0,0,0,0,,,0,0,0,0,,,0,0,0,0,,,0,0,0,0,,,0,0,0,0,AAPL
2024-10-22 12:24:43.029156425+00:00,10,39,38,C,A,0,236.6,2000,130,203725,46774,233.0,,2000,0,1,0,,,0,0,0,0,,,0,0,0,0,,,0,0,0,0,,,0,0,0,0,,,0,0,0,0,,,0,0,0,0,,,0,0,0,0,,,0,0,0,0,,,0,0,0,0,AAPL
2024-10-22 12:24:43.040017519+00:00,10,39,38,A,A,0,236.8,2000,130,203699,46775,233.0,236.8,2000,2000,1,1,,,0,0,0,0,,,0,0,0,0,,,0,0,0,0,,,0,0,0,0,,,0,0,0,0,,,0,0,0,0,,,0,0,0,0,,,0,0,0,0,,,0,0,0,0,AAPL
2024-10-22 12:24:43.544939963+00:00,10,39,38,A,A,0,236.6,2000,130,204017,46776,233.0,236.6,2000,2000,1,1,,236.8,0,2000,0,1,,,0,0,0,0,,,0,0,0,0,,,0,0,0,0,,,0,0,0,0,,,0,0,0,0,,,0,0,0,0,,,0,0,0,0,,,0,0,0,0,AAPL
2024-10-22 12:24:43.545122076+00:00,10,39,38,C,A,1,236.8,2000,130,203545,46777,233.0,236.6,2000,2000,1,1,,,0,0,0,0,,,0,0,0,0,,,0,0,0,0,,,0,0,0,0,,,0,0,0,0,,,0,0,0,0,,,0,0,0,0,,,0,0,0,0,,,0,0,0,0,AAPL
2024-10-22 12:24:45.024639691+00:00,10,40,38,A,B,0,234.99,200,194,202697,74164,,234.99,0,200,0,0,,,0,0,0,0,,,0,0,0,0,,,0,0,0,0,,,0,0,0,0,,,0,0,0,0,,,0,0,0,0,,,0,0,0,0,,,0,0,0,0,,,0,0,0,0,AAPL
2024-10-22 12:24:45.024768061+00:00,10,40,38,A,B,0,234.99,200,194,202619,74165,234.13,234.99,200,200,0,0,,,0,0,0,0,,,0,0,0,0,,,0,0,0,0,,,0,0,0,0,,,0,0,0,0,,,0,0,0,0,,,0,0,0,0,,,0,0,0,0,,,0,0,0,0,AAPL
2024-10-22 12:24:45.025059938+00:00,10,41,38,A,B,0,234.93,200,194,56648,121505,234.2,234.93,200,200,0,0,,,0,0,0,0,,,0,0,0,0,,,0,0,0,0,,,0,0,0,0,,,0,0,0,0,,,0,0,0,0,,,0,0,0,0,,,0,0,0,0,,,0,0,0,0,AAPL
2024-10-22 12:24:45.031449270+00:00,10,40,38,A,B,0,234.99,200,194,202588,74166,,234.99,0,200,0,0,,,0,0,0,0,,,0,0,0,0,,,0,0,0,0,,,0,0,0,0,,,0,0,0,0,,,0,0,0,0,,,0,0,0,0,,,0,0,0,0,,,0,0,0,0,AAPL
2024-10-22 12:24:45.031697376+00:00,10,41,38,A,B,0,234.93,200,194,55456,121506,,234.93,0,200,0,0,,,0,0,0,0,,,0,0,0,0,,,0,0,0,0,,,0,0,0,0,,,0,0,0,0,,,0,0,0,0,,,0,0,0,0,,,0,0,0,0,,,0,0,0,0,AAPL
2024-10-22 12:24:45.126349955+00:00,10,40,38,A,A,0,,0,194,202610,74167,,,0,0,0,0,,,0,0,0,0,,,0,0,0,0,,,0,0,0,0,,,0,0,0,0,,,0,0,0,0,,,0,0,0,0,,,0,0,0,0,,,0,0,0,0,,,0,0,0,0,AAPL
2024-10-22 12:24:45.187063958+00:00,10,40,38,A,A,0,234.97,200,194,202623,74168,,234.97,0,200,0,0,,,0,0,0,0,,,0,0,0,0,,,0,0,0,0,,,0,0,0,0,,,0,0,0,0,,,0,0,0,0,,,0,0,0,0,,,0,0,0,0,,,0,0,0,0,AAPL
2024-10-22 12:24:46.839937361+00:00,10,40,38,A,B,0,234.97,200,194,202784,74173,234.11,234.97,200,200,0,0,,,0,0,0,0,,,0,0,0,0,,,0,0,0,0,,,0,0,0,0,,,0,0,0,0,,,0,0,0,0,,,0,0,0,0,,,0,0,0,0,,,0,0,0,0,AAPL
2024-10-22 12:24:48.319597106+00:00,10,40,38,A,B,0,234.97,200,194,202501,74191,,234.97,0,200,0,0,,,0,0,0,0,,,0,0,0,0,,,0,0,0,0,,,0,0,0,0,,,0,0,0,0,,,0,0,0,0,,,0,0,0,0,,,0,0,0,0,,,0,0,0,0,AAPL
2024-10-22 12:24:48.320112437+00:00,10,41,38,A,B,0,234.93,200,194,56152,121581,234.18,234.93,200,200,0,0,,,0,0,0,0,,,0,0,0,0,,,0,0,0,0,,,0,0,0,0,,,0,0,0,0,,,0,0,0,0,,,0,0,0,0,,,0,0,0,0,,,0,0,0,0,AAPL
2024-10-22 12:24:48.421403061+00:00,10,41,38,A,B,0,234.93,200,194,55928,121585,,234.93,0,200,0,0,,,0,0,0,0,,,0,0,0,0,,,0,0,0,0,,,0,0,0,0,,,0,0,0,0,,,0,0,0,0,,,0,0,0,0,,,0,0,0,0,,,0,0,0,0,AAPL
2024-10-22 12:24:49.317559221+00:00,10,39,38,A,A,0,236.4,2000,130,203869,46813,233.0,236.4,2000,2000,1,1,,236.6,0,2000,0,1,,,0,0,0,0,,,0,0,0,0,,,0,0,0,0,,,0,0,0,0,,,0,0,0,0,,,0,0,0,0,,,0,0,0,0,,,0,0,0,0,AAPL
2024-10-22 12:24:49.318660150+00:00,10,39,38,C,A,0,236.4,2000,130,203690,46814,233.0,236.6,2000,2000,1,1,,,0,0,0,0,,,0,0,0,0,,,0,0,0,0,,,0,0,0,0,,,0,0,0,0,,,0,0,0,0,,,0,0,0,0,,,0,0,0,0,,,0,0,0,0,AAPL
2024-10-22 12:24:49.360830537+00:00,10,40,38,A,B,0,234.97,200,194,202382,74203,234.11,234.97,200,200,0,0,,,0,0,0,0,,,0,0,0,0,,,0,0,0,0,,,0,0,0,0,,,0,0,0,0,,,0,0,0,0,,,0,0,0,0,,,0,0,0,0,,,0,0,0,0,AAPL
2024-10-22 12:24:54.790634175+00:00,10,41,38,A,B,0,234.93,200,194,56113,121711,234.19,234.93,200,200,0,0,,,0,0,0,0,,,0,0,0,0,,,0,0,0,0,,,0,0,0,0,,,0,0,0,0,,,0,0,0,0,,,0,0,0,0,,,0,0,0,0,,,0,0,0,0,AAPL
2024-10-22 12:25:00.024638350+00:00,10,40,38,A,B,0,234.97,200,194,202867,74295,,234.97,0,200,0,0,,,0,0,0,0,,,0,0,0,0,,,0,0,0,0,,,0,0,0,0,,,0,0,0,0,,,0,0,0,0,,,0,0,0,0,,,0,0,0,0,,,0,0,0,0,AAPL
2024-10-22 12:25:00.024648766+00:00,10,40,38,A,A,0,,0,194,203035,74297,,,0,0,0,0,,,0,0,0,0,,,0,0,0,0,,,0,0,0,0,,,0,0,0,0,,,0,0,0,0,,,0,0,0,0,,,0,0,0,0,,,0,0,0,0,,,0,0,0,0,AAPL
2024-10-22 12:25:00.024812557+00:00,10,41,38,A,B,0,234.93,200,194,56682,121926,,234.93,0,200,0,0,,,0,0,0,0,,,0,0,0,0,,,0,0,0,0,,,0,0,0,0,,,0,0,0,0,,,0,0,0,0,,,0,0,0,0,,,0,0,0,0,,,0,0,0,0,AAPL
2024-10-22 12:25:00.024821947+00:00,10,41,38,A,A,0,,0,194,55816,121928,,,0,0,0,0,,,0,0,0,0,,,0,0,0,0,,,0,0,0,0,,,0,0,0,0,,,0,0,0,0,,,0,0,0,0,,,0,0,0,0,,,0,0,0,0,,,0,0,0,0,AAPL
2024-10-22 12:25:03.315744844+00:00,10,40,38,A,A,0,234.95,200,194,203142,74510,,234.95,0,200,0,0,,,0,0,0,0,,,0,0,0,0,,,0,0,0,0,,,0,0,0,0,,,0,0,0,0,,,0,0,0,0,,,0,0,0,0,,,0,0,0,0,,,0,0,0,0,AAPL
2024-10-22 12:25:03.316005524+00:00,10,41,38,A,A,0,234.88,200,194,56349,122686,,234.88,0,200,0,0,,,0,0,0,0,,,0,0,0,0,,,0,0,0,0,,,0,0,0,0,,,0,0,0,0,,,0,0,0,0,,,0,0,0,0,,,0,0,0,0,,,0,0,0,0,AAPL
2024-10-22 12:25:03.321711383+00:00,10,40,38,A,A,0,,0,194,203086,74511,,,0,0,0,0,,,0,0,0,0,,,0,0,0,0,,,0,0,0,0,,,0,0,0,0,,,0,0,0,0,,,0,0,0,0,,,0,0,0,0,,,0,0,0,0,,,0,0,0,0,AAPL
2024-10-22 12:25:03.321950681+00:00,10,41,38,A,A,0,,0,194,56306,122687,,,0,0,0,0,,,0,0,0,0,,,0,0,0,0,,,0,0,0,0,,,0,0,0,0,,,0,0,0,0,,,0,0,0,0,,,0,0,0,0,,,0,0,0,0,,,0,0,0,0,AAPL
2024-10-22 12:25:03.359806066+00:00,10,39,38,C,A,0,236.6,2000,130,204130,46967,233.0,,2000,0,1,0,,,0,0,0,0,,,0,0,0,0,,,0,0,0,0,,,0,0,0,0,,,0,0,0,0,,,0,0,0,0,,,0,0,0,0,,,0,0,0,0,,,0,0,0,0,AAPL
2024-10-22 12:25:03.673099496+00:00,10,39,38,A,A,0,236.8,2000,130,203655,46974,233.0,236.8,2000,2000,1,1,,,0,0,0,0,,,0,0,0,0,,,0,0,0,0,,,0,0,0,0,,,0,0,0,0,,,0,0,0,0,,,0,0,0,0,,,0,0,0,0,,,0,0,0,0,AAPL
2024-10-22 12:25:03.898194898+00:00,10,39,38,A,A,0,236.6,2000,130,203808,46975,233.0,236.6,2000,2000,1,1,,236.8,0,2000,0,1,,,0,0,0,0,,,0,0,0,0,,,0,0,0,0,,,0,0,0,0,,,0,0,0,0,,,0,0,0,0,,,0,0,0,0,,,0,0,0,0,AAPL
2024-10-22 12:25:03.898377242+00:00,10,39,38,C,A,1,236.8,2000,130,203622,46976,233.0,236.6,2000,2000,1,1,,,0,0,0,0,,,0,0,0,0,,,0,0,0,0,,,0,0,0,0,,,0,0,0,0,,,0,0,0,0,,,0,0,0,0,,,0,0,0,0,,,0,0,0,0,AAPL
2024-10-22 12:25:05.133839777+00:00,10,40,38,A,A,0,234.94,200,194,203170,74533,,234.94,0,200,0,0,,,0,0,0,0,,,0,0,0,0,,,0,0,0,0,,,0,0,0,0,,,0,0,0,0,,,0,0,0,0,,,0,0,0,0,,,0,0,0,0,,,0,0,0,0,AAPL
2024-10-22 12:25:05.650002935+00:00,10,41,38,A,A,0,234.83,200,194,56668,122777,,234.83,0,200,0,0,,,0,0,0,0,,,0,0,0,0,,,0,0,0,0,,,0,0,0,0,,,0,0,0,0,,,0,0,0,0,,,0,0,0,0,,,0,0,0,0,,,0,0,0,0,AAPL
2024-10-22 12:25:05.650069439+00:00,10,41,38,A,B,0,234.83,200,194,54337,122778,234.19,234.83,200,200,0,0,,,0,0,0,0,,,0,0,0,0,,,0,0,0,0,,,0,0,0,0,,,0,0,0,0,,,0,0,0,0,,,0,0,0,0,,,0,0,0,0,,,0,0,0,0,AAPL
2024-10-22 12:25:05.851874504+00:00,10,41,38,A,B,0,234.83,200,194,55664,122789,,234.83,0,200,0,0,,,0,0,0,0,,,0,0,0,0,,,0,0,0,0,,,0,0,0,0,,,0,0,0,0,,,0,0,0,0,,,0,0,0,0,,,0,0,0,0,,,0,0,0,0,AAPL
2024-10-22 12:25:06.355983714+00:00,10,40,38,A,A,0,,0,194,203336,74547,,,0,0,0,0,,,0,0,0,0,,,0,0,0,0,,,0,0,0,0,,,0,0,0,0,,,0,0,0,0,,,0,0,0,0,,,0,0,0,0,,,0,0,0,0,,,0,0,0,0,AAPL
2024-10-22 12:25:08.810018979+00:00,10,40,38,A,A,0,234.94,200,194,203153,74567,,234.94,0,200,0,0,,,0,0,0,0,,,0,0,0,0,,,0,0,0,0,,,0,0,0,0,,,0,0,0,0,,,0,0,0,0,,,0,0,0,0,,,0,0,0,0,,,0,0,0,0,AAPL
2024-10-22 12:25:11.082162762+00:00,10,39,38,C,A,0,236.6,2000,130,203710,47043,233.0,,2000,0,1,0,,,0,0,0,0,,,0,0,0,0,,,0,0,0,0,,,0,0,0,0,,,0,0,0,0,,,0,0,0,0,,,0,0,0,0,,,0,0,0,0,,,0,0,0,0,AAPL
2024-10-22 12:25:11.099312594+00:00,10,39,38,A,A,0,236.6,2000,130,203417,47044,233.0,236.6,2000,2000,1,1,,,0,0,0,0,,,0,0,0,0,,,0,0,0,0,,,0,0,0,0,,,0,0,0,0,,,0,0,0,0,,,0,0,0,0,,,0,0,0,0,,,0,0,0,0,AAPL
2024-10-22 12:25:11.157840729+00:00,10,39,38,C,A,0,236.6,2000,130,203398,47046,233.0,,2000,0,1,0,,,0,0,0,0,,,0,0,0,0,,,0,0,0,0,,,0,0,0,0,,,0,0,0,0,,,0,0,0,0,,,0,0,0,0,,,0,0,0,0,,,0,0,0,0,AAPL
2024-10-22 12:25:11.169359192+00:00,10,39,38,A,A,0,236.6,2000,130,203364,47047,233.0,236.6,2000,2000,1,1,,,0,0,0,0,,,0,0,0,0,,,0,0,0,0,,,0,0,0,0,,,0,0,0,0,,,0,0,0,0,,,0,0,0,0,,,0,0,0,0,,,0,0,0,0,AAPL
2024-10-22 12:25:13.248724861+00:00,10,40,38,A,B,0,234.94,200,194,203331,74600,234.12,234.94,200,200,0,0,,,0,0,0,0,,,0,0,0,0,,,0,0,0,0,,,0,0,0,0,,,0,0,0,0,,,0,0,0,0,,,0,0,0,0,,,0,0,0,0,,,0,0,0,0,AAPL
2024-10-22 12:25:13.248996301+00:00,10,41,38,A,B,0,234.83,200,194,60782,122978,234.19,234.83,200,200,0,0,,,0,0,0,0,,,0,0,0,0,,,0,0,0,0,,,0,0,0,0,,,0,0,0,0,,,0,0,0,0,,,0,0,0,0,,,0,0,0,0,,,0,0,0,0,AAPL
2024-10-22 12:25:13.349818956+00:00,10,40,38,A,B,0,234.94,200,194,203216,74601,,234.94,0,200,0,0,,,0,0,0,0,,,0,0,0,0,,,0,0,0,0,,,0,0,0,0,,,0,0,0,0,,,0,0,0,0,,,0,0,0,0,,,0,0,0,0,,,0,0,0,0,AAPL
2024-10-22 12:25:13.956906699+00:00,10,41,38,A,B,0,234.83,200,194,56272,123027,,234.83,0,200,0,0,,,0,0,0,0,,,0,0,0,0,,,0,0,0,0,,,0,0,0,0,,,0,0,0,0,,,0,0,0,0,,,0,0,0,0,,,0,0,0,0,,,0,0,0,0,AAPL
2024-10-22 12:25:15.066975499+00:00,10,40,38,A,B,0,234.94,200,194,203347,74617,234.12,234.94,200,200,0,0,,,0,0,0,0,,,0,0,0,0,,,0,0,0,0,,,0,0,0,0,,,0,0,0,0,,,0,0,0,0,,,0,0,0,0,,,0,0,0,0,,,0,0,0,0,AAPL
2024-10-22 12:25:15.067265230+00:00,10,41,38,A,B,0,234.83,200,194,56010,123052,234.19,234.83,200,200,0,0,,,0,0,0,0,,,0,0,0,0,,,0,0,0,0,,,0,0,0,0,,,0,0,0,0,,,0,0,0,0,,,0,0,0,0,,,0,0,0,0,,,0,0,0,0,AAPL
2024-10-22 12:25:15.168596536+00:00,10,40,38,A,B,0,234.94,200,194,203289,74618,,234.94,0,200,0,0,,,0,0,0,0,,,0,0,0,0,,,0,0,0,0,,,0,0,0,0,,,0,0,0,0,,,0,0,0,0,,,0,0,0,0,,,0,0,0,0,,,0,0,0,0,AAPL
2024-10-22 12:25:15.773571807+00:00,10,41,38,A,B,0,234.83,200,194,54583,123079,,234.83,0,200,0,0,,,0,0,0,0,,,0,0,0,0,,,0,0,0,0,,,0,0,0,0,,,0,0,0,0,,,0,0,0,0,,,0,0,0,0,,,0,0,0,0,,,0,0,0,0,AAPL
2024-10-22 12:25:17.132928139+00:00,10,40,38,A,B,0,234.94,200,194,203576,74635,234.12,234.94,200,200,0,0,,,0,0,0,0,,,0,0,0,0,,,0,0,0,0,,,0,0,0,0,,,0,0,0,0,,,0,0,0,0,,,0,0,0,0,,,0,0,0,0,,,0,0,0,0,AAPL
2024-10-22 12:25:17.133213869+00:00,10,41,38,A,B,0,234.83,200,194,55742,123137,234.19,234.83,200,200,0,0,,,0,0,0,0,,,0,0,0,0,,,0,0,0,0,,,0,0,0,0,,,0,0,0,0,,,0,0,0,0,,,0,0,0,0,,,0,0,0,0,,,0,0,0,0,AAPL
2024-10-22 12:25:17.133702564+00:00,10,39,38,C,A,0,236.6,2000,130,203138,47079,233.0,,2000,0,1,0,,,0,0,0,0,,,0,0,0,0,,,0,0,0,0,,,0,0,0,0,,,0,0,0,0,,,0,0,0,0,,,0,0,0,0,,,0,0,0,0,,,0,0,0,0,AAPL
2024-10-22 12:25:17.169332989+00:00,10,39,38,A,A,0,236.6,2000,130,202993,47082,233.0,236.6,2000,2000,1,1,,,0,0,0,0,,,0,0,0,0,,,0,0,0,0,,,0,0,0,0,,,0,0,0,0,,,0,0,0,0,,,0,0,0,0,,,0,0,0,0,,,0,0,0,0,AAPL
2024-10-22 12:25:17.239705156+00:00,10,41,38,A,B,0,234.83,200,194,60858,123139,,234.83,0,200,0,0,,,0,0,0,0,,,0,0,0,0,,,0,0,0,0,,,0,0,0,0,,,0,0,0,0,,,0,0,0,0,,,0,0,0,0,,,0,0,0,0,,,0,0,0,0,AAPL
2024-10-22 12:25:17.739692220+00:00,10,40,38,A,B,0,234.94,200,194,203454,74647,,234.94,0,200,0,0,,,0,0,0,0,,,0,0,0,0,,,0,0,0,0,,,0,0,0,0,,,0,0,0,0,,,0,0,0,0,,,0,0,0,0,,,0,0,0,0,,,0,0,0,0,AAPL
2024-10-22 12:25:18.320995062+00:00,10,40,38,A,B,0,234.94,200,194,203403,74656,234.12,234.94,200,200,0,0,,,0,0,0,0,,,0,0,0,0,,,0,0,0,0,,,0,0,0,0,,,0,0,0,0,,,0,0,0,0,,,0,0,0,0,,,0,0,0,0,,,0,0,0,0,AAPL
2024-10-22 12:25:18.321490780+00:00,10,41,38,A,B,0,234.83,200,194,55348,123203,234.19,234.83,200,200,0,0,,,0,0,0,0,,,0,0,0,0,,,0,0,0,0,,,0,0,0,0,,,0,0,0,0,,,0,0,0,0,,,0,0,0,0,,,0,0,0,0,,,0,0,0,0,AAPL
2024-10-22 12:25:18.525532945+00:00,10,41,38,A,B,0,234.83,200,194,55383,123213,,234.83,0,200,0,0,,,0,0,0,0,,,0,0,0,0,,,0,0,0,0,,,0,0,0,0,,,0,0,0,0,,,0,0,0,0,,,0,0,0,0,,,0,0,0,0,,,0,0,0,0,AAPL
2024-10-22 12:25:18.701874629+00:00,10,40,38,A,B,0,234.94,200,194,203498,74659,,234.94,0,200,0,0,,,0,0,0,0,,,0,0,0,0,,,0,0,0,0,,,0,0,0,0,,,0,0,0,0,,,0,0,0,0,,,0,0,0,0,,,0,0,0,0,,,0,0,0,0,AAPL
2024-10-22 12:25:20.855391814+00:00,10,39,38,C,A,0,236.6,2000,130,203201,47094,233.0,,2000,0,1,0,,,0,0,0,0,,,0,0,0,0,,,0,0,0,0,,,0,0,0,0,,,0,0,0,0,,,0,0,0,0,,,0,0,0,0,,,0,0,0,0,,,0,0,0,0,AAPL
2024-10-22 12:25:20.866775238+00:00,10,39,38,A,A,0,236.8,2000,130,202929,47095,233.0,236.8,2000,2000,1,1,,,0,0,0,0,,,0,0,0,0,,,0,0,0,0,,,0,0,0,0,,,0,0,0,0,,,0,0,0,0,,,0,0,0,0,,,0,0,0,0,,,0,0,0,0,AAPL
2024-10-22 12:25:20.883479575+00:00,10,39,38,A,A,0,236.6,2000,130,202989,47096,233.0,236.6,2000,2000,1,1,,236.8,0,2000,0,1,,,0,0,0,0,,,0,0,0,0,,,0,0,0,0,,,0,0,0,0,,,0,0,0,0,,,0,0,0,0,,,0,0,0,0,,,0,0,0,0,AAPL
2024-10-22 12:25:20.883663269+00:00,10,39,38,C,A,1,236.8,2000,130,202766,47097,233.0,236.6,2000,2000,1,1,,,0,0,0,0,,,0,0,0,0,,,0,0,0,0,,,0,0,0,0,,,0,0,0,0,,,0,0,0,0,,,0,0,0,0,,,0,0,0,0,,,0,0,0,0,AAPL
2024-10-22 12:25:20.897259267+00:00,10,39,38,C,A,0,236.6,2000,130,202821,47098,233.0,,2000,0,1,0,,,0,0,0,0,,,0,0,0,0,,,0,0,0,0,,,0,0,0,0,,,0,0,0,0,,,0,0,0,0,,,0,0,0,0,,,0,0,0,0,,,0,0,0,0,AAPL
2024-10-22 12:25:20.914185004+00:00,10,39,38,A,A,0,236.6,2000,130,202867,47099,233.0,236.6,2000,2000,1,1,,,0,0,0,0,,,0,0,0,0,,,0,0,0,0,,,0,0,0,0,,,0,0,0,0,,,0,0,0,0,,,0,0,0,0,,,0,0,0,0,,,0,0,0,0,AAPL
2024-10-22 12:25:20.933974220+00:00,10,39,38,C,A,0,236.6,2000,130,202812,47100,233.0,,2000,0,1,0,,,0,0,0,0,,,0,0,0,0,,,0,0,0,0,,,0,0,0,0,,,0,0,0,0,,,0,0,0,0,,,0,0,0,0,,,0,0,0,0,,,0,0,0,0,AAPL
2024-10-22 12:25:20.952172200+00:00,10,39,38,A,A,0,236.6,2000,130,202820,47101,233.0,236.6,2000,2000,1,1,,,0,0,0,0,,,0,0,0,0,,,0,0,0,0,,,0,0,0,0,,,0,0,0,0,,,0,0,0,0,,,0,0,0,0,,,0,0,0,0,,,0,0,0,0,AAPL
2024-10-22 12:25:24.648633440+00:00,10,40,38,A,B,0,234.94,200,194,203236,74693,234.12,234.94,200,200,0,0,,,0,0,0,0,,,0,0,0,0,,,0,0,0,0,,,0,0,0,0,,,0,0,0,0,,,0,0,0,0,,,0,0,0,0,,,0,0,0,0,,,0,0,0,0,AAPL
2024-10-22 12:25:24.648904698+00:00,10,41,38,A,B,0,234.83,200,194,56146,123410,234.19,234.83,200,200,0,0,,,0,0,0,0,,,0,0,0,0,,,0,0,0,0,,,0,0,0,0,,,0,0,0,0,,,0,0,0,0,,,0,0,0,0,,,0,0,0,0,,,0,0,0,0,AAPL
2024-10-22 12:25:24.750669821+00:00,10,40,38,A,B,0,234.94,200,194,203322,74694,,234.94,0,200,0,0,,,0,0,0,0,,,0,0,0,0,,,0,0,0,0,,,0,0,0,0,,,0,0,0,0,,,0,0,0,0,,,0,0,0,0,,,0,0,0,0,,,0,0,0,0,AAPL
2024-10-22 12:25:24.750820530+00:00,10,41,38,A,B,0,234.83,200,194,55468,123414,,234.83,0,200,0,0,,,0,0,0,0,,,0,0,0,0,,,0,0,0,0,,,0,0,0,0,,,0,0,0,0,,,0,0,0,0,,,0,0,0,0,,,0,0,0,0,,,0,0,0,0,AAPL
2024-10-22 12:25:24.808248604+00:00,10,40,38,A,B,0,234.94,200,194,203235,74695,234.12,234.94,200,200,0,0,,,0,0,0,0,,,0,0,0,0,,,0,0,0,0,,,0,0,0,0,,,0,0,0,0,,,0,0,0,0,,,0,0,0,0,,,0,0,0,0,,,0,0,0,0,AAPL
2024-10-22 12:25:25.306414357+00:00,10,40,38,A,B,0,234.94,200,194,203237,74702,,234.94,0,200,0,0,,,0,0,0,0,,,0,0,0,0,,,0,0,0,0,,,0,0,0,0,,,0,0,0,0,,,0,0,0,0,,,0,0,0,0,,,0,0,0,0,,,0,0,0,0,AAPL
2024-10-22 12:25:31.422946609+00:00,10,40,38,A,B,0,234.94,200,194,203147,74743,234.16,234.94,200,200,0,0,,,0,0,0,0,,,0,0,0,0,,,0,0,0,0,,,0,0,0,0,,,0,0,0,0,,,0,0,0,0,,,0,0,0,0,,,0,0,0,0,,,0,0,0,0,AAPL
2024-10-22 12:25:31.423403342+00:00,10,41,38,A,B,0,234.83,200,194,55470,123613,234.23,234.83,200,200,0,0,,,0,0,0,0,,,0,0,0,0,,,0,0,0,0,,,0,0,0,0,,,0,0,0,0,,,0,0,0,0,,,0,0,0,0,,,0,0,0,0,,,0,0,0,0,AAPL
2024-10-22 12:25:31.526365751+00:00,10,40,38,A,B,0,234.94,200,194,203275,74744,,234.94,0,200,0,0,,,0,0,0,0,,,0,0,0,0,,,0,0,0,0,,,0,0,0,0,,,0,0,0,0,,,0,0,0,0,,,0,0,0,0,,,0,0,0,0,,,0,0,0,0,AAPL
2024-10-22 12:25:31.526910691+00:00,10,41,38,A,B,0,234.83,200,194,56803,123618,,234.83,0,200,0,0,,,0,0,0,0,,,0,0,0,0,,,0,0,0,0,,,0,0,0,0,,,0,0,0,0,,,0,0,0,0,,,0,0,0,0,,,0,0,0,0,,,0,0,0,0,AAPL
2024-10-22 12:25:35.608826091+00:00,10,40,38,A,B,0,234.94,200,194,203322,74781,234.15,234.94,200,200,0,0,,,0,0,0,0,,,0,0,0,0,,,0,0,0,0,,,0,0,0,0,,,0,0,0,0,,,0,0,0,0,,,0,0,0,0,,,0,0,0,0,,,0,0,0,0,AAPL
2024-10-22 12:25:35.609329554+00:00,10,41,38,A,B,0,234.83,200,194,55499,123724,234.22,234.83,200,200,0,0,,,0,0,0,0,,,0,0,0,0,,,0,0,0,0,,,0,0,0,0,,,0,0,0,0,,,0,0,0,0,,,0,0,0,0,,,0,0,0,0,,,0,0,0,0,AAPL
2024-10-22 12:25:35.676685867+00:00,10,40,38,A,B,0,234.94,200,194,203068,74782,,234.94,0,200,0,0,,,0,0,0,0,,,0,0,0,0,,,0,0,0,0,,,0,0,0,0,,,0,0,0,0,,,0,0,0,0,,,0,0,0,0,,,0,0,0,0,,,0,0,0,0,AAPL
2024-10-22 12:25:35.676922939+00:00,10,41,38,A,B,0,234.83,200,194,61209,123725,,234.83,0,200,0,0,,,0,0,0,0,,,0,0,0,0,,,0,0,0,0,,,0,0,0,0,,,0,0,0,0,,,0,0,0,0,,,0,0,0,0,,,0,0,0,0,,,0,0,0,0,AAPL
2024-10-22 12:25:40.968453569+00:00,10,40,38,A,B,0,234.94,200,194,202886,74834,234.15,234.94,200,200,0,0,,,0,0,0,0,,,0,0,0,0,,,0,0,0,0,,,0,0,0,0,,,0,0,0,0,,,0,0,0,0,,,0,0,0,0,,,0,0,0,0,,,0,0,0,0,AAPL
2024-10-22 12:25:49.117000590+00:00,10,39,38,C,B,0,233.0,2000,130,203502,47289,,236.6,0,2000,0,1,,,0,0,0,0,,,0,0,0,0,,,0,0,0,0,,,0,0,0,0,,,0,0,0,0,,,0,0,0,0,,,0,0,0,0,,,0,0,0,0,,,0,0,0,0,AAPL
2024-10-22 12:25:49.128617714+00:00,10,39,38,A,B,0,232.8,2000,130,203532,47290,232.8,236.6,2000,2000,1,1,,,0,0,0,0,,,0,0,0,0,,,0,0,0,0,,,0,0,0,0,,,0,0,0,0,,,0,0,0,0,,,0,0,0,0,,,0,0,0,0,,,0,0,0,0,AAPL
2024-10-22 12:25:53.312586312+00:00,10,39,38,A,B,0,233.4,2000,130,203465,47315,233.4,236.6,2000,2000,1,1,232.8,,2000,0,1,0,,,0,0,0,0,,,0,0,0,0,,,0,0,0,0,,,0,0,0,0,,,0,0,0,0,,,0,0,0,0,,,0,0,0,0,,,0,0,0,0,AAPL
2024-10-22 12:25:53.312770921+00:00,10,39,38,C,B,1,232.8,2000,130,203337,47316,233.4,236.6,2000,2000,1,1,,,0,0,0,0,,,0,0,0,0,,,0,0,0,0,,,0,0,0,0,,,0,0,0,0,,,0,0,0,0,,,0,0,0,0,,,0,0,0,0,,,0,0,0,0,AAPL
2024-10-22 12:25:53.689370922+00:00,10,41,38,A,B,0,234.83,200,194,56116,124111,234.21,234.83,200,200,0,0,,,0,0,0,0,,,0,0,0,0,,,0,0,0,0,,,0,0,0,0,,,0,0,0,0,,,0,0,0,0,,,0,0,0,0,,,0,0,0,0,,,0,0,0,0,AAPL
2024-10-22 12:25:53.721717844+00:00,10,39,38,C,A,0,236.6,2000,130,203741,47317,233.4,,2000,0,1,0,,,0,0,0,0,,,0,0,0,0,,,0,0,0,0,,,0,0,0,0,,,0,0,0,0,,,0,0,0,0,,,0,0,0,0,,,0,0,0,0,,,0,0,0,0,AAPL
2024-10-22 12:25:53.758596707+00:00,10,40,38,A,B,0,234.94,200,194,202826,74967,,234.94,0,200,0,0,,,0,0,0,0,,,0,0,0,0,,,0,0,0,0,,,0,0,0,0,,,0,0,0,0,,,0,0,0,0,,,0,0,0,0,,,0,0,0,0,,,0,0,0,0,AAPL
2024-10-22 12:25:53.758620776+00:00,10,40,38,A,B,0,234.94,200,194,202744,74968,234.12,234.94,200,200,0,0,,,0,0,0,0,,,0,0,0,0,,,0,0,0,0,,,0,0,0,0,,,0,0,0,0,,,0,0,0,0,,,0,0,0,0,,,0,0,0,0,,,0,0,0,0,AAPL
2024-10-22 12:25:53.792113543+00:00,10,41,38,A,B,0,234.83,200,194,55773,124119,,234.83,0,200,0,0,,,0,0,0,0,,,0,0,0,0,,,0,0,0,0,,,0,0,0,0,,,0,0,0,0,,,0,0,0,0,,,0,0,0,0,,,0,0,0,0,,,0,0,0,0,AAPL
2024-10-22 12:25:54.039916093+00:00,10,39,38,A,A,0,236.6,2000,130,203522,47322,233.4,236.6,2000,2000,1,1,,,0,0,0,0,,,0,0,0,0,,,0,0,0,0,,,0,0,0,0,,,0,0,0,0,,,0,0,0,0,,,0,0,0,0,,,0,0,0,0,,,0,0,0,0,AAPL
2024-10-22 12:25:54.563630880+00:00,10,39,38,C,A,0,236.6,2000,130,203561,47324,233.4,,2000,0,1,0,,,0,0,0,0,,,0,0,0,0,,,0,0,0,0,,,0,0,0,0,,,0,0,0,0,,,0,0,0,0,,,0,0,0,0,,,0,0,0,0,,,0,0,0,0,AAPL
2024-10-22 12:25:54.574348485+00:00,10,39,38,A,A,0,236.8,2000,130,203331,47325,233.4,236.8,2000,2000,1,1,,,0,0,0,0,,,0,0,0,0,,,0,0,0,0,,,0,0,0,0,,,0,0,0,0,,,0,0,0,0,,,0,0,0,0,,,0,0,0,0,,,0,0,0,0,AAPL
2024-10-22 12:25:59.456158140+00:00,10,40,38,A,B,0,234.94,200,194,202974,75014,,234.94,0,200,0,0,,,0,0,0,0,,,0,0,0,0,,,0,0,0,0,,,0,0,0,0,,,0,0,0,0,,,0,0,0,0,,,0,0,0,0,,,0,0,0,0,,,0,0,0,0,AAPL
2024-10-22 12:25:59.986080525+00:00,10,40,38,A,B,0,234.94,200,194,202975,75020,234.12,234.94,200,200,0,0,,,0,0,0,0,,,0,0,0,0,,,0,0,0,0,,,0,0,0,0,,,0,0,0,0,,,0,0,0,0,,,0,0,0,0,,,0,0,0,0,,,0,0,0,0,AAPL
2024-10-22 12:26:00.120575008+00:00,10,40,38,A,B,0,234.94,200,194,202891,75062,,234.94,0,200,0,0,,,0,0,0,0,,,0,0,0,0,,,0,0,0,0,,,0,0,0,0,,,0,0,0,0,,,0,0,0,0,,,0,0,0,0,,,0,0,0,0,,,0,0,0,0,AAPL
2024-10-22 12:26:00.394708463+00:00,10,40,38,A,B,0,234.94,200,194,202928,75087,234.12,234.94,200,200,0,0,,,0,0,0,0,,,0,0,0,0,,,0,0,0,0,,,0,0,0,0,,,0,0,0,0,,,0,0,0,0,,,0,0,0,0,,,0,0,0,0,,,0,0,0,0,AAPL
2024-10-22 12:26:01.587162224+00:00,10,40,38,A,B,0,234.94,200,194,202927,75104,,234.94,0,200,0,0,,,0,0,0,0,,,0,0,0,0,,,0,0,0,0,,,0,0,0,0,,,0,0,0,0,,,0,0,0,0,,,0,0,0,0,,,0,0,0,0,,,0,0,0,0,AAPL
2024-10-22 12:26:02.104569965+00:00,10,39,38,A,A,0,236.6,2000,130,203843,47366,233.4,236.6,2000,2000,1,1,,236.8,0,2000,0,1,,,0,0,0,0,,,0,0,0,0,,,0,0,0,0,,,0,0,0,0,,,0,0,0,0,,,0,0,0,0,,,0,0,0,0,,,0,0,0,0,AAPL
2024-10-22 12:26:02.105300223+00:00,10,39,38,C,A,1,236.8,2000,130,203581,47367,233.4,236.6,2000,2000,1,1,,,0,0,0,0,,,0,0,0,0,,,0,0,0,0,,,0,0,0,0,,,0,0,0,0,,,0,0,0,0,,,0,0,0,0,,,0,0,0,0,,,0,0,0,0,AAPL
2024-10-22 12:26:05.770632108+00:00,10,40,38,A,B,0,234.94,200,194,203219,75138,234.12,234.94,200,200,0,0,,,0,0,0,0,,,0,0,0,0,,,0,0,0,0,,,0,0,0,0,,,0,0,0,0,,,0,0,0,0,,,0,0,0,0,,,0,0,0,0,,,0,0,0,0,AAPL
2024-10-22 12:26:05.823219521+00:00,10,39,38,C,A,0,236.6,2000,130,204114,47378,233.4,,2000,0,1,0,,,0,0,0,0,,,0,0,0,0,,,0,0,0,0,,,0,0,0,0,,,0,0,0,0,,,0,0,0,0,,,0,0,0,0,,,0,0,0,0,,,0,0,0,0,AAPL
2024-10-22 12:26:05.833955028+00:00,10,39,38,A,A,0,236.8,2000,130,203713,47379,233.4,236.8,2000,2000,1,1,,,0,0,0,0,,,0,0,0,0,,,0,0,0,0,,,0,0,0,0,,,0,0,0,0,,,0,0,0,0,,,0,0,0,0,,,0,0,0,0,,,0,0,0,0,AAPL
2024-10-22 12:26:05.850526893+00:00,10,39,38,C,A,0,236.8,2000,130,203661,47380,233.4,,2000,0,1,0,,,0,0,0,0,,,0,0,0,0,,,0,0,0,0,,,0,0,0,0,,,0,0,0,0,,,0,0,0,0,,,0,0,0,0,,,0,0,0,0,,,0,0,0,0,AAPL
2024-10-22 12:26:06.139592942+00:00,10,39,38,A,A,0,236.8,2000,130,203666,47384,233.4,236.8,2000,2000,1,1,,,0,0,0,0,,,0,0,0,0,,,0,0,0,0,,,0,0,0,0,,,0,0,0,0,,,0,0,0,0,,,0,0,0,0,,,0,0,0,0,,,0,0,0,0,AAPL
2024-10-22 12:26:06.701747802+00:00,10,40,38,A,B,0,234.94,200,194,203851,75140,,234.94,0,200,0,0,,,0,0,0,0,,,0,0,0,0,,,0,0,0,0,,,0,0,0,0,,,0,0,0,0,,,0,0,0,0,,,0,0,0,0,,,0,0,0,0,,,0,0,0,0,AAPL
2024-10-22 12:26:06.713138062+00:00,10,39,38,A,B,0,233.6,2000,130,204090,47390,233.6,236.8,2000,2000,1,1,233.4,,2000,0,1,0,,,0,0,0,0,,,0,0,0,0,,,0,0,0,0,,,0,0,0,0,,,0,0,0,0,,,0,0,0,0,,,0,0,0,0,,,0,0,0,0,AAPL
2024-10-22 12:26:06.713324553+00:00,10,39,38,C,B,1,233.4,2000,130,203767,47391,233.6,236.8,2000,2000,1,1,,,0,0,0,0,,,0,0,0,0,,,0,0,0,0,,,0,0,0,0,,,0,0,0,0,,,0,0,0,0,,,0,0,0,0,,,0,0,0,0,,,0,0,0,0,AAPL
2024-10-22 12:26:07.422602794+00:00,10,40,38,A,B,0,234.94,200,194,203758,75143,234.12,234.94,200,200,0,0,,,0,0,0,0,,,0,0,0,0,,,0,0,0,0,,,0,0,0,0,,,0,0,0,0,,,0,0,0,0,,,0,0,0,0,,,0,0,0,0,,,0,0,0,0,AAPL
2024-10-22 12:26:07.423097011+00:00,10,41,38,A,B,0,234.83,200,194,62820,124908,234.19,234.83,200,200,0,0,,,0,0,0,0,,,0,0,0,0,,,0,0,0,0,,,0,0,0,0,,,0,0,0,0,,,0,0,0,0,,,0,0,0,0,,,0,0,0,0,,,0,0,0,0,AAPL
2024-10-22 12:26:07.523484502+00:00,10,40,38,A,B,0,234.94,200,194,203118,75144,,234.94,0,200,0,0,,,0,0,0,0,,,0,0,0,0,,,0,0,0,0,,,0,0,0,0,,,0,0,0,0,,,0,0,0,0,,,0,0,0,0,,,0,0,0,0,,,0,0,0,0,AAPL
2024-10-22 12:26:07.523868413+00:00,10,41,38,A,B,0,234.83,200,194,55919,124910,,234.83,0,200,0,0,,,0,0,0,0,,,0,0,0,0,,,0,0,0,0,,,0,0,0,0,,,0,0,0,0,,,0,0,0,0,,,0,0,0,0,,,0,0,0,0,,,0,0,0,0,AAPL
2024-10-22 12:26:13.494704540+00:00,10,40,38,A,B,0,234.94,200,194,203355,75174,234.12,234.94,200,200,0,0,,,0,0,0,0,,,0,0,0,0,,,0,0,0,0,,,0,0,0,0,,,0,0,0,0,,,0,0,0,0,,,0,0,0,0,,,0,0,0,0,,,0,0,0,0,AAPL
2024-10-22 12:26:13.494983346+00:00,10,41,38,A,B,0,234.83,200,194,55635,125097,234.19,234.83,200,200,0,0,,,0,0,0,0,,,0,0,0,0,,,0,0,0,0,,,0,0,0,0,,,0,0,0,0,,,0,0,0,0,,,0,0,0,0,,,0,0,0,0,,,0,0,0,0,AAPL
2024-10-22 12:26:13.503404290+00:00,10,41,38,A,B,0,234.83,200,194,55152,125098,,234.83,0,200,0,0,,,0,0,0,0,,,0,0,0,0,,,0,0,0,0,,,0,0,0,0,,,0,0,0,0,,,0,0,0,0,,,0,0,0,0,,,0,0,0,0,,,0,0,0,0,AAPL
2024-10-22 12:26:13.503741451+00:00,10,40,38,A,B,0,234.94,200,194,203143,75175,,234.94,0,200,0,0,,,0,0,0,0,,,0,0,0,0,,,0,0,0,0,,,0,0,0,0,,,0,0,0,0,,,0,0,0,0,,,0,0,0,0,,,0,0,0,0,,,0,0,0,0,AAPL
2024-10-22 12:26:14.779089862+00:00,10,40,38,A,B,0,234.94,200,194,203682,75185,234.12,234.94,200,200,0,0,,,0,0,0,0,,,0,0,0,0,,,0,0,0,0,,,0,0,0,0,,,0,0,0,0,,,0,0,0,0,,,0,0,0,0,,,0,0,0,0,,,0,0,0,0,AAPL
2024-10-22 12:26:14.876364422+00:00,10,40,38,A,B,0,234.94,200,194,203398,75186,,234.94,0,200,0,0,,,0,0,0,0,,,0,0,0,0,,,0,0,0,0,,,0,0,0,0,,,0,0,0,0,,,0,0,0,0,,,0,0,0,0,,,0,0,0,0,,,0,0,0,0,AAPL
2024-10-22 12:26:20.366364233+00:00,10,40,38,A,B,0,234.94,200,194,203608,75225,234.16,234.94,200,200,0,0,,,0,0,0,0,,,0,0,0,0,,,0,0,0,0,,,0,0,0,0,,,0,0,0,0,,,0,0,0,0,,,0,0,0,0,,,0,0,0,0,,,0,0,0,0,AAPL
2024-10-22 12:26:20.468145791+00:00,10,40,38,A,B,0,234.94,200,194,203510,75227,,234.94,0,200,0,0,,,0,0,0,0,,,0,0,0,0,,,0,0,0,0,,,0,0,0,0,,,0,0,0,0,,,0,0,0,0,,,0,0,0,0,,,0,0,0,0,,,0,0,0,0,AAPL
2024-10-22 12:26:45.503283273+00:00,10,40,38,A,B,0,234.94,200,194,204131,75353,234.16,234.94,200,200,0,0,,,0,0,0,0,,,0,0,0,0,,,0,0,0,0,,,0,0,0,0,,,0,0,0,0,,,0,0,0,0,,,0,0,0,0,,,0,0,0,0,,,0,0,0,0,AAPL
2024-10-22 12:26:45.603785954+00:00,10,40,38,A,B,0,234.94,200,194,204043,75354,,234.94,0,200,0,0,,,0,0,0,0,,,0,0,0,0,,,0,0,0,0,,,0,0,0,0,,,0,0,0,0,,,0,0,0,0,,,0,0,0,0,,,0,0,0,0,,,0,0,0,0,AAPL
2024-10-22 12:26:46.247495623+00:00,10,40,38,A,B,0,234.94,200,194,203904,75361,234.16,234.94,200,200,0,0,,,0,0,0,0,,,0,0,0,0,,,0,0,0,0,,,0,0,0,0,,,0,0,0,0,,,0,0,0,0,,,0,0,0,0,,,0,0,0,0,,,0,0,0,0,AAPL
2024-10-22 12:26:46.300437874+00:00,10,40,38,A,B,0,234.94,200,194,203944,75362,,234.94,0,200,0,0,,,0,0,0,0,,,0,0,0,0,,,0,0,0,0,,,0,0,0,0,,,0,0,0,0,,,0,0,0,0,,,0,0,0,0,,,0,0,0,0,,,0,0,0,0,AAPL
2024-10-22 12:26:46.429257244+00:00,10,40,38,A,B,0,234.94,200,194,203941,75364,234.16,234.94,200,200,0,0,,,0,0,0,0,,,0,0,0,0,,,0,0,0,0,,,0,0,0,0,,,0,0,0,0,,,0,0,0,0,,,0,0,0,0,,,0,0,0,0,,,0,0,0,0,AAPL
2024-10-22 12:26:46.510678911+00:00,10,40,38,A,B,0,234.94,200,194,203969,75365,,234.94,0,200,0,0,,,0,0,0,0,,,0,0,0,0,,,0,0,0,0,,,0,0,0,0,,,0,0,0,0,,,0,0,0,0,,,0,0,0,0,,,0,0,0,0,,,0,0,0,0,AAPL
2024-10-22 12:26:46.736791215+00:00,10,40,38,A,B,0,234.94,200,194,204014,75366,234.16,234.94,200,200,0,0,,,0,0,0,0,,,0,0,0,0,,,0,0,0,0,,,0,0,0,0,,,0,0,0,0,,,0,0,0,0,,,0,0,0,0,,,0,0,0,0,,,0,0,0,0,AAPL
2024-10-22 12:26:46.839882675+00:00,10,40,38,A,B,0,234.94,200,194,203936,75367,,234.94,0,200,0,0,,,0,0,0,0,,,0,0,0,0,,,0,0,0,0,,,0,0,0,0,,,0,0,0,0,,,0,0,0,0,,,0,0,0,0,,,0,0,0,0,,,0,0,0,0,AAPL
2024-10-22 12:26:52.861139860+00:00,10,40,38,A,B,0,234.94,200,194,203850,75390,234.19,234.94,200,200,0,0,,,0,0,0,0,,,0,0,0,0,,,0,0,0,0,,,0,0,0,0,,,0,0,0,0,,,0,0,0,0,,,0,0,0,0,,,0,0,0,0,,,0,0,0,0,AAPL
2024-10-22 12:26:56.253862955+00:00,10,40,38,A,B,0,234.94,200,194,204144,75402,,234.94,0,200,0,0,,,0,0,0,0,,,0,0,0,0,,,0,0,0,0,,,0,0,0,0,,,0,0,0,0,,,0,0,0,0,,,0,0,0,0,,,0,0,0,0,,,0,0,0,0,AAPL
2024-10-22 12:26:56.253891157+00:00,10,40,38,A,B,0,234.94,200,194,203916,75403,234.17,234.94,200,200,0,0,,,0,0,0,0,,,0,0,0,0,,,0,0,0,0,,,0,0,0,0,,,0,0,0,0,,,0,0,0,0,,,0,0,0,0,,,0,0,0,0,,,0,0,0,0,AAPL
2024-10-22 12:26:56.253932580+00:00,10,40,38,A,B,0,234.94,200,194,203889,75404,,234.94,0,200,0,0,,,0,0,0,0,,,0,0,0,0,,,0,0,0,0,,,0,0,0,0,,,0,0,0,0,,,0,0,0,0,,,0,0,0,0,,,0,0,0,0,,,0,0,0,0,AAPL
2024-10-22 12:26:56.408059701+00:00,10,39,38,C,B,0,233.6,2000,130,204098,47571,,236.8,0,2000,0,1,,,0,0,0,0,,,0,0,0,0,,,0,0,0,0,,,0,0,0,0,,,0,0,0,0,,,0,0,0,0,,,0,0,0,0,,,0,0,0,0,,,0,0,0,0,AAPL
2024-10-22 12:26:56.419285823+00:00,10,39,38,A,B,0,233.4,2000,130,203696,47572,233.4,236.8,2000,2000,1,1,,,0,0,0,0,,,0,0,0,0,,,0,0,0,0,,,0,0,0,0,,,0,0,0,0,,,0,0,0,0,,,0,0,0,0,,,0,0,0,0,,,0,0,0,0,AAPL
2024-10-22 12:26:56.486332145+00:00,10,40,38,A,B,0,234.94,200,194,203884,75405,234.17,234.94,200,200,0,0,,,0,0,0,0,,,0,0,0,0,,,0,0,0,0,,,0,0,0,0,,,0,0,0,0,,,0,0,0,0,,,0,0,0,0,,,0,0,0,0,,,0,0,0,0,AAPL
2024-10-22 12:26:56.586353404+00:00,10,40,38,A,B,0,234.94,200,194,203820,75406,,234.94,0,200,0,0,,,0,0,0,0,,,0,0,0,0,,,0,0,0,0,,,0,0,0,0,,,0,0,0,0,,,0,0,0,0,,,0,0,0,0,,,0,0,0,0,,,0,0,0,0,AAPL
2024-10-22 12:26:58.621919227+00:00,10,40,38,A,B,0,234.94,200,194,203649,75423,234.17,234.94,200,200,0,0,,,0,0,0,0,,,0,0,0,0,,,0,0,0,0,,,0,0,0,0,,,0,0,0,0,,,0,0,0,0,,,0,0,0,0,,,0,0,0,0,,,0,0,0,0,AAPL
2024-10-22 12:26:58.659524218+00:00,10,40,38,A,B,0,234.94,200,194,203649,75424,,234.94,0,200,0,0,,,0,0,0,0,,,0,0,0,0,,,0,0,0,0,,,0,0,0,0,,,0,0,0,0,,,0,0,0,0,,,0,0,0,0,,,0,0,0,0,,,0,0,0,0,AAPL
2024-10-22 12:26:59.680460154+00:00,10,40,38,A,B,0,234.94,200,194,203674,75436,234.17,234.94,200,200,0,0,,,0,0,0,0,,,0,0,0,0,,,0,0,0,0,,,0,0,0,0,,,0,0,0,0,,,0,0,0,0,,,0,0,0,0,,,0,0,0,0,,,0,0,0,0,AAPL
2024-10-22 12:26:59.784073201+00:00,10,40,38,A,B,0,234.94,200,194,203863,75437,,234.94,0,200,0,0,,,0,0,0,0,,,0,0,0,0,,,0,0,0,0,,,0,0,0,0,,,0,0,0,0,,,0,0,0,0,,,0,0,0,0,,,0,0,0,0,,,0,0,0,0,AAPL
2024-10-22 12:27:11.698112886+00:00,10,39,38,A,B,0,233.6,2000,130,203998,47628,233.6,236.8,2000,2000,1,1,233.4,,2000,0,1,0,,,0,0,0,0,,,0,0,0,0,,,0,0,0,0,,,0,0,0,0,,,0,0,0,0,,,0,0,0,0,,,0,0,0,0,,,0,0,0,0,AAPL
2024-10-22 12:27:11.698305225+00:00,10,39,38,C,B,1,233.4,2000,130,203498,47629,233.6,236.8,2000,2000,1,1,,,0,0,0,0,,,0,0,0,0,,,0,0,0,0,,,0,0,0,0,,,0,0,0,0,,,0,0,0,0,,,0,0,0,0,,,0,0,0,0,,,0,0,0,0,AAPL
2024-10-22 12:27:30.080108063+00:00,10,40,38,A,B,0,234.94,200,194,203474,75758,234.17,234.94,200,200,0,0,,,0,0,0,0,,,0,0,0,0,,,0,0,0,0,,,0,0,0,0,,,0,0,0,0,,,0,0,0,0,,,0,0,0,0,,,0,0,0,0,,,0,0,0,0,AAPL
2024-10-22 12:27:30.080301390+00:00,10,41,38,A,B,0,234.83,200,194,55385,127005,234.23,234.83,200,200,0,0,,,0,0,0,0,,,0,0,0,0,,,0,0,0,0,,,0,0,0,0,,,0,0,0,0,,,0,0,0,0,,,0,0,0,0,,,0,0,0,0,,,0,0,0,0,AAPL
2024-10-22 12:27:32.031857147+00:00,10,41,10888,T,N,0,419.17,34,194,61961,127056,,,0,0,0,0,,,0,0,0,0,,,0,0,0,0,,,0,0,0,0,,,0,0,0,0,,,0,0,0,0,,,0,0,0,0,,,0,0,0,0,,,0,0,0,0,,,0,0,0,0,MSFT
2024-10-22 12:27:37.410432761+00:00,10,41,38,A,A,0,,0,194,56161,127114,234.23,,200,0,0,0,,,0,0,0,0,,,0,0,0,0,,,0,0,0,0,,,0,0,0,0,,,0,0,0,0,,,0,0,0,0,,,0,0,0,0,,,0,0,0,0,,,0,0,0,0,AAPL
2024-10-22 12:27:37.410520380+00:00,10,41,38,A,A,0,234.92,200,194,54664,127115,234.23,234.92,200,200,0,0,,,0,0,0,0,,,0,0,0,0,,,0,0,0,0,,,0,0,0,0,,,0,0,0,0,,,0,0,0,0,,,0,0,0,0,,,0,0,0,0,,,0,0,0,0,AAPL
2024-10-22 12:27:40.725414143+00:00,10,41,38,A,B,0,234.92,200,194,61259,127160,,234.92,0,200,0,0,,,0,0,0,0,,,0,0,0,0,,,0,0,0,0,,,0,0,0,0,,,0,0,0,0,,,0,0,0,0,,,0,0,0,0,,,0,0,0,0,,,0,0,0,0,AAPL
2024-10-22 12:27:40.826113718+00:00,10,41,38,A,B,0,234.92,200,194,55758,127163,234.23,234.92,200,200,0,0,,,0,0,0,0,,,0,0,0,0,,,0,0,0,0,,,0,0,0,0,,,0,0,0,0,,,0,0,0,0,,,0,0,0,0,,,0,0,0,0,,,0,0,0,0,AAPL
2024-10-22 12:27:43.746583873+00:00,10,40,38,A,B,0,234.94,200,194,203360,75829,,234.94,0,200,0,0,,,0,0,0,0,,,0,0,0,0,,,0,0,0,0,,,0,0,0,0,,,0,0,0,0,,,0,0,0,0,,,0,0,0,0,,,0,0,0,0,,,0,0,0,0,AAPL
2024-10-22 12:27:43.851842138+00:00,10,40,38,A,B,0,234.94,200,194,203009,75830,234.17,234.94,200,200,0,0,,,0,0,0,0,,,0,0,0,0,,,0,0,0,0,,,0,0,0,0,,,0,0,0,0,,,0,0,0,0,,,0,0,0,0,,,0,0,0,0,,,0,0,0,0,AAPL
2024-10-22 12:28:00.096749669+00:00,10,40,38,A,B,0,234.94,200,194,203212,76020,,234.94,0,200,0,0,,,0,0,0,0,,,0,0,0,0,,,0,0,0,0,,,0,0,0,0,,,0,0,0,0,,,0,0,0,0,,,0,0,0,0,,,0,0,0,0,,,0,0,0,0,AAPL
2024-10-22 12:28:00.096905694+00:00,10,41,38,A,B,0,234.92,200,194,58130,128198,,234.92,0,200,0,0,,,0,0,0,0,,,0,0,0,0,,,0,0,0,0,,,0,0,0,0,,,0,0,0,0,,,0,0,0,0,,,0,0,0,0,,,0,0,0,0,,,0,0,0,0,AAPL
2024-10-22 12:28:00.216278063+00:00,10,40,38,A,B,0,234.94,200,194,203204,76039,234.18,234.94,200,200,0,0,,,0,0,0,0,,,0,0,0,0,,,0,0,0,0,,,0,0,0,0,,,0,0,0,0,,,0,0,0,0,,,0,0,0,0,,,0,0,0,0,,,0,0,0,0,AAPL
2024-10-22 12:28:00.418115539+00:00,10,41,38,A,B,0,234.92,200,194,55161,128365,234.24,234.92,200,200,0,0,,,0,0,0,0,,,0,0,0,0,,,0,0,0,0,,,0,0,0,0,,,0,0,0,0,,,0,0,0,0,,,0,0,0,0,,,0,0,0,0,,,0,0,0,0,AAPL
2024-10-22 12:28:00.543674779+00:00,10,39,38,C,B,0,233.6,2000,130,203579,47817,,236.8,0,2000,0,1,,,0,0,0,0,,,0,0,0,0,,,0,0,0,0,,,0,0,0,0,,,0,0,0,0,,,0,0,0,0,,,0,0,0,0,,,0,0,0,0,,,0,0,0,0,AAPL
2024-10-22 12:28:00.562299357+00:00,10,39,38,A,A,0,236.6,2000,130,203622,47819,,236.6,0,2000,0,1,,236.8,0,2000,0,1,,,0,0,0,0,,,0,0,0,0,,,0,0,0,0,,,0,0,0,0,,,0,0,0,0,,,0,0,0,0,,,0,0,0,0,,,0,0,0,0,AAPL
2024-10-22 12:28:00.562493614+00:00,10,39,38,C,A,1,236.8,2000,130,203569,47820,,236.6,0,2000,0,1,,,0,0,0,0,,,0,0,0,0,,,0,0,0,0,,,0,0,0,0,,,0,0,0,0,,,0,0,0,0,,,0,0,0,0,,,0,0,0,0,,,0,0,0,0,AAPL
2024-10-22 12:28:00.605547752+00:00,10,39,38,A,B,0,233.4,2000,130,203509,47825,233.4,236.6,2000,2000,1,1,,,0,0,0,0,,,0,0,0,0,,,0,0,0,0,,,0,0,0,0,,,0,0,0,0,,,0,0,0,0,,,0,0,0,0,,,0,0,0,0,,,0,0,0,0,AAPL
2024-10-22 12:28:11.689329779+00:00,10,39,38,A,B,0,233.6,2000,130,203880,47886,233.6,236.6,2000,2000,1,1,233.4,,2000,0,1,0,,,0,0,0,0,,,0,0,0,0,,,0,0,0,0,,,0,0,0,0,,,0,0,0,0,,,0,0,0,0,,,0,0,0,0,,,0,0,0,0,AAPL
2024-10-22 12:28:11.689516107+00:00,10,39,38,C,B,1,233.4,2000,130,203318,47887,233.6,236.6,2000,2000,1,1,,,0,0,0,0,,,0,0,0,0,,,0,0,0,0,,,0,0,0,0,,,0,0,0,0,,,0,0,0,0,,,0,0,0,0,,,0,0,0,0,,,0,0,0,0,AAPL
2024-10-22 12:28:22.346524931+00:00,10,39,38,C,B,0,233.6,2000,130,203458,47907,,236.6,0,2000,0,1,,,0,0,0,0,,,0,0,0,0,,,0,0,0,0,,,0,0,0,0,,,0,0,0,0,,,0,0,0,0,,,0,0,0,0,,,0,0,0,0,,,0,0,0,0,AAPL
2024-10-22 12:28:22.357562309+00:00,10,39,38,A,B,0,233.4,2000,130,203144,47908,233.4,236.6,2000,2000,1,1,,,0,0,0,0,,,0,0,0,0,,,0,0,0,0,,,0,0,0,0,,,0,0,0,0,,,0,0,0,0,,,0,0,0,0,,,0,0,0,0,,,0,0,0,0,AAPL
2024-10-22 12:28:22.374798881+00:00,10,39,38,A,B,0,233.6,2000,130,203141,47909,233.6,236.6,2000,2000,1,1,233.4,,2000,0,1,0,,,0,0,0,0,,,0,0,0,0,,,0,0,0,0,,,0,0,0,0,,,0,0,0,0,,,0,0,0,0,,,0,0,0,0,,,0,0,0,0,AAPL
2024-10-22 12:28:22.375513531+00:00,10,39,38,C,B,1,233.4,2000,130,203149,47910,233.6,236.6,2000,2000,1,1,,,0,0,0,0,,,0,0,0,0,,,0,0,0,0,,,0,0,0,0,,,0,0,0,0,,,0,0,0,0,,,0,0,0,0,,,0,0,0,0,,,0,0,0,0,AAPL
2024-10-22 12:28:22.381311371+00:00,10,39,38,C,B,0,233.6,2000,130,203050,47911,,236.6,0,2000,0,1,,,0,0,0,0,,,0,0,0,0,,,0,0,0,0,,,0,0,0,0,,,0,0,0,0,,,0,0,0,0,,,0,0,0,0,,,0,0,0,0,,,0,0,0,0,AAPL
2024-10-22 12:28:22.392646658+00:00,10,39,38,A,B,0,233.4,2000,130,203018,47912,233.4,236.6,2000,2000,1,1,,,0,0,0,0,,,0,0,0,0,,,0,0,0,0,,,0,0,0,0,,,0,0,0,0,,,0,0,0,0,,,0,0,0,0,,,0,0,0,0,,,0,0,0,0,AAPL
2024-10-22 12:28:22.403860559+00:00,10,39,38,A,B,0,233.6,2000,130,203112,47913,233.6,236.6,2000,2000,1,1,233.4,,2000,0,1,0,,,0,0,0,0,,,0,0,0,0,,,0,0,0,0,,,0,0,0,0,,,0,0,0,0,,,0,0,0,0,,,0,0,0,0,,,0,0,0,0,AAPL
2024-10-22 12:28:22.404433580+00:00,10,39,38,C,B,1,233.4,2000,130,202976,47914,233.6,236.6,2000,2000,1,1,,,0,0,0,0,,,0,0,0,0,,,0,0,0,0,,,0,0,0,0,,,0,0,0,0,,,0,0,0,0,,,0,0,0,0,,,0,0,0,0,,,0,0,0,0,AAPL
2024-10-22 12:28:22.416237344+00:00,10,39,38,C,B,0,233.6,2000,130,202992,47915,,236.6,0,2000,0,1,,,0,0,0,0,,,0,0,0,0,,,0,0,0,0,,,0,0,0,0,,,0,0,0,0,,,0,0,0,0,,,0,0,0,0,,,0,0,0,0,,,0,0,0,0,AAPL
2024-10-22 12:28:22.431305229+00:00,10,39,38,A,B,0,233.6,2000,130,203211,47916,233.6,236.6,2000,2000,1,1,,,0,0,0,0,,,0,0,0,0,,,0,0,0,0,,,0,0,0,0,,,0,0,0,0,,,0,0,0,0,,,0,0,0,0,,,0,0,0,0,,,0,0,0,0,AAPL
2024-10-22 12:28:24.351031345+00:00,10,39,38,C,A,0,236.6,2000,130,203092,47925,233.6,,2000,0,1,0,,,0,0,0,0,,,0,0,0,0,,,0,0,0,0,,,0,0,0,0,,,0,0,0,0,,,0,0,0,0,,,0,0,0,0,,,0,0,0,0,,,0,0,0,0,AAPL
2024-10-22 12:28:24.388100153+00:00,10,39,38,A,A,0,236.6,2000,130,203244,47926,233.6,236.6,2000,2000,1,1,,,0,0,0,0,,,0,0,0,0,,,0,0,0,0,,,0,0,0,0,,,0,0,0,0,,,0,0,0,0,,,0,0,0,0,,,0,0,0,0,,,0,0,0,0,AAPL
2024-10-22 12:28:24.411232597+00:00,10,39,38,C,B,0,233.6,2000,130,203143,47927,,236.6,0,2000,0,1,,,0,0,0,0,,,0,0,0,0,,,0,0,0,0,,,0,0,0,0,,,0,0,0,0,,,0,0,0,0,,,0,0,0,0,,,0,0,0,0,,,0,0,0,0,AAPL
2024-10-22 12:28:24.434191936+00:00,10,39,38,A,B,0,233.4,2000,130,203229,47928,233.4,236.6,2000,2000,1,1,,,0,0,0,0,,,0,0,0,0,,,0,0,0,0,,,0,0,0,0,,,0,0,0,0,,,0,0,0,0,,,0,0,0,0,,,0,0,0,0,,,0,0,0,0,AAPL
2024-10-22 12:28:42.564667709+00:00,10,39,38,C,A,0,236.6,2000,130,203044,48007,233.4,,2000,0,1,0,,,0,0,0,0,,,0,0,0,0,,,0,0,0,0,,,0,0,0,0,,,0,0,0,0,,,0,0,0,0,,,0,0,0,0,,,0,0,0,0,,,0,0,0,0,AAPL
2024-10-22 12:28:42.879881467+00:00,10,39,38,A,A,0,236.8,2000,130,203181,48014,233.4,236.8,2000,2000,1,1,,,0,0,0,0,,,0,0,0,0,,,0,0,0,0,,,0,0,0,0,,,0,0,0,0,,,0,0,0,0,,,0,0,0,0,,,0,0,0,0,,,0,0,0,0,AAPL
2024-10-22 12:28:43.317792335+00:00,10,39,38,C,A,0,236.8,2000,130,202988,48030,233.4,,2000,0,1,0,,,0,0,0,0,,,0,0,0,0,,,0,0,0,0,,,0,0,0,0,,,0,0,0,0,,,0,0,0,0,,,0,0,0,0,,,0,0,0,0,,,0,0,0,0,AAPL
2024-10-22 12:28:43.328905190+00:00,10,39,38,A,A,0,236.6,2000,130,203064,48033,233.4,236.6,2000,2000,1,1,,,0,0,0,0,,,0,0,0,0,,,0,0,0,0,,,0,0,0,0,,,0,0,0,0,,,0,0,0,0,,,0,0,0,0,,,0,0,0,0,,,0,0,0,0,AAPL
2024-10-22 12:28:43.345070774+00:00,10,39,38,C,A,0,236.6,2000,130,202973,48036,233.4,,2000,0,1,0,,,0,0,0,0,,,0,0,0,0,,,0,0,0,0,,,0,0,0,0,,,0,0,0,0,,,0,0,0,0,,,0,0,0,0,,,0,0,0,0,,,0,0,0,0,AAPL
2024-10-22 12:28:43.356428830+00:00,10,39,38,A,A,0,236.8,2000,130,203062,48038,233.4,236.8,2000,2000,1,1,,,0,0,0,0,,,0,0,0,0,,,0,0,0,0,,,0,0,0,0,,,0,0,0,0,,,0,0,0,0,,,0,0,0,0,,,0,0,0,0,,,0,0,0,0,AAPL
2024-10-22 12:28:43.382935488+00:00,10,39,38,A,A,0,236.6,2000,130,203230,48039,233.4,236.6,2000,2000,1,1,,236.8,0,2000,0,1,,,0,0,0,0,,,0,0,0,0,,,0,0,0,0,,,0,0,0,0,,,0,0,0,0,,,0,0,0,0,,,0,0,0,0,,,0,0,0,0,AAPL
2024-10-22 12:28:43.383663003+00:00,10,39,38,C,A,1,236.8,2000,130,203023,48040,233.4,236.6,2000,2000,1,1,,,0,0,0,0,,,0,0,0,0,,,0,0,0,0,,,0,0,0,0,,,0,0,0,0,,,0,0,0,0,,,0,0,0,0,,,0,0,0,0,,,0,0,0,0,AAPL
2024-10-22 12:28:43.393445653+00:00,10,39,38,C,A,0,236.6,2000,130,203008,48041,233.4,,2000,0,1,0,,,0,0,0,0,,,0,0,0,0,,,0,0,0,0,,,0,0,0,0,,,0,0,0,0,,,0,0,0,0,,,0,0,0,0,,,0,0,0,0,,,0,0,0,0,AAPL
2024-10-22 12:28:43.404308983+00:00,10,39,38,A,A,0,236.8,2000,130,203033,48042,233.4,236.8,2000,2000,1,1,,,0,0,0,0,,,0,0,0,0,,,0,0,0,0,,,0,0,0,0,,,0,0,0,0,,,0,0,0,0,,,0,0,0,0,,,0,0,0,0,,,0,0,0,0,AAPL
2024-10-22 12:28:43.422239083+00:00,10,39,38,A,A,0,236.6,2000,130,203231,48043,233.4,236.6,2000,2000,1,1,,236.8,0,2000,0,1,,,0,0,0,0,,,0,0,0,0,,,0,0,0,0,,,0,0,0,0,,,0,0,0,0,,,0,0,0,0,,,0,0,0,0,,,0,0,0,0,AAPL
2024-10-22 12:28:43.422877294+00:00,10,39,38,C,A,1,236.8,2000,130,203084,48044,233.4,236.6,2000,2000,1,1,,,0,0,0,0,,,0,0,0,0,,,0,0,0,0,,,0,0,0,0,,,0,0,0,0,,,0,0,0,0,,,0,0,0,0,,,0,0,0,0,,,0,0,0,0,AAPL
2024-10-22 12:28:51.279966422+00:00,10,39,38,C,B,0,233.4,2000,130,203297,48073,,236.6,0,2000,0,1,,,0,0,0,0,,,0,0,0,0,,,0,0,0,0,,,0,0,0,0,,,0,0,0,0,,,0,0,0,0,,,0,0,0,0,,,0,0,0,0,,,0,0,0,0,AAPL
2024-10-22 12:28:51.316953582+00:00,10,39,38,C,A,0,236.6,2000,130,203142,48074,,,0,0,0,0,,,0,0,0,0,,,0,0,0,0,,,0,0,0,0,,,0,0,0,0,,,0,0,0,0,,,0,0,0,0,,,0,0,0,0,,,0,0,0,0,,,0,0,0,0,AAPL
2024-10-22 12:28:51.316963724+00:00,10,39,38,A,B,0,233.4,2000,130,203189,48075,233.4,,2000,0,1,0,,,0,0,0,0,,,0,0,0,0,,,0,0,0,0,,,0,0,0,0,,,0,0,0,0,,,0,0,0,0,,,0,0,0,0,,,0,0,0,0,,,0,0,0,0,AAPL
2024-10-22 12:28:51.327852246+00:00,10,39,38,A,A,0,236.8,2000,130,203097,48078,233.4,236.8,2000,2000,1,1,,,0,0,0,0,,,0,0,0,0,,,0,0,0,0,,,0,0,0,0,,,0,0,0,0,,,0,0,0,0,,,0,0,0,0,,,0,0,0,0,,,0,0,0,0,AAPL
2024-10-22 12:28:51.342516058+00:00,10,39,38,C,A,0,236.8,2000,130,203090,48079,233.4,,2000,0,1,0,,,0,0,0,0,,,0,0,0,0,,,0,0,0,0,,,0,0,0,0,,,0,0,0,0,,,0,0,0,0,,,0,0,0,0,,,0,0,0,0,,,0,0,0,0,AAPL
2024-10-22 12:28:51.352053852+00:00,10,39,38,C,B,0,233.4,2000,130,202974,48081,,,0,0,0,0,,,0,0,0,0,,,0,0,0,0,,,0,0,0,0,,,0,0,0,0,,,0,0,0,0,,,0,0,0,0,,,0,0,0,0,,,0,0,0,0,,,0,0,0,0,AAPL
2024-10-22 12:28:51.369869421+00:00,10,39,38,A,B,0,233.4,2000,130,203077,48082,233.4,,2000,0,1,0,,,0,0,0,0,,,0,0,0,0,,,0,0,0,0,,,0,0,0,0,,,0,0,0,0,,,0,0,0,0,,,0,0,0,0,,,0,0,0,0,,,0,0,0,0,AAPL
2024-10-22 12:28:51.390982867+00:00,10,39,38,A,A,0,237.0,2000,130,203015,48085,233.4,237.0,2000,2000,1,1,,,0,0,0,0,,,0,0,0,0,,,0,0,0,0,,,0,0,0,0,,,0,0,0,0,,,0,0,0,0,,,0,0,0,0,,,0,0,0,0,,,0,0,0,0,AAPL
2024-10-22 12:28:51.425981996+00:00,10,39,38,A,A,0,236.8,2000,130,203191,48089,233.4,236.8,2000,2000,1,1,,237.0,0,2000,0,1,,,0,0,0,0,,,0,0,0,0,,,0,0,0,0,,,0,0,0,0,,,0,0,0,0,,,0,0,0,0,,,0,0,0,0,,,0,0,0,0,AAPL
2024-10-22 12:28:51.426324707+00:00,10,39,38,C,A,1,237.0,2000,130,203085,48090,233.4,236.8,2000,2000,1,1,,,0,0,0,0,,,0,0,0,0,,,0,0,0,0,,,0,0,0,0,,,0,0,0,0,,,0,0,0,0,,,0,0,0,0,,,0,0,0,0,,,0,0,0,0,AAPL
2024-10-22 12:28:51.435074408+00:00,10,39,38,C,A,0,236.8,2000,130,203047,48092,233.4,,2000,0,1,0,,,0,0,0,0,,,0,0,0,0,,,0,0,0,0,,,0,0,0,0,,,0,0,0,0,,,0,0,0,0,,,0,0,0,0,,,0,0,0,0,,,0,0,0,0,AAPL
2024-10-22 12:28:51.446951503+00:00,10,39,38,A,A,0,237.0,2000,130,203101,48095,233.4,237.0,2000,2000,1,1,,,0,0,0,0,,,0,0,0,0,,,0,0,0,0,,,0,0,0,0,,,0,0,0,0,,,0,0,0,0,,,0,0,0,0,,,0,0,0,0,,,0,0,0,0,AAPL
2024-10-22 12:28:51.468650132+00:00,10,39,38,A,A,0,236.8,2000,130,203109,48097,233.4,236.8,2000,2000,1,1,,237.0,0,2000,0,1,,,0,0,0,0,,,0,0,0,0,,,0,0,0,0,,,0,0,0,0,,,0,0,0,0,,,0,0,0,0,,,0,0,0,0,,,0,0,0,0,AAPL
2024-10-22 12:28:51.468836054+00:00,10,39,38,C,A,1,237.0,2000,130,203069,48098,233.4,236.8,2000,2000,1,1,,,0,0,0,0,,,0,0,0,0,,,0,0,0,0,,,0,0,0,0,,,0,0,0,0,,,0,0,0,0,,,0,0,0,0,,,0,0,0,0,,,0,0,0,0,AAPL
2024-10-22 12:28:51.853474525+00:00,10,39,38,A,A,0,236.6,2000,130,203199,48102,233.4,236.6,2000,2000,1,1,,236.8,0,2000,0,1,,,0,0,0,0,,,0,0,0,0,,,0,0,0,0,,,0,0,0,0,,,0,0,0,0,,,0,0,0,0,,,0,0,0,0,,,0,0,0,0,AAPL
2024-10-22 12:28:51.853752441+00:00,10,39,38,C,A,1,236.8,2000,130,203047,48103,233.4,236.6,2000,2000,1,1,,,0,0,0,0,,,0,0,0,0,,,0,0,0,0,,,0,0,0,0,,,0,0,0,0,,,0,0,0,0,,,0,0,0,0,,,0,0,0,0,,,0,0,0,0,AAPL
2024-10-22 12:28:53.112347276+00:00,10,40,38,A,A,0,234.59,100,194,202694,76513,234.18,234.59,200,100,0,0,,,0,0,0,0,,,0,0,0,0,,,0,0,0,0,,,0,0,0,0,,,0,0,0,0,,,0,0,0,0,,,0,0,0,0,,,0,0,0,0,,,0,0,0,0,AAPL
2024-10-22 12:28:54.897459063+00:00,10,39,38,C,A,0,236.6,2000,130,203375,48126,233.4,,2000,0,1,0,,,0,0,0,0,,,0,0,0,0,,,0,0,0,0,,,0,0,0,0,,,0,0,0,0,,,0,0,0,0,,,0,0,0,0,,,0,0,0,0,,,0,0,0,0,AAPL
2024-10-22 12:28:55.216154077+00:00,10,39,38,A,A,0,236.8,2000,130,203580,48130,233.4,236.8,2000,2000,1,1,,,0,0,0,0,,,0,0,0,0,,,0,0,0,0,,,0,0,0,0,,,0,0,0,0,,,0,0,0,0,,,0,0,0,0,,,0,0,0,0,,,0,0,0,0,AAPL
2024-10-22 12:28:55.438137664+00:00,10,39,38,A,A,0,236.6,2000,130,203637,48136,233.4,236.6,2000,2000,1,1,,236.8,0,2000,0,1,,,0,0,0,0,,,0,0,0,0,,,0,0,0,0,,,0,0,0,0,,,0,0,0,0,,,0,0,0,0,,,0,0,0,0,,,0,0,0,0,AAPL
2024-10-22 12:28:55.438869831+00:00,10,39,38,C,A,1,236.8,2000,130,203260,48137,233.4,236.6,2000,2000,1,1,,,0,0,0,0,,,0,0,0,0,,,0,0,0,0,,,0,0,0,0,,,0,0,0,0,,,0,0,0,0,,,0,0,0,0,,,0,0,0,0,,,0,0,0,0,AAPL
2024-10-22 12:29:01.894346599+00:00,10,40,10888,A,A,0,418.79,100,194,203300,76774,,418.79,0,100,0,0,,,0,0,0,0,,,0,0,0,0,,,0,0,0,0,,,0,0,0,0,,,0,0,0,0,,,0,0,0,0,,,0,0,0,0,,,0,0,0,0,,,0,0,0,0,MSFT
2024-10-22 12:29:01.942213264+00:00,10,39,38,C,B,0,233.4,2000,130,203547,48201,,236.6,0,2000,0,1,,,0,0,0,0,,,0,0,0,0,,,0,0,0,0,,,0,0,0,0,,,0,0,0,0,,,0,0,0,0,,,0,0,0,0,,,0,0,0,0,,,0,0,0,0,AAPL
