ts_event,rtype,publisher_id,instrument_id,action,side,depth,price,size,flags,ts_in_delta,sequence,bid_px_00,ask_px_00,bid_sz_00,ask_sz_00,bid_ct_00,ask_ct_00,bid_px_01,ask_px_01,bid_sz_01,ask_sz_01,bid_ct_01,ask_ct_01,bid_px_02,ask_px_02,bid_sz_02,ask_sz_02,bid_ct_02,ask_ct_02,bid_px_03,ask_px_03,bid_sz_03,ask_sz_03,bid_ct_03,ask_ct_03,bid_px_04,ask_px_04,bid_sz_04,ask_sz_04,bid_ct_04,ask_ct_04,bid_px_05,ask_px_05,bid_sz_05,ask_sz_05,bid_ct_05,ask_ct_05,bid_px_06,ask_px_06,bid_sz_06,ask_sz_06,bid_ct_06,ask_ct_06,bid_px_07,ask_px_07,bid_sz_07,ask_sz_07,bid_ct_07,ask_ct_07,bid_px_08,ask_px_08,bid_sz_08,ask_sz_08,bid_ct_08,ask_ct_08,bid_px_09,ask_px_09,bid_sz_09,ask_sz_09,bid_ct_09,ask_ct_09,symbol
2024-10-22 12:29:01.975597540+00:00,10,39,38,C,A,0,236.6,2000,130,203507,48203,,,0,0,0,0,,,0,0,0,0,,,0,0,0,0,,,0,0,0,0,,,0,0,0,0,,,0,0,0,0,,,0,0,0,0,,,0,0,0,0,,,0,0,0,0,,,0,0,0,0,AAPL
2024-10-22 12:29:01.980173553+00:00,10,39,38,A,B,0,233.6,2000,130,203399,48204,233.6,,2000,0,1,0,,,0,0,0,0,,,0,0,0,0,,,0,0,0,0,,,0,0,0,0,,,0,0,0,0,,,0,0,0,0,,,0,0,0,0,,,0,0,0,0,,,0,0,0,0,AAPL
2024-10-22 12:29:02.106296705+00:00,10,39,38,A,A,0,236.8,2000,130,203401,48208,233.6,236.8,2000,2000,1,1,,,0,0,0,0,,,0,0,0,0,,,0,0,0,0,,,0,0,0,0,,,0,0,0,0,,,0,0,0,0,,,0,0,0,0,,,0,0,0,0,,,0,0,0,0,AAPL
2024-10-22 12:29:02.126596058+00:00,10,39,38,C,A,0,236.8,2000,130,203281,48209,233.6,,2000,0,1,0,,,0,0,0,0,,,0,0,0,0,,,0,0,0,0,,,0,0,0,0,,,0,0,0,0,,,0,0,0,0,,,0,0,0,0,,,0,0,0,0,,,0,0,0,0,AAPL
2024-10-22 12:29:02.155288335+00:00,10,39,38,A,A,0,236.8,2000,130,203411,48211,233.6,236.8,2000,2000,1,1,,,0,0,0,0,,,0,0,0,0,,,0,0,0,0,,,0,0,0,0,,,0,0,0,0,,,0,0,0,0,,,0,0,0,0,,,0,0,0,0,,,0,0,0,0,AAPL
2024-10-22 12:29:02.194061344+00:00,10,39,38,C,A,0,236.8,2000,130,203349,48216,233.6,,2000,0,1,0,,,0,0,0,0,,,0,0,0,0,,,0,0,0,0,,,0,0,0,0,,,0,0,0,0,,,0,0,0,0,,,0,0,0,0,,,0,0,0,0,,,0,0,0,0,AAPL
2024-10-22 12:29:02.209906847+00:00,10,39,38,A,A,0,236.6,2000,130,203328,48218,233.6,236.6,2000,2000,1,1,,,0,0,0,0,,,0,0,0,0,,,0,0,0,0,,,0,0,0,0,,,0,0,0,0,,,0,0,0,0,,,0,0,0,0,,,0,0,0,0,,,0,0,0,0,AAPL
2024-10-22 12:29:02.278693145+00:00,10,40,38,A,B,0,234.59,100,194,203310,76791,,234.59,0,100,0,0,,,0,0,0,0,,,0,0,0,0,,,0,0,0,0,,,0,0,0,0,,,0,0,0,0,,,0,0,0,0,,,0,0,0,0,,,0,0,0,0,,,0,0,0,0,AAPL
2024-10-22 12:29:02.278710330+00:00,10,40,38,A,B,0,234.59,100,194,203300,76792,234.03,234.59,200,100,0,0,,,0,0,0,0,,,0,0,0,0,,,0,0,0,0,,,0,0,0,0,,,0,0,0,0,,,0,0,0,0,,,0,0,0,0,,,0,0,0,0,,,0,0,0,0,AAPL
2024-10-22 12:29:02.278932986+00:00,10,41,38,A,B,0,234.92,200,194,56383,130571,,234.92,0,200,0,0,,,0,0,0,0,,,0,0,0,0,,,0,0,0,0,,,0,0,0,0,,,0,0,0,0,,,0,0,0,0,,,0,0,0,0,,,0,0,0,0,,,0,0,0,0,AAPL
2024-10-22 12:29:02.278982139+00:00,10,41,38,A,B,0,234.92,200,194,55647,130572,234.09,234.92,200,200,0,0,,,0,0,0,0,,,0,0,0,0,,,0,0,0,0,,,0,0,0,0,,,0,0,0,0,,,0,0,0,0,,,0,0,0,0,,,0,0,0,0,,,0,0,0,0,AAPL
2024-10-22 12:29:06.089823549+00:00,10,40,10888,A,A,0,,0,194,204080,76831,,,0,0,0,0,,,0,0,0,0,,,0,0,0,0,,,0,0,0,0,,,0,0,0,0,,,0,0,0,0,,,0,0,0,0,,,0,0,0,0,,,0,0,0,0,,,0,0,0,0,MSFT
2024-10-22 12:29:16.023663275+00:00,10,39,38,C,B,0,233.6,2000,130,204278,48311,,236.6,0,2000,0,1,,,0,0,0,0,,,0,0,0,0,,,0,0,0,0,,,0,0,0,0,,,0,0,0,0,,,0,0,0,0,,,0,0,0,0,,,0,0,0,0,,,0,0,0,0,AAPL
2024-10-22 12:29:16.034412398+00:00,10,39,38,A,B,0,233.4,2000,130,204326,48312,233.4,236.6,2000,2000,1,1,,,0,0,0,0,,,0,0,0,0,,,0,0,0,0,,,0,0,0,0,,,0,0,0,0,,,0,0,0,0,,,0,0,0,0,,,0,0,0,0,,,0,0,0,0,AAPL
2024-10-22 12:29:18.915912819+00:00,10,40,10888,A,A,0,418.79,100,194,203787,77029,,418.79,0,100,0,0,,,0,0,0,0,,,0,0,0,0,,,0,0,0,0,,,0,0,0,0,,,0,0,0,0,,,0,0,0,0,,,0,0,0,0,,,0,0,0,0,,,0,0,0,0,MSFT
2024-10-22 12:29:20.665451746+00:00,10,39,38,A,B,0,233.6,2000,130,204724,48363,233.6,236.6,2000,2000,1,1,233.4,,2000,0,1,0,,,0,0,0,0,,,0,0,0,0,,,0,0,0,0,,,0,0,0,0,,,0,0,0,0,,,0,0,0,0,,,0,0,0,0,,,0,0,0,0,AAPL
2024-10-22 12:29:20.666186486+00:00,10,39,38,C,B,1,233.4,2000,130,204362,48364,233.6,236.6,2000,2000,1,1,,,0,0,0,0,,,0,0,0,0,,,0,0,0,0,,,0,0,0,0,,,0,0,0,0,,,0,0,0,0,,,0,0,0,0,,,0,0,0,0,,,0,0,0,0,AAPL
2024-10-22 12:29:23.963466388+00:00,10,39,38,C,A,0,236.6,2000,130,204290,48401,233.6,,2000,0,1,0,,,0,0,0,0,,,0,0,0,0,,,0,0,0,0,,,0,0,0,0,,,0,0,0,0,,,0,0,0,0,,,0,0,0,0,,,0,0,0,0,,,0,0,0,0,AAPL
2024-10-22 12:29:23.974432216+00:00,10,39,38,A,A,0,236.8,2000,130,204270,48402,233.6,236.8,2000,2000,1,1,,,0,0,0,0,,,0,0,0,0,,,0,0,0,0,,,0,0,0,0,,,0,0,0,0,,,0,0,0,0,,,0,0,0,0,,,0,0,0,0,,,0,0,0,0,AAPL
2024-10-22 12:29:26.522406571+00:00,10,39,38,A,A,0,236.6,2000,130,204774,48427,233.6,236.6,2000,2000,1,1,,236.8,0,2000,0,1,,,0,0,0,0,,,0,0,0,0,,,0,0,0,0,,,0,0,0,0,,,0,0,0,0,,,0,0,0,0,,,0,0,0,0,,,0,0,0,0,AAPL
2024-10-22 12:29:26.522862726+00:00,10,39,38,C,A,1,236.8,2000,130,204271,48428,233.6,236.6,2000,2000,1,1,,,0,0,0,0,,,0,0,0,0,,,0,0,0,0,,,0,0,0,0,,,0,0,0,0,,,0,0,0,0,,,0,0,0,0,,,0,0,0,0,,,0,0,0,0,AAPL
2024-10-22 12:29:26.547672773+00:00,10,39,38,C,A,0,236.6,2000,130,204297,48430,233.6,,2000,0,1,0,,,0,0,0,0,,,0,0,0,0,,,0,0,0,0,,,0,0,0,0,,,0,0,0,0,,,0,0,0,0,,,0,0,0,0,,,0,0,0,0,,,0,0,0,0,AAPL
2024-10-22 12:29:26.558762284+00:00,10,39,38,A,A,0,236.8,2000,130,204443,48431,233.6,236.8,2000,2000,1,1,,,0,0,0,0,,,0,0,0,0,,,0,0,0,0,,,0,0,0,0,,,0,0,0,0,,,0,0,0,0,,,0,0,0,0,,,0,0,0,0,,,0,0,0,0,AAPL
2024-10-22 12:29:26.579217251+00:00,10,39,38,C,A,0,236.8,2000,130,204243,48434,233.6,,2000,0,1,0,,,0,0,0,0,,,0,0,0,0,,,0,0,0,0,,,0,0,0,0,,,0,0,0,0,,,0,0,0,0,,,0,0,0,0,,,0,0,0,0,,,0,0,0,0,AAPL
2024-10-22 12:29:26.777821661+00:00,10,39,38,A,A,0,236.8,2000,130,204432,48436,233.6,236.8,2000,2000,1,1,,,0,0,0,0,,,0,0,0,0,,,0,0,0,0,,,0,0,0,0,,,0,0,0,0,,,0,0,0,0,,,0,0,0,0,,,0,0,0,0,,,0,0,0,0,AAPL
2024-10-22 12:29:26.849537460+00:00,10,39,38,C,A,0,236.8,2000,130,204237,48437,233.6,,2000,0,1,0,,,0,0,0,0,,,0,0,0,0,,,0,0,0,0,,,0,0,0,0,,,0,0,0,0,,,0,0,0,0,,,0,0,0,0,,,0,0,0,0,,,0,0,0,0,AAPL
2024-10-22 12:29:26.865771754+00:00,10,39,38,A,A,0,236.8,2000,130,204304,48438,233.6,236.8,2000,2000,1,1,,,0,0,0,0,,,0,0,0,0,,,0,0,0,0,,,0,0,0,0,,,0,0,0,0,,,0,0,0,0,,,0,0,0,0,,,0,0,0,0,,,0,0,0,0,AAPL
2024-10-22 12:29:27.928781740+00:00,10,40,38,A,A,0,234.94,200,194,203929,77137,234.03,234.94,200,200,0,0,,,0,0,0,0,,,0,0,0,0,,,0,0,0,0,,,0,0,0,0,,,0,0,0,0,,,0,0,0,0,,,0,0,0,0,,,0,0,0,0,,,0,0,0,0,AAPL
2024-10-22 12:29:31.675586317+00:00,10,40,38,A,A,0,234.57,100,194,204035,77174,234.03,234.57,200,100,0,0,,,0,0,0,0,,,0,0,0,0,,,0,0,0,0,,,0,0,0,0,,,0,0,0,0,,,0,0,0,0,,,0,0,0,0,,,0,0,0,0,,,0,0,0,0,AAPL
2024-10-22 12:29:35.356019543+00:00,10,39,38,A,A,0,236.6,2000,130,204073,48494,233.6,236.6,2000,2000,1,1,,236.8,0,2000,0,1,,,0,0,0,0,,,0,0,0,0,,,0,0,0,0,,,0,0,0,0,,,0,0,0,0,,,0,0,0,0,,,0,0,0,0,,,0,0,0,0,AAPL
2024-10-22 12:29:35.356221262+00:00,10,39,38,C,A,1,236.8,2000,130,203960,48495,233.6,236.6,2000,2000,1,1,,,0,0,0,0,,,0,0,0,0,,,0,0,0,0,,,0,0,0,0,,,0,0,0,0,,,0,0,0,0,,,0,0,0,0,,,0,0,0,0,,,0,0,0,0,AAPL
2024-10-22 12:29:35.382652906+00:00,10,39,38,C,A,0,236.6,2000,130,203918,48497,233.6,,2000,0,1,0,,,0,0,0,0,,,0,0,0,0,,,0,0,0,0,,,0,0,0,0,,,0,0,0,0,,,0,0,0,0,,,0,0,0,0,,,0,0,0,0,,,0,0,0,0,AAPL
2024-10-22 12:29:35.700784088+00:00,10,39,38,A,A,0,236.8,2000,130,204302,48505,233.6,236.8,2000,2000,1,1,,,0,0,0,0,,,0,0,0,0,,,0,0,0,0,,,0,0,0,0,,,0,0,0,0,,,0,0,0,0,,,0,0,0,0,,,0,0,0,0,,,0,0,0,0,AAPL
2024-10-22 12:29:35.921894622+00:00,10,39,38,A,A,0,236.6,2000,130,204544,48506,233.6,236.6,2000,2000,1,1,,236.8,0,2000,0,1,,,0,0,0,0,,,0,0,0,0,,,0,0,0,0,,,0,0,0,0,,,0,0,0,0,,,0,0,0,0,,,0,0,0,0,,,0,0,0,0,AAPL
2024-10-22 12:29:35.922086332+00:00,10,39,38,C,A,1,236.8,2000,130,203939,48507,233.6,236.6,2000,2000,1,1,,,0,0,0,0,,,0,0,0,0,,,0,0,0,0,,,0,0,0,0,,,0,0,0,0,,,0,0,0,0,,,0,0,0,0,,,0,0,0,0,,,0,0,0,0,AAPL
2024-10-22 12:29:37.193784224+00:00,10,40,10888,A,A,0,,0,194,204223,77232,,,0,0,0,0,,,0,0,0,0,,,0,0,0,0,,,0,0,0,0,,,0,0,0,0,,,0,0,0,0,,,0,0,0,0,,,0,0,0,0,,,0,0,0,0,,,0,0,0,0,MSFT
2024-10-22 12:29:39.078964719+00:00,10,40,38,A,A,0,234.94,200,194,204417,77250,234.03,234.94,200,200,0,0,,,0,0,0,0,,,0,0,0,0,,,0,0,0,0,,,0,0,0,0,,,0,0,0,0,,,0,0,0,0,,,0,0,0,0,,,0,0,0,0,,,0,0,0,0,AAPL
2024-10-22 12:29:41.112027078+00:00,10,40,38,A,A,0,234.54,100,194,204185,77281,234.03,234.54,200,100,0,0,,,0,0,0,0,,,0,0,0,0,,,0,0,0,0,,,0,0,0,0,,,0,0,0,0,,,0,0,0,0,,,0,0,0,0,,,0,0,0,0,,,0,0,0,0,AAPL
2024-10-22 12:29:45.000923683+00:00,10,39,38,C,A,0,236.6,2000,130,204124,48566,233.6,,2000,0,1,0,,,0,0,0,0,,,0,0,0,0,,,0,0,0,0,,,0,0,0,0,,,0,0,0,0,,,0,0,0,0,,,0,0,0,0,,,0,0,0,0,,,0,0,0,0,AAPL
2024-10-22 12:29:45.012287732+00:00,10,39,38,A,A,0,236.8,2000,130,203728,48610,233.6,236.8,2000,2000,1,1,,,0,0,0,0,,,0,0,0,0,,,0,0,0,0,,,0,0,0,0,,,0,0,0,0,,,0,0,0,0,,,0,0,0,0,,,0,0,0,0,,,0,0,0,0,AAPL
2024-10-22 12:29:56.550713942+00:00,10,40,38,A,A,0,234.94,200,194,202767,77524,234.03,234.94,200,200,0,0,,,0,0,0,0,,,0,0,0,0,,,0,0,0,0,,,0,0,0,0,,,0,0,0,0,,,0,0,0,0,,,0,0,0,0,,,0,0,0,0,,,0,0,0,0,AAPL
2024-10-22 12:29:59.000496414+00:00,10,40,38,A,N,0,,0,194,202682,77583,,,0,0,0,0,,,0,0,0,0,,,0,0,0,0,,,0,0,0,0,,,0,0,0,0,,,0,0,0,0,,,0,0,0,0,,,0,0,0,0,,,0,0,0,0,,,0,0,0,0,AAPL
2024-10-22 12:29:59.000692432+00:00,10,41,38,A,B,0,234.92,200,192,103644,132327,,234.92,0,200,0,0,,,0,0,0,0,,,0,0,0,0,,,0,0,0,0,,,0,0,0,0,,,0,0,0,0,,,0,0,0,0,,,0,0,0,0,,,0,0,0,0,,,0,0,0,0,AAPL
2024-10-22 12:29:59.000714013+00:00,10,41,38,A,A,0,,0,192,90451,132338,,,0,0,0,0,,,0,0,0,0,,,0,0,0,0,,,0,0,0,0,,,0,0,0,0,,,0,0,0,0,,,0,0,0,0,,,0,0,0,0,,,0,0,0,0,,,0,0,0,0,AAPL
2024-10-22 12:30:00.967996256+00:00,10,39,38,C,B,0,233.6,2000,130,203638,48786,,236.8,0,2000,0,1,,,0,0,0,0,,,0,0,0,0,,,0,0,0,0,,,0,0,0,0,,,0,0,0,0,,,0,0,0,0,,,0,0,0,0,,,0,0,0,0,,,0,0,0,0,AAPL
2024-10-22 12:30:00.987243517+00:00,10,39,38,A,B,0,233.2,2000,130,203473,48787,233.2,236.8,2000,2000,1,1,,,0,0,0,0,,,0,0,0,0,,,0,0,0,0,,,0,0,0,0,,,0,0,0,0,,,0,0,0,0,,,0,0,0,0,,,0,0,0,0,,,0,0,0,0,AAPL
2024-10-22 12:30:03.340747006+00:00,10,41,38,A,B,0,,0,194,56945,134160,234.16,,200,0,0,0,,,0,0,0,0,,,0,0,0,0,,,0,0,0,0,,,0,0,0,0,,,0,0,0,0,,,0,0,0,0,,,0,0,0,0,,,0,0,0,0,,,0,0,0,0,AAPL
2024-10-22 12:30:03.340838275+00:00,10,40,38,A,B,0,,0,194,202308,78094,234.11,,200,0,0,0,,,0,0,0,0,,,0,0,0,0,,,0,0,0,0,,,0,0,0,0,,,0,0,0,0,,,0,0,0,0,,,0,0,0,0,,,0,0,0,0,,,0,0,0,0,AAPL
2024-10-22 12:30:03.340978464+00:00,10,40,38,A,A,0,234.89,200,194,202285,78095,234.11,234.89,200,200,0,0,,,0,0,0,0,,,0,0,0,0,,,0,0,0,0,,,0,0,0,0,,,0,0,0,0,,,0,0,0,0,,,0,0,0,0,,,0,0,0,0,,,0,0,0,0,AAPL
2024-10-22 12:30:03.344938211+00:00,10,40,38,A,A,0,,0,194,202298,78098,234.11,,200,0,0,0,,,0,0,0,0,,,0,0,0,0,,,0,0,0,0,,,0,0,0,0,,,0,0,0,0,,,0,0,0,0,,,0,0,0,0,,,0,0,0,0,,,0,0,0,0,AAPL
2024-10-22 12:30:03.345056742+00:00,10,40,38,A,B,0,,0,194,202291,78099,,,0,0,0,0,,,0,0,0,0,,,0,0,0,0,,,0,0,0,0,,,0,0,0,0,,,0,0,0,0,,,0,0,0,0,,,0,0,0,0,,,0,0,0,0,,,0,0,0,0,AAPL
2024-10-22 12:30:03.436892898+00:00,10,41,38,A,B,0,,0,194,56223,134204,,,0,0,0,0,,,0,0,0,0,,,0,0,0,0,,,0,0,0,0,,,0,0,0,0,,,0,0,0,0,,,0,0,0,0,,,0,0,0,0,,,0,0,0,0,,,0,0,0,0,AAPL
2024-10-22 12:30:12.490177352+00:00,10,41,38,A,B,0,,0,194,55787,135373,234.16,,200,0,0,0,,,0,0,0,0,,,0,0,0,0,,,0,0,0,0,,,0,0,0,0,,,0,0,0,0,,,0,0,0,0,,,0,0,0,0,,,0,0,0,0,,,0,0,0,0,AAPL
2024-10-22 12:30:12.561548786+00:00,10,41,38,A,B,0,,0,194,55389,135376,,,0,0,0,0,,,0,0,0,0,,,0,0,0,0,,,0,0,0,0,,,0,0,0,0,,,0,0,0,0,,,0,0,0,0,,,0,0,0,0,,,0,0,0,0,,,0,0,0,0,AAPL
2024-10-22 12:30:13.582680463+00:00,10,39,38,A,B,0,233.6,2000,130,204003,48913,233.6,236.8,2000,2000,1,1,233.2,,2000,0,1,0,,,0,0,0,0,,,0,0,0,0,,,0,0,0,0,,,0,0,0,0,,,0,0,0,0,,,0,0,0,0,,,0,0,0,0,,,0,0,0,0,AAPL
2024-10-22 12:30:13.583408476+00:00,10,39,38,C,B,1,233.2,2000,130,203552,48914,233.6,236.8,2000,2000,1,1,,,0,0,0,0,,,0,0,0,0,,,0,0,0,0,,,0,0,0,0,,,0,0,0,0,,,0,0,0,0,,,0,0,0,0,,,0,0,0,0,,,0,0,0,0,AAPL
2024-10-22 12:30:14.347957129+00:00,10,40,38,A,A,0,234.89,200,194,202312,78479,,234.89,0,200,0,0,,,0,0,0,0,,,0,0,0,0,,,0,0,0,0,,,0,0,0,0,,,0,0,0,0,,,0,0,0,0,,,0,0,0,0,,,0,0,0,0,,,0,0,0,0,AAPL
2024-10-22 12:30:14.348076610+00:00,10,40,38,A,B,0,234.89,200,194,202271,78480,234.1,234.89,200,200,0,0,,,0,0,0,0,,,0,0,0,0,,,0,0,0,0,,,0,0,0,0,,,0,0,0,0,,,0,0,0,0,,,0,0,0,0,,,0,0,0,0,,,0,0,0,0,AAPL
2024-10-22 12:30:14.348358823+00:00,10,41,38,A,B,0,,0,194,55861,135504,234.16,,200,0,0,0,,,0,0,0,0,,,0,0,0,0,,,0,0,0,0,,,0,0,0,0,,,0,0,0,0,,,0,0,0,0,,,0,0,0,0,,,0,0,0,0,,,0,0,0,0,AAPL
2024-10-22 12:30:14.348384075+00:00,10,41,38,A,A,0,234.83,200,194,55315,135505,234.16,234.83,200,200,0,0,,,0,0,0,0,,,0,0,0,0,,,0,0,0,0,,,0,0,0,0,,,0,0,0,0,,,0,0,0,0,,,0,0,0,0,,,0,0,0,0,,,0,0,0,0,AAPL
2024-10-22 12:30:14.348882635+00:00,10,41,38,A,A,0,,0,194,54304,135506,234.16,,200,0,0,0,,,0,0,0,0,,,0,0,0,0,,,0,0,0,0,,,0,0,0,0,,,0,0,0,0,,,0,0,0,0,,,0,0,0,0,,,0,0,0,0,,,0,0,0,0,AAPL
2024-10-22 12:30:14.372868129+00:00,10,40,38,A,B,0,234.89,200,194,202305,78481,,234.89,0,200,0,0,,,0,0,0,0,,,0,0,0,0,,,0,0,0,0,,,0,0,0,0,,,0,0,0,0,,,0,0,0,0,,,0,0,0,0,,,0,0,0,0,,,0,0,0,0,AAPL
2024-10-22 12:30:14.372943797+00:00,10,40,38,A,A,0,,0,194,202283,78482,,,0,0,0,0,,,0,0,0,0,,,0,0,0,0,,,0,0,0,0,,,0,0,0,0,,,0,0,0,0,,,0,0,0,0,,,0,0,0,0,,,0,0,0,0,,,0,0,0,0,AAPL
2024-10-22 12:30:14.475232760+00:00,10,41,38,A,B,0,,0,194,56270,135520,,,0,0,0,0,,,0,0,0,0,,,0,0,0,0,,,0,0,0,0,,,0,0,0,0,,,0,0,0,0,,,0,0,0,0,,,0,0,0,0,,,0,0,0,0,,,0,0,0,0,AAPL
2024-10-22 12:30:15.431121108+00:00,10,40,38,A,A,0,234.89,200,194,202224,78504,,234.89,0,200,0,0,,,0,0,0,0,,,0,0,0,0,,,0,0,0,0,,,0,0,0,0,,,0,0,0,0,,,0,0,0,0,,,0,0,0,0,,,0,0,0,0,,,0,0,0,0,AAPL
2024-10-22 12:30:15.431391938+00:00,10,41,38,A,B,0,,0,194,55815,135673,234.16,,200,0,0,0,,,0,0,0,0,,,0,0,0,0,,,0,0,0,0,,,0,0,0,0,,,0,0,0,0,,,0,0,0,0,,,0,0,0,0,,,0,0,0,0,,,0,0,0,0,AAPL
2024-10-22 12:30:15.431303933+00:00,10,40,38,A,B,0,234.89,200,194,202229,78505,234.1,234.89,200,200,0,0,,,0,0,0,0,,,0,0,0,0,,,0,0,0,0,,,0,0,0,0,,,0,0,0,0,,,0,0,0,0,,,0,0,0,0,,,0,0,0,0,,,0,0,0,0,AAPL
2024-10-22 12:30:15.431433783+00:00,10,41,38,A,A,0,234.83,200,194,54862,135674,234.16,234.83,200,200,0,0,,,0,0,0,0,,,0,0,0,0,,,0,0,0,0,,,0,0,0,0,,,0,0,0,0,,,0,0,0,0,,,0,0,0,0,,,0,0,0,0,,,0,0,0,0,AAPL
2024-10-22 12:30:15.481693099+00:00,10,40,38,A,B,0,234.89,200,194,202203,78507,,234.89,0,200,0,0,,,0,0,0,0,,,0,0,0,0,,,0,0,0,0,,,0,0,0,0,,,0,0,0,0,,,0,0,0,0,,,0,0,0,0,,,0,0,0,0,,,0,0,0,0,AAPL
2024-10-22 12:30:15.581720915+00:00,10,40,38,A,A,0,,0,194,202291,78509,,,0,0,0,0,,,0,0,0,0,,,0,0,0,0,,,0,0,0,0,,,0,0,0,0,,,0,0,0,0,,,0,0,0,0,,,0,0,0,0,,,0,0,0,0,,,0,0,0,0,AAPL
2024-10-22 12:30:15.581874131+00:00,10,41,38,A,B,0,234.83,200,194,55200,135726,,234.83,0,200,0,0,,,0,0,0,0,,,0,0,0,0,,,0,0,0,0,,,0,0,0,0,,,0,0,0,0,,,0,0,0,0,,,0,0,0,0,,,0,0,0,0,,,0,0,0,0,AAPL
2024-10-22 12:30:15.581915358+00:00,10,41,38,A,A,0,,0,194,60563,135727,,,0,0,0,0,,,0,0,0,0,,,0,0,0,0,,,0,0,0,0,,,0,0,0,0,,,0,0,0,0,,,0,0,0,0,,,0,0,0,0,,,0,0,0,0,,,0,0,0,0,AAPL
2024-10-22 12:30:18.804512427+00:00,10,40,38,A,N,0,234.89,200,194,202848,78555,234.12,234.89,200,200,0,0,,,0,0,0,0,,,0,0,0,0,,,0,0,0,0,,,0,0,0,0,,,0,0,0,0,,,0,0,0,0,,,0,0,0,0,,,0,0,0,0,,,0,0,0,0,AAPL
2024-10-22 12:30:18.804773051+00:00,10,41,38,A,A,0,234.83,200,194,55806,135925,,234.83,0,200,0,0,,,0,0,0,0,,,0,0,0,0,,,0,0,0,0,,,0,0,0,0,,,0,0,0,0,,,0,0,0,0,,,0,0,0,0,,,0,0,0,0,,,0,0,0,0,AAPL
2024-10-22 12:30:18.804793781+00:00,10,41,38,A,B,0,234.83,200,194,54376,135926,234.18,234.83,200,200,0,0,,,0,0,0,0,,,0,0,0,0,,,0,0,0,0,,,0,0,0,0,,,0,0,0,0,,,0,0,0,0,,,0,0,0,0,,,0,0,0,0,,,0,0,0,0,AAPL
2024-10-22 12:30:18.964052645+00:00,10,40,38,A,B,0,234.89,200,194,202525,78558,,234.89,0,200,0,0,,,0,0,0,0,,,0,0,0,0,,,0,0,0,0,,,0,0,0,0,,,0,0,0,0,,,0,0,0,0,,,0,0,0,0,,,0,0,0,0,,,0,0,0,0,AAPL
2024-10-22 12:30:18.964536389+00:00,10,41,38,A,B,0,234.83,200,194,60433,135933,,234.83,0,200,0,0,,,0,0,0,0,,,0,0,0,0,,,0,0,0,0,,,0,0,0,0,,,0,0,0,0,,,0,0,0,0,,,0,0,0,0,,,0,0,0,0,,,0,0,0,0,AAPL
2024-10-22 12:30:19.475472903+00:00,10,40,38,A,A,0,,0,194,202515,78569,,,0,0,0,0,,,0,0,0,0,,,0,0,0,0,,,0,0,0,0,,,0,0,0,0,,,0,0,0,0,,,0,0,0,0,,,0,0,0,0,,,0,0,0,0,,,0,0,0,0,AAPL
2024-10-22 12:30:19.475641165+00:00,10,41,38,A,A,0,,0,194,55689,135968,,,0,0,0,0,,,0,0,0,0,,,0,0,0,0,,,0,0,0,0,,,0,0,0,0,,,0,0,0,0,,,0,0,0,0,,,0,0,0,0,,,0,0,0,0,,,0,0,0,0,AAPL
2024-10-22 12:30:20.373603967+00:00,10,40,38,A,N,0,234.89,200,194,202639,78592,234.12,234.89,200,200,0,0,,,0,0,0,0,,,0,0,0,0,,,0,0,0,0,,,0,0,0,0,,,0,0,0,0,,,0,0,0,0,,,0,0,0,0,,,0,0,0,0,,,0,0,0,0,AAPL
2024-10-22 12:30:20.373873383+00:00,10,41,38,A,B,0,,0,194,55242,136065,234.18,,200,0,0,0,,,0,0,0,0,,,0,0,0,0,,,0,0,0,0,,,0,0,0,0,,,0,0,0,0,,,0,0,0,0,,,0,0,0,0,,,0,0,0,0,,,0,0,0,0,AAPL
2024-10-22 12:30:20.373884863+00:00,10,41,38,A,A,0,234.83,200,194,55549,136066,234.18,234.83,200,200,0,0,,,0,0,0,0,,,0,0,0,0,,,0,0,0,0,,,0,0,0,0,,,0,0,0,0,,,0,0,0,0,,,0,0,0,0,,,0,0,0,0,,,0,0,0,0,AAPL
2024-10-22 12:30:20.574507550+00:00,10,40,38,A,B,0,234.89,200,194,202604,78595,,234.89,0,200,0,0,,,0,0,0,0,,,0,0,0,0,,,0,0,0,0,,,0,0,0,0,,,0,0,0,0,,,0,0,0,0,,,0,0,0,0,,,0,0,0,0,,,0,0,0,0,AAPL
2024-10-22 12:30:20.574514743+00:00,10,40,38,A,A,0,,0,194,202515,78596,,,0,0,0,0,,,0,0,0,0,,,0,0,0,0,,,0,0,0,0,,,0,0,0,0,,,0,0,0,0,,,0,0,0,0,,,0,0,0,0,,,0,0,0,0,,,0,0,0,0,AAPL
2024-10-22 12:30:20.574749977+00:00,10,41,38,A,B,0,234.83,200,194,56227,136075,,234.83,0,200,0,0,,,0,0,0,0,,,0,0,0,0,,,0,0,0,0,,,0,0,0,0,,,0,0,0,0,,,0,0,0,0,,,0,0,0,0,,,0,0,0,0,,,0,0,0,0,AAPL
2024-10-22 12:30:20.677093391+00:00,10,40,38,A,A,0,234.89,200,194,202780,78597,,234.89,0,200,0,0,,,0,0,0,0,,,0,0,0,0,,,0,0,0,0,,,0,0,0,0,,,0,0,0,0,,,0,0,0,0,,,0,0,0,0,,,0,0,0,0,,,0,0,0,0,AAPL
2024-10-22 12:30:21.056790200+00:00,10,40,38,A,A,0,,0,194,202529,78605,,,0,0,0,0,,,0,0,0,0,,,0,0,0,0,,,0,0,0,0,,,0,0,0,0,,,0,0,0,0,,,0,0,0,0,,,0,0,0,0,,,0,0,0,0,,,0,0,0,0,AAPL
2024-10-22 12:30:21.561867958+00:00,10,41,38,A,A,0,,0,194,55849,136115,,,0,0,0,0,,,0,0,0,0,,,0,0,0,0,,,0,0,0,0,,,0,0,0,0,,,0,0,0,0,,,0,0,0,0,,,0,0,0,0,,,0,0,0,0,,,0,0,0,0,AAPL
2024-10-22 12:30:25.718969386+00:00,10,41,38,A,A,0,234.83,200,194,55522,136292,,234.83,0,200,0,0,,,0,0,0,0,,,0,0,0,0,,,0,0,0,0,,,0,0,0,0,,,0,0,0,0,,,0,0,0,0,,,0,0,0,0,,,0,0,0,0,,,0,0,0,0,AAPL
2024-10-22 12:30:25.821860230+00:00,10,41,38,A,A,0,,0,194,55263,136300,,,0,0,0,0,,,0,0,0,0,,,0,0,0,0,,,0,0,0,0,,,0,0,0,0,,,0,0,0,0,,,0,0,0,0,,,0,0,0,0,,,0,0,0,0,,,0,0,0,0,AAPL
2024-10-22 12:30:26.613115185+00:00,10,40,38,A,A,0,234.89,200,194,202336,78689,,234.89,0,200,0,0,,,0,0,0,0,,,0,0,0,0,,,0,0,0,0,,,0,0,0,0,,,0,0,0,0,,,0,0,0,0,,,0,0,0,0,,,0,0,0,0,,,0,0,0,0,AAPL
2024-10-22 12:30:30.419838396+00:00,10,41,38,A,A,0,234.83,200,194,60756,136639,,234.83,0,200,0,0,,,0,0,0,0,,,0,0,0,0,,,0,0,0,0,,,0,0,0,0,,,0,0,0,0,,,0,0,0,0,,,0,0,0,0,,,0,0,0,0,,,0,0,0,0,AAPL
2024-10-22 12:30:31.601859910+00:00,10,41,38,A,A,0,,0,194,54762,136716,,,0,0,0,0,,,0,0,0,0,,,0,0,0,0,,,0,0,0,0,,,0,0,0,0,,,0,0,0,0,,,0,0,0,0,,,0,0,0,0,,,0,0,0,0,,,0,0,0,0,AAPL
2024-10-22 12:30:32.731960413+00:00,10,41,38,A,A,0,234.83,200,194,55500,136904,,234.83,0,200,0,0,,,0,0,0,0,,,0,0,0,0,,,0,0,0,0,,,0,0,0,0,,,0,0,0,0,,,0,0,0,0,,,0,0,0,0,,,0,0,0,0,,,0,0,0,0,AAPL
2024-10-22 12:30:36.052293412+00:00,10,41,38,A,B,0,234.83,200,194,55569,137026,234.18,234.83,200,200,0,0,,,0,0,0,0,,,0,0,0,0,,,0,0,0,0,,,0,0,0,0,,,0,0,0,0,,,0,0,0,0,,,0,0,0,0,,,0,0,0,0,,,0,0,0,0,AAPL
2024-10-22 12:30:36.152604738+00:00,10,41,38,A,B,0,234.83,200,194,55402,137027,,234.83,0,200,0,0,,,0,0,0,0,,,0,0,0,0,,,0,0,0,0,,,0,0,0,0,,,0,0,0,0,,,0,0,0,0,,,0,0,0,0,,,0,0,0,0,,,0,0,0,0,AAPL
2024-10-22 12:30:41.087215085+00:00,10,40,38,A,B,0,234.89,200,194,202459,78861,234.12,234.89,200,200,0,0,,,0,0,0,0,,,0,0,0,0,,,0,0,0,0,,,0,0,0,0,,,0,0,0,0,,,0,0,0,0,,,0,0,0,0,,,0,0,0,0,,,0,0,0,0,AAPL
2024-10-22 12:30:41.087545113+00:00,10,41,38,A,B,0,234.83,200,194,57347,137212,234.18,234.83,200,200,0,0,,,0,0,0,0,,,0,0,0,0,,,0,0,0,0,,,0,0,0,0,,,0,0,0,0,,,0,0,0,0,,,0,0,0,0,,,0,0,0,0,,,0,0,0,0,AAPL
2024-10-22 12:30:41.088218144+00:00,10,39,38,C,A,0,236.8,2000,130,203979,49135,233.6,,2000,0,1,0,,,0,0,0,0,,,0,0,0,0,,,0,0,0,0,,,0,0,0,0,,,0,0,0,0,,,0,0,0,0,,,0,0,0,0,,,0,0,0,0,,,0,0,0,0,AAPL
2024-10-22 12:30:41.095269141+00:00,10,40,38,A,B,0,234.89,200,194,202335,78862,,234.89,0,200,0,0,,,0,0,0,0,,,0,0,0,0,,,0,0,0,0,,,0,0,0,0,,,0,0,0,0,,,0,0,0,0,,,0,0,0,0,,,0,0,0,0,,,0,0,0,0,AAPL
2024-10-22 12:30:41.124305074+00:00,10,39,38,A,A,0,236.8,2000,130,203123,49136,233.6,236.8,2000,2000,1,1,,,0,0,0,0,,,0,0,0,0,,,0,0,0,0,,,0,0,0,0,,,0,0,0,0,,,0,0,0,0,,,0,0,0,0,,,0,0,0,0,,,0,0,0,0,AAPL
2024-10-22 12:30:41.124944803+00:00,10,41,38,A,B,0,234.83,200,194,55227,137218,,234.83,0,200,0,0,,,0,0,0,0,,,0,0,0,0,,,0,0,0,0,,,0,0,0,0,,,0,0,0,0,,,0,0,0,0,,,0,0,0,0,,,0,0,0,0,,,0,0,0,0,AAPL
2024-10-22 12:30:41.239798729+00:00,10,41,38,A,A,0,,0,194,56149,137223,,,0,0,0,0,,,0,0,0,0,,,0,0,0,0,,,0,0,0,0,,,0,0,0,0,,,0,0,0,0,,,0,0,0,0,,,0,0,0,0,,,0,0,0,0,,,0,0,0,0,AAPL
2024-10-22 12:30:41.239840242+00:00,10,41,38,A,A,0,234.9,200,194,54871,137224,,234.9,0,200,0,0,,,0,0,0,0,,,0,0,0,0,,,0,0,0,0,,,0,0,0,0,,,0,0,0,0,,,0,0,0,0,,,0,0,0,0,,,0,0,0,0,,,0,0,0,0,AAPL
2024-10-22 12:30:42.951861292+00:00,10,41,38,A,A,0,,0,194,55879,137287,,,0,0,0,0,,,0,0,0,0,,,0,0,0,0,,,0,0,0,0,,,0,0,0,0,,,0,0,0,0,,,0,0,0,0,,,0,0,0,0,,,0,0,0,0,,,0,0,0,0,AAPL
2024-10-22 12:30:43.454765458+00:00,10,41,38,A,A,0,234.9,200,194,55885,137304,,234.9,0,200,0,0,,,0,0,0,0,,,0,0,0,0,,,0,0,0,0,,,0,0,0,0,,,0,0,0,0,,,0,0,0,0,,,0,0,0,0,,,0,0,0,0,,,0,0,0,0,AAPL
2024-10-22 12:30:44.660028365+00:00,10,40,38,A,B,0,234.89,200,194,202445,78881,234.13,234.89,200,200,0,0,,,0,0,0,0,,,0,0,0,0,,,0,0,0,0,,,0,0,0,0,,,0,0,0,0,,,0,0,0,0,,,0,0,0,0,,,0,0,0,0,,,0,0,0,0,AAPL
2024-10-22 12:30:45.166359933+00:00,10,40,38,A,A,0,,0,194,202621,78894,234.13,,200,0,0,0,,,0,0,0,0,,,0,0,0,0,,,0,0,0,0,,,0,0,0,0,,,0,0,0,0,,,0,0,0,0,,,0,0,0,0,,,0,0,0,0,,,0,0,0,0,AAPL
2024-10-22 12:30:47.076093301+00:00,10,40,38,A,B,0,,0,194,202518,78903,,,0,0,0,0,,,0,0,0,0,,,0,0,0,0,,,0,0,0,0,,,0,0,0,0,,,0,0,0,0,,,0,0,0,0,,,0,0,0,0,,,0,0,0,0,,,0,0,0,0,AAPL
2024-10-22 12:30:47.076439394+00:00,10,41,38,A,A,0,,0,194,55734,137488,,,0,0,0,0,,,0,0,0,0,,,0,0,0,0,,,0,0,0,0,,,0,0,0,0,,,0,0,0,0,,,0,0,0,0,,,0,0,0,0,,,0,0,0,0,,,0,0,0,0,AAPL
2024-10-22 12:30:48.813675978+00:00,10,39,38,C,B,0,233.6,2000,130,203284,49148,,236.8,0,2000,0,1,,,0,0,0,0,,,0,0,0,0,,,0,0,0,0,,,0,0,0,0,,,0,0,0,0,,,0,0,0,0,,,0,0,0,0,,,0,0,0,0,,,0,0,0,0,AAPL
2024-10-22 12:30:48.824591598+00:00,10,39,38,A,B,0,233.2,2000,130,203515,49149,233.2,236.8,2000,2000,1,1,,,0,0,0,0,,,0,0,0,0,,,0,0,0,0,,,0,0,0,0,,,0,0,0,0,,,0,0,0,0,,,0,0,0,0,,,0,0,0,0,,,0,0,0,0,AAPL
2024-10-22 12:30:49.051909071+00:00,10,41,38,A,A,0,234.9,200,194,55957,137605,,234.9,0,200,0,0,,,0,0,0,0,,,0,0,0,0,,,0,0,0,0,,,0,0,0,0,,,0,0,0,0,,,0,0,0,0,,,0,0,0,0,,,0,0,0,0,,,0,0,0,0,AAPL
2024-10-22 12:30:51.470483890+00:00,10,40,38,A,A,0,234.96,200,194,202429,78968,,234.96,0,200,0,0,,,0,0,0,0,,,0,0,0,0,,,0,0,0,0,,,0,0,0,0,,,0,0,0,0,,,0,0,0,0,,,0,0,0,0,,,0,0,0,0,,,0,0,0,0,AAPL
2024-10-22 12:30:51.470611775+00:00,10,40,38,A,B,0,234.96,200,194,202432,78969,234.15,234.96,200,200,0,0,,,0,0,0,0,,,0,0,0,0,,,0,0,0,0,,,0,0,0,0,,,0,0,0,0,,,0,0,0,0,,,0,0,0,0,,,0,0,0,0,,,0,0,0,0,AAPL
2024-10-22 12:30:55.369288670+00:00,10,40,38,A,A,0,,0,194,202507,79028,234.15,,200,0,0,0,,,0,0,0,0,,,0,0,0,0,,,0,0,0,0,,,0,0,0,0,,,0,0,0,0,,,0,0,0,0,,,0,0,0,0,,,0,0,0,0,,,0,0,0,0,AAPL
2024-10-22 12:30:55.369371684+00:00,10,40,38,A,B,0,,0,194,202494,79029,,,0,0,0,0,,,0,0,0,0,,,0,0,0,0,,,0,0,0,0,,,0,0,0,0,,,0,0,0,0,,,0,0,0,0,,,0,0,0,0,,,0,0,0,0,,,0,0,0,0,AAPL
2024-10-22 12:30:55.810062204+00:00,10,41,38,A,A,0,,0,194,55486,137826,,,0,0,0,0,,,0,0,0,0,,,0,0,0,0,,,0,0,0,0,,,0,0,0,0,,,0,0,0,0,,,0,0,0,0,,,0,0,0,0,,,0,0,0,0,,,0,0,0,0,AAPL
2024-10-22 12:31:01.836375890+00:00,10,40,38,A,A,0,234.93,200,194,202704,79385,,234.93,0,200,0,0,,,0,0,0,0,,,0,0,0,0,,,0,0,0,0,,,0,0,0,0,,,0,0,0,0,,,0,0,0,0,,,0,0,0,0,,,0,0,0,0,,,0,0,0,0,AAPL
2024-10-22 12:31:02.035951762+00:00,10,41,38,A,A,0,234.87,200,194,55914,139184,,234.87,0,200,0,0,,,0,0,0,0,,,0,0,0,0,,,0,0,0,0,,,0,0,0,0,,,0,0,0,0,,,0,0,0,0,,,0,0,0,0,,,0,0,0,0,,,0,0,0,0,AAPL
2024-10-22 12:31:11.334476960+00:00,10,41,38,A,B,0,234.87,200,194,55835,139777,234.19,234.87,200,200,0,0,,,0,0,0,0,,,0,0,0,0,,,0,0,0,0,,,0,0,0,0,,,0,0,0,0,,,0,0,0,0,,,0,0,0,0,,,0,0,0,0,,,0,0,0,0,AAPL
2024-10-22 12:31:11.420915586+00:00,10,41,38,A,B,0,234.87,200,194,60825,139778,,234.87,0,200,0,0,,,0,0,0,0,,,0,0,0,0,,,0,0,0,0,,,0,0,0,0,,,0,0,0,0,,,0,0,0,0,,,0,0,0,0,,,0,0,0,0,,,0,0,0,0,AAPL
2024-10-22 12:31:12.420617237+00:00,10,39,38,A,B,0,233.6,2000,130,203763,49386,233.6,236.8,2000,2000,1,1,233.2,,2000,0,1,0,,,0,0,0,0,,,0,0,0,0,,,0,0,0,0,,,0,0,0,0,,,0,0,0,0,,,0,0,0,0,,,0,0,0,0,,,0,0,0,0,AAPL
2024-10-22 12:31:12.420782683+00:00,10,39,38,C,B,1,233.2,2000,130,203329,49387,233.6,236.8,2000,2000,1,1,,,0,0,0,0,,,0,0,0,0,,,0,0,0,0,,,0,0,0,0,,,0,0,0,0,,,0,0,0,0,,,0,0,0,0,,,0,0,0,0,,,0,0,0,0,AAPL
2024-10-22 12:31:12.697717586+00:00,10,40,38,A,A,0,,0,194,202842,79613,,,0,0,0,0,,,0,0,0,0,,,0,0,0,0,,,0,0,0,0,,,0,0,0,0,,,0,0,0,0,,,0,0,0,0,,,0,0,0,0,,,0,0,0,0,,,0,0,0,0,AAPL
2024-10-22 12:31:12.698199920+00:00,10,41,38,A,A,0,,0,194,56370,139821,,,0,0,0,0,,,0,0,0,0,,,0,0,0,0,,,0,0,0,0,,,0,0,0,0,,,0,0,0,0,,,0,0,0,0,,,0,0,0,0,,,0,0,0,0,,,0,0,0,0,AAPL
2024-10-22 12:31:15.241095051+00:00,10,40,38,A,B,0,,0,194,202822,79658,234.12,,200,0,0,0,,,0,0,0,0,,,0,0,0,0,,,0,0,0,0,,,0,0,0,0,,,0,0,0,0,,,0,0,0,0,,,0,0,0,0,,,0,0,0,0,,,0,0,0,0,AAPL
2024-10-22 12:31:15.241362961+00:00,10,41,38,A,B,0,,0,194,55936,139898,234.18,,200,0,0,0,,,0,0,0,0,,,0,0,0,0,,,0,0,0,0,,,0,0,0,0,,,0,0,0,0,,,0,0,0,0,,,0,0,0,0,,,0,0,0,0,,,0,0,0,0,AAPL
2024-10-22 12:31:15.329370965+00:00,10,40,38,A,B,0,,0,194,202786,79659,,,0,0,0,0,,,0,0,0,0,,,0,0,0,0,,,0,0,0,0,,,0,0,0,0,,,0,0,0,0,,,0,0,0,0,,,0,0,0,0,,,0,0,0,0,,,0,0,0,0,AAPL
2024-10-22 12:31:15.329526627+00:00,10,41,38,A,B,0,,0,194,55700,139899,,,0,0,0,0,,,0,0,0,0,,,0,0,0,0,,,0,0,0,0,,,0,0,0,0,,,0,0,0,0,,,0,0,0,0,,,0,0,0,0,,,0,0,0,0,,,0,0,0,0,AAPL
2024-10-22 12:31:17.426384231+00:00,10,40,38,A,A,0,234.93,200,194,202678,79675,,234.93,0,200,0,0,,,0,0,0,0,,,0,0,0,0,,,0,0,0,0,,,0,0,0,0,,,0,0,0,0,,,0,0,0,0,,,0,0,0,0,,,0,0,0,0,,,0,0,0,0,AAPL
2024-10-22 12:31:17.426503758+00:00,10,40,38,A,B,0,234.93,200,194,202621,79676,234.12,234.93,200,200,0,0,,,0,0,0,0,,,0,0,0,0,,,0,0,0,0,,,0,0,0,0,,,0,0,0,0,,,0,0,0,0,,,0,0,0,0,,,0,0,0,0,,,0,0,0,0,AAPL
2024-10-22 12:31:17.426958036+00:00,10,41,38,A,A,0,234.87,200,194,55636,139993,,234.87,0,200,0,0,,,0,0,0,0,,,0,0,0,0,,,0,0,0,0,,,0,0,0,0,,,0,0,0,0,,,0,0,0,0,,,0,0,0,0,,,0,0,0,0,,,0,0,0,0,AAPL
2024-10-22 12:31:17.930881391+00:00,10,40,38,A,B,0,234.93,200,194,202724,79679,,234.93,0,200,0,0,,,0,0,0,0,,,0,0,0,0,,,0,0,0,0,,,0,0,0,0,,,0,0,0,0,,,0,0,0,0,,,0,0,0,0,,,0,0,0,0,,,0,0,0,0,AAPL
2024-10-22 12:31:20.145604250+00:00,10,40,38,A,A,0,,0,194,202921,79719,,,0,0,0,0,,,0,0,0,0,,,0,0,0,0,,,0,0,0,0,,,0,0,0,0,,,0,0,0,0,,,0,0,0,0,,,0,0,0,0,,,0,0,0,0,,,0,0,0,0,AAPL
2024-10-22 12:31:20.145628596+00:00,10,40,38,A,A,0,234.91,200,194,202916,79720,,234.91,0,200,0,0,,,0,0,0,0,,,0,0,0,0,,,0,0,0,0,,,0,0,0,0,,,0,0,0,0,,,0,0,0,0,,,0,0,0,0,,,0,0,0,0,,,0,0,0,0,AAPL
2024-10-22 12:31:20.145745555+00:00,10,40,38,A,B,0,234.91,200,194,202917,79721,234.12,234.91,200,200,0,0,,,0,0,0,0,,,0,0,0,0,,,0,0,0,0,,,0,0,0,0,,,0,0,0,0,,,0,0,0,0,,,0,0,0,0,,,0,0,0,0,,,0,0,0,0,AAPL
2024-10-22 12:31:20.236350858+00:00,10,40,38,A,B,0,234.91,200,194,202889,79723,,234.91,0,200,0,0,,,0,0,0,0,,,0,0,0,0,,,0,0,0,0,,,0,0,0,0,,,0,0,0,0,,,0,0,0,0,,,0,0,0,0,,,0,0,0,0,,,0,0,0,0,AAPL
2024-10-22 12:31:24.201944217+00:00,10,40,38,A,B,0,234.91,200,194,203009,79756,234.12,234.91,200,200,0,0,,,0,0,0,0,,,0,0,0,0,,,0,0,0,0,,,0,0,0,0,,,0,0,0,0,,,0,0,0,0,,,0,0,0,0,,,0,0,0,0,,,0,0,0,0,AAPL
2024-10-22 12:31:24.202196173+00:00,10,41,38,A,B,0,234.87,200,194,61254,140196,234.18,234.87,200,200,0,0,,,0,0,0,0,,,0,0,0,0,,,0,0,0,0,,,0,0,0,0,,,0,0,0,0,,,0,0,0,0,,,0,0,0,0,,,0,0,0,0,,,0,0,0,0,AAPL
2024-10-22 12:31:24.305317698+00:00,10,40,38,A,B,0,234.91,200,194,203022,79757,,234.91,0,200,0,0,,,0,0,0,0,,,0,0,0,0,,,0,0,0,0,,,0,0,0,0,,,0,0,0,0,,,0,0,0,0,,,0,0,0,0,,,0,0,0,0,,,0,0,0,0,AAPL
2024-10-22 12:31:24.305562914+00:00,10,41,38,A,B,0,234.87,200,194,55249,140200,,234.87,0,200,0,0,,,0,0,0,0,,,0,0,0,0,,,0,0,0,0,,,0,0,0,0,,,0,0,0,0,,,0,0,0,0,,,0,0,0,0,,,0,0,0,0,,,0,0,0,0,AAPL
2024-10-22 12:31:26.198222237+00:00,10,40,38,A,B,0,234.91,200,194,203009,79774,234.12,234.91,200,200,0,0,,,0,0,0,0,,,0,0,0,0,,,0,0,0,0,,,0,0,0,0,,,0,0,0,0,,,0,0,0,0,,,0,0,0,0,,,0,0,0,0,,,0,0,0,0,AAPL
2024-10-22 12:31:26.198738701+00:00,10,41,38,A,B,0,234.87,200,194,55742,140267,234.18,234.87,200,200,0,0,,,0,0,0,0,,,0,0,0,0,,,0,0,0,0,,,0,0,0,0,,,0,0,0,0,,,0,0,0,0,,,0,0,0,0,,,0,0,0,0,,,0,0,0,0,AAPL
2024-10-22 12:31:26.216535630+00:00,10,39,38,C,B,0,233.6,2000,130,203764,49474,,236.8,0,2000,0,1,,,0,0,0,0,,,0,0,0,0,,,0,0,0,0,,,0,0,0,0,,,0,0,0,0,,,0,0,0,0,,,0,0,0,0,,,0,0,0,0,,,0,0,0,0,AAPL
2024-10-22 12:31:26.253913730+00:00,10,39,38,A,B,0,233.6,2000,130,203670,49475,233.6,236.8,2000,2000,1,1,,,0,0,0,0,,,0,0,0,0,,,0,0,0,0,,,0,0,0,0,,,0,0,0,0,,,0,0,0,0,,,0,0,0,0,,,0,0,0,0,,,0,0,0,0,AAPL
2024-10-22 12:31:26.275489766+00:00,10,39,38,C,B,0,233.6,2000,130,203498,49476,,236.8,0,2000,0,1,,,0,0,0,0,,,0,0,0,0,,,0,0,0,0,,,0,0,0,0,,,0,0,0,0,,,0,0,0,0,,,0,0,0,0,,,0,0,0,0,,,0,0,0,0,AAPL
2024-10-22 12:31:26.286841042+00:00,10,39,38,A,B,0,233.2,2000,130,203532,49477,233.2,236.8,2000,2000,1,1,,,0,0,0,0,,,0,0,0,0,,,0,0,0,0,,,0,0,0,0,,,0,0,0,0,,,0,0,0,0,,,0,0,0,0,,,0,0,0,0,,,0,0,0,0,AAPL
2024-10-22 12:31:26.302295583+00:00,10,39,38,A,B,0,233.6,2000,130,203426,49478,233.6,236.8,2000,2000,1,1,233.2,,2000,0,1,0,,,0,0,0,0,,,0,0,0,0,,,0,0,0,0,,,0,0,0,0,,,0,0,0,0,,,0,0,0,0,,,0,0,0,0,,,0,0,0,0,AAPL
2024-10-22 12:31:26.302568270+00:00,10,39,38,C,B,1,233.2,2000,130,203386,49479,233.6,236.8,2000,2000,1,1,,,0,0,0,0,,,0,0,0,0,,,0,0,0,0,,,0,0,0,0,,,0,0,0,0,,,0,0,0,0,,,0,0,0,0,,,0,0,0,0,,,0,0,0,0,AAPL
2024-10-22 12:31:26.309211162+00:00,10,39,38,C,B,0,233.6,2000,130,203461,49480,,236.8,0,2000,0,1,,,0,0,0,0,,,0,0,0,0,,,0,0,0,0,,,0,0,0,0,,,0,0,0,0,,,0,0,0,0,,,0,0,0,0,,,0,0,0,0,,,0,0,0,0,AAPL
2024-10-22 12:31:26.321021923+00:00,10,39,38,A,B,0,233.2,2000,130,203452,49481,233.2,236.8,2000,2000,1,1,,,0,0,0,0,,,0,0,0,0,,,0,0,0,0,,,0,0,0,0,,,0,0,0,0,,,0,0,0,0,,,0,0,0,0,,,0,0,0,0,,,0,0,0,0,AAPL
2024-10-22 12:31:26.332324093+00:00,10,39,38,A,B,0,233.6,2000,130,203431,49482,233.6,236.8,2000,2000,1,1,233.2,,2000,0,1,0,,,0,0,0,0,,,0,0,0,0,,,0,0,0,0,,,0,0,0,0,,,0,0,0,0,,,0,0,0,0,,,0,0,0,0,,,0,0,0,0,AAPL
2024-10-22 12:31:26.332774263+00:00,10,39,38,C,B,1,233.2,2000,130,203395,49483,233.6,236.8,2000,2000,1,1,,,0,0,0,0,,,0,0,0,0,,,0,0,0,0,,,0,0,0,0,,,0,0,0,0,,,0,0,0,0,,,0,0,0,0,,,0,0,0,0,,,0,0,0,0,AAPL
2024-10-22 12:31:29.071704403+00:00,10,40,38,A,A,0,,0,194,203242,79832,234.12,,200,0,0,0,,,0,0,0,0,,,0,0,0,0,,,0,0,0,0,,,0,0,0,0,,,0,0,0,0,,,0,0,0,0,,,0,0,0,0,,,0,0,0,0,,,0,0,0,0,AAPL
2024-10-22 12:31:29.071733274+00:00,10,40,38,A,A,0,234.9,200,194,203032,79833,234.12,234.9,200,200,0,0,,,0,0,0,0,,,0,0,0,0,,,0,0,0,0,,,0,0,0,0,,,0,0,0,0,,,0,0,0,0,,,0,0,0,0,,,0,0,0,0,,,0,0,0,0,AAPL
2024-10-22 12:31:30.101857181+00:00,10,41,38,A,B,0,234.87,200,194,55607,140498,,234.87,0,200,0,0,,,0,0,0,0,,,0,0,0,0,,,0,0,0,0,,,0,0,0,0,,,0,0,0,0,,,0,0,0,0,,,0,0,0,0,,,0,0,0,0,,,0,0,0,0,AAPL
2024-10-22 12:31:30.101924889+00:00,10,41,38,A,B,0,234.87,200,194,54506,140499,234.11,234.87,200,200,0,0,,,0,0,0,0,,,0,0,0,0,,,0,0,0,0,,,0,0,0,0,,,0,0,0,0,,,0,0,0,0,,,0,0,0,0,,,0,0,0,0,,,0,0,0,0,AAPL
2024-10-22 12:31:34.728704740+00:00,10,39,38,C,B,0,233.6,2000,130,203780,49529,,236.8,0,2000,0,1,,,0,0,0,0,,,0,0,0,0,,,0,0,0,0,,,0,0,0,0,,,0,0,0,0,,,0,0,0,0,,,0,0,0,0,,,0,0,0,0,,,0,0,0,0,AAPL
2024-10-22 12:31:34.740551264+00:00,10,39,38,A,B,0,233.2,2000,130,203442,49533,233.2,236.8,2000,2000,1,1,,,0,0,0,0,,,0,0,0,0,,,0,0,0,0,,,0,0,0,0,,,0,0,0,0,,,0,0,0,0,,,0,0,0,0,,,0,0,0,0,,,0,0,0,0,AAPL
2024-10-22 12:31:35.913839331+00:00,10,39,38,A,B,0,233.6,2000,130,203475,49543,233.6,236.8,2000,2000,1,1,233.2,,2000,0,1,0,,,0,0,0,0,,,0,0,0,0,,,0,0,0,0,,,0,0,0,0,,,0,0,0,0,,,0,0,0,0,,,0,0,0,0,,,0,0,0,0,AAPL
2024-10-22 12:31:35.914568648+00:00,10,39,38,C,B,1,233.2,2000,130,203482,49544,233.6,236.8,2000,2000,1,1,,,0,0,0,0,,,0,0,0,0,,,0,0,0,0,,,0,0,0,0,,,0,0,0,0,,,0,0,0,0,,,0,0,0,0,,,0,0,0,0,,,0,0,0,0,AAPL
2024-10-22 12:31:52.161682849+00:00,10,39,38,C,A,0,236.8,2000,130,203417,49745,233.6,,2000,0,1,0,,,0,0,0,0,,,0,0,0,0,,,0,0,0,0,,,0,0,0,0,,,0,0,0,0,,,0,0,0,0,,,0,0,0,0,,,0,0,0,0,,,0,0,0,0,AAPL
2024-10-22 12:31:57.453709602+00:00,10,39,38,A,A,0,236.8,2000,130,203715,49842,233.6,236.8,2000,2000,1,1,,,0,0,0,0,,,0,0,0,0,,,0,0,0,0,,,0,0,0,0,,,0,0,0,0,,,0,0,0,0,,,0,0,0,0,,,0,0,0,0,,,0,0,0,0,AAPL
2024-10-22 12:31:57.510906359+00:00,10,39,38,C,A,0,236.8,2000,130,203460,49843,233.6,,2000,0,1,0,,,0,0,0,0,,,0,0,0,0,,,0,0,0,0,,,0,0,0,0,,,0,0,0,0,,,0,0,0,0,,,0,0,0,0,,,0,0,0,0,,,0,0,0,0,AAPL
2024-10-22 12:32:00.028105432+00:00,10,41,38,A,A,0,,0,194,54920,141689,234.11,,200,0,0,0,,,0,0,0,0,,,0,0,0,0,,,0,0,0,0,,,0,0,0,0,,,0,0,0,0,,,0,0,0,0,,,0,0,0,0,,,0,0,0,0,,,0,0,0,0,AAPL
2024-10-22 12:32:00.095339477+00:00,10,40,38,A,A,0,,0,194,203501,80348,234.12,,200,0,0,0,,,0,0,0,0,,,0,0,0,0,,,0,0,0,0,,,0,0,0,0,,,0,0,0,0,,,0,0,0,0,,,0,0,0,0,,,0,0,0,0,,,0,0,0,0,AAPL
2024-10-22 12:32:00.136777201+00:00,10,40,38,A,A,0,234.9,200,194,203643,80378,234.12,234.9,200,200,0,0,,,0,0,0,0,,,0,0,0,0,,,0,0,0,0,,,0,0,0,0,,,0,0,0,0,,,0,0,0,0,,,0,0,0,0,,,0,0,0,0,,,0,0,0,0,AAPL
2024-10-22 12:32:00.137271736+00:00,10,41,38,A,A,0,234.83,200,194,54608,142240,234.11,234.83,200,200,0,0,,,0,0,0,0,,,0,0,0,0,,,0,0,0,0,,,0,0,0,0,,,0,0,0,0,,,0,0,0,0,,,0,0,0,0,,,0,0,0,0,,,0,0,0,0,AAPL
2024-10-22 12:32:00.143527665+00:00,10,41,38,A,A,0,,0,194,56561,142252,234.11,,200,0,0,0,,,0,0,0,0,,,0,0,0,0,,,0,0,0,0,,,0,0,0,0,,,0,0,0,0,,,0,0,0,0,,,0,0,0,0,,,0,0,0,0,,,0,0,0,0,AAPL
2024-10-22 12:32:00.230152050+00:00,10,40,38,A,A,0,,0,194,203542,80409,234.12,,200,0,0,0,,,0,0,0,0,,,0,0,0,0,,,0,0,0,0,,,0,0,0,0,,,0,0,0,0,,,0,0,0,0,,,0,0,0,0,,,0,0,0,0,,,0,0,0,0,AAPL
2024-10-22 12:32:12.697222400+00:00,10,40,38,A,A,0,234.93,200,194,204030,80675,234.12,234.93,200,200,0,0,,,0,0,0,0,,,0,0,0,0,,,0,0,0,0,,,0,0,0,0,,,0,0,0,0,,,0,0,0,0,,,0,0,0,0,,,0,0,0,0,,,0,0,0,0,AAPL
2024-10-22 12:32:12.697432998+00:00,10,41,38,A,A,0,234.86,200,194,56184,143205,234.11,234.86,200,200,0,0,,,0,0,0,0,,,0,0,0,0,,,0,0,0,0,,,0,0,0,0,,,0,0,0,0,,,0,0,0,0,,,0,0,0,0,,,0,0,0,0,,,0,0,0,0,AAPL
2024-10-22 12:32:12.798143795+00:00,10,40,38,A,B,0,234.93,200,194,204085,80676,,234.93,0,200,0,0,,,0,0,0,0,,,0,0,0,0,,,0,0,0,0,,,0,0,0,0,,,0,0,0,0,,,0,0,0,0,,,0,0,0,0,,,0,0,0,0,,,0,0,0,0,AAPL
2024-10-22 12:32:12.798415319+00:00,10,41,38,A,B,0,234.86,200,194,55212,143207,,234.86,0,200,0,0,,,0,0,0,0,,,0,0,0,0,,,0,0,0,0,,,0,0,0,0,,,0,0,0,0,,,0,0,0,0,,,0,0,0,0,,,0,0,0,0,,,0,0,0,0,AAPL
2024-10-22 12:32:13.276877258+00:00,10,40,38,A,B,0,234.93,200,194,204068,80679,234.07,234.93,200,200,0,0,,,0,0,0,0,,,0,0,0,0,,,0,0,0,0,,,0,0,0,0,,,0,0,0,0,,,0,0,0,0,,,0,0,0,0,,,0,0,0,0,,,0,0,0,0,AAPL
2024-10-22 12:32:13.277160870+00:00,10,41,38,A,B,0,234.86,200,194,55304,143231,234.14,234.86,200,200,0,0,,,0,0,0,0,,,0,0,0,0,,,0,0,0,0,,,0,0,0,0,,,0,0,0,0,,,0,0,0,0,,,0,0,0,0,,,0,0,0,0,,,0,0,0,0,AAPL
2024-10-22 12:32:13.279197126+00:00,10,40,38,A,A,0,,0,194,204029,80680,234.07,,200,0,0,0,,,0,0,0,0,,,0,0,0,0,,,0,0,0,0,,,0,0,0,0,,,0,0,0,0,,,0,0,0,0,,,0,0,0,0,,,0,0,0,0,,,0,0,0,0,AAPL
2024-10-22 12:32:13.279454692+00:00,10,41,38,A,A,0,,0,194,56536,143239,234.14,,200,0,0,0,,,0,0,0,0,,,0,0,0,0,,,0,0,0,0,,,0,0,0,0,,,0,0,0,0,,,0,0,0,0,,,0,0,0,0,,,0,0,0,0,,,0,0,0,0,AAPL
2024-10-22 12:32:13.279365058+00:00,10,40,38,A,B,0,,0,194,203950,80682,,,0,0,0,0,,,0,0,0,0,,,0,0,0,0,,,0,0,0,0,,,0,0,0,0,,,0,0,0,0,,,0,0,0,0,,,0,0,0,0,,,0,0,0,0,,,0,0,0,0,AAPL
2024-10-22 12:32:13.290314772+00:00,10,39,38,A,A,0,236.8,2000,130,203807,50110,233.6,236.8,2000,2000,1,1,,,0,0,0,0,,,0,0,0,0,,,0,0,0,0,,,0,0,0,0,,,0,0,0,0,,,0,0,0,0,,,0,0,0,0,,,0,0,0,0,,,0,0,0,0,AAPL
2024-10-22 12:32:13.775629469+00:00,10,40,38,A,A,0,234.93,200,194,204074,80689,,234.93,0,200,0,0,,,0,0,0,0,,,0,0,0,0,,,0,0,0,0,,,0,0,0,0,,,0,0,0,0,,,0,0,0,0,,,0,0,0,0,,,0,0,0,0,,,0,0,0,0,AAPL
2024-10-22 12:32:13.775831206+00:00,10,41,38,A,A,0,234.86,200,194,55684,143280,234.14,234.86,200,200,0,0,,,0,0,0,0,,,0,0,0,0,,,0,0,0,0,,,0,0,0,0,,,0,0,0,0,,,0,0,0,0,,,0,0,0,0,,,0,0,0,0,,,0,0,0,0,AAPL
2024-10-22 12:32:13.987005649+00:00,10,40,38,A,B,0,234.93,200,194,204095,80694,234.05,234.93,200,200,0,0,,,0,0,0,0,,,0,0,0,0,,,0,0,0,0,,,0,0,0,0,,,0,0,0,0,,,0,0,0,0,,,0,0,0,0,,,0,0,0,0,,,0,0,0,0,AAPL
2024-10-22 12:32:16.446911322+00:00,10,41,38,A,B,0,234.86,200,194,59996,143467,,234.86,0,200,0,0,,,0,0,0,0,,,0,0,0,0,,,0,0,0,0,,,0,0,0,0,,,0,0,0,0,,,0,0,0,0,,,0,0,0,0,,,0,0,0,0,,,0,0,0,0,AAPL
2024-10-22 12:32:16.446974647+00:00,10,41,38,A,B,0,234.86,200,194,54911,143468,234.12,234.86,200,200,0,0,,,0,0,0,0,,,0,0,0,0,,,0,0,0,0,,,0,0,0,0,,,0,0,0,0,,,0,0,0,0,,,0,0,0,0,,,0,0,0,0,,,0,0,0,0,AAPL
2024-10-22 12:32:17.461749425+00:00,10,41,38,A,B,0,234.86,200,194,60075,143502,,234.86,0,200,0,0,,,0,0,0,0,,,0,0,0,0,,,0,0,0,0,,,0,0,0,0,,,0,0,0,0,,,0,0,0,0,,,0,0,0,0,,,0,0,0,0,,,0,0,0,0,AAPL
2024-10-22 12:32:18.944369804+00:00,10,41,38,A,B,0,234.86,200,194,55728,143566,234.12,234.86,200,200,0,0,,,0,0,0,0,,,0,0,0,0,,,0,0,0,0,,,0,0,0,0,,,0,0,0,0,,,0,0,0,0,,,0,0,0,0,,,0,0,0,0,,,0,0,0,0,AAPL
2024-10-22 12:32:19.434110380+00:00,10,39,38,C,A,0,236.8,2000,130,203870,50173,233.6,,2000,0,1,0,,,0,0,0,0,,,0,0,0,0,,,0,0,0,0,,,0,0,0,0,,,0,0,0,0,,,0,0,0,0,,,0,0,0,0,,,0,0,0,0,,,0,0,0,0,AAPL
2024-10-22 12:32:19.485036787+00:00,10,40,38,A,A,0,,0,194,204193,80780,234.05,,200,0,0,0,,,0,0,0,0,,,0,0,0,0,,,0,0,0,0,,,0,0,0,0,,,0,0,0,0,,,0,0,0,0,,,0,0,0,0,,,0,0,0,0,,,0,0,0,0,AAPL
2024-10-22 12:32:19.485462162+00:00,10,41,38,A,A,0,,0,194,55848,143623,234.12,,200,0,0,0,,,0,0,0,0,,,0,0,0,0,,,0,0,0,0,,,0,0,0,0,,,0,0,0,0,,,0,0,0,0,,,0,0,0,0,,,0,0,0,0,,,0,0,0,0,AAPL
2024-10-22 12:32:19.489534615+00:00,10,39,38,A,A,0,236.8,2000,130,203940,50174,233.6,236.8,2000,2000,1,1,,,0,0,0,0,,,0,0,0,0,,,0,0,0,0,,,0,0,0,0,,,0,0,0,0,,,0,0,0,0,,,0,0,0,0,,,0,0,0,0,,,0,0,0,0,AAPL
2024-10-22 12:32:19.493913054+00:00,10,39,38,C,A,0,236.8,2000,130,203830,50175,233.6,,2000,0,1,0,,,0,0,0,0,,,0,0,0,0,,,0,0,0,0,,,0,0,0,0,,,0,0,0,0,,,0,0,0,0,,,0,0,0,0,,,0,0,0,0,,,0,0,0,0,AAPL
2024-10-22 12:32:19.514047995+00:00,10,39,38,A,A,0,236.8,2000,130,203884,50176,233.6,236.8,2000,2000,1,1,,,0,0,0,0,,,0,0,0,0,,,0,0,0,0,,,0,0,0,0,,,0,0,0,0,,,0,0,0,0,,,0,0,0,0,,,0,0,0,0,,,0,0,0,0,AAPL
2024-10-22 12:32:19.530648196+00:00,10,39,38,C,A,0,236.8,2000,130,203882,50178,233.6,,2000,0,1,0,,,0,0,0,0,,,0,0,0,0,,,0,0,0,0,,,0,0,0,0,,,0,0,0,0,,,0,0,0,0,,,0,0,0,0,,,0,0,0,0,,,0,0,0,0,AAPL
2024-10-22 12:32:19.563843212+00:00,10,39,38,A,A,0,236.8,2000,130,203876,50182,233.6,236.8,2000,2000,1,1,,,0,0,0,0,,,0,0,0,0,,,0,0,0,0,,,0,0,0,0,,,0,0,0,0,,,0,0,0,0,,,0,0,0,0,,,0,0,0,0,,,0,0,0,0,AAPL
2024-10-22 12:32:19.810722072+00:00,10,40,38,A,A,0,234.87,200,194,204189,80789,234.05,234.87,200,200,0,0,,,0,0,0,0,,,0,0,0,0,,,0,0,0,0,,,0,0,0,0,,,0,0,0,0,,,0,0,0,0,,,0,0,0,0,,,0,0,0,0,,,0,0,0,0,AAPL
2024-10-22 12:32:19.910566537+00:00,10,41,38,A,B,0,,0,194,55576,143640,,,0,0,0,0,,,0,0,0,0,,,0,0,0,0,,,0,0,0,0,,,0,0,0,0,,,0,0,0,0,,,0,0,0,0,,,0,0,0,0,,,0,0,0,0,,,0,0,0,0,AAPL
2024-10-22 12:32:19.910637426+00:00,10,41,38,A,A,0,234.8,200,194,54275,143641,,234.8,0,200,0,0,,,0,0,0,0,,,0,0,0,0,,,0,0,0,0,,,0,0,0,0,,,0,0,0,0,,,0,0,0,0,,,0,0,0,0,,,0,0,0,0,,,0,0,0,0,AAPL
2024-10-22 12:32:25.991719198+00:00,10,40,38,A,B,0,234.87,200,194,204672,80858,,234.87,0,200,0,0,,,0,0,0,0,,,0,0,0,0,,,0,0,0,0,,,0,0,0,0,,,0,0,0,0,,,0,0,0,0,,,0,0,0,0,,,0,0,0,0,,,0,0,0,0,AAPL
2024-10-22 12:32:27.751918384+00:00,10,40,38,A,B,0,234.87,200,194,204715,80891,234.03,234.87,200,200,0,0,,,0,0,0,0,,,0,0,0,0,,,0,0,0,0,,,0,0,0,0,,,0,0,0,0,,,0,0,0,0,,,0,0,0,0,,,0,0,0,0,,,0,0,0,0,AAPL
2024-10-22 12:32:27.752973956+00:00,10,39,38,C,A,0,236.8,2000,130,203963,50347,233.6,,2000,0,1,0,,,0,0,0,0,,,0,0,0,0,,,0,0,0,0,,,0,0,0,0,,,0,0,0,0,,,0,0,0,0,,,0,0,0,0,,,0,0,0,0,,,0,0,0,0,AAPL
2024-10-22 12:32:27.840950456+00:00,10,41,38,A,B,0,234.8,200,194,56508,143991,234.1,234.8,200,200,0,0,,,0,0,0,0,,,0,0,0,0,,,0,0,0,0,,,0,0,0,0,,,0,0,0,0,,,0,0,0,0,,,0,0,0,0,,,0,0,0,0,,,0,0,0,0,AAPL
2024-10-22 12:32:27.841533518+00:00,10,39,38,C,B,0,233.6,2000,130,204165,50350,,,0,0,0,0,,,0,0,0,0,,,0,0,0,0,,,0,0,0,0,,,0,0,0,0,,,0,0,0,0,,,0,0,0,0,,,0,0,0,0,,,0,0,0,0,,,0,0,0,0,AAPL
2024-10-22 12:32:27.878385846+00:00,10,39,38,A,B,0,233.6,2000,130,204016,50352,233.6,,2000,0,1,0,,,0,0,0,0,,,0,0,0,0,,,0,0,0,0,,,0,0,0,0,,,0,0,0,0,,,0,0,0,0,,,0,0,0,0,,,0,0,0,0,,,0,0,0,0,AAPL
2024-10-22 12:32:28.249742200+00:00,10,41,38,A,B,0,234.8,200,194,55785,144010,,234.8,0,200,0,0,,,0,0,0,0,,,0,0,0,0,,,0,0,0,0,,,0,0,0,0,,,0,0,0,0,,,0,0,0,0,,,0,0,0,0,,,0,0,0,0,,,0,0,0,0,AAPL
2024-10-22 12:32:29.550114042+00:00,10,41,38,A,B,0,234.8,200,194,56079,144066,234.1,234.8,200,200,0,0,,,0,0,0,0,,,0,0,0,0,,,0,0,0,0,,,0,0,0,0,,,0,0,0,0,,,0,0,0,0,,,0,0,0,0,,,0,0,0,0,,,0,0,0,0,AAPL
2024-10-22 12:32:39.115372692+00:00,10,39,38,A,A,0,236.8,2000,130,204073,50444,233.6,236.8,2000,2000,1,1,,,0,0,0,0,,,0,0,0,0,,,0,0,0,0,,,0,0,0,0,,,0,0,0,0,,,0,0,0,0,,,0,0,0,0,,,0,0,0,0,,,0,0,0,0,AAPL
2024-10-22 12:32:57.409628275+00:00,10,39,38,C,B,0,233.6,2000,130,203904,50633,,236.8,0,2000,0,1,,,0,0,0,0,,,0,0,0,0,,,0,0,0,0,,,0,0,0,0,,,0,0,0,0,,,0,0,0,0,,,0,0,0,0,,,0,0,0,0,,,0,0,0,0,AAPL
2024-10-22 12:32:57.420588512+00:00,10,39,38,A,B,0,233.2,2000,130,203850,50634,233.2,236.8,2000,2000,1,1,,,0,0,0,0,,,0,0,0,0,,,0,0,0,0,,,0,0,0,0,,,0,0,0,0,,,0,0,0,0,,,0,0,0,0,,,0,0,0,0,,,0,0,0,0,AAPL
2024-10-22 12:33:00.043904233+00:00,10,40,38,A,B,0,234.87,200,194,204022,81342,,234.87,0,200,0,0,,,0,0,0,0,,,0,0,0,0,,,0,0,0,0,,,0,0,0,0,,,0,0,0,0,,,0,0,0,0,,,0,0,0,0,,,0,0,0,0,,,0,0,0,0,AAPL
2024-10-22 12:33:00.043914733+00:00,10,40,38,A,A,0,,0,194,204147,81343,,,0,0,0,0,,,0,0,0,0,,,0,0,0,0,,,0,0,0,0,,,0,0,0,0,,,0,0,0,0,,,0,0,0,0,,,0,0,0,0,,,0,0,0,0,,,0,0,0,0,AAPL
2024-10-22 12:33:00.138843668+00:00,10,40,38,A,B,0,,0,194,203974,81413,234.08,,200,0,0,0,,,0,0,0,0,,,0,0,0,0,,,0,0,0,0,,,0,0,0,0,,,0,0,0,0,,,0,0,0,0,,,0,0,0,0,,,0,0,0,0,,,0,0,0,0,AAPL
2024-10-22 12:33:00.138939759+00:00,10,40,38,A,A,0,234.92,200,194,203977,81414,234.08,234.92,200,200,0,0,,,0,0,0,0,,,0,0,0,0,,,0,0,0,0,,,0,0,0,0,,,0,0,0,0,,,0,0,0,0,,,0,0,0,0,,,0,0,0,0,,,0,0,0,0,AAPL
2024-10-22 12:33:00.371042947+00:00,10,39,10888,A,A,0,418.99,100,130,203702,76916,,418.99,0,100,0,1,,,0,0,0,0,,,0,0,0,0,,,0,0,0,0,,,0,0,0,0,,,0,0,0,0,,,0,0,0,0,,,0,0,0,0,,,0,0,0,0,,,0,0,0,0,MSFT
2024-10-22 12:33:00.490751335+00:00,10,40,38,A,A,0,,0,194,204044,81459,234.08,,200,0,0,0,,,0,0,0,0,,,0,0,0,0,,,0,0,0,0,,,0,0,0,0,,,0,0,0,0,,,0,0,0,0,,,0,0,0,0,,,0,0,0,0,,,0,0,0,0,AAPL
2024-10-22 12:33:03.496257267+00:00,10,40,38,A,A,0,234.92,200,194,203848,81522,234.08,234.92,200,200,0,0,,,0,0,0,0,,,0,0,0,0,,,0,0,0,0,,,0,0,0,0,,,0,0,0,0,,,0,0,0,0,,,0,0,0,0,,,0,0,0,0,,,0,0,0,0,AAPL
2024-10-22 12:33:04.393802775+00:00,10,40,38,A,B,0,234.92,200,194,203835,81526,,234.92,0,200,0,0,,,0,0,0,0,,,0,0,0,0,,,0,0,0,0,,,0,0,0,0,,,0,0,0,0,,,0,0,0,0,,,0,0,0,0,,,0,0,0,0,,,0,0,0,0,AAPL
2024-10-22 12:33:04.393827920+00:00,10,40,38,A,B,0,234.92,200,194,203776,81527,234.11,234.92,200,200,0,0,,,0,0,0,0,,,0,0,0,0,,,0,0,0,0,,,0,0,0,0,,,0,0,0,0,,,0,0,0,0,,,0,0,0,0,,,0,0,0,0,,,0,0,0,0,AAPL
2024-10-22 12:33:23.201051825+00:00,10,39,10888,C,A,0,418.99,100,130,204181,77045,,,0,0,0,0,,,0,0,0,0,,,0,0,0,0,,,0,0,0,0,,,0,0,0,0,,,0,0,0,0,,,0,0,0,0,,,0,0,0,0,,,0,0,0,0,,,0,0,0,0,MSFT
2024-10-22 12:33:23.730246294+00:00,10,40,10888,A,A,0,418.99,100,194,202302,81659,,418.99,0,100,0,0,,,0,0,0,0,,,0,0,0,0,,,0,0,0,0,,,0,0,0,0,,,0,0,0,0,,,0,0,0,0,,,0,0,0,0,,,0,0,0,0,,,0,0,0,0,MSFT
2024-10-22 12:33:26.904716956+00:00,10,39,38,C,A,0,236.8,2000,130,203746,50831,233.2,,2000,0,1,0,,,0,0,0,0,,,0,0,0,0,,,0,0,0,0,,,0,0,0,0,,,0,0,0,0,,,0,0,0,0,,,0,0,0,0,,,0,0,0,0,,,0,0,0,0,AAPL
2024-10-22 12:33:27.189828512+00:00,10,39,38,A,A,0,236.8,2000,130,203664,50834,233.2,236.8,2000,2000,1,1,,,0,0,0,0,,,0,0,0,0,,,0,0,0,0,,,0,0,0,0,,,0,0,0,0,,,0,0,0,0,,,0,0,0,0,,,0,0,0,0,,,0,0,0,0,AAPL
2024-10-22 12:33:32.115166681+00:00,10,39,38,C,A,0,236.8,2000,130,203694,50866,233.2,,2000,0,1,0,,,0,0,0,0,,,0,0,0,0,,,0,0,0,0,,,0,0,0,0,,,0,0,0,0,,,0,0,0,0,,,0,0,0,0,,,0,0,0,0,,,0,0,0,0,AAPL
2024-10-22 12:33:32.143051165+00:00,10,39,38,A,A,0,236.8,2000,130,203698,50867,233.2,236.8,2000,2000,1,1,,,0,0,0,0,,,0,0,0,0,,,0,0,0,0,,,0,0,0,0,,,0,0,0,0,,,0,0,0,0,,,0,0,0,0,,,0,0,0,0,,,0,0,0,0,AAPL
2024-10-22 12:33:32.164005449+00:00,10,39,38,C,A,0,236.8,2000,130,203632,50868,233.2,,2000,0,1,0,,,0,0,0,0,,,0,0,0,0,,,0,0,0,0,,,0,0,0,0,,,0,0,0,0,,,0,0,0,0,,,0,0,0,0,,,0,0,0,0,,,0,0,0,0,AAPL
2024-10-22 12:33:32.185335822+00:00,10,39,38,A,A,0,236.8,2000,130,203615,50869,233.2,236.8,2000,2000,1,1,,,0,0,0,0,,,0,0,0,0,,,0,0,0,0,,,0,0,0,0,,,0,0,0,0,,,0,0,0,0,,,0,0,0,0,,,0,0,0,0,,,0,0,0,0,AAPL
2024-10-22 12:33:35.532877132+00:00,10,39,38,C,B,0,233.2,2000,130,203484,50889,,236.8,0,2000,0,1,,,0,0,0,0,,,0,0,0,0,,,0,0,0,0,,,0,0,0,0,,,0,0,0,0,,,0,0,0,0,,,0,0,0,0,,,0,0,0,0,,,0,0,0,0,AAPL
2024-10-22 12:33:35.571979820+00:00,10,39,38,A,B,0,233.2,2000,130,203637,50890,233.2,236.8,2000,2000,1,1,,,0,0,0,0,,,0,0,0,0,,,0,0,0,0,,,0,0,0,0,,,0,0,0,0,,,0,0,0,0,,,0,0,0,0,,,0,0,0,0,,,0,0,0,0,AAPL
2024-10-22 12:33:35.596767197+00:00,10,39,38,C,A,0,236.8,2000,130,203469,50891,233.2,,2000,0,1,0,,,0,0,0,0,,,0,0,0,0,,,0,0,0,0,,,0,0,0,0,,,0,0,0,0,,,0,0,0,0,,,0,0,0,0,,,0,0,0,0,,,0,0,0,0,AAPL
2024-10-22 12:33:35.898879613+00:00,10,40,38,A,B,0,234.92,200,194,202570,81741,,234.92,0,200,0,0,,,0,0,0,0,,,0,0,0,0,,,0,0,0,0,,,0,0,0,0,,,0,0,0,0,,,0,0,0,0,,,0,0,0,0,,,0,0,0,0,,,0,0,0,0,AAPL
2024-10-22 12:33:35.898890991+00:00,10,40,38,A,A,0,,0,194,202410,81742,,,0,0,0,0,,,0,0,0,0,,,0,0,0,0,,,0,0,0,0,,,0,0,0,0,,,0,0,0,0,,,0,0,0,0,,,0,0,0,0,,,0,0,0,0,,,0,0,0,0,AAPL
2024-10-22 12:33:35.898902661+00:00,10,40,38,A,B,0,,0,194,202396,81743,233.97,,200,0,0,0,,,0,0,0,0,,,0,0,0,0,,,0,0,0,0,,,0,0,0,0,,,0,0,0,0,,,0,0,0,0,,,0,0,0,0,,,0,0,0,0,,,0,0,0,0,AAPL
2024-10-22 12:33:35.898909894+00:00,10,40,38,A,A,0,234.77,200,194,202389,81744,233.97,234.77,200,200,0,0,,,0,0,0,0,,,0,0,0,0,,,0,0,0,0,,,0,0,0,0,,,0,0,0,0,,,0,0,0,0,,,0,0,0,0,,,0,0,0,0,,,0,0,0,0,AAPL
2024-10-22 12:33:42.784382019+00:00,10,39,38,C,B,0,233.2,2000,130,203329,50989,,,0,0,0,0,,,0,0,0,0,,,0,0,0,0,,,0,0,0,0,,,0,0,0,0,,,0,0,0,0,,,0,0,0,0,,,0,0,0,0,,,0,0,0,0,,,0,0,0,0,AAPL
2024-10-22 12:33:42.850127230+00:00,10,39,38,A,B,0,233.2,2000,130,203252,50990,233.2,,2000,0,1,0,,,0,0,0,0,,,0,0,0,0,,,0,0,0,0,,,0,0,0,0,,,0,0,0,0,,,0,0,0,0,,,0,0,0,0,,,0,0,0,0,,,0,0,0,0,AAPL
2024-10-22 12:33:43.096938014+00:00,10,41,38,A,A,0,,0,194,56333,147104,234.1,,200,0,0,0,,,0,0,0,0,,,0,0,0,0,,,0,0,0,0,,,0,0,0,0,,,0,0,0,0,,,0,0,0,0,,,0,0,0,0,,,0,0,0,0,,,0,0,0,0,AAPL
2024-10-22 12:33:43.097009149+00:00,10,41,38,A,A,0,234.65,200,194,54488,147105,234.1,234.65,200,200,0,0,,,0,0,0,0,,,0,0,0,0,,,0,0,0,0,,,0,0,0,0,,,0,0,0,0,,,0,0,0,0,,,0,0,0,0,,,0,0,0,0,,,0,0,0,0,AAPL
2024-10-22 12:33:44.463770727+00:00,10,40,10888,A,A,0,,0,194,203303,81798,,,0,0,0,0,,,0,0,0,0,,,0,0,0,0,,,0,0,0,0,,,0,0,0,0,,,0,0,0,0,,,0,0,0,0,,,0,0,0,0,,,0,0,0,0,,,0,0,0,0,MSFT
2024-10-22 12:33:44.976903205+00:00,10,40,10888,A,A,0,418.99,100,194,203347,81809,,418.99,0,100,0,0,,,0,0,0,0,,,0,0,0,0,,,0,0,0,0,,,0,0,0,0,,,0,0,0,0,,,0,0,0,0,,,0,0,0,0,,,0,0,0,0,,,0,0,0,0,MSFT
2024-10-22 12:33:45.606605716+00:00,10,39,38,A,A,0,236.8,2000,130,203383,51007,233.2,236.8,2000,2000,1,1,,,0,0,0,0,,,0,0,0,0,,,0,0,0,0,,,0,0,0,0,,,0,0,0,0,,,0,0,0,0,,,0,0,0,0,,,0,0,0,0,,,0,0,0,0,AAPL
2024-10-22 12:33:46.964764868+00:00,10,39,38,C,B,0,233.2,2000,130,203307,51024,,236.8,0,2000,0,1,,,0,0,0,0,,,0,0,0,0,,,0,0,0,0,,,0,0,0,0,,,0,0,0,0,,,0,0,0,0,,,0,0,0,0,,,0,0,0,0,,,0,0,0,0,AAPL
2024-10-22 12:33:47.001198151+00:00,10,39,38,A,B,0,233.2,2000,130,203343,51026,233.2,236.8,2000,2000,1,1,,,0,0,0,0,,,0,0,0,0,,,0,0,0,0,,,0,0,0,0,,,0,0,0,0,,,0,0,0,0,,,0,0,0,0,,,0,0,0,0,,,0,0,0,0,AAPL
2024-10-22 12:33:47.263987259+00:00,10,40,10888,A,A,0,,0,194,203821,81832,,,0,0,0,0,,,0,0,0,0,,,0,0,0,0,,,0,0,0,0,,,0,0,0,0,,,0,0,0,0,,,0,0,0,0,,,0,0,0,0,,,0,0,0,0,,,0,0,0,0,MSFT
2024-10-22 12:33:47.840443230+00:00,10,39,10888,A,A,0,418.99,100,130,203274,77207,,418.99,0,100,0,1,,,0,0,0,0,,,0,0,0,0,,,0,0,0,0,,,0,0,0,0,,,0,0,0,0,,,0,0,0,0,,,0,0,0,0,,,0,0,0,0,,,0,0,0,0,MSFT
2024-10-22 12:33:49.964022011+00:00,10,39,38,C,B,0,233.2,2000,130,203297,51069,,236.8,0,2000,0,1,,,0,0,0,0,,,0,0,0,0,,,0,0,0,0,,,0,0,0,0,,,0,0,0,0,,,0,0,0,0,,,0,0,0,0,,,0,0,0,0,,,0,0,0,0,AAPL
2024-10-22 12:33:49.999956616+00:00,10,39,38,A,B,0,232.8,2000,130,203018,51070,232.8,236.8,2000,2000,1,1,,,0,0,0,0,,,0,0,0,0,,,0,0,0,0,,,0,0,0,0,,,0,0,0,0,,,0,0,0,0,,,0,0,0,0,,,0,0,0,0,,,0,0,0,0,AAPL
2024-10-22 12:33:50.260975390+00:00,10,41,38,A,B,0,234.65,200,194,55720,147300,,234.65,0,200,0,0,,,0,0,0,0,,,0,0,0,0,,,0,0,0,0,,,0,0,0,0,,,0,0,0,0,,,0,0,0,0,,,0,0,0,0,,,0,0,0,0,,,0,0,0,0,AAPL
2024-10-22 12:33:50.261002703+00:00,10,41,38,A,B,0,234.65,200,194,62067,147301,233.97,234.65,200,200,0,0,,,0,0,0,0,,,0,0,0,0,,,0,0,0,0,,,0,0,0,0,,,0,0,0,0,,,0,0,0,0,,,0,0,0,0,,,0,0,0,0,,,0,0,0,0,AAPL
2024-10-22 12:34:01.733175961+00:00,10,39,38,A,B,0,233.2,2000,130,204397,51178,233.2,236.8,2000,2000,1,1,232.8,,2000,0,1,0,,,0,0,0,0,,,0,0,0,0,,,0,0,0,0,,,0,0,0,0,,,0,0,0,0,,,0,0,0,0,,,0,0,0,0,,,0,0,0,0,AAPL
2024-10-22 12:34:01.733366420+00:00,10,39,38,C,B,1,232.8,2000,130,203297,51179,233.2,236.8,2000,2000,1,1,,,0,0,0,0,,,0,0,0,0,,,0,0,0,0,,,0,0,0,0,,,0,0,0,0,,,0,0,0,0,,,0,0,0,0,,,0,0,0,0,,,0,0,0,0,AAPL
2024-10-22 12:34:02.114940305+00:00,10,39,38,C,B,0,233.2,2000,130,203586,51182,,236.8,0,2000,0,1,,,0,0,0,0,,,0,0,0,0,,,0,0,0,0,,,0,0,0,0,,,0,0,0,0,,,0,0,0,0,,,0,0,0,0,,,0,0,0,0,,,0,0,0,0,AAPL
2024-10-22 12:34:02.152127604+00:00,10,39,38,A,B,0,233.2,2000,130,203394,51183,233.2,236.8,2000,2000,1,1,,,0,0,0,0,,,0,0,0,0,,,0,0,0,0,,,0,0,0,0,,,0,0,0,0,,,0,0,0,0,,,0,0,0,0,,,0,0,0,0,,,0,0,0,0,AAPL
2024-10-22 12:34:03.424022529+00:00,10,39,38,C,B,0,233.2,2000,130,203470,51191,,236.8,0,2000,0,1,,,0,0,0,0,,,0,0,0,0,,,0,0,0,0,,,0,0,0,0,,,0,0,0,0,,,0,0,0,0,,,0,0,0,0,,,0,0,0,0,,,0,0,0,0,AAPL
2024-10-22 12:34:03.436742007+00:00,10,39,38,A,B,0,232.8,2000,130,203318,51192,232.8,236.8,2000,2000,1,1,,,0,0,0,0,,,0,0,0,0,,,0,0,0,0,,,0,0,0,0,,,0,0,0,0,,,0,0,0,0,,,0,0,0,0,,,0,0,0,0,,,0,0,0,0,AAPL
2024-10-22 12:34:05.031184252+00:00,10,39,38,C,A,0,236.8,2000,130,203571,51206,232.8,,2000,0,1,0,,,0,0,0,0,,,0,0,0,0,,,0,0,0,0,,,0,0,0,0,,,0,0,0,0,,,0,0,0,0,,,0,0,0,0,,,0,0,0,0,,,0,0,0,0,AAPL
2024-10-22 12:34:16.774610872+00:00,10,39,38,A,B,0,233.2,2000,130,203516,51289,233.2,,2000,0,1,0,232.8,,2000,0,1,0,,,0,0,0,0,,,0,0,0,0,,,0,0,0,0,,,0,0,0,0,,,0,0,0,0,,,0,0,0,0,,,0,0,0,0,,,0,0,0,0,AAPL
2024-10-22 12:34:16.774792777+00:00,10,39,38,C,B,1,232.8,2000,130,203505,51290,233.2,,2000,0,1,0,,,0,0,0,0,,,0,0,0,0,,,0,0,0,0,,,0,0,0,0,,,0,0,0,0,,,0,0,0,0,,,0,0,0,0,,,0,0,0,0,,,0,0,0,0,AAPL
2024-10-22 12:34:17.376787873+00:00,10,39,38,C,B,0,233.2,2000,130,203649,51294,,,0,0,0,0,,,0,0,0,0,,,0,0,0,0,,,0,0,0,0,,,0,0,0,0,,,0,0,0,0,,,0,0,0,0,,,0,0,0,0,,,0,0,0,0,,,0,0,0,0,AAPL
2024-10-22 12:34:17.412519213+00:00,10,39,38,A,B,0,233.2,2000,130,203547,51296,233.2,,2000,0,1,0,,,0,0,0,0,,,0,0,0,0,,,0,0,0,0,,,0,0,0,0,,,0,0,0,0,,,0,0,0,0,,,0,0,0,0,,,0,0,0,0,,,0,0,0,0,AAPL
2024-10-22 12:34:17.498178170+00:00,10,39,38,C,B,0,233.2,2000,130,203449,51300,,,0,0,0,0,,,0,0,0,0,,,0,0,0,0,,,0,0,0,0,,,0,0,0,0,,,0,0,0,0,,,0,0,0,0,,,0,0,0,0,,,0,0,0,0,,,0,0,0,0,AAPL
2024-10-22 12:34:17.534661239+00:00,10,39,38,A,B,0,233.2,2000,130,203575,51301,233.2,,2000,0,1,0,,,0,0,0,0,,,0,0,0,0,,,0,0,0,0,,,0,0,0,0,,,0,0,0,0,,,0,0,0,0,,,0,0,0,0,,,0,0,0,0,,,0,0,0,0,AAPL
2024-10-22 12:34:19.263760732+00:00,10,39,10888,C,A,0,418.99,100,130,202884,77544,,,0,0,0,0,,,0,0,0,0,,,0,0,0,0,,,0,0,0,0,,,0,0,0,0,,,0,0,0,0,,,0,0,0,0,,,0,0,0,0,,,0,0,0,0,,,0,0,0,0,MSFT
2024-10-22 12:34:25.102317037+00:00,10,39,38,C,B,0,233.2,2000,130,203415,51404,,,0,0,0,0,,,0,0,0,0,,,0,0,0,0,,,0,0,0,0,,,0,0,0,0,,,0,0,0,0,,,0,0,0,0,,,0,0,0,0,,,0,0,0,0,,,0,0,0,0,AAPL
2024-10-22 12:34:25.137384101+00:00,10,39,38,A,B,0,233.2,2000,130,203386,51406,233.2,,2000,0,1,0,,,0,0,0,0,,,0,0,0,0,,,0,0,0,0,,,0,0,0,0,,,0,0,0,0,,,0,0,0,0,,,0,0,0,0,,,0,0,0,0,,,0,0,0,0,AAPL
2024-10-22 12:34:29.337167458+00:00,10,39,38,C,B,0,233.2,2000,130,203599,51467,,,0,0,0,0,,,0,0,0,0,,,0,0,0,0,,,0,0,0,0,,,0,0,0,0,,,0,0,0,0,,,0,0,0,0,,,0,0,0,0,,,0,0,0,0,,,0,0,0,0,AAPL
2024-10-22 12:34:29.348332769+00:00,10,39,38,A,B,0,232.8,2000,130,203599,51468,232.8,,2000,0,1,0,,,0,0,0,0,,,0,0,0,0,,,0,0,0,0,,,0,0,0,0,,,0,0,0,0,,,0,0,0,0,,,0,0,0,0,,,0,0,0,0,,,0,0,0,0,AAPL
2024-10-22 12:34:30.210401273+00:00,10,39,10888,A,A,0,418.97,100,130,202833,77832,,418.97,0,100,0,1,,,0,0,0,0,,,0,0,0,0,,,0,0,0,0,,,0,0,0,0,,,0,0,0,0,,,0,0,0,0,,,0,0,0,0,,,0,0,0,0,,,0,0,0,0,MSFT
2024-10-22 12:34:31.333268891+00:00,10,39,38,A,B,0,233.2,2000,130,203902,51485,233.2,,2000,0,1,0,232.8,,2000,0,1,0,,,0,0,0,0,,,0,0,0,0,,,0,0,0,0,,,0,0,0,0,,,0,0,0,0,,,0,0,0,0,,,0,0,0,0,,,0,0,0,0,AAPL
2024-10-22 12:34:31.333608093+00:00,10,39,38,C,B,1,232.8,2000,130,203501,51486,233.2,,2000,0,1,0,,,0,0,0,0,,,0,0,0,0,,,0,0,0,0,,,0,0,0,0,,,0,0,0,0,,,0,0,0,0,,,0,0,0,0,,,0,0,0,0,,,0,0,0,0,AAPL
2024-10-22 12:34:39.154128528+00:00,10,39,10888,C,A,0,418.97,100,130,203294,77979,,,0,0,0,0,,,0,0,0,0,,,0,0,0,0,,,0,0,0,0,,,0,0,0,0,,,0,0,0,0,,,0,0,0,0,,,0,0,0,0,,,0,0,0,0,,,0,0,0,0,MSFT
2024-10-22 12:34:40.844889993+00:00,10,39,10888,A,A,0,418.98,100,130,203634,78014,,418.98,0,100,0,1,,,0,0,0,0,,,0,0,0,0,,,0,0,0,0,,,0,0,0,0,,,0,0,0,0,,,0,0,0,0,,,0,0,0,0,,,0,0,0,0,,,0,0,0,0,MSFT
2024-10-22 12:34:42.287497279+00:00,10,39,10888,C,A,0,418.98,100,130,203370,78022,,,0,0,0,0,,,0,0,0,0,,,0,0,0,0,,,0,0,0,0,,,0,0,0,0,,,0,0,0,0,,,0,0,0,0,,,0,0,0,0,,,0,0,0,0,,,0,0,0,0,MSFT
2024-10-22 12:34:43.398885402+00:00,10,40,10888,A,A,0,418.95,100,194,203343,82893,,418.95,0,100,0,0,,,0,0,0,0,,,0,0,0,0,,,0,0,0,0,,,0,0,0,0,,,0,0,0,0,,,0,0,0,0,,,0,0,0,0,,,0,0,0,0,,,0,0,0,0,MSFT
2024-10-22 12:34:47.224395462+00:00,10,40,10888,A,A,0,,0,194,202880,82933,,,0,0,0,0,,,0,0,0,0,,,0,0,0,0,,,0,0,0,0,,,0,0,0,0,,,0,0,0,0,,,0,0,0,0,,,0,0,0,0,,,0,0,0,0,,,0,0,0,0,MSFT
2024-10-22 12:34:48.183190155+00:00,10,40,10888,A,A,0,418.98,100,194,202817,82942,,418.98,0,100,0,0,,,0,0,0,0,,,0,0,0,0,,,0,0,0,0,,,0,0,0,0,,,0,0,0,0,,,0,0,0,0,,,0,0,0,0,,,0,0,0,0,,,0,0,0,0,MSFT
2024-10-22 12:34:54.518155212+00:00,10,40,10888,A,A,0,,0,194,203035,82971,,,0,0,0,0,,,0,0,0,0,,,0,0,0,0,,,0,0,0,0,,,0,0,0,0,,,0,0,0,0,,,0,0,0,0,,,0,0,0,0,,,0,0,0,0,,,0,0,0,0,MSFT
2024-10-22 12:35:00.037385506+00:00,10,40,38,A,B,0,234.77,200,194,203041,83116,,234.77,0,200,0,0,,,0,0,0,0,,,0,0,0,0,,,0,0,0,0,,,0,0,0,0,,,0,0,0,0,,,0,0,0,0,,,0,0,0,0,,,0,0,0,0,,,0,0,0,0,AAPL
2024-10-22 12:35:00.037398037+00:00,10,40,38,A,A,0,,0,194,202902,83117,,,0,0,0,0,,,0,0,0,0,,,0,0,0,0,,,0,0,0,0,,,0,0,0,0,,,0,0,0,0,,,0,0,0,0,,,0,0,0,0,,,0,0,0,0,,,0,0,0,0,AAPL
2024-10-22 12:35:00.037664996+00:00,10,41,38,A,B,0,234.65,200,194,55353,150743,,234.65,0,200,0,0,,,0,0,0,0,,,0,0,0,0,,,0,0,0,0,,,0,0,0,0,,,0,0,0,0,,,0,0,0,0,,,0,0,0,0,,,0,0,0,0,,,0,0,0,0,AAPL
2024-10-22 12:35:00.037665975+00:00,10,41,38,A,A,0,,0,194,54130,150744,,,0,0,0,0,,,0,0,0,0,,,0,0,0,0,,,0,0,0,0,,,0,0,0,0,,,0,0,0,0,,,0,0,0,0,,,0,0,0,0,,,0,0,0,0,,,0,0,0,0,AAPL
2024-10-22 12:35:00.191759578+00:00,10,40,38,A,A,0,234.75,200,194,203027,83362,,234.75,0,200,0,0,,,0,0,0,0,,,0,0,0,0,,,0,0,0,0,,,0,0,0,0,,,0,0,0,0,,,0,0,0,0,,,0,0,0,0,,,0,0,0,0,,,0,0,0,0,AAPL
2024-10-22 12:35:00.455143869+00:00,10,41,38,A,A,0,234.69,200,194,56556,152109,,234.69,0,200,0,0,,,0,0,0,0,,,0,0,0,0,,,0,0,0,0,,,0,0,0,0,,,0,0,0,0,,,0,0,0,0,,,0,0,0,0,,,0,0,0,0,,,0,0,0,0,AAPL
2024-10-22 12:35:02.548520159+00:00,10,41,38,A,B,0,234.69,200,194,55682,152328,234.0,234.69,200,200,0,0,,,0,0,0,0,,,0,0,0,0,,,0,0,0,0,,,0,0,0,0,,,0,0,0,0,,,0,0,0,0,,,0,0,0,0,,,0,0,0,0,,,0,0,0,0,AAPL
2024-10-22 12:35:03.667235778+00:00,10,41,38,A,B,0,234.69,200,194,60670,152405,,234.69,0,200,0,0,,,0,0,0,0,,,0,0,0,0,,,0,0,0,0,,,0,0,0,0,,,0,0,0,0,,,0,0,0,0,,,0,0,0,0,,,0,0,0,0,,,0,0,0,0,AAPL
2024-10-22 12:35:03.955178415+00:00,10,41,38,A,B,0,234.69,200,194,56607,152424,234.0,234.69,200,200,0,0,,,0,0,0,0,,,0,0,0,0,,,0,0,0,0,,,0,0,0,0,,,0,0,0,0,,,0,0,0,0,,,0,0,0,0,,,0,0,0,0,,,0,0,0,0,AAPL
2024-10-22 12:35:05.242648010+00:00,10,40,38,A,B,0,234.75,200,194,202985,83569,233.94,234.75,200,200,0,0,,,0,0,0,0,,,0,0,0,0,,,0,0,0,0,,,0,0,0,0,,,0,0,0,0,,,0,0,0,0,,,0,0,0,0,,,0,0,0,0,,,0,0,0,0,AAPL
2024-10-22 12:35:09.460915877+00:00,10,39,38,C,B,0,233.2,2000,130,204061,51840,,,0,0,0,0,,,0,0,0,0,,,0,0,0,0,,,0,0,0,0,,,0,0,0,0,,,0,0,0,0,,,0,0,0,0,,,0,0,0,0,,,0,0,0,0,,,0,0,0,0,AAPL
2024-10-22 12:35:09.472505277+00:00,10,39,38,A,B,0,232.8,2000,130,204015,51841,232.8,,2000,0,1,0,,,0,0,0,0,,,0,0,0,0,,,0,0,0,0,,,0,0,0,0,,,0,0,0,0,,,0,0,0,0,,,0,0,0,0,,,0,0,0,0,,,0,0,0,0,AAPL
2024-10-22 12:35:15.011463731+00:00,10,39,38,A,B,0,233.0,2000,130,203820,51899,233.0,,2000,0,1,0,232.8,,2000,0,1,0,,,0,0,0,0,,,0,0,0,0,,,0,0,0,0,,,0,0,0,0,,,0,0,0,0,,,0,0,0,0,,,0,0,0,0,,,0,0,0,0,AAPL
2024-10-22 12:35:15.011743468+00:00,10,39,38,C,B,1,232.8,2000,130,203768,51908,233.0,,2000,0,1,0,,,0,0,0,0,,,0,0,0,0,,,0,0,0,0,,,0,0,0,0,,,0,0,0,0,,,0,0,0,0,,,0,0,0,0,,,0,0,0,0,,,0,0,0,0,AAPL
2024-10-22 12:35:19.678475186+00:00,10,39,38,A,B,0,233.4,2000,130,204128,52041,233.4,,2000,0,1,0,233.0,,2000,0,1,0,,,0,0,0,0,,,0,0,0,0,,,0,0,0,0,,,0,0,0,0,,,0,0,0,0,,,0,0,0,0,,,0,0,0,0,,,0,0,0,0,AAPL
2024-10-22 12:35:19.678663621+00:00,10,39,38,C,B,1,233.0,2000,130,203948,52042,233.4,,2000,0,1,0,,,0,0,0,0,,,0,0,0,0,,,0,0,0,0,,,0,0,0,0,,,0,0,0,0,,,0,0,0,0,,,0,0,0,0,,,0,0,0,0,,,0,0,0,0,AAPL
2024-10-22 12:35:23.474338021+00:00,10,39,38,C,B,0,233.4,2000,130,203665,52137,,,0,0,0,0,,,0,0,0,0,,,0,0,0,0,,,0,0,0,0,,,0,0,0,0,,,0,0,0,0,,,0,0,0,0,,,0,0,0,0,,,0,0,0,0,,,0,0,0,0,AAPL
2024-10-22 12:35:23.545203230+00:00,10,39,38,A,B,0,233.4,2000,130,203504,52140,233.4,,2000,0,1,0,,,0,0,0,0,,,0,0,0,0,,,0,0,0,0,,,0,0,0,0,,,0,0,0,0,,,0,0,0,0,,,0,0,0,0,,,0,0,0,0,,,0,0,0,0,AAPL
2024-10-22 12:35:23.566649027+00:00,10,39,38,A,B,0,233.6,2000,130,203531,52141,233.6,,2000,0,1,0,233.4,,2000,0,1,0,,,0,0,0,0,,,0,0,0,0,,,0,0,0,0,,,0,0,0,0,,,0,0,0,0,,,0,0,0,0,,,0,0,0,0,,,0,0,0,0,AAPL
2024-10-22 12:35:23.567374068+00:00,10,39,38,C,B,1,233.4,2000,130,203867,52142,233.6,,2000,0,1,0,,,0,0,0,0,,,0,0,0,0,,,0,0,0,0,,,0,0,0,0,,,0,0,0,0,,,0,0,0,0,,,0,0,0,0,,,0,0,0,0,,,0,0,0,0,AAPL
2024-10-22 12:35:25.514854456+00:00,10,39,38,C,B,0,233.6,2000,130,203423,52190,,,0,0,0,0,,,0,0,0,0,,,0,0,0,0,,,0,0,0,0,,,0,0,0,0,,,0,0,0,0,,,0,0,0,0,,,0,0,0,0,,,0,0,0,0,,,0,0,0,0,AAPL
2024-10-22 12:35:25.526113821+00:00,10,39,38,A,B,0,233.2,2000,130,203431,52191,233.2,,2000,0,1,0,,,0,0,0,0,,,0,0,0,0,,,0,0,0,0,,,0,0,0,0,,,0,0,0,0,,,0,0,0,0,,,0,0,0,0,,,0,0,0,0,,,0,0,0,0,AAPL
2024-10-22 12:35:25.541754682+00:00,10,39,38,A,B,0,233.6,2000,130,203413,52194,233.6,,2000,0,1,0,233.2,,2000,0,1,0,,,0,0,0,0,,,0,0,0,0,,,0,0,0,0,,,0,0,0,0,,,0,0,0,0,,,0,0,0,0,,,0,0,0,0,,,0,0,0,0,AAPL
2024-10-22 12:35:25.541954746+00:00,10,39,38,C,B,1,233.2,2000,130,203330,52195,233.6,,2000,0,1,0,,,0,0,0,0,,,0,0,0,0,,,0,0,0,0,,,0,0,0,0,,,0,0,0,0,,,0,0,0,0,,,0,0,0,0,,,0,0,0,0,,,0,0,0,0,AAPL
2024-10-22 12:35:28.240952021+00:00,10,39,38,C,B,0,233.6,2000,130,203318,52254,,,0,0,0,0,,,0,0,0,0,,,0,0,0,0,,,0,0,0,0,,,0,0,0,0,,,0,0,0,0,,,0,0,0,0,,,0,0,0,0,,,0,0,0,0,,,0,0,0,0,AAPL
2024-10-22 12:35:28.276627230+00:00,10,39,38,A,B,0,233.6,2000,130,203379,52257,233.6,,2000,0,1,0,,,0,0,0,0,,,0,0,0,0,,,0,0,0,0,,,0,0,0,0,,,0,0,0,0,,,0,0,0,0,,,0,0,0,0,,,0,0,0,0,,,0,0,0,0,AAPL
2024-10-22 12:35:29.690980733+00:00,10,39,38,C,B,0,233.6,2000,130,203907,52297,,,0,0,0,0,,,0,0,0,0,,,0,0,0,0,,,0,0,0,0,,,0,0,0,0,,,0,0,0,0,,,0,0,0,0,,,0,0,0,0,,,0,0,0,0,,,0,0,0,0,AAPL
2024-10-22 12:35:29.701729943+00:00,10,39,38,A,B,0,233.0,2000,130,203563,52299,233.0,,2000,0,1,0,,,0,0,0,0,,,0,0,0,0,,,0,0,0,0,,,0,0,0,0,,,0,0,0,0,,,0,0,0,0,,,0,0,0,0,,,0,0,0,0,,,0,0,0,0,AAPL
2024-10-22 12:35:29.720828220+00:00,10,39,38,A,B,0,233.4,2000,130,203462,52302,233.4,,2000,0,1,0,233.0,,2000,0,1,0,,,0,0,0,0,,,0,0,0,0,,,0,0,0,0,,,0,0,0,0,,,0,0,0,0,,,0,0,0,0,,,0,0,0,0,,,0,0,0,0,AAPL
2024-10-22 12:35:29.721568774+00:00,10,39,38,C,B,1,233.0,2000,130,203428,52303,233.4,,2000,0,1,0,,,0,0,0,0,,,0,0,0,0,,,0,0,0,0,,,0,0,0,0,,,0,0,0,0,,,0,0,0,0,,,0,0,0,0,,,0,0,0,0,,,0,0,0,0,AAPL
2024-10-22 12:35:29.892291140+00:00,10,39,38,A,B,0,233.6,2000,130,203700,52305,233.6,,2000,0,1,0,233.4,,2000,0,1,0,,,0,0,0,0,,,0,0,0,0,,,0,0,0,0,,,0,0,0,0,,,0,0,0,0,,,0,0,0,0,,,0,0,0,0,,,0,0,0,0,AAPL
2024-10-22 12:35:29.892970299+00:00,10,39,38,C,B,1,233.4,2000,130,203458,52306,233.6,,2000,0,1,0,,,0,0,0,0,,,0,0,0,0,,,0,0,0,0,,,0,0,0,0,,,0,0,0,0,,,0,0,0,0,,,0,0,0,0,,,0,0,0,0,,,0,0,0,0,AAPL
2024-10-22 12:35:31.553592768+00:00,10,39,38,C,B,0,233.6,2000,130,203482,52336,,,0,0,0,0,,,0,0,0,0,,,0,0,0,0,,,0,0,0,0,,,0,0,0,0,,,0,0,0,0,,,0,0,0,0,,,0,0,0,0,,,0,0,0,0,,,0,0,0,0,AAPL
2024-10-22 12:35:31.564351666+00:00,10,39,38,A,A,0,236.6,2000,130,203551,52338,,236.6,0,2000,0,1,,,0,0,0,0,,,0,0,0,0,,,0,0,0,0,,,0,0,0,0,,,0,0,0,0,,,0,0,0,0,,,0,0,0,0,,,0,0,0,0,,,0,0,0,0,AAPL
2024-10-22 12:35:31.593518395+00:00,10,39,38,A,B,0,233.4,2000,130,203543,52339,233.4,236.6,2000,2000,1,1,,,0,0,0,0,,,0,0,0,0,,,0,0,0,0,,,0,0,0,0,,,0,0,0,0,,,0,0,0,0,,,0,0,0,0,,,0,0,0,0,,,0,0,0,0,AAPL
2024-10-22 12:35:31.606462343+00:00,10,39,38,C,A,0,236.6,2000,130,203486,52340,233.4,,2000,0,1,0,,,0,0,0,0,,,0,0,0,0,,,0,0,0,0,,,0,0,0,0,,,0,0,0,0,,,0,0,0,0,,,0,0,0,0,,,0,0,0,0,,,0,0,0,0,AAPL
2024-10-22 12:35:38.302029157+00:00,10,39,38,A,A,0,236.6,2000,130,203461,52421,233.4,236.6,2000,2000,1,1,,,0,0,0,0,,,0,0,0,0,,,0,0,0,0,,,0,0,0,0,,,0,0,0,0,,,0,0,0,0,,,0,0,0,0,,,0,0,0,0,,,0,0,0,0,AAPL
2024-10-22 12:35:38.322088359+00:00,10,39,38,C,A,0,236.6,2000,130,203340,52426,233.4,,2000,0,1,0,,,0,0,0,0,,,0,0,0,0,,,0,0,0,0,,,0,0,0,0,,,0,0,0,0,,,0,0,0,0,,,0,0,0,0,,,0,0,0,0,,,0,0,0,0,AAPL
2024-10-22 12:35:41.363525331+00:00,10,39,38,A,A,0,236.6,2000,130,203525,52519,233.4,236.6,2000,2000,1,1,,,0,0,0,0,,,0,0,0,0,,,0,0,0,0,,,0,0,0,0,,,0,0,0,0,,,0,0,0,0,,,0,0,0,0,,,0,0,0,0,,,0,0,0,0,AAPL
2024-10-22 12:35:41.967573067+00:00,10,39,10888,A,A,0,418.98,100,130,204147,78742,,418.98,0,100,0,1,,,0,0,0,0,,,0,0,0,0,,,0,0,0,0,,,0,0,0,0,,,0,0,0,0,,,0,0,0,0,,,0,0,0,0,,,0,0,0,0,,,0,0,0,0,MSFT
2024-10-22 12:35:51.828776906+00:00,10,39,38,C,A,0,236.6,2000,130,204385,52670,233.4,,2000,0,1,0,,,0,0,0,0,,,0,0,0,0,,,0,0,0,0,,,0,0,0,0,,,0,0,0,0,,,0,0,0,0,,,0,0,0,0,,,0,0,0,0,,,0,0,0,0,AAPL
2024-10-22 12:35:52.713093956+00:00,10,39,38,A,A,0,236.6,2000,130,204079,52684,233.4,236.6,2000,2000,1,1,,,0,0,0,0,,,0,0,0,0,,,0,0,0,0,,,0,0,0,0,,,0,0,0,0,,,0,0,0,0,,,0,0,0,0,,,0,0,0,0,,,0,0,0,0,AAPL
2024-10-22 12:35:55.449832399+00:00,10,39,38,C,A,0,236.6,2000,130,203677,52708,233.4,,2000,0,1,0,,,0,0,0,0,,,0,0,0,0,,,0,0,0,0,,,0,0,0,0,,,0,0,0,0,,,0,0,0,0,,,0,0,0,0,,,0,0,0,0,,,0,0,0,0,AAPL
2024-10-22 12:36:00.207301154+00:00,10,39,10888,C,A,0,418.98,100,130,204341,78981,,,0,0,0,0,,,0,0,0,0,,,0,0,0,0,,,0,0,0,0,,,0,0,0,0,,,0,0,0,0,,,0,0,0,0,,,0,0,0,0,,,0,0,0,0,,,0,0,0,0,MSFT
2024-10-22 12:36:00.719437873+00:00,10,40,10888,A,A,0,418.99,100,194,203604,84605,,418.99,0,100,0,0,,,0,0,0,0,,,0,0,0,0,,,0,0,0,0,,,0,0,0,0,,,0,0,0,0,,,0,0,0,0,,,0,0,0,0,,,0,0,0,0,,,0,0,0,0,MSFT
2024-10-22 12:36:06.014669760+00:00,10,40,10888,A,A,0,,0,194,203409,84670,,,0,0,0,0,,,0,0,0,0,,,0,0,0,0,,,0,0,0,0,,,0,0,0,0,,,0,0,0,0,,,0,0,0,0,,,0,0,0,0,,,0,0,0,0,,,0,0,0,0,MSFT
2024-10-22 12:36:06.106203609+00:00,10,39,38,A,A,0,236.6,2000,130,203601,52885,233.4,236.6,2000,2000,1,1,,,0,0,0,0,,,0,0,0,0,,,0,0,0,0,,,0,0,0,0,,,0,0,0,0,,,0,0,0,0,,,0,0,0,0,,,0,0,0,0,,,0,0,0,0,AAPL
2024-10-22 12:36:06.115062305+00:00,10,39,38,C,A,0,236.6,2000,130,203545,52887,233.4,,2000,0,1,0,,,0,0,0,0,,,0,0,0,0,,,0,0,0,0,,,0,0,0,0,,,0,0,0,0,,,0,0,0,0,,,0,0,0,0,,,0,0,0,0,,,0,0,0,0,AAPL
2024-10-22 12:36:07.295715899+00:00,10,40,10888,A,A,0,418.98,100,194,203488,84676,,418.98,0,100,0,0,,,0,0,0,0,,,0,0,0,0,,,0,0,0,0,,,0,0,0,0,,,0,0,0,0,,,0,0,0,0,,,0,0,0,0,,,0,0,0,0,,,0,0,0,0,MSFT
2024-10-22 12:36:10.129231505+00:00,10,40,10888,A,A,0,,0,194,203257,84710,,,0,0,0,0,,,0,0,0,0,,,0,0,0,0,,,0,0,0,0,,,0,0,0,0,,,0,0,0,0,,,0,0,0,0,,,0,0,0,0,,,0,0,0,0,,,0,0,0,0,MSFT
2024-10-22 12:36:12.543519266+00:00,10,39,38,A,A,0,236.6,2000,130,203452,53008,233.4,236.6,2000,2000,1,1,,,0,0,0,0,,,0,0,0,0,,,0,0,0,0,,,0,0,0,0,,,0,0,0,0,,,0,0,0,0,,,0,0,0,0,,,0,0,0,0,,,0,0,0,0,AAPL
2024-10-22 12:36:12.597119287+00:00,10,39,38,C,A,0,236.6,2000,130,203357,53009,233.4,,2000,0,1,0,,,0,0,0,0,,,0,0,0,0,,,0,0,0,0,,,0,0,0,0,,,0,0,0,0,,,0,0,0,0,,,0,0,0,0,,,0,0,0,0,,,0,0,0,0,AAPL
2024-10-22 12:36:12.607993915+00:00,10,39,38,A,A,0,236.6,2000,130,203398,53010,233.4,236.6,2000,2000,1,1,,,0,0,0,0,,,0,0,0,0,,,0,0,0,0,,,0,0,0,0,,,0,0,0,0,,,0,0,0,0,,,0,0,0,0,,,0,0,0,0,,,0,0,0,0,AAPL
2024-10-22 12:36:12.879770663+00:00,10,39,38,C,A,0,236.6,2000,130,203374,53013,233.4,,2000,0,1,0,,,0,0,0,0,,,0,0,0,0,,,0,0,0,0,,,0,0,0,0,,,0,0,0,0,,,0,0,0,0,,,0,0,0,0,,,0,0,0,0,,,0,0,0,0,AAPL
2024-10-22 12:36:13.198337730+00:00,10,39,38,A,A,0,236.6,2000,130,203882,53015,233.4,236.6,2000,2000,1,1,,,0,0,0,0,,,0,0,0,0,,,0,0,0,0,,,0,0,0,0,,,0,0,0,0,,,0,0,0,0,,,0,0,0,0,,,0,0,0,0,,,0,0,0,0,AAPL
2024-10-22 12:36:13.442188221+00:00,10,41,38,A,A,0,,0,194,55856,156292,234.0,,200,0,0,0,,,0,0,0,0,,,0,0,0,0,,,0,0,0,0,,,0,0,0,0,,,0,0,0,0,,,0,0,0,0,,,0,0,0,0,,,0,0,0,0,,,0,0,0,0,AAPL
2024-10-22 12:36:13.442227459+00:00,10,41,38,A,A,0,234.58,200,194,54214,156293,234.0,234.58,200,200,0,0,,,0,0,0,0,,,0,0,0,0,,,0,0,0,0,,,0,0,0,0,,,0,0,0,0,,,0,0,0,0,,,0,0,0,0,,,0,0,0,0,,,0,0,0,0,AAPL
2024-10-22 12:36:13.445987373+00:00,10,39,38,C,B,0,233.4,2000,130,203555,53017,,236.6,0,2000,0,1,,,0,0,0,0,,,0,0,0,0,,,0,0,0,0,,,0,0,0,0,,,0,0,0,0,,,0,0,0,0,,,0,0,0,0,,,0,0,0,0,,,0,0,0,0,AAPL
2024-10-22 12:36:13.481038052+00:00,10,39,38,C,A,0,236.6,2000,130,203320,53019,,,0,0,0,0,,,0,0,0,0,,,0,0,0,0,,,0,0,0,0,,,0,0,0,0,,,0,0,0,0,,,0,0,0,0,,,0,0,0,0,,,0,0,0,0,,,0,0,0,0,AAPL
2024-10-22 12:36:13.484059153+00:00,10,39,38,A,B,0,233.4,2000,130,203307,53020,233.4,,2000,0,1,0,,,0,0,0,0,,,0,0,0,0,,,0,0,0,0,,,0,0,0,0,,,0,0,0,0,,,0,0,0,0,,,0,0,0,0,,,0,0,0,0,,,0,0,0,0,AAPL
2024-10-22 12:36:13.754044652+00:00,10,40,38,A,A,0,,0,194,203180,84771,233.94,,200,0,0,0,,,0,0,0,0,,,0,0,0,0,,,0,0,0,0,,,0,0,0,0,,,0,0,0,0,,,0,0,0,0,,,0,0,0,0,,,0,0,0,0,,,0,0,0,0,AAPL
2024-10-22 12:36:13.754072053+00:00,10,40,38,A,A,0,234.62,200,194,203086,84772,233.94,234.62,200,200,0,0,,,0,0,0,0,,,0,0,0,0,,,0,0,0,0,,,0,0,0,0,,,0,0,0,0,,,0,0,0,0,,,0,0,0,0,,,0,0,0,0,,,0,0,0,0,AAPL
2024-10-22 12:36:13.798306959+00:00,10,39,38,A,A,0,236.6,2000,130,203630,53021,233.4,236.6,2000,2000,1,1,,,0,0,0,0,,,0,0,0,0,,,0,0,0,0,,,0,0,0,0,,,0,0,0,0,,,0,0,0,0,,,0,0,0,0,,,0,0,0,0,,,0,0,0,0,AAPL
2024-10-22 12:36:14.399969177+00:00,10,39,38,C,A,0,236.6,2000,130,203351,53027,233.4,,2000,0,1,0,,,0,0,0,0,,,0,0,0,0,,,0,0,0,0,,,0,0,0,0,,,0,0,0,0,,,0,0,0,0,,,0,0,0,0,,,0,0,0,0,,,0,0,0,0,AAPL
2024-10-22 12:36:14.954792157+00:00,10,39,38,A,A,0,236.6,2000,130,203549,53035,233.4,236.6,2000,2000,1,1,,,0,0,0,0,,,0,0,0,0,,,0,0,0,0,,,0,0,0,0,,,0,0,0,0,,,0,0,0,0,,,0,0,0,0,,,0,0,0,0,,,0,0,0,0,AAPL
2024-10-22 12:36:16.372043301+00:00,10,39,38,C,A,0,236.6,2000,130,203281,53049,233.4,,2000,0,1,0,,,0,0,0,0,,,0,0,0,0,,,0,0,0,0,,,0,0,0,0,,,0,0,0,0,,,0,0,0,0,,,0,0,0,0,,,0,0,0,0,,,0,0,0,0,AAPL
2024-10-22 12:36:16.677056055+00:00,10,41,38,A,B,0,234.58,200,194,61415,156398,,234.58,0,200,0,0,,,0,0,0,0,,,0,0,0,0,,,0,0,0,0,,,0,0,0,0,,,0,0,0,0,,,0,0,0,0,,,0,0,0,0,,,0,0,0,0,,,0,0,0,0,AAPL
2024-10-22 12:36:16.677129346+00:00,10,41,38,A,B,0,234.58,200,194,54702,156399,233.89,234.58,200,200,0,0,,,0,0,0,0,,,0,0,0,0,,,0,0,0,0,,,0,0,0,0,,,0,0,0,0,,,0,0,0,0,,,0,0,0,0,,,0,0,0,0,,,0,0,0,0,AAPL
2024-10-22 12:36:16.692940750+00:00,10,39,38,A,A,0,236.6,2000,130,203286,53061,233.4,236.6,2000,2000,1,1,,,0,0,0,0,,,0,0,0,0,,,0,0,0,0,,,0,0,0,0,,,0,0,0,0,,,0,0,0,0,,,0,0,0,0,,,0,0,0,0,,,0,0,0,0,AAPL
2024-10-22 12:36:16.718366694+00:00,10,39,38,C,A,0,236.6,2000,130,203495,53062,233.4,,2000,0,1,0,,,0,0,0,0,,,0,0,0,0,,,0,0,0,0,,,0,0,0,0,,,0,0,0,0,,,0,0,0,0,,,0,0,0,0,,,0,0,0,0,,,0,0,0,0,AAPL
2024-10-22 12:36:16.729348694+00:00,10,39,38,A,A,0,236.6,2000,130,203437,53063,233.4,236.6,2000,2000,1,1,,,0,0,0,0,,,0,0,0,0,,,0,0,0,0,,,0,0,0,0,,,0,0,0,0,,,0,0,0,0,,,0,0,0,0,,,0,0,0,0,,,0,0,0,0,AAPL
2024-10-22 12:36:16.748454950+00:00,10,39,38,C,A,0,236.6,2000,130,203387,53064,233.4,,2000,0,1,0,,,0,0,0,0,,,0,0,0,0,,,0,0,0,0,,,0,0,0,0,,,0,0,0,0,,,0,0,0,0,,,0,0,0,0,,,0,0,0,0,,,0,0,0,0,AAPL
2024-10-22 12:36:16.760323595+00:00,10,39,38,A,A,0,236.6,2000,130,203367,53065,233.4,236.6,2000,2000,1,1,,,0,0,0,0,,,0,0,0,0,,,0,0,0,0,,,0,0,0,0,,,0,0,0,0,,,0,0,0,0,,,0,0,0,0,,,0,0,0,0,,,0,0,0,0,AAPL
2024-10-22 12:36:23.562248632+00:00,10,39,38,C,B,0,233.4,2000,130,203193,53195,,236.6,0,2000,0,1,,,0,0,0,0,,,0,0,0,0,,,0,0,0,0,,,0,0,0,0,,,0,0,0,0,,,0,0,0,0,,,0,0,0,0,,,0,0,0,0,,,0,0,0,0,AAPL
2024-10-22 12:36:23.581647223+00:00,10,39,38,A,B,0,233.4,2000,130,203075,53196,233.4,236.6,2000,2000,1,1,,,0,0,0,0,,,0,0,0,0,,,0,0,0,0,,,0,0,0,0,,,0,0,0,0,,,0,0,0,0,,,0,0,0,0,,,0,0,0,0,,,0,0,0,0,AAPL
2024-10-22 12:36:29.408842616+00:00,10,39,38,C,B,0,233.4,2000,130,202856,53282,,236.6,0,2000,0,1,,,0,0,0,0,,,0,0,0,0,,,0,0,0,0,,,0,0,0,0,,,0,0,0,0,,,0,0,0,0,,,0,0,0,0,,,0,0,0,0,,,0,0,0,0,AAPL
2024-10-22 12:36:29.419703161+00:00,10,39,38,A,B,0,233.2,2000,130,202688,53285,233.2,236.6,2000,2000,1,1,,,0,0,0,0,,,0,0,0,0,,,0,0,0,0,,,0,0,0,0,,,0,0,0,0,,,0,0,0,0,,,0,0,0,0,,,0,0,0,0,,,0,0,0,0,AAPL
2024-10-22 12:36:36.375163491+00:00,10,39,38,C,B,0,233.2,2000,130,202671,53337,,236.6,0,2000,0,1,,,0,0,0,0,,,0,0,0,0,,,0,0,0,0,,,0,0,0,0,,,0,0,0,0,,,0,0,0,0,,,0,0,0,0,,,0,0,0,0,,,0,0,0,0,AAPL
2024-10-22 12:36:36.415649945+00:00,10,39,38,A,B,0,233.4,2000,130,202716,53338,233.4,236.6,2000,2000,1,1,,,0,0,0,0,,,0,0,0,0,,,0,0,0,0,,,0,0,0,0,,,0,0,0,0,,,0,0,0,0,,,0,0,0,0,,,0,0,0,0,,,0,0,0,0,AAPL
2024-10-22 12:36:36.418253489+00:00,10,39,38,C,B,0,233.4,2000,130,202696,53339,,236.6,0,2000,0,1,,,0,0,0,0,,,0,0,0,0,,,0,0,0,0,,,0,0,0,0,,,0,0,0,0,,,0,0,0,0,,,0,0,0,0,,,0,0,0,0,,,0,0,0,0,AAPL
2024-10-22 12:36:36.429553504+00:00,10,39,38,A,B,0,233.2,2000,130,202725,53340,233.2,236.6,2000,2000,1,1,,,0,0,0,0,,,0,0,0,0,,,0,0,0,0,,,0,0,0,0,,,0,0,0,0,,,0,0,0,0,,,0,0,0,0,,,0,0,0,0,,,0,0,0,0,AAPL
2024-10-22 12:36:36.436601918+00:00,10,39,38,C,A,0,236.6,2000,130,202635,53341,233.2,,2000,0,1,0,,,0,0,0,0,,,0,0,0,0,,,0,0,0,0,,,0,0,0,0,,,0,0,0,0,,,0,0,0,0,,,0,0,0,0,,,0,0,0,0,,,0,0,0,0,AAPL
2024-10-22 12:36:36.446304836+00:00,10,39,38,A,B,0,233.4,2000,130,202662,53343,233.4,,2000,0,1,0,233.2,,2000,0,1,0,,,0,0,0,0,,,0,0,0,0,,,0,0,0,0,,,0,0,0,0,,,0,0,0,0,,,0,0,0,0,,,0,0,0,0,,,0,0,0,0,AAPL
2024-10-22 12:36:36.446498336+00:00,10,39,38,C,B,1,233.2,2000,130,202626,53344,233.4,,2000,0,1,0,,,0,0,0,0,,,0,0,0,0,,,0,0,0,0,,,0,0,0,0,,,0,0,0,0,,,0,0,0,0,,,0,0,0,0,,,0,0,0,0,,,0,0,0,0,AAPL
2024-10-22 12:36:36.454931904+00:00,10,39,38,C,B,0,233.4,2000,130,202593,53347,,,0,0,0,0,,,0,0,0,0,,,0,0,0,0,,,0,0,0,0,,,0,0,0,0,,,0,0,0,0,,,0,0,0,0,,,0,0,0,0,,,0,0,0,0,,,0,0,0,0,AAPL
2024-10-22 12:36:36.471832996+00:00,10,39,38,A,B,0,233.4,2000,130,202746,53348,233.4,,2000,0,1,0,,,0,0,0,0,,,0,0,0,0,,,0,0,0,0,,,0,0,0,0,,,0,0,0,0,,,0,0,0,0,,,0,0,0,0,,,0,0,0,0,,,0,0,0,0,AAPL
2024-10-22 12:36:36.666371942+00:00,10,40,38,A,B,0,234.62,200,194,202658,85001,,234.62,0,200,0,0,,,0,0,0,0,,,0,0,0,0,,,0,0,0,0,,,0,0,0,0,,,0,0,0,0,,,0,0,0,0,,,0,0,0,0,,,0,0,0,0,,,0,0,0,0,AAPL
2024-10-22 12:36:36.666392164+00:00,10,40,38,A,B,0,234.62,200,194,202894,85002,233.66,234.62,200,200,0,0,,,0,0,0,0,,,0,0,0,0,,,0,0,0,0,,,0,0,0,0,,,0,0,0,0,,,0,0,0,0,,,0,0,0,0,,,0,0,0,0,,,0,0,0,0,AAPL
2024-10-22 12:36:36.666402586+00:00,10,40,38,A,A,0,234.5,200,194,202904,85004,233.66,234.5,200,200,0,0,,,0,0,0,0,,,0,0,0,0,,,0,0,0,0,,,0,0,0,0,,,0,0,0,0,,,0,0,0,0,,,0,0,0,0,,,0,0,0,0,,,0,0,0,0,AAPL
2024-10-22 12:36:36.666904466+00:00,10,41,38,A,B,0,234.58,200,194,61040,157024,,234.58,0,200,0,0,,,0,0,0,0,,,0,0,0,0,,,0,0,0,0,,,0,0,0,0,,,0,0,0,0,,,0,0,0,0,,,0,0,0,0,,,0,0,0,0,,,0,0,0,0,AAPL
2024-10-22 12:36:36.666919561+00:00,10,41,38,A,A,0,,0,194,58153,157025,,,0,0,0,0,,,0,0,0,0,,,0,0,0,0,,,0,0,0,0,,,0,0,0,0,,,0,0,0,0,,,0,0,0,0,,,0,0,0,0,,,0,0,0,0,,,0,0,0,0,AAPL
2024-10-22 12:36:36.666974505+00:00,10,41,38,A,B,0,,0,194,54533,157026,233.72,,200,0,0,0,,,0,0,0,0,,,0,0,0,0,,,0,0,0,0,,,0,0,0,0,,,0,0,0,0,,,0,0,0,0,,,0,0,0,0,,,0,0,0,0,,,0,0,0,0,AAPL
2024-10-22 12:36:36.666995004+00:00,10,41,38,A,A,0,234.44,200,194,54854,157027,233.72,234.44,200,200,0,0,,,0,0,0,0,,,0,0,0,0,,,0,0,0,0,,,0,0,0,0,,,0,0,0,0,,,0,0,0,0,,,0,0,0,0,,,0,0,0,0,,,0,0,0,0,AAPL
2024-10-22 12:36:52.028522030+00:00,10,41,38,A,B,0,234.44,200,194,57360,157482,,234.44,0,200,0,0,,,0,0,0,0,,,0,0,0,0,,,0,0,0,0,,,0,0,0,0,,,0,0,0,0,,,0,0,0,0,,,0,0,0,0,,,0,0,0,0,,,0,0,0,0,AAPL
2024-10-22 12:36:52.028579280+00:00,10,41,38,A,B,0,234.44,200,194,57148,157483,233.82,234.44,200,200,0,0,,,0,0,0,0,,,0,0,0,0,,,0,0,0,0,,,0,0,0,0,,,0,0,0,0,,,0,0,0,0,,,0,0,0,0,,,0,0,0,0,,,0,0,0,0,AAPL
2024-10-22 12:36:53.989558246+00:00,10,41,38,A,A,0,,0,194,57331,157540,233.82,,200,0,0,0,,,0,0,0,0,,,0,0,0,0,,,0,0,0,0,,,0,0,0,0,,,0,0,0,0,,,0,0,0,0,,,0,0,0,0,,,0,0,0,0,,,0,0,0,0,AAPL
2024-10-22 12:36:53.989594485+00:00,10,41,38,A,A,0,234.55,200,194,54597,157541,233.82,234.55,200,200,0,0,,,0,0,0,0,,,0,0,0,0,,,0,0,0,0,,,0,0,0,0,,,0,0,0,0,,,0,0,0,0,,,0,0,0,0,,,0,0,0,0,,,0,0,0,0,AAPL
2024-10-22 12:36:56.681733418+00:00,10,40,38,A,A,0,,0,194,203443,85221,233.66,,200,0,0,0,,,0,0,0,0,,,0,0,0,0,,,0,0,0,0,,,0,0,0,0,,,0,0,0,0,,,0,0,0,0,,,0,0,0,0,,,0,0,0,0,,,0,0,0,0,AAPL
2024-10-22 12:36:56.681749039+00:00,10,40,38,A,A,0,234.62,200,194,203388,85222,233.66,234.62,200,200,0,0,,,0,0,0,0,,,0,0,0,0,,,0,0,0,0,,,0,0,0,0,,,0,0,0,0,,,0,0,0,0,,,0,0,0,0,,,0,0,0,0,,,0,0,0,0,AAPL
2024-10-22 12:36:57.029563793+00:00,10,40,38,A,B,0,234.62,200,194,203555,85224,,234.62,0,200,0,0,,,0,0,0,0,,,0,0,0,0,,,0,0,0,0,,,0,0,0,0,,,0,0,0,0,,,0,0,0,0,,,0,0,0,0,,,0,0,0,0,,,0,0,0,0,AAPL
2024-10-22 12:36:57.029583493+00:00,10,40,38,A,B,0,234.62,200,194,203444,85225,233.81,234.62,200,200,0,0,,,0,0,0,0,,,0,0,0,0,,,0,0,0,0,,,0,0,0,0,,,0,0,0,0,,,0,0,0,0,,,0,0,0,0,,,0,0,0,0,,,0,0,0,0,AAPL
2024-10-22 12:36:58.682731182+00:00,10,39,38,C,B,0,233.4,2000,130,202960,53590,,,0,0,0,0,,,0,0,0,0,,,0,0,0,0,,,0,0,0,0,,,0,0,0,0,,,0,0,0,0,,,0,0,0,0,,,0,0,0,0,,,0,0,0,0,,,0,0,0,0,AAPL
2024-10-22 12:36:58.720300840+00:00,10,39,38,A,B,0,233.4,2000,130,202758,53591,233.4,,2000,0,1,0,,,0,0,0,0,,,0,0,0,0,,,0,0,0,0,,,0,0,0,0,,,0,0,0,0,,,0,0,0,0,,,0,0,0,0,,,0,0,0,0,,,0,0,0,0,AAPL
2024-10-22 12:36:59.008679765+00:00,10,41,38,A,A,0,,0,194,56395,157652,233.82,,200,0,0,0,,,0,0,0,0,,,0,0,0,0,,,0,0,0,0,,,0,0,0,0,,,0,0,0,0,,,0,0,0,0,,,0,0,0,0,,,0,0,0,0,,,0,0,0,0,AAPL
2024-10-22 12:36:59.008722643+00:00,10,41,38,A,A,0,234.45,200,194,57783,157653,233.82,234.45,200,200,0,0,,,0,0,0,0,,,0,0,0,0,,,0,0,0,0,,,0,0,0,0,,,0,0,0,0,,,0,0,0,0,,,0,0,0,0,,,0,0,0,0,,,0,0,0,0,AAPL
2024-10-22 12:37:00.015351866+00:00,10,40,38,A,B,0,234.62,200,194,203558,85268,,234.62,0,200,0,0,,,0,0,0,0,,,0,0,0,0,,,0,0,0,0,,,0,0,0,0,,,0,0,0,0,,,0,0,0,0,,,0,0,0,0,,,0,0,0,0,,,0,0,0,0,AAPL
2024-10-22 12:37:00.015374280+00:00,10,40,38,A,B,0,234.62,200,194,203382,85269,233.76,234.62,200,200,0,0,,,0,0,0,0,,,0,0,0,0,,,0,0,0,0,,,0,0,0,0,,,0,0,0,0,,,0,0,0,0,,,0,0,0,0,,,0,0,0,0,,,0,0,0,0,AAPL
2024-10-22 12:37:00.015601597+00:00,10,41,38,A,B,0,234.45,200,194,56733,157747,,234.45,0,200,0,0,,,0,0,0,0,,,0,0,0,0,,,0,0,0,0,,,0,0,0,0,,,0,0,0,0,,,0,0,0,0,,,0,0,0,0,,,0,0,0,0,,,0,0,0,0,AAPL
2024-10-22 12:37:00.066214207+00:00,10,41,38,A,B,0,234.45,200,194,60060,157951,233.82,234.45,200,200,0,0,,,0,0,0,0,,,0,0,0,0,,,0,0,0,0,,,0,0,0,0,,,0,0,0,0,,,0,0,0,0,,,0,0,0,0,,,0,0,0,0,,,0,0,0,0,AAPL
2024-10-22 12:37:05.496046931+00:00,10,39,38,C,B,0,233.4,2000,130,202979,53665,,,0,0,0,0,,,0,0,0,0,,,0,0,0,0,,,0,0,0,0,,,0,0,0,0,,,0,0,0,0,,,0,0,0,0,,,0,0,0,0,,,0,0,0,0,,,0,0,0,0,AAPL
2024-10-22 12:37:05.532879827+00:00,10,39,38,A,B,0,233.2,2000,130,203003,53666,233.2,,2000,0,1,0,,,0,0,0,0,,,0,0,0,0,,,0,0,0,0,,,0,0,0,0,,,0,0,0,0,,,0,0,0,0,,,0,0,0,0,,,0,0,0,0,,,0,0,0,0,AAPL
2024-10-22 12:37:09.064102875+00:00,10,40,38,A,A,0,,0,194,204171,85559,233.76,,200,0,0,0,,,0,0,0,0,,,0,0,0,0,,,0,0,0,0,,,0,0,0,0,,,0,0,0,0,,,0,0,0,0,,,0,0,0,0,,,0,0,0,0,,,0,0,0,0,AAPL
2024-10-22 12:37:09.064117333+00:00,10,40,38,A,A,0,234.5,200,194,203728,85560,233.76,234.5,200,200,0,0,,,0,0,0,0,,,0,0,0,0,,,0,0,0,0,,,0,0,0,0,,,0,0,0,0,,,0,0,0,0,,,0,0,0,0,,,0,0,0,0,,,0,0,0,0,AAPL
2024-10-22 12:37:29.894556830+00:00,10,39,38,C,B,0,233.2,2000,130,203688,53875,,,0,0,0,0,,,0,0,0,0,,,0,0,0,0,,,0,0,0,0,,,0,0,0,0,,,0,0,0,0,,,0,0,0,0,,,0,0,0,0,,,0,0,0,0,,,0,0,0,0,AAPL
2024-10-22 12:37:29.911310334+00:00,10,39,38,A,A,0,236.4,2000,130,203519,53876,,236.4,0,2000,0,1,,,0,0,0,0,,,0,0,0,0,,,0,0,0,0,,,0,0,0,0,,,0,0,0,0,,,0,0,0,0,,,0,0,0,0,,,0,0,0,0,,,0,0,0,0,AAPL
2024-10-22 12:37:29.925830872+00:00,10,39,38,C,A,0,236.4,2000,130,203300,53877,,,0,0,0,0,,,0,0,0,0,,,0,0,0,0,,,0,0,0,0,,,0,0,0,0,,,0,0,0,0,,,0,0,0,0,,,0,0,0,0,,,0,0,0,0,,,0,0,0,0,AAPL
2024-10-22 12:37:29.937564199+00:00,10,39,38,A,B,0,232.6,2000,130,203419,53878,232.6,,2000,0,1,0,,,0,0,0,0,,,0,0,0,0,,,0,0,0,0,,,0,0,0,0,,,0,0,0,0,,,0,0,0,0,,,0,0,0,0,,,0,0,0,0,,,0,0,0,0,AAPL
2024-10-22 12:37:30.011074102+00:00,10,40,38,A,B,0,234.5,200,194,203746,85824,,234.5,0,200,0,0,,,0,0,0,0,,,0,0,0,0,,,0,0,0,0,,,0,0,0,0,,,0,0,0,0,,,0,0,0,0,,,0,0,0,0,,,0,0,0,0,,,0,0,0,0,AAPL
2024-10-22 12:37:30.011530763+00:00,10,41,38,A,B,0,234.45,200,194,55856,159530,,234.45,0,200,0,0,,,0,0,0,0,,,0,0,0,0,,,0,0,0,0,,,0,0,0,0,,,0,0,0,0,,,0,0,0,0,,,0,0,0,0,,,0,0,0,0,,,0,0,0,0,AAPL
2024-10-22 12:37:30.187919034+00:00,10,40,38,A,A,0,,0,194,203568,85828,,,0,0,0,0,,,0,0,0,0,,,0,0,0,0,,,0,0,0,0,,,0,0,0,0,,,0,0,0,0,,,0,0,0,0,,,0,0,0,0,,,0,0,0,0,,,0,0,0,0,AAPL
2024-10-22 12:37:30.187936889+00:00,10,40,38,A,A,0,234.37,200,194,203587,85829,,234.37,0,200,0,0,,,0,0,0,0,,,0,0,0,0,,,0,0,0,0,,,0,0,0,0,,,0,0,0,0,,,0,0,0,0,,,0,0,0,0,,,0,0,0,0,,,0,0,0,0,AAPL
2024-10-22 12:37:30.188161717+00:00,10,41,38,A,A,0,,0,194,60381,159533,,,0,0,0,0,,,0,0,0,0,,,0,0,0,0,,,0,0,0,0,,,0,0,0,0,,,0,0,0,0,,,0,0,0,0,,,0,0,0,0,,,0,0,0,0,,,0,0,0,0,AAPL
2024-10-22 12:37:30.188187607+00:00,10,41,38,A,A,0,234.31,200,194,56413,159534,,234.31,0,200,0,0,,,0,0,0,0,,,0,0,0,0,,,0,0,0,0,,,0,0,0,0,,,0,0,0,0,,,0,0,0,0,,,0,0,0,0,,,0,0,0,0,,,0,0,0,0,AAPL
2024-10-22 12:37:30.239368610+00:00,10,39,38,A,A,0,236.2,2000,130,203636,53888,232.6,236.2,2000,2000,1,1,,,0,0,0,0,,,0,0,0,0,,,0,0,0,0,,,0,0,0,0,,,0,0,0,0,,,0,0,0,0,,,0,0,0,0,,,0,0,0,0,,,0,0,0,0,AAPL
2024-10-22 12:37:30.472068768+00:00,10,40,38,A,B,0,234.37,200,194,203540,85836,233.56,234.37,200,200,0,0,,,0,0,0,0,,,0,0,0,0,,,0,0,0,0,,,0,0,0,0,,,0,0,0,0,,,0,0,0,0,,,0,0,0,0,,,0,0,0,0,,,0,0,0,0,AAPL
2024-10-22 12:37:30.483360389+00:00,10,39,38,A,B,0,233.0,2000,130,203611,53889,233.0,236.2,2000,2000,1,1,232.6,,2000,0,1,0,,,0,0,0,0,,,0,0,0,0,,,0,0,0,0,,,0,0,0,0,,,0,0,0,0,,,0,0,0,0,,,0,0,0,0,,,0,0,0,0,AAPL
2024-10-22 12:37:30.483540006+00:00,10,39,38,C,B,1,232.6,2000,130,203463,53890,233.0,236.2,2000,2000,1,1,,,0,0,0,0,,,0,0,0,0,,,0,0,0,0,,,0,0,0,0,,,0,0,0,0,,,0,0,0,0,,,0,0,0,0,,,0,0,0,0,,,0,0,0,0,AAPL
2024-10-22 12:37:30.786950671+00:00,10,41,38,A,B,0,234.31,200,194,55318,159547,233.62,234.31,200,200,0,0,,,0,0,0,0,,,0,0,0,0,,,0,0,0,0,,,0,0,0,0,,,0,0,0,0,,,0,0,0,0,,,0,0,0,0,,,0,0,0,0,,,0,0,0,0,AAPL
2024-10-22 12:37:30.910904817+00:00,10,39,38,C,A,0,236.2,2000,130,204108,53895,233.0,,2000,0,1,0,,,0,0,0,0,,,0,0,0,0,,,0,0,0,0,,,0,0,0,0,,,0,0,0,0,,,0,0,0,0,,,0,0,0,0,,,0,0,0,0,,,0,0,0,0,AAPL
2024-10-22 12:37:30.922652662+00:00,10,39,38,A,A,0,236.4,2000,130,203536,53896,233.0,236.4,2000,2000,1,1,,,0,0,0,0,,,0,0,0,0,,,0,0,0,0,,,0,0,0,0,,,0,0,0,0,,,0,0,0,0,,,0,0,0,0,,,0,0,0,0,,,0,0,0,0,AAPL
2024-10-22 12:37:31.211371138+00:00,10,41,38,A,B,0,234.31,200,194,60194,159560,,234.31,0,200,0,0,,,0,0,0,0,,,0,0,0,0,,,0,0,0,0,,,0,0,0,0,,,0,0,0,0,,,0,0,0,0,,,0,0,0,0,,,0,0,0,0,,,0,0,0,0,AAPL
2024-10-22 12:37:31.275923569+00:00,10,39,38,C,B,0,233.0,2000,130,203489,53904,,236.4,0,2000,0,1,,,0,0,0,0,,,0,0,0,0,,,0,0,0,0,,,0,0,0,0,,,0,0,0,0,,,0,0,0,0,,,0,0,0,0,,,0,0,0,0,,,0,0,0,0,AAPL
2024-10-22 12:37:31.289956449+00:00,10,39,38,A,B,0,232.8,2000,130,203493,53905,232.8,236.4,2000,2000,1,1,,,0,0,0,0,,,0,0,0,0,,,0,0,0,0,,,0,0,0,0,,,0,0,0,0,,,0,0,0,0,,,0,0,0,0,,,0,0,0,0,,,0,0,0,0,AAPL
2024-10-22 12:37:31.716176301+00:00,10,41,38,A,B,0,234.31,200,194,60216,159570,233.66,234.31,200,200,0,0,,,0,0,0,0,,,0,0,0,0,,,0,0,0,0,,,0,0,0,0,,,0,0,0,0,,,0,0,0,0,,,0,0,0,0,,,0,0,0,0,,,0,0,0,0,AAPL
2024-10-22 12:37:44.422927858+00:00,10,39,38,C,A,0,236.4,2000,130,203198,53996,232.8,,2000,0,1,0,,,0,0,0,0,,,0,0,0,0,,,0,0,0,0,,,0,0,0,0,,,0,0,0,0,,,0,0,0,0,,,0,0,0,0,,,0,0,0,0,,,0,0,0,0,AAPL
2024-10-22 12:37:59.750858141+00:00,10,39,38,C,B,0,232.8,2000,130,203712,54064,,,0,0,0,0,,,0,0,0,0,,,0,0,0,0,,,0,0,0,0,,,0,0,0,0,,,0,0,0,0,,,0,0,0,0,,,0,0,0,0,,,0,0,0,0,,,0,0,0,0,AAPL
2024-10-22 12:37:59.761596692+00:00,10,39,38,A,B,0,232.6,2000,130,203614,54065,232.6,,2000,0,1,0,,,0,0,0,0,,,0,0,0,0,,,0,0,0,0,,,0,0,0,0,,,0,0,0,0,,,0,0,0,0,,,0,0,0,0,,,0,0,0,0,,,0,0,0,0,AAPL
2024-10-22 12:38:00.400107892+00:00,10,39,38,A,B,0,232.8,2000,130,203812,54077,232.8,,2000,0,1,0,232.6,,2000,0,1,0,,,0,0,0,0,,,0,0,0,0,,,0,0,0,0,,,0,0,0,0,,,0,0,0,0,,,0,0,0,0,,,0,0,0,0,,,0,0,0,0,AAPL
2024-10-22 12:38:00.400287376+00:00,10,39,38,C,B,1,232.6,2000,130,203649,54078,232.8,,2000,0,1,0,,,0,0,0,0,,,0,0,0,0,,,0,0,0,0,,,0,0,0,0,,,0,0,0,0,,,0,0,0,0,,,0,0,0,0,,,0,0,0,0,,,0,0,0,0,AAPL
2024-10-22 12:38:01.011615300+00:00,10,39,38,A,B,0,233.0,2000,130,203787,54084,233.0,,2000,0,1,0,232.8,,2000,0,1,0,,,0,0,0,0,,,0,0,0,0,,,0,0,0,0,,,0,0,0,0,,,0,0,0,0,,,0,0,0,0,,,0,0,0,0,,,0,0,0,0,AAPL
2024-10-22 12:38:01.011803766+00:00,10,39,38,C,B,1,232.8,2000,130,203601,54085,233.0,,2000,0,1,0,,,0,0,0,0,,,0,0,0,0,,,0,0,0,0,,,0,0,0,0,,,0,0,0,0,,,0,0,0,0,,,0,0,0,0,,,0,0,0,0,,,0,0,0,0,AAPL
2024-10-22 12:38:01.039141993+00:00,10,39,38,C,B,0,233.0,2000,130,203627,54086,,,0,0,0,0,,,0,0,0,0,,,0,0,0,0,,,0,0,0,0,,,0,0,0,0,,,0,0,0,0,,,0,0,0,0,,,0,0,0,0,,,0,0,0,0,,,0,0,0,0,AAPL
2024-10-22 12:38:01.050557495+00:00,10,39,38,A,B,0,233.0,2000,130,203598,54087,233.0,,2000,0,1,0,,,0,0,0,0,,,0,0,0,0,,,0,0,0,0,,,0,0,0,0,,,0,0,0,0,,,0,0,0,0,,,0,0,0,0,,,0,0,0,0,,,0,0,0,0,AAPL
2024-10-22 12:38:01.065080585+00:00,10,39,38,C,B,0,233.0,2000,130,203565,54088,,,0,0,0,0,,,0,0,0,0,,,0,0,0,0,,,0,0,0,0,,,0,0,0,0,,,0,0,0,0,,,0,0,0,0,,,0,0,0,0,,,0,0,0,0,,,0,0,0,0,AAPL
2024-10-22 12:38:01.080402865+00:00,10,39,38,A,B,0,233.0,2000,130,203629,54089,233.0,,2000,0,1,0,,,0,0,0,0,,,0,0,0,0,,,0,0,0,0,,,0,0,0,0,,,0,0,0,0,,,0,0,0,0,,,0,0,0,0,,,0,0,0,0,,,0,0,0,0,AAPL
2024-10-22 12:38:04.242492942+00:00,10,39,38,C,B,0,233.0,2000,130,204008,54105,,,0,0,0,0,,,0,0,0,0,,,0,0,0,0,,,0,0,0,0,,,0,0,0,0,,,0,0,0,0,,,0,0,0,0,,,0,0,0,0,,,0,0,0,0,,,0,0,0,0,AAPL
2024-10-22 12:38:04.279423820+00:00,10,39,38,A,B,0,232.6,2000,130,203769,54106,232.6,,2000,0,1,0,,,0,0,0,0,,,0,0,0,0,,,0,0,0,0,,,0,0,0,0,,,0,0,0,0,,,0,0,0,0,,,0,0,0,0,,,0,0,0,0,,,0,0,0,0,AAPL
2024-10-22 12:38:08.168475910+00:00,10,39,38,A,B,0,233.0,2000,130,203950,54127,233.0,,2000,0,1,0,232.6,,2000,0,1,0,,,0,0,0,0,,,0,0,0,0,,,0,0,0,0,,,0,0,0,0,,,0,0,0,0,,,0,0,0,0,,,0,0,0,0,,,0,0,0,0,AAPL
2024-10-22 12:38:08.168667210+00:00,10,39,38,C,B,1,232.6,2000,130,203636,54128,233.0,,2000,0,1,0,,,0,0,0,0,,,0,0,0,0,,,0,0,0,0,,,0,0,0,0,,,0,0,0,0,,,0,0,0,0,,,0,0,0,0,,,0,0,0,0,,,0,0,0,0,AAPL
2024-10-22 12:38:08.221681208+00:00,10,39,38,C,B,0,233.0,2000,130,203569,54129,,,0,0,0,0,,,0,0,0,0,,,0,0,0,0,,,0,0,0,0,,,0,0,0,0,,,0,0,0,0,,,0,0,0,0,,,0,0,0,0,,,0,0,0,0,,,0,0,0,0,AAPL
2024-10-22 12:38:08.237865810+00:00,10,39,38,A,B,0,232.8,2000,130,203631,54130,232.8,,2000,0,1,0,,,0,0,0,0,,,0,0,0,0,,,0,0,0,0,,,0,0,0,0,,,0,0,0,0,,,0,0,0,0,,,0,0,0,0,,,0,0,0,0,,,0,0,0,0,AAPL
2024-10-22 12:38:22.744808782+00:00,10,39,38,A,B,0,233.0,2000,130,203995,54296,233.0,,2000,0,1,0,232.8,,2000,0,1,0,,,0,0,0,0,,,0,0,0,0,,,0,0,0,0,,,0,0,0,0,,,0,0,0,0,,,0,0,0,0,,,0,0,0,0,,,0,0,0,0,AAPL
2024-10-22 12:38:22.745000094+00:00,10,39,38,C,B,1,232.8,2000,130,203877,54297,233.0,,2000,0,1,0,,,0,0,0,0,,,0,0,0,0,,,0,0,0,0,,,0,0,0,0,,,0,0,0,0,,,0,0,0,0,,,0,0,0,0,,,0,0,0,0,,,0,0,0,0,AAPL
2024-10-22 12:38:22.764627945+00:00,10,39,38,C,B,0,233.0,2000,130,203624,54298,,,0,0,0,0,,,0,0,0,0,,,0,0,0,0,,,0,0,0,0,,,0,0,0,0,,,0,0,0,0,,,0,0,0,0,,,0,0,0,0,,,0,0,0,0,,,0,0,0,0,AAPL
2024-10-22 12:38:22.775495689+00:00,10,39,38,A,B,0,233.0,2000,130,203719,54299,233.0,,2000,0,1,0,,,0,0,0,0,,,0,0,0,0,,,0,0,0,0,,,0,0,0,0,,,0,0,0,0,,,0,0,0,0,,,0,0,0,0,,,0,0,0,0,,,0,0,0,0,AAPL
2024-10-22 12:38:22.795303525+00:00,10,39,38,C,B,0,233.0,2000,130,203836,54300,,,0,0,0,0,,,0,0,0,0,,,0,0,0,0,,,0,0,0,0,,,0,0,0,0,,,0,0,0,0,,,0,0,0,0,,,0,0,0,0,,,0,0,0,0,,,0,0,0,0,AAPL
2024-10-22 12:38:22.806660361+00:00,10,39,38,A,B,0,233.0,2000,130,203708,54301,233.0,,2000,0,1,0,,,0,0,0,0,,,0,0,0,0,,,0,0,0,0,,,0,0,0,0,,,0,0,0,0,,,0,0,0,0,,,0,0,0,0,,,0,0,0,0,,,0,0,0,0,AAPL
2024-10-22 12:38:36.425215899+00:00,10,40,38,A,B,0,234.37,200,194,203800,86593,,234.37,0,200,0,0,,,0,0,0,0,,,0,0,0,0,,,0,0,0,0,,,0,0,0,0,,,0,0,0,0,,,0,0,0,0,,,0,0,0,0,,,0,0,0,0,,,0,0,0,0,AAPL
2024-10-22 12:38:36.425239820+00:00,10,40,38,A,B,0,234.37,200,194,203732,86594,233.68,234.37,200,200,0,0,,,0,0,0,0,,,0,0,0,0,,,0,0,0,0,,,0,0,0,0,,,0,0,0,0,,,0,0,0,0,,,0,0,0,0,,,0,0,0,0,,,0,0,0,0,AAPL
2024-10-22 12:38:36.425312747+00:00,10,39,38,C,B,0,233.0,2000,130,203679,54412,,,0,0,0,0,,,0,0,0,0,,,0,0,0,0,,,0,0,0,0,,,0,0,0,0,,,0,0,0,0,,,0,0,0,0,,,0,0,0,0,,,0,0,0,0,,,0,0,0,0,AAPL
2024-10-22 12:38:36.436304506+00:00,10,39,38,A,B,0,232.8,2000,130,203621,54413,232.8,,2000,0,1,0,,,0,0,0,0,,,0,0,0,0,,,0,0,0,0,,,0,0,0,0,,,0,0,0,0,,,0,0,0,0,,,0,0,0,0,,,0,0,0,0,,,0,0,0,0,AAPL
2024-10-22 12:38:37.096468645+00:00,10,39,38,A,B,0,233.0,2000,130,203620,54429,233.0,,2000,0,1,0,232.8,,2000,0,1,0,,,0,0,0,0,,,0,0,0,0,,,0,0,0,0,,,0,0,0,0,,,0,0,0,0,,,0,0,0,0,,,0,0,0,0,,,0,0,0,0,AAPL
2024-10-22 12:38:37.096665930+00:00,10,39,38,C,B,1,232.8,2000,130,203540,54430,233.0,,2000,0,1,0,,,0,0,0,0,,,0,0,0,0,,,0,0,0,0,,,0,0,0,0,,,0,0,0,0,,,0,0,0,0,,,0,0,0,0,,,0,0,0,0,,,0,0,0,0,AAPL
2024-10-22 12:38:37.147045174+00:00,10,39,38,C,B,0,233.0,2000,130,203587,54432,,,0,0,0,0,,,0,0,0,0,,,0,0,0,0,,,0,0,0,0,,,0,0,0,0,,,0,0,0,0,,,0,0,0,0,,,0,0,0,0,,,0,0,0,0,,,0,0,0,0,AAPL
2024-10-22 12:38:37.157822540+00:00,10,39,38,A,B,0,232.8,2000,130,203689,54433,232.8,,2000,0,1,0,,,0,0,0,0,,,0,0,0,0,,,0,0,0,0,,,0,0,0,0,,,0,0,0,0,,,0,0,0,0,,,0,0,0,0,,,0,0,0,0,,,0,0,0,0,AAPL
2024-10-22 12:38:40.290595456+00:00,10,39,38,C,B,0,232.8,2000,130,203463,54485,,,0,0,0,0,,,0,0,0,0,,,0,0,0,0,,,0,0,0,0,,,0,0,0,0,,,0,0,0,0,,,0,0,0,0,,,0,0,0,0,,,0,0,0,0,,,0,0,0,0,AAPL
2024-10-22 12:38:40.326728659+00:00,10,39,38,A,B,0,233.0,2000,130,203493,54488,233.0,,2000,0,1,0,,,0,0,0,0,,,0,0,0,0,,,0,0,0,0,,,0,0,0,0,,,0,0,0,0,,,0,0,0,0,,,0,0,0,0,,,0,0,0,0,,,0,0,0,0,AAPL
2024-10-22 12:38:42.874300859+00:00,10,39,38,A,A,0,236.4,2000,130,203768,54513,233.0,236.4,2000,2000,1,1,,,0,0,0,0,,,0,0,0,0,,,0,0,0,0,,,0,0,0,0,,,0,0,0,0,,,0,0,0,0,,,0,0,0,0,,,0,0,0,0,,,0,0,0,0,AAPL
2024-10-22 12:38:42.886011645+00:00,10,39,38,C,A,0,236.4,2000,130,203439,54514,233.0,,2000,0,1,0,,,0,0,0,0,,,0,0,0,0,,,0,0,0,0,,,0,0,0,0,,,0,0,0,0,,,0,0,0,0,,,0,0,0,0,,,0,0,0,0,,,0,0,0,0,AAPL
2024-10-22 12:38:48.938270988+00:00,10,39,38,C,B,0,233.0,2000,130,203952,54572,,,0,0,0,0,,,0,0,0,0,,,0,0,0,0,,,0,0,0,0,,,0,0,0,0,,,0,0,0,0,,,0,0,0,0,,,0,0,0,0,,,0,0,0,0,,,0,0,0,0,AAPL
2024-10-22 12:38:48.949349895+00:00,10,39,38,A,B,0,232.8,2000,130,203835,54573,232.8,,2000,0,1,0,,,0,0,0,0,,,0,0,0,0,,,0,0,0,0,,,0,0,0,0,,,0,0,0,0,,,0,0,0,0,,,0,0,0,0,,,0,0,0,0,,,0,0,0,0,AAPL
2024-10-22 12:38:49.173352862+00:00,10,41,38,A,A,0,,0,194,63097,162388,233.66,,200,0,0,0,,,0,0,0,0,,,0,0,0,0,,,0,0,0,0,,,0,0,0,0,,,0,0,0,0,,,0,0,0,0,,,0,0,0,0,,,0,0,0,0,,,0,0,0,0,AAPL
2024-10-22 12:38:49.173429390+00:00,10,41,38,A,A,0,234.41,200,194,55003,162389,233.66,234.41,200,200,0,0,,,0,0,0,0,,,0,0,0,0,,,0,0,0,0,,,0,0,0,0,,,0,0,0,0,,,0,0,0,0,,,0,0,0,0,,,0,0,0,0,,,0,0,0,0,AAPL
2024-10-22 12:38:57.722624508+00:00,10,39,38,C,B,0,232.8,2000,130,203690,54642,,,0,0,0,0,,,0,0,0,0,,,0,0,0,0,,,0,0,0,0,,,0,0,0,0,,,0,0,0,0,,,0,0,0,0,,,0,0,0,0,,,0,0,0,0,,,0,0,0,0,AAPL
2024-10-22 12:38:57.758368601+00:00,10,39,38,A,B,0,232.6,2000,130,203624,54644,232.6,,2000,0,1,0,,,0,0,0,0,,,0,0,0,0,,,0,0,0,0,,,0,0,0,0,,,0,0,0,0,,,0,0,0,0,,,0,0,0,0,,,0,0,0,0,,,0,0,0,0,AAPL
2024-10-22 12:38:58.039259237+00:00,10,41,38,A,A,0,,0,194,60361,162584,233.66,,200,0,0,0,,,0,0,0,0,,,0,0,0,0,,,0,0,0,0,,,0,0,0,0,,,0,0,0,0,,,0,0,0,0,,,0,0,0,0,,,0,0,0,0,,,0,0,0,0,AAPL
2024-10-22 12:38:58.039317079+00:00,10,41,38,A,A,0,234.3,200,194,54613,162585,233.66,234.3,200,200,0,0,,,0,0,0,0,,,0,0,0,0,,,0,0,0,0,,,0,0,0,0,,,0,0,0,0,,,0,0,0,0,,,0,0,0,0,,,0,0,0,0,,,0,0,0,0,AAPL
2024-10-22 12:39:01.088034268+00:00,10,39,38,C,B,0,232.6,2000,130,203779,54672,,,0,0,0,0,,,0,0,0,0,,,0,0,0,0,,,0,0,0,0,,,0,0,0,0,,,0,0,0,0,,,0,0,0,0,,,0,0,0,0,,,0,0,0,0,,,0,0,0,0,AAPL
2024-10-22 12:39:01.099418845+00:00,10,39,38,A,B,0,232.4,2000,130,203698,54673,232.4,,2000,0,1,0,,,0,0,0,0,,,0,0,0,0,,,0,0,0,0,,,0,0,0,0,,,0,0,0,0,,,0,0,0,0,,,0,0,0,0,,,0,0,0,0,,,0,0,0,0,AAPL
2024-10-22 12:39:01.115057179+00:00,10,39,38,A,B,0,232.8,2000,130,203745,54674,232.8,,2000,0,1,0,232.4,,2000,0,1,0,,,0,0,0,0,,,0,0,0,0,,,0,0,0,0,,,0,0,0,0,,,0,0,0,0,,,0,0,0,0,,,0,0,0,0,,,0,0,0,0,AAPL
2024-10-22 12:39:01.115261364+00:00,10,39,38,C,B,1,232.4,2000,130,203605,54675,232.8,,2000,0,1,0,,,0,0,0,0,,,0,0,0,0,,,0,0,0,0,,,0,0,0,0,,,0,0,0,0,,,0,0,0,0,,,0,0,0,0,,,0,0,0,0,,,0,0,0,0,AAPL
2024-10-22 12:39:01.126929917+00:00,10,39,38,A,B,0,233.0,2000,130,203613,54676,233.0,,2000,0,1,0,232.8,,2000,0,1,0,,,0,0,0,0,,,0,0,0,0,,,0,0,0,0,,,0,0,0,0,,,0,0,0,0,,,0,0,0,0,,,0,0,0,0,,,0,0,0,0,AAPL
2024-10-22 12:39:01.127120023+00:00,10,39,38,C,B,1,232.8,2000,130,203539,54677,233.0,,2000,0,1,0,,,0,0,0,0,,,0,0,0,0,,,0,0,0,0,,,0,0,0,0,,,0,0,0,0,,,0,0,0,0,,,0,0,0,0,,,0,0,0,0,,,0,0,0,0,AAPL
2024-10-22 12:39:04.485524856+00:00,10,39,38,C,B,0,233.0,2000,130,203657,54695,,,0,0,0,0,,,0,0,0,0,,,0,0,0,0,,,0,0,0,0,,,0,0,0,0,,,0,0,0,0,,,0,0,0,0,,,0,0,0,0,,,0,0,0,0,,,0,0,0,0,AAPL
2024-10-22 12:39:04.521677146+00:00,10,39,38,A,B,0,232.8,2000,130,203679,54696,232.8,,2000,0,1,0,,,0,0,0,0,,,0,0,0,0,,,0,0,0,0,,,0,0,0,0,,,0,0,0,0,,,0,0,0,0,,,0,0,0,0,,,0,0,0,0,,,0,0,0,0,AAPL
2024-10-22 12:39:04.795301272+00:00,10,40,38,A,B,0,234.37,200,194,202981,87016,,234.37,0,200,0,0,,,0,0,0,0,,,0,0,0,0,,,0,0,0,0,,,0,0,0,0,,,0,0,0,0,,,0,0,0,0,,,0,0,0,0,,,0,0,0,0,,,0,0,0,0,AAPL
2024-10-22 12:39:04.795317699+00:00,10,40,38,A,B,0,234.37,200,194,202739,87017,233.54,234.37,200,200,0,0,,,0,0,0,0,,,0,0,0,0,,,0,0,0,0,,,0,0,0,0,,,0,0,0,0,,,0,0,0,0,,,0,0,0,0,,,0,0,0,0,,,0,0,0,0,AAPL
2024-10-22 12:39:05.487510657+00:00,10,39,38,C,B,0,232.8,2000,130,203917,54699,,,0,0,0,0,,,0,0,0,0,,,0,0,0,0,,,0,0,0,0,,,0,0,0,0,,,0,0,0,0,,,0,0,0,0,,,0,0,0,0,,,0,0,0,0,,,0,0,0,0,AAPL
2024-10-22 12:39:05.523067179+00:00,10,39,38,A,B,0,232.8,2000,130,203800,54701,232.8,,2000,0,1,0,,,0,0,0,0,,,0,0,0,0,,,0,0,0,0,,,0,0,0,0,,,0,0,0,0,,,0,0,0,0,,,0,0,0,0,,,0,0,0,0,,,0,0,0,0,AAPL
2024-10-22 12:39:06.487383916+00:00,10,39,38,C,B,0,232.8,2000,130,204080,54704,,,0,0,0,0,,,0,0,0,0,,,0,0,0,0,,,0,0,0,0,,,0,0,0,0,,,0,0,0,0,,,0,0,0,0,,,0,0,0,0,,,0,0,0,0,,,0,0,0,0,AAPL
2024-10-22 12:39:06.516079876+00:00,10,39,38,A,B,0,232.6,2000,130,203762,54705,232.6,,2000,0,1,0,,,0,0,0,0,,,0,0,0,0,,,0,0,0,0,,,0,0,0,0,,,0,0,0,0,,,0,0,0,0,,,0,0,0,0,,,0,0,0,0,,,0,0,0,0,AAPL
2024-10-22 12:39:06.786177671+00:00,10,41,38,A,B,0,234.3,200,194,55910,163462,,234.3,0,200,0,0,,,0,0,0,0,,,0,0,0,0,,,0,0,0,0,,,0,0,0,0,,,0,0,0,0,,,0,0,0,0,,,0,0,0,0,,,0,0,0,0,,,0,0,0,0,AAPL
2024-10-22 12:39:06.786231576+00:00,10,41,38,A,B,0,234.3,200,194,54352,163463,233.54,234.3,200,200,0,0,,,0,0,0,0,,,0,0,0,0,,,0,0,0,0,,,0,0,0,0,,,0,0,0,0,,,0,0,0,0,,,0,0,0,0,,,0,0,0,0,,,0,0,0,0,AAPL
2024-10-22 12:39:06.987807545+00:00,10,40,38,A,A,0,,0,194,202836,87039,233.54,,200,0,0,0,,,0,0,0,0,,,0,0,0,0,,,0,0,0,0,,,0,0,0,0,,,0,0,0,0,,,0,0,0,0,,,0,0,0,0,,,0,0,0,0,,,0,0,0,0,AAPL
2024-10-22 12:39:06.987823335+00:00,10,40,38,A,A,0,234.24,200,194,202587,87040,233.54,234.24,200,200,0,0,,,0,0,0,0,,,0,0,0,0,,,0,0,0,0,,,0,0,0,0,,,0,0,0,0,,,0,0,0,0,,,0,0,0,0,,,0,0,0,0,,,0,0,0,0,AAPL
2024-10-22 12:39:06.988030483+00:00,10,41,38,A,A,0,,0,194,55920,163471,233.54,,200,0,0,0,,,0,0,0,0,,,0,0,0,0,,,0,0,0,0,,,0,0,0,0,,,0,0,0,0,,,0,0,0,0,,,0,0,0,0,,,0,0,0,0,,,0,0,0,0,AAPL
2024-10-22 12:39:06.988059891+00:00,10,41,38,A,A,0,234.18,200,194,54476,163472,233.54,234.18,200,200,0,0,,,0,0,0,0,,,0,0,0,0,,,0,0,0,0,,,0,0,0,0,,,0,0,0,0,,,0,0,0,0,,,0,0,0,0,,,0,0,0,0,,,0,0,0,0,AAPL
2024-10-22 12:39:11.666948860+00:00,10,39,38,C,B,0,232.6,2000,130,203777,54716,,,0,0,0,0,,,0,0,0,0,,,0,0,0,0,,,0,0,0,0,,,0,0,0,0,,,0,0,0,0,,,0,0,0,0,,,0,0,0,0,,,0,0,0,0,,,0,0,0,0,AAPL
2024-10-22 12:39:11.702749626+00:00,10,39,38,A,B,0,232.8,2000,130,203509,54717,232.8,,2000,0,1,0,,,0,0,0,0,,,0,0,0,0,,,0,0,0,0,,,0,0,0,0,,,0,0,0,0,,,0,0,0,0,,,0,0,0,0,,,0,0,0,0,,,0,0,0,0,AAPL
2024-10-22 12:39:11.777438096+00:00,10,39,38,C,B,0,232.8,2000,130,203587,54719,,,0,0,0,0,,,0,0,0,0,,,0,0,0,0,,,0,0,0,0,,,0,0,0,0,,,0,0,0,0,,,0,0,0,0,,,0,0,0,0,,,0,0,0,0,,,0,0,0,0,AAPL
2024-10-22 12:39:11.842049385+00:00,10,39,38,A,B,0,232.0,2000,130,203415,54729,232.0,,2000,0,1,0,,,0,0,0,0,,,0,0,0,0,,,0,0,0,0,,,0,0,0,0,,,0,0,0,0,,,0,0,0,0,,,0,0,0,0,,,0,0,0,0,,,0,0,0,0,AAPL
2024-10-22 12:39:11.845011220+00:00,10,39,38,C,B,0,232.0,2000,130,203373,54730,,,0,0,0,0,,,0,0,0,0,,,0,0,0,0,,,0,0,0,0,,,0,0,0,0,,,0,0,0,0,,,0,0,0,0,,,0,0,0,0,,,0,0,0,0,,,0,0,0,0,AAPL
2024-10-22 12:39:11.870478030+00:00,10,39,38,A,B,0,232.0,2000,130,203417,54735,232.0,,2000,0,1,0,,,0,0,0,0,,,0,0,0,0,,,0,0,0,0,,,0,0,0,0,,,0,0,0,0,,,0,0,0,0,,,0,0,0,0,,,0,0,0,0,,,0,0,0,0,AAPL
2024-10-22 12:39:13.561724808+00:00,10,40,38,A,B,0,234.24,200,194,202828,87120,,234.24,0,200,0,0,,,0,0,0,0,,,0,0,0,0,,,0,0,0,0,,,0,0,0,0,,,0,0,0,0,,,0,0,0,0,,,0,0,0,0,,,0,0,0,0,,,0,0,0,0,AAPL
2024-10-22 12:39:13.561743194+00:00,10,40,38,A,B,0,234.24,200,194,202826,87121,233.41,234.24,200,200,0,0,,,0,0,0,0,,,0,0,0,0,,,0,0,0,0,,,0,0,0,0,,,0,0,0,0,,,0,0,0,0,,,0,0,0,0,,,0,0,0,0,,,0,0,0,0,AAPL
2024-10-22 12:39:21.467871472+00:00,10,39,38,A,B,0,232.2,2000,130,203560,54826,232.2,,2000,0,1,0,232.0,,2000,0,1,0,,,0,0,0,0,,,0,0,0,0,,,0,0,0,0,,,0,0,0,0,,,0,0,0,0,,,0,0,0,0,,,0,0,0,0,,,0,0,0,0,AAPL
2024-10-22 12:39:21.468171149+00:00,10,39,38,C,B,1,232.0,2000,130,202995,54827,232.2,,2000,0,1,0,,,0,0,0,0,,,0,0,0,0,,,0,0,0,0,,,0,0,0,0,,,0,0,0,0,,,0,0,0,0,,,0,0,0,0,,,0,0,0,0,,,0,0,0,0,AAPL
2024-10-22 12:39:23.737667845+00:00,10,39,38,C,B,0,232.2,2000,130,203064,54848,,,0,0,0,0,,,0,0,0,0,,,0,0,0,0,,,0,0,0,0,,,0,0,0,0,,,0,0,0,0,,,0,0,0,0,,,0,0,0,0,,,0,0,0,0,,,0,0,0,0,AAPL
2024-10-22 12:39:23.773884136+00:00,10,39,38,A,B,0,231.8,2000,130,203059,54849,231.8,,2000,0,1,0,,,0,0,0,0,,,0,0,0,0,,,0,0,0,0,,,0,0,0,0,,,0,0,0,0,,,0,0,0,0,,,0,0,0,0,,,0,0,0,0,,,0,0,0,0,AAPL
2024-10-22 12:39:23.942893908+00:00,10,39,38,A,B,0,232.0,2000,130,203171,54850,232.0,,2000,0,1,0,231.8,,2000,0,1,0,,,0,0,0,0,,,0,0,0,0,,,0,0,0,0,,,0,0,0,0,,,0,0,0,0,,,0,0,0,0,,,0,0,0,0,,,0,0,0,0,AAPL
2024-10-22 12:39:23.943075692+00:00,10,39,38,C,B,1,231.8,2000,130,203291,54851,232.0,,2000,0,1,0,,,0,0,0,0,,,0,0,0,0,,,0,0,0,0,,,0,0,0,0,,,0,0,0,0,,,0,0,0,0,,,0,0,0,0,,,0,0,0,0,,,0,0,0,0,AAPL
2024-10-22 12:39:25.794180600+00:00,10,39,38,C,B,0,232.0,2000,130,203055,54866,,,0,0,0,0,,,0,0,0,0,,,0,0,0,0,,,0,0,0,0,,,0,0,0,0,,,0,0,0,0,,,0,0,0,0,,,0,0,0,0,,,0,0,0,0,,,0,0,0,0,AAPL
2024-10-22 12:39:25.805209212+00:00,10,39,38,A,B,0,231.8,2000,130,202912,54867,231.8,,2000,0,1,0,,,0,0,0,0,,,0,0,0,0,,,0,0,0,0,,,0,0,0,0,,,0,0,0,0,,,0,0,0,0,,,0,0,0,0,,,0,0,0,0,,,0,0,0,0,AAPL
2024-10-22 12:39:25.829861027+00:00,10,39,38,C,B,0,231.8,2000,130,202833,54868,,,0,0,0,0,,,0,0,0,0,,,0,0,0,0,,,0,0,0,0,,,0,0,0,0,,,0,0,0,0,,,0,0,0,0,,,0,0,0,0,,,0,0,0,0,,,0,0,0,0,AAPL
2024-10-22 12:39:25.842050639+00:00,10,39,38,A,B,0,231.6,2000,130,202872,54869,231.6,,2000,0,1,0,,,0,0,0,0,,,0,0,0,0,,,0,0,0,0,,,0,0,0,0,,,0,0,0,0,,,0,0,0,0,,,0,0,0,0,,,0,0,0,0,,,0,0,0,0,AAPL
2024-10-22 12:39:26.689416702+00:00,10,39,38,C,B,0,231.6,2000,130,202988,54875,,,0,0,0,0,,,0,0,0,0,,,0,0,0,0,,,0,0,0,0,,,0,0,0,0,,,0,0,0,0,,,0,0,0,0,,,0,0,0,0,,,0,0,0,0,,,0,0,0,0,AAPL
2024-10-22 12:39:26.726484877+00:00,10,39,38,A,B,0,231.8,2000,130,202859,54876,231.8,,2000,0,1,0,,,0,0,0,0,,,0,0,0,0,,,0,0,0,0,,,0,0,0,0,,,0,0,0,0,,,0,0,0,0,,,0,0,0,0,,,0,0,0,0,,,0,0,0,0,AAPL
2024-10-22 12:39:33.030876541+00:00,10,39,38,C,B,0,231.8,2000,130,203756,54904,,,0,0,0,0,,,0,0,0,0,,,0,0,0,0,,,0,0,0,0,,,0,0,0,0,,,0,0,0,0,,,0,0,0,0,,,0,0,0,0,,,0,0,0,0,,,0,0,0,0,AAPL
2024-10-22 12:39:33.044073622+00:00,10,39,38,A,B,0,231.6,2000,130,202856,54905,231.6,,2000,0,1,0,,,0,0,0,0,,,0,0,0,0,,,0,0,0,0,,,0,0,0,0,,,0,0,0,0,,,0,0,0,0,,,0,0,0,0,,,0,0,0,0,,,0,0,0,0,AAPL
2024-10-22 12:39:37.325013344+00:00,10,39,38,A,B,0,232.0,2000,130,203202,54924,232.0,,2000,0,1,0,231.6,,2000,0,1,0,,,0,0,0,0,,,0,0,0,0,,,0,0,0,0,,,0,0,0,0,,,0,0,0,0,,,0,0,0,0,,,0,0,0,0,,,0,0,0,0,AAPL
2024-10-22 12:39:37.325214888+00:00,10,39,38,C,B,1,231.6,2000,130,202882,54925,232.0,,2000,0,1,0,,,0,0,0,0,,,0,0,0,0,,,0,0,0,0,,,0,0,0,0,,,0,0,0,0,,,0,0,0,0,,,0,0,0,0,,,0,0,0,0,,,0,0,0,0,AAPL
2024-10-22 12:39:38.362116430+00:00,10,39,38,C,B,0,232.0,2000,130,202549,54938,,,0,0,0,0,,,0,0,0,0,,,0,0,0,0,,,0,0,0,0,,,0,0,0,0,,,0,0,0,0,,,0,0,0,0,,,0,0,0,0,,,0,0,0,0,,,0,0,0,0,AAPL
2024-10-22 12:39:38.397420562+00:00,10,39,38,A,B,0,232.0,2000,130,202668,54939,232.0,,2000,0,1,0,,,0,0,0,0,,,0,0,0,0,,,0,0,0,0,,,0,0,0,0,,,0,0,0,0,,,0,0,0,0,,,0,0,0,0,,,0,0,0,0,,,0,0,0,0,AAPL
2024-10-22 12:39:50.250327187+00:00,10,39,38,A,B,0,232.2,2000,130,203926,55049,232.2,,2000,0,1,0,232.0,,2000,0,1,0,,,0,0,0,0,,,0,0,0,0,,,0,0,0,0,,,0,0,0,0,,,0,0,0,0,,,0,0,0,0,,,0,0,0,0,,,0,0,0,0,AAPL
2024-10-22 12:39:50.250525414+00:00,10,39,38,C,B,1,232.0,2000,130,203322,55050,232.2,,2000,0,1,0,,,0,0,0,0,,,0,0,0,0,,,0,0,0,0,,,0,0,0,0,,,0,0,0,0,,,0,0,0,0,,,0,0,0,0,,,0,0,0,0,,,0,0,0,0,AAPL
2024-10-22 12:39:53.822363560+00:00,10,39,38,C,B,0,232.2,2000,130,203223,55081,,,0,0,0,0,,,0,0,0,0,,,0,0,0,0,,,0,0,0,0,,,0,0,0,0,,,0,0,0,0,,,0,0,0,0,,,0,0,0,0,,,0,0,0,0,,,0,0,0,0,AAPL
2024-10-22 12:39:53.833087126+00:00,10,39,38,A,B,0,231.8,2000,130,203323,55082,231.8,,2000,0,1,0,,,0,0,0,0,,,0,0,0,0,,,0,0,0,0,,,0,0,0,0,,,0,0,0,0,,,0,0,0,0,,,0,0,0,0,,,0,0,0,0,,,0,0,0,0,AAPL
2024-10-22 12:39:56.933206632+00:00,10,39,38,A,B,0,232.2,2000,130,204137,55094,232.2,,2000,0,1,0,231.8,,2000,0,1,0,,,0,0,0,0,,,0,0,0,0,,,0,0,0,0,,,0,0,0,0,,,0,0,0,0,,,0,0,0,0,,,0,0,0,0,,,0,0,0,0,AAPL
2024-10-22 12:39:56.933390976+00:00,10,39,38,C,B,1,231.8,2000,130,203428,55095,232.2,,2000,0,1,0,,,0,0,0,0,,,0,0,0,0,,,0,0,0,0,,,0,0,0,0,,,0,0,0,0,,,0,0,0,0,,,0,0,0,0,,,0,0,0,0,,,0,0,0,0,AAPL
2024-10-22 12:40:00.015226692+00:00,10,40,38,A,N,0,,0,194,203532,87630,,,0,0,0,0,,,0,0,0,0,,,0,0,0,0,,,0,0,0,0,,,0,0,0,0,,,0,0,0,0,,,0,0,0,0,,,0,0,0,0,,,0,0,0,0,,,0,0,0,0,AAPL
2024-10-22 12:40:00.015606779+00:00,10,41,38,A,B,0,234.18,200,194,58239,165335,,234.18,0,200,0,0,,,0,0,0,0,,,0,0,0,0,,,0,0,0,0,,,0,0,0,0,,,0,0,0,0,,,0,0,0,0,,,0,0,0,0,,,0,0,0,0,,,0,0,0,0,AAPL
2024-10-22 12:40:00.015614201+00:00,10,41,38,A,A,0,,0,194,55570,165339,,,0,0,0,0,,,0,0,0,0,,,0,0,0,0,,,0,0,0,0,,,0,0,0,0,,,0,0,0,0,,,0,0,0,0,,,0,0,0,0,,,0,0,0,0,,,0,0,0,0,AAPL
2024-10-22 12:40:00.038582099+00:00,10,40,38,A,A,0,234.19,200,194,203461,87687,,234.19,0,200,0,0,,,0,0,0,0,,,0,0,0,0,,,0,0,0,0,,,0,0,0,0,,,0,0,0,0,,,0,0,0,0,,,0,0,0,0,,,0,0,0,0,,,0,0,0,0,AAPL
2024-10-22 12:40:00.145378862+00:00,10,40,38,A,B,0,234.19,200,194,203331,87878,233.44,234.19,200,200,0,0,,,0,0,0,0,,,0,0,0,0,,,0,0,0,0,,,0,0,0,0,,,0,0,0,0,,,0,0,0,0,,,0,0,0,0,,,0,0,0,0,,,0,0,0,0,AAPL
2024-10-22 12:40:00.145564748+00:00,10,41,38,A,B,0,,0,194,57477,166449,233.5,,200,0,0,0,,,0,0,0,0,,,0,0,0,0,,,0,0,0,0,,,0,0,0,0,,,0,0,0,0,,,0,0,0,0,,,0,0,0,0,,,0,0,0,0,,,0,0,0,0,AAPL
2024-10-22 12:40:00.145568104+00:00,10,41,38,A,A,0,234.13,200,194,56000,166451,233.5,234.13,200,200,0,0,,,0,0,0,0,,,0,0,0,0,,,0,0,0,0,,,0,0,0,0,,,0,0,0,0,,,0,0,0,0,,,0,0,0,0,,,0,0,0,0,,,0,0,0,0,AAPL
2024-10-22 12:40:00.177624148+00:00,10,41,38,A,B,0,234.13,200,194,56158,166621,,234.13,0,200,0,0,,,0,0,0,0,,,0,0,0,0,,,0,0,0,0,,,0,0,0,0,,,0,0,0,0,,,0,0,0,0,,,0,0,0,0,,,0,0,0,0,,,0,0,0,0,AAPL
2024-10-22 12:40:00.233454812+00:00,10,40,38,A,B,0,234.19,200,194,203247,87981,,234.19,0,200,0,0,,,0,0,0,0,,,0,0,0,0,,,0,0,0,0,,,0,0,0,0,,,0,0,0,0,,,0,0,0,0,,,0,0,0,0,,,0,0,0,0,,,0,0,0,0,AAPL
2024-10-22 12:40:00.490277566+00:00,10,41,38,A,B,0,234.13,200,194,54516,167002,233.5,234.13,200,200,0,0,,,0,0,0,0,,,0,0,0,0,,,0,0,0,0,,,0,0,0,0,,,0,0,0,0,,,0,0,0,0,,,0,0,0,0,,,0,0,0,0,,,0,0,0,0,AAPL
2024-10-22 12:40:00.490184045+00:00,10,40,38,A,B,0,234.19,200,194,203281,88019,233.44,234.19,200,200,0,0,,,0,0,0,0,,,0,0,0,0,,,0,0,0,0,,,0,0,0,0,,,0,0,0,0,,,0,0,0,0,,,0,0,0,0,,,0,0,0,0,,,0,0,0,0,AAPL
2024-10-22 12:40:04.869041351+00:00,10,39,38,C,B,0,232.2,2000,130,203530,55182,,,0,0,0,0,,,0,0,0,0,,,0,0,0,0,,,0,0,0,0,,,0,0,0,0,,,0,0,0,0,,,0,0,0,0,,,0,0,0,0,,,0,0,0,0,,,0,0,0,0,AAPL
2024-10-22 12:40:04.879790776+00:00,10,39,38,A,B,0,232.0,2000,130,203630,55183,232.0,,2000,0,1,0,,,0,0,0,0,,,0,0,0,0,,,0,0,0,0,,,0,0,0,0,,,0,0,0,0,,,0,0,0,0,,,0,0,0,0,,,0,0,0,0,,,0,0,0,0,AAPL
2024-10-22 12:40:04.891152100+00:00,10,39,38,A,B,0,232.2,2000,130,203602,55184,232.2,,2000,0,1,0,232.0,,2000,0,1,0,,,0,0,0,0,,,0,0,0,0,,,0,0,0,0,,,0,0,0,0,,,0,0,0,0,,,0,0,0,0,,,0,0,0,0,,,0,0,0,0,AAPL
2024-10-22 12:40:04.891351966+00:00,10,39,38,C,B,1,232.0,2000,130,203507,55185,232.2,,2000,0,1,0,,,0,0,0,0,,,0,0,0,0,,,0,0,0,0,,,0,0,0,0,,,0,0,0,0,,,0,0,0,0,,,0,0,0,0,,,0,0,0,0,,,0,0,0,0,AAPL
2024-10-22 12:40:04.915471094+00:00,10,39,38,C,B,0,232.2,2000,130,203476,55186,,,0,0,0,0,,,0,0,0,0,,,0,0,0,0,,,0,0,0,0,,,0,0,0,0,,,0,0,0,0,,,0,0,0,0,,,0,0,0,0,,,0,0,0,0,,,0,0,0,0,AAPL
2024-10-22 12:40:04.934950184+00:00,10,39,38,A,B,0,232.2,2000,130,203488,55187,232.2,,2000,0,1,0,,,0,0,0,0,,,0,0,0,0,,,0,0,0,0,,,0,0,0,0,,,0,0,0,0,,,0,0,0,0,,,0,0,0,0,,,0,0,0,0,,,0,0,0,0,AAPL
2024-10-22 12:40:04.951346853+00:00,10,39,38,C,B,0,232.2,2000,130,203524,55188,,,0,0,0,0,,,0,0,0,0,,,0,0,0,0,,,0,0,0,0,,,0,0,0,0,,,0,0,0,0,,,0,0,0,0,,,0,0,0,0,,,0,0,0,0,,,0,0,0,0,AAPL
2024-10-22 12:40:04.968207535+00:00,10,39,38,A,B,0,232.2,2000,130,203538,55189,232.2,,2000,0,1,0,,,0,0,0,0,,,0,0,0,0,,,0,0,0,0,,,0,0,0,0,,,0,0,0,0,,,0,0,0,0,,,0,0,0,0,,,0,0,0,0,,,0,0,0,0,AAPL
2024-10-22 12:40:14.822906485+00:00,10,39,38,C,B,0,232.2,2000,130,203476,55302,,,0,0,0,0,,,0,0,0,0,,,0,0,0,0,,,0,0,0,0,,,0,0,0,0,,,0,0,0,0,,,0,0,0,0,,,0,0,0,0,,,0,0,0,0,,,0,0,0,0,AAPL
2024-10-22 12:40:14.834496834+00:00,10,39,38,A,B,0,232.2,2000,130,203572,55303,232.2,,2000,0,1,0,,,0,0,0,0,,,0,0,0,0,,,0,0,0,0,,,0,0,0,0,,,0,0,0,0,,,0,0,0,0,,,0,0,0,0,,,0,0,0,0,,,0,0,0,0,AAPL
2024-10-22 12:40:14.854485732+00:00,10,39,38,C,B,0,232.2,2000,130,203624,55304,,,0,0,0,0,,,0,0,0,0,,,0,0,0,0,,,0,0,0,0,,,0,0,0,0,,,0,0,0,0,,,0,0,0,0,,,0,0,0,0,,,0,0,0,0,,,0,0,0,0,AAPL
2024-10-22 12:40:14.871706339+00:00,10,39,38,A,B,0,231.8,2000,130,203575,55305,231.8,,2000,0,1,0,,,0,0,0,0,,,0,0,0,0,,,0,0,0,0,,,0,0,0,0,,,0,0,0,0,,,0,0,0,0,,,0,0,0,0,,,0,0,0,0,,,0,0,0,0,AAPL
2024-10-22 12:40:15.027386132+00:00,10,39,38,C,B,0,231.8,2000,130,203625,55309,,,0,0,0,0,,,0,0,0,0,,,0,0,0,0,,,0,0,0,0,,,0,0,0,0,,,0,0,0,0,,,0,0,0,0,,,0,0,0,0,,,0,0,0,0,,,0,0,0,0,AAPL
2024-10-22 12:40:15.040880849+00:00,10,39,38,A,B,0,231.8,2000,130,203600,55310,231.8,,2000,0,1,0,,,0,0,0,0,,,0,0,0,0,,,0,0,0,0,,,0,0,0,0,,,0,0,0,0,,,0,0,0,0,,,0,0,0,0,,,0,0,0,0,,,0,0,0,0,AAPL
2024-10-22 12:40:28.531529070+00:00,10,39,38,C,B,0,231.8,2000,130,203303,55517,,,0,0,0,0,,,0,0,0,0,,,0,0,0,0,,,0,0,0,0,,,0,0,0,0,,,0,0,0,0,,,0,0,0,0,,,0,0,0,0,,,0,0,0,0,,,0,0,0,0,AAPL
2024-10-22 12:40:28.542465697+00:00,10,39,38,A,B,0,231.6,2000,130,203098,55518,231.6,,2000,0,1,0,,,0,0,0,0,,,0,0,0,0,,,0,0,0,0,,,0,0,0,0,,,0,0,0,0,,,0,0,0,0,,,0,0,0,0,,,0,0,0,0,,,0,0,0,0,AAPL
2024-10-22 12:40:29.965669683+00:00,10,39,38,A,B,0,232.0,2000,130,203653,55523,232.0,,2000,0,1,0,231.6,,2000,0,1,0,,,0,0,0,0,,,0,0,0,0,,,0,0,0,0,,,0,0,0,0,,,0,0,0,0,,,0,0,0,0,,,0,0,0,0,,,0,0,0,0,AAPL
2024-10-22 12:40:29.965872532+00:00,10,39,38,C,B,1,231.6,2000,130,203148,55524,232.0,,2000,0,1,0,,,0,0,0,0,,,0,0,0,0,,,0,0,0,0,,,0,0,0,0,,,0,0,0,0,,,0,0,0,0,,,0,0,0,0,,,0,0,0,0,,,0,0,0,0,AAPL
2024-10-22 12:40:29.992376961+00:00,10,39,38,C,B,0,232.0,2000,130,203156,55525,,,0,0,0,0,,,0,0,0,0,,,0,0,0,0,,,0,0,0,0,,,0,0,0,0,,,0,0,0,0,,,0,0,0,0,,,0,0,0,0,,,0,0,0,0,,,0,0,0,0,AAPL
2024-10-22 12:40:30.003336590+00:00,10,39,38,A,B,0,231.8,2000,130,203333,55527,231.8,,2000,0,1,0,,,0,0,0,0,,,0,0,0,0,,,0,0,0,0,,,0,0,0,0,,,0,0,0,0,,,0,0,0,0,,,0,0,0,0,,,0,0,0,0,,,0,0,0,0,AAPL
2024-10-22 12:40:30.023990956+00:00,10,39,38,C,B,0,231.8,2000,130,203119,55528,,,0,0,0,0,,,0,0,0,0,,,0,0,0,0,,,0,0,0,0,,,0,0,0,0,,,0,0,0,0,,,0,0,0,0,,,0,0,0,0,,,0,0,0,0,,,0,0,0,0,AAPL
2024-10-22 12:40:30.036085827+00:00,10,39,38,A,B,0,231.6,2000,130,203145,55529,231.6,,2000,0,1,0,,,0,0,0,0,,,0,0,0,0,,,0,0,0,0,,,0,0,0,0,,,0,0,0,0,,,0,0,0,0,,,0,0,0,0,,,0,0,0,0,,,0,0,0,0,AAPL
2024-10-22 12:40:32.239730146+00:00,10,39,38,A,B,0,231.8,2000,130,203711,55539,231.8,,2000,0,1,0,231.6,,2000,0,1,0,,,0,0,0,0,,,0,0,0,0,,,0,0,0,0,,,0,0,0,0,,,0,0,0,0,,,0,0,0,0,,,0,0,0,0,,,0,0,0,0,AAPL
2024-10-22 12:40:32.240461811+00:00,10,39,38,C,B,1,231.6,2000,130,203425,55540,231.8,,2000,0,1,0,,,0,0,0,0,,,0,0,0,0,,,0,0,0,0,,,0,0,0,0,,,0,0,0,0,,,0,0,0,0,,,0,0,0,0,,,0,0,0,0,,,0,0,0,0,AAPL
2024-10-22 12:40:39.184485457+00:00,10,39,38,A,B,0,232.0,2000,130,204031,55573,232.0,,2000,0,1,0,231.8,,2000,0,1,0,,,0,0,0,0,,,0,0,0,0,,,0,0,0,0,,,0,0,0,0,,,0,0,0,0,,,0,0,0,0,,,0,0,0,0,,,0,0,0,0,AAPL
2024-10-22 12:40:39.184661372+00:00,10,39,38,C,B,1,231.8,2000,130,203614,55574,232.0,,2000,0,1,0,,,0,0,0,0,,,0,0,0,0,,,0,0,0,0,,,0,0,0,0,,,0,0,0,0,,,0,0,0,0,,,0,0,0,0,,,0,0,0,0,,,0,0,0,0,AAPL
2024-10-22 12:40:39.441109155+00:00,10,39,38,A,B,0,232.2,2000,130,203621,55577,232.2,,2000,0,1,0,232.0,,2000,0,1,0,,,0,0,0,0,,,0,0,0,0,,,0,0,0,0,,,0,0,0,0,,,0,0,0,0,,,0,0,0,0,,,0,0,0,0,,,0,0,0,0,AAPL
2024-10-22 12:40:39.441287101+00:00,10,39,38,C,B,1,232.0,2000,130,203491,55578,232.2,,2000,0,1,0,,,0,0,0,0,,,0,0,0,0,,,0,0,0,0,,,0,0,0,0,,,0,0,0,0,,,0,0,0,0,,,0,0,0,0,,,0,0,0,0,,,0,0,0,0,AAPL
2024-10-22 12:40:39.968818451+00:00,10,39,38,C,B,0,232.2,2000,130,203893,55581,,,0,0,0,0,,,0,0,0,0,,,0,0,0,0,,,0,0,0,0,,,0,0,0,0,,,0,0,0,0,,,0,0,0,0,,,0,0,0,0,,,0,0,0,0,,,0,0,0,0,AAPL
2024-10-22 12:40:40.004807911+00:00,10,39,38,A,B,0,232.2,2000,130,203793,55583,232.2,,2000,0,1,0,,,0,0,0,0,,,0,0,0,0,,,0,0,0,0,,,0,0,0,0,,,0,0,0,0,,,0,0,0,0,,,0,0,0,0,,,0,0,0,0,,,0,0,0,0,AAPL
2024-10-22 12:40:51.714042940+00:00,10,39,38,C,B,0,232.2,2000,130,204175,55646,,,0,0,0,0,,,0,0,0,0,,,0,0,0,0,,,0,0,0,0,,,0,0,0,0,,,0,0,0,0,,,0,0,0,0,,,0,0,0,0,,,0,0,0,0,,,0,0,0,0,AAPL
2024-10-22 12:40:51.750368912+00:00,10,39,38,A,B,0,232.2,2000,130,204039,55647,232.2,,2000,0,1,0,,,0,0,0,0,,,0,0,0,0,,,0,0,0,0,,,0,0,0,0,,,0,0,0,0,,,0,0,0,0,,,0,0,0,0,,,0,0,0,0,,,0,0,0,0,AAPL
2024-10-22 12:40:55.393423888+00:00,10,39,38,C,B,0,232.2,2000,130,204505,55654,,,0,0,0,0,,,0,0,0,0,,,0,0,0,0,,,0,0,0,0,,,0,0,0,0,,,0,0,0,0,,,0,0,0,0,,,0,0,0,0,,,0,0,0,0,,,0,0,0,0,AAPL
2024-10-22 12:40:55.429506081+00:00,10,39,38,A,B,0,232.0,2000,130,204194,55655,232.0,,2000,0,1,0,,,0,0,0,0,,,0,0,0,0,,,0,0,0,0,,,0,0,0,0,,,0,0,0,0,,,0,0,0,0,,,0,0,0,0,,,0,0,0,0,,,0,0,0,0,AAPL
2024-10-22 12:40:55.493874013+00:00,10,39,38,C,B,0,232.0,2000,130,204212,55656,,,0,0,0,0,,,0,0,0,0,,,0,0,0,0,,,0,0,0,0,,,0,0,0,0,,,0,0,0,0,,,0,0,0,0,,,0,0,0,0,,,0,0,0,0,,,0,0,0,0,AAPL
2024-10-22 12:40:55.507591035+00:00,10,39,38,A,B,0,232.0,2000,130,204547,55657,232.0,,2000,0,1,0,,,0,0,0,0,,,0,0,0,0,,,0,0,0,0,,,0,0,0,0,,,0,0,0,0,,,0,0,0,0,,,0,0,0,0,,,0,0,0,0,,,0,0,0,0,AAPL
2024-10-22 12:40:57.313885811+00:00,10,39,38,C,B,0,232.0,2000,130,204300,55676,,,0,0,0,0,,,0,0,0,0,,,0,0,0,0,,,0,0,0,0,,,0,0,0,0,,,0,0,0,0,,,0,0,0,0,,,0,0,0,0,,,0,0,0,0,,,0,0,0,0,AAPL
2024-10-22 12:40:57.351614800+00:00,10,39,38,A,B,0,232.2,2000,130,204288,55677,232.2,,2000,0,1,0,,,0,0,0,0,,,0,0,0,0,,,0,0,0,0,,,0,0,0,0,,,0,0,0,0,,,0,0,0,0,,,0,0,0,0,,,0,0,0,0,,,0,0,0,0,AAPL
2024-10-22 12:40:57.356023909+00:00,10,39,38,C,B,0,232.2,2000,130,204223,55678,,,0,0,0,0,,,0,0,0,0,,,0,0,0,0,,,0,0,0,0,,,0,0,0,0,,,0,0,0,0,,,0,0,0,0,,,0,0,0,0,,,0,0,0,0,,,0,0,0,0,AAPL
2024-10-22 12:40:57.367442807+00:00,10,39,38,A,B,0,232.0,2000,130,204234,55679,232.0,,2000,0,1,0,,,0,0,0,0,,,0,0,0,0,,,0,0,0,0,,,0,0,0,0,,,0,0,0,0,,,0,0,0,0,,,0,0,0,0,,,0,0,0,0,,,0,0,0,0,AAPL
2024-10-22 12:40:57.376531169+00:00,10,39,38,C,B,0,232.0,2000,130,204315,55680,,,0,0,0,0,,,0,0,0,0,,,0,0,0,0,,,0,0,0,0,,,0,0,0,0,,,0,0,0,0,,,0,0,0,0,,,0,0,0,0,,,0,0,0,0,,,0,0,0,0,AAPL
2024-10-22 12:40:57.387712440+00:00,10,39,38,A,B,0,231.8,2000,130,204331,55681,231.8,,2000,0,1,0,,,0,0,0,0,,,0,0,0,0,,,0,0,0,0,,,0,0,0,0,,,0,0,0,0,,,0,0,0,0,,,0,0,0,0,,,0,0,0,0,,,0,0,0,0,AAPL
2024-10-22 12:41:00.510750299+00:00,10,39,38,A,B,0,232.2,2000,130,204506,55698,232.2,,2000,0,1,0,231.8,,2000,0,1,0,,,0,0,0,0,,,0,0,0,0,,,0,0,0,0,,,0,0,0,0,,,0,0,0,0,,,0,0,0,0,,,0,0,0,0,,,0,0,0,0,AAPL
2024-10-22 12:41:00.510920499+00:00,10,39,38,C,B,1,231.8,2000,130,204275,55699,232.2,,2000,0,1,0,,,0,0,0,0,,,0,0,0,0,,,0,0,0,0,,,0,0,0,0,,,0,0,0,0,,,0,0,0,0,,,0,0,0,0,,,0,0,0,0,,,0,0,0,0,AAPL
2024-10-22 12:41:10.460445308+00:00,10,39,38,C,B,0,232.2,2000,130,204019,55789,,,0,0,0,0,,,0,0,0,0,,,0,0,0,0,,,0,0,0,0,,,0,0,0,0,,,0,0,0,0,,,0,0,0,0,,,0,0,0,0,,,0,0,0,0,,,0,0,0,0,AAPL
2024-10-22 12:41:10.471353389+00:00,10,39,38,A,B,0,232.0,2000,130,203934,55790,232.0,,2000,0,1,0,,,0,0,0,0,,,0,0,0,0,,,0,0,0,0,,,0,0,0,0,,,0,0,0,0,,,0,0,0,0,,,0,0,0,0,,,0,0,0,0,,,0,0,0,0,AAPL
2024-10-22 12:41:10.491581007+00:00,10,39,38,C,B,0,232.0,2000,130,203943,55791,,,0,0,0,0,,,0,0,0,0,,,0,0,0,0,,,0,0,0,0,,,0,0,0,0,,,0,0,0,0,,,0,0,0,0,,,0,0,0,0,,,0,0,0,0,,,0,0,0,0,AAPL
2024-10-22 12:41:10.502710897+00:00,10,39,38,A,B,0,231.8,2000,130,203894,55793,231.8,,2000,0,1,0,,,0,0,0,0,,,0,0,0,0,,,0,0,0,0,,,0,0,0,0,,,0,0,0,0,,,0,0,0,0,,,0,0,0,0,,,0,0,0,0,,,0,0,0,0,AAPL
2024-10-22 12:41:13.102696489+00:00,10,39,38,C,B,0,231.8,2000,130,204577,55811,,,0,0,0,0,,,0,0,0,0,,,0,0,0,0,,,0,0,0,0,,,0,0,0,0,,,0,0,0,0,,,0,0,0,0,,,0,0,0,0,,,0,0,0,0,,,0,0,0,0,AAPL
2024-10-22 12:41:13.115657992+00:00,10,39,38,A,B,0,231.8,2000,130,203782,55812,231.8,,2000,0,1,0,,,0,0,0,0,,,0,0,0,0,,,0,0,0,0,,,0,0,0,0,,,0,0,0,0,,,0,0,0,0,,,0,0,0,0,,,0,0,0,0,,,0,0,0,0,AAPL
2024-10-22 12:41:18.232351921+00:00,10,39,38,A,B,0,232.2,2000,130,204141,55838,232.2,,2000,0,1,0,231.8,,2000,0,1,0,,,0,0,0,0,,,0,0,0,0,,,0,0,0,0,,,0,0,0,0,,,0,0,0,0,,,0,0,0,0,,,0,0,0,0,,,0,0,0,0,AAPL
2024-10-22 12:41:18.232550497+00:00,10,39,38,C,B,1,231.8,2000,130,203962,55839,232.2,,2000,0,1,0,,,0,0,0,0,,,0,0,0,0,,,0,0,0,0,,,0,0,0,0,,,0,0,0,0,,,0,0,0,0,,,0,0,0,0,,,0,0,0,0,,,0,0,0,0,AAPL
2024-10-22 12:41:18.258270743+00:00,10,39,38,C,B,0,232.2,2000,130,203941,55840,,,0,0,0,0,,,0,0,0,0,,,0,0,0,0,,,0,0,0,0,,,0,0,0,0,,,0,0,0,0,,,0,0,0,0,,,0,0,0,0,,,0,0,0,0,,,0,0,0,0,AAPL
2024-10-22 12:41:18.269408370+00:00,10,39,38,A,B,0,232.2,2000,130,204094,55841,232.2,,2000,0,1,0,,,0,0,0,0,,,0,0,0,0,,,0,0,0,0,,,0,0,0,0,,,0,0,0,0,,,0,0,0,0,,,0,0,0,0,,,0,0,0,0,,,0,0,0,0,AAPL
2024-10-22 12:41:18.289751422+00:00,10,39,38,C,B,0,232.2,2000,130,203854,55842,,,0,0,0,0,,,0,0,0,0,,,0,0,0,0,,,0,0,0,0,,,0,0,0,0,,,0,0,0,0,,,0,0,0,0,,,0,0,0,0,,,0,0,0,0,,,0,0,0,0,AAPL
2024-10-22 12:41:18.301197317+00:00,10,39,38,A,B,0,232.2,2000,130,203878,55843,232.2,,2000,0,1,0,,,0,0,0,0,,,0,0,0,0,,,0,0,0,0,,,0,0,0,0,,,0,0,0,0,,,0,0,0,0,,,0,0,0,0,,,0,0,0,0,,,0,0,0,0,AAPL
2024-10-22 12:41:18.303296579+00:00,10,39,38,C,B,0,232.2,2000,130,203829,55844,,,0,0,0,0,,,0,0,0,0,,,0,0,0,0,,,0,0,0,0,,,0,0,0,0,,,0,0,0,0,,,0,0,0,0,,,0,0,0,0,,,0,0,0,0,,,0,0,0,0,AAPL
2024-10-22 12:41:18.315936521+00:00,10,39,38,A,B,0,232.2,2000,130,203945,55845,232.2,,2000,0,1,0,,,0,0,0,0,,,0,0,0,0,,,0,0,0,0,,,0,0,0,0,,,0,0,0,0,,,0,0,0,0,,,0,0,0,0,,,0,0,0,0,,,0,0,0,0,AAPL
2024-10-22 12:41:29.127571946+00:00,10,39,38,C,B,0,232.2,2000,130,203631,55972,,,0,0,0,0,,,0,0,0,0,,,0,0,0,0,,,0,0,0,0,,,0,0,0,0,,,0,0,0,0,,,0,0,0,0,,,0,0,0,0,,,0,0,0,0,,,0,0,0,0,AAPL
2024-10-22 12:41:29.140541899+00:00,10,39,38,A,B,0,231.8,2000,130,203628,55974,231.8,,2000,0,1,0,,,0,0,0,0,,,0,0,0,0,,,0,0,0,0,,,0,0,0,0,,,0,0,0,0,,,0,0,0,0,,,0,0,0,0,,,0,0,0,0,,,0,0,0,0,AAPL
2024-10-22 12:41:29.660275173+00:00,10,39,10888,A,B,0,418.02,100,130,203157,82199,418.02,,100,0,1,0,,,0,0,0,0,,,0,0,0,0,,,0,0,0,0,,,0,0,0,0,,,0,0,0,0,,,0,0,0,0,,,0,0,0,0,,,0,0,0,0,,,0,0,0,0,MSFT
2024-10-22 12:41:35.083834789+00:00,10,39,10888,C,B,0,418.02,100,130,203700,82246,,,0,0,0,0,,,0,0,0,0,,,0,0,0,0,,,0,0,0,0,,,0,0,0,0,,,0,0,0,0,,,0,0,0,0,,,0,0,0,0,,,0,0,0,0,,,0,0,0,0,MSFT
2024-10-22 12:41:35.563812299+00:00,10,39,10888,A,B,0,417.91,100,130,203555,82249,417.91,,100,0,1,0,,,0,0,0,0,,,0,0,0,0,,,0,0,0,0,,,0,0,0,0,,,0,0,0,0,,,0,0,0,0,,,0,0,0,0,,,0,0,0,0,,,0,0,0,0,MSFT
2024-10-22 12:41:35.639673924+00:00,10,39,38,A,B,0,232.0,2000,130,203886,56027,232.0,,2000,0,1,0,231.8,,2000,0,1,0,,,0,0,0,0,,,0,0,0,0,,,0,0,0,0,,,0,0,0,0,,,0,0,0,0,,,0,0,0,0,,,0,0,0,0,,,0,0,0,0,AAPL
2024-10-22 12:41:35.639876917+00:00,10,39,38,C,B,1,231.8,2000,130,203599,56028,232.0,,2000,0,1,0,,,0,0,0,0,,,0,0,0,0,,,0,0,0,0,,,0,0,0,0,,,0,0,0,0,,,0,0,0,0,,,0,0,0,0,,,0,0,0,0,,,0,0,0,0,AAPL
2024-10-22 12:41:37.790037178+00:00,10,39,38,A,B,0,232.2,2000,130,203681,56037,232.2,,2000,0,1,0,232.0,,2000,0,1,0,,,0,0,0,0,,,0,0,0,0,,,0,0,0,0,,,0,0,0,0,,,0,0,0,0,,,0,0,0,0,,,0,0,0,0,,,0,0,0,0,AAPL
2024-10-22 12:41:37.790350011+00:00,10,39,38,C,B,1,232.0,2000,130,203581,56038,232.2,,2000,0,1,0,,,0,0,0,0,,,0,0,0,0,,,0,0,0,0,,,0,0,0,0,,,0,0,0,0,,,0,0,0,0,,,0,0,0,0,,,0,0,0,0,,,0,0,0,0,AAPL
2024-10-22 12:41:39.421317861+00:00,10,39,10888,C,B,0,417.91,100,130,203525,82284,,,0,0,0,0,,,0,0,0,0,,,0,0,0,0,,,0,0,0,0,,,0,0,0,0,,,0,0,0,0,,,0,0,0,0,,,0,0,0,0,,,0,0,0,0,,,0,0,0,0,MSFT
2024-10-22 12:41:39.884609042+00:00,10,39,10888,A,B,0,417.94,100,130,203657,82291,417.94,,100,0,1,0,,,0,0,0,0,,,0,0,0,0,,,0,0,0,0,,,0,0,0,0,,,0,0,0,0,,,0,0,0,0,,,0,0,0,0,,,0,0,0,0,,,0,0,0,0,MSFT
2024-10-22 12:41:45.585277754+00:00,10,39,38,C,B,0,232.2,2000,130,204058,56082,,,0,0,0,0,,,0,0,0,0,,,0,0,0,0,,,0,0,0,0,,,0,0,0,0,,,0,0,0,0,,,0,0,0,0,,,0,0,0,0,,,0,0,0,0,,,0,0,0,0,AAPL
2024-10-22 12:41:45.596688039+00:00,10,39,38,A,B,0,232.0,2000,130,203883,56083,232.0,,2000,0,1,0,,,0,0,0,0,,,0,0,0,0,,,0,0,0,0,,,0,0,0,0,,,0,0,0,0,,,0,0,0,0,,,0,0,0,0,,,0,0,0,0,,,0,0,0,0,AAPL
2024-10-22 12:41:45.851899834+00:00,10,41,38,A,B,0,234.13,200,194,56298,171316,,234.13,0,200,0,0,,,0,0,0,0,,,0,0,0,0,,,0,0,0,0,,,0,0,0,0,,,0,0,0,0,,,0,0,0,0,,,0,0,0,0,,,0,0,0,0,,,0,0,0,0,AAPL
2024-10-22 12:41:45.851930161+00:00,10,41,38,A,B,0,234.13,200,194,55500,171317,233.6,234.13,200,200,0,0,,,0,0,0,0,,,0,0,0,0,,,0,0,0,0,,,0,0,0,0,,,0,0,0,0,,,0,0,0,0,,,0,0,0,0,,,0,0,0,0,,,0,0,0,0,AAPL
2024-10-22 12:41:46.815200321+00:00,10,39,38,A,B,0,232.2,2000,130,203921,56087,232.2,,2000,0,1,0,232.0,,2000,0,1,0,,,0,0,0,0,,,0,0,0,0,,,0,0,0,0,,,0,0,0,0,,,0,0,0,0,,,0,0,0,0,,,0,0,0,0,,,0,0,0,0,AAPL
2024-10-22 12:41:46.815935516+00:00,10,39,38,C,B,1,232.0,2000,130,203875,56088,232.2,,2000,0,1,0,,,0,0,0,0,,,0,0,0,0,,,0,0,0,0,,,0,0,0,0,,,0,0,0,0,,,0,0,0,0,,,0,0,0,0,,,0,0,0,0,,,0,0,0,0,AAPL
2024-10-22 12:41:51.290459600+00:00,10,39,38,C,B,0,232.2,2000,130,203950,56117,,,0,0,0,0,,,0,0,0,0,,,0,0,0,0,,,0,0,0,0,,,0,0,0,0,,,0,0,0,0,,,0,0,0,0,,,0,0,0,0,,,0,0,0,0,,,0,0,0,0,AAPL
2024-10-22 12:41:51.330861951+00:00,10,39,38,A,B,0,231.8,2000,130,203983,56118,231.8,,2000,0,1,0,,,0,0,0,0,,,0,0,0,0,,,0,0,0,0,,,0,0,0,0,,,0,0,0,0,,,0,0,0,0,,,0,0,0,0,,,0,0,0,0,,,0,0,0,0,AAPL
2024-10-22 12:41:51.353299379+00:00,10,39,38,A,B,0,232.0,2000,130,203949,56119,232.0,,2000,0,1,0,231.8,,2000,0,1,0,,,0,0,0,0,,,0,0,0,0,,,0,0,0,0,,,0,0,0,0,,,0,0,0,0,,,0,0,0,0,,,0,0,0,0,,,0,0,0,0,AAPL
2024-10-22 12:41:51.353481455+00:00,10,39,38,C,B,1,231.8,2000,130,203875,56120,232.0,,2000,0,1,0,,,0,0,0,0,,,0,0,0,0,,,0,0,0,0,,,0,0,0,0,,,0,0,0,0,,,0,0,0,0,,,0,0,0,0,,,0,0,0,0,,,0,0,0,0,AAPL
2024-10-22 12:41:51.365888205+00:00,10,39,38,C,B,0,232.0,2000,130,203893,56121,,,0,0,0,0,,,0,0,0,0,,,0,0,0,0,,,0,0,0,0,,,0,0,0,0,,,0,0,0,0,,,0,0,0,0,,,0,0,0,0,,,0,0,0,0,,,0,0,0,0,AAPL
2024-10-22 12:41:51.380924152+00:00,10,39,38,A,B,0,232.0,2000,130,204084,56122,232.0,,2000,0,1,0,,,0,0,0,0,,,0,0,0,0,,,0,0,0,0,,,0,0,0,0,,,0,0,0,0,,,0,0,0,0,,,0,0,0,0,,,0,0,0,0,,,0,0,0,0,AAPL
2024-10-22 12:41:51.598944786+00:00,10,39,38,C,B,0,232.0,2000,130,203902,56124,,,0,0,0,0,,,0,0,0,0,,,0,0,0,0,,,0,0,0,0,,,0,0,0,0,,,0,0,0,0,,,0,0,0,0,,,0,0,0,0,,,0,0,0,0,,,0,0,0,0,AAPL
2024-10-22 12:41:51.635258360+00:00,10,39,38,A,B,0,231.8,2000,130,203897,56128,231.8,,2000,0,1,0,,,0,0,0,0,,,0,0,0,0,,,0,0,0,0,,,0,0,0,0,,,0,0,0,0,,,0,0,0,0,,,0,0,0,0,,,0,0,0,0,,,0,0,0,0,AAPL
2024-10-22 12:41:52.307064783+00:00,10,39,38,A,B,0,232.0,2000,130,204606,56130,232.0,,2000,0,1,0,231.8,,2000,0,1,0,,,0,0,0,0,,,0,0,0,0,,,0,0,0,0,,,0,0,0,0,,,0,0,0,0,,,0,0,0,0,,,0,0,0,0,,,0,0,0,0,AAPL
2024-10-22 12:41:52.307257359+00:00,10,39,38,C,B,1,231.8,2000,130,204015,56131,232.0,,2000,0,1,0,,,0,0,0,0,,,0,0,0,0,,,0,0,0,0,,,0,0,0,0,,,0,0,0,0,,,0,0,0,0,,,0,0,0,0,,,0,0,0,0,,,0,0,0,0,AAPL
2024-10-22 12:41:56.267201117+00:00,10,39,10888,C,B,0,417.94,100,130,203742,82476,,,0,0,0,0,,,0,0,0,0,,,0,0,0,0,,,0,0,0,0,,,0,0,0,0,,,0,0,0,0,,,0,0,0,0,,,0,0,0,0,,,0,0,0,0,,,0,0,0,0,MSFT
2024-10-22 12:41:56.748088542+00:00,10,39,10888,A,B,0,417.96,100,130,203919,82480,417.96,,100,0,1,0,,,0,0,0,0,,,0,0,0,0,,,0,0,0,0,,,0,0,0,0,,,0,0,0,0,,,0,0,0,0,,,0,0,0,0,,,0,0,0,0,,,0,0,0,0,MSFT
2024-10-22 12:42:03.448552284+00:00,10,39,38,A,B,0,232.2,2000,130,204206,56219,232.2,,2000,0,1,0,232.0,,2000,0,1,0,,,0,0,0,0,,,0,0,0,0,,,0,0,0,0,,,0,0,0,0,,,0,0,0,0,,,0,0,0,0,,,0,0,0,0,,,0,0,0,0,AAPL
2024-10-22 12:42:03.449282379+00:00,10,39,38,C,B,1,232.0,2000,130,203869,56220,232.2,,2000,0,1,0,,,0,0,0,0,,,0,0,0,0,,,0,0,0,0,,,0,0,0,0,,,0,0,0,0,,,0,0,0,0,,,0,0,0,0,,,0,0,0,0,,,0,0,0,0,AAPL
2024-10-22 12:42:12.746955943+00:00,10,39,10888,C,B,0,417.96,100,130,203902,82598,,,0,0,0,0,,,0,0,0,0,,,0,0,0,0,,,0,0,0,0,,,0,0,0,0,,,0,0,0,0,,,0,0,0,0,,,0,0,0,0,,,0,0,0,0,,,0,0,0,0,MSFT
2024-10-22 12:42:13.511861139+00:00,10,40,38,A,A,0,,0,194,203518,89520,233.44,,200,0,0,0,,,0,0,0,0,,,0,0,0,0,,,0,0,0,0,,,0,0,0,0,,,0,0,0,0,,,0,0,0,0,,,0,0,0,0,,,0,0,0,0,,,0,0,0,0,AAPL
2024-10-22 12:42:13.511880461+00:00,10,40,38,A,A,0,234.36,200,194,203373,89521,233.44,234.36,200,200,0,0,,,0,0,0,0,,,0,0,0,0,,,0,0,0,0,,,0,0,0,0,,,0,0,0,0,,,0,0,0,0,,,0,0,0,0,,,0,0,0,0,,,0,0,0,0,AAPL
2024-10-22 12:42:13.512113169+00:00,10,41,38,A,A,0,,0,194,55599,172778,233.6,,200,0,0,0,,,0,0,0,0,,,0,0,0,0,,,0,0,0,0,,,0,0,0,0,,,0,0,0,0,,,0,0,0,0,,,0,0,0,0,,,0,0,0,0,,,0,0,0,0,AAPL
2024-10-22 12:42:13.512139155+00:00,10,41,38,A,A,0,234.3,200,194,54225,172779,233.6,234.3,200,200,0,0,,,0,0,0,0,,,0,0,0,0,,,0,0,0,0,,,0,0,0,0,,,0,0,0,0,,,0,0,0,0,,,0,0,0,0,,,0,0,0,0,,,0,0,0,0,AAPL
2024-10-22 12:42:14.859741668+00:00,10,39,10888,A,B,0,417.86,100,130,203464,82606,417.86,,100,0,1,0,,,0,0,0,0,,,0,0,0,0,,,0,0,0,0,,,0,0,0,0,,,0,0,0,0,,,0,0,0,0,,,0,0,0,0,,,0,0,0,0,,,0,0,0,0,MSFT
2024-10-22 12:42:16.651205043+00:00,10,39,10888,C,B,0,417.86,100,130,203708,82612,,,0,0,0,0,,,0,0,0,0,,,0,0,0,0,,,0,0,0,0,,,0,0,0,0,,,0,0,0,0,,,0,0,0,0,,,0,0,0,0,,,0,0,0,0,,,0,0,0,0,MSFT
2024-10-22 12:42:25.096347569+00:00,10,39,38,C,B,0,232.2,2000,130,203047,56367,,,0,0,0,0,,,0,0,0,0,,,0,0,0,0,,,0,0,0,0,,,0,0,0,0,,,0,0,0,0,,,0,0,0,0,,,0,0,0,0,,,0,0,0,0,,,0,0,0,0,AAPL
2024-10-22 12:42:41.344156419+00:00,10,41,38,A,A,0,,0,194,55953,173614,233.6,,200,0,0,0,,,0,0,0,0,,,0,0,0,0,,,0,0,0,0,,,0,0,0,0,,,0,0,0,0,,,0,0,0,0,,,0,0,0,0,,,0,0,0,0,,,0,0,0,0,AAPL
2024-10-22 12:42:41.344220733+00:00,10,41,38,A,A,0,234.2,200,194,54396,173615,233.6,234.2,200,200,0,0,,,0,0,0,0,,,0,0,0,0,,,0,0,0,0,,,0,0,0,0,,,0,0,0,0,,,0,0,0,0,,,0,0,0,0,,,0,0,0,0,,,0,0,0,0,AAPL
2024-10-22 12:42:48.495461771+00:00,10,39,38,A,B,0,231.6,2000,130,203361,56656,231.6,,2000,0,1,0,,,0,0,0,0,,,0,0,0,0,,,0,0,0,0,,,0,0,0,0,,,0,0,0,0,,,0,0,0,0,,,0,0,0,0,,,0,0,0,0,,,0,0,0,0,AAPL
2024-10-22 12:43:00.008013627+00:00,10,41,38,A,B,0,234.2,200,194,55744,174224,,234.2,0,200,0,0,,,0,0,0,0,,,0,0,0,0,,,0,0,0,0,,,0,0,0,0,,,0,0,0,0,,,0,0,0,0,,,0,0,0,0,,,0,0,0,0,,,0,0,0,0,AAPL
2024-10-22 12:43:00.108645851+00:00,10,41,38,A,B,0,234.2,200,194,54368,174571,233.59,234.2,200,200,0,0,,,0,0,0,0,,,0,0,0,0,,,0,0,0,0,,,0,0,0,0,,,0,0,0,0,,,0,0,0,0,,,0,0,0,0,,,0,0,0,0,,,0,0,0,0,AAPL
2024-10-22 12:43:03.187051213+00:00,10,39,38,C,B,0,231.6,2000,130,203882,56748,,,0,0,0,0,,,0,0,0,0,,,0,0,0,0,,,0,0,0,0,,,0,0,0,0,,,0,0,0,0,,,0,0,0,0,,,0,0,0,0,,,0,0,0,0,,,0,0,0,0,AAPL
2024-10-22 12:43:03.311450384+00:00,10,39,38,A,B,0,231.6,2000,130,203565,56751,231.6,,2000,0,1,0,,,0,0,0,0,,,0,0,0,0,,,0,0,0,0,,,0,0,0,0,,,0,0,0,0,,,0,0,0,0,,,0,0,0,0,,,0,0,0,0,,,0,0,0,0,AAPL
2024-10-22 12:43:04.816631764+00:00,10,39,38,C,B,0,231.6,2000,130,204058,56757,,,0,0,0,0,,,0,0,0,0,,,0,0,0,0,,,0,0,0,0,,,0,0,0,0,,,0,0,0,0,,,0,0,0,0,,,0,0,0,0,,,0,0,0,0,,,0,0,0,0,AAPL
2024-10-22 12:43:11.670827459+00:00,10,39,38,A,B,0,231.6,2000,130,204461,56786,231.6,,2000,0,1,0,,,0,0,0,0,,,0,0,0,0,,,0,0,0,0,,,0,0,0,0,,,0,0,0,0,,,0,0,0,0,,,0,0,0,0,,,0,0,0,0,,,0,0,0,0,AAPL
2024-10-22 12:43:21.457365554+00:00,10,40,38,A,A,0,,0,194,203747,90533,233.44,,200,0,0,0,,,0,0,0,0,,,0,0,0,0,,,0,0,0,0,,,0,0,0,0,,,0,0,0,0,,,0,0,0,0,,,0,0,0,0,,,0,0,0,0,,,0,0,0,0,AAPL
2024-10-22 12:43:21.457394215+00:00,10,40,38,A,A,0,234.24,200,194,203427,90534,233.44,234.24,200,200,0,0,,,0,0,0,0,,,0,0,0,0,,,0,0,0,0,,,0,0,0,0,,,0,0,0,0,,,0,0,0,0,,,0,0,0,0,,,0,0,0,0,,,0,0,0,0,AAPL
2024-10-22 12:43:25.273951904+00:00,10,39,38,C,B,0,231.6,2000,130,203915,56923,,,0,0,0,0,,,0,0,0,0,,,0,0,0,0,,,0,0,0,0,,,0,0,0,0,,,0,0,0,0,,,0,0,0,0,,,0,0,0,0,,,0,0,0,0,,,0,0,0,0,AAPL
2024-10-22 12:43:25.309316549+00:00,10,39,38,A,B,0,231.4,2000,130,203678,56937,231.4,,2000,0,1,0,,,0,0,0,0,,,0,0,0,0,,,0,0,0,0,,,0,0,0,0,,,0,0,0,0,,,0,0,0,0,,,0,0,0,0,,,0,0,0,0,,,0,0,0,0,AAPL
2024-10-22 12:43:25.385660165+00:00,10,39,38,C,B,0,231.4,2000,130,203786,56950,,,0,0,0,0,,,0,0,0,0,,,0,0,0,0,,,0,0,0,0,,,0,0,0,0,,,0,0,0,0,,,0,0,0,0,,,0,0,0,0,,,0,0,0,0,,,0,0,0,0,AAPL
2024-10-22 12:43:25.421415195+00:00,10,39,38,A,B,0,231.6,2000,130,203688,56958,231.6,,2000,0,1,0,,,0,0,0,0,,,0,0,0,0,,,0,0,0,0,,,0,0,0,0,,,0,0,0,0,,,0,0,0,0,,,0,0,0,0,,,0,0,0,0,,,0,0,0,0,AAPL
2024-10-22 12:43:25.681105036+00:00,10,41,38,A,B,0,234.2,200,194,55109,176039,,234.2,0,200,0,0,,,0,0,0,0,,,0,0,0,0,,,0,0,0,0,,,0,0,0,0,,,0,0,0,0,,,0,0,0,0,,,0,0,0,0,,,0,0,0,0,,,0,0,0,0,AAPL
2024-10-22 12:43:25.681152529+00:00,10,41,38,A,B,0,234.2,200,194,54245,176040,233.48,234.2,200,200,0,0,,,0,0,0,0,,,0,0,0,0,,,0,0,0,0,,,0,0,0,0,,,0,0,0,0,,,0,0,0,0,,,0,0,0,0,,,0,0,0,0,,,0,0,0,0,AAPL
2024-10-22 12:43:25.980991970+00:00,10,39,38,C,B,0,231.6,2000,130,203597,56987,,,0,0,0,0,,,0,0,0,0,,,0,0,0,0,,,0,0,0,0,,,0,0,0,0,,,0,0,0,0,,,0,0,0,0,,,0,0,0,0,,,0,0,0,0,,,0,0,0,0,AAPL
2024-10-22 12:43:26.208417135+00:00,10,39,38,A,B,0,231.6,2000,130,203717,56997,231.6,,2000,0,1,0,,,0,0,0,0,,,0,0,0,0,,,0,0,0,0,,,0,0,0,0,,,0,0,0,0,,,0,0,0,0,,,0,0,0,0,,,0,0,0,0,,,0,0,0,0,AAPL
2024-10-22 12:43:26.306056260+00:00,10,41,38,A,A,0,,0,194,55893,176121,233.48,,200,0,0,0,,,0,0,0,0,,,0,0,0,0,,,0,0,0,0,,,0,0,0,0,,,0,0,0,0,,,0,0,0,0,,,0,0,0,0,,,0,0,0,0,,,0,0,0,0,AAPL
2024-10-22 12:43:26.306095607+00:00,10,41,38,A,A,0,234.1,200,194,56150,176124,233.48,234.1,200,200,0,0,,,0,0,0,0,,,0,0,0,0,,,0,0,0,0,,,0,0,0,0,,,0,0,0,0,,,0,0,0,0,,,0,0,0,0,,,0,0,0,0,,,0,0,0,0,AAPL
2024-10-22 12:43:32.938467278+00:00,10,39,10888,A,B,0,417.21,100,130,203929,83597,417.21,,100,0,1,0,,,0,0,0,0,,,0,0,0,0,,,0,0,0,0,,,0,0,0,0,,,0,0,0,0,,,0,0,0,0,,,0,0,0,0,,,0,0,0,0,,,0,0,0,0,MSFT
2024-10-22 12:43:39.193882633+00:00,10,39,10888,C,B,0,417.21,100,130,203860,83753,,,0,0,0,0,,,0,0,0,0,,,0,0,0,0,,,0,0,0,0,,,0,0,0,0,,,0,0,0,0,,,0,0,0,0,,,0,0,0,0,,,0,0,0,0,,,0,0,0,0,MSFT
2024-10-22 12:43:39.691201568+00:00,10,39,10888,A,B,0,417.25,100,130,203869,83768,417.25,,100,0,1,0,,,0,0,0,0,,,0,0,0,0,,,0,0,0,0,,,0,0,0,0,,,0,0,0,0,,,0,0,0,0,,,0,0,0,0,,,0,0,0,0,,,0,0,0,0,MSFT
2024-10-22 12:43:45.226316781+00:00,10,39,10888,C,B,0,417.25,100,130,204598,83931,,,0,0,0,0,,,0,0,0,0,,,0,0,0,0,,,0,0,0,0,,,0,0,0,0,,,0,0,0,0,,,0,0,0,0,,,0,0,0,0,,,0,0,0,0,,,0,0,0,0,MSFT
2024-10-22 12:43:50.138087349+00:00,10,39,38,C,B,0,231.6,2000,130,204608,57264,,,0,0,0,0,,,0,0,0,0,,,0,0,0,0,,,0,0,0,0,,,0,0,0,0,,,0,0,0,0,,,0,0,0,0,,,0,0,0,0,,,0,0,0,0,,,0,0,0,0,AAPL
2024-10-22 12:43:50.148888734+00:00,10,39,38,A,B,0,231.4,2000,130,204168,57265,231.4,,2000,0,1,0,,,0,0,0,0,,,0,0,0,0,,,0,0,0,0,,,0,0,0,0,,,0,0,0,0,,,0,0,0,0,,,0,0,0,0,,,0,0,0,0,,,0,0,0,0,AAPL
2024-10-22 12:43:53.387655788+00:00,10,39,38,C,B,0,231.4,2000,130,204490,57284,,,0,0,0,0,,,0,0,0,0,,,0,0,0,0,,,0,0,0,0,,,0,0,0,0,,,0,0,0,0,,,0,0,0,0,,,0,0,0,0,,,0,0,0,0,,,0,0,0,0,AAPL
2024-10-22 12:43:59.497364557+00:00,10,39,38,A,B,0,231.6,2000,130,203958,57340,231.6,,2000,0,1,0,,,0,0,0,0,,,0,0,0,0,,,0,0,0,0,,,0,0,0,0,,,0,0,0,0,,,0,0,0,0,,,0,0,0,0,,,0,0,0,0,,,0,0,0,0,AAPL
2024-10-22 12:44:16.820102723+00:00,10,39,38,C,B,0,231.6,2000,130,203481,57535,,,0,0,0,0,,,0,0,0,0,,,0,0,0,0,,,0,0,0,0,,,0,0,0,0,,,0,0,0,0,,,0,0,0,0,,,0,0,0,0,,,0,0,0,0,,,0,0,0,0,AAPL
2024-10-22 12:44:16.831520294+00:00,10,39,38,A,B,0,231.6,2000,130,203402,57536,231.6,,2000,0,1,0,,,0,0,0,0,,,0,0,0,0,,,0,0,0,0,,,0,0,0,0,,,0,0,0,0,,,0,0,0,0,,,0,0,0,0,,,0,0,0,0,,,0,0,0,0,AAPL
2024-10-22 12:44:16.843726936+00:00,10,39,38,C,B,0,231.6,2000,130,203427,57537,,,0,0,0,0,,,0,0,0,0,,,0,0,0,0,,,0,0,0,0,,,0,0,0,0,,,0,0,0,0,,,0,0,0,0,,,0,0,0,0,,,0,0,0,0,,,0,0,0,0,AAPL
2024-10-22 12:44:16.856536047+00:00,10,39,38,A,B,0,231.6,2000,130,203414,57538,231.6,,2000,0,1,0,,,0,0,0,0,,,0,0,0,0,,,0,0,0,0,,,0,0,0,0,,,0,0,0,0,,,0,0,0,0,,,0,0,0,0,,,0,0,0,0,,,0,0,0,0,AAPL
2024-10-22 12:44:19.907579525+00:00,10,41,38,A,A,0,,0,194,55968,178461,233.48,,200,0,0,0,,,0,0,0,0,,,0,0,0,0,,,0,0,0,0,,,0,0,0,0,,,0,0,0,0,,,0,0,0,0,,,0,0,0,0,,,0,0,0,0,,,0,0,0,0,AAPL
2024-10-22 12:44:19.907646140+00:00,10,41,38,A,A,0,234.2,200,194,54755,178462,233.48,234.2,200,200,0,0,,,0,0,0,0,,,0,0,0,0,,,0,0,0,0,,,0,0,0,0,,,0,0,0,0,,,0,0,0,0,,,0,0,0,0,,,0,0,0,0,,,0,0,0,0,AAPL
2024-10-22 12:44:22.558012545+00:00,10,39,38,C,B,0,231.6,2000,130,203881,57601,,,0,0,0,0,,,0,0,0,0,,,0,0,0,0,,,0,0,0,0,,,0,0,0,0,,,0,0,0,0,,,0,0,0,0,,,0,0,0,0,,,0,0,0,0,,,0,0,0,0,AAPL
2024-10-22 12:44:40.458465684+00:00,10,39,10888,A,B,0,418.19,100,130,203523,84916,418.19,,100,0,1,0,,,0,0,0,0,,,0,0,0,0,,,0,0,0,0,,,0,0,0,0,,,0,0,0,0,,,0,0,0,0,,,0,0,0,0,,,0,0,0,0,,,0,0,0,0,MSFT
2024-10-22 12:44:40.985579828+00:00,10,39,10888,C,B,0,418.19,100,130,203416,84923,,,0,0,0,0,,,0,0,0,0,,,0,0,0,0,,,0,0,0,0,,,0,0,0,0,,,0,0,0,0,,,0,0,0,0,,,0,0,0,0,,,0,0,0,0,,,0,0,0,0,MSFT
2024-10-22 12:44:41.963869849+00:00,10,39,10888,A,B,0,417.93,100,130,203393,84946,417.93,,100,0,1,0,,,0,0,0,0,,,0,0,0,0,,,0,0,0,0,,,0,0,0,0,,,0,0,0,0,,,0,0,0,0,,,0,0,0,0,,,0,0,0,0,,,0,0,0,0,MSFT
2024-10-22 12:44:43.177818884+00:00,10,39,10888,C,B,0,417.93,100,130,203435,84978,,,0,0,0,0,,,0,0,0,0,,,0,0,0,0,,,0,0,0,0,,,0,0,0,0,,,0,0,0,0,,,0,0,0,0,,,0,0,0,0,,,0,0,0,0,,,0,0,0,0,MSFT
2024-10-22 12:44:43.610179355+00:00,10,39,10888,A,B,0,417.93,100,130,203445,84990,417.93,,100,0,1,0,,,0,0,0,0,,,0,0,0,0,,,0,0,0,0,,,0,0,0,0,,,0,0,0,0,,,0,0,0,0,,,0,0,0,0,,,0,0,0,0,,,0,0,0,0,MSFT
2024-10-22 12:44:51.641887121+00:00,10,39,10888,C,B,0,417.93,100,130,203723,85108,,,0,0,0,0,,,0,0,0,0,,,0,0,0,0,,,0,0,0,0,,,0,0,0,0,,,0,0,0,0,,,0,0,0,0,,,0,0,0,0,,,0,0,0,0,,,0,0,0,0,MSFT
2024-10-22 12:44:52.346769019+00:00,10,40,10888,A,B,0,,0,194,204993,92112,417.96,,100,0,0,0,,,0,0,0,0,,,0,0,0,0,,,0,0,0,0,,,0,0,0,0,,,0,0,0,0,,,0,0,0,0,,,0,0,0,0,,,0,0,0,0,,,0,0,0,0,MSFT
2024-10-22 12:44:53.946384664+00:00,10,40,10888,A,B,0,,0,194,204501,92132,,,0,0,0,0,,,0,0,0,0,,,0,0,0,0,,,0,0,0,0,,,0,0,0,0,,,0,0,0,0,,,0,0,0,0,,,0,0,0,0,,,0,0,0,0,,,0,0,0,0,MSFT
2024-10-22 12:44:54.476465202+00:00,10,40,10888,A,B,0,,0,194,204534,92137,418.02,,100,0,0,0,,,0,0,0,0,,,0,0,0,0,,,0,0,0,0,,,0,0,0,0,,,0,0,0,0,,,0,0,0,0,,,0,0,0,0,,,0,0,0,0,,,0,0,0,0,MSFT
2024-10-22 12:44:55.481796381+00:00,10,40,10888,A,B,0,,0,194,204746,92146,,,0,0,0,0,,,0,0,0,0,,,0,0,0,0,,,0,0,0,0,,,0,0,0,0,,,0,0,0,0,,,0,0,0,0,,,0,0,0,0,,,0,0,0,0,,,0,0,0,0,MSFT
2024-10-22 12:44:55.978542119+00:00,10,39,10888,A,B,0,418.1,100,130,203361,85134,418.1,,100,0,1,0,,,0,0,0,0,,,0,0,0,0,,,0,0,0,0,,,0,0,0,0,,,0,0,0,0,,,0,0,0,0,,,0,0,0,0,,,0,0,0,0,,,0,0,0,0,MSFT
2024-10-22 12:44:56.681554554+00:00,10,39,10888,C,B,0,418.1,100,130,204180,85136,,,0,0,0,0,,,0,0,0,0,,,0,0,0,0,,,0,0,0,0,,,0,0,0,0,,,0,0,0,0,,,0,0,0,0,,,0,0,0,0,,,0,0,0,0,,,0,0,0,0,MSFT
2024-10-22 12:45:00.014509304+00:00,10,40,38,A,B,0,234.24,200,194,204719,92242,,234.24,0,200,0,0,,,0,0,0,0,,,0,0,0,0,,,0,0,0,0,,,0,0,0,0,,,0,0,0,0,,,0,0,0,0,,,0,0,0,0,,,0,0,0,0,,,0,0,0,0,AAPL
2024-10-22 12:45:00.014527730+00:00,10,40,38,A,A,0,,0,194,204264,92244,,,0,0,0,0,,,0,0,0,0,,,0,0,0,0,,,0,0,0,0,,,0,0,0,0,,,0,0,0,0,,,0,0,0,0,,,0,0,0,0,,,0,0,0,0,,,0,0,0,0,AAPL
2024-10-22 12:45:00.014873971+00:00,10,41,38,A,B,0,234.2,200,192,64134,180100,,234.2,0,200,0,0,,,0,0,0,0,,,0,0,0,0,,,0,0,0,0,,,0,0,0,0,,,0,0,0,0,,,0,0,0,0,,,0,0,0,0,,,0,0,0,0,,,0,0,0,0,AAPL
2024-10-22 12:45:00.014884894+00:00,10,41,38,A,A,0,,0,192,65556,180107,,,0,0,0,0,,,0,0,0,0,,,0,0,0,0,,,0,0,0,0,,,0,0,0,0,,,0,0,0,0,,,0,0,0,0,,,0,0,0,0,,,0,0,0,0,,,0,0,0,0,AAPL
2024-10-22 12:45:00.195502567+00:00,10,40,38,A,A,0,234.25,200,194,204245,92608,,234.25,0,200,0,0,,,0,0,0,0,,,0,0,0,0,,,0,0,0,0,,,0,0,0,0,,,0,0,0,0,,,0,0,0,0,,,0,0,0,0,,,0,0,0,0,,,0,0,0,0,AAPL
2024-10-22 12:45:00.195748572+00:00,10,41,38,A,A,0,234.2,200,194,54826,181424,,234.2,0,200,0,0,,,0,0,0,0,,,0,0,0,0,,,0,0,0,0,,,0,0,0,0,,,0,0,0,0,,,0,0,0,0,,,0,0,0,0,,,0,0,0,0,,,0,0,0,0,AAPL
2024-10-22 12:45:00.483170776+00:00,10,41,38,A,B,0,234.2,200,194,55318,181733,233.52,234.2,200,200,0,0,,,0,0,0,0,,,0,0,0,0,,,0,0,0,0,,,0,0,0,0,,,0,0,0,0,,,0,0,0,0,,,0,0,0,0,,,0,0,0,0,,,0,0,0,0,AAPL
2024-10-22 12:45:00.685084599+00:00,10,41,38,A,B,0,234.2,200,194,55205,181781,,234.2,0,200,0,0,,,0,0,0,0,,,0,0,0,0,,,0,0,0,0,,,0,0,0,0,,,0,0,0,0,,,0,0,0,0,,,0,0,0,0,,,0,0,0,0,,,0,0,0,0,AAPL
2024-10-22 12:45:00.738895016+00:00,10,41,38,A,B,0,234.2,200,194,55124,181793,233.52,234.2,200,200,0,0,,,0,0,0,0,,,0,0,0,0,,,0,0,0,0,,,0,0,0,0,,,0,0,0,0,,,0,0,0,0,,,0,0,0,0,,,0,0,0,0,,,0,0,0,0,AAPL
2024-10-22 12:45:01.231114674+00:00,10,40,38,A,B,0,234.25,200,194,204160,92739,233.47,234.25,200,200,0,0,,,0,0,0,0,,,0,0,0,0,,,0,0,0,0,,,0,0,0,0,,,0,0,0,0,,,0,0,0,0,,,0,0,0,0,,,0,0,0,0,,,0,0,0,0,AAPL
2024-10-22 12:45:01.268483320+00:00,10,39,38,A,B,0,231.6,2000,130,203409,57910,231.6,,2000,0,1,0,,,0,0,0,0,,,0,0,0,0,,,0,0,0,0,,,0,0,0,0,,,0,0,0,0,,,0,0,0,0,,,0,0,0,0,,,0,0,0,0,,,0,0,0,0,AAPL
2024-10-22 12:45:22.037565374+00:00,10,39,38,C,B,0,231.6,2000,130,203466,58097,,,0,0,0,0,,,0,0,0,0,,,0,0,0,0,,,0,0,0,0,,,0,0,0,0,,,0,0,0,0,,,0,0,0,0,,,0,0,0,0,,,0,0,0,0,,,0,0,0,0,AAPL
2024-10-22 12:45:27.545998012+00:00,10,39,10888,A,B,0,417.81,100,130,203380,85529,417.81,,100,0,1,0,,,0,0,0,0,,,0,0,0,0,,,0,0,0,0,,,0,0,0,0,,,0,0,0,0,,,0,0,0,0,,,0,0,0,0,,,0,0,0,0,,,0,0,0,0,MSFT
2024-10-22 12:45:35.305236202+00:00,10,39,10888,C,B,0,417.81,100,130,203728,85590,,,0,0,0,0,,,0,0,0,0,,,0,0,0,0,,,0,0,0,0,,,0,0,0,0,,,0,0,0,0,,,0,0,0,0,,,0,0,0,0,,,0,0,0,0,,,0,0,0,0,MSFT
2024-10-22 12:45:56.720054194+00:00,10,39,38,A,B,0,231.6,2000,130,203127,58297,231.6,,2000,0,1,0,,,0,0,0,0,,,0,0,0,0,,,0,0,0,0,,,0,0,0,0,,,0,0,0,0,,,0,0,0,0,,,0,0,0,0,,,0,0,0,0,,,0,0,0,0,AAPL
2024-10-22 12:45:57.071295113+00:00,10,39,38,A,B,0,231.8,2000,130,203792,58299,231.8,,2000,0,1,0,231.6,,2000,0,1,0,,,0,0,0,0,,,0,0,0,0,,,0,0,0,0,,,0,0,0,0,,,0,0,0,0,,,0,0,0,0,,,0,0,0,0,,,0,0,0,0,AAPL
2024-10-22 12:45:57.071472754+00:00,10,39,38,C,B,1,231.6,2000,130,203167,58300,231.8,,2000,0,1,0,,,0,0,0,0,,,0,0,0,0,,,0,0,0,0,,,0,0,0,0,,,0,0,0,0,,,0,0,0,0,,,0,0,0,0,,,0,0,0,0,,,0,0,0,0,AAPL
2024-10-22 12:46:00.098583090+00:00,10,40,38,A,B,0,234.25,200,194,203996,93614,,234.25,0,200,0,0,,,0,0,0,0,,,0,0,0,0,,,0,0,0,0,,,0,0,0,0,,,0,0,0,0,,,0,0,0,0,,,0,0,0,0,,,0,0,0,0,,,0,0,0,0,AAPL
2024-10-22 12:46:00.199316260+00:00,10,40,38,A,B,0,234.25,200,194,204017,93658,233.5,234.25,200,200,0,0,,,0,0,0,0,,,0,0,0,0,,,0,0,0,0,,,0,0,0,0,,,0,0,0,0,,,0,0,0,0,,,0,0,0,0,,,0,0,0,0,,,0,0,0,0,AAPL
2024-10-22 12:46:34.652002124+00:00,10,39,38,C,B,0,231.8,2000,130,204073,58564,,,0,0,0,0,,,0,0,0,0,,,0,0,0,0,,,0,0,0,0,,,0,0,0,0,,,0,0,0,0,,,0,0,0,0,,,0,0,0,0,,,0,0,0,0,,,0,0,0,0,AAPL
2024-10-22 12:46:34.663513394+00:00,10,39,38,A,B,0,231.8,2000,130,203695,58565,231.8,,2000,0,1,0,,,0,0,0,0,,,0,0,0,0,,,0,0,0,0,,,0,0,0,0,,,0,0,0,0,,,0,0,0,0,,,0,0,0,0,,,0,0,0,0,,,0,0,0,0,AAPL
2024-10-22 12:46:34.681977146+00:00,10,39,38,C,B,0,231.8,2000,130,203619,58566,,,0,0,0,0,,,0,0,0,0,,,0,0,0,0,,,0,0,0,0,,,0,0,0,0,,,0,0,0,0,,,0,0,0,0,,,0,0,0,0,,,0,0,0,0,,,0,0,0,0,AAPL
2024-10-22 12:46:34.693437561+00:00,10,39,38,A,B,0,231.8,2000,130,203654,58567,231.8,,2000,0,1,0,,,0,0,0,0,,,0,0,0,0,,,0,0,0,0,,,0,0,0,0,,,0,0,0,0,,,0,0,0,0,,,0,0,0,0,,,0,0,0,0,,,0,0,0,0,AAPL
2024-10-22 12:47:00.550606991+00:00,10,40,38,A,B,0,234.25,200,194,202692,94375,,234.25,0,200,0,0,,,0,0,0,0,,,0,0,0,0,,,0,0,0,0,,,0,0,0,0,,,0,0,0,0,,,0,0,0,0,,,0,0,0,0,,,0,0,0,0,,,0,0,0,0,AAPL
2024-10-22 12:47:01.332471641+00:00,10,40,38,A,B,0,234.25,200,194,202778,94379,233.5,234.25,200,200,0,0,,,0,0,0,0,,,0,0,0,0,,,0,0,0,0,,,0,0,0,0,,,0,0,0,0,,,0,0,0,0,,,0,0,0,0,,,0,0,0,0,,,0,0,0,0,AAPL
2024-10-22 12:47:02.766491245+00:00,10,39,38,C,B,0,231.8,2000,130,204246,58712,,,0,0,0,0,,,0,0,0,0,,,0,0,0,0,,,0,0,0,0,,,0,0,0,0,,,0,0,0,0,,,0,0,0,0,,,0,0,0,0,,,0,0,0,0,,,0,0,0,0,AAPL
2024-10-22 12:47:02.802477809+00:00,10,39,38,A,B,0,231.6,2000,130,204175,58713,231.6,,2000,0,1,0,,,0,0,0,0,,,0,0,0,0,,,0,0,0,0,,,0,0,0,0,,,0,0,0,0,,,0,0,0,0,,,0,0,0,0,,,0,0,0,0,,,0,0,0,0,AAPL
2024-10-22 12:47:30.551309805+00:00,10,39,38,A,A,0,235.0,2000,130,204112,58998,231.6,235.0,2000,2000,1,1,,,0,0,0,0,,,0,0,0,0,,,0,0,0,0,,,0,0,0,0,,,0,0,0,0,,,0,0,0,0,,,0,0,0,0,,,0,0,0,0,,,0,0,0,0,AAPL
2024-10-22 12:47:36.818738850+00:00,10,39,38,C,A,0,235.0,2000,130,203428,59026,231.6,,2000,0,1,0,,,0,0,0,0,,,0,0,0,0,,,0,0,0,0,,,0,0,0,0,,,0,0,0,0,,,0,0,0,0,,,0,0,0,0,,,0,0,0,0,,,0,0,0,0,AAPL
2024-10-22 12:47:36.854711521+00:00,10,39,38,A,A,0,234.8,2000,130,203467,59027,231.6,234.8,2000,2000,1,1,,,0,0,0,0,,,0,0,0,0,,,0,0,0,0,,,0,0,0,0,,,0,0,0,0,,,0,0,0,0,,,0,0,0,0,,,0,0,0,0,,,0,0,0,0,AAPL
2024-10-22 12:47:41.058653947+00:00,10,39,38,C,B,0,231.6,2000,130,203821,59054,,234.8,0,2000,0,1,,,0,0,0,0,,,0,0,0,0,,,0,0,0,0,,,0,0,0,0,,,0,0,0,0,,,0,0,0,0,,,0,0,0,0,,,0,0,0,0,,,0,0,0,0,AAPL
2024-10-22 12:47:45.731414572+00:00,10,39,38,A,B,0,231.6,2000,130,203978,59080,231.6,234.8,2000,2000,1,1,,,0,0,0,0,,,0,0,0,0,,,0,0,0,0,,,0,0,0,0,,,0,0,0,0,,,0,0,0,0,,,0,0,0,0,,,0,0,0,0,,,0,0,0,0,AAPL
2024-10-22 12:47:45.758180095+00:00,10,39,38,C,B,0,231.6,2000,130,203572,59081,,234.8,0,2000,0,1,,,0,0,0,0,,,0,0,0,0,,,0,0,0,0,,,0,0,0,0,,,0,0,0,0,,,0,0,0,0,,,0,0,0,0,,,0,0,0,0,,,0,0,0,0,AAPL
2024-10-22 12:48:01.721458253+00:00,10,39,38,A,B,0,231.6,2000,130,203904,59161,231.6,234.8,2000,2000,1,1,,,0,0,0,0,,,0,0,0,0,,,0,0,0,0,,,0,0,0,0,,,0,0,0,0,,,0,0,0,0,,,0,0,0,0,,,0,0,0,0,,,0,0,0,0,AAPL
2024-10-22 12:48:01.788129767+00:00,10,40,38,A,B,0,234.25,200,194,202802,95097,,234.25,0,200,0,0,,,0,0,0,0,,,0,0,0,0,,,0,0,0,0,,,0,0,0,0,,,0,0,0,0,,,0,0,0,0,,,0,0,0,0,,,0,0,0,0,,,0,0,0,0,AAPL
2024-10-22 12:48:01.788146706+00:00,10,40,38,A,B,0,234.25,200,194,202501,95098,233.45,234.25,200,200,0,0,,,0,0,0,0,,,0,0,0,0,,,0,0,0,0,,,0,0,0,0,,,0,0,0,0,,,0,0,0,0,,,0,0,0,0,,,0,0,0,0,,,0,0,0,0,AAPL
2024-10-22 12:48:02.040854055+00:00,10,39,38,C,A,0,234.8,2000,130,203528,59168,231.6,,2000,0,1,0,,,0,0,0,0,,,0,0,0,0,,,0,0,0,0,,,0,0,0,0,,,0,0,0,0,,,0,0,0,0,,,0,0,0,0,,,0,0,0,0,,,0,0,0,0,AAPL
2024-10-22 12:48:02.054108401+00:00,10,39,38,A,A,0,235.0,2000,130,203996,59169,231.6,235.0,2000,2000,1,1,,,0,0,0,0,,,0,0,0,0,,,0,0,0,0,,,0,0,0,0,,,0,0,0,0,,,0,0,0,0,,,0,0,0,0,,,0,0,0,0,,,0,0,0,0,AAPL
2024-10-22 12:48:02.136174532+00:00,10,39,38,C,B,0,231.6,2000,130,203715,59171,,235.0,0,2000,0,1,,,0,0,0,0,,,0,0,0,0,,,0,0,0,0,,,0,0,0,0,,,0,0,0,0,,,0,0,0,0,,,0,0,0,0,,,0,0,0,0,,,0,0,0,0,AAPL
2024-10-22 12:48:02.171765162+00:00,10,39,38,A,B,0,231.4,2000,130,203746,59173,231.4,235.0,2000,2000,1,1,,,0,0,0,0,,,0,0,0,0,,,0,0,0,0,,,0,0,0,0,,,0,0,0,0,,,0,0,0,0,,,0,0,0,0,,,0,0,0,0,,,0,0,0,0,AAPL
2024-10-22 12:48:02.171771043+00:00,10,39,38,A,A,0,234.8,2000,130,203701,59174,231.4,234.8,2000,2000,1,1,,235.0,0,2000,0,1,,,0,0,0,0,,,0,0,0,0,,,0,0,0,0,,,0,0,0,0,,,0,0,0,0,,,0,0,0,0,,,0,0,0,0,,,0,0,0,0,AAPL
2024-10-22 12:48:02.171805946+00:00,10,39,38,C,A,1,235.0,2000,130,203551,59175,231.4,234.8,2000,2000,1,1,,,0,0,0,0,,,0,0,0,0,,,0,0,0,0,,,0,0,0,0,,,0,0,0,0,,,0,0,0,0,,,0,0,0,0,,,0,0,0,0,,,0,0,0,0,AAPL
2024-10-22 12:48:02.185774882+00:00,10,39,38,C,B,0,231.4,2000,130,203638,59176,,234.8,0,2000,0,1,,,0,0,0,0,,,0,0,0,0,,,0,0,0,0,,,0,0,0,0,,,0,0,0,0,,,0,0,0,0,,,0,0,0,0,,,0,0,0,0,,,0,0,0,0,AAPL
2024-10-22 12:48:02.201305643+00:00,10,39,38,C,A,0,234.8,2000,130,203544,59178,,,0,0,0,0,,,0,0,0,0,,,0,0,0,0,,,0,0,0,0,,,0,0,0,0,,,0,0,0,0,,,0,0,0,0,,,0,0,0,0,,,0,0,0,0,,,0,0,0,0,AAPL
2024-10-22 12:48:02.213892367+00:00,10,39,38,A,A,0,235.0,2000,130,203552,59179,,235.0,0,2000,0,1,,,0,0,0,0,,,0,0,0,0,,,0,0,0,0,,,0,0,0,0,,,0,0,0,0,,,0,0,0,0,,,0,0,0,0,,,0,0,0,0,,,0,0,0,0,AAPL
2024-10-22 12:48:02.222346196+00:00,10,39,38,A,B,0,231.6,2000,130,203598,59180,231.6,235.0,2000,2000,1,1,,,0,0,0,0,,,0,0,0,0,,,0,0,0,0,,,0,0,0,0,,,0,0,0,0,,,0,0,0,0,,,0,0,0,0,,,0,0,0,0,,,0,0,0,0,AAPL
2024-10-22 12:48:02.817026199+00:00,10,41,38,A,B,0,234.2,200,194,55557,191446,,234.2,0,200,0,0,,,0,0,0,0,,,0,0,0,0,,,0,0,0,0,,,0,0,0,0,,,0,0,0,0,,,0,0,0,0,,,0,0,0,0,,,0,0,0,0,,,0,0,0,0,AAPL
2024-10-22 12:48:02.817084061+00:00,10,41,38,A,B,0,234.2,200,194,55089,191447,233.47,234.2,200,200,0,0,,,0,0,0,0,,,0,0,0,0,,,0,0,0,0,,,0,0,0,0,,,0,0,0,0,,,0,0,0,0,,,0,0,0,0,,,0,0,0,0,,,0,0,0,0,AAPL
2024-10-22 12:48:14.089348398+00:00,10,39,38,A,A,0,234.8,2000,130,203353,59285,231.6,234.8,2000,2000,1,1,,235.0,0,2000,0,1,,,0,0,0,0,,,0,0,0,0,,,0,0,0,0,,,0,0,0,0,,,0,0,0,0,,,0,0,0,0,,,0,0,0,0,,,0,0,0,0,AAPL
2024-10-22 12:48:14.089534790+00:00,10,39,38,C,A,1,235.0,2000,130,203545,59286,231.6,234.8,2000,2000,1,1,,,0,0,0,0,,,0,0,0,0,,,0,0,0,0,,,0,0,0,0,,,0,0,0,0,,,0,0,0,0,,,0,0,0,0,,,0,0,0,0,,,0,0,0,0,AAPL
2024-10-22 12:48:22.623218329+00:00,10,39,38,C,A,0,234.8,2000,130,203441,59328,231.6,,2000,0,1,0,,,0,0,0,0,,,0,0,0,0,,,0,0,0,0,,,0,0,0,0,,,0,0,0,0,,,0,0,0,0,,,0,0,0,0,,,0,0,0,0,,,0,0,0,0,AAPL
2024-10-22 12:48:22.636350235+00:00,10,39,38,A,A,0,235.0,2000,130,203123,59329,231.6,235.0,2000,2000,1,1,,,0,0,0,0,,,0,0,0,0,,,0,0,0,0,,,0,0,0,0,,,0,0,0,0,,,0,0,0,0,,,0,0,0,0,,,0,0,0,0,,,0,0,0,0,AAPL
2024-10-22 12:48:22.861735042+00:00,10,40,38,A,A,0,,0,194,202836,95494,233.45,,200,0,0,0,,,0,0,0,0,,,0,0,0,0,,,0,0,0,0,,,0,0,0,0,,,0,0,0,0,,,0,0,0,0,,,0,0,0,0,,,0,0,0,0,,,0,0,0,0,AAPL
2024-10-22 12:48:22.861754086+00:00,10,40,38,A,A,0,234.11,200,194,202782,95495,233.45,234.11,200,200,0,0,,,0,0,0,0,,,0,0,0,0,,,0,0,0,0,,,0,0,0,0,,,0,0,0,0,,,0,0,0,0,,,0,0,0,0,,,0,0,0,0,,,0,0,0,0,AAPL
2024-10-22 12:48:22.861990093+00:00,10,41,38,A,A,0,,0,194,55756,192507,233.47,,200,0,0,0,,,0,0,0,0,,,0,0,0,0,,,0,0,0,0,,,0,0,0,0,,,0,0,0,0,,,0,0,0,0,,,0,0,0,0,,,0,0,0,0,,,0,0,0,0,AAPL
2024-10-22 12:48:22.862034170+00:00,10,41,38,A,A,0,234.05,200,194,57283,192508,233.47,234.05,200,200,0,0,,,0,0,0,0,,,0,0,0,0,,,0,0,0,0,,,0,0,0,0,,,0,0,0,0,,,0,0,0,0,,,0,0,0,0,,,0,0,0,0,,,0,0,0,0,AAPL
2024-10-22 12:48:26.707827794+00:00,10,39,38,C,B,0,231.6,2000,130,202819,59358,,235.0,0,2000,0,1,,,0,0,0,0,,,0,0,0,0,,,0,0,0,0,,,0,0,0,0,,,0,0,0,0,,,0,0,0,0,,,0,0,0,0,,,0,0,0,0,,,0,0,0,0,AAPL
2024-10-22 12:48:26.718385314+00:00,10,39,38,A,A,0,234.8,2000,130,202713,59359,,234.8,0,2000,0,1,,235.0,0,2000,0,1,,,0,0,0,0,,,0,0,0,0,,,0,0,0,0,,,0,0,0,0,,,0,0,0,0,,,0,0,0,0,,,0,0,0,0,,,0,0,0,0,AAPL
2024-10-22 12:48:26.718570032+00:00,10,39,38,C,A,1,235.0,2000,130,202714,59360,,234.8,0,2000,0,1,,,0,0,0,0,,,0,0,0,0,,,0,0,0,0,,,0,0,0,0,,,0,0,0,0,,,0,0,0,0,,,0,0,0,0,,,0,0,0,0,,,0,0,0,0,AAPL
2024-10-22 12:48:26.744383252+00:00,10,39,38,A,B,0,231.4,2000,130,202689,59361,231.4,234.8,2000,2000,1,1,,,0,0,0,0,,,0,0,0,0,,,0,0,0,0,,,0,0,0,0,,,0,0,0,0,,,0,0,0,0,,,0,0,0,0,,,0,0,0,0,,,0,0,0,0,AAPL
2024-10-22 12:48:26.952457308+00:00,10,39,38,A,B,0,231.6,2000,130,202800,59364,231.6,234.8,2000,2000,1,1,231.4,,2000,0,1,0,,,0,0,0,0,,,0,0,0,0,,,0,0,0,0,,,0,0,0,0,,,0,0,0,0,,,0,0,0,0,,,0,0,0,0,,,0,0,0,0,AAPL
2024-10-22 12:48:26.952657696+00:00,10,39,38,C,B,1,231.4,2000,130,202676,59365,231.6,234.8,2000,2000,1,1,,,0,0,0,0,,,0,0,0,0,,,0,0,0,0,,,0,0,0,0,,,0,0,0,0,,,0,0,0,0,,,0,0,0,0,,,0,0,0,0,,,0,0,0,0,AAPL
2024-10-22 12:48:29.334016769+00:00,10,39,38,C,B,0,231.6,2000,130,203084,59373,,234.8,0,2000,0,1,,,0,0,0,0,,,0,0,0,0,,,0,0,0,0,,,0,0,0,0,,,0,0,0,0,,,0,0,0,0,,,0,0,0,0,,,0,0,0,0,,,0,0,0,0,AAPL
2024-10-22 12:48:29.344742952+00:00,10,39,38,A,B,0,231.4,2000,130,202672,59374,231.4,234.8,2000,2000,1,1,,,0,0,0,0,,,0,0,0,0,,,0,0,0,0,,,0,0,0,0,,,0,0,0,0,,,0,0,0,0,,,0,0,0,0,,,0,0,0,0,,,0,0,0,0,AAPL
2024-10-22 12:48:51.287227346+00:00,10,39,38,C,A,0,234.8,2000,130,203018,59522,231.4,,2000,0,1,0,,,0,0,0,0,,,0,0,0,0,,,0,0,0,0,,,0,0,0,0,,,0,0,0,0,,,0,0,0,0,,,0,0,0,0,,,0,0,0,0,,,0,0,0,0,AAPL
2024-10-22 12:48:51.299942613+00:00,10,39,38,A,A,0,235.0,2000,130,202875,59523,231.4,235.0,2000,2000,1,1,,,0,0,0,0,,,0,0,0,0,,,0,0,0,0,,,0,0,0,0,,,0,0,0,0,,,0,0,0,0,,,0,0,0,0,,,0,0,0,0,,,0,0,0,0,AAPL
2024-10-22 12:48:52.805828359+00:00,10,39,38,C,A,0,235.0,2000,130,202966,59534,231.4,,2000,0,1,0,,,0,0,0,0,,,0,0,0,0,,,0,0,0,0,,,0,0,0,0,,,0,0,0,0,,,0,0,0,0,,,0,0,0,0,,,0,0,0,0,,,0,0,0,0,AAPL
2024-10-22 12:48:52.815684199+00:00,10,39,38,A,B,0,231.8,2000,130,202886,59535,231.8,,2000,0,1,0,231.4,,2000,0,1,0,,,0,0,0,0,,,0,0,0,0,,,0,0,0,0,,,0,0,0,0,,,0,0,0,0,,,0,0,0,0,,,0,0,0,0,,,0,0,0,0,AAPL
2024-10-22 12:48:52.815890799+00:00,10,39,38,C,B,1,231.4,2000,130,202753,59536,231.8,,2000,0,1,0,,,0,0,0,0,,,0,0,0,0,,,0,0,0,0,,,0,0,0,0,,,0,0,0,0,,,0,0,0,0,,,0,0,0,0,,,0,0,0,0,,,0,0,0,0,AAPL
2024-10-22 12:48:52.842468433+00:00,10,39,38,A,A,0,235.0,2000,130,202834,59537,231.8,235.0,2000,2000,1,1,,,0,0,0,0,,,0,0,0,0,,,0,0,0,0,,,0,0,0,0,,,0,0,0,0,,,0,0,0,0,,,0,0,0,0,,,0,0,0,0,,,0,0,0,0,AAPL
2024-10-22 12:48:58.328650156+00:00,10,39,38,A,A,0,234.8,2000,130,202896,59568,231.8,234.8,2000,2000,1,1,,235.0,0,2000,0,1,,,0,0,0,0,,,0,0,0,0,,,0,0,0,0,,,0,0,0,0,,,0,0,0,0,,,0,0,0,0,,,0,0,0,0,,,0,0,0,0,AAPL
2024-10-22 12:48:58.328842313+00:00,10,39,38,C,A,1,235.0,2000,130,202644,59569,231.8,234.8,2000,2000,1,1,,,0,0,0,0,,,0,0,0,0,,,0,0,0,0,,,0,0,0,0,,,0,0,0,0,,,0,0,0,0,,,0,0,0,0,,,0,0,0,0,,,0,0,0,0,AAPL
2024-10-22 12:48:58.382113964+00:00,10,39,38,C,A,0,234.8,2000,130,202729,59570,231.8,,2000,0,1,0,,,0,0,0,0,,,0,0,0,0,,,0,0,0,0,,,0,0,0,0,,,0,0,0,0,,,0,0,0,0,,,0,0,0,0,,,0,0,0,0,,,0,0,0,0,AAPL
2024-10-22 12:48:58.394994162+00:00,10,39,38,A,A,0,235.0,2000,130,202743,59571,231.8,235.0,2000,2000,1,1,,,0,0,0,0,,,0,0,0,0,,,0,0,0,0,,,0,0,0,0,,,0,0,0,0,,,0,0,0,0,,,0,0,0,0,,,0,0,0,0,,,0,0,0,0,AAPL
2024-10-22 12:48:58.882289507+00:00,10,39,38,C,B,0,231.8,2000,130,202687,59584,,235.0,0,2000,0,1,,,0,0,0,0,,,0,0,0,0,,,0,0,0,0,,,0,0,0,0,,,0,0,0,0,,,0,0,0,0,,,0,0,0,0,,,0,0,0,0,,,0,0,0,0,AAPL
2024-10-22 12:48:58.918177801+00:00,10,39,38,A,B,0,231.6,2000,130,202753,59587,231.6,235.0,2000,2000,1,1,,,0,0,0,0,,,0,0,0,0,,,0,0,0,0,,,0,0,0,0,,,0,0,0,0,,,0,0,0,0,,,0,0,0,0,,,0,0,0,0,,,0,0,0,0,AAPL
2024-10-22 12:48:59.171704576+00:00,10,39,38,A,B,0,231.8,2000,130,203681,59591,231.8,235.0,2000,2000,1,1,231.6,,2000,0,1,0,,,0,0,0,0,,,0,0,0,0,,,0,0,0,0,,,0,0,0,0,,,0,0,0,0,,,0,0,0,0,,,0,0,0,0,,,0,0,0,0,AAPL
2024-10-22 12:48:59.172436283+00:00,10,39,38,C,B,1,231.6,2000,130,202694,59592,231.8,235.0,2000,2000,1,1,,,0,0,0,0,,,0,0,0,0,,,0,0,0,0,,,0,0,0,0,,,0,0,0,0,,,0,0,0,0,,,0,0,0,0,,,0,0,0,0,,,0,0,0,0,AAPL
2024-10-22 12:49:02.849798141+00:00,10,39,38,C,B,0,231.8,2000,130,202706,59634,,235.0,0,2000,0,1,,,0,0,0,0,,,0,0,0,0,,,0,0,0,0,,,0,0,0,0,,,0,0,0,0,,,0,0,0,0,,,0,0,0,0,,,0,0,0,0,,,0,0,0,0,AAPL
2024-10-22 12:49:02.885927371+00:00,10,39,38,A,B,0,231.6,2000,130,202488,59635,231.6,235.0,2000,2000,1,1,,,0,0,0,0,,,0,0,0,0,,,0,0,0,0,,,0,0,0,0,,,0,0,0,0,,,0,0,0,0,,,0,0,0,0,,,0,0,0,0,,,0,0,0,0,AAPL
2024-10-22 12:49:03.562269755+00:00,10,39,38,A,B,0,231.8,2000,130,202854,59639,231.8,235.0,2000,2000,1,1,231.6,,2000,0,1,0,,,0,0,0,0,,,0,0,0,0,,,0,0,0,0,,,0,0,0,0,,,0,0,0,0,,,0,0,0,0,,,0,0,0,0,,,0,0,0,0,AAPL
2024-10-22 12:49:03.562594388+00:00,10,39,38,C,B,1,231.6,2000,130,202618,59640,231.8,235.0,2000,2000,1,1,,,0,0,0,0,,,0,0,0,0,,,0,0,0,0,,,0,0,0,0,,,0,0,0,0,,,0,0,0,0,,,0,0,0,0,,,0,0,0,0,,,0,0,0,0,AAPL
2024-10-22 12:49:03.805377356+00:00,10,39,38,C,B,0,231.8,2000,130,202551,59643,,235.0,0,2000,0,1,,,0,0,0,0,,,0,0,0,0,,,0,0,0,0,,,0,0,0,0,,,0,0,0,0,,,0,0,0,0,,,0,0,0,0,,,0,0,0,0,,,0,0,0,0,AAPL
2024-10-22 12:49:03.816578794+00:00,10,39,38,A,B,0,231.8,2000,130,202551,59645,231.8,235.0,2000,2000,1,1,,,0,0,0,0,,,0,0,0,0,,,0,0,0,0,,,0,0,0,0,,,0,0,0,0,,,0,0,0,0,,,0,0,0,0,,,0,0,0,0,,,0,0,0,0,AAPL
2024-10-22 12:49:11.841099997+00:00,10,39,38,A,A,0,234.8,2000,130,203109,59698,231.8,234.8,2000,2000,1,1,,235.0,0,2000,0,1,,,0,0,0,0,,,0,0,0,0,,,0,0,0,0,,,0,0,0,0,,,0,0,0,0,,,0,0,0,0,,,0,0,0,0,,,0,0,0,0,AAPL
2024-10-22 12:49:11.841296073+00:00,10,39,38,C,A,1,235.0,2000,130,202961,59699,231.8,234.8,2000,2000,1,1,,,0,0,0,0,,,0,0,0,0,,,0,0,0,0,,,0,0,0,0,,,0,0,0,0,,,0,0,0,0,,,0,0,0,0,,,0,0,0,0,,,0,0,0,0,AAPL
2024-10-22 12:49:11.906523434+00:00,10,39,38,C,A,0,234.8,2000,130,202978,59700,231.8,,2000,0,1,0,,,0,0,0,0,,,0,0,0,0,,,0,0,0,0,,,0,0,0,0,,,0,0,0,0,,,0,0,0,0,,,0,0,0,0,,,0,0,0,0,,,0,0,0,0,AAPL
2024-10-22 12:49:11.917294398+00:00,10,39,38,A,A,0,235.0,2000,130,202985,59701,231.8,235.0,2000,2000,1,1,,,0,0,0,0,,,0,0,0,0,,,0,0,0,0,,,0,0,0,0,,,0,0,0,0,,,0,0,0,0,,,0,0,0,0,,,0,0,0,0,,,0,0,0,0,AAPL
2024-10-22 12:49:15.914578641+00:00,10,39,38,C,B,0,231.8,2000,130,203084,59738,,235.0,0,2000,0,1,,,0,0,0,0,,,0,0,0,0,,,0,0,0,0,,,0,0,0,0,,,0,0,0,0,,,0,0,0,0,,,0,0,0,0,,,0,0,0,0,,,0,0,0,0,AAPL
2024-10-22 12:49:16.895245220+00:00,10,39,38,C,A,0,235.0,2000,130,203003,59744,,,0,0,0,0,,,0,0,0,0,,,0,0,0,0,,,0,0,0,0,,,0,0,0,0,,,0,0,0,0,,,0,0,0,0,,,0,0,0,0,,,0,0,0,0,,,0,0,0,0,AAPL
2024-10-22 12:49:16.905224473+00:00,10,39,38,A,B,0,231.8,2000,130,202883,59745,231.8,,2000,0,1,0,,,0,0,0,0,,,0,0,0,0,,,0,0,0,0,,,0,0,0,0,,,0,0,0,0,,,0,0,0,0,,,0,0,0,0,,,0,0,0,0,,,0,0,0,0,AAPL
2024-10-22 12:49:16.928204182+00:00,10,39,38,C,B,0,231.8,2000,130,202777,59746,,,0,0,0,0,,,0,0,0,0,,,0,0,0,0,,,0,0,0,0,,,0,0,0,0,,,0,0,0,0,,,0,0,0,0,,,0,0,0,0,,,0,0,0,0,,,0,0,0,0,AAPL
2024-10-22 12:49:16.930441150+00:00,10,39,38,A,A,0,234.8,2000,130,202910,59747,,234.8,0,2000,0,1,,,0,0,0,0,,,0,0,0,0,,,0,0,0,0,,,0,0,0,0,,,0,0,0,0,,,0,0,0,0,,,0,0,0,0,,,0,0,0,0,,,0,0,0,0,AAPL
2024-10-22 12:49:16.938996042+00:00,10,39,38,A,B,0,231.4,2000,130,202834,59748,231.4,234.8,2000,2000,1,1,,,0,0,0,0,,,0,0,0,0,,,0,0,0,0,,,0,0,0,0,,,0,0,0,0,,,0,0,0,0,,,0,0,0,0,,,0,0,0,0,,,0,0,0,0,AAPL
2024-10-22 12:49:16.958210872+00:00,10,39,38,C,B,0,231.4,2000,130,202740,59749,,234.8,0,2000,0,1,,,0,0,0,0,,,0,0,0,0,,,0,0,0,0,,,0,0,0,0,,,0,0,0,0,,,0,0,0,0,,,0,0,0,0,,,0,0,0,0,,,0,0,0,0,AAPL
2024-10-22 12:49:20.058364805+00:00,10,39,38,A,B,0,231.4,2000,130,203489,59760,231.4,234.8,2000,2000,1,1,,,0,0,0,0,,,0,0,0,0,,,0,0,0,0,,,0,0,0,0,,,0,0,0,0,,,0,0,0,0,,,0,0,0,0,,,0,0,0,0,,,0,0,0,0,AAPL
2024-10-22 12:49:24.850851769+00:00,10,39,38,C,A,0,234.8,2000,130,202776,59787,231.4,,2000,0,1,0,,,0,0,0,0,,,0,0,0,0,,,0,0,0,0,,,0,0,0,0,,,0,0,0,0,,,0,0,0,0,,,0,0,0,0,,,0,0,0,0,,,0,0,0,0,AAPL
2024-10-22 12:49:24.861374454+00:00,10,39,38,A,B,0,231.6,2000,130,202698,59788,231.6,,2000,0,1,0,231.4,,2000,0,1,0,,,0,0,0,0,,,0,0,0,0,,,0,0,0,0,,,0,0,0,0,,,0,0,0,0,,,0,0,0,0,,,0,0,0,0,,,0,0,0,0,AAPL
2024-10-22 12:49:24.861557194+00:00,10,39,38,C,B,1,231.4,2000,130,202642,59789,231.6,,2000,0,1,0,,,0,0,0,0,,,0,0,0,0,,,0,0,0,0,,,0,0,0,0,,,0,0,0,0,,,0,0,0,0,,,0,0,0,0,,,0,0,0,0,,,0,0,0,0,AAPL
2024-10-22 12:49:24.887329709+00:00,10,39,38,A,A,0,235.0,2000,130,202716,59790,231.6,235.0,2000,2000,1,1,,,0,0,0,0,,,0,0,0,0,,,0,0,0,0,,,0,0,0,0,,,0,0,0,0,,,0,0,0,0,,,0,0,0,0,,,0,0,0,0,,,0,0,0,0,AAPL
2024-10-22 12:49:27.715120415+00:00,10,39,38,C,A,0,235.0,2000,130,203592,59806,231.6,,2000,0,1,0,,,0,0,0,0,,,0,0,0,0,,,0,0,0,0,,,0,0,0,0,,,0,0,0,0,,,0,0,0,0,,,0,0,0,0,,,0,0,0,0,,,0,0,0,0,AAPL
2024-10-22 12:49:27.725496933+00:00,10,39,38,A,B,0,231.8,2000,130,203136,59807,231.8,,2000,0,1,0,231.6,,2000,0,1,0,,,0,0,0,0,,,0,0,0,0,,,0,0,0,0,,,0,0,0,0,,,0,0,0,0,,,0,0,0,0,,,0,0,0,0,,,0,0,0,0,AAPL
2024-10-22 12:49:27.725671365+00:00,10,39,38,C,B,1,231.6,2000,130,203025,59808,231.8,,2000,0,1,0,,,0,0,0,0,,,0,0,0,0,,,0,0,0,0,,,0,0,0,0,,,0,0,0,0,,,0,0,0,0,,,0,0,0,0,,,0,0,0,0,,,0,0,0,0,AAPL
2024-10-22 12:49:27.751415991+00:00,10,39,38,A,A,0,235.0,2000,130,203122,59809,231.8,235.0,2000,2000,1,1,,,0,0,0,0,,,0,0,0,0,,,0,0,0,0,,,0,0,0,0,,,0,0,0,0,,,0,0,0,0,,,0,0,0,0,,,0,0,0,0,,,0,0,0,0,AAPL
2024-10-22 12:49:41.406702914+00:00,10,39,38,C,B,0,231.8,2000,130,203589,59877,,235.0,0,2000,0,1,,,0,0,0,0,,,0,0,0,0,,,0,0,0,0,,,0,0,0,0,,,0,0,0,0,,,0,0,0,0,,,0,0,0,0,,,0,0,0,0,,,0,0,0,0,AAPL
2024-10-22 12:49:43.455197736+00:00,10,40,38,A,A,0,,0,194,203647,96700,233.45,,200,0,0,0,,,0,0,0,0,,,0,0,0,0,,,0,0,0,0,,,0,0,0,0,,,0,0,0,0,,,0,0,0,0,,,0,0,0,0,,,0,0,0,0,,,0,0,0,0,AAPL
2024-10-22 12:49:43.455216426+00:00,10,40,38,A,A,0,234.24,200,194,203641,96701,233.45,234.24,200,200,0,0,,,0,0,0,0,,,0,0,0,0,,,0,0,0,0,,,0,0,0,0,,,0,0,0,0,,,0,0,0,0,,,0,0,0,0,,,0,0,0,0,,,0,0,0,0,AAPL
2024-10-22 12:49:43.455661533+00:00,10,41,38,A,A,0,,0,194,55852,196436,233.47,,200,0,0,0,,,0,0,0,0,,,0,0,0,0,,,0,0,0,0,,,0,0,0,0,,,0,0,0,0,,,0,0,0,0,,,0,0,0,0,,,0,0,0,0,,,0,0,0,0,AAPL
2024-10-22 12:49:43.455710173+00:00,10,41,38,A,A,0,234.18,200,194,54482,196437,233.47,234.18,200,200,0,0,,,0,0,0,0,,,0,0,0,0,,,0,0,0,0,,,0,0,0,0,,,0,0,0,0,,,0,0,0,0,,,0,0,0,0,,,0,0,0,0,,,0,0,0,0,AAPL
2024-10-22 12:49:43.456360214+00:00,10,39,38,C,A,0,235.0,2000,130,203842,59881,,,0,0,0,0,,,0,0,0,0,,,0,0,0,0,,,0,0,0,0,,,0,0,0,0,,,0,0,0,0,,,0,0,0,0,,,0,0,0,0,,,0,0,0,0,,,0,0,0,0,AAPL
2024-10-22 12:49:43.466380606+00:00,10,39,38,A,B,0,231.8,2000,130,203632,59882,231.8,,2000,0,1,0,,,0,0,0,0,,,0,0,0,0,,,0,0,0,0,,,0,0,0,0,,,0,0,0,0,,,0,0,0,0,,,0,0,0,0,,,0,0,0,0,,,0,0,0,0,AAPL
2024-10-22 12:49:43.492537833+00:00,10,39,38,A,A,0,235.0,2000,130,203535,59886,231.8,235.0,2000,2000,1,1,,,0,0,0,0,,,0,0,0,0,,,0,0,0,0,,,0,0,0,0,,,0,0,0,0,,,0,0,0,0,,,0,0,0,0,,,0,0,0,0,,,0,0,0,0,AAPL
2024-10-22 12:49:50.423331827+00:00,10,39,38,C,B,0,231.8,2000,130,204001,59928,,235.0,0,2000,0,1,,,0,0,0,0,,,0,0,0,0,,,0,0,0,0,,,0,0,0,0,,,0,0,0,0,,,0,0,0,0,,,0,0,0,0,,,0,0,0,0,,,0,0,0,0,AAPL
2024-10-22 12:49:50.434372820+00:00,10,39,38,A,B,0,231.8,2000,130,203938,59929,231.8,235.0,2000,2000,1,1,,,0,0,0,0,,,0,0,0,0,,,0,0,0,0,,,0,0,0,0,,,0,0,0,0,,,0,0,0,0,,,0,0,0,0,,,0,0,0,0,,,0,0,0,0,AAPL
2024-10-22 12:49:50.449373266+00:00,10,39,38,C,B,0,231.8,2000,130,203866,59930,,235.0,0,2000,0,1,,,0,0,0,0,,,0,0,0,0,,,0,0,0,0,,,0,0,0,0,,,0,0,0,0,,,0,0,0,0,,,0,0,0,0,,,0,0,0,0,,,0,0,0,0,AAPL
2024-10-22 12:49:50.463724245+00:00,10,39,38,A,B,0,231.6,2000,130,203943,59931,231.6,235.0,2000,2000,1,1,,,0,0,0,0,,,0,0,0,0,,,0,0,0,0,,,0,0,0,0,,,0,0,0,0,,,0,0,0,0,,,0,0,0,0,,,0,0,0,0,,,0,0,0,0,AAPL
2024-10-22 12:49:52.010450927+00:00,10,39,38,C,A,0,235.0,2000,130,204387,59941,231.6,,2000,0,1,0,,,0,0,0,0,,,0,0,0,0,,,0,0,0,0,,,0,0,0,0,,,0,0,0,0,,,0,0,0,0,,,0,0,0,0,,,0,0,0,0,,,0,0,0,0,AAPL
2024-10-22 12:49:52.020515947+00:00,10,39,38,A,B,0,231.8,2000,130,203949,59942,231.8,,2000,0,1,0,231.6,,2000,0,1,0,,,0,0,0,0,,,0,0,0,0,,,0,0,0,0,,,0,0,0,0,,,0,0,0,0,,,0,0,0,0,,,0,0,0,0,,,0,0,0,0,AAPL
2024-10-22 12:49:52.020691752+00:00,10,39,38,C,B,1,231.6,2000,130,203856,59943,231.8,,2000,0,1,0,,,0,0,0,0,,,0,0,0,0,,,0,0,0,0,,,0,0,0,0,,,0,0,0,0,,,0,0,0,0,,,0,0,0,0,,,0,0,0,0,,,0,0,0,0,AAPL
2024-10-22 12:49:52.046663200+00:00,10,39,38,A,A,0,235.2,2000,130,203964,59944,231.8,235.2,2000,2000,1,1,,,0,0,0,0,,,0,0,0,0,,,0,0,0,0,,,0,0,0,0,,,0,0,0,0,,,0,0,0,0,,,0,0,0,0,,,0,0,0,0,,,0,0,0,0,AAPL
2024-10-22 12:49:52.300788575+00:00,10,39,38,A,A,0,235.0,2000,130,204287,59945,231.8,235.0,2000,2000,1,1,,235.2,0,2000,0,1,,,0,0,0,0,,,0,0,0,0,,,0,0,0,0,,,0,0,0,0,,,0,0,0,0,,,0,0,0,0,,,0,0,0,0,,,0,0,0,0,AAPL
2024-10-22 12:49:52.301048203+00:00,10,39,38,C,A,1,235.2,2000,130,203802,59946,231.8,235.0,2000,2000,1,1,,,0,0,0,0,,,0,0,0,0,,,0,0,0,0,,,0,0,0,0,,,0,0,0,0,,,0,0,0,0,,,0,0,0,0,,,0,0,0,0,,,0,0,0,0,AAPL
2024-10-22 12:49:56.472517647+00:00,10,39,38,C,A,0,235.0,2000,130,203683,59957,231.8,,2000,0,1,0,,,0,0,0,0,,,0,0,0,0,,,0,0,0,0,,,0,0,0,0,,,0,0,0,0,,,0,0,0,0,,,0,0,0,0,,,0,0,0,0,,,0,0,0,0,AAPL
2024-10-22 12:49:56.483705591+00:00,10,39,38,A,A,0,235.0,2000,130,203752,59958,231.8,235.0,2000,2000,1,1,,,0,0,0,0,,,0,0,0,0,,,0,0,0,0,,,0,0,0,0,,,0,0,0,0,,,0,0,0,0,,,0,0,0,0,,,0,0,0,0,,,0,0,0,0,AAPL
2024-10-22 12:49:56.510895553+00:00,10,39,38,C,A,0,235.0,2000,130,203647,59959,231.8,,2000,0,1,0,,,0,0,0,0,,,0,0,0,0,,,0,0,0,0,,,0,0,0,0,,,0,0,0,0,,,0,0,0,0,,,0,0,0,0,,,0,0,0,0,,,0,0,0,0,AAPL
2024-10-22 12:49:56.522658759+00:00,10,39,38,A,A,0,235.2,2000,130,203674,59960,231.8,235.2,2000,2000,1,1,,,0,0,0,0,,,0,0,0,0,,,0,0,0,0,,,0,0,0,0,,,0,0,0,0,,,0,0,0,0,,,0,0,0,0,,,0,0,0,0,,,0,0,0,0,AAPL
2024-10-22 12:49:57.266828040+00:00,10,41,38,A,A,0,,0,194,55838,197011,233.47,,200,0,0,0,,,0,0,0,0,,,0,0,0,0,,,0,0,0,0,,,0,0,0,0,,,0,0,0,0,,,0,0,0,0,,,0,0,0,0,,,0,0,0,0,,,0,0,0,0,AAPL
2024-10-22 12:49:57.266858447+00:00,10,41,38,A,A,0,234.29,200,194,54416,197012,233.47,234.29,200,200,0,0,,,0,0,0,0,,,0,0,0,0,,,0,0,0,0,,,0,0,0,0,,,0,0,0,0,,,0,0,0,0,,,0,0,0,0,,,0,0,0,0,,,0,0,0,0,AAPL
2024-10-22 12:50:00.035515699+00:00,10,40,38,A,B,0,234.24,200,194,204931,96992,,234.24,0,200,0,0,,,0,0,0,0,,,0,0,0,0,,,0,0,0,0,,,0,0,0,0,,,0,0,0,0,,,0,0,0,0,,,0,0,0,0,,,0,0,0,0,,,0,0,0,0,AAPL
2024-10-22 12:50:00.035530159+00:00,10,40,38,A,A,0,,0,194,204733,96993,,,0,0,0,0,,,0,0,0,0,,,0,0,0,0,,,0,0,0,0,,,0,0,0,0,,,0,0,0,0,,,0,0,0,0,,,0,0,0,0,,,0,0,0,0,,,0,0,0,0,AAPL
2024-10-22 12:50:00.035565040+00:00,10,40,38,A,A,0,234.35,200,194,204847,96996,,234.35,0,200,0,0,,,0,0,0,0,,,0,0,0,0,,,0,0,0,0,,,0,0,0,0,,,0,0,0,0,,,0,0,0,0,,,0,0,0,0,,,0,0,0,0,,,0,0,0,0,AAPL
2024-10-22 12:50:00.035671416+00:00,10,40,38,A,A,0,,0,194,204788,96998,,,0,0,0,0,,,0,0,0,0,,,0,0,0,0,,,0,0,0,0,,,0,0,0,0,,,0,0,0,0,,,0,0,0,0,,,0,0,0,0,,,0,0,0,0,,,0,0,0,0,AAPL
2024-10-22 12:50:00.035887808+00:00,10,41,38,A,B,0,234.29,200,194,58443,197545,,234.29,0,200,0,0,,,0,0,0,0,,,0,0,0,0,,,0,0,0,0,,,0,0,0,0,,,0,0,0,0,,,0,0,0,0,,,0,0,0,0,,,0,0,0,0,,,0,0,0,0,AAPL
2024-10-22 12:50:00.035914315+00:00,10,41,38,A,A,0,,0,194,60121,197552,,,0,0,0,0,,,0,0,0,0,,,0,0,0,0,,,0,0,0,0,,,0,0,0,0,,,0,0,0,0,,,0,0,0,0,,,0,0,0,0,,,0,0,0,0,,,0,0,0,0,AAPL
2024-10-22 12:50:00.237501477+00:00,10,41,38,A,A,0,234.29,200,194,55646,198624,,234.29,0,200,0,0,,,0,0,0,0,,,0,0,0,0,,,0,0,0,0,,,0,0,0,0,,,0,0,0,0,,,0,0,0,0,,,0,0,0,0,,,0,0,0,0,,,0,0,0,0,AAPL
2024-10-22 12:50:00.237393960+00:00,10,40,38,A,A,0,234.35,200,194,204780,97226,,234.35,0,200,0,0,,,0,0,0,0,,,0,0,0,0,,,0,0,0,0,,,0,0,0,0,,,0,0,0,0,,,0,0,0,0,,,0,0,0,0,,,0,0,0,0,,,0,0,0,0,AAPL
2024-10-22 12:50:01.071383820+00:00,10,40,38,A,B,0,234.35,200,194,204633,97285,233.5,234.35,200,200,0,0,,,0,0,0,0,,,0,0,0,0,,,0,0,0,0,,,0,0,0,0,,,0,0,0,0,,,0,0,0,0,,,0,0,0,0,,,0,0,0,0,,,0,0,0,0,AAPL
2024-10-22 12:50:01.071619773+00:00,10,41,38,A,B,0,234.29,200,194,56161,198821,233.56,234.29,200,200,0,0,,,0,0,0,0,,,0,0,0,0,,,0,0,0,0,,,0,0,0,0,,,0,0,0,0,,,0,0,0,0,,,0,0,0,0,,,0,0,0,0,,,0,0,0,0,AAPL
2024-10-22 12:50:01.127900331+00:00,10,40,38,A,B,0,234.35,200,194,204600,97288,,234.35,0,200,0,0,,,0,0,0,0,,,0,0,0,0,,,0,0,0,0,,,0,0,0,0,,,0,0,0,0,,,0,0,0,0,,,0,0,0,0,,,0,0,0,0,,,0,0,0,0,AAPL
2024-10-22 12:50:01.128286107+00:00,10,41,38,A,B,0,234.29,200,194,56009,198836,,234.29,0,200,0,0,,,0,0,0,0,,,0,0,0,0,,,0,0,0,0,,,0,0,0,0,,,0,0,0,0,,,0,0,0,0,,,0,0,0,0,,,0,0,0,0,,,0,0,0,0,AAPL
2024-10-22 12:50:03.838367409+00:00,10,41,38,A,B,0,234.29,200,194,55946,199078,233.56,234.29,200,200,0,0,,,0,0,0,0,,,0,0,0,0,,,0,0,0,0,,,0,0,0,0,,,0,0,0,0,,,0,0,0,0,,,0,0,0,0,,,0,0,0,0,,,0,0,0,0,AAPL
2024-10-22 12:50:05.752662264+00:00,10,40,38,A,B,0,234.35,200,194,204738,97363,233.5,234.35,200,200,0,0,,,0,0,0,0,,,0,0,0,0,,,0,0,0,0,,,0,0,0,0,,,0,0,0,0,,,0,0,0,0,,,0,0,0,0,,,0,0,0,0,,,0,0,0,0,AAPL
2024-10-22 12:50:07.257493578+00:00,10,39,38,C,B,0,231.8,2000,130,204159,60020,,235.2,0,2000,0,1,,,0,0,0,0,,,0,0,0,0,,,0,0,0,0,,,0,0,0,0,,,0,0,0,0,,,0,0,0,0,,,0,0,0,0,,,0,0,0,0,,,0,0,0,0,AAPL
2024-10-22 12:50:07.341628663+00:00,10,39,38,A,A,0,235.0,2000,130,203632,60021,,235.0,0,2000,0,1,,235.2,0,2000,0,1,,,0,0,0,0,,,0,0,0,0,,,0,0,0,0,,,0,0,0,0,,,0,0,0,0,,,0,0,0,0,,,0,0,0,0,,,0,0,0,0,AAPL
2024-10-22 12:50:07.341800987+00:00,10,39,38,C,A,1,235.2,2000,130,203545,60022,,235.0,0,2000,0,1,,,0,0,0,0,,,0,0,0,0,,,0,0,0,0,,,0,0,0,0,,,0,0,0,0,,,0,0,0,0,,,0,0,0,0,,,0,0,0,0,,,0,0,0,0,AAPL
2024-10-22 12:50:07.972579681+00:00,10,40,38,A,B,0,234.35,200,194,204405,97404,,234.35,0,200,0,0,,,0,0,0,0,,,0,0,0,0,,,0,0,0,0,,,0,0,0,0,,,0,0,0,0,,,0,0,0,0,,,0,0,0,0,,,0,0,0,0,,,0,0,0,0,AAPL
2024-10-22 12:50:08.371712049+00:00,10,40,38,A,B,0,234.35,200,194,204496,97417,233.5,234.35,200,200,0,0,,,0,0,0,0,,,0,0,0,0,,,0,0,0,0,,,0,0,0,0,,,0,0,0,0,,,0,0,0,0,,,0,0,0,0,,,0,0,0,0,,,0,0,0,0,AAPL
2024-10-22 12:51:13.141638329+00:00,10,39,38,A,A,0,234.8,2000,130,203634,60422,,234.8,0,2000,0,1,,235.0,0,2000,0,1,,,0,0,0,0,,,0,0,0,0,,,0,0,0,0,,,0,0,0,0,,,0,0,0,0,,,0,0,0,0,,,0,0,0,0,,,0,0,0,0,AAPL
2024-10-22 12:51:13.141833947+00:00,10,39,38,C,A,1,235.0,2000,130,203254,60423,,234.8,0,2000,0,1,,,0,0,0,0,,,0,0,0,0,,,0,0,0,0,,,0,0,0,0,,,0,0,0,0,,,0,0,0,0,,,0,0,0,0,,,0,0,0,0,,,0,0,0,0,AAPL
2024-10-22 12:51:14.194801419+00:00,10,39,38,A,B,0,231.6,2000,130,203358,60434,231.6,234.8,2000,2000,1,1,,,0,0,0,0,,,0,0,0,0,,,0,0,0,0,,,0,0,0,0,,,0,0,0,0,,,0,0,0,0,,,0,0,0,0,,,0,0,0,0,,,0,0,0,0,AAPL
2024-10-22 12:51:18.919658059+00:00,10,39,38,C,B,0,231.6,2000,130,203588,60469,,234.8,0,2000,0,1,,,0,0,0,0,,,0,0,0,0,,,0,0,0,0,,,0,0,0,0,,,0,0,0,0,,,0,0,0,0,,,0,0,0,0,,,0,0,0,0,,,0,0,0,0,AAPL
2024-10-22 12:51:20.170306948+00:00,10,39,38,A,B,0,231.6,2000,130,203599,60474,231.6,234.8,2000,2000,1,1,,,0,0,0,0,,,0,0,0,0,,,0,0,0,0,,,0,0,0,0,,,0,0,0,0,,,0,0,0,0,,,0,0,0,0,,,0,0,0,0,,,0,0,0,0,AAPL
2024-10-22 12:51:25.184501743+00:00,10,39,38,C,B,0,231.6,2000,130,203345,60537,,234.8,0,2000,0,1,,,0,0,0,0,,,0,0,0,0,,,0,0,0,0,,,0,0,0,0,,,0,0,0,0,,,0,0,0,0,,,0,0,0,0,,,0,0,0,0,,,0,0,0,0,AAPL
2024-10-22 12:51:44.592787745+00:00,10,39,38,C,A,0,234.8,2000,130,204026,60738,,,0,0,0,0,,,0,0,0,0,,,0,0,0,0,,,0,0,0,0,,,0,0,0,0,,,0,0,0,0,,,0,0,0,0,,,0,0,0,0,,,0,0,0,0,,,0,0,0,0,AAPL
2024-10-22 12:51:44.602767812+00:00,10,39,38,A,B,0,231.8,2000,130,203475,60739,231.8,,2000,0,1,0,,,0,0,0,0,,,0,0,0,0,,,0,0,0,0,,,0,0,0,0,,,0,0,0,0,,,0,0,0,0,,,0,0,0,0,,,0,0,0,0,,,0,0,0,0,AAPL
2024-10-22 12:51:44.629132149+00:00,10,39,38,C,B,0,231.8,2000,130,203398,60740,,,0,0,0,0,,,0,0,0,0,,,0,0,0,0,,,0,0,0,0,,,0,0,0,0,,,0,0,0,0,,,0,0,0,0,,,0,0,0,0,,,0,0,0,0,,,0,0,0,0,AAPL
2024-10-22 12:51:44.629260631+00:00,10,39,38,A,A,0,234.8,2000,130,203470,60741,,234.8,0,2000,0,1,,,0,0,0,0,,,0,0,0,0,,,0,0,0,0,,,0,0,0,0,,,0,0,0,0,,,0,0,0,0,,,0,0,0,0,,,0,0,0,0,,,0,0,0,0,AAPL
2024-10-22 12:51:44.641952441+00:00,10,39,38,A,B,0,231.8,2000,130,203753,60742,231.8,234.8,2000,2000,1,1,,,0,0,0,0,,,0,0,0,0,,,0,0,0,0,,,0,0,0,0,,,0,0,0,0,,,0,0,0,0,,,0,0,0,0,,,0,0,0,0,,,0,0,0,0,AAPL
2024-10-22 12:51:44.643696073+00:00,10,39,38,C,B,0,231.8,2000,130,203360,60743,,234.8,0,2000,0,1,,,0,0,0,0,,,0,0,0,0,,,0,0,0,0,,,0,0,0,0,,,0,0,0,0,,,0,0,0,0,,,0,0,0,0,,,0,0,0,0,,,0,0,0,0,AAPL
2024-10-22 12:51:53.291748403+00:00,10,39,38,A,B,0,231.8,2000,130,203919,60791,231.8,234.8,2000,2000,1,1,,,0,0,0,0,,,0,0,0,0,,,0,0,0,0,,,0,0,0,0,,,0,0,0,0,,,0,0,0,0,,,0,0,0,0,,,0,0,0,0,,,0,0,0,0,AAPL
2024-10-22 12:51:53.316982649+00:00,10,39,38,C,B,0,231.8,2000,130,203428,60792,,234.8,0,2000,0,1,,,0,0,0,0,,,0,0,0,0,,,0,0,0,0,,,0,0,0,0,,,0,0,0,0,,,0,0,0,0,,,0,0,0,0,,,0,0,0,0,,,0,0,0,0,AAPL
2024-10-22 12:51:53.327950118+00:00,10,39,38,A,B,0,231.8,2000,130,203509,60793,231.8,234.8,2000,2000,1,1,,,0,0,0,0,,,0,0,0,0,,,0,0,0,0,,,0,0,0,0,,,0,0,0,0,,,0,0,0,0,,,0,0,0,0,,,0,0,0,0,,,0,0,0,0,AAPL
2024-10-22 12:51:53.343590488+00:00,10,39,38,C,B,0,231.8,2000,130,203517,60794,,234.8,0,2000,0,1,,,0,0,0,0,,,0,0,0,0,,,0,0,0,0,,,0,0,0,0,,,0,0,0,0,,,0,0,0,0,,,0,0,0,0,,,0,0,0,0,,,0,0,0,0,AAPL
2024-10-22 12:51:53.358369567+00:00,10,39,38,A,B,0,231.6,2000,130,203450,60795,231.6,234.8,2000,2000,1,1,,,0,0,0,0,,,0,0,0,0,,,0,0,0,0,,,0,0,0,0,,,0,0,0,0,,,0,0,0,0,,,0,0,0,0,,,0,0,0,0,,,0,0,0,0,AAPL
2024-10-22 12:52:00.034536494+00:00,10,40,38,A,B,0,234.35,200,194,202074,98722,,234.35,0,200,0,0,,,0,0,0,0,,,0,0,0,0,,,0,0,0,0,,,0,0,0,0,,,0,0,0,0,,,0,0,0,0,,,0,0,0,0,,,0,0,0,0,,,0,0,0,0,AAPL
2024-10-22 12:52:00.070644025+00:00,10,40,38,A,B,0,234.35,200,194,202126,98738,233.6,234.35,200,200,0,0,,,0,0,0,0,,,0,0,0,0,,,0,0,0,0,,,0,0,0,0,,,0,0,0,0,,,0,0,0,0,,,0,0,0,0,,,0,0,0,0,,,0,0,0,0,AAPL
2024-10-22 12:52:06.277465614+00:00,10,39,38,C,A,0,234.8,2000,130,203758,60939,231.6,,2000,0,1,0,,,0,0,0,0,,,0,0,0,0,,,0,0,0,0,,,0,0,0,0,,,0,0,0,0,,,0,0,0,0,,,0,0,0,0,,,0,0,0,0,,,0,0,0,0,AAPL
2024-10-22 12:52:06.292615538+00:00,10,39,38,A,B,0,231.8,2000,130,203778,60940,231.8,,2000,0,1,0,231.6,,2000,0,1,0,,,0,0,0,0,,,0,0,0,0,,,0,0,0,0,,,0,0,0,0,,,0,0,0,0,,,0,0,0,0,,,0,0,0,0,,,0,0,0,0,AAPL
2024-10-22 12:52:06.293007527+00:00,10,39,38,C,B,1,231.6,2000,130,203638,60941,231.8,,2000,0,1,0,,,0,0,0,0,,,0,0,0,0,,,0,0,0,0,,,0,0,0,0,,,0,0,0,0,,,0,0,0,0,,,0,0,0,0,,,0,0,0,0,,,0,0,0,0,AAPL
2024-10-22 12:52:06.314878453+00:00,10,39,38,A,A,0,234.8,2000,130,203704,60942,231.8,234.8,2000,2000,1,1,,,0,0,0,0,,,0,0,0,0,,,0,0,0,0,,,0,0,0,0,,,0,0,0,0,,,0,0,0,0,,,0,0,0,0,,,0,0,0,0,,,0,0,0,0,AAPL
2024-10-22 12:52:08.530179806+00:00,10,39,38,C,A,0,234.8,2000,130,203836,60975,231.8,,2000,0,1,0,,,0,0,0,0,,,0,0,0,0,,,0,0,0,0,,,0,0,0,0,,,0,0,0,0,,,0,0,0,0,,,0,0,0,0,,,0,0,0,0,,,0,0,0,0,AAPL
2024-10-22 12:52:08.541295750+00:00,10,39,38,A,A,0,235.0,2000,130,203723,60976,231.8,235.0,2000,2000,1,1,,,0,0,0,0,,,0,0,0,0,,,0,0,0,0,,,0,0,0,0,,,0,0,0,0,,,0,0,0,0,,,0,0,0,0,,,0,0,0,0,,,0,0,0,0,AAPL
2024-10-22 12:52:08.848432927+00:00,10,39,38,A,A,0,234.8,2000,130,203765,60979,231.8,234.8,2000,2000,1,1,,235.0,0,2000,0,1,,,0,0,0,0,,,0,0,0,0,,,0,0,0,0,,,0,0,0,0,,,0,0,0,0,,,0,0,0,0,,,0,0,0,0,,,0,0,0,0,AAPL
2024-10-22 12:52:08.848635653+00:00,10,39,38,C,A,1,235.0,2000,130,203636,60980,231.8,234.8,2000,2000,1,1,,,0,0,0,0,,,0,0,0,0,,,0,0,0,0,,,0,0,0,0,,,0,0,0,0,,,0,0,0,0,,,0,0,0,0,,,0,0,0,0,,,0,0,0,0,AAPL
2024-10-22 12:52:11.559422898+00:00,10,41,38,A,B,0,234.29,200,194,55731,205469,,234.29,0,200,0,0,,,0,0,0,0,,,0,0,0,0,,,0,0,0,0,,,0,0,0,0,,,0,0,0,0,,,0,0,0,0,,,0,0,0,0,,,0,0,0,0,,,0,0,0,0,AAPL
2024-10-22 12:52:11.559501920+00:00,10,41,38,A,B,0,234.29,200,194,54368,205470,233.66,234.29,200,200,0,0,,,0,0,0,0,,,0,0,0,0,,,0,0,0,0,,,0,0,0,0,,,0,0,0,0,,,0,0,0,0,,,0,0,0,0,,,0,0,0,0,,,0,0,0,0,AAPL
2024-10-22 12:52:15.695548567+00:00,10,39,38,C,A,0,234.8,2000,130,203984,61040,231.8,,2000,0,1,0,,,0,0,0,0,,,0,0,0,0,,,0,0,0,0,,,0,0,0,0,,,0,0,0,0,,,0,0,0,0,,,0,0,0,0,,,0,0,0,0,,,0,0,0,0,AAPL
2024-10-22 12:52:15.706926190+00:00,10,39,38,A,A,0,235.2,2000,130,203886,61041,231.8,235.2,2000,2000,1,1,,,0,0,0,0,,,0,0,0,0,,,0,0,0,0,,,0,0,0,0,,,0,0,0,0,,,0,0,0,0,,,0,0,0,0,,,0,0,0,0,,,0,0,0,0,AAPL
2024-10-22 12:52:25.077008602+00:00,10,39,38,A,A,0,235.0,2000,130,203848,61156,231.8,235.0,2000,2000,1,1,,235.2,0,2000,0,1,,,0,0,0,0,,,0,0,0,0,,,0,0,0,0,,,0,0,0,0,,,0,0,0,0,,,0,0,0,0,,,0,0,0,0,,,0,0,0,0,AAPL
2024-10-22 12:52:25.077211396+00:00,10,39,38,C,A,1,235.2,2000,130,203628,61157,231.8,235.0,2000,2000,1,1,,,0,0,0,0,,,0,0,0,0,,,0,0,0,0,,,0,0,0,0,,,0,0,0,0,,,0,0,0,0,,,0,0,0,0,,,0,0,0,0,,,0,0,0,0,AAPL
2024-10-22 12:52:25.103258383+00:00,10,39,38,C,A,0,235.0,2000,130,203530,61158,231.8,,2000,0,1,0,,,0,0,0,0,,,0,0,0,0,,,0,0,0,0,,,0,0,0,0,,,0,0,0,0,,,0,0,0,0,,,0,0,0,0,,,0,0,0,0,,,0,0,0,0,AAPL
2024-10-22 12:52:25.114954306+00:00,10,39,38,A,A,0,235.2,2000,130,203609,61159,231.8,235.2,2000,2000,1,1,,,0,0,0,0,,,0,0,0,0,,,0,0,0,0,,,0,0,0,0,,,0,0,0,0,,,0,0,0,0,,,0,0,0,0,,,0,0,0,0,,,0,0,0,0,AAPL
2024-10-22 12:52:31.959557837+00:00,10,39,38,A,A,0,235.0,2000,130,203658,61242,231.8,235.0,2000,2000,1,1,,235.2,0,2000,0,1,,,0,0,0,0,,,0,0,0,0,,,0,0,0,0,,,0,0,0,0,,,0,0,0,0,,,0,0,0,0,,,0,0,0,0,,,0,0,0,0,AAPL
2024-10-22 12:52:31.959741400+00:00,10,39,38,C,A,1,235.2,2000,130,203540,61243,231.8,235.0,2000,2000,1,1,,,0,0,0,0,,,0,0,0,0,,,0,0,0,0,,,0,0,0,0,,,0,0,0,0,,,0,0,0,0,,,0,0,0,0,,,0,0,0,0,,,0,0,0,0,AAPL
2024-10-22 12:52:33.957166851+00:00,10,39,38,C,B,0,231.8,2000,130,203780,61253,,235.0,0,2000,0,1,,,0,0,0,0,,,0,0,0,0,,,0,0,0,0,,,0,0,0,0,,,0,0,0,0,,,0,0,0,0,,,0,0,0,0,,,0,0,0,0,,,0,0,0,0,AAPL
2024-10-22 12:52:39.788547105+00:00,10,39,38,A,B,0,231.8,2000,130,203903,61293,231.8,235.0,2000,2000,1,1,,,0,0,0,0,,,0,0,0,0,,,0,0,0,0,,,0,0,0,0,,,0,0,0,0,,,0,0,0,0,,,0,0,0,0,,,0,0,0,0,,,0,0,0,0,AAPL
2024-10-22 12:52:45.666651561+00:00,10,39,38,C,B,0,231.8,2000,130,203863,61349,,235.0,0,2000,0,1,,,0,0,0,0,,,0,0,0,0,,,0,0,0,0,,,0,0,0,0,,,0,0,0,0,,,0,0,0,0,,,0,0,0,0,,,0,0,0,0,,,0,0,0,0,AAPL
2024-10-22 12:53:05.003692690+00:00,10,39,38,C,A,0,235.0,2000,130,204168,61473,,,0,0,0,0,,,0,0,0,0,,,0,0,0,0,,,0,0,0,0,,,0,0,0,0,,,0,0,0,0,,,0,0,0,0,,,0,0,0,0,,,0,0,0,0,,,0,0,0,0,AAPL
2024-10-22 12:53:05.014561201+00:00,10,39,38,A,A,0,235.2,2000,130,203687,61474,,235.2,0,2000,0,1,,,0,0,0,0,,,0,0,0,0,,,0,0,0,0,,,0,0,0,0,,,0,0,0,0,,,0,0,0,0,,,0,0,0,0,,,0,0,0,0,,,0,0,0,0,AAPL
2024-10-22 12:53:05.843721083+00:00,10,39,38,A,A,0,235.0,2000,130,203655,61485,,235.0,0,2000,0,1,,235.2,0,2000,0,1,,,0,0,0,0,,,0,0,0,0,,,0,0,0,0,,,0,0,0,0,,,0,0,0,0,,,0,0,0,0,,,0,0,0,0,,,0,0,0,0,AAPL
2024-10-22 12:53:05.843912156+00:00,10,39,38,C,A,1,235.2,2000,130,203476,61486,,235.0,0,2000,0,1,,,0,0,0,0,,,0,0,0,0,,,0,0,0,0,,,0,0,0,0,,,0,0,0,0,,,0,0,0,0,,,0,0,0,0,,,0,0,0,0,,,0,0,0,0,AAPL
2024-10-22 12:53:05.868941667+00:00,10,39,38,C,A,0,235.0,2000,130,203464,61488,,,0,0,0,0,,,0,0,0,0,,,0,0,0,0,,,0,0,0,0,,,0,0,0,0,,,0,0,0,0,,,0,0,0,0,,,0,0,0,0,,,0,0,0,0,,,0,0,0,0,AAPL
2024-10-22 12:53:05.879893238+00:00,10,39,38,A,A,0,235.2,2000,130,203581,61489,,235.2,0,2000,0,1,,,0,0,0,0,,,0,0,0,0,,,0,0,0,0,,,0,0,0,0,,,0,0,0,0,,,0,0,0,0,,,0,0,0,0,,,0,0,0,0,,,0,0,0,0,AAPL
2024-10-22 12:53:09.817386870+00:00,10,39,38,A,B,0,231.8,2000,130,203643,61505,231.8,235.2,2000,2000,1,1,,,0,0,0,0,,,0,0,0,0,,,0,0,0,0,,,0,0,0,0,,,0,0,0,0,,,0,0,0,0,,,0,0,0,0,,,0,0,0,0,,,0,0,0,0,AAPL
2024-10-22 12:53:09.839084272+00:00,10,39,38,C,B,0,231.8,2000,130,203582,61506,,235.2,0,2000,0,1,,,0,0,0,0,,,0,0,0,0,,,0,0,0,0,,,0,0,0,0,,,0,0,0,0,,,0,0,0,0,,,0,0,0,0,,,0,0,0,0,,,0,0,0,0,AAPL
2024-10-22 12:53:17.857704578+00:00,10,39,38,C,A,0,235.2,2000,130,203710,61562,,,0,0,0,0,,,0,0,0,0,,,0,0,0,0,,,0,0,0,0,,,0,0,0,0,,,0,0,0,0,,,0,0,0,0,,,0,0,0,0,,,0,0,0,0,,,0,0,0,0,AAPL
2024-10-22 12:53:17.870248959+00:00,10,39,38,A,A,0,235.6,2000,130,203477,61563,,235.6,0,2000,0,1,,,0,0,0,0,,,0,0,0,0,,,0,0,0,0,,,0,0,0,0,,,0,0,0,0,,,0,0,0,0,,,0,0,0,0,,,0,0,0,0,,,0,0,0,0,AAPL
2024-10-22 12:53:22.407745313+00:00,10,39,38,A,B,0,231.8,2000,130,203544,61588,231.8,235.6,2000,2000,1,1,,,0,0,0,0,,,0,0,0,0,,,0,0,0,0,,,0,0,0,0,,,0,0,0,0,,,0,0,0,0,,,0,0,0,0,,,0,0,0,0,,,0,0,0,0,AAPL
2024-10-22 12:53:22.461026576+00:00,10,39,38,C,B,0,231.8,2000,130,203338,61589,,235.6,0,2000,0,1,,,0,0,0,0,,,0,0,0,0,,,0,0,0,0,,,0,0,0,0,,,0,0,0,0,,,0,0,0,0,,,0,0,0,0,,,0,0,0,0,,,0,0,0,0,AAPL
2024-10-22 12:53:23.244672011+00:00,10,39,38,C,A,0,235.6,2000,130,203859,61594,,,0,0,0,0,,,0,0,0,0,,,0,0,0,0,,,0,0,0,0,,,0,0,0,0,,,0,0,0,0,,,0,0,0,0,,,0,0,0,0,,,0,0,0,0,,,0,0,0,0,AAPL
2024-10-22 12:53:23.255832129+00:00,10,39,38,A,A,0,235.8,2000,130,203525,61595,,235.8,0,2000,0,1,,,0,0,0,0,,,0,0,0,0,,,0,0,0,0,,,0,0,0,0,,,0,0,0,0,,,0,0,0,0,,,0,0,0,0,,,0,0,0,0,,,0,0,0,0,AAPL
2024-10-22 12:53:31.976877076+00:00,10,39,38,A,B,0,231.6,2000,130,203730,61660,231.6,235.8,2000,2000,1,1,,,0,0,0,0,,,0,0,0,0,,,0,0,0,0,,,0,0,0,0,,,0,0,0,0,,,0,0,0,0,,,0,0,0,0,,,0,0,0,0,,,0,0,0,0,AAPL
2024-10-22 12:53:32.114333342+00:00,10,39,38,C,A,0,235.8,2000,130,203571,61666,231.6,,2000,0,1,0,,,0,0,0,0,,,0,0,0,0,,,0,0,0,0,,,0,0,0,0,,,0,0,0,0,,,0,0,0,0,,,0,0,0,0,,,0,0,0,0,,,0,0,0,0,AAPL
2024-10-22 12:53:32.125306928+00:00,10,39,38,A,A,0,236.2,2000,130,203698,61668,231.6,236.2,2000,2000,1,1,,,0,0,0,0,,,0,0,0,0,,,0,0,0,0,,,0,0,0,0,,,0,0,0,0,,,0,0,0,0,,,0,0,0,0,,,0,0,0,0,,,0,0,0,0,AAPL
2024-10-22 12:53:33.791598755+00:00,10,39,38,C,A,0,236.2,2000,130,203831,61676,231.6,,2000,0,1,0,,,0,0,0,0,,,0,0,0,0,,,0,0,0,0,,,0,0,0,0,,,0,0,0,0,,,0,0,0,0,,,0,0,0,0,,,0,0,0,0,,,0,0,0,0,AAPL
2024-10-22 12:53:33.802397317+00:00,10,39,38,A,A,0,236.4,2000,130,203730,61677,231.6,236.4,2000,2000,1,1,,,0,0,0,0,,,0,0,0,0,,,0,0,0,0,,,0,0,0,0,,,0,0,0,0,,,0,0,0,0,,,0,0,0,0,,,0,0,0,0,,,0,0,0,0,AAPL
2024-10-22 12:53:38.103318518+00:00,10,39,38,A,B,0,231.8,2000,130,204107,61712,231.8,236.4,2000,2000,1,1,231.6,,2000,0,1,0,,,0,0,0,0,,,0,0,0,0,,,0,0,0,0,,,0,0,0,0,,,0,0,0,0,,,0,0,0,0,,,0,0,0,0,,,0,0,0,0,AAPL
2024-10-22 12:53:38.103508536+00:00,10,39,38,C,B,1,231.6,2000,130,203611,61713,231.8,236.4,2000,2000,1,1,,,0,0,0,0,,,0,0,0,0,,,0,0,0,0,,,0,0,0,0,,,0,0,0,0,,,0,0,0,0,,,0,0,0,0,,,0,0,0,0,,,0,0,0,0,AAPL
2024-10-22 12:53:38.414958552+00:00,10,39,38,C,B,0,231.8,2000,130,203746,61716,,236.4,0,2000,0,1,,,0,0,0,0,,,0,0,0,0,,,0,0,0,0,,,0,0,0,0,,,0,0,0,0,,,0,0,0,0,,,0,0,0,0,,,0,0,0,0,,,0,0,0,0,AAPL
2024-10-22 12:53:38.425674679+00:00,10,39,38,A,B,0,231.6,2000,130,203683,61717,231.6,236.4,2000,2000,1,1,,,0,0,0,0,,,0,0,0,0,,,0,0,0,0,,,0,0,0,0,,,0,0,0,0,,,0,0,0,0,,,0,0,0,0,,,0,0,0,0,,,0,0,0,0,AAPL
2024-10-22 12:53:39.656408043+00:00,10,39,38,C,B,0,231.6,2000,130,203778,61747,,236.4,0,2000,0,1,,,0,0,0,0,,,0,0,0,0,,,0,0,0,0,,,0,0,0,0,,,0,0,0,0,,,0,0,0,0,,,0,0,0,0,,,0,0,0,0,,,0,0,0,0,AAPL
2024-10-22 12:53:45.772409033+00:00,10,39,38,A,A,0,235.8,2000,130,204797,61768,,235.8,0,2000,0,1,,236.4,0,2000,0,1,,,0,0,0,0,,,0,0,0,0,,,0,0,0,0,,,0,0,0,0,,,0,0,0,0,,,0,0,0,0,,,0,0,0,0,,,0,0,0,0,AAPL
2024-10-22 12:53:45.772610573+00:00,10,39,38,C,A,1,236.4,2000,130,203810,61769,,235.8,0,2000,0,1,,,0,0,0,0,,,0,0,0,0,,,0,0,0,0,,,0,0,0,0,,,0,0,0,0,,,0,0,0,0,,,0,0,0,0,,,0,0,0,0,,,0,0,0,0,AAPL
2024-10-22 12:53:45.830364777+00:00,10,39,38,C,A,0,235.8,2000,130,203779,61770,,,0,0,0,0,,,0,0,0,0,,,0,0,0,0,,,0,0,0,0,,,0,0,0,0,,,0,0,0,0,,,0,0,0,0,,,0,0,0,0,,,0,0,0,0,,,0,0,0,0,AAPL
2024-10-22 12:53:45.841720922+00:00,10,39,38,A,A,0,236.0,2000,130,203828,61771,,236.0,0,2000,0,1,,,0,0,0,0,,,0,0,0,0,,,0,0,0,0,,,0,0,0,0,,,0,0,0,0,,,0,0,0,0,,,0,0,0,0,,,0,0,0,0,,,0,0,0,0,AAPL
2024-10-22 12:53:53.685359014+00:00,10,39,38,A,B,0,231.6,2000,130,204320,61822,231.6,236.0,2000,2000,1,1,,,0,0,0,0,,,0,0,0,0,,,0,0,0,0,,,0,0,0,0,,,0,0,0,0,,,0,0,0,0,,,0,0,0,0,,,0,0,0,0,,,0,0,0,0,AAPL
2024-10-22 12:54:01.784047248+00:00,10,39,38,C,A,0,236.0,2000,130,203917,61886,231.6,,2000,0,1,0,,,0,0,0,0,,,0,0,0,0,,,0,0,0,0,,,0,0,0,0,,,0,0,0,0,,,0,0,0,0,,,0,0,0,0,,,0,0,0,0,,,0,0,0,0,AAPL
2024-10-22 12:54:01.794822204+00:00,10,39,38,A,A,0,236.0,2000,130,203711,61888,231.6,236.0,2000,2000,1,1,,,0,0,0,0,,,0,0,0,0,,,0,0,0,0,,,0,0,0,0,,,0,0,0,0,,,0,0,0,0,,,0,0,0,0,,,0,0,0,0,,,0,0,0,0,AAPL
2024-10-22 12:54:02.686565784+00:00,10,39,38,C,B,0,231.6,2000,130,203688,61904,,236.0,0,2000,0,1,,,0,0,0,0,,,0,0,0,0,,,0,0,0,0,,,0,0,0,0,,,0,0,0,0,,,0,0,0,0,,,0,0,0,0,,,0,0,0,0,,,0,0,0,0,AAPL
2024-10-22 12:54:02.738981416+00:00,10,39,38,A,B,0,231.8,2000,130,203536,61905,231.8,236.0,2000,2000,1,1,,,0,0,0,0,,,0,0,0,0,,,0,0,0,0,,,0,0,0,0,,,0,0,0,0,,,0,0,0,0,,,0,0,0,0,,,0,0,0,0,,,0,0,0,0,AAPL
2024-10-22 12:54:02.788735130+00:00,10,39,38,C,B,0,231.8,2000,130,203518,61906,,236.0,0,2000,0,1,,,0,0,0,0,,,0,0,0,0,,,0,0,0,0,,,0,0,0,0,,,0,0,0,0,,,0,0,0,0,,,0,0,0,0,,,0,0,0,0,,,0,0,0,0,AAPL
2024-10-22 12:54:02.804776381+00:00,10,39,38,A,B,0,231.8,2000,130,203558,61907,231.8,236.0,2000,2000,1,1,,,0,0,0,0,,,0,0,0,0,,,0,0,0,0,,,0,0,0,0,,,0,0,0,0,,,0,0,0,0,,,0,0,0,0,,,0,0,0,0,,,0,0,0,0,AAPL
2024-10-22 12:54:04.706828684+00:00,10,39,38,C,A,0,236.0,2000,130,203485,61918,231.8,,2000,0,1,0,,,0,0,0,0,,,0,0,0,0,,,0,0,0,0,,,0,0,0,0,,,0,0,0,0,,,0,0,0,0,,,0,0,0,0,,,0,0,0,0,,,0,0,0,0,AAPL
2024-10-22 12:54:04.717895119+00:00,10,39,38,A,A,0,236.2,2000,130,203287,61919,231.8,236.2,2000,2000,1,1,,,0,0,0,0,,,0,0,0,0,,,0,0,0,0,,,0,0,0,0,,,0,0,0,0,,,0,0,0,0,,,0,0,0,0,,,0,0,0,0,,,0,0,0,0,AAPL
2024-10-22 12:54:16.393781947+00:00,10,39,38,C,A,0,236.2,2000,130,202997,62003,231.8,,2000,0,1,0,,,0,0,0,0,,,0,0,0,0,,,0,0,0,0,,,0,0,0,0,,,0,0,0,0,,,0,0,0,0,,,0,0,0,0,,,0,0,0,0,,,0,0,0,0,AAPL
2024-10-22 12:54:24.321029858+00:00,10,39,38,C,B,0,231.8,2000,130,203485,62069,,,0,0,0,0,,,0,0,0,0,,,0,0,0,0,,,0,0,0,0,,,0,0,0,0,,,0,0,0,0,,,0,0,0,0,,,0,0,0,0,,,0,0,0,0,,,0,0,0,0,AAPL
2024-10-22 12:54:25.336685921+00:00,10,39,38,A,B,0,231.8,2000,130,203378,62072,231.8,,2000,0,1,0,,,0,0,0,0,,,0,0,0,0,,,0,0,0,0,,,0,0,0,0,,,0,0,0,0,,,0,0,0,0,,,0,0,0,0,,,0,0,0,0,,,0,0,0,0,AAPL
2024-10-22 12:54:25.363178017+00:00,10,39,38,C,B,0,231.8,2000,130,203018,62073,,,0,0,0,0,,,0,0,0,0,,,0,0,0,0,,,0,0,0,0,,,0,0,0,0,,,0,0,0,0,,,0,0,0,0,,,0,0,0,0,,,0,0,0,0,,,0,0,0,0,AAPL
2024-10-22 12:54:46.966517886+00:00,10,39,38,A,B,0,231.8,2000,130,203410,62264,231.8,,2000,0,1,0,,,0,0,0,0,,,0,0,0,0,,,0,0,0,0,,,0,0,0,0,,,0,0,0,0,,,0,0,0,0,,,0,0,0,0,,,0,0,0,0,,,0,0,0,0,AAPL
2024-10-22 12:54:47.322519919+00:00,10,40,38,A,A,0,,0,194,202685,100781,233.6,,200,0,0,0,,,0,0,0,0,,,0,0,0,0,,,0,0,0,0,,,0,0,0,0,,,0,0,0,0,,,0,0,0,0,,,0,0,0,0,,,0,0,0,0,,,0,0,0,0,AAPL
2024-10-22 12:54:47.322534977+00:00,10,40,38,A,A,0,234.47,200,194,203004,100782,233.6,234.47,200,200,0,0,,,0,0,0,0,,,0,0,0,0,,,0,0,0,0,,,0,0,0,0,,,0,0,0,0,,,0,0,0,0,,,0,0,0,0,,,0,0,0,0,,,0,0,0,0,AAPL
2024-10-22 12:54:47.322989055+00:00,10,41,38,A,A,0,,0,194,56093,211727,233.66,,200,0,0,0,,,0,0,0,0,,,0,0,0,0,,,0,0,0,0,,,0,0,0,0,,,0,0,0,0,,,0,0,0,0,,,0,0,0,0,,,0,0,0,0,,,0,0,0,0,AAPL
2024-10-22 12:54:47.323060784+00:00,10,41,38,A,A,0,234.41,200,194,56985,211728,233.66,234.41,200,200,0,0,,,0,0,0,0,,,0,0,0,0,,,0,0,0,0,,,0,0,0,0,,,0,0,0,0,,,0,0,0,0,,,0,0,0,0,,,0,0,0,0,,,0,0,0,0,AAPL
2024-10-22 12:54:51.491728065+00:00,10,40,38,A,B,0,234.47,200,194,203617,100807,,234.47,0,200,0,0,,,0,0,0,0,,,0,0,0,0,,,0,0,0,0,,,0,0,0,0,,,0,0,0,0,,,0,0,0,0,,,0,0,0,0,,,0,0,0,0,,,0,0,0,0,AAPL
2024-10-22 12:54:51.491749685+00:00,10,40,38,A,B,0,234.47,200,194,203068,100808,233.74,234.47,200,200,0,0,,,0,0,0,0,,,0,0,0,0,,,0,0,0,0,,,0,0,0,0,,,0,0,0,0,,,0,0,0,0,,,0,0,0,0,,,0,0,0,0,,,0,0,0,0,AAPL
2024-10-22 12:54:51.491870224+00:00,10,41,38,A,B,0,234.41,200,194,62073,211837,,234.41,0,200,0,0,,,0,0,0,0,,,0,0,0,0,,,0,0,0,0,,,0,0,0,0,,,0,0,0,0,,,0,0,0,0,,,0,0,0,0,,,0,0,0,0,,,0,0,0,0,AAPL
2024-10-22 12:54:51.491921800+00:00,10,41,38,A,B,0,234.41,200,194,55147,211838,233.8,234.41,200,200,0,0,,,0,0,0,0,,,0,0,0,0,,,0,0,0,0,,,0,0,0,0,,,0,0,0,0,,,0,0,0,0,,,0,0,0,0,,,0,0,0,0,,,0,0,0,0,AAPL
2024-10-22 12:54:52.921041824+00:00,10,39,38,C,B,0,231.8,2000,130,203483,62284,,,0,0,0,0,,,0,0,0,0,,,0,0,0,0,,,0,0,0,0,,,0,0,0,0,,,0,0,0,0,,,0,0,0,0,,,0,0,0,0,,,0,0,0,0,,,0,0,0,0,AAPL
2024-10-22 12:54:56.340799977+00:00,10,39,10888,A,B,0,418.42,100,130,204028,91740,418.42,,100,0,1,0,,,0,0,0,0,,,0,0,0,0,,,0,0,0,0,,,0,0,0,0,,,0,0,0,0,,,0,0,0,0,,,0,0,0,0,,,0,0,0,0,,,0,0,0,0,MSFT
2024-10-22 12:54:57.364351684+00:00,10,39,10888,C,B,0,418.42,100,130,203635,91747,,,0,0,0,0,,,0,0,0,0,,,0,0,0,0,,,0,0,0,0,,,0,0,0,0,,,0,0,0,0,,,0,0,0,0,,,0,0,0,0,,,0,0,0,0,,,0,0,0,0,MSFT
2024-10-22 12:55:00.050201782+00:00,10,40,38,A,B,0,234.47,200,194,203644,100984,,234.47,0,200,0,0,,,0,0,0,0,,,0,0,0,0,,,0,0,0,0,,,0,0,0,0,,,0,0,0,0,,,0,0,0,0,,,0,0,0,0,,,0,0,0,0,,,0,0,0,0,AAPL
2024-10-22 12:55:00.050212023+00:00,10,40,38,A,A,0,,0,194,203621,100985,,,0,0,0,0,,,0,0,0,0,,,0,0,0,0,,,0,0,0,0,,,0,0,0,0,,,0,0,0,0,,,0,0,0,0,,,0,0,0,0,,,0,0,0,0,,,0,0,0,0,AAPL
2024-10-22 12:55:00.050441162+00:00,10,41,38,A,B,0,234.41,200,194,56061,212541,,234.41,0,200,0,0,,,0,0,0,0,,,0,0,0,0,,,0,0,0,0,,,0,0,0,0,,,0,0,0,0,,,0,0,0,0,,,0,0,0,0,,,0,0,0,0,,,0,0,0,0,AAPL
2024-10-22 12:55:00.050462758+00:00,10,41,38,A,A,0,,0,192,63600,212544,,,0,0,0,0,,,0,0,0,0,,,0,0,0,0,,,0,0,0,0,,,0,0,0,0,,,0,0,0,0,,,0,0,0,0,,,0,0,0,0,,,0,0,0,0,,,0,0,0,0,AAPL
2024-10-22 12:55:00.150805583+00:00,10,40,38,A,A,0,234.49,200,194,203627,101086,,234.49,0,200,0,0,,,0,0,0,0,,,0,0,0,0,,,0,0,0,0,,,0,0,0,0,,,0,0,0,0,,,0,0,0,0,,,0,0,0,0,,,0,0,0,0,,,0,0,0,0,AAPL
2024-10-22 12:55:00.151042688+00:00,10,41,38,A,A,0,234.43,200,194,55359,212987,,234.43,0,200,0,0,,,0,0,0,0,,,0,0,0,0,,,0,0,0,0,,,0,0,0,0,,,0,0,0,0,,,0,0,0,0,,,0,0,0,0,,,0,0,0,0,,,0,0,0,0,AAPL
2024-10-22 12:55:00.150937055+00:00,10,40,38,A,B,0,234.49,200,194,203610,101087,233.76,234.49,200,200,0,0,,,0,0,0,0,,,0,0,0,0,,,0,0,0,0,,,0,0,0,0,,,0,0,0,0,,,0,0,0,0,,,0,0,0,0,,,0,0,0,0,,,0,0,0,0,AAPL
2024-10-22 12:55:00.351992720+00:00,10,40,38,A,B,0,234.49,200,194,203769,101129,,234.49,0,200,0,0,,,0,0,0,0,,,0,0,0,0,,,0,0,0,0,,,0,0,0,0,,,0,0,0,0,,,0,0,0,0,,,0,0,0,0,,,0,0,0,0,,,0,0,0,0,AAPL
2024-10-22 12:55:00.417402509+00:00,10,40,38,A,B,0,234.49,200,194,203633,101140,233.76,234.49,200,200,0,0,,,0,0,0,0,,,0,0,0,0,,,0,0,0,0,,,0,0,0,0,,,0,0,0,0,,,0,0,0,0,,,0,0,0,0,,,0,0,0,0,,,0,0,0,0,AAPL
2024-10-22 12:55:00.417791629+00:00,10,41,38,A,B,0,234.43,200,194,55591,213239,233.82,234.43,200,200,0,0,,,0,0,0,0,,,0,0,0,0,,,0,0,0,0,,,0,0,0,0,,,0,0,0,0,,,0,0,0,0,,,0,0,0,0,,,0,0,0,0,,,0,0,0,0,AAPL
2024-10-22 12:55:00.721654338+00:00,10,40,38,A,B,0,234.49,200,194,203628,101162,,234.49,0,200,0,0,,,0,0,0,0,,,0,0,0,0,,,0,0,0,0,,,0,0,0,0,,,0,0,0,0,,,0,0,0,0,,,0,0,0,0,,,0,0,0,0,,,0,0,0,0,AAPL
2024-10-22 12:55:01.168080903+00:00,10,40,38,A,B,0,234.49,200,194,203497,101181,233.76,234.49,200,200,0,0,,,0,0,0,0,,,0,0,0,0,,,0,0,0,0,,,0,0,0,0,,,0,0,0,0,,,0,0,0,0,,,0,0,0,0,,,0,0,0,0,,,0,0,0,0,AAPL
2024-10-22 12:55:01.369225052+00:00,10,40,38,A,B,0,234.49,200,194,203721,101185,,234.49,0,200,0,0,,,0,0,0,0,,,0,0,0,0,,,0,0,0,0,,,0,0,0,0,,,0,0,0,0,,,0,0,0,0,,,0,0,0,0,,,0,0,0,0,,,0,0,0,0,AAPL
2024-10-22 12:55:02.443874748+00:00,10,40,38,A,B,0,234.49,200,194,203696,101196,233.75,234.49,200,200,0,0,,,0,0,0,0,,,0,0,0,0,,,0,0,0,0,,,0,0,0,0,,,0,0,0,0,,,0,0,0,0,,,0,0,0,0,,,0,0,0,0,,,0,0,0,0,AAPL
2024-10-22 12:55:03.150674958+00:00,10,40,38,A,B,0,234.49,200,194,203936,101207,,234.49,0,200,0,0,,,0,0,0,0,,,0,0,0,0,,,0,0,0,0,,,0,0,0,0,,,0,0,0,0,,,0,0,0,0,,,0,0,0,0,,,0,0,0,0,,,0,0,0,0,AAPL
2024-10-22 12:55:03.744799559+00:00,10,40,38,A,B,0,234.49,200,194,203980,101213,233.75,234.49,200,200,0,0,,,0,0,0,0,,,0,0,0,0,,,0,0,0,0,,,0,0,0,0,,,0,0,0,0,,,0,0,0,0,,,0,0,0,0,,,0,0,0,0,,,0,0,0,0,AAPL
2024-10-22 12:55:03.755704138+00:00,10,39,38,A,B,0,231.8,2000,130,204138,62328,231.8,,2000,0,1,0,,,0,0,0,0,,,0,0,0,0,,,0,0,0,0,,,0,0,0,0,,,0,0,0,0,,,0,0,0,0,,,0,0,0,0,,,0,0,0,0,,,0,0,0,0,AAPL
2024-10-22 12:55:04.421395409+00:00,10,40,38,A,B,0,234.49,200,194,204122,101222,,234.49,0,200,0,0,,,0,0,0,0,,,0,0,0,0,,,0,0,0,0,,,0,0,0,0,,,0,0,0,0,,,0,0,0,0,,,0,0,0,0,,,0,0,0,0,,,0,0,0,0,AAPL
2024-10-22 12:55:05.766361287+00:00,10,40,38,A,B,0,234.49,200,194,204148,101253,233.75,234.49,200,200,0,0,,,0,0,0,0,,,0,0,0,0,,,0,0,0,0,,,0,0,0,0,,,0,0,0,0,,,0,0,0,0,,,0,0,0,0,,,0,0,0,0,,,0,0,0,0,AAPL
2024-10-22 12:55:21.089073320+00:00,10,39,38,A,B,0,232.2,2000,130,203427,62438,232.2,,2000,0,1,0,231.8,,2000,0,1,0,,,0,0,0,0,,,0,0,0,0,,,0,0,0,0,,,0,0,0,0,,,0,0,0,0,,,0,0,0,0,,,0,0,0,0,,,0,0,0,0,AAPL
2024-10-22 12:55:21.089269359+00:00,10,39,38,C,B,1,231.8,2000,130,203417,62439,232.2,,2000,0,1,0,,,0,0,0,0,,,0,0,0,0,,,0,0,0,0,,,0,0,0,0,,,0,0,0,0,,,0,0,0,0,,,0,0,0,0,,,0,0,0,0,,,0,0,0,0,AAPL
2024-10-22 12:55:21.117654247+00:00,10,39,38,A,A,0,236.4,2000,130,203437,62453,232.2,236.4,2000,2000,1,1,,,0,0,0,0,,,0,0,0,0,,,0,0,0,0,,,0,0,0,0,,,0,0,0,0,,,0,0,0,0,,,0,0,0,0,,,0,0,0,0,,,0,0,0,0,AAPL
2024-10-22 12:55:21.125435319+00:00,10,39,38,A,B,0,232.4,2000,130,203443,62456,232.4,236.4,2000,2000,1,1,232.2,,2000,0,1,0,,,0,0,0,0,,,0,0,0,0,,,0,0,0,0,,,0,0,0,0,,,0,0,0,0,,,0,0,0,0,,,0,0,0,0,,,0,0,0,0,AAPL
2024-10-22 12:55:21.126167703+00:00,10,39,38,C,B,1,232.2,2000,130,203368,62457,232.4,236.4,2000,2000,1,1,,,0,0,0,0,,,0,0,0,0,,,0,0,0,0,,,0,0,0,0,,,0,0,0,0,,,0,0,0,0,,,0,0,0,0,,,0,0,0,0,,,0,0,0,0,AAPL
2024-10-22 12:55:21.166961484+00:00,10,39,38,A,A,0,236.2,2000,130,203434,62466,232.4,236.2,2000,2000,1,1,,236.4,0,2000,0,1,,,0,0,0,0,,,0,0,0,0,,,0,0,0,0,,,0,0,0,0,,,0,0,0,0,,,0,0,0,0,,,0,0,0,0,,,0,0,0,0,AAPL
2024-10-22 12:55:21.167162346+00:00,10,39,38,C,A,1,236.4,2000,130,203404,62467,232.4,236.2,2000,2000,1,1,,,0,0,0,0,,,0,0,0,0,,,0,0,0,0,,,0,0,0,0,,,0,0,0,0,,,0,0,0,0,,,0,0,0,0,,,0,0,0,0,,,0,0,0,0,AAPL
2024-10-22 12:55:27.968451187+00:00,10,39,38,C,B,0,232.4,2000,130,203483,62516,,236.2,0,2000,0,1,,,0,0,0,0,,,0,0,0,0,,,0,0,0,0,,,0,0,0,0,,,0,0,0,0,,,0,0,0,0,,,0,0,0,0,,,0,0,0,0,,,0,0,0,0,AAPL
2024-10-22 12:55:27.979368026+00:00,10,39,38,A,B,0,232.2,2000,130,203550,62517,232.2,236.2,2000,2000,1,1,,,0,0,0,0,,,0,0,0,0,,,0,0,0,0,,,0,0,0,0,,,0,0,0,0,,,0,0,0,0,,,0,0,0,0,,,0,0,0,0,,,0,0,0,0,AAPL
2024-10-22 12:55:30.199578220+00:00,10,39,38,C,A,0,236.2,2000,130,203427,62533,232.2,,2000,0,1,0,,,0,0,0,0,,,0,0,0,0,,,0,0,0,0,,,0,0,0,0,,,0,0,0,0,,,0,0,0,0,,,0,0,0,0,,,0,0,0,0,,,0,0,0,0,AAPL
2024-10-22 12:55:30.209310260+00:00,10,39,38,A,B,0,232.4,2000,130,203493,62534,232.4,,2000,0,1,0,232.2,,2000,0,1,0,,,0,0,0,0,,,0,0,0,0,,,0,0,0,0,,,0,0,0,0,,,0,0,0,0,,,0,0,0,0,,,0,0,0,0,,,0,0,0,0,AAPL
2024-10-22 12:55:30.209510852+00:00,10,39,38,C,B,1,232.2,2000,130,203410,62535,232.4,,2000,0,1,0,,,0,0,0,0,,,0,0,0,0,,,0,0,0,0,,,0,0,0,0,,,0,0,0,0,,,0,0,0,0,,,0,0,0,0,,,0,0,0,0,,,0,0,0,0,AAPL
2024-10-22 12:55:30.226994117+00:00,10,39,38,A,A,0,236.2,2000,130,203488,62536,232.4,236.2,2000,2000,1,1,,,0,0,0,0,,,0,0,0,0,,,0,0,0,0,,,0,0,0,0,,,0,0,0,0,,,0,0,0,0,,,0,0,0,0,,,0,0,0,0,,,0,0,0,0,AAPL
2024-10-22 12:55:30.237511621+00:00,10,39,38,C,B,0,232.4,2000,130,203441,62537,,236.2,0,2000,0,1,,,0,0,0,0,,,0,0,0,0,,,0,0,0,0,,,0,0,0,0,,,0,0,0,0,,,0,0,0,0,,,0,0,0,0,,,0,0,0,0,,,0,0,0,0,AAPL
2024-10-22 12:55:30.248429541+00:00,10,39,38,A,B,0,232.2,2000,130,203502,62538,232.2,236.2,2000,2000,1,1,,,0,0,0,0,,,0,0,0,0,,,0,0,0,0,,,0,0,0,0,,,0,0,0,0,,,0,0,0,0,,,0,0,0,0,,,0,0,0,0,,,0,0,0,0,AAPL
2024-10-22 12:55:30.261489763+00:00,10,39,38,C,B,0,232.2,2000,130,203735,62539,,236.2,0,2000,0,1,,,0,0,0,0,,,0,0,0,0,,,0,0,0,0,,,0,0,0,0,,,0,0,0,0,,,0,0,0,0,,,0,0,0,0,,,0,0,0,0,,,0,0,0,0,AAPL
2024-10-22 12:55:30.275267657+00:00,10,39,38,A,B,0,232.0,2000,130,203443,62540,232.0,236.2,2000,2000,1,1,,,0,0,0,0,,,0,0,0,0,,,0,0,0,0,,,0,0,0,0,,,0,0,0,0,,,0,0,0,0,,,0,0,0,0,,,0,0,0,0,,,0,0,0,0,AAPL
2024-10-22 12:55:31.461170007+00:00,10,39,38,C,A,0,236.2,2000,130,203991,62556,232.0,,2000,0,1,0,,,0,0,0,0,,,0,0,0,0,,,0,0,0,0,,,0,0,0,0,,,0,0,0,0,,,0,0,0,0,,,0,0,0,0,,,0,0,0,0,,,0,0,0,0,AAPL
2024-10-22 12:55:31.471748516+00:00,10,39,38,A,B,0,232.4,2000,130,203564,62557,232.4,,2000,0,1,0,232.0,,2000,0,1,0,,,0,0,0,0,,,0,0,0,0,,,0,0,0,0,,,0,0,0,0,,,0,0,0,0,,,0,0,0,0,,,0,0,0,0,,,0,0,0,0,AAPL
2024-10-22 12:55:31.471943482+00:00,10,39,38,C,B,1,232.0,2000,130,203643,62558,232.4,,2000,0,1,0,,,0,0,0,0,,,0,0,0,0,,,0,0,0,0,,,0,0,0,0,,,0,0,0,0,,,0,0,0,0,,,0,0,0,0,,,0,0,0,0,,,0,0,0,0,AAPL
2024-10-22 12:55:31.486149499+00:00,10,39,38,A,A,0,236.4,2000,130,203600,62559,232.4,236.4,2000,2000,1,1,,,0,0,0,0,,,0,0,0,0,,,0,0,0,0,,,0,0,0,0,,,0,0,0,0,,,0,0,0,0,,,0,0,0,0,,,0,0,0,0,,,0,0,0,0,AAPL
2024-10-22 12:55:40.984585702+00:00,10,39,38,A,A,0,236.0,2000,130,204139,62625,232.4,236.0,2000,2000,1,1,,236.4,0,2000,0,1,,,0,0,0,0,,,0,0,0,0,,,0,0,0,0,,,0,0,0,0,,,0,0,0,0,,,0,0,0,0,,,0,0,0,0,,,0,0,0,0,AAPL
2024-10-22 12:55:40.984781642+00:00,10,39,38,C,A,1,236.4,2000,130,203949,62626,232.4,236.0,2000,2000,1,1,,,0,0,0,0,,,0,0,0,0,,,0,0,0,0,,,0,0,0,0,,,0,0,0,0,,,0,0,0,0,,,0,0,0,0,,,0,0,0,0,,,0,0,0,0,AAPL
2024-10-22 12:55:41.004038277+00:00,10,39,38,C,A,0,236.0,2000,130,203975,62628,232.4,,2000,0,1,0,,,0,0,0,0,,,0,0,0,0,,,0,0,0,0,,,0,0,0,0,,,0,0,0,0,,,0,0,0,0,,,0,0,0,0,,,0,0,0,0,,,0,0,0,0,AAPL
2024-10-22 12:55:41.015525468+00:00,10,39,38,A,A,0,236.2,2000,130,204034,62629,232.4,236.2,2000,2000,1,1,,,0,0,0,0,,,0,0,0,0,,,0,0,0,0,,,0,0,0,0,,,0,0,0,0,,,0,0,0,0,,,0,0,0,0,,,0,0,0,0,,,0,0,0,0,AAPL
2024-10-22 12:55:42.044374272+00:00,10,39,38,C,A,0,236.2,2000,130,204092,62631,232.4,,2000,0,1,0,,,0,0,0,0,,,0,0,0,0,,,0,0,0,0,,,0,0,0,0,,,0,0,0,0,,,0,0,0,0,,,0,0,0,0,,,0,0,0,0,,,0,0,0,0,AAPL
2024-10-22 12:55:42.054911052+00:00,10,39,38,A,A,0,236.0,2000,130,203959,62633,232.4,236.0,2000,2000,1,1,,,0,0,0,0,,,0,0,0,0,,,0,0,0,0,,,0,0,0,0,,,0,0,0,0,,,0,0,0,0,,,0,0,0,0,,,0,0,0,0,,,0,0,0,0,AAPL
2024-10-22 12:55:46.784220169+00:00,10,39,38,A,B,0,232.6,2000,130,203876,62660,232.6,236.0,2000,2000,1,1,232.4,,2000,0,1,0,,,0,0,0,0,,,0,0,0,0,,,0,0,0,0,,,0,0,0,0,,,0,0,0,0,,,0,0,0,0,,,0,0,0,0,,,0,0,0,0,AAPL
2024-10-22 12:55:46.784418207+00:00,10,39,38,C,B,1,232.4,2000,130,203883,62661,232.6,236.0,2000,2000,1,1,,,0,0,0,0,,,0,0,0,0,,,0,0,0,0,,,0,0,0,0,,,0,0,0,0,,,0,0,0,0,,,0,0,0,0,,,0,0,0,0,,,0,0,0,0,AAPL
2024-10-22 12:56:00.014470332+00:00,10,41,38,A,B,0,234.43,200,194,56458,215619,,234.43,0,200,0,0,,,0,0,0,0,,,0,0,0,0,,,0,0,0,0,,,0,0,0,0,,,0,0,0,0,,,0,0,0,0,,,0,0,0,0,,,0,0,0,0,,,0,0,0,0,AAPL
2024-10-22 12:56:00.014491359+00:00,10,41,38,A,B,0,234.43,200,194,54279,215620,233.84,234.43,200,200,0,0,,,0,0,0,0,,,0,0,0,0,,,0,0,0,0,,,0,0,0,0,,,0,0,0,0,,,0,0,0,0,,,0,0,0,0,,,0,0,0,0,,,0,0,0,0,AAPL
2024-10-22 12:56:00.063583152+00:00,10,40,38,A,B,0,234.49,200,194,203968,101797,,234.49,0,200,0,0,,,0,0,0,0,,,0,0,0,0,,,0,0,0,0,,,0,0,0,0,,,0,0,0,0,,,0,0,0,0,,,0,0,0,0,,,0,0,0,0,,,0,0,0,0,AAPL
2024-10-22 12:56:00.659787929+00:00,10,40,38,A,B,0,234.49,200,194,203962,101861,233.78,234.49,200,200,0,0,,,0,0,0,0,,,0,0,0,0,,,0,0,0,0,,,0,0,0,0,,,0,0,0,0,,,0,0,0,0,,,0,0,0,0,,,0,0,0,0,,,0,0,0,0,AAPL
2024-10-22 12:56:35.288993350+00:00,10,39,38,C,A,0,236.0,2000,130,203647,62961,232.6,,2000,0,1,0,,,0,0,0,0,,,0,0,0,0,,,0,0,0,0,,,0,0,0,0,,,0,0,0,0,,,0,0,0,0,,,0,0,0,0,,,0,0,0,0,,,0,0,0,0,AAPL
2024-10-22 12:56:35.987975820+00:00,10,39,10888,A,B,0,418.51,100,130,203701,92546,418.51,,100,0,1,0,,,0,0,0,0,,,0,0,0,0,,,0,0,0,0,,,0,0,0,0,,,0,0,0,0,,,0,0,0,0,,,0,0,0,0,,,0,0,0,0,,,0,0,0,0,MSFT
2024-10-22 12:56:39.676549884+00:00,10,39,38,A,A,0,236.2,2000,130,203824,62996,232.6,236.2,2000,2000,1,1,,,0,0,0,0,,,0,0,0,0,,,0,0,0,0,,,0,0,0,0,,,0,0,0,0,,,0,0,0,0,,,0,0,0,0,,,0,0,0,0,,,0,0,0,0,AAPL
2024-10-22 12:56:39.941496915+00:00,10,39,38,C,A,0,236.2,2000,130,203653,62999,232.6,,2000,0,1,0,,,0,0,0,0,,,0,0,0,0,,,0,0,0,0,,,0,0,0,0,,,0,0,0,0,,,0,0,0,0,,,0,0,0,0,,,0,0,0,0,,,0,0,0,0,AAPL
2024-10-22 12:56:39.964288401+00:00,10,39,38,A,A,0,236.4,2000,130,203616,63000,232.6,236.4,2000,2000,1,1,,,0,0,0,0,,,0,0,0,0,,,0,0,0,0,,,0,0,0,0,,,0,0,0,0,,,0,0,0,0,,,0,0,0,0,,,0,0,0,0,,,0,0,0,0,AAPL
2024-10-22 12:56:39.984130281+00:00,10,39,38,C,A,0,236.4,2000,130,203589,63001,232.6,,2000,0,1,0,,,0,0,0,0,,,0,0,0,0,,,0,0,0,0,,,0,0,0,0,,,0,0,0,0,,,0,0,0,0,,,0,0,0,0,,,0,0,0,0,,,0,0,0,0,AAPL
2024-10-22 12:56:39.994989832+00:00,10,39,38,A,A,0,236.6,2000,130,203628,63002,232.6,236.6,2000,2000,1,1,,,0,0,0,0,,,0,0,0,0,,,0,0,0,0,,,0,0,0,0,,,0,0,0,0,,,0,0,0,0,,,0,0,0,0,,,0,0,0,0,,,0,0,0,0,AAPL
2024-10-22 12:56:40.044497153+00:00,10,39,38,A,A,0,236.4,2000,130,203585,63006,232.6,236.4,2000,2000,1,1,,236.6,0,2000,0,1,,,0,0,0,0,,,0,0,0,0,,,0,0,0,0,,,0,0,0,0,,,0,0,0,0,,,0,0,0,0,,,0,0,0,0,,,0,0,0,0,AAPL
2024-10-22 12:56:40.044940377+00:00,10,39,38,C,A,1,236.6,2000,130,203543,63007,232.6,236.4,2000,2000,1,1,,,0,0,0,0,,,0,0,0,0,,,0,0,0,0,,,0,0,0,0,,,0,0,0,0,,,0,0,0,0,,,0,0,0,0,,,0,0,0,0,,,0,0,0,0,AAPL
2024-10-22 12:56:47.731077302+00:00,10,41,38,A,A,0,,0,194,56354,218023,233.84,,200,0,0,0,,,0,0,0,0,,,0,0,0,0,,,0,0,0,0,,,0,0,0,0,,,0,0,0,0,,,0,0,0,0,,,0,0,0,0,,,0,0,0,0,,,0,0,0,0,AAPL
2024-10-22 12:56:47.731115925+00:00,10,41,38,A,A,0,234.53,200,194,54494,218024,233.84,234.53,200,200,0,0,,,0,0,0,0,,,0,0,0,0,,,0,0,0,0,,,0,0,0,0,,,0,0,0,0,,,0,0,0,0,,,0,0,0,0,,,0,0,0,0,,,0,0,0,0,AAPL
2024-10-22 12:56:48.092736603+00:00,10,39,38,A,A,0,236.2,2000,130,203657,63041,232.6,236.2,2000,2000,1,1,,236.4,0,2000,0,1,,,0,0,0,0,,,0,0,0,0,,,0,0,0,0,,,0,0,0,0,,,0,0,0,0,,,0,0,0,0,,,0,0,0,0,,,0,0,0,0,AAPL
2024-10-22 12:56:48.092940488+00:00,10,39,38,C,A,1,236.4,2000,130,203437,63042,232.6,236.2,2000,2000,1,1,,,0,0,0,0,,,0,0,0,0,,,0,0,0,0,,,0,0,0,0,,,0,0,0,0,,,0,0,0,0,,,0,0,0,0,,,0,0,0,0,,,0,0,0,0,AAPL
2024-10-22 12:56:49.090215461+00:00,10,39,38,C,B,0,232.6,2000,130,203313,63048,,236.2,0,2000,0,1,,,0,0,0,0,,,0,0,0,0,,,0,0,0,0,,,0,0,0,0,,,0,0,0,0,,,0,0,0,0,,,0,0,0,0,,,0,0,0,0,,,0,0,0,0,AAPL
2024-10-22 12:56:49.102138333+00:00,10,39,38,A,B,0,232.4,2000,130,203319,63049,232.4,236.2,2000,2000,1,1,,,0,0,0,0,,,0,0,0,0,,,0,0,0,0,,,0,0,0,0,,,0,0,0,0,,,0,0,0,0,,,0,0,0,0,,,0,0,0,0,,,0,0,0,0,AAPL
2024-10-22 12:56:49.107156795+00:00,10,39,10888,C,B,0,418.51,100,130,203360,92670,,,0,0,0,0,,,0,0,0,0,,,0,0,0,0,,,0,0,0,0,,,0,0,0,0,,,0,0,0,0,,,0,0,0,0,,,0,0,0,0,,,0,0,0,0,,,0,0,0,0,MSFT
2024-10-22 12:56:50.236789307+00:00,10,39,38,C,B,0,232.4,2000,130,203675,63055,,236.2,0,2000,0,1,,,0,0,0,0,,,0,0,0,0,,,0,0,0,0,,,0,0,0,0,,,0,0,0,0,,,0,0,0,0,,,0,0,0,0,,,0,0,0,0,,,0,0,0,0,AAPL
2024-10-22 12:56:50.249467933+00:00,10,39,38,A,B,0,232.4,2000,130,203450,63056,232.4,236.2,2000,2000,1,1,,,0,0,0,0,,,0,0,0,0,,,0,0,0,0,,,0,0,0,0,,,0,0,0,0,,,0,0,0,0,,,0,0,0,0,,,0,0,0,0,,,0,0,0,0,AAPL
2024-10-22 12:56:52.212991390+00:00,10,39,38,C,B,0,232.4,2000,130,204525,63061,,236.2,0,2000,0,1,,,0,0,0,0,,,0,0,0,0,,,0,0,0,0,,,0,0,0,0,,,0,0,0,0,,,0,0,0,0,,,0,0,0,0,,,0,0,0,0,,,0,0,0,0,AAPL
2024-10-22 12:56:52.225032908+00:00,10,39,38,A,B,0,232.2,2000,130,203386,63062,232.2,236.2,2000,2000,1,1,,,0,0,0,0,,,0,0,0,0,,,0,0,0,0,,,0,0,0,0,,,0,0,0,0,,,0,0,0,0,,,0,0,0,0,,,0,0,0,0,,,0,0,0,0,AAPL
2024-10-22 12:56:54.913604825+00:00,10,39,38,A,B,0,232.6,2000,130,203489,63083,232.6,236.2,2000,2000,1,1,232.2,,2000,0,1,0,,,0,0,0,0,,,0,0,0,0,,,0,0,0,0,,,0,0,0,0,,,0,0,0,0,,,0,0,0,0,,,0,0,0,0,,,0,0,0,0,AAPL
2024-10-22 12:56:54.913799701+00:00,10,39,38,C,B,1,232.2,2000,130,203081,63084,232.6,236.2,2000,2000,1,1,,,0,0,0,0,,,0,0,0,0,,,0,0,0,0,,,0,0,0,0,,,0,0,0,0,,,0,0,0,0,,,0,0,0,0,,,0,0,0,0,,,0,0,0,0,AAPL
2024-10-22 12:56:55.210277029+00:00,10,39,38,C,A,0,236.2,2000,130,203300,63086,232.6,,2000,0,1,0,,,0,0,0,0,,,0,0,0,0,,,0,0,0,0,,,0,0,0,0,,,0,0,0,0,,,0,0,0,0,,,0,0,0,0,,,0,0,0,0,,,0,0,0,0,AAPL
2024-10-22 12:56:55.222550747+00:00,10,39,38,A,A,0,236.4,2000,130,203120,63087,232.6,236.4,2000,2000,1,1,,,0,0,0,0,,,0,0,0,0,,,0,0,0,0,,,0,0,0,0,,,0,0,0,0,,,0,0,0,0,,,0,0,0,0,,,0,0,0,0,,,0,0,0,0,AAPL
2024-10-22 12:56:56.380796091+00:00,10,39,38,C,A,0,236.4,2000,130,203140,63103,232.6,,2000,0,1,0,,,0,0,0,0,,,0,0,0,0,,,0,0,0,0,,,0,0,0,0,,,0,0,0,0,,,0,0,0,0,,,0,0,0,0,,,0,0,0,0,,,0,0,0,0,AAPL
2024-10-22 12:56:56.417463752+00:00,10,39,38,A,A,0,236.2,2000,130,203187,63104,232.6,236.2,2000,2000,1,1,,,0,0,0,0,,,0,0,0,0,,,0,0,0,0,,,0,0,0,0,,,0,0,0,0,,,0,0,0,0,,,0,0,0,0,,,0,0,0,0,,,0,0,0,0,AAPL
2024-10-22 12:56:56.432295381+00:00,10,39,38,C,A,0,236.2,2000,130,203141,63105,232.6,,2000,0,1,0,,,0,0,0,0,,,0,0,0,0,,,0,0,0,0,,,0,0,0,0,,,0,0,0,0,,,0,0,0,0,,,0,0,0,0,,,0,0,0,0,,,0,0,0,0,AAPL
2024-10-22 12:56:56.448290021+00:00,10,39,38,A,A,0,236.2,2000,130,203042,63106,232.6,236.2,2000,2000,1,1,,,0,0,0,0,,,0,0,0,0,,,0,0,0,0,,,0,0,0,0,,,0,0,0,0,,,0,0,0,0,,,0,0,0,0,,,0,0,0,0,,,0,0,0,0,AAPL
2024-10-22 12:56:56.718253734+00:00,10,40,38,A,B,0,234.49,200,194,202812,102534,,234.49,0,200,0,0,,,0,0,0,0,,,0,0,0,0,,,0,0,0,0,,,0,0,0,0,,,0,0,0,0,,,0,0,0,0,,,0,0,0,0,,,0,0,0,0,,,0,0,0,0,AAPL
2024-10-22 12:56:56.718274126+00:00,10,40,38,A,B,0,234.49,200,194,202591,102535,233.92,234.49,200,200,0,0,,,0,0,0,0,,,0,0,0,0,,,0,0,0,0,,,0,0,0,0,,,0,0,0,0,,,0,0,0,0,,,0,0,0,0,,,0,0,0,0,,,0,0,0,0,AAPL
2024-10-22 12:56:56.718474779+00:00,10,41,38,A,B,0,234.53,200,194,56501,218268,,234.53,0,200,0,0,,,0,0,0,0,,,0,0,0,0,,,0,0,0,0,,,0,0,0,0,,,0,0,0,0,,,0,0,0,0,,,0,0,0,0,,,0,0,0,0,,,0,0,0,0,AAPL
2024-10-22 12:56:56.718514031+00:00,10,41,38,A,B,0,234.53,200,194,55447,218269,233.97,234.53,200,200,0,0,,,0,0,0,0,,,0,0,0,0,,,0,0,0,0,,,0,0,0,0,,,0,0,0,0,,,0,0,0,0,,,0,0,0,0,,,0,0,0,0,,,0,0,0,0,AAPL
2024-10-22 12:56:56.995818870+00:00,10,39,38,C,B,0,232.6,2000,130,203147,63107,,236.2,0,2000,0,1,,,0,0,0,0,,,0,0,0,0,,,0,0,0,0,,,0,0,0,0,,,0,0,0,0,,,0,0,0,0,,,0,0,0,0,,,0,0,0,0,,,0,0,0,0,AAPL
2024-10-22 12:56:57.007512042+00:00,10,39,38,A,B,0,232.4,2000,130,203168,63109,232.4,236.2,2000,2000,1,1,,,0,0,0,0,,,0,0,0,0,,,0,0,0,0,,,0,0,0,0,,,0,0,0,0,,,0,0,0,0,,,0,0,0,0,,,0,0,0,0,,,0,0,0,0,AAPL
2024-10-22 12:56:58.261701005+00:00,10,40,38,A,A,0,,0,194,202609,102564,233.92,,200,0,0,0,,,0,0,0,0,,,0,0,0,0,,,0,0,0,0,,,0,0,0,0,,,0,0,0,0,,,0,0,0,0,,,0,0,0,0,,,0,0,0,0,,,0,0,0,0,AAPL
2024-10-22 12:56:58.261730092+00:00,10,40,38,A,A,0,234.6,200,194,202580,102565,233.92,234.6,200,200,0,0,,,0,0,0,0,,,0,0,0,0,,,0,0,0,0,,,0,0,0,0,,,0,0,0,0,,,0,0,0,0,,,0,0,0,0,,,0,0,0,0,,,0,0,0,0,AAPL
2024-10-22 12:56:58.314478190+00:00,10,39,38,A,B,0,232.6,2000,130,203512,63113,232.6,236.2,2000,2000,1,1,232.4,,2000,0,1,0,,,0,0,0,0,,,0,0,0,0,,,0,0,0,0,,,0,0,0,0,,,0,0,0,0,,,0,0,0,0,,,0,0,0,0,,,0,0,0,0,AAPL
2024-10-22 12:56:58.315230905+00:00,10,39,38,C,B,1,232.4,2000,130,202946,63114,232.6,236.2,2000,2000,1,1,,,0,0,0,0,,,0,0,0,0,,,0,0,0,0,,,0,0,0,0,,,0,0,0,0,,,0,0,0,0,,,0,0,0,0,,,0,0,0,0,,,0,0,0,0,AAPL
2024-10-22 12:56:58.354902577+00:00,10,39,38,C,A,0,236.2,2000,130,203264,63115,232.6,,2000,0,1,0,,,0,0,0,0,,,0,0,0,0,,,0,0,0,0,,,0,0,0,0,,,0,0,0,0,,,0,0,0,0,,,0,0,0,0,,,0,0,0,0,,,0,0,0,0,AAPL
2024-10-22 12:56:58.366369429+00:00,10,39,38,A,A,0,236.2,2000,130,203118,63116,232.6,236.2,2000,2000,1,1,,,0,0,0,0,,,0,0,0,0,,,0,0,0,0,,,0,0,0,0,,,0,0,0,0,,,0,0,0,0,,,0,0,0,0,,,0,0,0,0,,,0,0,0,0,AAPL
2024-10-22 12:57:00.015571335+00:00,10,40,38,A,B,0,234.6,200,194,202576,102605,,234.6,0,200,0,0,,,0,0,0,0,,,0,0,0,0,,,0,0,0,0,,,0,0,0,0,,,0,0,0,0,,,0,0,0,0,,,0,0,0,0,,,0,0,0,0,,,0,0,0,0,AAPL
2024-10-22 12:57:00.015726158+00:00,10,41,38,A,B,0,234.53,200,194,56020,218429,,234.53,0,200,0,0,,,0,0,0,0,,,0,0,0,0,,,0,0,0,0,,,0,0,0,0,,,0,0,0,0,,,0,0,0,0,,,0,0,0,0,,,0,0,0,0,,,0,0,0,0,AAPL
2024-10-22 12:57:00.016497844+00:00,10,39,38,C,A,0,236.2,2000,130,203534,63125,232.6,,2000,0,1,0,,,0,0,0,0,,,0,0,0,0,,,0,0,0,0,,,0,0,0,0,,,0,0,0,0,,,0,0,0,0,,,0,0,0,0,,,0,0,0,0,,,0,0,0,0,AAPL
2024-10-22 12:57:00.027791113+00:00,10,39,38,A,A,0,236.4,2000,130,203091,63126,232.6,236.4,2000,2000,1,1,,,0,0,0,0,,,0,0,0,0,,,0,0,0,0,,,0,0,0,0,,,0,0,0,0,,,0,0,0,0,,,0,0,0,0,,,0,0,0,0,,,0,0,0,0,AAPL
2024-10-22 12:57:00.116762472+00:00,10,40,38,A,B,0,234.6,200,194,202538,102661,233.92,234.6,200,200,0,0,,,0,0,0,0,,,0,0,0,0,,,0,0,0,0,,,0,0,0,0,,,0,0,0,0,,,0,0,0,0,,,0,0,0,0,,,0,0,0,0,,,0,0,0,0,AAPL
2024-10-22 12:57:00.277619447+00:00,10,41,38,A,B,0,234.53,200,194,56626,218761,233.97,234.53,200,200,0,0,,,0,0,0,0,,,0,0,0,0,,,0,0,0,0,,,0,0,0,0,,,0,0,0,0,,,0,0,0,0,,,0,0,0,0,,,0,0,0,0,,,0,0,0,0,AAPL
2024-10-22 12:57:04.529383693+00:00,10,39,38,A,A,0,236.2,2000,130,203374,63177,232.6,236.2,2000,2000,1,1,,236.4,0,2000,0,1,,,0,0,0,0,,,0,0,0,0,,,0,0,0,0,,,0,0,0,0,,,0,0,0,0,,,0,0,0,0,,,0,0,0,0,,,0,0,0,0,AAPL
2024-10-22 12:57:04.529585791+00:00,10,39,38,C,A,1,236.4,2000,130,203182,63178,232.6,236.2,2000,2000,1,1,,,0,0,0,0,,,0,0,0,0,,,0,0,0,0,,,0,0,0,0,,,0,0,0,0,,,0,0,0,0,,,0,0,0,0,,,0,0,0,0,,,0,0,0,0,AAPL
2024-10-22 12:57:04.582564526+00:00,10,40,38,A,B,0,234.6,200,194,202690,102746,,234.6,0,200,0,0,,,0,0,0,0,,,0,0,0,0,,,0,0,0,0,,,0,0,0,0,,,0,0,0,0,,,0,0,0,0,,,0,0,0,0,,,0,0,0,0,,,0,0,0,0,AAPL
2024-10-22 12:57:04.582594039+00:00,10,40,38,A,B,0,234.6,200,194,202754,102747,233.95,234.6,200,200,0,0,,,0,0,0,0,,,0,0,0,0,,,0,0,0,0,,,0,0,0,0,,,0,0,0,0,,,0,0,0,0,,,0,0,0,0,,,0,0,0,0,,,0,0,0,0,AAPL
2024-10-22 12:57:04.582658415+00:00,10,39,38,C,A,0,236.2,2000,130,202941,63179,232.6,,2000,0,1,0,,,0,0,0,0,,,0,0,0,0,,,0,0,0,0,,,0,0,0,0,,,0,0,0,0,,,0,0,0,0,,,0,0,0,0,,,0,0,0,0,,,0,0,0,0,AAPL
2024-10-22 12:57:04.593537521+00:00,10,39,38,A,A,0,236.4,2000,130,203009,63180,232.6,236.4,2000,2000,1,1,,,0,0,0,0,,,0,0,0,0,,,0,0,0,0,,,0,0,0,0,,,0,0,0,0,,,0,0,0,0,,,0,0,0,0,,,0,0,0,0,,,0,0,0,0,AAPL
2024-10-22 12:57:07.675368131+00:00,10,39,38,C,A,0,236.4,2000,130,203211,63204,232.6,,2000,0,1,0,,,0,0,0,0,,,0,0,0,0,,,0,0,0,0,,,0,0,0,0,,,0,0,0,0,,,0,0,0,0,,,0,0,0,0,,,0,0,0,0,,,0,0,0,0,AAPL
2024-10-22 12:57:11.293240701+00:00,10,40,38,A,B,0,234.6,200,194,202390,102877,,234.6,0,200,0,0,,,0,0,0,0,,,0,0,0,0,,,0,0,0,0,,,0,0,0,0,,,0,0,0,0,,,0,0,0,0,,,0,0,0,0,,,0,0,0,0,,,0,0,0,0,AAPL
2024-10-22 12:57:11.794208833+00:00,10,41,38,A,B,0,234.53,200,194,55899,219421,,234.53,0,200,0,0,,,0,0,0,0,,,0,0,0,0,,,0,0,0,0,,,0,0,0,0,,,0,0,0,0,,,0,0,0,0,,,0,0,0,0,,,0,0,0,0,,,0,0,0,0,AAPL
2024-10-22 12:57:13.237656351+00:00,10,40,38,A,B,0,234.6,200,194,202390,102908,233.97,234.6,200,200,0,0,,,0,0,0,0,,,0,0,0,0,,,0,0,0,0,,,0,0,0,0,,,0,0,0,0,,,0,0,0,0,,,0,0,0,0,,,0,0,0,0,,,0,0,0,0,AAPL
2024-10-22 12:57:13.237924442+00:00,10,41,38,A,B,0,234.53,200,194,55373,219496,234.02,234.53,200,200,0,0,,,0,0,0,0,,,0,0,0,0,,,0,0,0,0,,,0,0,0,0,,,0,0,0,0,,,0,0,0,0,,,0,0,0,0,,,0,0,0,0,,,0,0,0,0,AAPL
2024-10-22 12:57:13.251347759+00:00,10,39,38,A,A,0,236.6,2000,130,202881,63247,232.6,236.6,2000,2000,1,1,,,0,0,0,0,,,0,0,0,0,,,0,0,0,0,,,0,0,0,0,,,0,0,0,0,,,0,0,0,0,,,0,0,0,0,,,0,0,0,0,,,0,0,0,0,AAPL
2024-10-22 12:57:13.301119089+00:00,10,39,38,C,B,0,232.6,2000,130,202865,63248,,236.6,0,2000,0,1,,,0,0,0,0,,,0,0,0,0,,,0,0,0,0,,,0,0,0,0,,,0,0,0,0,,,0,0,0,0,,,0,0,0,0,,,0,0,0,0,,,0,0,0,0,AAPL
2024-10-22 12:57:13.312768397+00:00,10,39,38,A,B,0,232.4,2000,130,202754,63249,232.4,236.6,2000,2000,1,1,,,0,0,0,0,,,0,0,0,0,,,0,0,0,0,,,0,0,0,0,,,0,0,0,0,,,0,0,0,0,,,0,0,0,0,,,0,0,0,0,,,0,0,0,0,AAPL
2024-10-22 12:57:13.475438367+00:00,10,41,38,A,B,0,234.53,200,194,55928,219503,,234.53,0,200,0,0,,,0,0,0,0,,,0,0,0,0,,,0,0,0,0,,,0,0,0,0,,,0,0,0,0,,,0,0,0,0,,,0,0,0,0,,,0,0,0,0,,,0,0,0,0,AAPL
2024-10-22 12:57:13.475420871+00:00,10,39,38,A,B,0,232.6,2000,130,203021,63250,232.6,236.6,2000,2000,1,1,232.4,,2000,0,1,0,,,0,0,0,0,,,0,0,0,0,,,0,0,0,0,,,0,0,0,0,,,0,0,0,0,,,0,0,0,0,,,0,0,0,0,,,0,0,0,0,AAPL
2024-10-22 12:57:13.475650144+00:00,10,39,38,C,B,1,232.4,2000,130,202800,63251,232.6,236.6,2000,2000,1,1,,,0,0,0,0,,,0,0,0,0,,,0,0,0,0,,,0,0,0,0,,,0,0,0,0,,,0,0,0,0,,,0,0,0,0,,,0,0,0,0,,,0,0,0,0,AAPL
2024-10-22 12:57:14.472736908+00:00,10,41,38,A,B,0,234.53,200,194,60985,219545,234.02,234.53,200,200,0,0,,,0,0,0,0,,,0,0,0,0,,,0,0,0,0,,,0,0,0,0,,,0,0,0,0,,,0,0,0,0,,,0,0,0,0,,,0,0,0,0,,,0,0,0,0,AAPL
2024-10-22 12:57:14.661600942+00:00,10,41,38,A,B,0,234.53,200,194,55466,219548,,234.53,0,200,0,0,,,0,0,0,0,,,0,0,0,0,,,0,0,0,0,,,0,0,0,0,,,0,0,0,0,,,0,0,0,0,,,0,0,0,0,,,0,0,0,0,,,0,0,0,0,AAPL
2024-10-22 12:57:14.776900206+00:00,10,41,38,A,A,0,,0,194,60353,219549,,,0,0,0,0,,,0,0,0,0,,,0,0,0,0,,,0,0,0,0,,,0,0,0,0,,,0,0,0,0,,,0,0,0,0,,,0,0,0,0,,,0,0,0,0,,,0,0,0,0,AAPL
2024-10-22 12:57:14.776941425+00:00,10,41,38,A,A,0,234.63,200,194,54559,219550,,234.63,0,200,0,0,,,0,0,0,0,,,0,0,0,0,,,0,0,0,0,,,0,0,0,0,,,0,0,0,0,,,0,0,0,0,,,0,0,0,0,,,0,0,0,0,,,0,0,0,0,AAPL
2024-10-22 12:57:15.239276646+00:00,10,41,38,A,B,0,234.63,200,194,55490,219564,234.02,234.63,200,200,0,0,,,0,0,0,0,,,0,0,0,0,,,0,0,0,0,,,0,0,0,0,,,0,0,0,0,,,0,0,0,0,,,0,0,0,0,,,0,0,0,0,,,0,0,0,0,AAPL
2024-10-22 12:57:15.276786295+00:00,10,39,38,A,A,0,236.4,2000,130,203330,63288,232.6,236.4,2000,2000,1,1,,236.6,0,2000,0,1,,,0,0,0,0,,,0,0,0,0,,,0,0,0,0,,,0,0,0,0,,,0,0,0,0,,,0,0,0,0,,,0,0,0,0,,,0,0,0,0,AAPL
2024-10-22 12:57:15.276980982+00:00,10,39,38,C,A,1,236.6,2000,130,203027,63289,232.6,236.4,2000,2000,1,1,,,0,0,0,0,,,0,0,0,0,,,0,0,0,0,,,0,0,0,0,,,0,0,0,0,,,0,0,0,0,,,0,0,0,0,,,0,0,0,0,,,0,0,0,0,AAPL
2024-10-22 12:57:15.303459305+00:00,10,39,38,C,A,0,236.4,2000,130,203075,63290,232.6,,2000,0,1,0,,,0,0,0,0,,,0,0,0,0,,,0,0,0,0,,,0,0,0,0,,,0,0,0,0,,,0,0,0,0,,,0,0,0,0,,,0,0,0,0,,,0,0,0,0,AAPL
2024-10-22 12:57:15.314146122+00:00,10,39,38,A,A,0,236.6,2000,130,203093,63291,232.6,236.6,2000,2000,1,1,,,0,0,0,0,,,0,0,0,0,,,0,0,0,0,,,0,0,0,0,,,0,0,0,0,,,0,0,0,0,,,0,0,0,0,,,0,0,0,0,,,0,0,0,0,AAPL
2024-10-22 12:57:15.655269913+00:00,10,41,38,A,B,0,234.63,200,194,56682,219572,,234.63,0,200,0,0,,,0,0,0,0,,,0,0,0,0,,,0,0,0,0,,,0,0,0,0,,,0,0,0,0,,,0,0,0,0,,,0,0,0,0,,,0,0,0,0,,,0,0,0,0,AAPL
2024-10-22 12:57:20.214151474+00:00,10,41,38,A,B,0,234.63,200,194,58376,219742,234.02,234.63,200,200,0,0,,,0,0,0,0,,,0,0,0,0,,,0,0,0,0,,,0,0,0,0,,,0,0,0,0,,,0,0,0,0,,,0,0,0,0,,,0,0,0,0,,,0,0,0,0,AAPL
2024-10-22 12:57:20.376906649+00:00,10,41,38,A,B,0,234.63,200,194,55134,219746,,234.63,0,200,0,0,,,0,0,0,0,,,0,0,0,0,,,0,0,0,0,,,0,0,0,0,,,0,0,0,0,,,0,0,0,0,,,0,0,0,0,,,0,0,0,0,,,0,0,0,0,AAPL
2024-10-22 12:57:21.682855664+00:00,10,39,38,A,A,0,236.4,2000,130,203415,63342,232.6,236.4,2000,2000,1,1,,236.6,0,2000,0,1,,,0,0,0,0,,,0,0,0,0,,,0,0,0,0,,,0,0,0,0,,,0,0,0,0,,,0,0,0,0,,,0,0,0,0,,,0,0,0,0,AAPL
2024-10-22 12:57:21.683043472+00:00,10,39,38,C,A,1,236.6,2000,130,203093,63343,232.6,236.4,2000,2000,1,1,,,0,0,0,0,,,0,0,0,0,,,0,0,0,0,,,0,0,0,0,,,0,0,0,0,,,0,0,0,0,,,0,0,0,0,,,0,0,0,0,,,0,0,0,0,AAPL
2024-10-22 12:57:21.956502379+00:00,10,39,38,A,A,0,236.2,2000,130,203512,63344,232.6,236.2,2000,2000,1,1,,236.4,0,2000,0,1,,,0,0,0,0,,,0,0,0,0,,,0,0,0,0,,,0,0,0,0,,,0,0,0,0,,,0,0,0,0,,,0,0,0,0,,,0,0,0,0,AAPL
2024-10-22 12:57:21.956698947+00:00,10,39,38,C,A,1,236.4,2000,130,203001,63345,232.6,236.2,2000,2000,1,1,,,0,0,0,0,,,0,0,0,0,,,0,0,0,0,,,0,0,0,0,,,0,0,0,0,,,0,0,0,0,,,0,0,0,0,,,0,0,0,0,,,0,0,0,0,AAPL
2024-10-22 12:57:21.976456523+00:00,10,39,38,C,A,0,236.2,2000,130,203008,63346,232.6,,2000,0,1,0,,,0,0,0,0,,,0,0,0,0,,,0,0,0,0,,,0,0,0,0,,,0,0,0,0,,,0,0,0,0,,,0,0,0,0,,,0,0,0,0,,,0,0,0,0,AAPL
2024-10-22 12:57:21.987562415+00:00,10,39,38,A,A,0,236.2,2000,130,203089,63347,232.6,236.2,2000,2000,1,1,,,0,0,0,0,,,0,0,0,0,,,0,0,0,0,,,0,0,0,0,,,0,0,0,0,,,0,0,0,0,,,0,0,0,0,,,0,0,0,0,,,0,0,0,0,AAPL
