ts_event,rtype,publisher_id,instrument_id,action,side,depth,price,size,flags,ts_in_delta,sequence,bid_px_00,ask_px_00,bid_sz_00,ask_sz_00,bid_ct_00,ask_ct_00,bid_px_01,ask_px_01,bid_sz_01,ask_sz_01,bid_ct_01,ask_ct_01,bid_px_02,ask_px_02,bid_sz_02,ask_sz_02,bid_ct_02,ask_ct_02,bid_px_03,ask_px_03,bid_sz_03,ask_sz_03,bid_ct_03,ask_ct_03,bid_px_04,ask_px_04,bid_sz_04,ask_sz_04,bid_ct_04,ask_ct_04,bid_px_05,ask_px_05,bid_sz_05,ask_sz_05,bid_ct_05,ask_ct_05,bid_px_06,ask_px_06,bid_sz_06,ask_sz_06,bid_ct_06,ask_ct_06,bid_px_07,ask_px_07,bid_sz_07,ask_sz_07,bid_ct_07,ask_ct_07,bid_px_08,ask_px_08,bid_sz_08,ask_sz_08,bid_ct_08,ask_ct_08,bid_px_09,ask_px_09,bid_sz_09,ask_sz_09,bid_ct_09,ask_ct_09,symbol
2024-10-22 12:57:25.116577355+00:00,10,41,38,A,B,0,234.63,200,194,55629,219914,234.02,234.63,200,200,0,0,,,0,0,0,0,,,0,0,0,0,,,0,0,0,0,,,0,0,0,0,,,0,0,0,0,,,0,0,0,0,,,0,0,0,0,,,0,0,0,0,,,0,0,0,0,AAPL
2024-10-22 12:57:25.116930931+00:00,10,39,38,C,A,0,236.2,2000,130,203272,63378,232.6,,2000,0,1,0,,,0,0,0,0,,,0,0,0,0,,,0,0,0,0,,,0,0,0,0,,,0,0,0,0,,,0,0,0,0,,,0,0,0,0,,,0,0,0,0,,,0,0,0,0,AAPL
2024-10-22 12:57:25.153975366+00:00,10,39,38,A,A,0,236.4,2000,130,203191,63379,232.6,236.4,2000,2000,1,1,,,0,0,0,0,,,0,0,0,0,,,0,0,0,0,,,0,0,0,0,,,0,0,0,0,,,0,0,0,0,,,0,0,0,0,,,0,0,0,0,,,0,0,0,0,AAPL
2024-10-22 12:57:25.185479054+00:00,10,41,38,A,B,0,234.63,200,194,55306,219918,,234.63,0,200,0,0,,,0,0,0,0,,,0,0,0,0,,,0,0,0,0,,,0,0,0,0,,,0,0,0,0,,,0,0,0,0,,,0,0,0,0,,,0,0,0,0,,,0,0,0,0,AAPL
2024-10-22 12:57:26.385337616+00:00,10,40,38,A,A,0,,0,194,202245,103059,233.97,,200,0,0,0,,,0,0,0,0,,,0,0,0,0,,,0,0,0,0,,,0,0,0,0,,,0,0,0,0,,,0,0,0,0,,,0,0,0,0,,,0,0,0,0,,,0,0,0,0,AAPL
2024-10-22 12:57:26.385366644+00:00,10,40,38,A,A,0,234.67,200,194,202179,103060,233.97,234.67,200,200,0,0,,,0,0,0,0,,,0,0,0,0,,,0,0,0,0,,,0,0,0,0,,,0,0,0,0,,,0,0,0,0,,,0,0,0,0,,,0,0,0,0,,,0,0,0,0,AAPL
2024-10-22 12:57:27.377831121+00:00,10,40,38,A,B,0,234.67,200,194,202312,103080,,234.67,0,200,0,0,,,0,0,0,0,,,0,0,0,0,,,0,0,0,0,,,0,0,0,0,,,0,0,0,0,,,0,0,0,0,,,0,0,0,0,,,0,0,0,0,,,0,0,0,0,AAPL
2024-10-22 12:57:28.275993498+00:00,10,40,38,A,B,0,234.67,200,194,202360,103091,233.97,234.67,200,200,0,0,,,0,0,0,0,,,0,0,0,0,,,0,0,0,0,,,0,0,0,0,,,0,0,0,0,,,0,0,0,0,,,0,0,0,0,,,0,0,0,0,,,0,0,0,0,AAPL
2024-10-22 12:57:28.381645449+00:00,10,40,38,A,B,0,234.67,200,194,202297,103093,,234.67,0,200,0,0,,,0,0,0,0,,,0,0,0,0,,,0,0,0,0,,,0,0,0,0,,,0,0,0,0,,,0,0,0,0,,,0,0,0,0,,,0,0,0,0,,,0,0,0,0,AAPL
2024-10-22 12:57:29.937369129+00:00,10,39,38,A,A,0,236.2,2000,130,203347,63403,232.6,236.2,2000,2000,1,1,,236.4,0,2000,0,1,,,0,0,0,0,,,0,0,0,0,,,0,0,0,0,,,0,0,0,0,,,0,0,0,0,,,0,0,0,0,,,0,0,0,0,,,0,0,0,0,AAPL
2024-10-22 12:57:29.937555082+00:00,10,39,38,C,A,1,236.4,2000,130,203221,63404,232.6,236.2,2000,2000,1,1,,,0,0,0,0,,,0,0,0,0,,,0,0,0,0,,,0,0,0,0,,,0,0,0,0,,,0,0,0,0,,,0,0,0,0,,,0,0,0,0,,,0,0,0,0,AAPL
2024-10-22 12:57:34.250202111+00:00,10,39,38,C,A,0,236.2,2000,130,203320,63422,232.6,,2000,0,1,0,,,0,0,0,0,,,0,0,0,0,,,0,0,0,0,,,0,0,0,0,,,0,0,0,0,,,0,0,0,0,,,0,0,0,0,,,0,0,0,0,,,0,0,0,0,AAPL
2024-10-22 12:57:34.261808788+00:00,10,39,38,A,A,0,236.6,2000,130,203215,63423,232.6,236.6,2000,2000,1,1,,,0,0,0,0,,,0,0,0,0,,,0,0,0,0,,,0,0,0,0,,,0,0,0,0,,,0,0,0,0,,,0,0,0,0,,,0,0,0,0,,,0,0,0,0,AAPL
2024-10-22 12:57:38.433239798+00:00,10,40,38,A,B,0,234.67,200,194,202211,103192,233.99,234.67,200,200,0,0,,,0,0,0,0,,,0,0,0,0,,,0,0,0,0,,,0,0,0,0,,,0,0,0,0,,,0,0,0,0,,,0,0,0,0,,,0,0,0,0,,,0,0,0,0,AAPL
2024-10-22 12:57:38.433592465+00:00,10,41,38,A,B,0,234.63,200,194,60444,220399,234.04,234.63,200,200,0,0,,,0,0,0,0,,,0,0,0,0,,,0,0,0,0,,,0,0,0,0,,,0,0,0,0,,,0,0,0,0,,,0,0,0,0,,,0,0,0,0,,,0,0,0,0,AAPL
2024-10-22 12:57:38.434126440+00:00,10,41,38,A,A,0,,0,194,54653,220400,234.04,,200,0,0,0,,,0,0,0,0,,,0,0,0,0,,,0,0,0,0,,,0,0,0,0,,,0,0,0,0,,,0,0,0,0,,,0,0,0,0,,,0,0,0,0,,,0,0,0,0,AAPL
2024-10-22 12:57:38.685259722+00:00,10,41,38,A,A,0,234.62,200,194,54996,220413,234.04,234.62,200,200,0,0,,,0,0,0,0,,,0,0,0,0,,,0,0,0,0,,,0,0,0,0,,,0,0,0,0,,,0,0,0,0,,,0,0,0,0,,,0,0,0,0,,,0,0,0,0,AAPL
2024-10-22 12:57:38.727572832+00:00,10,40,38,A,B,0,234.67,200,194,202092,103193,,234.67,0,200,0,0,,,0,0,0,0,,,0,0,0,0,,,0,0,0,0,,,0,0,0,0,,,0,0,0,0,,,0,0,0,0,,,0,0,0,0,,,0,0,0,0,,,0,0,0,0,AAPL
2024-10-22 12:57:38.728141638+00:00,10,41,38,A,B,0,234.62,200,194,55201,220414,,234.62,0,200,0,0,,,0,0,0,0,,,0,0,0,0,,,0,0,0,0,,,0,0,0,0,,,0,0,0,0,,,0,0,0,0,,,0,0,0,0,,,0,0,0,0,,,0,0,0,0,AAPL
2024-10-22 12:57:38.964027119+00:00,10,41,38,A,A,0,,0,194,60116,220425,,,0,0,0,0,,,0,0,0,0,,,0,0,0,0,,,0,0,0,0,,,0,0,0,0,,,0,0,0,0,,,0,0,0,0,,,0,0,0,0,,,0,0,0,0,,,0,0,0,0,AAPL
2024-10-22 12:57:41.789302215+00:00,10,41,38,A,A,0,234.62,200,194,55758,220509,,234.62,0,200,0,0,,,0,0,0,0,,,0,0,0,0,,,0,0,0,0,,,0,0,0,0,,,0,0,0,0,,,0,0,0,0,,,0,0,0,0,,,0,0,0,0,,,0,0,0,0,AAPL
2024-10-22 12:57:46.969707275+00:00,10,39,38,A,B,0,232.8,2000,130,203870,63471,232.8,236.6,2000,2000,1,1,232.6,,2000,0,1,0,,,0,0,0,0,,,0,0,0,0,,,0,0,0,0,,,0,0,0,0,,,0,0,0,0,,,0,0,0,0,,,0,0,0,0,,,0,0,0,0,AAPL
2024-10-22 12:57:46.969995976+00:00,10,39,38,C,B,1,232.6,2000,130,203661,63472,232.8,236.6,2000,2000,1,1,,,0,0,0,0,,,0,0,0,0,,,0,0,0,0,,,0,0,0,0,,,0,0,0,0,,,0,0,0,0,,,0,0,0,0,,,0,0,0,0,,,0,0,0,0,AAPL
2024-10-22 12:57:52.240288047+00:00,10,40,38,A,B,0,234.67,200,194,202154,103379,233.99,234.67,200,200,0,0,,,0,0,0,0,,,0,0,0,0,,,0,0,0,0,,,0,0,0,0,,,0,0,0,0,,,0,0,0,0,,,0,0,0,0,,,0,0,0,0,,,0,0,0,0,AAPL
2024-10-22 12:57:52.240567115+00:00,10,41,38,A,B,0,234.62,200,194,60072,220887,234.04,234.62,200,200,0,0,,,0,0,0,0,,,0,0,0,0,,,0,0,0,0,,,0,0,0,0,,,0,0,0,0,,,0,0,0,0,,,0,0,0,0,,,0,0,0,0,,,0,0,0,0,AAPL
2024-10-22 12:57:52.247582168+00:00,10,41,38,A,B,0,234.62,200,194,55449,220888,,234.62,0,200,0,0,,,0,0,0,0,,,0,0,0,0,,,0,0,0,0,,,0,0,0,0,,,0,0,0,0,,,0,0,0,0,,,0,0,0,0,,,0,0,0,0,,,0,0,0,0,AAPL
2024-10-22 12:57:52.341693787+00:00,10,40,38,A,B,0,234.67,200,194,202101,103381,,234.67,0,200,0,0,,,0,0,0,0,,,0,0,0,0,,,0,0,0,0,,,0,0,0,0,,,0,0,0,0,,,0,0,0,0,,,0,0,0,0,,,0,0,0,0,,,0,0,0,0,AAPL
2024-10-22 12:57:58.572012571+00:00,10,40,38,A,B,0,234.67,200,194,202793,103443,233.97,234.67,200,200,0,0,,,0,0,0,0,,,0,0,0,0,,,0,0,0,0,,,0,0,0,0,,,0,0,0,0,,,0,0,0,0,,,0,0,0,0,,,0,0,0,0,,,0,0,0,0,AAPL
2024-10-22 12:58:00.098829349+00:00,10,40,38,A,B,0,234.67,200,194,203165,103542,,234.67,0,200,0,0,,,0,0,0,0,,,0,0,0,0,,,0,0,0,0,,,0,0,0,0,,,0,0,0,0,,,0,0,0,0,,,0,0,0,0,,,0,0,0,0,,,0,0,0,0,AAPL
2024-10-22 12:58:00.098837593+00:00,10,40,38,A,A,0,,0,194,203160,103544,,,0,0,0,0,,,0,0,0,0,,,0,0,0,0,,,0,0,0,0,,,0,0,0,0,,,0,0,0,0,,,0,0,0,0,,,0,0,0,0,,,0,0,0,0,,,0,0,0,0,AAPL
2024-10-22 12:58:00.099278295+00:00,10,41,38,A,A,0,,0,194,54869,221469,,,0,0,0,0,,,0,0,0,0,,,0,0,0,0,,,0,0,0,0,,,0,0,0,0,,,0,0,0,0,,,0,0,0,0,,,0,0,0,0,,,0,0,0,0,,,0,0,0,0,AAPL
2024-10-22 12:58:01.615710296+00:00,10,41,38,A,A,0,234.62,200,194,55648,221733,,234.62,0,200,0,0,,,0,0,0,0,,,0,0,0,0,,,0,0,0,0,,,0,0,0,0,,,0,0,0,0,,,0,0,0,0,,,0,0,0,0,,,0,0,0,0,,,0,0,0,0,AAPL
2024-10-22 12:58:01.672737349+00:00,10,40,38,A,B,0,,0,194,203078,103608,233.97,,200,0,0,0,,,0,0,0,0,,,0,0,0,0,,,0,0,0,0,,,0,0,0,0,,,0,0,0,0,,,0,0,0,0,,,0,0,0,0,,,0,0,0,0,,,0,0,0,0,AAPL
2024-10-22 12:58:01.672871583+00:00,10,40,38,A,A,0,234.67,200,194,203059,103609,233.97,234.67,200,200,0,0,,,0,0,0,0,,,0,0,0,0,,,0,0,0,0,,,0,0,0,0,,,0,0,0,0,,,0,0,0,0,,,0,0,0,0,,,0,0,0,0,,,0,0,0,0,AAPL
2024-10-22 12:58:01.774749362+00:00,10,40,38,A,B,0,234.67,200,194,203079,103611,,234.67,0,200,0,0,,,0,0,0,0,,,0,0,0,0,,,0,0,0,0,,,0,0,0,0,,,0,0,0,0,,,0,0,0,0,,,0,0,0,0,,,0,0,0,0,,,0,0,0,0,AAPL
2024-10-22 12:58:01.774898975+00:00,10,40,38,A,A,0,,0,194,203108,103612,,,0,0,0,0,,,0,0,0,0,,,0,0,0,0,,,0,0,0,0,,,0,0,0,0,,,0,0,0,0,,,0,0,0,0,,,0,0,0,0,,,0,0,0,0,,,0,0,0,0,AAPL
2024-10-22 12:58:03.150581732+00:00,10,41,38,A,B,0,234.62,200,194,55504,221827,234.02,234.62,200,200,0,0,,,0,0,0,0,,,0,0,0,0,,,0,0,0,0,,,0,0,0,0,,,0,0,0,0,,,0,0,0,0,,,0,0,0,0,,,0,0,0,0,,,0,0,0,0,AAPL
2024-10-22 12:58:03.276744578+00:00,10,41,38,A,B,0,234.62,200,194,55434,221833,,234.62,0,200,0,0,,,0,0,0,0,,,0,0,0,0,,,0,0,0,0,,,0,0,0,0,,,0,0,0,0,,,0,0,0,0,,,0,0,0,0,,,0,0,0,0,,,0,0,0,0,AAPL
2024-10-22 12:58:04.672702608+00:00,10,40,38,A,A,0,234.67,200,194,203640,103660,,234.67,0,200,0,0,,,0,0,0,0,,,0,0,0,0,,,0,0,0,0,,,0,0,0,0,,,0,0,0,0,,,0,0,0,0,,,0,0,0,0,,,0,0,0,0,,,0,0,0,0,AAPL
2024-10-22 12:58:06.626563765+00:00,10,40,38,A,B,0,234.67,200,194,203914,103681,233.97,234.67,200,200,0,0,,,0,0,0,0,,,0,0,0,0,,,0,0,0,0,,,0,0,0,0,,,0,0,0,0,,,0,0,0,0,,,0,0,0,0,,,0,0,0,0,,,0,0,0,0,AAPL
2024-10-22 12:58:06.627039238+00:00,10,41,38,A,B,0,234.62,200,194,56153,221967,234.02,234.62,200,200,0,0,,,0,0,0,0,,,0,0,0,0,,,0,0,0,0,,,0,0,0,0,,,0,0,0,0,,,0,0,0,0,,,0,0,0,0,,,0,0,0,0,,,0,0,0,0,AAPL
2024-10-22 12:58:06.755358542+00:00,10,41,38,A,B,0,234.62,200,194,56609,221972,,234.62,0,200,0,0,,,0,0,0,0,,,0,0,0,0,,,0,0,0,0,,,0,0,0,0,,,0,0,0,0,,,0,0,0,0,,,0,0,0,0,,,0,0,0,0,,,0,0,0,0,AAPL
2024-10-22 12:58:10.651530095+00:00,10,41,38,A,B,0,234.62,200,194,55807,222117,234.02,234.62,200,200,0,0,,,0,0,0,0,,,0,0,0,0,,,0,0,0,0,,,0,0,0,0,,,0,0,0,0,,,0,0,0,0,,,0,0,0,0,,,0,0,0,0,,,0,0,0,0,AAPL
2024-10-22 12:58:10.651897584+00:00,10,39,38,C,B,0,232.8,2000,130,204226,63607,,236.6,0,2000,0,1,,,0,0,0,0,,,0,0,0,0,,,0,0,0,0,,,0,0,0,0,,,0,0,0,0,,,0,0,0,0,,,0,0,0,0,,,0,0,0,0,,,0,0,0,0,AAPL
2024-10-22 12:58:10.663928464+00:00,10,39,38,A,A,0,236.2,2000,130,204118,63608,,236.2,0,2000,0,1,,236.6,0,2000,0,1,,,0,0,0,0,,,0,0,0,0,,,0,0,0,0,,,0,0,0,0,,,0,0,0,0,,,0,0,0,0,,,0,0,0,0,,,0,0,0,0,AAPL
2024-10-22 12:58:10.664125940+00:00,10,39,38,C,A,1,236.6,2000,130,203882,63609,,236.2,0,2000,0,1,,,0,0,0,0,,,0,0,0,0,,,0,0,0,0,,,0,0,0,0,,,0,0,0,0,,,0,0,0,0,,,0,0,0,0,,,0,0,0,0,,,0,0,0,0,AAPL
2024-10-22 12:58:10.690354047+00:00,10,39,38,A,B,0,232.6,2000,130,203921,63610,232.6,236.2,2000,2000,1,1,,,0,0,0,0,,,0,0,0,0,,,0,0,0,0,,,0,0,0,0,,,0,0,0,0,,,0,0,0,0,,,0,0,0,0,,,0,0,0,0,,,0,0,0,0,AAPL
2024-10-22 12:58:23.103775630+00:00,10,39,38,A,B,0,232.8,2000,130,204217,63714,232.8,236.2,2000,2000,1,1,232.6,,2000,0,1,0,,,0,0,0,0,,,0,0,0,0,,,0,0,0,0,,,0,0,0,0,,,0,0,0,0,,,0,0,0,0,,,0,0,0,0,,,0,0,0,0,AAPL
2024-10-22 12:58:23.103962143+00:00,10,39,38,C,B,1,232.6,2000,130,203962,63715,232.8,236.2,2000,2000,1,1,,,0,0,0,0,,,0,0,0,0,,,0,0,0,0,,,0,0,0,0,,,0,0,0,0,,,0,0,0,0,,,0,0,0,0,,,0,0,0,0,,,0,0,0,0,AAPL
2024-10-22 12:58:33.959969958+00:00,10,39,38,C,A,0,236.2,2000,130,203801,63778,232.8,,2000,0,1,0,,,0,0,0,0,,,0,0,0,0,,,0,0,0,0,,,0,0,0,0,,,0,0,0,0,,,0,0,0,0,,,0,0,0,0,,,0,0,0,0,,,0,0,0,0,AAPL
2024-10-22 12:58:33.970843188+00:00,10,39,38,A,A,0,236.2,2000,130,203759,63779,232.8,236.2,2000,2000,1,1,,,0,0,0,0,,,0,0,0,0,,,0,0,0,0,,,0,0,0,0,,,0,0,0,0,,,0,0,0,0,,,0,0,0,0,,,0,0,0,0,,,0,0,0,0,AAPL
2024-10-22 12:58:33.987225271+00:00,10,39,38,C,A,0,236.2,2000,130,203755,63780,232.8,,2000,0,1,0,,,0,0,0,0,,,0,0,0,0,,,0,0,0,0,,,0,0,0,0,,,0,0,0,0,,,0,0,0,0,,,0,0,0,0,,,0,0,0,0,,,0,0,0,0,AAPL
2024-10-22 12:58:34.001059837+00:00,10,39,38,A,A,0,236.2,2000,130,204030,63782,232.8,236.2,2000,2000,1,1,,,0,0,0,0,,,0,0,0,0,,,0,0,0,0,,,0,0,0,0,,,0,0,0,0,,,0,0,0,0,,,0,0,0,0,,,0,0,0,0,,,0,0,0,0,AAPL
2024-10-22 12:58:34.273427654+00:00,10,41,38,A,B,0,234.62,200,194,58769,222818,,234.62,0,200,0,0,,,0,0,0,0,,,0,0,0,0,,,0,0,0,0,,,0,0,0,0,,,0,0,0,0,,,0,0,0,0,,,0,0,0,0,,,0,0,0,0,,,0,0,0,0,AAPL
2024-10-22 12:58:34.273450150+00:00,10,41,38,A,B,0,234.62,200,194,54672,222819,233.97,234.62,200,200,0,0,,,0,0,0,0,,,0,0,0,0,,,0,0,0,0,,,0,0,0,0,,,0,0,0,0,,,0,0,0,0,,,0,0,0,0,,,0,0,0,0,,,0,0,0,0,AAPL
2024-10-22 12:58:36.475220442+00:00,10,39,38,C,B,0,232.8,2000,130,203902,63815,,236.2,0,2000,0,1,,,0,0,0,0,,,0,0,0,0,,,0,0,0,0,,,0,0,0,0,,,0,0,0,0,,,0,0,0,0,,,0,0,0,0,,,0,0,0,0,,,0,0,0,0,AAPL
2024-10-22 12:58:36.511484132+00:00,10,39,38,A,B,0,232.8,2000,130,203698,63816,232.8,236.2,2000,2000,1,1,,,0,0,0,0,,,0,0,0,0,,,0,0,0,0,,,0,0,0,0,,,0,0,0,0,,,0,0,0,0,,,0,0,0,0,,,0,0,0,0,,,0,0,0,0,AAPL
2024-10-22 12:58:39.896222911+00:00,10,39,38,C,A,0,236.2,2000,130,203474,63830,232.8,,2000,0,1,0,,,0,0,0,0,,,0,0,0,0,,,0,0,0,0,,,0,0,0,0,,,0,0,0,0,,,0,0,0,0,,,0,0,0,0,,,0,0,0,0,,,0,0,0,0,AAPL
2024-10-22 12:58:39.907685122+00:00,10,39,38,A,A,0,236.4,2000,130,203563,63831,232.8,236.4,2000,2000,1,1,,,0,0,0,0,,,0,0,0,0,,,0,0,0,0,,,0,0,0,0,,,0,0,0,0,,,0,0,0,0,,,0,0,0,0,,,0,0,0,0,,,0,0,0,0,AAPL
2024-10-22 12:58:40.141074740+00:00,10,40,38,A,B,0,234.67,200,194,203021,104011,,234.67,0,200,0,0,,,0,0,0,0,,,0,0,0,0,,,0,0,0,0,,,0,0,0,0,,,0,0,0,0,,,0,0,0,0,,,0,0,0,0,,,0,0,0,0,,,0,0,0,0,AAPL
2024-10-22 12:58:40.141100111+00:00,10,40,38,A,B,0,234.67,200,194,203144,104012,233.85,234.67,200,200,0,0,,,0,0,0,0,,,0,0,0,0,,,0,0,0,0,,,0,0,0,0,,,0,0,0,0,,,0,0,0,0,,,0,0,0,0,,,0,0,0,0,,,0,0,0,0,AAPL
2024-10-22 12:58:40.948629854+00:00,10,39,38,A,A,0,236.2,2000,130,204216,63834,232.8,236.2,2000,2000,1,1,,236.4,0,2000,0,1,,,0,0,0,0,,,0,0,0,0,,,0,0,0,0,,,0,0,0,0,,,0,0,0,0,,,0,0,0,0,,,0,0,0,0,,,0,0,0,0,AAPL
2024-10-22 12:58:40.948823549+00:00,10,39,38,C,A,1,236.4,2000,130,203546,63835,232.8,236.2,2000,2000,1,1,,,0,0,0,0,,,0,0,0,0,,,0,0,0,0,,,0,0,0,0,,,0,0,0,0,,,0,0,0,0,,,0,0,0,0,,,0,0,0,0,,,0,0,0,0,AAPL
2024-10-22 12:58:41.275807069+00:00,10,41,38,A,A,0,,0,194,55978,223174,233.97,,200,0,0,0,,,0,0,0,0,,,0,0,0,0,,,0,0,0,0,,,0,0,0,0,,,0,0,0,0,,,0,0,0,0,,,0,0,0,0,,,0,0,0,0,,,0,0,0,0,AAPL
2024-10-22 12:58:41.275832237+00:00,10,41,38,A,A,0,234.53,200,194,54331,223175,233.97,234.53,200,200,0,0,,,0,0,0,0,,,0,0,0,0,,,0,0,0,0,,,0,0,0,0,,,0,0,0,0,,,0,0,0,0,,,0,0,0,0,,,0,0,0,0,,,0,0,0,0,AAPL
2024-10-22 12:58:49.570778432+00:00,10,39,38,C,A,0,236.2,2000,130,204158,63872,232.8,,2000,0,1,0,,,0,0,0,0,,,0,0,0,0,,,0,0,0,0,,,0,0,0,0,,,0,0,0,0,,,0,0,0,0,,,0,0,0,0,,,0,0,0,0,,,0,0,0,0,AAPL
2024-10-22 12:58:49.581626452+00:00,10,39,38,A,A,0,236.4,2000,130,203630,63873,232.8,236.4,2000,2000,1,1,,,0,0,0,0,,,0,0,0,0,,,0,0,0,0,,,0,0,0,0,,,0,0,0,0,,,0,0,0,0,,,0,0,0,0,,,0,0,0,0,,,0,0,0,0,AAPL
2024-10-22 12:58:49.634462355+00:00,10,41,38,A,B,0,234.53,200,194,56138,223509,,234.53,0,200,0,0,,,0,0,0,0,,,0,0,0,0,,,0,0,0,0,,,0,0,0,0,,,0,0,0,0,,,0,0,0,0,,,0,0,0,0,,,0,0,0,0,,,0,0,0,0,AAPL
2024-10-22 12:58:49.634491670+00:00,10,41,38,A,B,0,234.53,200,194,57593,223510,233.9,234.53,200,200,0,0,,,0,0,0,0,,,0,0,0,0,,,0,0,0,0,,,0,0,0,0,,,0,0,0,0,,,0,0,0,0,,,0,0,0,0,,,0,0,0,0,,,0,0,0,0,AAPL
2024-10-22 12:58:49.835394801+00:00,10,40,38,A,A,0,,0,194,202825,104088,233.85,,200,0,0,0,,,0,0,0,0,,,0,0,0,0,,,0,0,0,0,,,0,0,0,0,,,0,0,0,0,,,0,0,0,0,,,0,0,0,0,,,0,0,0,0,,,0,0,0,0,AAPL
2024-10-22 12:58:49.835415139+00:00,10,40,38,A,A,0,234.54,200,194,202756,104089,233.85,234.54,200,200,0,0,,,0,0,0,0,,,0,0,0,0,,,0,0,0,0,,,0,0,0,0,,,0,0,0,0,,,0,0,0,0,,,0,0,0,0,,,0,0,0,0,,,0,0,0,0,AAPL
2024-10-22 12:58:55.409061452+00:00,10,39,38,A,A,0,236.2,2000,130,203354,63904,232.8,236.2,2000,2000,1,1,,236.4,0,2000,0,1,,,0,0,0,0,,,0,0,0,0,,,0,0,0,0,,,0,0,0,0,,,0,0,0,0,,,0,0,0,0,,,0,0,0,0,,,0,0,0,0,AAPL
2024-10-22 12:58:55.409254380+00:00,10,39,38,C,A,1,236.4,2000,130,203318,63905,232.8,236.2,2000,2000,1,1,,,0,0,0,0,,,0,0,0,0,,,0,0,0,0,,,0,0,0,0,,,0,0,0,0,,,0,0,0,0,,,0,0,0,0,,,0,0,0,0,,,0,0,0,0,AAPL
2024-10-22 12:59:16.496438720+00:00,10,39,38,C,A,0,236.2,2000,130,203959,64006,232.8,,2000,0,1,0,,,0,0,0,0,,,0,0,0,0,,,0,0,0,0,,,0,0,0,0,,,0,0,0,0,,,0,0,0,0,,,0,0,0,0,,,0,0,0,0,,,0,0,0,0,AAPL
2024-10-22 12:59:16.533074776+00:00,10,39,38,A,A,0,236.2,2000,130,203509,64007,232.8,236.2,2000,2000,1,1,,,0,0,0,0,,,0,0,0,0,,,0,0,0,0,,,0,0,0,0,,,0,0,0,0,,,0,0,0,0,,,0,0,0,0,,,0,0,0,0,,,0,0,0,0,AAPL
2024-10-22 12:59:26.226642160+00:00,10,39,38,C,A,0,236.2,2000,130,204513,64085,232.8,,2000,0,1,0,,,0,0,0,0,,,0,0,0,0,,,0,0,0,0,,,0,0,0,0,,,0,0,0,0,,,0,0,0,0,,,0,0,0,0,,,0,0,0,0,,,0,0,0,0,AAPL
2024-10-22 12:59:26.237492643+00:00,10,39,38,A,A,0,236.4,2000,130,203944,64086,232.8,236.4,2000,2000,1,1,,,0,0,0,0,,,0,0,0,0,,,0,0,0,0,,,0,0,0,0,,,0,0,0,0,,,0,0,0,0,,,0,0,0,0,,,0,0,0,0,,,0,0,0,0,AAPL
2024-10-22 12:59:26.258864754+00:00,10,39,38,A,A,0,236.2,2000,130,204014,64087,232.8,236.2,2000,2000,1,1,,236.4,0,2000,0,1,,,0,0,0,0,,,0,0,0,0,,,0,0,0,0,,,0,0,0,0,,,0,0,0,0,,,0,0,0,0,,,0,0,0,0,,,0,0,0,0,AAPL
2024-10-22 12:59:26.259594311+00:00,10,39,38,C,A,1,236.4,2000,130,203828,64088,232.8,236.2,2000,2000,1,1,,,0,0,0,0,,,0,0,0,0,,,0,0,0,0,,,0,0,0,0,,,0,0,0,0,,,0,0,0,0,,,0,0,0,0,,,0,0,0,0,,,0,0,0,0,AAPL
2024-10-22 12:59:26.262401037+00:00,10,39,38,C,A,0,236.2,2000,130,203916,64089,232.8,,2000,0,1,0,,,0,0,0,0,,,0,0,0,0,,,0,0,0,0,,,0,0,0,0,,,0,0,0,0,,,0,0,0,0,,,0,0,0,0,,,0,0,0,0,,,0,0,0,0,AAPL
2024-10-22 12:59:26.281047908+00:00,10,39,38,A,A,0,236.2,2000,130,203837,64090,232.8,236.2,2000,2000,1,1,,,0,0,0,0,,,0,0,0,0,,,0,0,0,0,,,0,0,0,0,,,0,0,0,0,,,0,0,0,0,,,0,0,0,0,,,0,0,0,0,,,0,0,0,0,AAPL
2024-10-22 12:59:26.303349338+00:00,10,39,38,C,A,0,236.2,2000,130,203815,64091,232.8,,2000,0,1,0,,,0,0,0,0,,,0,0,0,0,,,0,0,0,0,,,0,0,0,0,,,0,0,0,0,,,0,0,0,0,,,0,0,0,0,,,0,0,0,0,,,0,0,0,0,AAPL
2024-10-22 12:59:26.315035779+00:00,10,39,38,A,A,0,236.4,2000,130,203798,64092,232.8,236.4,2000,2000,1,1,,,0,0,0,0,,,0,0,0,0,,,0,0,0,0,,,0,0,0,0,,,0,0,0,0,,,0,0,0,0,,,0,0,0,0,,,0,0,0,0,,,0,0,0,0,AAPL
2024-10-22 12:59:26.341390516+00:00,10,39,38,A,A,0,236.2,2000,130,203835,64093,232.8,236.2,2000,2000,1,1,,236.4,0,2000,0,1,,,0,0,0,0,,,0,0,0,0,,,0,0,0,0,,,0,0,0,0,,,0,0,0,0,,,0,0,0,0,,,0,0,0,0,,,0,0,0,0,AAPL
2024-10-22 12:59:26.342118087+00:00,10,39,38,C,A,1,236.4,2000,130,203800,64094,232.8,236.2,2000,2000,1,1,,,0,0,0,0,,,0,0,0,0,,,0,0,0,0,,,0,0,0,0,,,0,0,0,0,,,0,0,0,0,,,0,0,0,0,,,0,0,0,0,,,0,0,0,0,AAPL
2024-10-22 12:59:27.097114728+00:00,10,39,38,C,B,0,232.8,2000,130,204137,64098,,236.2,0,2000,0,1,,,0,0,0,0,,,0,0,0,0,,,0,0,0,0,,,0,0,0,0,,,0,0,0,0,,,0,0,0,0,,,0,0,0,0,,,0,0,0,0,,,0,0,0,0,AAPL
2024-10-22 12:59:27.108562893+00:00,10,39,38,A,B,0,232.6,2000,130,203907,64099,232.6,236.2,2000,2000,1,1,,,0,0,0,0,,,0,0,0,0,,,0,0,0,0,,,0,0,0,0,,,0,0,0,0,,,0,0,0,0,,,0,0,0,0,,,0,0,0,0,,,0,0,0,0,AAPL
2024-10-22 12:59:27.137852041+00:00,10,39,38,A,B,0,232.8,2000,130,203833,64101,232.8,236.2,2000,2000,1,1,232.6,,2000,0,1,0,,,0,0,0,0,,,0,0,0,0,,,0,0,0,0,,,0,0,0,0,,,0,0,0,0,,,0,0,0,0,,,0,0,0,0,,,0,0,0,0,AAPL
2024-10-22 12:59:27.138574235+00:00,10,39,38,C,B,1,232.6,2000,130,203787,64102,232.8,236.2,2000,2000,1,1,,,0,0,0,0,,,0,0,0,0,,,0,0,0,0,,,0,0,0,0,,,0,0,0,0,,,0,0,0,0,,,0,0,0,0,,,0,0,0,0,,,0,0,0,0,AAPL
2024-10-22 12:59:35.484975659+00:00,10,39,38,C,A,0,236.2,2000,130,203845,64168,232.8,,2000,0,1,0,,,0,0,0,0,,,0,0,0,0,,,0,0,0,0,,,0,0,0,0,,,0,0,0,0,,,0,0,0,0,,,0,0,0,0,,,0,0,0,0,,,0,0,0,0,AAPL
2024-10-22 12:59:35.522668177+00:00,10,39,38,A,A,0,236.2,2000,130,203809,64169,232.8,236.2,2000,2000,1,1,,,0,0,0,0,,,0,0,0,0,,,0,0,0,0,,,0,0,0,0,,,0,0,0,0,,,0,0,0,0,,,0,0,0,0,,,0,0,0,0,,,0,0,0,0,AAPL
2024-10-22 12:59:55.692582474+00:00,10,39,38,C,A,0,236.2,2000,130,203727,64302,232.8,,2000,0,1,0,,,0,0,0,0,,,0,0,0,0,,,0,0,0,0,,,0,0,0,0,,,0,0,0,0,,,0,0,0,0,,,0,0,0,0,,,0,0,0,0,,,0,0,0,0,AAPL
2024-10-22 12:59:55.704323234+00:00,10,39,38,A,A,0,236.6,2000,130,203230,64303,232.8,236.6,2000,2000,1,1,,,0,0,0,0,,,0,0,0,0,,,0,0,0,0,,,0,0,0,0,,,0,0,0,0,,,0,0,0,0,,,0,0,0,0,,,0,0,0,0,,,0,0,0,0,AAPL
2024-10-22 13:00:00.011635628+00:00,10,40,38,A,B,0,234.54,200,194,204312,104987,,234.54,0,200,0,0,,,0,0,0,0,,,0,0,0,0,,,0,0,0,0,,,0,0,0,0,,,0,0,0,0,,,0,0,0,0,,,0,0,0,0,,,0,0,0,0,,,0,0,0,0,AAPL
2024-10-22 13:00:00.011645254+00:00,10,40,38,A,A,0,,0,194,204375,104988,,,0,0,0,0,,,0,0,0,0,,,0,0,0,0,,,0,0,0,0,,,0,0,0,0,,,0,0,0,0,,,0,0,0,0,,,0,0,0,0,,,0,0,0,0,,,0,0,0,0,AAPL
2024-10-22 13:00:00.011996560+00:00,10,41,38,A,B,0,234.53,200,194,55206,227433,,234.53,0,200,0,0,,,0,0,0,0,,,0,0,0,0,,,0,0,0,0,,,0,0,0,0,,,0,0,0,0,,,0,0,0,0,,,0,0,0,0,,,0,0,0,0,,,0,0,0,0,AAPL
2024-10-22 13:00:00.012009508+00:00,10,41,38,A,A,0,,0,194,55791,227435,,,0,0,0,0,,,0,0,0,0,,,0,0,0,0,,,0,0,0,0,,,0,0,0,0,,,0,0,0,0,,,0,0,0,0,,,0,0,0,0,,,0,0,0,0,,,0,0,0,0,AAPL
2024-10-22 13:00:00.249702575+00:00,10,39,38,C,B,0,232.8,2000,130,203580,64320,,236.6,0,2000,0,1,,,0,0,0,0,,,0,0,0,0,,,0,0,0,0,,,0,0,0,0,,,0,0,0,0,,,0,0,0,0,,,0,0,0,0,,,0,0,0,0,,,0,0,0,0,AAPL
2024-10-22 13:00:00.261588483+00:00,10,39,38,A,B,0,232.6,2000,130,202967,64321,232.6,236.6,2000,2000,1,1,,,0,0,0,0,,,0,0,0,0,,,0,0,0,0,,,0,0,0,0,,,0,0,0,0,,,0,0,0,0,,,0,0,0,0,,,0,0,0,0,,,0,0,0,0,AAPL
2024-10-22 13:00:00.712633215+00:00,10,39,38,C,A,0,236.6,2000,130,203303,64322,232.6,,2000,0,1,0,,,0,0,0,0,,,0,0,0,0,,,0,0,0,0,,,0,0,0,0,,,0,0,0,0,,,0,0,0,0,,,0,0,0,0,,,0,0,0,0,,,0,0,0,0,AAPL
2024-10-22 13:00:03.912258981+00:00,10,41,38,A,B,0,,0,194,55852,230370,233.98,,200,0,0,0,,,0,0,0,0,,,0,0,0,0,,,0,0,0,0,,,0,0,0,0,,,0,0,0,0,,,0,0,0,0,,,0,0,0,0,,,0,0,0,0,,,0,0,0,0,AAPL
2024-10-22 13:00:03.912800097+00:00,10,41,38,A,A,0,234.57,200,194,55730,230371,233.98,234.57,200,200,0,0,,,0,0,0,0,,,0,0,0,0,,,0,0,0,0,,,0,0,0,0,,,0,0,0,0,,,0,0,0,0,,,0,0,0,0,,,0,0,0,0,,,0,0,0,0,AAPL
2024-10-22 13:00:03.946772463+00:00,10,41,38,A,A,0,,0,194,60551,230372,233.98,,200,0,0,0,,,0,0,0,0,,,0,0,0,0,,,0,0,0,0,,,0,0,0,0,,,0,0,0,0,,,0,0,0,0,,,0,0,0,0,,,0,0,0,0,,,0,0,0,0,AAPL
2024-10-22 13:00:04.077865439+00:00,10,41,38,A,B,0,,0,194,55205,230381,,,0,0,0,0,,,0,0,0,0,,,0,0,0,0,,,0,0,0,0,,,0,0,0,0,,,0,0,0,0,,,0,0,0,0,,,0,0,0,0,,,0,0,0,0,,,0,0,0,0,AAPL
2024-10-22 13:00:05.012487350+00:00,10,39,38,A,A,0,236.4,2000,130,203923,64356,232.6,236.4,2000,2000,1,1,,,0,0,0,0,,,0,0,0,0,,,0,0,0,0,,,0,0,0,0,,,0,0,0,0,,,0,0,0,0,,,0,0,0,0,,,0,0,0,0,,,0,0,0,0,AAPL
2024-10-22 13:00:05.070239496+00:00,10,39,38,C,A,0,236.4,2000,130,202997,64357,232.6,,2000,0,1,0,,,0,0,0,0,,,0,0,0,0,,,0,0,0,0,,,0,0,0,0,,,0,0,0,0,,,0,0,0,0,,,0,0,0,0,,,0,0,0,0,,,0,0,0,0,AAPL
2024-10-22 13:00:05.082506448+00:00,10,39,38,A,A,0,236.6,2000,130,202973,64358,232.6,236.6,2000,2000,1,1,,,0,0,0,0,,,0,0,0,0,,,0,0,0,0,,,0,0,0,0,,,0,0,0,0,,,0,0,0,0,,,0,0,0,0,,,0,0,0,0,,,0,0,0,0,AAPL
2024-10-22 13:00:15.795047064+00:00,10,40,38,A,B,0,,0,194,204560,105813,233.92,,200,0,0,0,,,0,0,0,0,,,0,0,0,0,,,0,0,0,0,,,0,0,0,0,,,0,0,0,0,,,0,0,0,0,,,0,0,0,0,,,0,0,0,0,,,0,0,0,0,AAPL
2024-10-22 13:00:15.795291025+00:00,10,41,38,A,A,0,234.57,200,194,55820,231697,,234.57,0,200,0,0,,,0,0,0,0,,,0,0,0,0,,,0,0,0,0,,,0,0,0,0,,,0,0,0,0,,,0,0,0,0,,,0,0,0,0,,,0,0,0,0,,,0,0,0,0,AAPL
2024-10-22 13:00:15.795291467+00:00,10,41,38,A,B,0,234.57,200,194,54138,231698,233.98,234.57,200,200,0,0,,,0,0,0,0,,,0,0,0,0,,,0,0,0,0,,,0,0,0,0,,,0,0,0,0,,,0,0,0,0,,,0,0,0,0,,,0,0,0,0,,,0,0,0,0,AAPL
2024-10-22 13:00:15.840545262+00:00,10,41,38,A,A,0,,0,194,55042,231704,233.98,,200,0,0,0,,,0,0,0,0,,,0,0,0,0,,,0,0,0,0,,,0,0,0,0,,,0,0,0,0,,,0,0,0,0,,,0,0,0,0,,,0,0,0,0,,,0,0,0,0,AAPL
2024-10-22 13:00:15.938232111+00:00,10,40,38,A,B,0,,0,194,204781,105814,,,0,0,0,0,,,0,0,0,0,,,0,0,0,0,,,0,0,0,0,,,0,0,0,0,,,0,0,0,0,,,0,0,0,0,,,0,0,0,0,,,0,0,0,0,,,0,0,0,0,AAPL
2024-10-22 13:00:16.003185219+00:00,10,40,38,A,B,0,,0,194,204695,105819,233.92,,200,0,0,0,,,0,0,0,0,,,0,0,0,0,,,0,0,0,0,,,0,0,0,0,,,0,0,0,0,,,0,0,0,0,,,0,0,0,0,,,0,0,0,0,,,0,0,0,0,AAPL
2024-10-22 13:00:16.003192383+00:00,10,40,38,A,A,0,234.63,200,194,204423,105820,233.92,234.63,200,200,0,0,,,0,0,0,0,,,0,0,0,0,,,0,0,0,0,,,0,0,0,0,,,0,0,0,0,,,0,0,0,0,,,0,0,0,0,,,0,0,0,0,,,0,0,0,0,AAPL
2024-10-22 13:00:16.003487213+00:00,10,41,38,A,A,0,234.57,200,194,55610,231712,233.98,234.57,200,200,0,0,,,0,0,0,0,,,0,0,0,0,,,0,0,0,0,,,0,0,0,0,,,0,0,0,0,,,0,0,0,0,,,0,0,0,0,,,0,0,0,0,,,0,0,0,0,AAPL
2024-10-22 13:00:16.103623678+00:00,10,40,38,A,A,0,,0,194,204462,105823,233.92,,200,0,0,0,,,0,0,0,0,,,0,0,0,0,,,0,0,0,0,,,0,0,0,0,,,0,0,0,0,,,0,0,0,0,,,0,0,0,0,,,0,0,0,0,,,0,0,0,0,AAPL
2024-10-22 13:00:16.103859715+00:00,10,41,38,A,A,0,,0,194,55592,231726,233.98,,200,0,0,0,,,0,0,0,0,,,0,0,0,0,,,0,0,0,0,,,0,0,0,0,,,0,0,0,0,,,0,0,0,0,,,0,0,0,0,,,0,0,0,0,,,0,0,0,0,AAPL
2024-10-22 13:00:16.104206385+00:00,10,40,38,A,B,0,,0,194,204478,105824,,,0,0,0,0,,,0,0,0,0,,,0,0,0,0,,,0,0,0,0,,,0,0,0,0,,,0,0,0,0,,,0,0,0,0,,,0,0,0,0,,,0,0,0,0,,,0,0,0,0,AAPL
2024-10-22 13:00:17.336212242+00:00,10,41,38,A,B,0,,0,194,55587,231823,,,0,0,0,0,,,0,0,0,0,,,0,0,0,0,,,0,0,0,0,,,0,0,0,0,,,0,0,0,0,,,0,0,0,0,,,0,0,0,0,,,0,0,0,0,,,0,0,0,0,AAPL
2024-10-22 13:00:20.535683521+00:00,10,40,38,A,B,0,,0,194,204477,105926,233.91,,200,0,0,0,,,0,0,0,0,,,0,0,0,0,,,0,0,0,0,,,0,0,0,0,,,0,0,0,0,,,0,0,0,0,,,0,0,0,0,,,0,0,0,0,,,0,0,0,0,AAPL
2024-10-22 13:00:20.535931771+00:00,10,41,38,A,B,0,,0,194,54712,232089,233.97,,200,0,0,0,,,0,0,0,0,,,0,0,0,0,,,0,0,0,0,,,0,0,0,0,,,0,0,0,0,,,0,0,0,0,,,0,0,0,0,,,0,0,0,0,,,0,0,0,0,AAPL
2024-10-22 13:00:20.535942082+00:00,10,41,38,A,A,0,234.57,200,194,54366,232090,233.97,234.57,200,200,0,0,,,0,0,0,0,,,0,0,0,0,,,0,0,0,0,,,0,0,0,0,,,0,0,0,0,,,0,0,0,0,,,0,0,0,0,,,0,0,0,0,,,0,0,0,0,AAPL
2024-10-22 13:00:20.535855699+00:00,10,40,38,A,A,0,234.63,200,194,204463,105927,233.91,234.63,200,200,0,0,,,0,0,0,0,,,0,0,0,0,,,0,0,0,0,,,0,0,0,0,,,0,0,0,0,,,0,0,0,0,,,0,0,0,0,,,0,0,0,0,,,0,0,0,0,AAPL
2024-10-22 13:00:20.582113116+00:00,10,41,38,A,A,0,,0,194,56086,232099,233.97,,200,0,0,0,,,0,0,0,0,,,0,0,0,0,,,0,0,0,0,,,0,0,0,0,,,0,0,0,0,,,0,0,0,0,,,0,0,0,0,,,0,0,0,0,,,0,0,0,0,AAPL
2024-10-22 13:00:20.605725467+00:00,10,40,38,A,A,0,,0,194,204459,105934,233.91,,200,0,0,0,,,0,0,0,0,,,0,0,0,0,,,0,0,0,0,,,0,0,0,0,,,0,0,0,0,,,0,0,0,0,,,0,0,0,0,,,0,0,0,0,,,0,0,0,0,AAPL
2024-10-22 13:00:20.854917054+00:00,10,41,38,A,A,0,234.57,200,194,55199,232145,233.97,234.57,200,200,0,0,,,0,0,0,0,,,0,0,0,0,,,0,0,0,0,,,0,0,0,0,,,0,0,0,0,,,0,0,0,0,,,0,0,0,0,,,0,0,0,0,,,0,0,0,0,AAPL
2024-10-22 13:00:20.854863482+00:00,10,40,38,A,A,0,234.62,200,194,204497,105937,233.91,234.62,200,200,0,0,,,0,0,0,0,,,0,0,0,0,,,0,0,0,0,,,0,0,0,0,,,0,0,0,0,,,0,0,0,0,,,0,0,0,0,,,0,0,0,0,,,0,0,0,0,AAPL
2024-10-22 13:00:20.855211340+00:00,10,40,38,A,A,0,,0,194,204477,105938,233.91,,200,0,0,0,,,0,0,0,0,,,0,0,0,0,,,0,0,0,0,,,0,0,0,0,,,0,0,0,0,,,0,0,0,0,,,0,0,0,0,,,0,0,0,0,,,0,0,0,0,AAPL
2024-10-22 13:00:20.901444403+00:00,10,41,38,A,A,0,,0,194,55258,232156,233.97,,200,0,0,0,,,0,0,0,0,,,0,0,0,0,,,0,0,0,0,,,0,0,0,0,,,0,0,0,0,,,0,0,0,0,,,0,0,0,0,,,0,0,0,0,,,0,0,0,0,AAPL
2024-10-22 13:00:20.981202746+00:00,10,40,38,A,B,0,,0,194,204498,105956,,,0,0,0,0,,,0,0,0,0,,,0,0,0,0,,,0,0,0,0,,,0,0,0,0,,,0,0,0,0,,,0,0,0,0,,,0,0,0,0,,,0,0,0,0,,,0,0,0,0,AAPL
2024-10-22 13:00:21.459596608+00:00,10,41,38,A,B,0,,0,194,55387,232217,,,0,0,0,0,,,0,0,0,0,,,0,0,0,0,,,0,0,0,0,,,0,0,0,0,,,0,0,0,0,,,0,0,0,0,,,0,0,0,0,,,0,0,0,0,,,0,0,0,0,AAPL
2024-10-22 13:00:26.902765998+00:00,10,41,38,A,A,0,234.52,200,194,55479,232598,,234.52,0,200,0,0,,,0,0,0,0,,,0,0,0,0,,,0,0,0,0,,,0,0,0,0,,,0,0,0,0,,,0,0,0,0,,,0,0,0,0,,,0,0,0,0,,,0,0,0,0,AAPL
2024-10-22 13:00:27.690502218+00:00,10,40,38,A,N,0,234.58,200,194,205015,106098,233.88,234.58,200,200,0,0,,,0,0,0,0,,,0,0,0,0,,,0,0,0,0,,,0,0,0,0,,,0,0,0,0,,,0,0,0,0,,,0,0,0,0,,,0,0,0,0,,,0,0,0,0,AAPL
2024-10-22 13:00:27.690998299+00:00,10,41,38,A,B,0,234.52,200,194,55292,232654,233.94,234.52,200,200,0,0,,,0,0,0,0,,,0,0,0,0,,,0,0,0,0,,,0,0,0,0,,,0,0,0,0,,,0,0,0,0,,,0,0,0,0,,,0,0,0,0,,,0,0,0,0,AAPL
2024-10-22 13:00:27.891870612+00:00,10,41,38,A,B,0,234.52,200,194,55320,232664,,234.52,0,200,0,0,,,0,0,0,0,,,0,0,0,0,,,0,0,0,0,,,0,0,0,0,,,0,0,0,0,,,0,0,0,0,,,0,0,0,0,,,0,0,0,0,,,0,0,0,0,AAPL
2024-10-22 13:00:28.321744485+00:00,10,41,38,A,B,0,234.52,200,194,55661,232692,233.94,234.52,200,200,0,0,,,0,0,0,0,,,0,0,0,0,,,0,0,0,0,,,0,0,0,0,,,0,0,0,0,,,0,0,0,0,,,0,0,0,0,,,0,0,0,0,,,0,0,0,0,AAPL
2024-10-22 13:00:28.496499313+00:00,10,41,38,A,B,0,234.52,200,194,55459,232704,,234.52,0,200,0,0,,,0,0,0,0,,,0,0,0,0,,,0,0,0,0,,,0,0,0,0,,,0,0,0,0,,,0,0,0,0,,,0,0,0,0,,,0,0,0,0,,,0,0,0,0,AAPL
2024-10-22 13:00:28.497846766+00:00,10,41,38,A,B,0,234.52,200,194,55018,232705,233.94,234.52,200,200,0,0,,,0,0,0,0,,,0,0,0,0,,,0,0,0,0,,,0,0,0,0,,,0,0,0,0,,,0,0,0,0,,,0,0,0,0,,,0,0,0,0,,,0,0,0,0,AAPL
2024-10-22 13:00:28.697853095+00:00,10,41,38,A,B,0,234.52,200,194,60687,232713,,234.52,0,200,0,0,,,0,0,0,0,,,0,0,0,0,,,0,0,0,0,,,0,0,0,0,,,0,0,0,0,,,0,0,0,0,,,0,0,0,0,,,0,0,0,0,,,0,0,0,0,AAPL
2024-10-22 13:00:29.135528818+00:00,10,40,38,A,B,0,234.58,200,194,204601,106140,,234.58,0,200,0,0,,,0,0,0,0,,,0,0,0,0,,,0,0,0,0,,,0,0,0,0,,,0,0,0,0,,,0,0,0,0,,,0,0,0,0,,,0,0,0,0,,,0,0,0,0,AAPL
2024-10-22 13:00:29.135649923+00:00,10,40,38,A,A,0,,0,194,204661,106141,,,0,0,0,0,,,0,0,0,0,,,0,0,0,0,,,0,0,0,0,,,0,0,0,0,,,0,0,0,0,,,0,0,0,0,,,0,0,0,0,,,0,0,0,0,,,0,0,0,0,AAPL
2024-10-22 13:00:32.171349183+00:00,10,39,38,A,A,0,236.4,2000,130,203628,64638,232.6,236.4,2000,2000,1,1,,236.6,0,2000,0,1,,,0,0,0,0,,,0,0,0,0,,,0,0,0,0,,,0,0,0,0,,,0,0,0,0,,,0,0,0,0,,,0,0,0,0,,,0,0,0,0,AAPL
2024-10-22 13:00:32.171516994+00:00,10,39,38,C,A,1,236.6,2000,130,203498,64639,232.6,236.4,2000,2000,1,1,,,0,0,0,0,,,0,0,0,0,,,0,0,0,0,,,0,0,0,0,,,0,0,0,0,,,0,0,0,0,,,0,0,0,0,,,0,0,0,0,,,0,0,0,0,AAPL
2024-10-22 13:00:34.162310024+00:00,10,40,38,A,A,0,234.58,200,194,204727,106245,,234.58,0,200,0,0,,,0,0,0,0,,,0,0,0,0,,,0,0,0,0,,,0,0,0,0,,,0,0,0,0,,,0,0,0,0,,,0,0,0,0,,,0,0,0,0,,,0,0,0,0,AAPL
2024-10-22 13:00:34.162399868+00:00,10,40,38,A,B,0,234.58,200,194,204658,106246,233.88,234.58,200,200,0,0,,,0,0,0,0,,,0,0,0,0,,,0,0,0,0,,,0,0,0,0,,,0,0,0,0,,,0,0,0,0,,,0,0,0,0,,,0,0,0,0,,,0,0,0,0,AAPL
2024-10-22 13:00:34.597196321+00:00,10,41,38,A,B,0,234.52,200,194,55760,233151,233.94,234.52,200,200,0,0,,,0,0,0,0,,,0,0,0,0,,,0,0,0,0,,,0,0,0,0,,,0,0,0,0,,,0,0,0,0,,,0,0,0,0,,,0,0,0,0,,,0,0,0,0,AAPL
2024-10-22 13:00:35.085106656+00:00,10,41,38,A,B,0,234.52,200,194,55462,233173,,234.52,0,200,0,0,,,0,0,0,0,,,0,0,0,0,,,0,0,0,0,,,0,0,0,0,,,0,0,0,0,,,0,0,0,0,,,0,0,0,0,,,0,0,0,0,,,0,0,0,0,AAPL
2024-10-22 13:00:36.308668290+00:00,10,40,38,A,A,0,,0,194,204547,106281,233.88,,200,0,0,0,,,0,0,0,0,,,0,0,0,0,,,0,0,0,0,,,0,0,0,0,,,0,0,0,0,,,0,0,0,0,,,0,0,0,0,,,0,0,0,0,,,0,0,0,0,AAPL
2024-10-22 13:00:40.201539711+00:00,10,41,38,A,B,0,234.52,200,194,55509,233569,233.96,234.52,200,200,0,0,,,0,0,0,0,,,0,0,0,0,,,0,0,0,0,,,0,0,0,0,,,0,0,0,0,,,0,0,0,0,,,0,0,0,0,,,0,0,0,0,,,0,0,0,0,AAPL
2024-10-22 13:00:40.201958611+00:00,10,40,38,A,A,0,234.58,200,194,204465,106329,233.88,234.58,200,200,0,0,,,0,0,0,0,,,0,0,0,0,,,0,0,0,0,,,0,0,0,0,,,0,0,0,0,,,0,0,0,0,,,0,0,0,0,,,0,0,0,0,,,0,0,0,0,AAPL
2024-10-22 13:00:40.269861867+00:00,10,40,38,A,A,0,,0,194,204477,106330,233.88,,200,0,0,0,,,0,0,0,0,,,0,0,0,0,,,0,0,0,0,,,0,0,0,0,,,0,0,0,0,,,0,0,0,0,,,0,0,0,0,,,0,0,0,0,,,0,0,0,0,AAPL
2024-10-22 13:00:40.705313281+00:00,10,40,38,A,A,0,234.58,200,194,204552,106334,233.88,234.58,200,200,0,0,,,0,0,0,0,,,0,0,0,0,,,0,0,0,0,,,0,0,0,0,,,0,0,0,0,,,0,0,0,0,,,0,0,0,0,,,0,0,0,0,,,0,0,0,0,AAPL
2024-10-22 13:00:40.962819447+00:00,10,41,38,A,B,0,234.52,200,194,55279,233601,,234.52,0,200,0,0,,,0,0,0,0,,,0,0,0,0,,,0,0,0,0,,,0,0,0,0,,,0,0,0,0,,,0,0,0,0,,,0,0,0,0,,,0,0,0,0,,,0,0,0,0,AAPL
2024-10-22 13:00:41.024449818+00:00,10,40,38,A,A,0,,0,194,204973,106339,233.88,,200,0,0,0,,,0,0,0,0,,,0,0,0,0,,,0,0,0,0,,,0,0,0,0,,,0,0,0,0,,,0,0,0,0,,,0,0,0,0,,,0,0,0,0,,,0,0,0,0,AAPL
2024-10-22 13:00:41.024590330+00:00,10,40,38,A,B,0,,0,194,204464,106340,,,0,0,0,0,,,0,0,0,0,,,0,0,0,0,,,0,0,0,0,,,0,0,0,0,,,0,0,0,0,,,0,0,0,0,,,0,0,0,0,,,0,0,0,0,,,0,0,0,0,AAPL
2024-10-22 13:00:42.546530276+00:00,10,41,38,A,A,0,,0,194,60248,233711,,,0,0,0,0,,,0,0,0,0,,,0,0,0,0,,,0,0,0,0,,,0,0,0,0,,,0,0,0,0,,,0,0,0,0,,,0,0,0,0,,,0,0,0,0,,,0,0,0,0,AAPL
2024-10-22 13:00:42.547072917+00:00,10,41,38,A,B,0,,0,194,54412,233714,233.97,,200,0,0,0,,,0,0,0,0,,,0,0,0,0,,,0,0,0,0,,,0,0,0,0,,,0,0,0,0,,,0,0,0,0,,,0,0,0,0,,,0,0,0,0,,,0,0,0,0,AAPL
2024-10-22 13:00:42.745757070+00:00,10,40,38,A,B,0,,0,194,204481,106387,233.9,,200,0,0,0,,,0,0,0,0,,,0,0,0,0,,,0,0,0,0,,,0,0,0,0,,,0,0,0,0,,,0,0,0,0,,,0,0,0,0,,,0,0,0,0,,,0,0,0,0,AAPL
2024-10-22 13:00:42.745768431+00:00,10,40,38,A,A,0,234.57,200,194,204461,106388,233.9,234.57,200,200,0,0,,,0,0,0,0,,,0,0,0,0,,,0,0,0,0,,,0,0,0,0,,,0,0,0,0,,,0,0,0,0,,,0,0,0,0,,,0,0,0,0,,,0,0,0,0,AAPL
2024-10-22 13:00:42.745826672+00:00,10,40,38,A,A,0,,0,194,204463,106389,233.9,,200,0,0,0,,,0,0,0,0,,,0,0,0,0,,,0,0,0,0,,,0,0,0,0,,,0,0,0,0,,,0,0,0,0,,,0,0,0,0,,,0,0,0,0,,,0,0,0,0,AAPL
2024-10-22 13:00:42.746239059+00:00,10,41,38,A,A,0,234.51,200,194,55570,233760,233.97,234.51,200,200,0,0,,,0,0,0,0,,,0,0,0,0,,,0,0,0,0,,,0,0,0,0,,,0,0,0,0,,,0,0,0,0,,,0,0,0,0,,,0,0,0,0,,,0,0,0,0,AAPL
2024-10-22 13:00:42.757776130+00:00,10,39,38,C,A,0,236.4,2000,130,203878,64736,232.6,,2000,0,1,0,,,0,0,0,0,,,0,0,0,0,,,0,0,0,0,,,0,0,0,0,,,0,0,0,0,,,0,0,0,0,,,0,0,0,0,,,0,0,0,0,,,0,0,0,0,AAPL
2024-10-22 13:00:42.770312177+00:00,10,39,38,A,A,0,236.6,2000,130,203831,64737,232.6,236.6,2000,2000,1,1,,,0,0,0,0,,,0,0,0,0,,,0,0,0,0,,,0,0,0,0,,,0,0,0,0,,,0,0,0,0,,,0,0,0,0,,,0,0,0,0,,,0,0,0,0,AAPL
2024-10-22 13:00:42.791291666+00:00,10,39,38,A,A,0,236.4,2000,130,203856,64738,232.6,236.4,2000,2000,1,1,,236.6,0,2000,0,1,,,0,0,0,0,,,0,0,0,0,,,0,0,0,0,,,0,0,0,0,,,0,0,0,0,,,0,0,0,0,,,0,0,0,0,,,0,0,0,0,AAPL
2024-10-22 13:00:42.791471172+00:00,10,39,38,C,A,1,236.6,2000,130,203874,64739,232.6,236.4,2000,2000,1,1,,,0,0,0,0,,,0,0,0,0,,,0,0,0,0,,,0,0,0,0,,,0,0,0,0,,,0,0,0,0,,,0,0,0,0,,,0,0,0,0,,,0,0,0,0,AAPL
2024-10-22 13:00:42.820070143+00:00,10,39,38,C,A,0,236.4,2000,130,203833,64740,232.6,,2000,0,1,0,,,0,0,0,0,,,0,0,0,0,,,0,0,0,0,,,0,0,0,0,,,0,0,0,0,,,0,0,0,0,,,0,0,0,0,,,0,0,0,0,,,0,0,0,0,AAPL
2024-10-22 13:00:42.831292217+00:00,10,39,38,A,A,0,236.6,2000,130,203851,64741,232.6,236.6,2000,2000,1,1,,,0,0,0,0,,,0,0,0,0,,,0,0,0,0,,,0,0,0,0,,,0,0,0,0,,,0,0,0,0,,,0,0,0,0,,,0,0,0,0,,,0,0,0,0,AAPL
2024-10-22 13:00:48.776896506+00:00,10,41,38,A,A,0,,0,194,55696,234053,233.97,,200,0,0,0,,,0,0,0,0,,,0,0,0,0,,,0,0,0,0,,,0,0,0,0,,,0,0,0,0,,,0,0,0,0,,,0,0,0,0,,,0,0,0,0,,,0,0,0,0,AAPL
2024-10-22 13:00:49.178279622+00:00,10,41,38,A,A,0,234.52,200,194,56265,234079,233.97,234.52,200,200,0,0,,,0,0,0,0,,,0,0,0,0,,,0,0,0,0,,,0,0,0,0,,,0,0,0,0,,,0,0,0,0,,,0,0,0,0,,,0,0,0,0,,,0,0,0,0,AAPL
2024-10-22 13:00:50.066642770+00:00,10,41,38,A,A,0,,0,194,56059,234156,233.97,,200,0,0,0,,,0,0,0,0,,,0,0,0,0,,,0,0,0,0,,,0,0,0,0,,,0,0,0,0,,,0,0,0,0,,,0,0,0,0,,,0,0,0,0,,,0,0,0,0,AAPL
2024-10-22 13:00:50.210461286+00:00,10,41,38,A,A,0,234.52,200,194,55452,234178,233.97,234.52,200,200,0,0,,,0,0,0,0,,,0,0,0,0,,,0,0,0,0,,,0,0,0,0,,,0,0,0,0,,,0,0,0,0,,,0,0,0,0,,,0,0,0,0,,,0,0,0,0,AAPL
2024-10-22 13:00:50.766501875+00:00,10,40,38,A,A,0,234.62,200,194,204554,106529,233.9,234.62,200,200,0,0,,,0,0,0,0,,,0,0,0,0,,,0,0,0,0,,,0,0,0,0,,,0,0,0,0,,,0,0,0,0,,,0,0,0,0,,,0,0,0,0,,,0,0,0,0,AAPL
2024-10-22 13:00:50.969118060+00:00,10,41,38,A,A,0,,0,194,60637,234202,233.97,,200,0,0,0,,,0,0,0,0,,,0,0,0,0,,,0,0,0,0,,,0,0,0,0,,,0,0,0,0,,,0,0,0,0,,,0,0,0,0,,,0,0,0,0,,,0,0,0,0,AAPL
2024-10-22 13:00:51.171701434+00:00,10,40,38,A,A,0,,0,194,204456,106534,233.9,,200,0,0,0,,,0,0,0,0,,,0,0,0,0,,,0,0,0,0,,,0,0,0,0,,,0,0,0,0,,,0,0,0,0,,,0,0,0,0,,,0,0,0,0,,,0,0,0,0,AAPL
2024-10-22 13:00:51.271712652+00:00,10,40,38,A,A,0,234.62,200,194,204507,106536,233.9,234.62,200,200,0,0,,,0,0,0,0,,,0,0,0,0,,,0,0,0,0,,,0,0,0,0,,,0,0,0,0,,,0,0,0,0,,,0,0,0,0,,,0,0,0,0,,,0,0,0,0,AAPL
2024-10-22 13:00:51.371699254+00:00,10,40,38,A,A,0,,0,194,204486,106540,233.9,,200,0,0,0,,,0,0,0,0,,,0,0,0,0,,,0,0,0,0,,,0,0,0,0,,,0,0,0,0,,,0,0,0,0,,,0,0,0,0,,,0,0,0,0,,,0,0,0,0,AAPL
2024-10-22 13:00:51.471903451+00:00,10,40,38,A,A,0,234.62,200,194,204496,106551,233.9,234.62,200,200,0,0,,,0,0,0,0,,,0,0,0,0,,,0,0,0,0,,,0,0,0,0,,,0,0,0,0,,,0,0,0,0,,,0,0,0,0,,,0,0,0,0,,,0,0,0,0,AAPL
2024-10-22 13:01:00.083008979+00:00,10,40,38,A,B,0,234.62,200,194,204251,106740,,234.62,0,200,0,0,,,0,0,0,0,,,0,0,0,0,,,0,0,0,0,,,0,0,0,0,,,0,0,0,0,,,0,0,0,0,,,0,0,0,0,,,0,0,0,0,,,0,0,0,0,AAPL
2024-10-22 13:01:00.083019471+00:00,10,40,38,A,A,0,,0,194,204233,106741,,,0,0,0,0,,,0,0,0,0,,,0,0,0,0,,,0,0,0,0,,,0,0,0,0,,,0,0,0,0,,,0,0,0,0,,,0,0,0,0,,,0,0,0,0,,,0,0,0,0,AAPL
2024-10-22 13:01:00.083223659+00:00,10,41,38,A,B,0,,0,194,55129,234998,,,0,0,0,0,,,0,0,0,0,,,0,0,0,0,,,0,0,0,0,,,0,0,0,0,,,0,0,0,0,,,0,0,0,0,,,0,0,0,0,,,0,0,0,0,,,0,0,0,0,AAPL
2024-10-22 13:01:02.780972725+00:00,10,41,38,A,B,0,,0,194,55805,235483,233.98,,200,0,0,0,,,0,0,0,0,,,0,0,0,0,,,0,0,0,0,,,0,0,0,0,,,0,0,0,0,,,0,0,0,0,,,0,0,0,0,,,0,0,0,0,,,0,0,0,0,AAPL
2024-10-22 13:01:05.015628793+00:00,10,40,38,A,B,0,,0,194,204335,106902,233.92,,200,0,0,0,,,0,0,0,0,,,0,0,0,0,,,0,0,0,0,,,0,0,0,0,,,0,0,0,0,,,0,0,0,0,,,0,0,0,0,,,0,0,0,0,,,0,0,0,0,AAPL
2024-10-22 13:01:05.016129478+00:00,10,41,38,A,A,0,234.56,200,194,55150,235940,233.98,234.56,200,200,0,0,,,0,0,0,0,,,0,0,0,0,,,0,0,0,0,,,0,0,0,0,,,0,0,0,0,,,0,0,0,0,,,0,0,0,0,,,0,0,0,0,,,0,0,0,0,AAPL
2024-10-22 13:01:05.083232438+00:00,10,41,38,A,A,0,,0,194,55262,235946,233.98,,200,0,0,0,,,0,0,0,0,,,0,0,0,0,,,0,0,0,0,,,0,0,0,0,,,0,0,0,0,,,0,0,0,0,,,0,0,0,0,,,0,0,0,0,,,0,0,0,0,AAPL
2024-10-22 13:01:06.238154359+00:00,10,40,38,A,A,0,234.61,200,194,204239,106934,233.92,234.61,200,200,0,0,,,0,0,0,0,,,0,0,0,0,,,0,0,0,0,,,0,0,0,0,,,0,0,0,0,,,0,0,0,0,,,0,0,0,0,,,0,0,0,0,,,0,0,0,0,AAPL
2024-10-22 13:01:06.238313909+00:00,10,41,38,A,A,0,234.56,200,194,57793,236030,233.98,234.56,200,200,0,0,,,0,0,0,0,,,0,0,0,0,,,0,0,0,0,,,0,0,0,0,,,0,0,0,0,,,0,0,0,0,,,0,0,0,0,,,0,0,0,0,,,0,0,0,0,AAPL
2024-10-22 13:01:06.238721700+00:00,10,39,38,C,B,0,232.6,2000,130,203891,64911,,236.6,0,2000,0,1,,,0,0,0,0,,,0,0,0,0,,,0,0,0,0,,,0,0,0,0,,,0,0,0,0,,,0,0,0,0,,,0,0,0,0,,,0,0,0,0,,,0,0,0,0,AAPL
2024-10-22 13:01:06.249102701+00:00,10,39,38,A,A,0,236.4,2000,130,203724,64912,,236.4,0,2000,0,1,,236.6,0,2000,0,1,,,0,0,0,0,,,0,0,0,0,,,0,0,0,0,,,0,0,0,0,,,0,0,0,0,,,0,0,0,0,,,0,0,0,0,,,0,0,0,0,AAPL
2024-10-22 13:01:06.249270813+00:00,10,39,38,C,A,1,236.6,2000,130,203664,64913,,236.4,0,2000,0,1,,,0,0,0,0,,,0,0,0,0,,,0,0,0,0,,,0,0,0,0,,,0,0,0,0,,,0,0,0,0,,,0,0,0,0,,,0,0,0,0,,,0,0,0,0,AAPL
2024-10-22 13:01:06.274585631+00:00,10,39,38,C,A,0,236.4,2000,130,203643,64914,,,0,0,0,0,,,0,0,0,0,,,0,0,0,0,,,0,0,0,0,,,0,0,0,0,,,0,0,0,0,,,0,0,0,0,,,0,0,0,0,,,0,0,0,0,,,0,0,0,0,AAPL
2024-10-22 13:01:06.274724883+00:00,10,39,38,A,B,0,232.6,2000,130,203737,64915,232.6,,2000,0,1,0,,,0,0,0,0,,,0,0,0,0,,,0,0,0,0,,,0,0,0,0,,,0,0,0,0,,,0,0,0,0,,,0,0,0,0,,,0,0,0,0,,,0,0,0,0,AAPL
2024-10-22 13:01:06.287919056+00:00,10,39,38,A,A,0,236.6,2000,130,203715,64916,232.6,236.6,2000,2000,1,1,,,0,0,0,0,,,0,0,0,0,,,0,0,0,0,,,0,0,0,0,,,0,0,0,0,,,0,0,0,0,,,0,0,0,0,,,0,0,0,0,,,0,0,0,0,AAPL
2024-10-22 13:01:06.306577830+00:00,10,39,38,C,A,0,236.6,2000,130,203755,64917,232.6,,2000,0,1,0,,,0,0,0,0,,,0,0,0,0,,,0,0,0,0,,,0,0,0,0,,,0,0,0,0,,,0,0,0,0,,,0,0,0,0,,,0,0,0,0,,,0,0,0,0,AAPL
2024-10-22 13:01:06.394372318+00:00,10,40,38,A,B,0,234.61,200,194,204277,106936,,234.61,0,200,0,0,,,0,0,0,0,,,0,0,0,0,,,0,0,0,0,,,0,0,0,0,,,0,0,0,0,,,0,0,0,0,,,0,0,0,0,,,0,0,0,0,,,0,0,0,0,AAPL
2024-10-22 13:01:06.394608467+00:00,10,41,38,A,B,0,234.56,200,194,55196,236036,,234.56,0,200,0,0,,,0,0,0,0,,,0,0,0,0,,,0,0,0,0,,,0,0,0,0,,,0,0,0,0,,,0,0,0,0,,,0,0,0,0,,,0,0,0,0,,,0,0,0,0,AAPL
2024-10-22 13:01:06.394611803+00:00,10,41,38,A,A,0,,0,194,57252,236037,,,0,0,0,0,,,0,0,0,0,,,0,0,0,0,,,0,0,0,0,,,0,0,0,0,,,0,0,0,0,,,0,0,0,0,,,0,0,0,0,,,0,0,0,0,,,0,0,0,0,AAPL
2024-10-22 13:01:06.394534837+00:00,10,40,38,A,A,0,,0,194,204243,106937,,,0,0,0,0,,,0,0,0,0,,,0,0,0,0,,,0,0,0,0,,,0,0,0,0,,,0,0,0,0,,,0,0,0,0,,,0,0,0,0,,,0,0,0,0,,,0,0,0,0,AAPL
2024-10-22 13:01:09.545556189+00:00,10,40,38,A,N,0,234.53,200,194,204546,107010,233.85,234.53,200,200,0,0,,,0,0,0,0,,,0,0,0,0,,,0,0,0,0,,,0,0,0,0,,,0,0,0,0,,,0,0,0,0,,,0,0,0,0,,,0,0,0,0,,,0,0,0,0,AAPL
2024-10-22 13:01:09.545730284+00:00,10,41,38,A,B,0,,0,194,56622,236455,233.91,,200,0,0,0,,,0,0,0,0,,,0,0,0,0,,,0,0,0,0,,,0,0,0,0,,,0,0,0,0,,,0,0,0,0,,,0,0,0,0,,,0,0,0,0,,,0,0,0,0,AAPL
2024-10-22 13:01:09.545764776+00:00,10,41,38,A,A,0,234.47,200,194,54163,236456,233.91,234.47,200,200,0,0,,,0,0,0,0,,,0,0,0,0,,,0,0,0,0,,,0,0,0,0,,,0,0,0,0,,,0,0,0,0,,,0,0,0,0,,,0,0,0,0,,,0,0,0,0,AAPL
2024-10-22 13:01:09.746375345+00:00,10,40,38,A,B,0,234.53,200,194,204318,107015,,234.53,0,200,0,0,,,0,0,0,0,,,0,0,0,0,,,0,0,0,0,,,0,0,0,0,,,0,0,0,0,,,0,0,0,0,,,0,0,0,0,,,0,0,0,0,,,0,0,0,0,AAPL
2024-10-22 13:01:09.746915064+00:00,10,41,38,A,B,0,234.47,200,194,60765,236471,,234.47,0,200,0,0,,,0,0,0,0,,,0,0,0,0,,,0,0,0,0,,,0,0,0,0,,,0,0,0,0,,,0,0,0,0,,,0,0,0,0,,,0,0,0,0,,,0,0,0,0,AAPL
2024-10-22 13:01:09.790830859+00:00,10,40,38,A,A,0,,0,194,204316,107019,,,0,0,0,0,,,0,0,0,0,,,0,0,0,0,,,0,0,0,0,,,0,0,0,0,,,0,0,0,0,,,0,0,0,0,,,0,0,0,0,,,0,0,0,0,,,0,0,0,0,AAPL
2024-10-22 13:01:09.791294353+00:00,10,41,38,A,A,0,,0,194,55494,236474,,,0,0,0,0,,,0,0,0,0,,,0,0,0,0,,,0,0,0,0,,,0,0,0,0,,,0,0,0,0,,,0,0,0,0,,,0,0,0,0,,,0,0,0,0,,,0,0,0,0,AAPL
2024-10-22 13:01:09.801902572+00:00,10,39,38,A,A,0,236.6,2000,130,204535,64940,232.6,236.6,2000,2000,1,1,,,0,0,0,0,,,0,0,0,0,,,0,0,0,0,,,0,0,0,0,,,0,0,0,0,,,0,0,0,0,,,0,0,0,0,,,0,0,0,0,,,0,0,0,0,AAPL
2024-10-22 13:01:10.830729789+00:00,10,40,38,A,A,0,234.53,200,194,204419,107041,,234.53,0,200,0,0,,,0,0,0,0,,,0,0,0,0,,,0,0,0,0,,,0,0,0,0,,,0,0,0,0,,,0,0,0,0,,,0,0,0,0,,,0,0,0,0,,,0,0,0,0,AAPL
2024-10-22 13:01:10.830819211+00:00,10,40,38,A,B,0,234.53,200,194,204327,107042,233.85,234.53,200,200,0,0,,,0,0,0,0,,,0,0,0,0,,,0,0,0,0,,,0,0,0,0,,,0,0,0,0,,,0,0,0,0,,,0,0,0,0,,,0,0,0,0,,,0,0,0,0,AAPL
2024-10-22 13:01:11.031995163+00:00,10,40,38,A,B,0,234.53,200,194,204426,107046,,234.53,0,200,0,0,,,0,0,0,0,,,0,0,0,0,,,0,0,0,0,,,0,0,0,0,,,0,0,0,0,,,0,0,0,0,,,0,0,0,0,,,0,0,0,0,,,0,0,0,0,AAPL
2024-10-22 13:01:11.339842892+00:00,10,40,38,A,A,0,,0,194,204266,107050,,,0,0,0,0,,,0,0,0,0,,,0,0,0,0,,,0,0,0,0,,,0,0,0,0,,,0,0,0,0,,,0,0,0,0,,,0,0,0,0,,,0,0,0,0,,,0,0,0,0,AAPL
2024-10-22 13:01:13.080130612+00:00,10,40,38,A,B,0,,0,194,204188,107082,233.85,,200,0,0,0,,,0,0,0,0,,,0,0,0,0,,,0,0,0,0,,,0,0,0,0,,,0,0,0,0,,,0,0,0,0,,,0,0,0,0,,,0,0,0,0,,,0,0,0,0,AAPL
2024-10-22 13:01:13.080136909+00:00,10,40,38,A,A,0,234.53,200,194,204122,107083,233.85,234.53,200,200,0,0,,,0,0,0,0,,,0,0,0,0,,,0,0,0,0,,,0,0,0,0,,,0,0,0,0,,,0,0,0,0,,,0,0,0,0,,,0,0,0,0,,,0,0,0,0,AAPL
2024-10-22 13:01:13.080370874+00:00,10,41,38,A,A,0,234.47,200,194,55556,236766,,234.47,0,200,0,0,,,0,0,0,0,,,0,0,0,0,,,0,0,0,0,,,0,0,0,0,,,0,0,0,0,,,0,0,0,0,,,0,0,0,0,,,0,0,0,0,,,0,0,0,0,AAPL
2024-10-22 13:01:13.080373124+00:00,10,41,38,A,B,0,234.47,200,194,54294,236767,233.91,234.47,200,200,0,0,,,0,0,0,0,,,0,0,0,0,,,0,0,0,0,,,0,0,0,0,,,0,0,0,0,,,0,0,0,0,,,0,0,0,0,,,0,0,0,0,,,0,0,0,0,AAPL
2024-10-22 13:01:13.253523162+00:00,10,41,38,A,B,0,234.47,200,194,55435,236774,,234.47,0,200,0,0,,,0,0,0,0,,,0,0,0,0,,,0,0,0,0,,,0,0,0,0,,,0,0,0,0,,,0,0,0,0,,,0,0,0,0,,,0,0,0,0,,,0,0,0,0,AAPL
2024-10-22 13:01:13.254029964+00:00,10,41,38,A,A,0,,0,194,54419,236776,,,0,0,0,0,,,0,0,0,0,,,0,0,0,0,,,0,0,0,0,,,0,0,0,0,,,0,0,0,0,,,0,0,0,0,,,0,0,0,0,,,0,0,0,0,,,0,0,0,0,AAPL
2024-10-22 13:01:13.554784600+00:00,10,40,38,A,B,0,234.53,200,194,204271,107087,,234.53,0,200,0,0,,,0,0,0,0,,,0,0,0,0,,,0,0,0,0,,,0,0,0,0,,,0,0,0,0,,,0,0,0,0,,,0,0,0,0,,,0,0,0,0,,,0,0,0,0,AAPL
2024-10-22 13:01:13.554870756+00:00,10,40,38,A,A,0,,0,194,204235,107088,,,0,0,0,0,,,0,0,0,0,,,0,0,0,0,,,0,0,0,0,,,0,0,0,0,,,0,0,0,0,,,0,0,0,0,,,0,0,0,0,,,0,0,0,0,,,0,0,0,0,AAPL
2024-10-22 13:01:14.361731742+00:00,10,40,38,A,A,0,234.53,200,194,204209,107102,,234.53,0,200,0,0,,,0,0,0,0,,,0,0,0,0,,,0,0,0,0,,,0,0,0,0,,,0,0,0,0,,,0,0,0,0,,,0,0,0,0,,,0,0,0,0,,,0,0,0,0,AAPL
2024-10-22 13:01:14.534439736+00:00,10,40,38,A,B,0,234.53,200,194,204230,107105,233.85,234.53,200,200,0,0,,,0,0,0,0,,,0,0,0,0,,,0,0,0,0,,,0,0,0,0,,,0,0,0,0,,,0,0,0,0,,,0,0,0,0,,,0,0,0,0,,,0,0,0,0,AAPL
2024-10-22 13:01:14.534699941+00:00,10,41,38,A,B,0,,0,194,55750,236834,233.91,,200,0,0,0,,,0,0,0,0,,,0,0,0,0,,,0,0,0,0,,,0,0,0,0,,,0,0,0,0,,,0,0,0,0,,,0,0,0,0,,,0,0,0,0,,,0,0,0,0,AAPL
2024-10-22 13:01:14.534705858+00:00,10,41,38,A,A,0,234.47,200,194,57200,236835,233.91,234.47,200,200,0,0,,,0,0,0,0,,,0,0,0,0,,,0,0,0,0,,,0,0,0,0,,,0,0,0,0,,,0,0,0,0,,,0,0,0,0,,,0,0,0,0,,,0,0,0,0,AAPL
2024-10-22 13:01:14.716470989+00:00,10,41,38,A,B,0,234.47,200,194,55731,236840,,234.47,0,200,0,0,,,0,0,0,0,,,0,0,0,0,,,0,0,0,0,,,0,0,0,0,,,0,0,0,0,,,0,0,0,0,,,0,0,0,0,,,0,0,0,0,,,0,0,0,0,AAPL
2024-10-22 13:01:14.716499781+00:00,10,41,38,A,A,0,,0,194,54728,236841,,,0,0,0,0,,,0,0,0,0,,,0,0,0,0,,,0,0,0,0,,,0,0,0,0,,,0,0,0,0,,,0,0,0,0,,,0,0,0,0,,,0,0,0,0,,,0,0,0,0,AAPL
2024-10-22 13:01:15.316348664+00:00,10,40,38,A,B,0,234.53,200,194,204216,107112,,234.53,0,200,0,0,,,0,0,0,0,,,0,0,0,0,,,0,0,0,0,,,0,0,0,0,,,0,0,0,0,,,0,0,0,0,,,0,0,0,0,,,0,0,0,0,,,0,0,0,0,AAPL
2024-10-22 13:01:15.316427829+00:00,10,40,38,A,A,0,,0,194,204158,107113,,,0,0,0,0,,,0,0,0,0,,,0,0,0,0,,,0,0,0,0,,,0,0,0,0,,,0,0,0,0,,,0,0,0,0,,,0,0,0,0,,,0,0,0,0,,,0,0,0,0,AAPL
2024-10-22 13:01:15.686368418+00:00,10,40,38,A,A,0,234.53,200,194,204492,107114,,234.53,0,200,0,0,,,0,0,0,0,,,0,0,0,0,,,0,0,0,0,,,0,0,0,0,,,0,0,0,0,,,0,0,0,0,,,0,0,0,0,,,0,0,0,0,,,0,0,0,0,AAPL
2024-10-22 13:01:15.686457589+00:00,10,40,38,A,B,0,234.53,200,194,204247,107115,233.85,234.53,200,200,0,0,,,0,0,0,0,,,0,0,0,0,,,0,0,0,0,,,0,0,0,0,,,0,0,0,0,,,0,0,0,0,,,0,0,0,0,,,0,0,0,0,,,0,0,0,0,AAPL
2024-10-22 13:01:16.115515061+00:00,10,40,38,A,B,0,234.53,200,194,204157,107130,,234.53,0,200,0,0,,,0,0,0,0,,,0,0,0,0,,,0,0,0,0,,,0,0,0,0,,,0,0,0,0,,,0,0,0,0,,,0,0,0,0,,,0,0,0,0,,,0,0,0,0,AAPL
2024-10-22 13:01:23.019302993+00:00,10,41,38,A,A,0,234.46,200,194,54809,237216,,234.46,0,200,0,0,,,0,0,0,0,,,0,0,0,0,,,0,0,0,0,,,0,0,0,0,,,0,0,0,0,,,0,0,0,0,,,0,0,0,0,,,0,0,0,0,,,0,0,0,0,AAPL
2024-10-22 13:01:23.029354486+00:00,10,39,38,A,A,0,236.4,2000,130,203801,65047,232.6,236.4,2000,2000,1,1,,236.6,0,2000,0,1,,,0,0,0,0,,,0,0,0,0,,,0,0,0,0,,,0,0,0,0,,,0,0,0,0,,,0,0,0,0,,,0,0,0,0,,,0,0,0,0,AAPL
2024-10-22 13:01:23.029531051+00:00,10,39,38,C,A,1,236.6,2000,130,203627,65048,232.6,236.4,2000,2000,1,1,,,0,0,0,0,,,0,0,0,0,,,0,0,0,0,,,0,0,0,0,,,0,0,0,0,,,0,0,0,0,,,0,0,0,0,,,0,0,0,0,,,0,0,0,0,AAPL
2024-10-22 13:01:23.287787756+00:00,10,40,38,A,B,0,234.53,200,194,202978,107230,233.85,234.53,200,200,0,0,,,0,0,0,0,,,0,0,0,0,,,0,0,0,0,,,0,0,0,0,,,0,0,0,0,,,0,0,0,0,,,0,0,0,0,,,0,0,0,0,,,0,0,0,0,AAPL
2024-10-22 13:01:23.288034769+00:00,10,41,38,A,B,0,234.46,200,194,54584,237253,233.91,234.46,200,200,0,0,,,0,0,0,0,,,0,0,0,0,,,0,0,0,0,,,0,0,0,0,,,0,0,0,0,,,0,0,0,0,,,0,0,0,0,,,0,0,0,0,,,0,0,0,0,AAPL
2024-10-22 13:01:23.288716827+00:00,10,39,38,C,B,0,232.6,2000,130,203475,65056,,236.4,0,2000,0,1,,,0,0,0,0,,,0,0,0,0,,,0,0,0,0,,,0,0,0,0,,,0,0,0,0,,,0,0,0,0,,,0,0,0,0,,,0,0,0,0,,,0,0,0,0,AAPL
2024-10-22 13:01:23.324298763+00:00,10,39,38,A,B,0,232.6,2000,130,203479,65060,232.6,236.4,2000,2000,1,1,,,0,0,0,0,,,0,0,0,0,,,0,0,0,0,,,0,0,0,0,,,0,0,0,0,,,0,0,0,0,,,0,0,0,0,,,0,0,0,0,,,0,0,0,0,AAPL
2024-10-22 13:01:23.494778818+00:00,10,41,38,A,A,0,,0,194,55429,237285,233.91,,200,0,0,0,,,0,0,0,0,,,0,0,0,0,,,0,0,0,0,,,0,0,0,0,,,0,0,0,0,,,0,0,0,0,,,0,0,0,0,,,0,0,0,0,,,0,0,0,0,AAPL
2024-10-22 13:01:26.036975517+00:00,10,41,38,A,A,0,234.46,200,194,56788,237444,233.91,234.46,200,200,0,0,,,0,0,0,0,,,0,0,0,0,,,0,0,0,0,,,0,0,0,0,,,0,0,0,0,,,0,0,0,0,,,0,0,0,0,,,0,0,0,0,,,0,0,0,0,AAPL
2024-10-22 13:01:26.222163301+00:00,10,41,38,A,A,0,,0,194,55597,237455,233.91,,200,0,0,0,,,0,0,0,0,,,0,0,0,0,,,0,0,0,0,,,0,0,0,0,,,0,0,0,0,,,0,0,0,0,,,0,0,0,0,,,0,0,0,0,,,0,0,0,0,AAPL
2024-10-22 13:01:29.987639699+00:00,10,41,38,A,B,0,,0,194,55472,237642,,,0,0,0,0,,,0,0,0,0,,,0,0,0,0,,,0,0,0,0,,,0,0,0,0,,,0,0,0,0,,,0,0,0,0,,,0,0,0,0,,,0,0,0,0,,,0,0,0,0,AAPL
2024-10-22 13:01:33.912197757+00:00,10,41,38,A,B,0,,0,194,55859,238217,233.87,,200,0,0,0,,,0,0,0,0,,,0,0,0,0,,,0,0,0,0,,,0,0,0,0,,,0,0,0,0,,,0,0,0,0,,,0,0,0,0,,,0,0,0,0,,,0,0,0,0,AAPL
2024-10-22 13:01:34.347929385+00:00,10,41,38,A,A,0,234.46,200,194,57398,238238,233.87,234.46,200,200,0,0,,,0,0,0,0,,,0,0,0,0,,,0,0,0,0,,,0,0,0,0,,,0,0,0,0,,,0,0,0,0,,,0,0,0,0,,,0,0,0,0,,,0,0,0,0,AAPL
2024-10-22 13:01:34.549875863+00:00,10,41,38,A,A,0,,0,194,55644,238246,233.87,,200,0,0,0,,,0,0,0,0,,,0,0,0,0,,,0,0,0,0,,,0,0,0,0,,,0,0,0,0,,,0,0,0,0,,,0,0,0,0,,,0,0,0,0,,,0,0,0,0,AAPL
2024-10-22 13:01:36.215119617+00:00,10,41,38,A,B,0,,0,194,56138,238374,,,0,0,0,0,,,0,0,0,0,,,0,0,0,0,,,0,0,0,0,,,0,0,0,0,,,0,0,0,0,,,0,0,0,0,,,0,0,0,0,,,0,0,0,0,,,0,0,0,0,AAPL
2024-10-22 13:01:36.215664998+00:00,10,41,38,A,B,0,,0,194,56304,238376,233.87,,200,0,0,0,,,0,0,0,0,,,0,0,0,0,,,0,0,0,0,,,0,0,0,0,,,0,0,0,0,,,0,0,0,0,,,0,0,0,0,,,0,0,0,0,,,0,0,0,0,AAPL
2024-10-22 13:01:36.223266940+00:00,10,41,38,A,B,0,,0,194,55217,238384,,,0,0,0,0,,,0,0,0,0,,,0,0,0,0,,,0,0,0,0,,,0,0,0,0,,,0,0,0,0,,,0,0,0,0,,,0,0,0,0,,,0,0,0,0,,,0,0,0,0,AAPL
2024-10-22 13:01:37.129019302+00:00,10,40,38,A,B,0,234.53,200,194,202379,107445,,234.53,0,200,0,0,,,0,0,0,0,,,0,0,0,0,,,0,0,0,0,,,0,0,0,0,,,0,0,0,0,,,0,0,0,0,,,0,0,0,0,,,0,0,0,0,,,0,0,0,0,AAPL
2024-10-22 13:01:37.129046164+00:00,10,40,38,A,B,0,234.53,200,194,202242,107446,233.81,234.53,200,200,0,0,,,0,0,0,0,,,0,0,0,0,,,0,0,0,0,,,0,0,0,0,,,0,0,0,0,,,0,0,0,0,,,0,0,0,0,,,0,0,0,0,,,0,0,0,0,AAPL
2024-10-22 13:01:38.082002416+00:00,10,41,38,A,B,0,,0,194,55457,239000,233.87,,200,0,0,0,,,0,0,0,0,,,0,0,0,0,,,0,0,0,0,,,0,0,0,0,,,0,0,0,0,,,0,0,0,0,,,0,0,0,0,,,0,0,0,0,,,0,0,0,0,AAPL
2024-10-22 13:01:38.082033725+00:00,10,41,38,A,A,0,234.46,200,194,54235,239001,233.87,234.46,200,200,0,0,,,0,0,0,0,,,0,0,0,0,,,0,0,0,0,,,0,0,0,0,,,0,0,0,0,,,0,0,0,0,,,0,0,0,0,,,0,0,0,0,,,0,0,0,0,AAPL
2024-10-22 13:01:38.484744239+00:00,10,41,38,A,B,0,234.46,200,194,55643,239015,,234.46,0,200,0,0,,,0,0,0,0,,,0,0,0,0,,,0,0,0,0,,,0,0,0,0,,,0,0,0,0,,,0,0,0,0,,,0,0,0,0,,,0,0,0,0,,,0,0,0,0,AAPL
2024-10-22 13:01:38.485254552+00:00,10,41,38,A,A,0,,0,194,56439,239016,,,0,0,0,0,,,0,0,0,0,,,0,0,0,0,,,0,0,0,0,,,0,0,0,0,,,0,0,0,0,,,0,0,0,0,,,0,0,0,0,,,0,0,0,0,,,0,0,0,0,AAPL
2024-10-22 13:01:39.994488505+00:00,10,40,38,A,B,0,234.53,200,194,202342,107484,,234.53,0,200,0,0,,,0,0,0,0,,,0,0,0,0,,,0,0,0,0,,,0,0,0,0,,,0,0,0,0,,,0,0,0,0,,,0,0,0,0,,,0,0,0,0,,,0,0,0,0,AAPL
2024-10-22 13:01:39.994575404+00:00,10,40,38,A,A,0,,0,194,202239,107485,,,0,0,0,0,,,0,0,0,0,,,0,0,0,0,,,0,0,0,0,,,0,0,0,0,,,0,0,0,0,,,0,0,0,0,,,0,0,0,0,,,0,0,0,0,,,0,0,0,0,AAPL
2024-10-22 13:01:40.196372934+00:00,10,40,38,A,A,0,234.52,200,194,202269,107495,,234.52,0,200,0,0,,,0,0,0,0,,,0,0,0,0,,,0,0,0,0,,,0,0,0,0,,,0,0,0,0,,,0,0,0,0,,,0,0,0,0,,,0,0,0,0,,,0,0,0,0,AAPL
2024-10-22 13:01:40.196462114+00:00,10,40,38,A,B,0,234.52,200,194,202275,107496,233.81,234.52,200,200,0,0,,,0,0,0,0,,,0,0,0,0,,,0,0,0,0,,,0,0,0,0,,,0,0,0,0,,,0,0,0,0,,,0,0,0,0,,,0,0,0,0,,,0,0,0,0,AAPL
2024-10-22 13:01:40.196918340+00:00,10,41,38,A,A,0,234.46,200,194,55633,239088,,234.46,0,200,0,0,,,0,0,0,0,,,0,0,0,0,,,0,0,0,0,,,0,0,0,0,,,0,0,0,0,,,0,0,0,0,,,0,0,0,0,,,0,0,0,0,,,0,0,0,0,AAPL
2024-10-22 13:01:40.539247341+00:00,10,41,38,A,B,0,234.46,200,194,63807,239127,233.87,234.46,200,200,0,0,,,0,0,0,0,,,0,0,0,0,,,0,0,0,0,,,0,0,0,0,,,0,0,0,0,,,0,0,0,0,,,0,0,0,0,,,0,0,0,0,,,0,0,0,0,AAPL
2024-10-22 13:01:48.389530161+00:00,10,41,38,A,B,0,234.46,200,194,56749,239851,,234.46,0,200,0,0,,,0,0,0,0,,,0,0,0,0,,,0,0,0,0,,,0,0,0,0,,,0,0,0,0,,,0,0,0,0,,,0,0,0,0,,,0,0,0,0,,,0,0,0,0,AAPL
2024-10-22 13:01:48.389669658+00:00,10,41,38,A,B,0,234.46,200,194,54458,239852,233.87,234.46,200,200,0,0,,,0,0,0,0,,,0,0,0,0,,,0,0,0,0,,,0,0,0,0,,,0,0,0,0,,,0,0,0,0,,,0,0,0,0,,,0,0,0,0,,,0,0,0,0,AAPL
2024-10-22 13:01:48.591193357+00:00,10,41,38,A,A,0,,0,194,55612,239863,233.87,,200,0,0,0,,,0,0,0,0,,,0,0,0,0,,,0,0,0,0,,,0,0,0,0,,,0,0,0,0,,,0,0,0,0,,,0,0,0,0,,,0,0,0,0,,,0,0,0,0,AAPL
2024-10-22 13:01:50.687430037+00:00,10,41,38,A,A,0,234.46,200,194,60575,240038,233.87,234.46,200,200,0,0,,,0,0,0,0,,,0,0,0,0,,,0,0,0,0,,,0,0,0,0,,,0,0,0,0,,,0,0,0,0,,,0,0,0,0,,,0,0,0,0,,,0,0,0,0,AAPL
2024-10-22 13:01:50.719040952+00:00,10,39,38,C,A,0,236.4,2000,130,204061,65266,232.6,,2000,0,1,0,,,0,0,0,0,,,0,0,0,0,,,0,0,0,0,,,0,0,0,0,,,0,0,0,0,,,0,0,0,0,,,0,0,0,0,,,0,0,0,0,,,0,0,0,0,AAPL
2024-10-22 13:01:50.729898443+00:00,10,39,38,A,A,0,236.4,2000,130,203650,65267,232.6,236.4,2000,2000,1,1,,,0,0,0,0,,,0,0,0,0,,,0,0,0,0,,,0,0,0,0,,,0,0,0,0,,,0,0,0,0,,,0,0,0,0,,,0,0,0,0,,,0,0,0,0,AAPL
2024-10-22 13:01:50.755042480+00:00,10,39,38,C,A,0,236.4,2000,130,203660,65268,232.6,,2000,0,1,0,,,0,0,0,0,,,0,0,0,0,,,0,0,0,0,,,0,0,0,0,,,0,0,0,0,,,0,0,0,0,,,0,0,0,0,,,0,0,0,0,,,0,0,0,0,AAPL
2024-10-22 13:01:50.901399492+00:00,10,41,38,A,A,0,,0,194,55058,240049,233.87,,200,0,0,0,,,0,0,0,0,,,0,0,0,0,,,0,0,0,0,,,0,0,0,0,,,0,0,0,0,,,0,0,0,0,,,0,0,0,0,,,0,0,0,0,,,0,0,0,0,AAPL
2024-10-22 13:01:53.703868437+00:00,10,41,38,A,A,0,234.44,200,194,55655,240237,233.87,234.44,200,200,0,0,,,0,0,0,0,,,0,0,0,0,,,0,0,0,0,,,0,0,0,0,,,0,0,0,0,,,0,0,0,0,,,0,0,0,0,,,0,0,0,0,,,0,0,0,0,AAPL
2024-10-22 13:01:54.010327960+00:00,10,41,38,A,A,0,,0,194,55747,240244,233.87,,200,0,0,0,,,0,0,0,0,,,0,0,0,0,,,0,0,0,0,,,0,0,0,0,,,0,0,0,0,,,0,0,0,0,,,0,0,0,0,,,0,0,0,0,,,0,0,0,0,AAPL
2024-10-22 13:01:54.021885946+00:00,10,39,38,A,A,0,236.4,2000,130,204346,65281,232.6,236.4,2000,2000,1,1,,,0,0,0,0,,,0,0,0,0,,,0,0,0,0,,,0,0,0,0,,,0,0,0,0,,,0,0,0,0,,,0,0,0,0,,,0,0,0,0,,,0,0,0,0,AAPL
2024-10-22 13:01:57.030297353+00:00,10,40,38,A,A,0,,0,194,203620,107812,233.81,,200,0,0,0,,,0,0,0,0,,,0,0,0,0,,,0,0,0,0,,,0,0,0,0,,,0,0,0,0,,,0,0,0,0,,,0,0,0,0,,,0,0,0,0,,,0,0,0,0,AAPL
2024-10-22 13:01:57.030331085+00:00,10,40,38,A,A,0,234.49,200,194,203571,107813,233.81,234.49,200,200,0,0,,,0,0,0,0,,,0,0,0,0,,,0,0,0,0,,,0,0,0,0,,,0,0,0,0,,,0,0,0,0,,,0,0,0,0,,,0,0,0,0,,,0,0,0,0,AAPL
2024-10-22 13:01:57.984476548+00:00,10,40,38,A,A,0,,0,194,203492,107833,233.81,,200,0,0,0,,,0,0,0,0,,,0,0,0,0,,,0,0,0,0,,,0,0,0,0,,,0,0,0,0,,,0,0,0,0,,,0,0,0,0,,,0,0,0,0,,,0,0,0,0,AAPL
2024-10-22 13:01:59.551303774+00:00,10,40,38,A,A,0,234.49,200,194,203415,107875,233.81,234.49,200,200,0,0,,,0,0,0,0,,,0,0,0,0,,,0,0,0,0,,,0,0,0,0,,,0,0,0,0,,,0,0,0,0,,,0,0,0,0,,,0,0,0,0,,,0,0,0,0,AAPL
2024-10-22 13:01:59.551522070+00:00,10,41,38,A,A,0,234.43,200,194,55930,240575,233.87,234.43,200,200,0,0,,,0,0,0,0,,,0,0,0,0,,,0,0,0,0,,,0,0,0,0,,,0,0,0,0,,,0,0,0,0,,,0,0,0,0,,,0,0,0,0,,,0,0,0,0,AAPL
2024-10-22 13:01:59.618106045+00:00,10,39,38,C,A,0,236.4,2000,130,203930,65307,232.6,,2000,0,1,0,,,0,0,0,0,,,0,0,0,0,,,0,0,0,0,,,0,0,0,0,,,0,0,0,0,,,0,0,0,0,,,0,0,0,0,,,0,0,0,0,,,0,0,0,0,AAPL
2024-10-22 13:01:59.632350400+00:00,10,39,38,A,A,0,236.4,2000,130,203793,65308,232.6,236.4,2000,2000,1,1,,,0,0,0,0,,,0,0,0,0,,,0,0,0,0,,,0,0,0,0,,,0,0,0,0,,,0,0,0,0,,,0,0,0,0,,,0,0,0,0,,,0,0,0,0,AAPL
2024-10-22 13:01:59.731864643+00:00,10,41,38,A,A,0,,0,194,55481,240585,233.87,,200,0,0,0,,,0,0,0,0,,,0,0,0,0,,,0,0,0,0,,,0,0,0,0,,,0,0,0,0,,,0,0,0,0,,,0,0,0,0,,,0,0,0,0,,,0,0,0,0,AAPL
2024-10-22 13:01:59.731889623+00:00,10,41,38,A,A,0,234.4,200,194,54503,240586,233.87,234.4,200,200,0,0,,,0,0,0,0,,,0,0,0,0,,,0,0,0,0,,,0,0,0,0,,,0,0,0,0,,,0,0,0,0,,,0,0,0,0,,,0,0,0,0,,,0,0,0,0,AAPL
2024-10-22 13:01:59.766234319+00:00,10,40,38,A,B,0,234.49,200,194,203590,107878,,234.49,0,200,0,0,,,0,0,0,0,,,0,0,0,0,,,0,0,0,0,,,0,0,0,0,,,0,0,0,0,,,0,0,0,0,,,0,0,0,0,,,0,0,0,0,,,0,0,0,0,AAPL
2024-10-22 13:01:59.766405929+00:00,10,41,38,A,B,0,234.4,200,194,55471,240588,,234.4,0,200,0,0,,,0,0,0,0,,,0,0,0,0,,,0,0,0,0,,,0,0,0,0,,,0,0,0,0,,,0,0,0,0,,,0,0,0,0,,,0,0,0,0,,,0,0,0,0,AAPL
2024-10-22 13:01:59.766362841+00:00,10,40,38,A,A,0,,0,194,203432,107879,,,0,0,0,0,,,0,0,0,0,,,0,0,0,0,,,0,0,0,0,,,0,0,0,0,,,0,0,0,0,,,0,0,0,0,,,0,0,0,0,,,0,0,0,0,,,0,0,0,0,AAPL
2024-10-22 13:01:59.766942727+00:00,10,41,38,A,A,0,,0,194,54728,240589,,,0,0,0,0,,,0,0,0,0,,,0,0,0,0,,,0,0,0,0,,,0,0,0,0,,,0,0,0,0,,,0,0,0,0,,,0,0,0,0,,,0,0,0,0,,,0,0,0,0,AAPL
2024-10-22 13:02:00.316293270+00:00,10,40,38,A,A,0,234.46,200,194,203367,108033,,234.46,0,200,0,0,,,0,0,0,0,,,0,0,0,0,,,0,0,0,0,,,0,0,0,0,,,0,0,0,0,,,0,0,0,0,,,0,0,0,0,,,0,0,0,0,,,0,0,0,0,AAPL
2024-10-22 13:02:00.316549870+00:00,10,41,38,A,B,0,,0,194,55740,241229,233.85,,200,0,0,0,,,0,0,0,0,,,0,0,0,0,,,0,0,0,0,,,0,0,0,0,,,0,0,0,0,,,0,0,0,0,,,0,0,0,0,,,0,0,0,0,,,0,0,0,0,AAPL
2024-10-22 13:02:00.316448917+00:00,10,40,38,A,B,0,234.46,200,194,203400,108034,233.79,234.46,200,200,0,0,,,0,0,0,0,,,0,0,0,0,,,0,0,0,0,,,0,0,0,0,,,0,0,0,0,,,0,0,0,0,,,0,0,0,0,,,0,0,0,0,,,0,0,0,0,AAPL
2024-10-22 13:02:00.316557418+00:00,10,41,38,A,A,0,234.4,200,194,54368,241230,233.85,234.4,200,200,0,0,,,0,0,0,0,,,0,0,0,0,,,0,0,0,0,,,0,0,0,0,,,0,0,0,0,,,0,0,0,0,,,0,0,0,0,,,0,0,0,0,,,0,0,0,0,AAPL
2024-10-22 13:02:00.470005970+00:00,10,41,38,A,B,0,234.4,200,194,55681,241309,,234.4,0,200,0,0,,,0,0,0,0,,,0,0,0,0,,,0,0,0,0,,,0,0,0,0,,,0,0,0,0,,,0,0,0,0,,,0,0,0,0,,,0,0,0,0,,,0,0,0,0,AAPL
2024-10-22 13:02:00.568877066+00:00,10,40,38,A,B,0,234.46,200,194,203403,108056,,234.46,0,200,0,0,,,0,0,0,0,,,0,0,0,0,,,0,0,0,0,,,0,0,0,0,,,0,0,0,0,,,0,0,0,0,,,0,0,0,0,,,0,0,0,0,,,0,0,0,0,AAPL
2024-10-22 13:02:00.568956601+00:00,10,40,38,A,A,0,,0,194,203386,108057,,,0,0,0,0,,,0,0,0,0,,,0,0,0,0,,,0,0,0,0,,,0,0,0,0,,,0,0,0,0,,,0,0,0,0,,,0,0,0,0,,,0,0,0,0,,,0,0,0,0,AAPL
2024-10-22 13:02:00.907191559+00:00,10,40,38,A,A,0,234.46,200,194,203341,108066,,234.46,0,200,0,0,,,0,0,0,0,,,0,0,0,0,,,0,0,0,0,,,0,0,0,0,,,0,0,0,0,,,0,0,0,0,,,0,0,0,0,,,0,0,0,0,,,0,0,0,0,AAPL
2024-10-22 13:02:00.907437008+00:00,10,41,38,A,B,0,234.4,200,194,55484,241372,233.85,234.4,200,200,0,0,,,0,0,0,0,,,0,0,0,0,,,0,0,0,0,,,0,0,0,0,,,0,0,0,0,,,0,0,0,0,,,0,0,0,0,,,0,0,0,0,,,0,0,0,0,AAPL
2024-10-22 13:02:00.907355352+00:00,10,40,38,A,B,0,234.46,200,194,203339,108067,233.79,234.46,200,200,0,0,,,0,0,0,0,,,0,0,0,0,,,0,0,0,0,,,0,0,0,0,,,0,0,0,0,,,0,0,0,0,,,0,0,0,0,,,0,0,0,0,,,0,0,0,0,AAPL
2024-10-22 13:02:00.954565712+00:00,10,41,38,A,B,0,234.4,200,194,54908,241388,,234.4,0,200,0,0,,,0,0,0,0,,,0,0,0,0,,,0,0,0,0,,,0,0,0,0,,,0,0,0,0,,,0,0,0,0,,,0,0,0,0,,,0,0,0,0,,,0,0,0,0,AAPL
2024-10-22 13:02:01.039586664+00:00,10,41,38,A,A,0,,0,194,55067,241403,,,0,0,0,0,,,0,0,0,0,,,0,0,0,0,,,0,0,0,0,,,0,0,0,0,,,0,0,0,0,,,0,0,0,0,,,0,0,0,0,,,0,0,0,0,,,0,0,0,0,AAPL
2024-10-22 13:02:01.302450404+00:00,10,40,38,A,B,0,234.46,200,194,203431,108085,,234.46,0,200,0,0,,,0,0,0,0,,,0,0,0,0,,,0,0,0,0,,,0,0,0,0,,,0,0,0,0,,,0,0,0,0,,,0,0,0,0,,,0,0,0,0,,,0,0,0,0,AAPL
2024-10-22 13:02:01.302530838+00:00,10,40,38,A,A,0,,0,194,203282,108086,,,0,0,0,0,,,0,0,0,0,,,0,0,0,0,,,0,0,0,0,,,0,0,0,0,,,0,0,0,0,,,0,0,0,0,,,0,0,0,0,,,0,0,0,0,,,0,0,0,0,AAPL
2024-10-22 13:02:01.962666910+00:00,10,41,38,A,A,0,234.4,200,194,55474,241490,,234.4,0,200,0,0,,,0,0,0,0,,,0,0,0,0,,,0,0,0,0,,,0,0,0,0,,,0,0,0,0,,,0,0,0,0,,,0,0,0,0,,,0,0,0,0,,,0,0,0,0,AAPL
2024-10-22 13:02:04.159759980+00:00,10,41,38,A,A,0,,0,194,56772,241688,,,0,0,0,0,,,0,0,0,0,,,0,0,0,0,,,0,0,0,0,,,0,0,0,0,,,0,0,0,0,,,0,0,0,0,,,0,0,0,0,,,0,0,0,0,,,0,0,0,0,AAPL
2024-10-22 13:02:05.515991779+00:00,10,40,38,A,A,0,234.45,200,194,203029,108161,,234.45,0,200,0,0,,,0,0,0,0,,,0,0,0,0,,,0,0,0,0,,,0,0,0,0,,,0,0,0,0,,,0,0,0,0,,,0,0,0,0,,,0,0,0,0,,,0,0,0,0,AAPL
2024-10-22 13:02:05.516047714+00:00,10,40,38,A,B,0,234.45,200,194,203021,108162,233.8,234.45,200,200,0,0,,,0,0,0,0,,,0,0,0,0,,,0,0,0,0,,,0,0,0,0,,,0,0,0,0,,,0,0,0,0,,,0,0,0,0,,,0,0,0,0,,,0,0,0,0,AAPL
2024-10-22 13:02:05.516463024+00:00,10,41,38,A,B,0,,0,194,61253,241778,233.85,,200,0,0,0,,,0,0,0,0,,,0,0,0,0,,,0,0,0,0,,,0,0,0,0,,,0,0,0,0,,,0,0,0,0,,,0,0,0,0,,,0,0,0,0,,,0,0,0,0,AAPL
2024-10-22 13:02:05.516474921+00:00,10,41,38,A,A,0,234.4,200,194,54801,241779,233.85,234.4,200,200,0,0,,,0,0,0,0,,,0,0,0,0,,,0,0,0,0,,,0,0,0,0,,,0,0,0,0,,,0,0,0,0,,,0,0,0,0,,,0,0,0,0,,,0,0,0,0,AAPL
2024-10-22 13:02:05.717975849+00:00,10,41,38,A,B,0,234.4,200,194,55472,241792,,234.4,0,200,0,0,,,0,0,0,0,,,0,0,0,0,,,0,0,0,0,,,0,0,0,0,,,0,0,0,0,,,0,0,0,0,,,0,0,0,0,,,0,0,0,0,,,0,0,0,0,AAPL
2024-10-22 13:02:05.717869486+00:00,10,40,38,A,B,0,234.45,200,194,203375,108163,,234.45,0,200,0,0,,,0,0,0,0,,,0,0,0,0,,,0,0,0,0,,,0,0,0,0,,,0,0,0,0,,,0,0,0,0,,,0,0,0,0,,,0,0,0,0,,,0,0,0,0,AAPL
2024-10-22 13:02:05.717988485+00:00,10,40,38,A,A,0,,0,194,203161,108164,,,0,0,0,0,,,0,0,0,0,,,0,0,0,0,,,0,0,0,0,,,0,0,0,0,,,0,0,0,0,,,0,0,0,0,,,0,0,0,0,,,0,0,0,0,,,0,0,0,0,AAPL
2024-10-22 13:02:05.718485110+00:00,10,41,38,A,A,0,,0,194,55817,241793,,,0,0,0,0,,,0,0,0,0,,,0,0,0,0,,,0,0,0,0,,,0,0,0,0,,,0,0,0,0,,,0,0,0,0,,,0,0,0,0,,,0,0,0,0,,,0,0,0,0,AAPL
2024-10-22 13:02:05.873843152+00:00,10,40,38,A,B,0,,0,194,203085,108167,233.8,,200,0,0,0,,,0,0,0,0,,,0,0,0,0,,,0,0,0,0,,,0,0,0,0,,,0,0,0,0,,,0,0,0,0,,,0,0,0,0,,,0,0,0,0,,,0,0,0,0,AAPL
2024-10-22 13:02:05.873851078+00:00,10,40,38,A,A,0,234.45,200,194,203064,108168,233.8,234.45,200,200,0,0,,,0,0,0,0,,,0,0,0,0,,,0,0,0,0,,,0,0,0,0,,,0,0,0,0,,,0,0,0,0,,,0,0,0,0,,,0,0,0,0,,,0,0,0,0,AAPL
2024-10-22 13:02:05.874163973+00:00,10,41,38,A,B,0,,0,194,54170,241804,233.85,,200,0,0,0,,,0,0,0,0,,,0,0,0,0,,,0,0,0,0,,,0,0,0,0,,,0,0,0,0,,,0,0,0,0,,,0,0,0,0,,,0,0,0,0,,,0,0,0,0,AAPL
2024-10-22 13:02:05.874173004+00:00,10,41,38,A,A,0,234.4,200,194,55916,241805,233.85,234.4,200,200,0,0,,,0,0,0,0,,,0,0,0,0,,,0,0,0,0,,,0,0,0,0,,,0,0,0,0,,,0,0,0,0,,,0,0,0,0,,,0,0,0,0,,,0,0,0,0,AAPL
2024-10-22 13:02:05.890406248+00:00,10,39,38,C,B,0,232.6,2000,130,204412,65352,,236.4,0,2000,0,1,,,0,0,0,0,,,0,0,0,0,,,0,0,0,0,,,0,0,0,0,,,0,0,0,0,,,0,0,0,0,,,0,0,0,0,,,0,0,0,0,,,0,0,0,0,AAPL
2024-10-22 13:02:05.926702118+00:00,10,39,38,A,B,0,232.6,2000,130,203924,65353,232.6,236.4,2000,2000,1,1,,,0,0,0,0,,,0,0,0,0,,,0,0,0,0,,,0,0,0,0,,,0,0,0,0,,,0,0,0,0,,,0,0,0,0,,,0,0,0,0,,,0,0,0,0,AAPL
2024-10-22 13:02:06.061717786+00:00,10,40,38,A,B,0,234.45,200,194,203114,108183,,234.45,0,200,0,0,,,0,0,0,0,,,0,0,0,0,,,0,0,0,0,,,0,0,0,0,,,0,0,0,0,,,0,0,0,0,,,0,0,0,0,,,0,0,0,0,,,0,0,0,0,AAPL
2024-10-22 13:02:06.061852443+00:00,10,41,38,A,B,0,234.4,200,194,55375,241865,,234.4,0,200,0,0,,,0,0,0,0,,,0,0,0,0,,,0,0,0,0,,,0,0,0,0,,,0,0,0,0,,,0,0,0,0,,,0,0,0,0,,,0,0,0,0,,,0,0,0,0,AAPL
2024-10-22 13:02:06.061868937+00:00,10,40,38,A,A,0,,0,194,203019,108184,,,0,0,0,0,,,0,0,0,0,,,0,0,0,0,,,0,0,0,0,,,0,0,0,0,,,0,0,0,0,,,0,0,0,0,,,0,0,0,0,,,0,0,0,0,,,0,0,0,0,AAPL
2024-10-22 13:02:06.062396039+00:00,10,41,38,A,A,0,,0,194,55549,241866,,,0,0,0,0,,,0,0,0,0,,,0,0,0,0,,,0,0,0,0,,,0,0,0,0,,,0,0,0,0,,,0,0,0,0,,,0,0,0,0,,,0,0,0,0,,,0,0,0,0,AAPL
2024-10-22 13:02:06.950583493+00:00,10,40,38,A,A,0,234.45,200,194,202991,108205,,234.45,0,200,0,0,,,0,0,0,0,,,0,0,0,0,,,0,0,0,0,,,0,0,0,0,,,0,0,0,0,,,0,0,0,0,,,0,0,0,0,,,0,0,0,0,,,0,0,0,0,AAPL
2024-10-22 13:02:06.951234790+00:00,10,41,38,A,A,0,234.4,200,194,55741,241915,,234.4,0,200,0,0,,,0,0,0,0,,,0,0,0,0,,,0,0,0,0,,,0,0,0,0,,,0,0,0,0,,,0,0,0,0,,,0,0,0,0,,,0,0,0,0,,,0,0,0,0,AAPL
2024-10-22 13:02:07.818990054+00:00,10,40,38,A,B,0,234.45,200,194,203329,108213,233.8,234.45,200,200,0,0,,,0,0,0,0,,,0,0,0,0,,,0,0,0,0,,,0,0,0,0,,,0,0,0,0,,,0,0,0,0,,,0,0,0,0,,,0,0,0,0,,,0,0,0,0,AAPL
2024-10-22 13:02:07.819322386+00:00,10,41,38,A,B,0,234.4,200,194,55466,241969,233.85,234.4,200,200,0,0,,,0,0,0,0,,,0,0,0,0,,,0,0,0,0,,,0,0,0,0,,,0,0,0,0,,,0,0,0,0,,,0,0,0,0,,,0,0,0,0,,,0,0,0,0,AAPL
2024-10-22 13:02:07.819833846+00:00,10,39,38,C,B,0,232.6,2000,130,203891,65369,,236.4,0,2000,0,1,,,0,0,0,0,,,0,0,0,0,,,0,0,0,0,,,0,0,0,0,,,0,0,0,0,,,0,0,0,0,,,0,0,0,0,,,0,0,0,0,,,0,0,0,0,AAPL
2024-10-22 13:02:07.855369566+00:00,10,39,38,A,B,0,232.6,2000,130,203972,65370,232.6,236.4,2000,2000,1,1,,,0,0,0,0,,,0,0,0,0,,,0,0,0,0,,,0,0,0,0,,,0,0,0,0,,,0,0,0,0,,,0,0,0,0,,,0,0,0,0,,,0,0,0,0,AAPL
2024-10-22 13:02:07.957491097+00:00,10,40,38,A,B,0,234.45,200,194,203150,108225,,234.45,0,200,0,0,,,0,0,0,0,,,0,0,0,0,,,0,0,0,0,,,0,0,0,0,,,0,0,0,0,,,0,0,0,0,,,0,0,0,0,,,0,0,0,0,,,0,0,0,0,AAPL
2024-10-22 13:02:07.958056650+00:00,10,41,38,A,B,0,234.4,200,194,55536,241988,,234.4,0,200,0,0,,,0,0,0,0,,,0,0,0,0,,,0,0,0,0,,,0,0,0,0,,,0,0,0,0,,,0,0,0,0,,,0,0,0,0,,,0,0,0,0,,,0,0,0,0,AAPL
2024-10-22 13:02:08.462051899+00:00,10,39,38,A,A,0,236.0,2000,130,204081,65372,232.6,236.0,2000,2000,1,1,,236.4,0,2000,0,1,,,0,0,0,0,,,0,0,0,0,,,0,0,0,0,,,0,0,0,0,,,0,0,0,0,,,0,0,0,0,,,0,0,0,0,,,0,0,0,0,AAPL
2024-10-22 13:02:08.462254791+00:00,10,39,38,C,A,1,236.4,2000,130,203933,65373,232.6,236.0,2000,2000,1,1,,,0,0,0,0,,,0,0,0,0,,,0,0,0,0,,,0,0,0,0,,,0,0,0,0,,,0,0,0,0,,,0,0,0,0,,,0,0,0,0,,,0,0,0,0,AAPL
2024-10-22 13:02:11.109399410+00:00,10,40,38,A,B,0,234.45,200,194,203339,108293,233.8,234.45,200,200,0,0,,,0,0,0,0,,,0,0,0,0,,,0,0,0,0,,,0,0,0,0,,,0,0,0,0,,,0,0,0,0,,,0,0,0,0,,,0,0,0,0,,,0,0,0,0,AAPL
2024-10-22 13:02:11.109777600+00:00,10,41,38,A,B,0,234.4,200,194,55507,242210,233.85,234.4,200,200,0,0,,,0,0,0,0,,,0,0,0,0,,,0,0,0,0,,,0,0,0,0,,,0,0,0,0,,,0,0,0,0,,,0,0,0,0,,,0,0,0,0,,,0,0,0,0,AAPL
2024-10-22 13:02:11.110228753+00:00,10,39,38,C,B,0,232.6,2000,130,204258,65381,,236.0,0,2000,0,1,,,0,0,0,0,,,0,0,0,0,,,0,0,0,0,,,0,0,0,0,,,0,0,0,0,,,0,0,0,0,,,0,0,0,0,,,0,0,0,0,,,0,0,0,0,AAPL
2024-10-22 13:02:11.146222741+00:00,10,39,38,A,B,0,232.6,2000,130,203825,65383,232.6,236.0,2000,2000,1,1,,,0,0,0,0,,,0,0,0,0,,,0,0,0,0,,,0,0,0,0,,,0,0,0,0,,,0,0,0,0,,,0,0,0,0,,,0,0,0,0,,,0,0,0,0,AAPL
2024-10-22 13:02:11.236169629+00:00,10,40,38,A,B,0,234.45,200,194,203291,108297,,234.45,0,200,0,0,,,0,0,0,0,,,0,0,0,0,,,0,0,0,0,,,0,0,0,0,,,0,0,0,0,,,0,0,0,0,,,0,0,0,0,,,0,0,0,0,,,0,0,0,0,AAPL
2024-10-22 13:02:11.236286733+00:00,10,40,38,A,A,0,,0,194,203144,108298,,,0,0,0,0,,,0,0,0,0,,,0,0,0,0,,,0,0,0,0,,,0,0,0,0,,,0,0,0,0,,,0,0,0,0,,,0,0,0,0,,,0,0,0,0,,,0,0,0,0,AAPL
2024-10-22 13:02:11.259474205+00:00,10,41,38,A,B,0,234.4,200,194,55383,242230,,234.4,0,200,0,0,,,0,0,0,0,,,0,0,0,0,,,0,0,0,0,,,0,0,0,0,,,0,0,0,0,,,0,0,0,0,,,0,0,0,0,,,0,0,0,0,,,0,0,0,0,AAPL
2024-10-22 13:02:11.259975426+00:00,10,41,38,A,A,0,,0,194,54503,242231,,,0,0,0,0,,,0,0,0,0,,,0,0,0,0,,,0,0,0,0,,,0,0,0,0,,,0,0,0,0,,,0,0,0,0,,,0,0,0,0,,,0,0,0,0,,,0,0,0,0,AAPL
2024-10-22 13:02:12.301878068+00:00,10,41,38,A,A,0,234.4,200,194,55540,242278,,234.4,0,200,0,0,,,0,0,0,0,,,0,0,0,0,,,0,0,0,0,,,0,0,0,0,,,0,0,0,0,,,0,0,0,0,,,0,0,0,0,,,0,0,0,0,,,0,0,0,0,AAPL
2024-10-22 13:02:12.302073466+00:00,10,40,38,A,A,0,234.45,200,194,203267,108306,,234.45,0,200,0,0,,,0,0,0,0,,,0,0,0,0,,,0,0,0,0,,,0,0,0,0,,,0,0,0,0,,,0,0,0,0,,,0,0,0,0,,,0,0,0,0,,,0,0,0,0,AAPL
2024-10-22 13:02:13.009349765+00:00,10,40,38,A,B,0,234.45,200,194,202998,108315,233.8,234.45,200,200,0,0,,,0,0,0,0,,,0,0,0,0,,,0,0,0,0,,,0,0,0,0,,,0,0,0,0,,,0,0,0,0,,,0,0,0,0,,,0,0,0,0,,,0,0,0,0,AAPL
2024-10-22 13:02:13.009841908+00:00,10,41,38,A,B,0,234.4,200,194,54823,242305,233.85,234.4,200,200,0,0,,,0,0,0,0,,,0,0,0,0,,,0,0,0,0,,,0,0,0,0,,,0,0,0,0,,,0,0,0,0,,,0,0,0,0,,,0,0,0,0,,,0,0,0,0,AAPL
2024-10-22 13:02:13.066915906+00:00,10,40,38,A,B,0,234.45,200,194,203028,108316,,234.45,0,200,0,0,,,0,0,0,0,,,0,0,0,0,,,0,0,0,0,,,0,0,0,0,,,0,0,0,0,,,0,0,0,0,,,0,0,0,0,,,0,0,0,0,,,0,0,0,0,AAPL
2024-10-22 13:02:13.140948710+00:00,10,40,38,A,A,0,,0,194,203041,108322,,,0,0,0,0,,,0,0,0,0,,,0,0,0,0,,,0,0,0,0,,,0,0,0,0,,,0,0,0,0,,,0,0,0,0,,,0,0,0,0,,,0,0,0,0,,,0,0,0,0,AAPL
2024-10-22 13:02:13.140964586+00:00,10,40,38,A,A,0,234.46,200,194,203040,108323,,234.46,0,200,0,0,,,0,0,0,0,,,0,0,0,0,,,0,0,0,0,,,0,0,0,0,,,0,0,0,0,,,0,0,0,0,,,0,0,0,0,,,0,0,0,0,,,0,0,0,0,AAPL
2024-10-22 13:02:13.141191893+00:00,10,41,38,A,B,0,234.4,200,194,54549,242343,,234.4,0,200,0,0,,,0,0,0,0,,,0,0,0,0,,,0,0,0,0,,,0,0,0,0,,,0,0,0,0,,,0,0,0,0,,,0,0,0,0,,,0,0,0,0,,,0,0,0,0,AAPL
2024-10-22 13:02:15.280060722+00:00,10,40,38,A,B,0,234.46,200,194,203136,108382,233.8,234.46,200,200,0,0,,,0,0,0,0,,,0,0,0,0,,,0,0,0,0,,,0,0,0,0,,,0,0,0,0,,,0,0,0,0,,,0,0,0,0,,,0,0,0,0,,,0,0,0,0,AAPL
2024-10-22 13:02:15.280562052+00:00,10,41,38,A,B,0,234.4,200,194,55358,242503,233.85,234.4,200,200,0,0,,,0,0,0,0,,,0,0,0,0,,,0,0,0,0,,,0,0,0,0,,,0,0,0,0,,,0,0,0,0,,,0,0,0,0,,,0,0,0,0,,,0,0,0,0,AAPL
2024-10-22 13:02:15.381725626+00:00,10,40,38,A,B,0,234.46,200,194,203100,108388,,234.46,0,200,0,0,,,0,0,0,0,,,0,0,0,0,,,0,0,0,0,,,0,0,0,0,,,0,0,0,0,,,0,0,0,0,,,0,0,0,0,,,0,0,0,0,,,0,0,0,0,AAPL
2024-10-22 13:02:15.399071260+00:00,10,40,38,A,A,0,,0,194,203075,108389,,,0,0,0,0,,,0,0,0,0,,,0,0,0,0,,,0,0,0,0,,,0,0,0,0,,,0,0,0,0,,,0,0,0,0,,,0,0,0,0,,,0,0,0,0,,,0,0,0,0,AAPL
2024-10-22 13:02:15.431711540+00:00,10,40,38,A,B,0,,0,194,203135,108391,233.81,,200,0,0,0,,,0,0,0,0,,,0,0,0,0,,,0,0,0,0,,,0,0,0,0,,,0,0,0,0,,,0,0,0,0,,,0,0,0,0,,,0,0,0,0,,,0,0,0,0,AAPL
2024-10-22 13:02:15.431833029+00:00,10,40,38,A,A,0,234.47,200,194,203092,108392,233.81,234.47,200,200,0,0,,,0,0,0,0,,,0,0,0,0,,,0,0,0,0,,,0,0,0,0,,,0,0,0,0,,,0,0,0,0,,,0,0,0,0,,,0,0,0,0,,,0,0,0,0,AAPL
2024-10-22 13:02:18.175574786+00:00,10,40,38,A,B,0,234.47,200,194,203412,108422,,234.47,0,200,0,0,,,0,0,0,0,,,0,0,0,0,,,0,0,0,0,,,0,0,0,0,,,0,0,0,0,,,0,0,0,0,,,0,0,0,0,,,0,0,0,0,,,0,0,0,0,AAPL
2024-10-22 13:02:18.326171393+00:00,10,41,38,A,B,0,234.4,200,194,55478,242651,,234.4,0,200,0,0,,,0,0,0,0,,,0,0,0,0,,,0,0,0,0,,,0,0,0,0,,,0,0,0,0,,,0,0,0,0,,,0,0,0,0,,,0,0,0,0,,,0,0,0,0,AAPL
2024-10-22 13:02:18.326679264+00:00,10,41,38,A,A,0,,0,194,55365,242652,,,0,0,0,0,,,0,0,0,0,,,0,0,0,0,,,0,0,0,0,,,0,0,0,0,,,0,0,0,0,,,0,0,0,0,,,0,0,0,0,,,0,0,0,0,,,0,0,0,0,AAPL
2024-10-22 13:02:19.503356379+00:00,10,40,38,A,B,0,234.47,200,194,203391,108441,233.82,234.47,200,200,0,0,,,0,0,0,0,,,0,0,0,0,,,0,0,0,0,,,0,0,0,0,,,0,0,0,0,,,0,0,0,0,,,0,0,0,0,,,0,0,0,0,,,0,0,0,0,AAPL
2024-10-22 13:02:19.503530810+00:00,10,41,38,A,B,0,,0,194,55600,242712,233.87,,200,0,0,0,,,0,0,0,0,,,0,0,0,0,,,0,0,0,0,,,0,0,0,0,,,0,0,0,0,,,0,0,0,0,,,0,0,0,0,,,0,0,0,0,,,0,0,0,0,AAPL
2024-10-22 13:02:19.565072054+00:00,10,41,38,A,A,0,234.42,200,194,55146,242715,233.87,234.42,200,200,0,0,,,0,0,0,0,,,0,0,0,0,,,0,0,0,0,,,0,0,0,0,,,0,0,0,0,,,0,0,0,0,,,0,0,0,0,,,0,0,0,0,,,0,0,0,0,AAPL
2024-10-22 13:02:20.520605903+00:00,10,41,38,A,A,0,,0,194,55792,242780,233.87,,200,0,0,0,,,0,0,0,0,,,0,0,0,0,,,0,0,0,0,,,0,0,0,0,,,0,0,0,0,,,0,0,0,0,,,0,0,0,0,,,0,0,0,0,,,0,0,0,0,AAPL
2024-10-22 13:02:21.580316759+00:00,10,39,38,C,B,0,232.6,2000,130,203916,65515,,236.0,0,2000,0,1,,,0,0,0,0,,,0,0,0,0,,,0,0,0,0,,,0,0,0,0,,,0,0,0,0,,,0,0,0,0,,,0,0,0,0,,,0,0,0,0,,,0,0,0,0,AAPL
2024-10-22 13:02:21.592014999+00:00,10,39,38,A,B,0,232.4,2000,130,203732,65516,232.4,236.0,2000,2000,1,1,,,0,0,0,0,,,0,0,0,0,,,0,0,0,0,,,0,0,0,0,,,0,0,0,0,,,0,0,0,0,,,0,0,0,0,,,0,0,0,0,,,0,0,0,0,AAPL
2024-10-22 13:02:23.769187594+00:00,10,41,38,A,A,0,234.42,200,194,56193,242918,233.87,234.42,200,200,0,0,,,0,0,0,0,,,0,0,0,0,,,0,0,0,0,,,0,0,0,0,,,0,0,0,0,,,0,0,0,0,,,0,0,0,0,,,0,0,0,0,,,0,0,0,0,AAPL
2024-10-22 13:02:24.952650596+00:00,10,40,38,A,B,0,234.47,200,194,204259,108539,,234.47,0,200,0,0,,,0,0,0,0,,,0,0,0,0,,,0,0,0,0,,,0,0,0,0,,,0,0,0,0,,,0,0,0,0,,,0,0,0,0,,,0,0,0,0,,,0,0,0,0,AAPL
2024-10-22 13:02:25.235881872+00:00,10,40,38,A,B,0,234.47,200,194,203878,108543,233.81,234.47,200,200,0,0,,,0,0,0,0,,,0,0,0,0,,,0,0,0,0,,,0,0,0,0,,,0,0,0,0,,,0,0,0,0,,,0,0,0,0,,,0,0,0,0,,,0,0,0,0,AAPL
2024-10-22 13:02:25.352175180+00:00,10,40,38,A,B,0,234.47,200,194,203753,108546,,234.47,0,200,0,0,,,0,0,0,0,,,0,0,0,0,,,0,0,0,0,,,0,0,0,0,,,0,0,0,0,,,0,0,0,0,,,0,0,0,0,,,0,0,0,0,,,0,0,0,0,AAPL
2024-10-22 13:02:25.352406995+00:00,10,41,38,A,B,0,234.42,200,194,57204,243030,,234.42,0,200,0,0,,,0,0,0,0,,,0,0,0,0,,,0,0,0,0,,,0,0,0,0,,,0,0,0,0,,,0,0,0,0,,,0,0,0,0,,,0,0,0,0,,,0,0,0,0,AAPL
2024-10-22 13:02:25.352943378+00:00,10,41,38,A,A,0,,0,194,55473,243031,,,0,0,0,0,,,0,0,0,0,,,0,0,0,0,,,0,0,0,0,,,0,0,0,0,,,0,0,0,0,,,0,0,0,0,,,0,0,0,0,,,0,0,0,0,,,0,0,0,0,AAPL
2024-10-22 13:02:25.586856548+00:00,10,39,38,C,A,0,236.0,2000,130,203709,65537,232.4,,2000,0,1,0,,,0,0,0,0,,,0,0,0,0,,,0,0,0,0,,,0,0,0,0,,,0,0,0,0,,,0,0,0,0,,,0,0,0,0,,,0,0,0,0,,,0,0,0,0,AAPL
2024-10-22 13:02:25.597608396+00:00,10,39,38,A,A,0,236.4,2000,130,203542,65538,232.4,236.4,2000,2000,1,1,,,0,0,0,0,,,0,0,0,0,,,0,0,0,0,,,0,0,0,0,,,0,0,0,0,,,0,0,0,0,,,0,0,0,0,,,0,0,0,0,,,0,0,0,0,AAPL
2024-10-22 13:02:26.636927599+00:00,10,41,38,A,A,0,234.42,200,194,61126,243103,,234.42,0,200,0,0,,,0,0,0,0,,,0,0,0,0,,,0,0,0,0,,,0,0,0,0,,,0,0,0,0,,,0,0,0,0,,,0,0,0,0,,,0,0,0,0,,,0,0,0,0,AAPL
2024-10-22 13:02:31.549883764+00:00,10,40,38,A,B,0,234.47,200,194,203922,108623,233.81,234.47,200,200,0,0,,,0,0,0,0,,,0,0,0,0,,,0,0,0,0,,,0,0,0,0,,,0,0,0,0,,,0,0,0,0,,,0,0,0,0,,,0,0,0,0,,,0,0,0,0,AAPL
2024-10-22 13:02:31.550154786+00:00,10,41,38,A,B,0,234.42,200,194,70570,243360,233.86,234.42,200,200,0,0,,,0,0,0,0,,,0,0,0,0,,,0,0,0,0,,,0,0,0,0,,,0,0,0,0,,,0,0,0,0,,,0,0,0,0,,,0,0,0,0,,,0,0,0,0,AAPL
2024-10-22 13:02:31.751702089+00:00,10,40,38,A,B,0,234.47,200,194,203981,108629,,234.47,0,200,0,0,,,0,0,0,0,,,0,0,0,0,,,0,0,0,0,,,0,0,0,0,,,0,0,0,0,,,0,0,0,0,,,0,0,0,0,,,0,0,0,0,,,0,0,0,0,AAPL
2024-10-22 13:02:31.751856839+00:00,10,41,38,A,B,0,234.42,200,194,58231,243384,,234.42,0,200,0,0,,,0,0,0,0,,,0,0,0,0,,,0,0,0,0,,,0,0,0,0,,,0,0,0,0,,,0,0,0,0,,,0,0,0,0,,,0,0,0,0,,,0,0,0,0,AAPL
2024-10-22 13:02:32.490146408+00:00,10,41,38,A,A,0,,0,194,55339,243413,,,0,0,0,0,,,0,0,0,0,,,0,0,0,0,,,0,0,0,0,,,0,0,0,0,,,0,0,0,0,,,0,0,0,0,,,0,0,0,0,,,0,0,0,0,,,0,0,0,0,AAPL
2024-10-22 13:02:32.659604053+00:00,10,41,38,A,A,0,234.42,200,194,55500,243429,,234.42,0,200,0,0,,,0,0,0,0,,,0,0,0,0,,,0,0,0,0,,,0,0,0,0,,,0,0,0,0,,,0,0,0,0,,,0,0,0,0,,,0,0,0,0,,,0,0,0,0,AAPL
2024-10-22 13:02:37.602178320+00:00,10,39,38,A,B,0,232.6,2000,130,203412,65643,232.6,236.4,2000,2000,1,1,232.4,,2000,0,1,0,,,0,0,0,0,,,0,0,0,0,,,0,0,0,0,,,0,0,0,0,,,0,0,0,0,,,0,0,0,0,,,0,0,0,0,,,0,0,0,0,AAPL
2024-10-22 13:02:37.602880092+00:00,10,39,38,C,B,1,232.4,2000,130,202922,65644,232.6,236.4,2000,2000,1,1,,,0,0,0,0,,,0,0,0,0,,,0,0,0,0,,,0,0,0,0,,,0,0,0,0,,,0,0,0,0,,,0,0,0,0,,,0,0,0,0,,,0,0,0,0,AAPL
2024-10-22 13:02:37.831384565+00:00,10,40,38,A,B,0,234.47,200,194,204005,108703,233.81,234.47,200,200,0,0,,,0,0,0,0,,,0,0,0,0,,,0,0,0,0,,,0,0,0,0,,,0,0,0,0,,,0,0,0,0,,,0,0,0,0,,,0,0,0,0,,,0,0,0,0,AAPL
2024-10-22 13:02:49.395464105+00:00,10,41,38,A,B,0,234.42,200,194,56143,244037,233.86,234.42,200,200,0,0,,,0,0,0,0,,,0,0,0,0,,,0,0,0,0,,,0,0,0,0,,,0,0,0,0,,,0,0,0,0,,,0,0,0,0,,,0,0,0,0,,,0,0,0,0,AAPL
2024-10-22 13:02:49.906708599+00:00,10,41,38,A,B,0,234.42,200,194,56064,244065,,234.42,0,200,0,0,,,0,0,0,0,,,0,0,0,0,,,0,0,0,0,,,0,0,0,0,,,0,0,0,0,,,0,0,0,0,,,0,0,0,0,,,0,0,0,0,,,0,0,0,0,AAPL
2024-10-22 13:02:51.836779856+00:00,10,41,38,A,B,0,234.42,200,194,55674,244106,233.86,234.42,200,200,0,0,,,0,0,0,0,,,0,0,0,0,,,0,0,0,0,,,0,0,0,0,,,0,0,0,0,,,0,0,0,0,,,0,0,0,0,,,0,0,0,0,,,0,0,0,0,AAPL
2024-10-22 13:02:57.594969420+00:00,10,39,38,C,A,0,236.4,2000,130,204021,65738,232.6,,2000,0,1,0,,,0,0,0,0,,,0,0,0,0,,,0,0,0,0,,,0,0,0,0,,,0,0,0,0,,,0,0,0,0,,,0,0,0,0,,,0,0,0,0,,,0,0,0,0,AAPL
2024-10-22 13:03:00.060419758+00:00,10,40,38,A,B,0,234.47,200,194,203553,108981,,234.47,0,200,0,0,,,0,0,0,0,,,0,0,0,0,,,0,0,0,0,,,0,0,0,0,,,0,0,0,0,,,0,0,0,0,,,0,0,0,0,,,0,0,0,0,,,0,0,0,0,AAPL
2024-10-22 13:03:00.060429370+00:00,10,40,38,A,A,0,,0,194,203564,108982,,,0,0,0,0,,,0,0,0,0,,,0,0,0,0,,,0,0,0,0,,,0,0,0,0,,,0,0,0,0,,,0,0,0,0,,,0,0,0,0,,,0,0,0,0,,,0,0,0,0,AAPL
2024-10-22 13:03:00.060778668+00:00,10,41,38,A,B,0,234.42,200,194,64956,244675,,234.42,0,200,0,0,,,0,0,0,0,,,0,0,0,0,,,0,0,0,0,,,0,0,0,0,,,0,0,0,0,,,0,0,0,0,,,0,0,0,0,,,0,0,0,0,,,0,0,0,0,AAPL
2024-10-22 13:03:00.060787923+00:00,10,41,38,A,A,0,,0,194,60454,244677,,,0,0,0,0,,,0,0,0,0,,,0,0,0,0,,,0,0,0,0,,,0,0,0,0,,,0,0,0,0,,,0,0,0,0,,,0,0,0,0,,,0,0,0,0,,,0,0,0,0,AAPL
2024-10-22 13:03:00.060790549+00:00,10,40,38,A,B,0,,0,194,203813,108984,233.82,,200,0,0,0,,,0,0,0,0,,,0,0,0,0,,,0,0,0,0,,,0,0,0,0,,,0,0,0,0,,,0,0,0,0,,,0,0,0,0,,,0,0,0,0,,,0,0,0,0,AAPL
2024-10-22 13:03:00.060800466+00:00,10,40,38,A,A,0,234.48,200,194,203572,108985,233.82,234.48,200,200,0,0,,,0,0,0,0,,,0,0,0,0,,,0,0,0,0,,,0,0,0,0,,,0,0,0,0,,,0,0,0,0,,,0,0,0,0,,,0,0,0,0,,,0,0,0,0,AAPL
2024-10-22 13:03:00.060979935+00:00,10,41,38,A,B,0,,0,194,56040,244679,233.87,,200,0,0,0,,,0,0,0,0,,,0,0,0,0,,,0,0,0,0,,,0,0,0,0,,,0,0,0,0,,,0,0,0,0,,,0,0,0,0,,,0,0,0,0,,,0,0,0,0,AAPL
2024-10-22 13:03:00.061016383+00:00,10,41,38,A,A,0,234.43,200,194,55558,244680,233.87,234.43,200,200,0,0,,,0,0,0,0,,,0,0,0,0,,,0,0,0,0,,,0,0,0,0,,,0,0,0,0,,,0,0,0,0,,,0,0,0,0,,,0,0,0,0,,,0,0,0,0,AAPL
2024-10-22 13:03:01.328310284+00:00,10,40,38,A,B,0,234.48,200,194,203486,109121,,234.48,0,200,0,0,,,0,0,0,0,,,0,0,0,0,,,0,0,0,0,,,0,0,0,0,,,0,0,0,0,,,0,0,0,0,,,0,0,0,0,,,0,0,0,0,,,0,0,0,0,AAPL
2024-10-22 13:03:01.328320348+00:00,10,40,38,A,A,0,,0,194,203462,109122,,,0,0,0,0,,,0,0,0,0,,,0,0,0,0,,,0,0,0,0,,,0,0,0,0,,,0,0,0,0,,,0,0,0,0,,,0,0,0,0,,,0,0,0,0,,,0,0,0,0,AAPL
2024-10-22 13:03:01.328483981+00:00,10,41,38,A,B,0,234.43,200,194,55557,245132,,234.43,0,200,0,0,,,0,0,0,0,,,0,0,0,0,,,0,0,0,0,,,0,0,0,0,,,0,0,0,0,,,0,0,0,0,,,0,0,0,0,,,0,0,0,0,,,0,0,0,0,AAPL
2024-10-22 13:03:01.328493824+00:00,10,41,38,A,A,0,,0,194,59708,245133,,,0,0,0,0,,,0,0,0,0,,,0,0,0,0,,,0,0,0,0,,,0,0,0,0,,,0,0,0,0,,,0,0,0,0,,,0,0,0,0,,,0,0,0,0,,,0,0,0,0,AAPL
2024-10-22 13:03:02.769284668+00:00,10,40,38,A,N,0,234.51,200,194,203890,109142,233.82,234.51,200,200,0,0,,,0,0,0,0,,,0,0,0,0,,,0,0,0,0,,,0,0,0,0,,,0,0,0,0,,,0,0,0,0,,,0,0,0,0,,,0,0,0,0,,,0,0,0,0,AAPL
2024-10-22 13:03:02.769772047+00:00,10,41,38,A,B,0,,0,194,55473,245215,233.87,,200,0,0,0,,,0,0,0,0,,,0,0,0,0,,,0,0,0,0,,,0,0,0,0,,,0,0,0,0,,,0,0,0,0,,,0,0,0,0,,,0,0,0,0,,,0,0,0,0,AAPL
2024-10-22 13:03:02.769773351+00:00,10,41,38,A,A,0,234.46,200,194,54842,245216,233.87,234.46,200,200,0,0,,,0,0,0,0,,,0,0,0,0,,,0,0,0,0,,,0,0,0,0,,,0,0,0,0,,,0,0,0,0,,,0,0,0,0,,,0,0,0,0,,,0,0,0,0,AAPL
2024-10-22 13:03:05.864524256+00:00,10,41,38,A,B,0,234.46,200,194,55813,245379,,234.46,0,200,0,0,,,0,0,0,0,,,0,0,0,0,,,0,0,0,0,,,0,0,0,0,,,0,0,0,0,,,0,0,0,0,,,0,0,0,0,,,0,0,0,0,,,0,0,0,0,AAPL
2024-10-22 13:03:08.064205986+00:00,10,41,38,A,B,0,234.46,200,194,55573,245504,233.88,234.46,200,200,0,0,,,0,0,0,0,,,0,0,0,0,,,0,0,0,0,,,0,0,0,0,,,0,0,0,0,,,0,0,0,0,,,0,0,0,0,,,0,0,0,0,,,0,0,0,0,AAPL
2024-10-22 13:03:37.308205218+00:00,10,39,38,A,A,0,236.4,2000,130,204258,65986,232.6,236.4,2000,2000,1,1,,,0,0,0,0,,,0,0,0,0,,,0,0,0,0,,,0,0,0,0,,,0,0,0,0,,,0,0,0,0,,,0,0,0,0,,,0,0,0,0,,,0,0,0,0,AAPL
2024-10-22 13:03:45.301713067+00:00,10,39,38,A,B,0,232.8,2000,130,203910,66005,232.8,236.4,2000,2000,1,1,232.6,,2000,0,1,0,,,0,0,0,0,,,0,0,0,0,,,0,0,0,0,,,0,0,0,0,,,0,0,0,0,,,0,0,0,0,,,0,0,0,0,,,0,0,0,0,AAPL
2024-10-22 13:03:45.302061729+00:00,10,39,38,C,B,1,232.6,2000,130,203690,66006,232.8,236.4,2000,2000,1,1,,,0,0,0,0,,,0,0,0,0,,,0,0,0,0,,,0,0,0,0,,,0,0,0,0,,,0,0,0,0,,,0,0,0,0,,,0,0,0,0,,,0,0,0,0,AAPL
2024-10-22 13:03:57.136862162+00:00,10,39,38,C,B,0,232.8,2000,130,204088,66031,,236.4,0,2000,0,1,,,0,0,0,0,,,0,0,0,0,,,0,0,0,0,,,0,0,0,0,,,0,0,0,0,,,0,0,0,0,,,0,0,0,0,,,0,0,0,0,,,0,0,0,0,AAPL
2024-10-22 13:03:57.172353361+00:00,10,39,38,A,B,0,232.8,2000,130,203691,66033,232.8,236.4,2000,2000,1,1,,,0,0,0,0,,,0,0,0,0,,,0,0,0,0,,,0,0,0,0,,,0,0,0,0,,,0,0,0,0,,,0,0,0,0,,,0,0,0,0,,,0,0,0,0,AAPL
2024-10-22 13:03:57.197068492+00:00,10,39,38,C,A,0,236.4,2000,130,203724,66034,232.8,,2000,0,1,0,,,0,0,0,0,,,0,0,0,0,,,0,0,0,0,,,0,0,0,0,,,0,0,0,0,,,0,0,0,0,,,0,0,0,0,,,0,0,0,0,,,0,0,0,0,AAPL
2024-10-22 13:03:57.220302239+00:00,10,39,38,A,A,0,236.4,2000,130,203828,66035,232.8,236.4,2000,2000,1,1,,,0,0,0,0,,,0,0,0,0,,,0,0,0,0,,,0,0,0,0,,,0,0,0,0,,,0,0,0,0,,,0,0,0,0,,,0,0,0,0,,,0,0,0,0,AAPL
2024-10-22 13:03:57.350036638+00:00,10,41,38,A,B,0,234.46,200,194,55621,247516,,234.46,0,200,0,0,,,0,0,0,0,,,0,0,0,0,,,0,0,0,0,,,0,0,0,0,,,0,0,0,0,,,0,0,0,0,,,0,0,0,0,,,0,0,0,0,,,0,0,0,0,AAPL
2024-10-22 13:03:57.350065061+00:00,10,41,38,A,B,0,234.46,200,194,61826,247517,233.85,234.46,200,200,0,0,,,0,0,0,0,,,0,0,0,0,,,0,0,0,0,,,0,0,0,0,,,0,0,0,0,,,0,0,0,0,,,0,0,0,0,,,0,0,0,0,,,0,0,0,0,AAPL
2024-10-22 13:04:00.091726651+00:00,10,40,38,A,B,0,234.51,200,194,202832,109929,,234.51,0,200,0,0,,,0,0,0,0,,,0,0,0,0,,,0,0,0,0,,,0,0,0,0,,,0,0,0,0,,,0,0,0,0,,,0,0,0,0,,,0,0,0,0,,,0,0,0,0,AAPL
2024-10-22 13:04:00.091749636+00:00,10,40,38,A,A,0,,0,194,202926,109932,,,0,0,0,0,,,0,0,0,0,,,0,0,0,0,,,0,0,0,0,,,0,0,0,0,,,0,0,0,0,,,0,0,0,0,,,0,0,0,0,,,0,0,0,0,,,0,0,0,0,AAPL
2024-10-22 13:04:00.092158373+00:00,10,41,38,A,B,0,234.46,200,194,59003,248000,,234.46,0,200,0,0,,,0,0,0,0,,,0,0,0,0,,,0,0,0,0,,,0,0,0,0,,,0,0,0,0,,,0,0,0,0,,,0,0,0,0,,,0,0,0,0,,,0,0,0,0,AAPL
2024-10-22 13:04:00.519393255+00:00,10,39,38,C,B,0,232.8,2000,130,203687,66074,,236.4,0,2000,0,1,,,0,0,0,0,,,0,0,0,0,,,0,0,0,0,,,0,0,0,0,,,0,0,0,0,,,0,0,0,0,,,0,0,0,0,,,0,0,0,0,,,0,0,0,0,AAPL
2024-10-22 13:04:00.519496128+00:00,10,40,38,A,A,0,234.49,200,194,202773,110005,,234.49,0,200,0,0,,,0,0,0,0,,,0,0,0,0,,,0,0,0,0,,,0,0,0,0,,,0,0,0,0,,,0,0,0,0,,,0,0,0,0,,,0,0,0,0,,,0,0,0,0,AAPL
2024-10-22 13:04:00.530274984+00:00,10,39,38,A,B,0,232.6,2000,130,203609,66075,232.6,236.4,2000,2000,1,1,,,0,0,0,0,,,0,0,0,0,,,0,0,0,0,,,0,0,0,0,,,0,0,0,0,,,0,0,0,0,,,0,0,0,0,,,0,0,0,0,,,0,0,0,0,AAPL
2024-10-22 13:04:00.548083087+00:00,10,39,38,C,B,0,232.6,2000,130,203592,66076,,236.4,0,2000,0,1,,,0,0,0,0,,,0,0,0,0,,,0,0,0,0,,,0,0,0,0,,,0,0,0,0,,,0,0,0,0,,,0,0,0,0,,,0,0,0,0,,,0,0,0,0,AAPL
2024-10-22 13:04:00.559346983+00:00,10,39,38,A,B,0,232.4,2000,130,203635,66077,232.4,236.4,2000,2000,1,1,,,0,0,0,0,,,0,0,0,0,,,0,0,0,0,,,0,0,0,0,,,0,0,0,0,,,0,0,0,0,,,0,0,0,0,,,0,0,0,0,,,0,0,0,0,AAPL
2024-10-22 13:04:00.978503390+00:00,10,40,38,A,A,0,,0,194,202794,110034,,,0,0,0,0,,,0,0,0,0,,,0,0,0,0,,,0,0,0,0,,,0,0,0,0,,,0,0,0,0,,,0,0,0,0,,,0,0,0,0,,,0,0,0,0,,,0,0,0,0,AAPL
2024-10-22 13:04:00.978734117+00:00,10,41,38,A,A,0,,0,194,55950,248330,,,0,0,0,0,,,0,0,0,0,,,0,0,0,0,,,0,0,0,0,,,0,0,0,0,,,0,0,0,0,,,0,0,0,0,,,0,0,0,0,,,0,0,0,0,,,0,0,0,0,AAPL
2024-10-22 13:04:01.270817963+00:00,10,40,38,A,B,0,,0,194,202617,110044,233.83,,200,0,0,0,,,0,0,0,0,,,0,0,0,0,,,0,0,0,0,,,0,0,0,0,,,0,0,0,0,,,0,0,0,0,,,0,0,0,0,,,0,0,0,0,,,0,0,0,0,AAPL
2024-10-22 13:04:01.270824154+00:00,10,40,38,A,A,0,234.49,200,194,202615,110045,233.83,234.49,200,200,0,0,,,0,0,0,0,,,0,0,0,0,,,0,0,0,0,,,0,0,0,0,,,0,0,0,0,,,0,0,0,0,,,0,0,0,0,,,0,0,0,0,,,0,0,0,0,AAPL
2024-10-22 13:04:01.271070928+00:00,10,41,38,A,B,0,,0,194,55361,248353,233.88,,200,0,0,0,,,0,0,0,0,,,0,0,0,0,,,0,0,0,0,,,0,0,0,0,,,0,0,0,0,,,0,0,0,0,,,0,0,0,0,,,0,0,0,0,,,0,0,0,0,AAPL
2024-10-22 13:04:01.271082702+00:00,10,41,38,A,A,0,234.44,200,194,54627,248354,233.88,234.44,200,200,0,0,,,0,0,0,0,,,0,0,0,0,,,0,0,0,0,,,0,0,0,0,,,0,0,0,0,,,0,0,0,0,,,0,0,0,0,,,0,0,0,0,,,0,0,0,0,AAPL
2024-10-22 13:04:01.281475105+00:00,10,39,38,A,B,0,232.8,2000,130,204097,66085,232.8,236.4,2000,2000,1,1,232.4,,2000,0,1,0,,,0,0,0,0,,,0,0,0,0,,,0,0,0,0,,,0,0,0,0,,,0,0,0,0,,,0,0,0,0,,,0,0,0,0,,,0,0,0,0,AAPL
2024-10-22 13:04:01.281663916+00:00,10,39,38,C,B,1,232.4,2000,130,203629,66086,232.8,236.4,2000,2000,1,1,,,0,0,0,0,,,0,0,0,0,,,0,0,0,0,,,0,0,0,0,,,0,0,0,0,,,0,0,0,0,,,0,0,0,0,,,0,0,0,0,,,0,0,0,0,AAPL
2024-10-22 13:04:02.679756132+00:00,10,40,38,A,B,0,234.49,200,194,202895,110069,,234.49,0,200,0,0,,,0,0,0,0,,,0,0,0,0,,,0,0,0,0,,,0,0,0,0,,,0,0,0,0,,,0,0,0,0,,,0,0,0,0,,,0,0,0,0,,,0,0,0,0,AAPL
2024-10-22 13:04:02.679762584+00:00,10,40,38,A,A,0,,0,194,202661,110070,,,0,0,0,0,,,0,0,0,0,,,0,0,0,0,,,0,0,0,0,,,0,0,0,0,,,0,0,0,0,,,0,0,0,0,,,0,0,0,0,,,0,0,0,0,,,0,0,0,0,AAPL
2024-10-22 13:04:02.680095024+00:00,10,41,38,A,A,0,,0,194,55845,248434,233.88,,200,0,0,0,,,0,0,0,0,,,0,0,0,0,,,0,0,0,0,,,0,0,0,0,,,0,0,0,0,,,0,0,0,0,,,0,0,0,0,,,0,0,0,0,,,0,0,0,0,AAPL
2024-10-22 13:04:02.680096837+00:00,10,41,38,A,B,0,,0,194,60869,248435,,,0,0,0,0,,,0,0,0,0,,,0,0,0,0,,,0,0,0,0,,,0,0,0,0,,,0,0,0,0,,,0,0,0,0,,,0,0,0,0,,,0,0,0,0,,,0,0,0,0,AAPL
2024-10-22 13:04:02.781727128+00:00,10,40,38,A,A,0,234.49,200,194,202649,110072,,234.49,0,200,0,0,,,0,0,0,0,,,0,0,0,0,,,0,0,0,0,,,0,0,0,0,,,0,0,0,0,,,0,0,0,0,,,0,0,0,0,,,0,0,0,0,,,0,0,0,0,AAPL
2024-10-22 13:04:02.781868969+00:00,10,41,38,A,B,0,,0,194,55205,248443,233.88,,200,0,0,0,,,0,0,0,0,,,0,0,0,0,,,0,0,0,0,,,0,0,0,0,,,0,0,0,0,,,0,0,0,0,,,0,0,0,0,,,0,0,0,0,,,0,0,0,0,AAPL
2024-10-22 13:04:02.781874871+00:00,10,41,38,A,A,0,234.44,200,194,54430,248444,233.88,234.44,200,200,0,0,,,0,0,0,0,,,0,0,0,0,,,0,0,0,0,,,0,0,0,0,,,0,0,0,0,,,0,0,0,0,,,0,0,0,0,,,0,0,0,0,,,0,0,0,0,AAPL
2024-10-22 13:04:02.781857593+00:00,10,40,38,A,B,0,234.49,200,194,202740,110073,233.83,234.49,200,200,0,0,,,0,0,0,0,,,0,0,0,0,,,0,0,0,0,,,0,0,0,0,,,0,0,0,0,,,0,0,0,0,,,0,0,0,0,,,0,0,0,0,,,0,0,0,0,AAPL
2024-10-22 13:04:04.054546944+00:00,10,39,38,C,B,0,232.8,2000,130,203668,66104,,236.4,0,2000,0,1,,,0,0,0,0,,,0,0,0,0,,,0,0,0,0,,,0,0,0,0,,,0,0,0,0,,,0,0,0,0,,,0,0,0,0,,,0,0,0,0,,,0,0,0,0,AAPL
2024-10-22 13:04:04.066977044+00:00,10,39,38,A,B,0,232.4,2000,130,203632,66107,232.4,236.4,2000,2000,1,1,,,0,0,0,0,,,0,0,0,0,,,0,0,0,0,,,0,0,0,0,,,0,0,0,0,,,0,0,0,0,,,0,0,0,0,,,0,0,0,0,,,0,0,0,0,AAPL
2024-10-22 13:04:04.082736187+00:00,10,39,38,A,B,0,232.8,2000,130,203606,66108,232.8,236.4,2000,2000,1,1,232.4,,2000,0,1,0,,,0,0,0,0,,,0,0,0,0,,,0,0,0,0,,,0,0,0,0,,,0,0,0,0,,,0,0,0,0,,,0,0,0,0,,,0,0,0,0,AAPL
2024-10-22 13:04:04.082923111+00:00,10,39,38,C,B,1,232.4,2000,130,203560,66109,232.8,236.4,2000,2000,1,1,,,0,0,0,0,,,0,0,0,0,,,0,0,0,0,,,0,0,0,0,,,0,0,0,0,,,0,0,0,0,,,0,0,0,0,,,0,0,0,0,,,0,0,0,0,AAPL
2024-10-22 13:04:05.272040384+00:00,10,41,38,A,B,0,234.44,200,194,56081,248572,,234.44,0,200,0,0,,,0,0,0,0,,,0,0,0,0,,,0,0,0,0,,,0,0,0,0,,,0,0,0,0,,,0,0,0,0,,,0,0,0,0,,,0,0,0,0,,,0,0,0,0,AAPL
2024-10-22 13:04:05.472928968+00:00,10,40,38,A,B,0,234.49,200,194,202636,110114,,234.49,0,200,0,0,,,0,0,0,0,,,0,0,0,0,,,0,0,0,0,,,0,0,0,0,,,0,0,0,0,,,0,0,0,0,,,0,0,0,0,,,0,0,0,0,,,0,0,0,0,AAPL
2024-10-22 13:04:06.773658511+00:00,10,40,38,A,B,0,234.49,200,194,202641,110132,233.8,234.49,200,200,0,0,,,0,0,0,0,,,0,0,0,0,,,0,0,0,0,,,0,0,0,0,,,0,0,0,0,,,0,0,0,0,,,0,0,0,0,,,0,0,0,0,,,0,0,0,0,AAPL
2024-10-22 13:04:07.781073503+00:00,10,41,38,A,B,0,234.44,200,194,60906,248694,233.85,234.44,200,200,0,0,,,0,0,0,0,,,0,0,0,0,,,0,0,0,0,,,0,0,0,0,,,0,0,0,0,,,0,0,0,0,,,0,0,0,0,,,0,0,0,0,,,0,0,0,0,AAPL
2024-10-22 13:04:22.656344039+00:00,10,39,10888,A,A,0,422.4,2000,130,203746,98524,,422.4,0,2000,0,1,,,0,0,0,0,,,0,0,0,0,,,0,0,0,0,,,0,0,0,0,,,0,0,0,0,,,0,0,0,0,,,0,0,0,0,,,0,0,0,0,,,0,0,0,0,MSFT
2024-10-22 13:04:22.746035758+00:00,10,39,10888,C,A,0,422.4,2000,130,203536,98527,,,0,0,0,0,,,0,0,0,0,,,0,0,0,0,,,0,0,0,0,,,0,0,0,0,,,0,0,0,0,,,0,0,0,0,,,0,0,0,0,,,0,0,0,0,,,0,0,0,0,MSFT
2024-10-22 13:04:39.496481937+00:00,10,39,38,C,A,0,236.4,2000,130,203955,66348,232.8,,2000,0,1,0,,,0,0,0,0,,,0,0,0,0,,,0,0,0,0,,,0,0,0,0,,,0,0,0,0,,,0,0,0,0,,,0,0,0,0,,,0,0,0,0,,,0,0,0,0,AAPL
2024-10-22 13:04:39.508079999+00:00,10,39,38,A,A,0,236.4,2000,130,203865,66349,232.8,236.4,2000,2000,1,1,,,0,0,0,0,,,0,0,0,0,,,0,0,0,0,,,0,0,0,0,,,0,0,0,0,,,0,0,0,0,,,0,0,0,0,,,0,0,0,0,,,0,0,0,0,AAPL
2024-10-22 13:04:39.529168825+00:00,10,39,38,C,A,0,236.4,2000,130,203721,66350,232.8,,2000,0,1,0,,,0,0,0,0,,,0,0,0,0,,,0,0,0,0,,,0,0,0,0,,,0,0,0,0,,,0,0,0,0,,,0,0,0,0,,,0,0,0,0,,,0,0,0,0,AAPL
2024-10-22 13:04:46.811747072+00:00,10,39,38,C,B,0,232.8,2000,130,203971,66400,,,0,0,0,0,,,0,0,0,0,,,0,0,0,0,,,0,0,0,0,,,0,0,0,0,,,0,0,0,0,,,0,0,0,0,,,0,0,0,0,,,0,0,0,0,,,0,0,0,0,AAPL
2024-10-22 13:04:46.841473623+00:00,10,39,38,A,B,0,232.8,2000,130,203975,66402,232.8,,2000,0,1,0,,,0,0,0,0,,,0,0,0,0,,,0,0,0,0,,,0,0,0,0,,,0,0,0,0,,,0,0,0,0,,,0,0,0,0,,,0,0,0,0,,,0,0,0,0,AAPL
2024-10-22 13:04:51.513321560+00:00,10,39,38,A,A,0,236.4,2000,130,204395,66443,232.8,236.4,2000,2000,1,1,,,0,0,0,0,,,0,0,0,0,,,0,0,0,0,,,0,0,0,0,,,0,0,0,0,,,0,0,0,0,,,0,0,0,0,,,0,0,0,0,,,0,0,0,0,AAPL
2024-10-22 13:04:55.504903405+00:00,10,39,38,C,A,0,236.4,2000,130,203991,66473,232.8,,2000,0,1,0,,,0,0,0,0,,,0,0,0,0,,,0,0,0,0,,,0,0,0,0,,,0,0,0,0,,,0,0,0,0,,,0,0,0,0,,,0,0,0,0,,,0,0,0,0,AAPL
2024-10-22 13:04:56.941230129+00:00,10,39,38,C,B,0,232.8,2000,130,203737,66479,,,0,0,0,0,,,0,0,0,0,,,0,0,0,0,,,0,0,0,0,,,0,0,0,0,,,0,0,0,0,,,0,0,0,0,,,0,0,0,0,,,0,0,0,0,,,0,0,0,0,AAPL
2024-10-22 13:04:56.978952950+00:00,10,39,38,A,B,0,232.6,2000,130,203752,66480,232.6,,2000,0,1,0,,,0,0,0,0,,,0,0,0,0,,,0,0,0,0,,,0,0,0,0,,,0,0,0,0,,,0,0,0,0,,,0,0,0,0,,,0,0,0,0,,,0,0,0,0,AAPL
2024-10-22 13:04:59.567413161+00:00,10,39,38,A,A,0,236.4,2000,130,203894,66502,232.6,236.4,2000,2000,1,1,,,0,0,0,0,,,0,0,0,0,,,0,0,0,0,,,0,0,0,0,,,0,0,0,0,,,0,0,0,0,,,0,0,0,0,,,0,0,0,0,,,0,0,0,0,AAPL
2024-10-22 13:04:59.619527716+00:00,10,39,38,C,A,0,236.4,2000,130,203597,66503,232.6,,2000,0,1,0,,,0,0,0,0,,,0,0,0,0,,,0,0,0,0,,,0,0,0,0,,,0,0,0,0,,,0,0,0,0,,,0,0,0,0,,,0,0,0,0,,,0,0,0,0,AAPL
2024-10-22 13:04:59.630877305+00:00,10,39,38,A,A,0,236.4,2000,130,203562,66504,232.6,236.4,2000,2000,1,1,,,0,0,0,0,,,0,0,0,0,,,0,0,0,0,,,0,0,0,0,,,0,0,0,0,,,0,0,0,0,,,0,0,0,0,,,0,0,0,0,,,0,0,0,0,AAPL
2024-10-22 13:05:00.028490887+00:00,10,40,38,A,B,0,234.49,200,194,203355,110996,,234.49,0,200,0,0,,,0,0,0,0,,,0,0,0,0,,,0,0,0,0,,,0,0,0,0,,,0,0,0,0,,,0,0,0,0,,,0,0,0,0,,,0,0,0,0,,,0,0,0,0,AAPL
2024-10-22 13:05:00.028618651+00:00,10,41,38,A,B,0,234.44,200,194,56271,251915,,234.44,0,200,0,0,,,0,0,0,0,,,0,0,0,0,,,0,0,0,0,,,0,0,0,0,,,0,0,0,0,,,0,0,0,0,,,0,0,0,0,,,0,0,0,0,,,0,0,0,0,AAPL
2024-10-22 13:05:00.028505864+00:00,10,40,38,A,A,0,,0,194,203301,110997,,,0,0,0,0,,,0,0,0,0,,,0,0,0,0,,,0,0,0,0,,,0,0,0,0,,,0,0,0,0,,,0,0,0,0,,,0,0,0,0,,,0,0,0,0,,,0,0,0,0,AAPL
2024-10-22 13:05:00.028630835+00:00,10,41,38,A,A,0,,0,194,55291,251916,,,0,0,0,0,,,0,0,0,0,,,0,0,0,0,,,0,0,0,0,,,0,0,0,0,,,0,0,0,0,,,0,0,0,0,,,0,0,0,0,,,0,0,0,0,,,0,0,0,0,AAPL
2024-10-22 13:05:03.651202050+00:00,10,41,38,A,A,0,234.39,200,194,56299,252911,,234.39,0,200,0,0,,,0,0,0,0,,,0,0,0,0,,,0,0,0,0,,,0,0,0,0,,,0,0,0,0,,,0,0,0,0,,,0,0,0,0,,,0,0,0,0,,,0,0,0,0,AAPL
2024-10-22 13:05:03.651223136+00:00,10,41,38,A,B,0,234.39,200,194,54689,252912,233.84,234.39,200,200,0,0,,,0,0,0,0,,,0,0,0,0,,,0,0,0,0,,,0,0,0,0,,,0,0,0,0,,,0,0,0,0,,,0,0,0,0,,,0,0,0,0,,,0,0,0,0,AAPL
2024-10-22 13:05:03.752302916+00:00,10,41,38,A,B,0,234.39,200,194,56129,252915,,234.39,0,200,0,0,,,0,0,0,0,,,0,0,0,0,,,0,0,0,0,,,0,0,0,0,,,0,0,0,0,,,0,0,0,0,,,0,0,0,0,,,0,0,0,0,,,0,0,0,0,AAPL
2024-10-22 13:05:03.752812520+00:00,10,41,38,A,A,0,,0,194,55458,252916,,,0,0,0,0,,,0,0,0,0,,,0,0,0,0,,,0,0,0,0,,,0,0,0,0,,,0,0,0,0,,,0,0,0,0,,,0,0,0,0,,,0,0,0,0,,,0,0,0,0,AAPL
2024-10-22 13:05:04.274055819+00:00,10,41,38,A,B,0,,0,194,56508,252973,233.84,,200,0,0,0,,,0,0,0,0,,,0,0,0,0,,,0,0,0,0,,,0,0,0,0,,,0,0,0,0,,,0,0,0,0,,,0,0,0,0,,,0,0,0,0,,,0,0,0,0,AAPL
2024-10-22 13:05:04.274072786+00:00,10,41,38,A,A,0,234.39,200,194,55491,252974,233.84,234.39,200,200,0,0,,,0,0,0,0,,,0,0,0,0,,,0,0,0,0,,,0,0,0,0,,,0,0,0,0,,,0,0,0,0,,,0,0,0,0,,,0,0,0,0,,,0,0,0,0,AAPL
2024-10-22 13:05:04.273962531+00:00,10,40,38,A,A,0,234.44,200,194,203360,111310,,234.44,0,200,0,0,,,0,0,0,0,,,0,0,0,0,,,0,0,0,0,,,0,0,0,0,,,0,0,0,0,,,0,0,0,0,,,0,0,0,0,,,0,0,0,0,,,0,0,0,0,AAPL
2024-10-22 13:05:04.274043528+00:00,10,40,38,A,A,0,,0,194,203347,111311,,,0,0,0,0,,,0,0,0,0,,,0,0,0,0,,,0,0,0,0,,,0,0,0,0,,,0,0,0,0,,,0,0,0,0,,,0,0,0,0,,,0,0,0,0,,,0,0,0,0,AAPL
2024-10-22 13:05:04.274142311+00:00,10,40,38,A,B,0,,0,194,203349,111312,233.78,,200,0,0,0,,,0,0,0,0,,,0,0,0,0,,,0,0,0,0,,,0,0,0,0,,,0,0,0,0,,,0,0,0,0,,,0,0,0,0,,,0,0,0,0,,,0,0,0,0,AAPL
2024-10-22 13:05:04.274577474+00:00,10,39,38,C,B,0,232.6,2000,130,203759,66580,,236.4,0,2000,0,1,,,0,0,0,0,,,0,0,0,0,,,0,0,0,0,,,0,0,0,0,,,0,0,0,0,,,0,0,0,0,,,0,0,0,0,,,0,0,0,0,,,0,0,0,0,AAPL
2024-10-22 13:05:04.282306328+00:00,10,40,38,A,B,0,,0,194,203203,111314,,,0,0,0,0,,,0,0,0,0,,,0,0,0,0,,,0,0,0,0,,,0,0,0,0,,,0,0,0,0,,,0,0,0,0,,,0,0,0,0,,,0,0,0,0,,,0,0,0,0,AAPL
2024-10-22 13:05:04.310592574+00:00,10,39,38,A,B,0,232.6,2000,130,203624,66581,232.6,236.4,2000,2000,1,1,,,0,0,0,0,,,0,0,0,0,,,0,0,0,0,,,0,0,0,0,,,0,0,0,0,,,0,0,0,0,,,0,0,0,0,,,0,0,0,0,,,0,0,0,0,AAPL
2024-10-22 13:05:04.342970211+00:00,10,39,38,C,A,0,236.4,2000,130,203588,66582,232.6,,2000,0,1,0,,,0,0,0,0,,,0,0,0,0,,,0,0,0,0,,,0,0,0,0,,,0,0,0,0,,,0,0,0,0,,,0,0,0,0,,,0,0,0,0,,,0,0,0,0,AAPL
2024-10-22 13:05:04.356326806+00:00,10,39,38,A,A,0,236.4,2000,130,203512,66583,232.6,236.4,2000,2000,1,1,,,0,0,0,0,,,0,0,0,0,,,0,0,0,0,,,0,0,0,0,,,0,0,0,0,,,0,0,0,0,,,0,0,0,0,,,0,0,0,0,,,0,0,0,0,AAPL
2024-10-22 13:05:04.453185765+00:00,10,41,38,A,B,0,234.39,200,194,55197,252993,,234.39,0,200,0,0,,,0,0,0,0,,,0,0,0,0,,,0,0,0,0,,,0,0,0,0,,,0,0,0,0,,,0,0,0,0,,,0,0,0,0,,,0,0,0,0,,,0,0,0,0,AAPL
2024-10-22 13:05:04.453202969+00:00,10,41,38,A,A,0,,0,194,54428,252994,,,0,0,0,0,,,0,0,0,0,,,0,0,0,0,,,0,0,0,0,,,0,0,0,0,,,0,0,0,0,,,0,0,0,0,,,0,0,0,0,,,0,0,0,0,,,0,0,0,0,AAPL
2024-10-22 13:05:05.646396645+00:00,10,40,38,A,B,0,,0,194,203437,111344,233.72,,200,0,0,0,,,0,0,0,0,,,0,0,0,0,,,0,0,0,0,,,0,0,0,0,,,0,0,0,0,,,0,0,0,0,,,0,0,0,0,,,0,0,0,0,,,0,0,0,0,AAPL
2024-10-22 13:05:05.646404966+00:00,10,40,38,A,A,0,234.42,200,194,203172,111345,233.72,234.42,200,200,0,0,,,0,0,0,0,,,0,0,0,0,,,0,0,0,0,,,0,0,0,0,,,0,0,0,0,,,0,0,0,0,,,0,0,0,0,,,0,0,0,0,,,0,0,0,0,AAPL
2024-10-22 13:05:05.646643356+00:00,10,41,38,A,B,0,,0,194,55946,253078,233.77,,200,0,0,0,,,0,0,0,0,,,0,0,0,0,,,0,0,0,0,,,0,0,0,0,,,0,0,0,0,,,0,0,0,0,,,0,0,0,0,,,0,0,0,0,,,0,0,0,0,AAPL
2024-10-22 13:05:05.646644706+00:00,10,41,38,A,A,0,234.37,200,194,55370,253079,233.77,234.37,200,200,0,0,,,0,0,0,0,,,0,0,0,0,,,0,0,0,0,,,0,0,0,0,,,0,0,0,0,,,0,0,0,0,,,0,0,0,0,,,0,0,0,0,,,0,0,0,0,AAPL
2024-10-22 13:05:05.848797450+00:00,10,40,38,A,B,0,234.42,200,194,203250,111350,,234.42,0,200,0,0,,,0,0,0,0,,,0,0,0,0,,,0,0,0,0,,,0,0,0,0,,,0,0,0,0,,,0,0,0,0,,,0,0,0,0,,,0,0,0,0,,,0,0,0,0,AAPL
2024-10-22 13:05:05.848806376+00:00,10,40,38,A,A,0,,0,194,203127,111351,,,0,0,0,0,,,0,0,0,0,,,0,0,0,0,,,0,0,0,0,,,0,0,0,0,,,0,0,0,0,,,0,0,0,0,,,0,0,0,0,,,0,0,0,0,,,0,0,0,0,AAPL
2024-10-22 13:05:05.849190469+00:00,10,41,38,A,B,0,234.37,200,194,55617,253087,,234.37,0,200,0,0,,,0,0,0,0,,,0,0,0,0,,,0,0,0,0,,,0,0,0,0,,,0,0,0,0,,,0,0,0,0,,,0,0,0,0,,,0,0,0,0,,,0,0,0,0,AAPL
2024-10-22 13:05:05.849708683+00:00,10,41,38,A,A,0,,0,194,55377,253088,,,0,0,0,0,,,0,0,0,0,,,0,0,0,0,,,0,0,0,0,,,0,0,0,0,,,0,0,0,0,,,0,0,0,0,,,0,0,0,0,,,0,0,0,0,,,0,0,0,0,AAPL
2024-10-22 13:05:06.323243216+00:00,10,41,38,A,A,0,234.32,200,194,55746,253118,,234.32,0,200,0,0,,,0,0,0,0,,,0,0,0,0,,,0,0,0,0,,,0,0,0,0,,,0,0,0,0,,,0,0,0,0,,,0,0,0,0,,,0,0,0,0,,,0,0,0,0,AAPL
2024-10-22 13:05:06.333478952+00:00,10,39,38,A,A,0,236.2,2000,130,203638,66602,232.6,236.2,2000,2000,1,1,,236.4,0,2000,0,1,,,0,0,0,0,,,0,0,0,0,,,0,0,0,0,,,0,0,0,0,,,0,0,0,0,,,0,0,0,0,,,0,0,0,0,,,0,0,0,0,AAPL
2024-10-22 13:05:06.333659303+00:00,10,39,38,C,A,1,236.4,2000,130,203495,66603,232.6,236.2,2000,2000,1,1,,,0,0,0,0,,,0,0,0,0,,,0,0,0,0,,,0,0,0,0,,,0,0,0,0,,,0,0,0,0,,,0,0,0,0,,,0,0,0,0,,,0,0,0,0,AAPL
2024-10-22 13:05:06.342818294+00:00,10,40,38,A,N,0,234.37,200,194,203369,111369,233.72,234.37,200,200,0,0,,,0,0,0,0,,,0,0,0,0,,,0,0,0,0,,,0,0,0,0,,,0,0,0,0,,,0,0,0,0,,,0,0,0,0,,,0,0,0,0,,,0,0,0,0,AAPL
2024-10-22 13:05:06.343303203+00:00,10,41,38,A,B,0,234.32,200,194,55453,253127,233.77,234.32,200,200,0,0,,,0,0,0,0,,,0,0,0,0,,,0,0,0,0,,,0,0,0,0,,,0,0,0,0,,,0,0,0,0,,,0,0,0,0,,,0,0,0,0,,,0,0,0,0,AAPL
2024-10-22 13:05:06.343724859+00:00,10,39,38,C,B,0,232.6,2000,130,203478,66604,,236.2,0,2000,0,1,,,0,0,0,0,,,0,0,0,0,,,0,0,0,0,,,0,0,0,0,,,0,0,0,0,,,0,0,0,0,,,0,0,0,0,,,0,0,0,0,,,0,0,0,0,AAPL
2024-10-22 13:05:06.379611304+00:00,10,39,38,A,B,0,232.6,2000,130,203685,66606,232.6,236.2,2000,2000,1,1,,,0,0,0,0,,,0,0,0,0,,,0,0,0,0,,,0,0,0,0,,,0,0,0,0,,,0,0,0,0,,,0,0,0,0,,,0,0,0,0,,,0,0,0,0,AAPL
2024-10-22 13:05:06.394848864+00:00,10,39,38,C,B,0,232.6,2000,130,203492,66607,,236.2,0,2000,0,1,,,0,0,0,0,,,0,0,0,0,,,0,0,0,0,,,0,0,0,0,,,0,0,0,0,,,0,0,0,0,,,0,0,0,0,,,0,0,0,0,,,0,0,0,0,AAPL
2024-10-22 13:05:06.410669039+00:00,10,39,38,A,B,0,232.6,2000,130,203522,66608,232.6,236.2,2000,2000,1,1,,,0,0,0,0,,,0,0,0,0,,,0,0,0,0,,,0,0,0,0,,,0,0,0,0,,,0,0,0,0,,,0,0,0,0,,,0,0,0,0,,,0,0,0,0,AAPL
2024-10-22 13:05:06.511856588+00:00,10,41,38,A,B,0,234.32,200,194,55535,253145,,234.32,0,200,0,0,,,0,0,0,0,,,0,0,0,0,,,0,0,0,0,,,0,0,0,0,,,0,0,0,0,,,0,0,0,0,,,0,0,0,0,,,0,0,0,0,,,0,0,0,0,AAPL
2024-10-22 13:05:06.666815949+00:00,10,41,38,A,B,0,234.32,200,194,55901,253160,233.74,234.32,200,200,0,0,,,0,0,0,0,,,0,0,0,0,,,0,0,0,0,,,0,0,0,0,,,0,0,0,0,,,0,0,0,0,,,0,0,0,0,,,0,0,0,0,,,0,0,0,0,AAPL
2024-10-22 13:05:06.784906942+00:00,10,40,38,A,B,0,234.37,200,194,203280,111379,,234.37,0,200,0,0,,,0,0,0,0,,,0,0,0,0,,,0,0,0,0,,,0,0,0,0,,,0,0,0,0,,,0,0,0,0,,,0,0,0,0,,,0,0,0,0,,,0,0,0,0,AAPL
2024-10-22 13:05:06.784992845+00:00,10,40,38,A,B,0,234.37,200,194,203236,111380,233.69,234.37,200,200,0,0,,,0,0,0,0,,,0,0,0,0,,,0,0,0,0,,,0,0,0,0,,,0,0,0,0,,,0,0,0,0,,,0,0,0,0,,,0,0,0,0,,,0,0,0,0,AAPL
2024-10-22 13:05:06.785368697+00:00,10,41,38,A,B,0,234.32,200,194,55514,253165,,234.32,0,200,0,0,,,0,0,0,0,,,0,0,0,0,,,0,0,0,0,,,0,0,0,0,,,0,0,0,0,,,0,0,0,0,,,0,0,0,0,,,0,0,0,0,,,0,0,0,0,AAPL
2024-10-22 13:05:06.852075435+00:00,10,40,38,A,B,0,234.37,200,194,203305,111381,,234.37,0,200,0,0,,,0,0,0,0,,,0,0,0,0,,,0,0,0,0,,,0,0,0,0,,,0,0,0,0,,,0,0,0,0,,,0,0,0,0,,,0,0,0,0,,,0,0,0,0,AAPL
2024-10-22 13:05:06.852171200+00:00,10,39,38,C,B,0,232.6,2000,130,204037,66611,,236.2,0,2000,0,1,,,0,0,0,0,,,0,0,0,0,,,0,0,0,0,,,0,0,0,0,,,0,0,0,0,,,0,0,0,0,,,0,0,0,0,,,0,0,0,0,,,0,0,0,0,AAPL
2024-10-22 13:05:06.862882688+00:00,10,39,38,A,B,0,232.4,2000,130,203644,66612,232.4,236.2,2000,2000,1,1,,,0,0,0,0,,,0,0,0,0,,,0,0,0,0,,,0,0,0,0,,,0,0,0,0,,,0,0,0,0,,,0,0,0,0,,,0,0,0,0,,,0,0,0,0,AAPL
2024-10-22 13:05:07.330927918+00:00,10,39,38,C,A,0,236.2,2000,130,203610,66616,232.4,,2000,0,1,0,,,0,0,0,0,,,0,0,0,0,,,0,0,0,0,,,0,0,0,0,,,0,0,0,0,,,0,0,0,0,,,0,0,0,0,,,0,0,0,0,,,0,0,0,0,AAPL
2024-10-22 13:05:07.342693064+00:00,10,39,38,A,A,0,236.4,2000,130,203625,66617,232.4,236.4,2000,2000,1,1,,,0,0,0,0,,,0,0,0,0,,,0,0,0,0,,,0,0,0,0,,,0,0,0,0,,,0,0,0,0,,,0,0,0,0,,,0,0,0,0,,,0,0,0,0,AAPL
2024-10-22 13:05:07.456421121+00:00,10,40,38,A,B,0,234.37,200,194,203202,111401,233.69,234.37,200,200,0,0,,,0,0,0,0,,,0,0,0,0,,,0,0,0,0,,,0,0,0,0,,,0,0,0,0,,,0,0,0,0,,,0,0,0,0,,,0,0,0,0,,,0,0,0,0,AAPL
2024-10-22 13:05:07.456675792+00:00,10,41,38,A,B,0,234.32,200,194,55655,253250,233.74,234.32,200,200,0,0,,,0,0,0,0,,,0,0,0,0,,,0,0,0,0,,,0,0,0,0,,,0,0,0,0,,,0,0,0,0,,,0,0,0,0,,,0,0,0,0,,,0,0,0,0,AAPL
2024-10-22 13:05:07.457272215+00:00,10,39,38,C,B,0,232.4,2000,130,203756,66618,,236.4,0,2000,0,1,,,0,0,0,0,,,0,0,0,0,,,0,0,0,0,,,0,0,0,0,,,0,0,0,0,,,0,0,0,0,,,0,0,0,0,,,0,0,0,0,,,0,0,0,0,AAPL
2024-10-22 13:05:07.492630369+00:00,10,39,38,A,B,0,232.6,2000,130,203636,66621,232.6,236.4,2000,2000,1,1,,,0,0,0,0,,,0,0,0,0,,,0,0,0,0,,,0,0,0,0,,,0,0,0,0,,,0,0,0,0,,,0,0,0,0,,,0,0,0,0,,,0,0,0,0,AAPL
2024-10-22 13:05:07.492676442+00:00,10,40,38,A,B,0,234.37,200,194,203238,111403,,234.37,0,200,0,0,,,0,0,0,0,,,0,0,0,0,,,0,0,0,0,,,0,0,0,0,,,0,0,0,0,,,0,0,0,0,,,0,0,0,0,,,0,0,0,0,,,0,0,0,0,AAPL
2024-10-22 13:05:07.520410247+00:00,10,39,38,C,A,0,236.4,2000,130,203621,66623,232.6,,2000,0,1,0,,,0,0,0,0,,,0,0,0,0,,,0,0,0,0,,,0,0,0,0,,,0,0,0,0,,,0,0,0,0,,,0,0,0,0,,,0,0,0,0,,,0,0,0,0,AAPL
2024-10-22 13:05:07.529343534+00:00,10,40,38,A,A,0,,0,194,203312,111404,,,0,0,0,0,,,0,0,0,0,,,0,0,0,0,,,0,0,0,0,,,0,0,0,0,,,0,0,0,0,,,0,0,0,0,,,0,0,0,0,,,0,0,0,0,,,0,0,0,0,AAPL
2024-10-22 13:05:07.529362624+00:00,10,40,38,A,A,0,234.35,200,194,203265,111405,,234.35,0,200,0,0,,,0,0,0,0,,,0,0,0,0,,,0,0,0,0,,,0,0,0,0,,,0,0,0,0,,,0,0,0,0,,,0,0,0,0,,,0,0,0,0,,,0,0,0,0,AAPL
2024-10-22 13:05:07.564130800+00:00,10,41,38,A,B,0,234.32,200,194,54895,253278,,234.32,0,200,0,0,,,0,0,0,0,,,0,0,0,0,,,0,0,0,0,,,0,0,0,0,,,0,0,0,0,,,0,0,0,0,,,0,0,0,0,,,0,0,0,0,,,0,0,0,0,AAPL
2024-10-22 13:05:07.564662857+00:00,10,41,38,A,A,0,,0,194,55549,253279,,,0,0,0,0,,,0,0,0,0,,,0,0,0,0,,,0,0,0,0,,,0,0,0,0,,,0,0,0,0,,,0,0,0,0,,,0,0,0,0,,,0,0,0,0,,,0,0,0,0,AAPL
2024-10-22 13:05:08.270852669+00:00,10,41,38,A,A,0,234.3,200,194,55659,253365,,234.3,0,200,0,0,,,0,0,0,0,,,0,0,0,0,,,0,0,0,0,,,0,0,0,0,,,0,0,0,0,,,0,0,0,0,,,0,0,0,0,,,0,0,0,0,,,0,0,0,0,AAPL
2024-10-22 13:05:08.369157394+00:00,10,40,38,A,B,0,234.35,200,194,203310,111431,233.68,234.35,200,200,0,0,,,0,0,0,0,,,0,0,0,0,,,0,0,0,0,,,0,0,0,0,,,0,0,0,0,,,0,0,0,0,,,0,0,0,0,,,0,0,0,0,,,0,0,0,0,AAPL
2024-10-22 13:05:08.369630250+00:00,10,41,38,A,B,0,234.3,200,194,55263,253393,233.73,234.3,200,200,0,0,,,0,0,0,0,,,0,0,0,0,,,0,0,0,0,,,0,0,0,0,,,0,0,0,0,,,0,0,0,0,,,0,0,0,0,,,0,0,0,0,,,0,0,0,0,AAPL
2024-10-22 13:05:08.470004533+00:00,10,40,38,A,B,0,234.35,200,194,203401,111433,,234.35,0,200,0,0,,,0,0,0,0,,,0,0,0,0,,,0,0,0,0,,,0,0,0,0,,,0,0,0,0,,,0,0,0,0,,,0,0,0,0,,,0,0,0,0,,,0,0,0,0,AAPL
2024-10-22 13:05:08.471420177+00:00,10,41,38,A,B,0,234.3,200,194,55595,253414,,234.3,0,200,0,0,,,0,0,0,0,,,0,0,0,0,,,0,0,0,0,,,0,0,0,0,,,0,0,0,0,,,0,0,0,0,,,0,0,0,0,,,0,0,0,0,,,0,0,0,0,AAPL
2024-10-22 13:05:11.686382078+00:00,10,40,38,A,B,0,234.35,200,194,203980,111478,233.69,234.35,200,200,0,0,,,0,0,0,0,,,0,0,0,0,,,0,0,0,0,,,0,0,0,0,,,0,0,0,0,,,0,0,0,0,,,0,0,0,0,,,0,0,0,0,,,0,0,0,0,AAPL
2024-10-22 13:05:11.686902031+00:00,10,41,38,A,B,0,234.3,200,194,55686,253610,233.74,234.3,200,200,0,0,,,0,0,0,0,,,0,0,0,0,,,0,0,0,0,,,0,0,0,0,,,0,0,0,0,,,0,0,0,0,,,0,0,0,0,,,0,0,0,0,,,0,0,0,0,AAPL
2024-10-22 13:05:17.845080869+00:00,10,41,38,A,B,0,234.3,200,194,55852,253977,,234.3,0,200,0,0,,,0,0,0,0,,,0,0,0,0,,,0,0,0,0,,,0,0,0,0,,,0,0,0,0,,,0,0,0,0,,,0,0,0,0,,,0,0,0,0,,,0,0,0,0,AAPL
2024-10-22 13:05:18.733777074+00:00,10,41,38,A,B,0,234.3,200,194,55522,254024,233.74,234.3,200,200,0,0,,,0,0,0,0,,,0,0,0,0,,,0,0,0,0,,,0,0,0,0,,,0,0,0,0,,,0,0,0,0,,,0,0,0,0,,,0,0,0,0,,,0,0,0,0,AAPL
2024-10-22 13:05:20.734536735+00:00,10,41,38,A,B,0,234.3,200,194,55869,254111,,234.3,0,200,0,0,,,0,0,0,0,,,0,0,0,0,,,0,0,0,0,,,0,0,0,0,,,0,0,0,0,,,0,0,0,0,,,0,0,0,0,,,0,0,0,0,,,0,0,0,0,AAPL
2024-10-22 13:05:20.853915855+00:00,10,41,38,A,B,0,234.3,200,194,55165,254121,233.74,234.3,200,200,0,0,,,0,0,0,0,,,0,0,0,0,,,0,0,0,0,,,0,0,0,0,,,0,0,0,0,,,0,0,0,0,,,0,0,0,0,,,0,0,0,0,,,0,0,0,0,AAPL
2024-10-22 13:05:21.961177+00:00,10,41,38,A,B,0,234.3,200,194,60778,254152,,234.3,0,200,0,0,,,0,0,0,0,,,0,0,0,0,,,0,0,0,0,,,0,0,0,0,,,0,0,0,0,,,0,0,0,0,,,0,0,0,0,,,0,0,0,0,,,0,0,0,0,AAPL
2024-10-22 13:05:22.532985707+00:00,10,41,38,A,B,0,234.3,200,194,55818,254171,233.73,234.3,200,200,0,0,,,0,0,0,0,,,0,0,0,0,,,0,0,0,0,,,0,0,0,0,,,0,0,0,0,,,0,0,0,0,,,0,0,0,0,,,0,0,0,0,,,0,0,0,0,AAPL
2024-10-22 13:05:22.570024509+00:00,10,40,38,A,B,0,234.35,200,194,203643,111652,,234.35,0,200,0,0,,,0,0,0,0,,,0,0,0,0,,,0,0,0,0,,,0,0,0,0,,,0,0,0,0,,,0,0,0,0,,,0,0,0,0,,,0,0,0,0,,,0,0,0,0,AAPL
2024-10-22 13:05:22.735612938+00:00,10,41,38,A,B,0,234.3,200,194,55775,254177,,234.3,0,200,0,0,,,0,0,0,0,,,0,0,0,0,,,0,0,0,0,,,0,0,0,0,,,0,0,0,0,,,0,0,0,0,,,0,0,0,0,,,0,0,0,0,,,0,0,0,0,AAPL
2024-10-22 13:05:23.410207704+00:00,10,41,38,A,B,0,234.3,200,194,55475,254208,233.73,234.3,200,200,0,0,,,0,0,0,0,,,0,0,0,0,,,0,0,0,0,,,0,0,0,0,,,0,0,0,0,,,0,0,0,0,,,0,0,0,0,,,0,0,0,0,,,0,0,0,0,AAPL
2024-10-22 13:05:23.410689729+00:00,10,39,38,C,B,0,232.6,2000,130,203781,66724,,,0,0,0,0,,,0,0,0,0,,,0,0,0,0,,,0,0,0,0,,,0,0,0,0,,,0,0,0,0,,,0,0,0,0,,,0,0,0,0,,,0,0,0,0,,,0,0,0,0,AAPL
2024-10-22 13:05:23.411495620+00:00,10,40,38,A,B,0,234.35,200,194,203832,111662,233.68,234.35,200,200,0,0,,,0,0,0,0,,,0,0,0,0,,,0,0,0,0,,,0,0,0,0,,,0,0,0,0,,,0,0,0,0,,,0,0,0,0,,,0,0,0,0,,,0,0,0,0,AAPL
2024-10-22 13:05:23.449124464+00:00,10,39,38,A,B,0,232.4,2000,130,203513,66725,232.4,,2000,0,1,0,,,0,0,0,0,,,0,0,0,0,,,0,0,0,0,,,0,0,0,0,,,0,0,0,0,,,0,0,0,0,,,0,0,0,0,,,0,0,0,0,,,0,0,0,0,AAPL
2024-10-22 13:05:23.615395623+00:00,10,40,38,A,B,0,234.35,200,194,203704,111664,,234.35,0,200,0,0,,,0,0,0,0,,,0,0,0,0,,,0,0,0,0,,,0,0,0,0,,,0,0,0,0,,,0,0,0,0,,,0,0,0,0,,,0,0,0,0,,,0,0,0,0,AAPL
2024-10-22 13:05:23.615650640+00:00,10,41,38,A,B,0,234.3,200,194,55456,254218,,234.3,0,200,0,0,,,0,0,0,0,,,0,0,0,0,,,0,0,0,0,,,0,0,0,0,,,0,0,0,0,,,0,0,0,0,,,0,0,0,0,,,0,0,0,0,,,0,0,0,0,AAPL
2024-10-22 13:05:24.944023120+00:00,10,40,38,A,B,0,234.35,200,194,203688,111675,233.66,234.35,200,200,0,0,,,0,0,0,0,,,0,0,0,0,,,0,0,0,0,,,0,0,0,0,,,0,0,0,0,,,0,0,0,0,,,0,0,0,0,,,0,0,0,0,,,0,0,0,0,AAPL
2024-10-22 13:05:24.944259213+00:00,10,41,38,A,B,0,234.3,200,194,54571,254276,233.71,234.3,200,200,0,0,,,0,0,0,0,,,0,0,0,0,,,0,0,0,0,,,0,0,0,0,,,0,0,0,0,,,0,0,0,0,,,0,0,0,0,,,0,0,0,0,,,0,0,0,0,AAPL
2024-10-22 13:05:25.137001492+00:00,10,40,38,A,B,0,234.35,200,194,203623,111679,,234.35,0,200,0,0,,,0,0,0,0,,,0,0,0,0,,,0,0,0,0,,,0,0,0,0,,,0,0,0,0,,,0,0,0,0,,,0,0,0,0,,,0,0,0,0,,,0,0,0,0,AAPL
2024-10-22 13:05:25.137233488+00:00,10,41,38,A,B,0,234.3,200,194,55126,254285,,234.3,0,200,0,0,,,0,0,0,0,,,0,0,0,0,,,0,0,0,0,,,0,0,0,0,,,0,0,0,0,,,0,0,0,0,,,0,0,0,0,,,0,0,0,0,,,0,0,0,0,AAPL
2024-10-22 13:05:26.129492150+00:00,10,40,38,A,B,0,234.35,200,194,203980,111685,233.68,234.35,200,200,0,0,,,0,0,0,0,,,0,0,0,0,,,0,0,0,0,,,0,0,0,0,,,0,0,0,0,,,0,0,0,0,,,0,0,0,0,,,0,0,0,0,,,0,0,0,0,AAPL
2024-10-22 13:05:26.129765478+00:00,10,41,38,A,B,0,234.3,200,194,55995,254317,233.73,234.3,200,200,0,0,,,0,0,0,0,,,0,0,0,0,,,0,0,0,0,,,0,0,0,0,,,0,0,0,0,,,0,0,0,0,,,0,0,0,0,,,0,0,0,0,,,0,0,0,0,AAPL
2024-10-22 13:05:26.331713838+00:00,10,40,38,A,B,0,234.35,200,194,203772,111687,,234.35,0,200,0,0,,,0,0,0,0,,,0,0,0,0,,,0,0,0,0,,,0,0,0,0,,,0,0,0,0,,,0,0,0,0,,,0,0,0,0,,,0,0,0,0,,,0,0,0,0,AAPL
2024-10-22 13:05:26.331855704+00:00,10,41,38,A,B,0,234.3,200,194,55410,254324,,234.3,0,200,0,0,,,0,0,0,0,,,0,0,0,0,,,0,0,0,0,,,0,0,0,0,,,0,0,0,0,,,0,0,0,0,,,0,0,0,0,,,0,0,0,0,,,0,0,0,0,AAPL
2024-10-22 13:05:27.290057294+00:00,10,40,38,A,B,0,234.35,200,194,203936,111692,233.66,234.35,200,200,0,0,,,0,0,0,0,,,0,0,0,0,,,0,0,0,0,,,0,0,0,0,,,0,0,0,0,,,0,0,0,0,,,0,0,0,0,,,0,0,0,0,,,0,0,0,0,AAPL
2024-10-22 13:05:27.290334197+00:00,10,41,38,A,B,0,234.3,200,194,55231,254342,233.71,234.3,200,200,0,0,,,0,0,0,0,,,0,0,0,0,,,0,0,0,0,,,0,0,0,0,,,0,0,0,0,,,0,0,0,0,,,0,0,0,0,,,0,0,0,0,,,0,0,0,0,AAPL
2024-10-22 13:05:27.495410090+00:00,10,40,38,A,B,0,234.35,200,194,203743,111693,,234.35,0,200,0,0,,,0,0,0,0,,,0,0,0,0,,,0,0,0,0,,,0,0,0,0,,,0,0,0,0,,,0,0,0,0,,,0,0,0,0,,,0,0,0,0,,,0,0,0,0,AAPL
2024-10-22 13:05:27.496040588+00:00,10,41,38,A,B,0,234.3,200,194,55725,254352,,234.3,0,200,0,0,,,0,0,0,0,,,0,0,0,0,,,0,0,0,0,,,0,0,0,0,,,0,0,0,0,,,0,0,0,0,,,0,0,0,0,,,0,0,0,0,,,0,0,0,0,AAPL
2024-10-22 13:05:29.050889414+00:00,10,40,38,A,B,0,234.35,200,194,203699,111712,233.66,234.35,200,200,0,0,,,0,0,0,0,,,0,0,0,0,,,0,0,0,0,,,0,0,0,0,,,0,0,0,0,,,0,0,0,0,,,0,0,0,0,,,0,0,0,0,,,0,0,0,0,AAPL
2024-10-22 13:05:29.051379496+00:00,10,41,38,A,B,0,234.3,200,194,55445,254405,233.71,234.3,200,200,0,0,,,0,0,0,0,,,0,0,0,0,,,0,0,0,0,,,0,0,0,0,,,0,0,0,0,,,0,0,0,0,,,0,0,0,0,,,0,0,0,0,,,0,0,0,0,AAPL
2024-10-22 13:05:29.206360864+00:00,10,40,38,A,B,0,234.35,200,194,203677,111713,,234.35,0,200,0,0,,,0,0,0,0,,,0,0,0,0,,,0,0,0,0,,,0,0,0,0,,,0,0,0,0,,,0,0,0,0,,,0,0,0,0,,,0,0,0,0,,,0,0,0,0,AAPL
2024-10-22 13:05:29.771024718+00:00,10,41,38,A,B,0,234.3,200,194,55518,254447,,234.3,0,200,0,0,,,0,0,0,0,,,0,0,0,0,,,0,0,0,0,,,0,0,0,0,,,0,0,0,0,,,0,0,0,0,,,0,0,0,0,,,0,0,0,0,,,0,0,0,0,AAPL
2024-10-22 13:05:31.884578920+00:00,10,40,38,A,B,0,234.35,200,194,204167,111739,233.66,234.35,200,200,0,0,,,0,0,0,0,,,0,0,0,0,,,0,0,0,0,,,0,0,0,0,,,0,0,0,0,,,0,0,0,0,,,0,0,0,0,,,0,0,0,0,,,0,0,0,0,AAPL
2024-10-22 13:05:31.884875687+00:00,10,41,38,A,B,0,234.3,200,194,55702,254529,233.71,234.3,200,200,0,0,,,0,0,0,0,,,0,0,0,0,,,0,0,0,0,,,0,0,0,0,,,0,0,0,0,,,0,0,0,0,,,0,0,0,0,,,0,0,0,0,,,0,0,0,0,AAPL
2024-10-22 13:05:32.088095463+00:00,10,41,38,A,B,0,234.3,200,194,55411,254541,,234.3,0,200,0,0,,,0,0,0,0,,,0,0,0,0,,,0,0,0,0,,,0,0,0,0,,,0,0,0,0,,,0,0,0,0,,,0,0,0,0,,,0,0,0,0,,,0,0,0,0,AAPL
2024-10-22 13:05:32.994642069+00:00,10,40,38,A,B,0,234.35,200,194,203397,111749,,234.35,0,200,0,0,,,0,0,0,0,,,0,0,0,0,,,0,0,0,0,,,0,0,0,0,,,0,0,0,0,,,0,0,0,0,,,0,0,0,0,,,0,0,0,0,,,0,0,0,0,AAPL
2024-10-22 13:05:33.598923216+00:00,10,40,38,A,B,0,234.35,200,194,203285,111759,233.66,234.35,200,200,0,0,,,0,0,0,0,,,0,0,0,0,,,0,0,0,0,,,0,0,0,0,,,0,0,0,0,,,0,0,0,0,,,0,0,0,0,,,0,0,0,0,,,0,0,0,0,AAPL
2024-10-22 13:05:36.111149388+00:00,10,41,38,A,B,0,234.3,200,194,56120,254696,233.71,234.3,200,200,0,0,,,0,0,0,0,,,0,0,0,0,,,0,0,0,0,,,0,0,0,0,,,0,0,0,0,,,0,0,0,0,,,0,0,0,0,,,0,0,0,0,,,0,0,0,0,AAPL
2024-10-22 13:05:37.351865463+00:00,10,41,38,A,B,0,234.3,200,194,55786,254723,,234.3,0,200,0,0,,,0,0,0,0,,,0,0,0,0,,,0,0,0,0,,,0,0,0,0,,,0,0,0,0,,,0,0,0,0,,,0,0,0,0,,,0,0,0,0,,,0,0,0,0,AAPL
2024-10-22 13:05:37.801348674+00:00,10,39,38,A,A,0,236.4,2000,130,204152,66809,232.4,236.4,2000,2000,1,1,,,0,0,0,0,,,0,0,0,0,,,0,0,0,0,,,0,0,0,0,,,0,0,0,0,,,0,0,0,0,,,0,0,0,0,,,0,0,0,0,,,0,0,0,0,AAPL
2024-10-22 13:05:37.891695778+00:00,10,40,38,A,B,0,234.35,200,194,203522,111789,,234.35,0,200,0,0,,,0,0,0,0,,,0,0,0,0,,,0,0,0,0,,,0,0,0,0,,,0,0,0,0,,,0,0,0,0,,,0,0,0,0,,,0,0,0,0,,,0,0,0,0,AAPL
2024-10-22 13:05:39.247515196+00:00,10,40,38,A,B,0,234.35,200,194,202979,111798,233.66,234.35,200,200,0,0,,,0,0,0,0,,,0,0,0,0,,,0,0,0,0,,,0,0,0,0,,,0,0,0,0,,,0,0,0,0,,,0,0,0,0,,,0,0,0,0,,,0,0,0,0,AAPL
2024-10-22 13:05:39.247989368+00:00,10,41,38,A,B,0,234.3,200,194,55382,254808,233.71,234.3,200,200,0,0,,,0,0,0,0,,,0,0,0,0,,,0,0,0,0,,,0,0,0,0,,,0,0,0,0,,,0,0,0,0,,,0,0,0,0,,,0,0,0,0,,,0,0,0,0,AAPL
2024-10-22 13:05:39.451851032+00:00,10,41,38,A,B,0,234.3,200,194,60908,254820,,234.3,0,200,0,0,,,0,0,0,0,,,0,0,0,0,,,0,0,0,0,,,0,0,0,0,,,0,0,0,0,,,0,0,0,0,,,0,0,0,0,,,0,0,0,0,,,0,0,0,0,AAPL
2024-10-22 13:05:40.153510261+00:00,10,41,38,A,B,0,234.3,200,194,55522,254844,233.71,234.3,200,200,0,0,,,0,0,0,0,,,0,0,0,0,,,0,0,0,0,,,0,0,0,0,,,0,0,0,0,,,0,0,0,0,,,0,0,0,0,,,0,0,0,0,,,0,0,0,0,AAPL
2024-10-22 13:05:40.376826423+00:00,10,41,38,A,B,0,234.3,200,194,55308,254877,,234.3,0,200,0,0,,,0,0,0,0,,,0,0,0,0,,,0,0,0,0,,,0,0,0,0,,,0,0,0,0,,,0,0,0,0,,,0,0,0,0,,,0,0,0,0,,,0,0,0,0,AAPL
2024-10-22 13:05:41.664960021+00:00,10,41,38,A,B,0,234.3,200,194,60573,254907,233.71,234.3,200,200,0,0,,,0,0,0,0,,,0,0,0,0,,,0,0,0,0,,,0,0,0,0,,,0,0,0,0,,,0,0,0,0,,,0,0,0,0,,,0,0,0,0,,,0,0,0,0,AAPL
2024-10-22 13:05:44.697703163+00:00,10,41,38,A,B,0,234.3,200,194,55845,255020,,234.3,0,200,0,0,,,0,0,0,0,,,0,0,0,0,,,0,0,0,0,,,0,0,0,0,,,0,0,0,0,,,0,0,0,0,,,0,0,0,0,,,0,0,0,0,,,0,0,0,0,AAPL
2024-10-22 13:05:47.080014265+00:00,10,41,38,A,B,0,234.3,200,194,55644,255093,233.71,234.3,200,200,0,0,,,0,0,0,0,,,0,0,0,0,,,0,0,0,0,,,0,0,0,0,,,0,0,0,0,,,0,0,0,0,,,0,0,0,0,,,0,0,0,0,,,0,0,0,0,AAPL
2024-10-22 13:05:51.300786165+00:00,10,41,38,A,B,0,234.3,200,194,56316,255284,,234.3,0,200,0,0,,,0,0,0,0,,,0,0,0,0,,,0,0,0,0,,,0,0,0,0,,,0,0,0,0,,,0,0,0,0,,,0,0,0,0,,,0,0,0,0,,,0,0,0,0,AAPL
2024-10-22 13:05:51.400517648+00:00,10,41,38,A,B,0,234.3,200,194,55077,255292,233.73,234.3,200,200,0,0,,,0,0,0,0,,,0,0,0,0,,,0,0,0,0,,,0,0,0,0,,,0,0,0,0,,,0,0,0,0,,,0,0,0,0,,,0,0,0,0,,,0,0,0,0,AAPL
2024-10-22 13:05:53.571170042+00:00,10,41,38,A,B,0,234.3,200,194,55691,255410,,234.3,0,200,0,0,,,0,0,0,0,,,0,0,0,0,,,0,0,0,0,,,0,0,0,0,,,0,0,0,0,,,0,0,0,0,,,0,0,0,0,,,0,0,0,0,,,0,0,0,0,AAPL
2024-10-22 13:05:57.556265654+00:00,10,41,38,A,B,0,234.3,200,194,61195,255544,233.73,234.3,200,200,0,0,,,0,0,0,0,,,0,0,0,0,,,0,0,0,0,,,0,0,0,0,,,0,0,0,0,,,0,0,0,0,,,0,0,0,0,,,0,0,0,0,,,0,0,0,0,AAPL
2024-10-22 13:05:59.933896260+00:00,10,41,38,A,B,0,234.3,200,194,55246,255607,,234.3,0,200,0,0,,,0,0,0,0,,,0,0,0,0,,,0,0,0,0,,,0,0,0,0,,,0,0,0,0,,,0,0,0,0,,,0,0,0,0,,,0,0,0,0,,,0,0,0,0,AAPL
2024-10-22 13:06:00.034315384+00:00,10,40,38,A,B,0,234.35,200,194,201921,112047,,234.35,0,200,0,0,,,0,0,0,0,,,0,0,0,0,,,0,0,0,0,,,0,0,0,0,,,0,0,0,0,,,0,0,0,0,,,0,0,0,0,,,0,0,0,0,,,0,0,0,0,AAPL
2024-10-22 13:06:00.034322302+00:00,10,40,38,A,A,0,,0,194,201876,112048,,,0,0,0,0,,,0,0,0,0,,,0,0,0,0,,,0,0,0,0,,,0,0,0,0,,,0,0,0,0,,,0,0,0,0,,,0,0,0,0,,,0,0,0,0,,,0,0,0,0,AAPL
2024-10-22 13:06:00.034482474+00:00,10,41,38,A,A,0,,0,194,56250,255780,,,0,0,0,0,,,0,0,0,0,,,0,0,0,0,,,0,0,0,0,,,0,0,0,0,,,0,0,0,0,,,0,0,0,0,,,0,0,0,0,,,0,0,0,0,,,0,0,0,0,AAPL
2024-10-22 13:06:00.228070125+00:00,10,40,38,A,A,0,234.35,200,194,201899,112117,,234.35,0,200,0,0,,,0,0,0,0,,,0,0,0,0,,,0,0,0,0,,,0,0,0,0,,,0,0,0,0,,,0,0,0,0,,,0,0,0,0,,,0,0,0,0,,,0,0,0,0,AAPL
2024-10-22 13:06:00.474333856+00:00,10,41,38,A,A,0,234.3,200,194,55986,256154,,234.3,0,200,0,0,,,0,0,0,0,,,0,0,0,0,,,0,0,0,0,,,0,0,0,0,,,0,0,0,0,,,0,0,0,0,,,0,0,0,0,,,0,0,0,0,,,0,0,0,0,AAPL
2024-10-22 13:06:00.915223116+00:00,10,41,38,A,A,0,,0,194,54707,256220,,,0,0,0,0,,,0,0,0,0,,,0,0,0,0,,,0,0,0,0,,,0,0,0,0,,,0,0,0,0,,,0,0,0,0,,,0,0,0,0,,,0,0,0,0,,,0,0,0,0,AAPL
2024-10-22 13:06:01.223152891+00:00,10,40,38,A,A,0,,0,194,201929,112169,,,0,0,0,0,,,0,0,0,0,,,0,0,0,0,,,0,0,0,0,,,0,0,0,0,,,0,0,0,0,,,0,0,0,0,,,0,0,0,0,,,0,0,0,0,,,0,0,0,0,AAPL
2024-10-22 13:06:01.284038703+00:00,10,40,38,A,A,0,234.35,200,194,201857,112175,,234.35,0,200,0,0,,,0,0,0,0,,,0,0,0,0,,,0,0,0,0,,,0,0,0,0,,,0,0,0,0,,,0,0,0,0,,,0,0,0,0,,,0,0,0,0,,,0,0,0,0,AAPL
2024-10-22 13:06:02.225503282+00:00,10,41,38,A,A,0,234.28,200,194,55649,256302,,234.28,0,200,0,0,,,0,0,0,0,,,0,0,0,0,,,0,0,0,0,,,0,0,0,0,,,0,0,0,0,,,0,0,0,0,,,0,0,0,0,,,0,0,0,0,,,0,0,0,0,AAPL
2024-10-22 13:06:02.225446192+00:00,10,40,38,A,B,0,234.35,200,194,201951,112193,233.68,234.35,200,200,0,0,,,0,0,0,0,,,0,0,0,0,,,0,0,0,0,,,0,0,0,0,,,0,0,0,0,,,0,0,0,0,,,0,0,0,0,,,0,0,0,0,,,0,0,0,0,AAPL
2024-10-22 13:06:02.225683787+00:00,10,41,38,A,B,0,234.28,200,194,54615,256303,233.73,234.28,200,200,0,0,,,0,0,0,0,,,0,0,0,0,,,0,0,0,0,,,0,0,0,0,,,0,0,0,0,,,0,0,0,0,,,0,0,0,0,,,0,0,0,0,,,0,0,0,0,AAPL
2024-10-22 13:06:03.535144773+00:00,10,41,38,A,B,0,234.28,200,194,55328,256380,,234.28,0,200,0,0,,,0,0,0,0,,,0,0,0,0,,,0,0,0,0,,,0,0,0,0,,,0,0,0,0,,,0,0,0,0,,,0,0,0,0,,,0,0,0,0,,,0,0,0,0,AAPL
2024-10-22 13:06:04.646349518+00:00,10,40,38,A,B,0,234.35,200,194,202217,112212,,234.35,0,200,0,0,,,0,0,0,0,,,0,0,0,0,,,0,0,0,0,,,0,0,0,0,,,0,0,0,0,,,0,0,0,0,,,0,0,0,0,,,0,0,0,0,,,0,0,0,0,AAPL
2024-10-22 13:06:05.162761986+00:00,10,40,38,A,B,0,234.35,200,194,202198,112216,233.68,234.35,200,200,0,0,,,0,0,0,0,,,0,0,0,0,,,0,0,0,0,,,0,0,0,0,,,0,0,0,0,,,0,0,0,0,,,0,0,0,0,,,0,0,0,0,,,0,0,0,0,AAPL
2024-10-22 13:06:05.163291824+00:00,10,41,38,A,B,0,234.28,200,194,55327,256467,233.73,234.28,200,200,0,0,,,0,0,0,0,,,0,0,0,0,,,0,0,0,0,,,0,0,0,0,,,0,0,0,0,,,0,0,0,0,,,0,0,0,0,,,0,0,0,0,,,0,0,0,0,AAPL
2024-10-22 13:06:09.129779138+00:00,10,41,38,A,B,0,234.28,200,194,55986,256685,,234.28,0,200,0,0,,,0,0,0,0,,,0,0,0,0,,,0,0,0,0,,,0,0,0,0,,,0,0,0,0,,,0,0,0,0,,,0,0,0,0,,,0,0,0,0,,,0,0,0,0,AAPL
2024-10-22 13:06:09.247000306+00:00,10,40,38,A,B,0,234.35,200,194,203464,112247,,234.35,0,200,0,0,,,0,0,0,0,,,0,0,0,0,,,0,0,0,0,,,0,0,0,0,,,0,0,0,0,,,0,0,0,0,,,0,0,0,0,,,0,0,0,0,,,0,0,0,0,AAPL
2024-10-22 13:06:10.153757295+00:00,10,40,38,A,B,0,234.35,200,194,203107,112257,233.68,234.35,200,200,0,0,,,0,0,0,0,,,0,0,0,0,,,0,0,0,0,,,0,0,0,0,,,0,0,0,0,,,0,0,0,0,,,0,0,0,0,,,0,0,0,0,,,0,0,0,0,AAPL
2024-10-22 13:06:12.768230802+00:00,10,41,38,A,B,0,234.28,200,194,55349,256800,233.73,234.28,200,200,0,0,,,0,0,0,0,,,0,0,0,0,,,0,0,0,0,,,0,0,0,0,,,0,0,0,0,,,0,0,0,0,,,0,0,0,0,,,0,0,0,0,,,0,0,0,0,AAPL
2024-10-22 13:06:12.970007579+00:00,10,41,38,A,B,0,234.28,200,194,56067,256807,,234.28,0,200,0,0,,,0,0,0,0,,,0,0,0,0,,,0,0,0,0,,,0,0,0,0,,,0,0,0,0,,,0,0,0,0,,,0,0,0,0,,,0,0,0,0,,,0,0,0,0,AAPL
2024-10-22 13:06:15.442811825+00:00,10,41,38,A,B,0,234.28,200,194,60239,256874,233.73,234.28,200,200,0,0,,,0,0,0,0,,,0,0,0,0,,,0,0,0,0,,,0,0,0,0,,,0,0,0,0,,,0,0,0,0,,,0,0,0,0,,,0,0,0,0,,,0,0,0,0,AAPL
2024-10-22 13:06:15.443294412+00:00,10,39,38,C,A,0,236.4,2000,130,203663,67026,232.4,,2000,0,1,0,,,0,0,0,0,,,0,0,0,0,,,0,0,0,0,,,0,0,0,0,,,0,0,0,0,,,0,0,0,0,,,0,0,0,0,,,0,0,0,0,,,0,0,0,0,AAPL
2024-10-22 13:06:15.479457895+00:00,10,39,38,A,A,0,236.4,2000,130,203449,67027,232.4,236.4,2000,2000,1,1,,,0,0,0,0,,,0,0,0,0,,,0,0,0,0,,,0,0,0,0,,,0,0,0,0,,,0,0,0,0,,,0,0,0,0,,,0,0,0,0,,,0,0,0,0,AAPL
2024-10-22 13:06:16.671021403+00:00,10,41,38,A,B,0,234.28,200,194,60647,256910,,234.28,0,200,0,0,,,0,0,0,0,,,0,0,0,0,,,0,0,0,0,,,0,0,0,0,,,0,0,0,0,,,0,0,0,0,,,0,0,0,0,,,0,0,0,0,,,0,0,0,0,AAPL
2024-10-22 13:06:19.864600441+00:00,10,41,38,A,B,0,234.28,200,194,55693,257044,233.73,234.28,200,200,0,0,,,0,0,0,0,,,0,0,0,0,,,0,0,0,0,,,0,0,0,0,,,0,0,0,0,,,0,0,0,0,,,0,0,0,0,,,0,0,0,0,,,0,0,0,0,AAPL
2024-10-22 13:06:26.944791414+00:00,10,41,38,A,B,0,234.28,200,194,60712,257317,,234.28,0,200,0,0,,,0,0,0,0,,,0,0,0,0,,,0,0,0,0,,,0,0,0,0,,,0,0,0,0,,,0,0,0,0,,,0,0,0,0,,,0,0,0,0,,,0,0,0,0,AAPL
2024-10-22 13:06:27.471996371+00:00,10,41,38,A,B,0,234.28,200,194,65001,257337,233.73,234.28,200,200,0,0,,,0,0,0,0,,,0,0,0,0,,,0,0,0,0,,,0,0,0,0,,,0,0,0,0,,,0,0,0,0,,,0,0,0,0,,,0,0,0,0,,,0,0,0,0,AAPL
2024-10-22 13:06:27.920450531+00:00,10,39,38,C,B,0,232.4,2000,130,203398,67097,,236.4,0,2000,0,1,,,0,0,0,0,,,0,0,0,0,,,0,0,0,0,,,0,0,0,0,,,0,0,0,0,,,0,0,0,0,,,0,0,0,0,,,0,0,0,0,,,0,0,0,0,AAPL
2024-10-22 13:06:27.958013207+00:00,10,39,38,A,B,0,232.6,2000,130,203425,67104,232.6,236.4,2000,2000,1,1,,,0,0,0,0,,,0,0,0,0,,,0,0,0,0,,,0,0,0,0,,,0,0,0,0,,,0,0,0,0,,,0,0,0,0,,,0,0,0,0,,,0,0,0,0,AAPL
2024-10-22 13:06:27.984919086+00:00,10,39,38,C,A,0,236.4,2000,130,203413,67108,232.6,,2000,0,1,0,,,0,0,0,0,,,0,0,0,0,,,0,0,0,0,,,0,0,0,0,,,0,0,0,0,,,0,0,0,0,,,0,0,0,0,,,0,0,0,0,,,0,0,0,0,AAPL
2024-10-22 13:06:28.503559596+00:00,10,39,38,C,B,0,232.6,2000,130,203442,67116,,,0,0,0,0,,,0,0,0,0,,,0,0,0,0,,,0,0,0,0,,,0,0,0,0,,,0,0,0,0,,,0,0,0,0,,,0,0,0,0,,,0,0,0,0,,,0,0,0,0,AAPL
2024-10-22 13:06:28.514422951+00:00,10,39,38,A,B,0,232.4,2000,130,203463,67117,232.4,,2000,0,1,0,,,0,0,0,0,,,0,0,0,0,,,0,0,0,0,,,0,0,0,0,,,0,0,0,0,,,0,0,0,0,,,0,0,0,0,,,0,0,0,0,,,0,0,0,0,AAPL
2024-10-22 13:06:29.304125775+00:00,10,40,38,A,B,0,234.35,200,194,203990,112389,,234.35,0,200,0,0,,,0,0,0,0,,,0,0,0,0,,,0,0,0,0,,,0,0,0,0,,,0,0,0,0,,,0,0,0,0,,,0,0,0,0,,,0,0,0,0,,,0,0,0,0,AAPL
2024-10-22 13:06:29.304789745+00:00,10,41,38,A,B,0,234.28,200,194,60673,257427,,234.28,0,200,0,0,,,0,0,0,0,,,0,0,0,0,,,0,0,0,0,,,0,0,0,0,,,0,0,0,0,,,0,0,0,0,,,0,0,0,0,,,0,0,0,0,,,0,0,0,0,AAPL
2024-10-22 13:06:30.657217688+00:00,10,40,38,A,B,0,234.35,200,194,203840,112392,233.62,234.35,200,200,0,0,,,0,0,0,0,,,0,0,0,0,,,0,0,0,0,,,0,0,0,0,,,0,0,0,0,,,0,0,0,0,,,0,0,0,0,,,0,0,0,0,,,0,0,0,0,AAPL
2024-10-22 13:06:30.657818029+00:00,10,41,38,A,B,0,234.28,200,194,55816,257484,233.67,234.28,200,200,0,0,,,0,0,0,0,,,0,0,0,0,,,0,0,0,0,,,0,0,0,0,,,0,0,0,0,,,0,0,0,0,,,0,0,0,0,,,0,0,0,0,,,0,0,0,0,AAPL
2024-10-22 13:06:34.890654530+00:00,10,39,38,A,A,0,236.4,2000,130,203878,67174,232.4,236.4,2000,2000,1,1,,,0,0,0,0,,,0,0,0,0,,,0,0,0,0,,,0,0,0,0,,,0,0,0,0,,,0,0,0,0,,,0,0,0,0,,,0,0,0,0,,,0,0,0,0,AAPL
2024-10-22 13:06:34.951683235+00:00,10,39,38,C,A,0,236.4,2000,130,203456,67176,232.4,,2000,0,1,0,,,0,0,0,0,,,0,0,0,0,,,0,0,0,0,,,0,0,0,0,,,0,0,0,0,,,0,0,0,0,,,0,0,0,0,,,0,0,0,0,,,0,0,0,0,AAPL
2024-10-22 13:06:44.909707697+00:00,10,39,38,A,A,0,236.4,2000,130,203444,67245,232.4,236.4,2000,2000,1,1,,,0,0,0,0,,,0,0,0,0,,,0,0,0,0,,,0,0,0,0,,,0,0,0,0,,,0,0,0,0,,,0,0,0,0,,,0,0,0,0,,,0,0,0,0,AAPL
2024-10-22 13:06:48.344000530+00:00,10,39,38,C,A,0,236.4,2000,130,203757,67275,232.4,,2000,0,1,0,,,0,0,0,0,,,0,0,0,0,,,0,0,0,0,,,0,0,0,0,,,0,0,0,0,,,0,0,0,0,,,0,0,0,0,,,0,0,0,0,,,0,0,0,0,AAPL
2024-10-22 13:06:54.800076674+00:00,10,39,38,A,A,0,236.4,2000,130,203747,67306,232.4,236.4,2000,2000,1,1,,,0,0,0,0,,,0,0,0,0,,,0,0,0,0,,,0,0,0,0,,,0,0,0,0,,,0,0,0,0,,,0,0,0,0,,,0,0,0,0,,,0,0,0,0,AAPL
2024-10-22 13:06:54.851608977+00:00,10,39,38,C,A,0,236.4,2000,130,203382,67307,232.4,,2000,0,1,0,,,0,0,0,0,,,0,0,0,0,,,0,0,0,0,,,0,0,0,0,,,0,0,0,0,,,0,0,0,0,,,0,0,0,0,,,0,0,0,0,,,0,0,0,0,AAPL
2024-10-22 13:06:54.871015905+00:00,10,39,38,A,A,0,236.4,2000,130,203372,67308,232.4,236.4,2000,2000,1,1,,,0,0,0,0,,,0,0,0,0,,,0,0,0,0,,,0,0,0,0,,,0,0,0,0,,,0,0,0,0,,,0,0,0,0,,,0,0,0,0,,,0,0,0,0,AAPL
2024-10-22 13:07:00.014986085+00:00,10,40,38,A,B,0,234.35,200,194,204091,112669,,234.35,0,200,0,0,,,0,0,0,0,,,0,0,0,0,,,0,0,0,0,,,0,0,0,0,,,0,0,0,0,,,0,0,0,0,,,0,0,0,0,,,0,0,0,0,,,0,0,0,0,AAPL
2024-10-22 13:07:00.015224062+00:00,10,41,38,A,B,0,234.28,200,194,57423,258708,,234.28,0,200,0,0,,,0,0,0,0,,,0,0,0,0,,,0,0,0,0,,,0,0,0,0,,,0,0,0,0,,,0,0,0,0,,,0,0,0,0,,,0,0,0,0,,,0,0,0,0,AAPL
2024-10-22 13:07:00.015246572+00:00,10,41,38,A,A,0,,0,192,70436,258711,,,0,0,0,0,,,0,0,0,0,,,0,0,0,0,,,0,0,0,0,,,0,0,0,0,,,0,0,0,0,,,0,0,0,0,,,0,0,0,0,,,0,0,0,0,,,0,0,0,0,AAPL
2024-10-22 13:07:00.206221746+00:00,10,41,38,A,A,0,234.26,200,194,55082,258998,,234.26,0,200,0,0,,,0,0,0,0,,,0,0,0,0,,,0,0,0,0,,,0,0,0,0,,,0,0,0,0,,,0,0,0,0,,,0,0,0,0,,,0,0,0,0,,,0,0,0,0,AAPL
2024-10-22 13:07:00.619260137+00:00,10,40,38,A,B,0,234.35,200,194,204188,112749,233.62,234.35,200,200,0,0,,,0,0,0,0,,,0,0,0,0,,,0,0,0,0,,,0,0,0,0,,,0,0,0,0,,,0,0,0,0,,,0,0,0,0,,,0,0,0,0,,,0,0,0,0,AAPL
2024-10-22 13:07:00.921704735+00:00,10,40,38,A,B,0,234.35,200,194,204226,112753,,234.35,0,200,0,0,,,0,0,0,0,,,0,0,0,0,,,0,0,0,0,,,0,0,0,0,,,0,0,0,0,,,0,0,0,0,,,0,0,0,0,,,0,0,0,0,,,0,0,0,0,AAPL
2024-10-22 13:07:01.587762462+00:00,10,40,38,A,B,0,234.35,200,194,204130,112761,233.62,234.35,200,200,0,0,,,0,0,0,0,,,0,0,0,0,,,0,0,0,0,,,0,0,0,0,,,0,0,0,0,,,0,0,0,0,,,0,0,0,0,,,0,0,0,0,,,0,0,0,0,AAPL
2024-10-22 13:07:02.695518127+00:00,10,41,38,A,B,0,234.26,200,194,55736,259254,233.68,234.26,200,200,0,0,,,0,0,0,0,,,0,0,0,0,,,0,0,0,0,,,0,0,0,0,,,0,0,0,0,,,0,0,0,0,,,0,0,0,0,,,0,0,0,0,,,0,0,0,0,AAPL
2024-10-22 13:07:10.067351119+00:00,10,39,38,C,A,0,236.4,2000,130,204511,67390,232.4,,2000,0,1,0,,,0,0,0,0,,,0,0,0,0,,,0,0,0,0,,,0,0,0,0,,,0,0,0,0,,,0,0,0,0,,,0,0,0,0,,,0,0,0,0,,,0,0,0,0,AAPL
2024-10-22 13:07:10.098353245+00:00,10,39,38,A,A,0,236.4,2000,130,204054,67391,232.4,236.4,2000,2000,1,1,,,0,0,0,0,,,0,0,0,0,,,0,0,0,0,,,0,0,0,0,,,0,0,0,0,,,0,0,0,0,,,0,0,0,0,,,0,0,0,0,,,0,0,0,0,AAPL
2024-10-22 13:07:10.309162871+00:00,10,39,38,C,B,0,232.4,2000,130,204169,67392,,236.4,0,2000,0,1,,,0,0,0,0,,,0,0,0,0,,,0,0,0,0,,,0,0,0,0,,,0,0,0,0,,,0,0,0,0,,,0,0,0,0,,,0,0,0,0,,,0,0,0,0,AAPL
2024-10-22 13:07:10.320807131+00:00,10,39,38,A,B,0,232.4,2000,130,204089,67393,232.4,236.4,2000,2000,1,1,,,0,0,0,0,,,0,0,0,0,,,0,0,0,0,,,0,0,0,0,,,0,0,0,0,,,0,0,0,0,,,0,0,0,0,,,0,0,0,0,,,0,0,0,0,AAPL
2024-10-22 13:07:13.241875730+00:00,10,39,38,C,A,0,236.4,2000,130,204247,67401,232.4,,2000,0,1,0,,,0,0,0,0,,,0,0,0,0,,,0,0,0,0,,,0,0,0,0,,,0,0,0,0,,,0,0,0,0,,,0,0,0,0,,,0,0,0,0,,,0,0,0,0,AAPL
2024-10-22 13:07:39.575771833+00:00,10,39,38,C,B,0,232.4,2000,130,203839,67469,,,0,0,0,0,,,0,0,0,0,,,0,0,0,0,,,0,0,0,0,,,0,0,0,0,,,0,0,0,0,,,0,0,0,0,,,0,0,0,0,,,0,0,0,0,,,0,0,0,0,AAPL
2024-10-22 13:07:39.581343887+00:00,10,39,38,A,A,0,236.4,2000,130,203647,67470,,236.4,0,2000,0,1,,,0,0,0,0,,,0,0,0,0,,,0,0,0,0,,,0,0,0,0,,,0,0,0,0,,,0,0,0,0,,,0,0,0,0,,,0,0,0,0,,,0,0,0,0,AAPL
2024-10-22 13:07:39.620606917+00:00,10,39,38,A,B,0,232.4,2000,130,203629,67471,232.4,236.4,2000,2000,1,1,,,0,0,0,0,,,0,0,0,0,,,0,0,0,0,,,0,0,0,0,,,0,0,0,0,,,0,0,0,0,,,0,0,0,0,,,0,0,0,0,,,0,0,0,0,AAPL
2024-10-22 13:07:43.998391654+00:00,10,39,38,C,B,0,232.4,2000,130,204156,67479,,236.4,0,2000,0,1,,,0,0,0,0,,,0,0,0,0,,,0,0,0,0,,,0,0,0,0,,,0,0,0,0,,,0,0,0,0,,,0,0,0,0,,,0,0,0,0,,,0,0,0,0,AAPL
2024-10-22 13:07:44.009724413+00:00,10,39,38,A,B,0,232.2,2000,130,203610,67481,232.2,236.4,2000,2000,1,1,,,0,0,0,0,,,0,0,0,0,,,0,0,0,0,,,0,0,0,0,,,0,0,0,0,,,0,0,0,0,,,0,0,0,0,,,0,0,0,0,,,0,0,0,0,AAPL
2024-10-22 13:08:00.028221861+00:00,10,40,38,A,B,0,234.35,200,194,202960,113289,,234.35,0,200,0,0,,,0,0,0,0,,,0,0,0,0,,,0,0,0,0,,,0,0,0,0,,,0,0,0,0,,,0,0,0,0,,,0,0,0,0,,,0,0,0,0,,,0,0,0,0,AAPL
2024-10-22 13:08:00.028231195+00:00,10,40,38,A,A,0,,0,194,203005,113290,,,0,0,0,0,,,0,0,0,0,,,0,0,0,0,,,0,0,0,0,,,0,0,0,0,,,0,0,0,0,,,0,0,0,0,,,0,0,0,0,,,0,0,0,0,,,0,0,0,0,AAPL
2024-10-22 13:08:00.028257042+00:00,10,40,38,A,A,0,234.33,200,194,202962,113291,,234.33,0,200,0,0,,,0,0,0,0,,,0,0,0,0,,,0,0,0,0,,,0,0,0,0,,,0,0,0,0,,,0,0,0,0,,,0,0,0,0,,,0,0,0,0,,,0,0,0,0,AAPL
2024-10-22 13:08:00.028465730+00:00,10,41,38,A,A,0,,0,194,54689,261691,233.68,,200,0,0,0,,,0,0,0,0,,,0,0,0,0,,,0,0,0,0,,,0,0,0,0,,,0,0,0,0,,,0,0,0,0,,,0,0,0,0,,,0,0,0,0,,,0,0,0,0,AAPL
2024-10-22 13:08:00.028480755+00:00,10,41,38,A,B,0,,0,194,54214,261692,,,0,0,0,0,,,0,0,0,0,,,0,0,0,0,,,0,0,0,0,,,0,0,0,0,,,0,0,0,0,,,0,0,0,0,,,0,0,0,0,,,0,0,0,0,,,0,0,0,0,AAPL
2024-10-22 13:08:00.028484782+00:00,10,41,38,A,A,0,234.28,200,194,54541,261693,,234.28,0,200,0,0,,,0,0,0,0,,,0,0,0,0,,,0,0,0,0,,,0,0,0,0,,,0,0,0,0,,,0,0,0,0,,,0,0,0,0,,,0,0,0,0,,,0,0,0,0,AAPL
2024-10-22 13:08:00.104325824+00:00,10,41,38,A,B,0,234.28,200,194,54342,261860,233.71,234.28,200,200,0,0,,,0,0,0,0,,,0,0,0,0,,,0,0,0,0,,,0,0,0,0,,,0,0,0,0,,,0,0,0,0,,,0,0,0,0,,,0,0,0,0,,,0,0,0,0,AAPL
2024-10-22 13:08:01.232677302+00:00,10,40,38,A,B,0,234.33,200,194,202927,113365,233.65,234.33,200,200,0,0,,,0,0,0,0,,,0,0,0,0,,,0,0,0,0,,,0,0,0,0,,,0,0,0,0,,,0,0,0,0,,,0,0,0,0,,,0,0,0,0,,,0,0,0,0,AAPL
2024-10-22 13:08:25.473972480+00:00,10,39,38,C,A,0,236.4,2000,130,203012,67748,232.2,,2000,0,1,0,,,0,0,0,0,,,0,0,0,0,,,0,0,0,0,,,0,0,0,0,,,0,0,0,0,,,0,0,0,0,,,0,0,0,0,,,0,0,0,0,,,0,0,0,0,AAPL
2024-10-22 13:08:31.949740676+00:00,10,41,38,A,B,0,234.28,200,194,60710,263760,,234.28,0,200,0,0,,,0,0,0,0,,,0,0,0,0,,,0,0,0,0,,,0,0,0,0,,,0,0,0,0,,,0,0,0,0,,,0,0,0,0,,,0,0,0,0,,,0,0,0,0,AAPL
2024-10-22 13:08:31.949764355+00:00,10,41,38,A,B,0,234.28,200,194,54838,263761,233.64,234.28,200,200,0,0,,,0,0,0,0,,,0,0,0,0,,,0,0,0,0,,,0,0,0,0,,,0,0,0,0,,,0,0,0,0,,,0,0,0,0,,,0,0,0,0,,,0,0,0,0,AAPL
2024-10-22 13:08:31.987246349+00:00,10,40,38,A,B,0,234.33,200,194,203158,113773,,234.33,0,200,0,0,,,0,0,0,0,,,0,0,0,0,,,0,0,0,0,,,0,0,0,0,,,0,0,0,0,,,0,0,0,0,,,0,0,0,0,,,0,0,0,0,,,0,0,0,0,AAPL
2024-10-22 13:08:31.987269781+00:00,10,40,38,A,B,0,234.33,200,194,203136,113774,233.59,234.33,200,200,0,0,,,0,0,0,0,,,0,0,0,0,,,0,0,0,0,,,0,0,0,0,,,0,0,0,0,,,0,0,0,0,,,0,0,0,0,,,0,0,0,0,,,0,0,0,0,AAPL
2024-10-22 13:08:34.359171725+00:00,10,39,38,C,B,0,232.2,2000,130,203495,67784,,,0,0,0,0,,,0,0,0,0,,,0,0,0,0,,,0,0,0,0,,,0,0,0,0,,,0,0,0,0,,,0,0,0,0,,,0,0,0,0,,,0,0,0,0,,,0,0,0,0,AAPL
2024-10-22 13:08:34.395610129+00:00,10,39,38,A,B,0,232.4,2000,130,203347,67785,232.4,,2000,0,1,0,,,0,0,0,0,,,0,0,0,0,,,0,0,0,0,,,0,0,0,0,,,0,0,0,0,,,0,0,0,0,,,0,0,0,0,,,0,0,0,0,,,0,0,0,0,AAPL
2024-10-22 13:08:34.511681672+00:00,10,39,38,C,B,0,232.4,2000,130,203398,67786,,,0,0,0,0,,,0,0,0,0,,,0,0,0,0,,,0,0,0,0,,,0,0,0,0,,,0,0,0,0,,,0,0,0,0,,,0,0,0,0,,,0,0,0,0,,,0,0,0,0,AAPL
2024-10-22 13:08:34.548843962+00:00,10,39,38,A,B,0,232.4,2000,130,203130,67789,232.4,,2000,0,1,0,,,0,0,0,0,,,0,0,0,0,,,0,0,0,0,,,0,0,0,0,,,0,0,0,0,,,0,0,0,0,,,0,0,0,0,,,0,0,0,0,,,0,0,0,0,AAPL
2024-10-22 13:08:34.812371971+00:00,10,41,38,A,A,0,,0,194,56086,263882,233.64,,200,0,0,0,,,0,0,0,0,,,0,0,0,0,,,0,0,0,0,,,0,0,0,0,,,0,0,0,0,,,0,0,0,0,,,0,0,0,0,,,0,0,0,0,,,0,0,0,0,AAPL
2024-10-22 13:08:34.812423258+00:00,10,41,38,A,A,0,234.15,200,194,54578,263883,233.64,234.15,200,200,0,0,,,0,0,0,0,,,0,0,0,0,,,0,0,0,0,,,0,0,0,0,,,0,0,0,0,,,0,0,0,0,,,0,0,0,0,,,0,0,0,0,,,0,0,0,0,AAPL
2024-10-22 13:08:34.862509405+00:00,10,39,38,C,B,0,232.4,2000,130,203435,67790,,,0,0,0,0,,,0,0,0,0,,,0,0,0,0,,,0,0,0,0,,,0,0,0,0,,,0,0,0,0,,,0,0,0,0,,,0,0,0,0,,,0,0,0,0,,,0,0,0,0,AAPL
2024-10-22 13:08:34.941907018+00:00,10,39,38,A,B,0,231.8,2000,130,203348,67791,231.8,,2000,0,1,0,,,0,0,0,0,,,0,0,0,0,,,0,0,0,0,,,0,0,0,0,,,0,0,0,0,,,0,0,0,0,,,0,0,0,0,,,0,0,0,0,,,0,0,0,0,AAPL
2024-10-22 13:08:34.955371074+00:00,10,39,38,A,B,0,232.0,2000,130,203203,67792,232.0,,2000,0,1,0,231.8,,2000,0,1,0,,,0,0,0,0,,,0,0,0,0,,,0,0,0,0,,,0,0,0,0,,,0,0,0,0,,,0,0,0,0,,,0,0,0,0,,,0,0,0,0,AAPL
2024-10-22 13:08:34.955549834+00:00,10,39,38,C,B,1,231.8,2000,130,203169,67793,232.0,,2000,0,1,0,,,0,0,0,0,,,0,0,0,0,,,0,0,0,0,,,0,0,0,0,,,0,0,0,0,,,0,0,0,0,,,0,0,0,0,,,0,0,0,0,,,0,0,0,0,AAPL
2024-10-22 13:08:34.965115149+00:00,10,39,38,C,B,0,232.0,2000,130,203180,67794,,,0,0,0,0,,,0,0,0,0,,,0,0,0,0,,,0,0,0,0,,,0,0,0,0,,,0,0,0,0,,,0,0,0,0,,,0,0,0,0,,,0,0,0,0,,,0,0,0,0,AAPL
2024-10-22 13:08:34.976302121+00:00,10,39,38,A,B,0,231.8,2000,130,203152,67795,231.8,,2000,0,1,0,,,0,0,0,0,,,0,0,0,0,,,0,0,0,0,,,0,0,0,0,,,0,0,0,0,,,0,0,0,0,,,0,0,0,0,,,0,0,0,0,,,0,0,0,0,AAPL
2024-10-22 13:08:34.984402725+00:00,10,40,38,A,A,0,,0,194,203415,113807,233.59,,200,0,0,0,,,0,0,0,0,,,0,0,0,0,,,0,0,0,0,,,0,0,0,0,,,0,0,0,0,,,0,0,0,0,,,0,0,0,0,,,0,0,0,0,,,0,0,0,0,AAPL
2024-10-22 13:08:34.984425239+00:00,10,40,38,A,A,0,234.18,200,194,203288,113808,233.59,234.18,200,200,0,0,,,0,0,0,0,,,0,0,0,0,,,0,0,0,0,,,0,0,0,0,,,0,0,0,0,,,0,0,0,0,,,0,0,0,0,,,0,0,0,0,,,0,0,0,0,AAPL
2024-10-22 13:08:35.005618859+00:00,10,39,38,C,B,0,231.8,2000,130,203216,67797,,,0,0,0,0,,,0,0,0,0,,,0,0,0,0,,,0,0,0,0,,,0,0,0,0,,,0,0,0,0,,,0,0,0,0,,,0,0,0,0,,,0,0,0,0,,,0,0,0,0,AAPL
2024-10-22 13:08:35.016316348+00:00,10,39,38,A,A,0,236.2,2000,130,203166,67798,,236.2,0,2000,0,1,,,0,0,0,0,,,0,0,0,0,,,0,0,0,0,,,0,0,0,0,,,0,0,0,0,,,0,0,0,0,,,0,0,0,0,,,0,0,0,0,,,0,0,0,0,AAPL
2024-10-22 13:08:35.062522836+00:00,10,39,38,A,B,0,232.4,2000,130,203157,67802,232.4,236.2,2000,2000,1,1,,,0,0,0,0,,,0,0,0,0,,,0,0,0,0,,,0,0,0,0,,,0,0,0,0,,,0,0,0,0,,,0,0,0,0,,,0,0,0,0,,,0,0,0,0,AAPL
2024-10-22 13:08:35.313724097+00:00,10,41,38,A,B,0,234.15,200,194,55498,263935,,234.15,0,200,0,0,,,0,0,0,0,,,0,0,0,0,,,0,0,0,0,,,0,0,0,0,,,0,0,0,0,,,0,0,0,0,,,0,0,0,0,,,0,0,0,0,,,0,0,0,0,AAPL
2024-10-22 13:08:35.313747313+00:00,10,41,38,A,B,0,234.15,200,194,61748,263936,233.55,234.15,200,200,0,0,,,0,0,0,0,,,0,0,0,0,,,0,0,0,0,,,0,0,0,0,,,0,0,0,0,,,0,0,0,0,,,0,0,0,0,,,0,0,0,0,,,0,0,0,0,AAPL
2024-10-22 13:08:35.996149686+00:00,10,39,38,C,A,0,236.2,2000,130,203494,67820,232.4,,2000,0,1,0,,,0,0,0,0,,,0,0,0,0,,,0,0,0,0,,,0,0,0,0,,,0,0,0,0,,,0,0,0,0,,,0,0,0,0,,,0,0,0,0,,,0,0,0,0,AAPL
2024-10-22 13:08:36.080828467+00:00,10,39,38,A,A,0,236.2,2000,130,203360,67822,232.4,236.2,2000,2000,1,1,,,0,0,0,0,,,0,0,0,0,,,0,0,0,0,,,0,0,0,0,,,0,0,0,0,,,0,0,0,0,,,0,0,0,0,,,0,0,0,0,,,0,0,0,0,AAPL
2024-10-22 13:08:36.104058010+00:00,10,39,38,C,A,0,236.2,2000,130,203240,67823,232.4,,2000,0,1,0,,,0,0,0,0,,,0,0,0,0,,,0,0,0,0,,,0,0,0,0,,,0,0,0,0,,,0,0,0,0,,,0,0,0,0,,,0,0,0,0,,,0,0,0,0,AAPL
2024-10-22 13:08:36.926327397+00:00,10,39,38,A,A,0,236.2,2000,130,203330,67830,232.4,236.2,2000,2000,1,1,,,0,0,0,0,,,0,0,0,0,,,0,0,0,0,,,0,0,0,0,,,0,0,0,0,,,0,0,0,0,,,0,0,0,0,,,0,0,0,0,,,0,0,0,0,AAPL
2024-10-22 13:08:36.954798660+00:00,10,39,38,C,A,0,236.2,2000,130,203219,67836,232.4,,2000,0,1,0,,,0,0,0,0,,,0,0,0,0,,,0,0,0,0,,,0,0,0,0,,,0,0,0,0,,,0,0,0,0,,,0,0,0,0,,,0,0,0,0,,,0,0,0,0,AAPL
2024-10-22 13:08:36.965726285+00:00,10,39,38,A,A,0,236.2,2000,130,203419,67837,232.4,236.2,2000,2000,1,1,,,0,0,0,0,,,0,0,0,0,,,0,0,0,0,,,0,0,0,0,,,0,0,0,0,,,0,0,0,0,,,0,0,0,0,,,0,0,0,0,,,0,0,0,0,AAPL
2024-10-22 13:08:36.980023207+00:00,10,39,38,C,A,0,236.2,2000,130,203218,67840,232.4,,2000,0,1,0,,,0,0,0,0,,,0,0,0,0,,,0,0,0,0,,,0,0,0,0,,,0,0,0,0,,,0,0,0,0,,,0,0,0,0,,,0,0,0,0,,,0,0,0,0,AAPL
2024-10-22 13:08:38.189852288+00:00,10,39,38,A,A,0,236.2,2000,130,204019,67850,232.4,236.2,2000,2000,1,1,,,0,0,0,0,,,0,0,0,0,,,0,0,0,0,,,0,0,0,0,,,0,0,0,0,,,0,0,0,0,,,0,0,0,0,,,0,0,0,0,,,0,0,0,0,AAPL
2024-10-22 13:08:38.244498848+00:00,10,39,38,C,A,0,236.2,2000,130,203280,67851,232.4,,2000,0,1,0,,,0,0,0,0,,,0,0,0,0,,,0,0,0,0,,,0,0,0,0,,,0,0,0,0,,,0,0,0,0,,,0,0,0,0,,,0,0,0,0,,,0,0,0,0,AAPL
2024-10-22 13:08:38.282338512+00:00,10,39,38,A,A,0,236.2,2000,130,203321,67852,232.4,236.2,2000,2000,1,1,,,0,0,0,0,,,0,0,0,0,,,0,0,0,0,,,0,0,0,0,,,0,0,0,0,,,0,0,0,0,,,0,0,0,0,,,0,0,0,0,,,0,0,0,0,AAPL
2024-10-22 13:08:42.556397944+00:00,10,39,38,C,B,0,232.4,2000,130,203897,67858,,236.2,0,2000,0,1,,,0,0,0,0,,,0,0,0,0,,,0,0,0,0,,,0,0,0,0,,,0,0,0,0,,,0,0,0,0,,,0,0,0,0,,,0,0,0,0,,,0,0,0,0,AAPL
2024-10-22 13:08:42.594342169+00:00,10,39,38,A,B,0,232.4,2000,130,203461,67859,232.4,236.2,2000,2000,1,1,,,0,0,0,0,,,0,0,0,0,,,0,0,0,0,,,0,0,0,0,,,0,0,0,0,,,0,0,0,0,,,0,0,0,0,,,0,0,0,0,,,0,0,0,0,AAPL
2024-10-22 13:08:42.724103897+00:00,10,39,38,C,A,0,236.2,2000,130,203411,67861,232.4,,2000,0,1,0,,,0,0,0,0,,,0,0,0,0,,,0,0,0,0,,,0,0,0,0,,,0,0,0,0,,,0,0,0,0,,,0,0,0,0,,,0,0,0,0,,,0,0,0,0,AAPL
2024-10-22 13:08:42.734865990+00:00,10,39,38,A,A,0,236.2,2000,130,203389,67862,232.4,236.2,2000,2000,1,1,,,0,0,0,0,,,0,0,0,0,,,0,0,0,0,,,0,0,0,0,,,0,0,0,0,,,0,0,0,0,,,0,0,0,0,,,0,0,0,0,,,0,0,0,0,AAPL
2024-10-22 13:08:42.899298440+00:00,10,40,38,A,B,0,234.18,200,194,202478,113988,,234.18,0,200,0,0,,,0,0,0,0,,,0,0,0,0,,,0,0,0,0,,,0,0,0,0,,,0,0,0,0,,,0,0,0,0,,,0,0,0,0,,,0,0,0,0,,,0,0,0,0,AAPL
2024-10-22 13:08:42.899323652+00:00,10,40,38,A,B,0,234.18,200,194,202547,113989,233.47,234.18,200,200,0,0,,,0,0,0,0,,,0,0,0,0,,,0,0,0,0,,,0,0,0,0,,,0,0,0,0,,,0,0,0,0,,,0,0,0,0,,,0,0,0,0,,,0,0,0,0,AAPL
2024-10-22 13:08:43.422138934+00:00,10,41,38,A,A,0,,0,194,60770,264464,233.55,,200,0,0,0,,,0,0,0,0,,,0,0,0,0,,,0,0,0,0,,,0,0,0,0,,,0,0,0,0,,,0,0,0,0,,,0,0,0,0,,,0,0,0,0,,,0,0,0,0,AAPL
2024-10-22 13:08:43.422170135+00:00,10,41,38,A,A,0,234.06,200,194,54467,264465,233.55,234.06,200,200,0,0,,,0,0,0,0,,,0,0,0,0,,,0,0,0,0,,,0,0,0,0,,,0,0,0,0,,,0,0,0,0,,,0,0,0,0,,,0,0,0,0,,,0,0,0,0,AAPL
2024-10-22 13:08:48.086131950+00:00,10,39,38,C,B,0,232.4,2000,130,203788,67871,,236.2,0,2000,0,1,,,0,0,0,0,,,0,0,0,0,,,0,0,0,0,,,0,0,0,0,,,0,0,0,0,,,0,0,0,0,,,0,0,0,0,,,0,0,0,0,,,0,0,0,0,AAPL
2024-10-22 13:08:48.097601268+00:00,10,39,38,A,B,0,232.2,2000,130,203572,67872,232.2,236.2,2000,2000,1,1,,,0,0,0,0,,,0,0,0,0,,,0,0,0,0,,,0,0,0,0,,,0,0,0,0,,,0,0,0,0,,,0,0,0,0,,,0,0,0,0,,,0,0,0,0,AAPL
2024-10-22 13:08:49.135537915+00:00,10,39,10888,A,A,0,421.6,2000,130,204105,100158,,421.6,0,2000,0,1,,,0,0,0,0,,,0,0,0,0,,,0,0,0,0,,,0,0,0,0,,,0,0,0,0,,,0,0,0,0,,,0,0,0,0,,,0,0,0,0,,,0,0,0,0,MSFT
2024-10-22 13:08:51.446641950+00:00,10,39,38,A,B,0,232.4,2000,130,203815,67896,232.4,236.2,2000,2000,1,1,232.2,,2000,0,1,0,,,0,0,0,0,,,0,0,0,0,,,0,0,0,0,,,0,0,0,0,,,0,0,0,0,,,0,0,0,0,,,0,0,0,0,,,0,0,0,0,AAPL
2024-10-22 13:08:51.446833758+00:00,10,39,38,C,B,1,232.2,2000,130,203636,67897,232.4,236.2,2000,2000,1,1,,,0,0,0,0,,,0,0,0,0,,,0,0,0,0,,,0,0,0,0,,,0,0,0,0,,,0,0,0,0,,,0,0,0,0,,,0,0,0,0,,,0,0,0,0,AAPL
2024-10-22 13:08:57.175303602+00:00,10,39,10888,C,A,0,421.6,2000,130,203648,100216,,,0,0,0,0,,,0,0,0,0,,,0,0,0,0,,,0,0,0,0,,,0,0,0,0,,,0,0,0,0,,,0,0,0,0,,,0,0,0,0,,,0,0,0,0,,,0,0,0,0,MSFT
2024-10-22 13:08:57.211504390+00:00,10,39,10888,A,A,0,421.2,2000,130,203737,100217,,421.2,0,2000,0,1,,,0,0,0,0,,,0,0,0,0,,,0,0,0,0,,,0,0,0,0,,,0,0,0,0,,,0,0,0,0,,,0,0,0,0,,,0,0,0,0,,,0,0,0,0,MSFT
2024-10-22 13:09:00.022797636+00:00,10,40,38,A,B,0,234.18,200,194,201890,114235,,234.18,0,200,0,0,,,0,0,0,0,,,0,0,0,0,,,0,0,0,0,,,0,0,0,0,,,0,0,0,0,,,0,0,0,0,,,0,0,0,0,,,0,0,0,0,,,0,0,0,0,AAPL
2024-10-22 13:09:00.022817120+00:00,10,40,38,A,A,0,,0,194,201900,114236,,,0,0,0,0,,,0,0,0,0,,,0,0,0,0,,,0,0,0,0,,,0,0,0,0,,,0,0,0,0,,,0,0,0,0,,,0,0,0,0,,,0,0,0,0,,,0,0,0,0,AAPL
2024-10-22 13:09:00.022835364+00:00,10,40,38,A,A,0,234.11,200,194,201875,114237,,234.11,0,200,0,0,,,0,0,0,0,,,0,0,0,0,,,0,0,0,0,,,0,0,0,0,,,0,0,0,0,,,0,0,0,0,,,0,0,0,0,,,0,0,0,0,,,0,0,0,0,AAPL
2024-10-22 13:09:00.023167921+00:00,10,41,38,A,B,0,234.06,200,194,58976,265797,,234.06,0,200,0,0,,,0,0,0,0,,,0,0,0,0,,,0,0,0,0,,,0,0,0,0,,,0,0,0,0,,,0,0,0,0,,,0,0,0,0,,,0,0,0,0,,,0,0,0,0,AAPL
2024-10-22 13:09:00.111056919+00:00,10,40,38,A,B,0,234.11,200,194,201893,114280,233.48,234.11,200,200,0,0,,,0,0,0,0,,,0,0,0,0,,,0,0,0,0,,,0,0,0,0,,,0,0,0,0,,,0,0,0,0,,,0,0,0,0,,,0,0,0,0,,,0,0,0,0,AAPL
2024-10-22 13:09:00.343195415+00:00,10,40,38,A,B,0,234.11,200,194,201905,114307,,234.11,0,200,0,0,,,0,0,0,0,,,0,0,0,0,,,0,0,0,0,,,0,0,0,0,,,0,0,0,0,,,0,0,0,0,,,0,0,0,0,,,0,0,0,0,,,0,0,0,0,AAPL
2024-10-22 13:09:01.975859826+00:00,10,40,38,A,B,0,234.11,200,194,202008,114343,233.48,234.11,200,200,0,0,,,0,0,0,0,,,0,0,0,0,,,0,0,0,0,,,0,0,0,0,,,0,0,0,0,,,0,0,0,0,,,0,0,0,0,,,0,0,0,0,,,0,0,0,0,AAPL
2024-10-22 13:09:01.976102303+00:00,10,41,38,A,B,0,234.06,200,194,55909,266218,233.53,234.06,200,200,0,0,,,0,0,0,0,,,0,0,0,0,,,0,0,0,0,,,0,0,0,0,,,0,0,0,0,,,0,0,0,0,,,0,0,0,0,,,0,0,0,0,,,0,0,0,0,AAPL
2024-10-22 13:09:02.180129638+00:00,10,41,38,A,B,0,234.06,200,194,60642,266226,,234.06,0,200,0,0,,,0,0,0,0,,,0,0,0,0,,,0,0,0,0,,,0,0,0,0,,,0,0,0,0,,,0,0,0,0,,,0,0,0,0,,,0,0,0,0,,,0,0,0,0,AAPL
2024-10-22 13:09:02.746231332+00:00,10,41,38,A,B,0,234.06,200,194,54878,266258,233.53,234.06,200,200,0,0,,,0,0,0,0,,,0,0,0,0,,,0,0,0,0,,,0,0,0,0,,,0,0,0,0,,,0,0,0,0,,,0,0,0,0,,,0,0,0,0,,,0,0,0,0,AAPL
2024-10-22 13:09:04.936816969+00:00,10,39,38,C,B,0,232.4,2000,130,203285,67958,,236.2,0,2000,0,1,,,0,0,0,0,,,0,0,0,0,,,0,0,0,0,,,0,0,0,0,,,0,0,0,0,,,0,0,0,0,,,0,0,0,0,,,0,0,0,0,,,0,0,0,0,AAPL
2024-10-22 13:09:04.972386178+00:00,10,39,38,A,B,0,232.4,2000,130,203330,67959,232.4,236.2,2000,2000,1,1,,,0,0,0,0,,,0,0,0,0,,,0,0,0,0,,,0,0,0,0,,,0,0,0,0,,,0,0,0,0,,,0,0,0,0,,,0,0,0,0,,,0,0,0,0,AAPL
2024-10-22 13:09:05.002849007+00:00,10,39,38,C,A,0,236.2,2000,130,203243,67961,232.4,,2000,0,1,0,,,0,0,0,0,,,0,0,0,0,,,0,0,0,0,,,0,0,0,0,,,0,0,0,0,,,0,0,0,0,,,0,0,0,0,,,0,0,0,0,,,0,0,0,0,AAPL
2024-10-22 13:09:09.680877012+00:00,10,39,38,A,A,0,236.2,2000,130,203997,67963,232.4,236.2,2000,2000,1,1,,,0,0,0,0,,,0,0,0,0,,,0,0,0,0,,,0,0,0,0,,,0,0,0,0,,,0,0,0,0,,,0,0,0,0,,,0,0,0,0,,,0,0,0,0,AAPL
2024-10-22 13:09:10.157007873+00:00,10,39,38,C,B,0,232.4,2000,130,204136,67965,,236.2,0,2000,0,1,,,0,0,0,0,,,0,0,0,0,,,0,0,0,0,,,0,0,0,0,,,0,0,0,0,,,0,0,0,0,,,0,0,0,0,,,0,0,0,0,,,0,0,0,0,AAPL
2024-10-22 13:09:10.168767175+00:00,10,39,38,A,B,0,232.2,2000,130,203528,67966,232.2,236.2,2000,2000,1,1,,,0,0,0,0,,,0,0,0,0,,,0,0,0,0,,,0,0,0,0,,,0,0,0,0,,,0,0,0,0,,,0,0,0,0,,,0,0,0,0,,,0,0,0,0,AAPL
2024-10-22 13:09:10.183075376+00:00,10,39,38,C,B,0,232.2,2000,130,203385,67967,,236.2,0,2000,0,1,,,0,0,0,0,,,0,0,0,0,,,0,0,0,0,,,0,0,0,0,,,0,0,0,0,,,0,0,0,0,,,0,0,0,0,,,0,0,0,0,,,0,0,0,0,AAPL
2024-10-22 13:09:10.196701376+00:00,10,39,38,A,B,0,232.0,2000,130,203528,67969,232.0,236.2,2000,2000,1,1,,,0,0,0,0,,,0,0,0,0,,,0,0,0,0,,,0,0,0,0,,,0,0,0,0,,,0,0,0,0,,,0,0,0,0,,,0,0,0,0,,,0,0,0,0,AAPL
2024-10-22 13:09:10.727225194+00:00,10,39,38,C,A,0,236.2,2000,130,203477,67971,232.0,,2000,0,1,0,,,0,0,0,0,,,0,0,0,0,,,0,0,0,0,,,0,0,0,0,,,0,0,0,0,,,0,0,0,0,,,0,0,0,0,,,0,0,0,0,,,0,0,0,0,AAPL
2024-10-22 13:09:10.738694118+00:00,10,39,38,A,B,0,232.4,2000,130,203325,67972,232.4,,2000,0,1,0,232.0,,2000,0,1,0,,,0,0,0,0,,,0,0,0,0,,,0,0,0,0,,,0,0,0,0,,,0,0,0,0,,,0,0,0,0,,,0,0,0,0,,,0,0,0,0,AAPL
2024-10-22 13:09:10.738876842+00:00,10,39,38,C,B,1,232.0,2000,130,203423,67973,232.4,,2000,0,1,0,,,0,0,0,0,,,0,0,0,0,,,0,0,0,0,,,0,0,0,0,,,0,0,0,0,,,0,0,0,0,,,0,0,0,0,,,0,0,0,0,,,0,0,0,0,AAPL
2024-10-22 13:09:10.761529593+00:00,10,39,38,A,A,0,236.2,2000,130,203327,67974,232.4,236.2,2000,2000,1,1,,,0,0,0,0,,,0,0,0,0,,,0,0,0,0,,,0,0,0,0,,,0,0,0,0,,,0,0,0,0,,,0,0,0,0,,,0,0,0,0,,,0,0,0,0,AAPL
2024-10-22 13:09:10.779909771+00:00,10,39,38,C,A,0,236.2,2000,130,203405,67975,232.4,,2000,0,1,0,,,0,0,0,0,,,0,0,0,0,,,0,0,0,0,,,0,0,0,0,,,0,0,0,0,,,0,0,0,0,,,0,0,0,0,,,0,0,0,0,,,0,0,0,0,AAPL
2024-10-22 13:09:10.794536013+00:00,10,39,38,A,A,0,236.2,2000,130,203359,67976,232.4,236.2,2000,2000,1,1,,,0,0,0,0,,,0,0,0,0,,,0,0,0,0,,,0,0,0,0,,,0,0,0,0,,,0,0,0,0,,,0,0,0,0,,,0,0,0,0,,,0,0,0,0,AAPL
2024-10-22 13:09:11.060554634+00:00,10,41,38,A,A,0,,0,194,55740,266724,233.53,,200,0,0,0,,,0,0,0,0,,,0,0,0,0,,,0,0,0,0,,,0,0,0,0,,,0,0,0,0,,,0,0,0,0,,,0,0,0,0,,,0,0,0,0,,,0,0,0,0,AAPL
2024-10-22 13:09:11.060572093+00:00,10,41,38,A,A,0,234.21,200,194,63493,266725,233.53,234.21,200,200,0,0,,,0,0,0,0,,,0,0,0,0,,,0,0,0,0,,,0,0,0,0,,,0,0,0,0,,,0,0,0,0,,,0,0,0,0,,,0,0,0,0,,,0,0,0,0,AAPL
2024-10-22 13:09:11.061018874+00:00,10,39,38,C,A,0,236.2,2000,130,203894,67978,232.4,,2000,0,1,0,,,0,0,0,0,,,0,0,0,0,,,0,0,0,0,,,0,0,0,0,,,0,0,0,0,,,0,0,0,0,,,0,0,0,0,,,0,0,0,0,,,0,0,0,0,AAPL
2024-10-22 13:09:11.357685722+00:00,10,40,38,A,A,0,,0,194,201610,114521,233.48,,200,0,0,0,,,0,0,0,0,,,0,0,0,0,,,0,0,0,0,,,0,0,0,0,,,0,0,0,0,,,0,0,0,0,,,0,0,0,0,,,0,0,0,0,,,0,0,0,0,AAPL
2024-10-22 13:09:11.357703399+00:00,10,40,38,A,A,0,234.26,200,194,201568,114522,233.48,234.26,200,200,0,0,,,0,0,0,0,,,0,0,0,0,,,0,0,0,0,,,0,0,0,0,,,0,0,0,0,,,0,0,0,0,,,0,0,0,0,,,0,0,0,0,,,0,0,0,0,AAPL
2024-10-22 13:09:20.382796873+00:00,10,39,38,C,B,0,232.4,2000,130,204062,68036,,,0,0,0,0,,,0,0,0,0,,,0,0,0,0,,,0,0,0,0,,,0,0,0,0,,,0,0,0,0,,,0,0,0,0,,,0,0,0,0,,,0,0,0,0,,,0,0,0,0,AAPL
2024-10-22 13:09:20.397651832+00:00,10,39,38,A,B,0,232.2,2000,130,203676,68037,232.2,,2000,0,1,0,,,0,0,0,0,,,0,0,0,0,,,0,0,0,0,,,0,0,0,0,,,0,0,0,0,,,0,0,0,0,,,0,0,0,0,,,0,0,0,0,,,0,0,0,0,AAPL
2024-10-22 13:09:20.413925809+00:00,10,39,38,C,B,0,232.2,2000,130,203550,68038,,,0,0,0,0,,,0,0,0,0,,,0,0,0,0,,,0,0,0,0,,,0,0,0,0,,,0,0,0,0,,,0,0,0,0,,,0,0,0,0,,,0,0,0,0,,,0,0,0,0,AAPL
2024-10-22 13:09:20.424892768+00:00,10,39,38,A,B,0,232.0,2000,130,203583,68039,232.0,,2000,0,1,0,,,0,0,0,0,,,0,0,0,0,,,0,0,0,0,,,0,0,0,0,,,0,0,0,0,,,0,0,0,0,,,0,0,0,0,,,0,0,0,0,,,0,0,0,0,AAPL
2024-10-22 13:09:20.655558566+00:00,10,41,38,A,B,0,234.21,200,194,56579,267288,,234.21,0,200,0,0,,,0,0,0,0,,,0,0,0,0,,,0,0,0,0,,,0,0,0,0,,,0,0,0,0,,,0,0,0,0,,,0,0,0,0,,,0,0,0,0,,,0,0,0,0,AAPL
2024-10-22 13:09:20.655589574+00:00,10,41,38,A,B,0,234.21,200,194,54490,267289,233.62,234.21,200,200,0,0,,,0,0,0,0,,,0,0,0,0,,,0,0,0,0,,,0,0,0,0,,,0,0,0,0,,,0,0,0,0,,,0,0,0,0,,,0,0,0,0,,,0,0,0,0,AAPL
2024-10-22 13:09:24.985321563+00:00,10,39,38,A,B,0,232.2,2000,130,203891,68061,232.2,,2000,0,1,0,232.0,,2000,0,1,0,,,0,0,0,0,,,0,0,0,0,,,0,0,0,0,,,0,0,0,0,,,0,0,0,0,,,0,0,0,0,,,0,0,0,0,,,0,0,0,0,AAPL
2024-10-22 13:09:24.985515512+00:00,10,39,38,C,B,1,232.0,2000,130,203452,68062,232.2,,2000,0,1,0,,,0,0,0,0,,,0,0,0,0,,,0,0,0,0,,,0,0,0,0,,,0,0,0,0,,,0,0,0,0,,,0,0,0,0,,,0,0,0,0,,,0,0,0,0,AAPL
2024-10-22 13:09:25.284909139+00:00,10,40,38,A,B,0,234.26,200,194,201465,114696,,234.26,0,200,0,0,,,0,0,0,0,,,0,0,0,0,,,0,0,0,0,,,0,0,0,0,,,0,0,0,0,,,0,0,0,0,,,0,0,0,0,,,0,0,0,0,,,0,0,0,0,AAPL
2024-10-22 13:09:25.284923902+00:00,10,40,38,A,B,0,234.26,200,194,201486,114697,233.6,234.26,200,200,0,0,,,0,0,0,0,,,0,0,0,0,,,0,0,0,0,,,0,0,0,0,,,0,0,0,0,,,0,0,0,0,,,0,0,0,0,,,0,0,0,0,,,0,0,0,0,AAPL
2024-10-22 13:09:28.016204964+00:00,10,39,38,C,B,0,232.2,2000,130,203788,68103,,,0,0,0,0,,,0,0,0,0,,,0,0,0,0,,,0,0,0,0,,,0,0,0,0,,,0,0,0,0,,,0,0,0,0,,,0,0,0,0,,,0,0,0,0,,,0,0,0,0,AAPL
2024-10-22 13:09:28.052306998+00:00,10,39,38,A,B,0,232.4,2000,130,203857,68104,232.4,,2000,0,1,0,,,0,0,0,0,,,0,0,0,0,,,0,0,0,0,,,0,0,0,0,,,0,0,0,0,,,0,0,0,0,,,0,0,0,0,,,0,0,0,0,,,0,0,0,0,AAPL
2024-10-22 13:09:28.118640224+00:00,10,39,38,C,B,0,232.4,2000,130,203724,68106,,,0,0,0,0,,,0,0,0,0,,,0,0,0,0,,,0,0,0,0,,,0,0,0,0,,,0,0,0,0,,,0,0,0,0,,,0,0,0,0,,,0,0,0,0,,,0,0,0,0,AAPL
2024-10-22 13:09:28.132452411+00:00,10,39,38,A,B,0,232.4,2000,130,203861,68107,232.4,,2000,0,1,0,,,0,0,0,0,,,0,0,0,0,,,0,0,0,0,,,0,0,0,0,,,0,0,0,0,,,0,0,0,0,,,0,0,0,0,,,0,0,0,0,,,0,0,0,0,AAPL
2024-10-22 13:09:28.321715910+00:00,10,40,38,A,B,0,234.26,200,194,201555,114747,,234.26,0,200,0,0,,,0,0,0,0,,,0,0,0,0,,,0,0,0,0,,,0,0,0,0,,,0,0,0,0,,,0,0,0,0,,,0,0,0,0,,,0,0,0,0,,,0,0,0,0,AAPL
2024-10-22 13:09:28.321735692+00:00,10,40,38,A,B,0,234.26,200,194,201496,114748,233.49,234.26,200,200,0,0,,,0,0,0,0,,,0,0,0,0,,,0,0,0,0,,,0,0,0,0,,,0,0,0,0,,,0,0,0,0,,,0,0,0,0,,,0,0,0,0,,,0,0,0,0,AAPL
2024-10-22 13:09:38.172011618+00:00,10,39,38,C,B,0,232.4,2000,130,204271,68136,,,0,0,0,0,,,0,0,0,0,,,0,0,0,0,,,0,0,0,0,,,0,0,0,0,,,0,0,0,0,,,0,0,0,0,,,0,0,0,0,,,0,0,0,0,,,0,0,0,0,AAPL
2024-10-22 13:09:38.184470213+00:00,10,39,38,A,B,0,232.2,2000,130,204044,68137,232.2,,2000,0,1,0,,,0,0,0,0,,,0,0,0,0,,,0,0,0,0,,,0,0,0,0,,,0,0,0,0,,,0,0,0,0,,,0,0,0,0,,,0,0,0,0,,,0,0,0,0,AAPL
2024-10-22 13:09:50.543526857+00:00,10,39,38,A,B,0,232.4,2000,130,204567,68180,232.4,,2000,0,1,0,232.2,,2000,0,1,0,,,0,0,0,0,,,0,0,0,0,,,0,0,0,0,,,0,0,0,0,,,0,0,0,0,,,0,0,0,0,,,0,0,0,0,,,0,0,0,0,AAPL
2024-10-22 13:09:50.543727716+00:00,10,39,38,C,B,1,232.2,2000,130,204172,68181,232.4,,2000,0,1,0,,,0,0,0,0,,,0,0,0,0,,,0,0,0,0,,,0,0,0,0,,,0,0,0,0,,,0,0,0,0,,,0,0,0,0,,,0,0,0,0,,,0,0,0,0,AAPL
2024-10-22 13:09:50.939543097+00:00,10,39,38,A,A,0,236.2,2000,130,204223,68184,232.4,236.2,2000,2000,1,1,,,0,0,0,0,,,0,0,0,0,,,0,0,0,0,,,0,0,0,0,,,0,0,0,0,,,0,0,0,0,,,0,0,0,0,,,0,0,0,0,,,0,0,0,0,AAPL
2024-10-22 13:09:50.993918614+00:00,10,39,38,C,A,0,236.2,2000,130,204076,68190,232.4,,2000,0,1,0,,,0,0,0,0,,,0,0,0,0,,,0,0,0,0,,,0,0,0,0,,,0,0,0,0,,,0,0,0,0,,,0,0,0,0,,,0,0,0,0,,,0,0,0,0,AAPL
2024-10-22 13:09:57.549411421+00:00,10,39,10888,C,A,0,421.2,2000,130,204220,100642,,,0,0,0,0,,,0,0,0,0,,,0,0,0,0,,,0,0,0,0,,,0,0,0,0,,,0,0,0,0,,,0,0,0,0,,,0,0,0,0,,,0,0,0,0,,,0,0,0,0,MSFT
2024-10-22 13:09:57.586360772+00:00,10,39,10888,A,A,0,421.2,2000,130,204046,100644,,421.2,0,2000,0,1,,,0,0,0,0,,,0,0,0,0,,,0,0,0,0,,,0,0,0,0,,,0,0,0,0,,,0,0,0,0,,,0,0,0,0,,,0,0,0,0,,,0,0,0,0,MSFT
2024-10-22 13:10:00.031414323+00:00,10,40,38,A,B,0,234.26,200,194,202499,115075,,234.26,0,200,0,0,,,0,0,0,0,,,0,0,0,0,,,0,0,0,0,,,0,0,0,0,,,0,0,0,0,,,0,0,0,0,,,0,0,0,0,,,0,0,0,0,,,0,0,0,0,AAPL
2024-10-22 13:10:00.031422515+00:00,10,40,38,A,A,0,,0,194,202558,115076,,,0,0,0,0,,,0,0,0,0,,,0,0,0,0,,,0,0,0,0,,,0,0,0,0,,,0,0,0,0,,,0,0,0,0,,,0,0,0,0,,,0,0,0,0,,,0,0,0,0,AAPL
2024-10-22 13:10:00.031878908+00:00,10,41,38,A,B,0,234.21,200,194,55622,269000,,234.21,0,200,0,0,,,0,0,0,0,,,0,0,0,0,,,0,0,0,0,,,0,0,0,0,,,0,0,0,0,,,0,0,0,0,,,0,0,0,0,,,0,0,0,0,,,0,0,0,0,AAPL
2024-10-22 13:10:00.031887376+00:00,10,41,38,A,A,0,,0,194,58729,269001,,,0,0,0,0,,,0,0,0,0,,,0,0,0,0,,,0,0,0,0,,,0,0,0,0,,,0,0,0,0,,,0,0,0,0,,,0,0,0,0,,,0,0,0,0,,,0,0,0,0,AAPL
2024-10-22 13:10:00.529563598+00:00,10,41,38,A,A,0,234.2,200,194,56220,269417,,234.2,0,200,0,0,,,0,0,0,0,,,0,0,0,0,,,0,0,0,0,,,0,0,0,0,,,0,0,0,0,,,0,0,0,0,,,0,0,0,0,,,0,0,0,0,,,0,0,0,0,AAPL
2024-10-22 13:10:00.529480007+00:00,10,40,38,A,A,0,234.25,200,194,202457,115177,,234.25,0,200,0,0,,,0,0,0,0,,,0,0,0,0,,,0,0,0,0,,,0,0,0,0,,,0,0,0,0,,,0,0,0,0,,,0,0,0,0,,,0,0,0,0,,,0,0,0,0,AAPL
2024-10-22 13:10:00.931887668+00:00,10,40,38,A,A,0,,0,194,202533,115188,,,0,0,0,0,,,0,0,0,0,,,0,0,0,0,,,0,0,0,0,,,0,0,0,0,,,0,0,0,0,,,0,0,0,0,,,0,0,0,0,,,0,0,0,0,,,0,0,0,0,AAPL
2024-10-22 13:10:00.932174727+00:00,10,41,38,A,A,0,,0,194,55514,269456,,,0,0,0,0,,,0,0,0,0,,,0,0,0,0,,,0,0,0,0,,,0,0,0,0,,,0,0,0,0,,,0,0,0,0,,,0,0,0,0,,,0,0,0,0,,,0,0,0,0,AAPL
2024-10-22 13:10:02.684863831+00:00,10,40,38,A,B,0,,0,194,202896,115223,233.54,,200,0,0,0,,,0,0,0,0,,,0,0,0,0,,,0,0,0,0,,,0,0,0,0,,,0,0,0,0,,,0,0,0,0,,,0,0,0,0,,,0,0,0,0,,,0,0,0,0,AAPL
2024-10-22 13:10:02.684871257+00:00,10,40,38,A,A,0,234.25,200,194,202743,115224,233.54,234.25,200,200,0,0,,,0,0,0,0,,,0,0,0,0,,,0,0,0,0,,,0,0,0,0,,,0,0,0,0,,,0,0,0,0,,,0,0,0,0,,,0,0,0,0,,,0,0,0,0,AAPL
2024-10-22 13:10:02.685102892+00:00,10,41,38,A,B,0,,0,194,60439,269624,233.59,,200,0,0,0,,,0,0,0,0,,,0,0,0,0,,,0,0,0,0,,,0,0,0,0,,,0,0,0,0,,,0,0,0,0,,,0,0,0,0,,,0,0,0,0,,,0,0,0,0,AAPL
2024-10-22 13:10:02.685115050+00:00,10,41,38,A,A,0,234.2,200,194,54597,269625,233.59,234.2,200,200,0,0,,,0,0,0,0,,,0,0,0,0,,,0,0,0,0,,,0,0,0,0,,,0,0,0,0,,,0,0,0,0,,,0,0,0,0,,,0,0,0,0,,,0,0,0,0,AAPL
2024-10-22 13:10:08.003064574+00:00,10,39,10888,C,A,0,421.2,2000,130,204727,100705,,,0,0,0,0,,,0,0,0,0,,,0,0,0,0,,,0,0,0,0,,,0,0,0,0,,,0,0,0,0,,,0,0,0,0,,,0,0,0,0,,,0,0,0,0,,,0,0,0,0,MSFT
2024-10-22 13:10:08.014373935+00:00,10,39,10888,A,A,0,421.6,2000,130,204294,100706,,421.6,0,2000,0,1,,,0,0,0,0,,,0,0,0,0,,,0,0,0,0,,,0,0,0,0,,,0,0,0,0,,,0,0,0,0,,,0,0,0,0,,,0,0,0,0,,,0,0,0,0,MSFT
2024-10-22 13:10:08.538327152+00:00,10,39,10888,A,A,0,421.2,2000,130,204621,100707,,421.2,0,2000,0,1,,421.6,0,2000,0,1,,,0,0,0,0,,,0,0,0,0,,,0,0,0,0,,,0,0,0,0,,,0,0,0,0,,,0,0,0,0,,,0,0,0,0,,,0,0,0,0,MSFT
2024-10-22 13:10:08.538505762+00:00,10,39,10888,C,A,1,421.6,2000,130,204246,100708,,421.2,0,2000,0,1,,,0,0,0,0,,,0,0,0,0,,,0,0,0,0,,,0,0,0,0,,,0,0,0,0,,,0,0,0,0,,,0,0,0,0,,,0,0,0,0,,,0,0,0,0,MSFT
2024-10-22 13:10:13.478846912+00:00,10,39,38,A,A,0,236.2,2000,130,204039,68293,232.4,236.2,2000,2000,1,1,,,0,0,0,0,,,0,0,0,0,,,0,0,0,0,,,0,0,0,0,,,0,0,0,0,,,0,0,0,0,,,0,0,0,0,,,0,0,0,0,,,0,0,0,0,AAPL
2024-10-22 13:10:13.505177837+00:00,10,39,38,C,A,0,236.2,2000,130,203568,68294,232.4,,2000,0,1,0,,,0,0,0,0,,,0,0,0,0,,,0,0,0,0,,,0,0,0,0,,,0,0,0,0,,,0,0,0,0,,,0,0,0,0,,,0,0,0,0,,,0,0,0,0,AAPL
2024-10-22 13:10:25.682522788+00:00,10,39,10888,C,A,0,421.2,2000,130,203841,100799,,,0,0,0,0,,,0,0,0,0,,,0,0,0,0,,,0,0,0,0,,,0,0,0,0,,,0,0,0,0,,,0,0,0,0,,,0,0,0,0,,,0,0,0,0,,,0,0,0,0,MSFT
2024-10-22 13:10:25.719661520+00:00,10,39,10888,A,A,0,421.2,2000,130,203833,100802,,421.2,0,2000,0,1,,,0,0,0,0,,,0,0,0,0,,,0,0,0,0,,,0,0,0,0,,,0,0,0,0,,,0,0,0,0,,,0,0,0,0,,,0,0,0,0,,,0,0,0,0,MSFT
2024-10-22 13:10:28.312343507+00:00,10,39,10888,C,A,0,421.2,2000,130,204376,100821,,,0,0,0,0,,,0,0,0,0,,,0,0,0,0,,,0,0,0,0,,,0,0,0,0,,,0,0,0,0,,,0,0,0,0,,,0,0,0,0,,,0,0,0,0,,,0,0,0,0,MSFT
2024-10-22 13:10:28.347917242+00:00,10,39,10888,A,A,0,421.2,2000,130,204183,100823,,421.2,0,2000,0,1,,,0,0,0,0,,,0,0,0,0,,,0,0,0,0,,,0,0,0,0,,,0,0,0,0,,,0,0,0,0,,,0,0,0,0,,,0,0,0,0,,,0,0,0,0,MSFT
2024-10-22 13:10:32.919729810+00:00,10,39,38,C,B,0,232.4,2000,130,204677,68418,,,0,0,0,0,,,0,0,0,0,,,0,0,0,0,,,0,0,0,0,,,0,0,0,0,,,0,0,0,0,,,0,0,0,0,,,0,0,0,0,,,0,0,0,0,,,0,0,0,0,AAPL
2024-10-22 13:10:32.934962838+00:00,10,39,38,A,B,0,232.2,2000,130,204094,68419,232.2,,2000,0,1,0,,,0,0,0,0,,,0,0,0,0,,,0,0,0,0,,,0,0,0,0,,,0,0,0,0,,,0,0,0,0,,,0,0,0,0,,,0,0,0,0,,,0,0,0,0,AAPL
2024-10-22 13:10:44.132274458+00:00,10,39,38,C,B,0,232.2,2000,130,204131,68460,,,0,0,0,0,,,0,0,0,0,,,0,0,0,0,,,0,0,0,0,,,0,0,0,0,,,0,0,0,0,,,0,0,0,0,,,0,0,0,0,,,0,0,0,0,,,0,0,0,0,AAPL
2024-10-22 13:10:44.142344659+00:00,10,39,38,A,A,0,236.2,2000,130,203872,68461,,236.2,0,2000,0,1,,,0,0,0,0,,,0,0,0,0,,,0,0,0,0,,,0,0,0,0,,,0,0,0,0,,,0,0,0,0,,,0,0,0,0,,,0,0,0,0,,,0,0,0,0,AAPL
2024-10-22 13:10:44.169300710+00:00,10,39,38,A,B,0,232.2,2000,130,203829,68462,232.2,236.2,2000,2000,1,1,,,0,0,0,0,,,0,0,0,0,,,0,0,0,0,,,0,0,0,0,,,0,0,0,0,,,0,0,0,0,,,0,0,0,0,,,0,0,0,0,,,0,0,0,0,AAPL
2024-10-22 13:10:44.284465786+00:00,10,39,38,C,A,0,236.2,2000,130,203808,68463,232.2,,2000,0,1,0,,,0,0,0,0,,,0,0,0,0,,,0,0,0,0,,,0,0,0,0,,,0,0,0,0,,,0,0,0,0,,,0,0,0,0,,,0,0,0,0,,,0,0,0,0,AAPL
2024-10-22 13:10:44.300322655+00:00,10,39,38,A,A,0,236.2,2000,130,203714,68464,232.2,236.2,2000,2000,1,1,,,0,0,0,0,,,0,0,0,0,,,0,0,0,0,,,0,0,0,0,,,0,0,0,0,,,0,0,0,0,,,0,0,0,0,,,0,0,0,0,,,0,0,0,0,AAPL
2024-10-22 13:10:44.353143962+00:00,10,39,38,C,A,0,236.2,2000,130,203637,68465,232.2,,2000,0,1,0,,,0,0,0,0,,,0,0,0,0,,,0,0,0,0,,,0,0,0,0,,,0,0,0,0,,,0,0,0,0,,,0,0,0,0,,,0,0,0,0,,,0,0,0,0,AAPL
2024-10-22 13:10:44.390400858+00:00,10,39,38,A,A,0,236.2,2000,130,203738,68466,232.2,236.2,2000,2000,1,1,,,0,0,0,0,,,0,0,0,0,,,0,0,0,0,,,0,0,0,0,,,0,0,0,0,,,0,0,0,0,,,0,0,0,0,,,0,0,0,0,,,0,0,0,0,AAPL
2024-10-22 13:10:46.353921107+00:00,10,39,38,C,A,0,236.2,2000,130,203756,68500,232.2,,2000,0,1,0,,,0,0,0,0,,,0,0,0,0,,,0,0,0,0,,,0,0,0,0,,,0,0,0,0,,,0,0,0,0,,,0,0,0,0,,,0,0,0,0,,,0,0,0,0,AAPL
2024-10-22 13:10:46.362475142+00:00,10,39,38,A,B,0,232.4,2000,130,203675,68501,232.4,,2000,0,1,0,232.2,,2000,0,1,0,,,0,0,0,0,,,0,0,0,0,,,0,0,0,0,,,0,0,0,0,,,0,0,0,0,,,0,0,0,0,,,0,0,0,0,,,0,0,0,0,AAPL
2024-10-22 13:10:46.363154635+00:00,10,39,38,C,B,1,232.2,2000,130,203517,68502,232.4,,2000,0,1,0,,,0,0,0,0,,,0,0,0,0,,,0,0,0,0,,,0,0,0,0,,,0,0,0,0,,,0,0,0,0,,,0,0,0,0,,,0,0,0,0,,,0,0,0,0,AAPL
2024-10-22 13:10:46.387247106+00:00,10,39,38,C,B,0,232.4,2000,130,203577,68504,,,0,0,0,0,,,0,0,0,0,,,0,0,0,0,,,0,0,0,0,,,0,0,0,0,,,0,0,0,0,,,0,0,0,0,,,0,0,0,0,,,0,0,0,0,,,0,0,0,0,AAPL
2024-10-22 13:10:46.398406656+00:00,10,39,38,A,B,0,232.2,2000,130,203526,68505,232.2,,2000,0,1,0,,,0,0,0,0,,,0,0,0,0,,,0,0,0,0,,,0,0,0,0,,,0,0,0,0,,,0,0,0,0,,,0,0,0,0,,,0,0,0,0,,,0,0,0,0,AAPL
2024-10-22 13:10:46.606361523+00:00,10,39,38,C,B,0,232.2,2000,130,203469,68508,,,0,0,0,0,,,0,0,0,0,,,0,0,0,0,,,0,0,0,0,,,0,0,0,0,,,0,0,0,0,,,0,0,0,0,,,0,0,0,0,,,0,0,0,0,,,0,0,0,0,AAPL
2024-10-22 13:10:46.617368812+00:00,10,39,38,A,B,0,232.2,2000,130,203482,68509,232.2,,2000,0,1,0,,,0,0,0,0,,,0,0,0,0,,,0,0,0,0,,,0,0,0,0,,,0,0,0,0,,,0,0,0,0,,,0,0,0,0,,,0,0,0,0,,,0,0,0,0,AAPL
2024-10-22 13:10:46.666294+00:00,10,39,38,C,B,0,232.2,2000,130,203478,68510,,,0,0,0,0,,,0,0,0,0,,,0,0,0,0,,,0,0,0,0,,,0,0,0,0,,,0,0,0,0,,,0,0,0,0,,,0,0,0,0,,,0,0,0,0,,,0,0,0,0,AAPL
2024-10-22 13:10:46.677384648+00:00,10,39,38,A,B,0,232.2,2000,130,203482,68511,232.2,,2000,0,1,0,,,0,0,0,0,,,0,0,0,0,,,0,0,0,0,,,0,0,0,0,,,0,0,0,0,,,0,0,0,0,,,0,0,0,0,,,0,0,0,0,,,0,0,0,0,AAPL
2024-10-22 13:10:49.491547195+00:00,10,39,38,A,B,0,232.4,2000,130,203679,68527,232.4,,2000,0,1,0,232.2,,2000,0,1,0,,,0,0,0,0,,,0,0,0,0,,,0,0,0,0,,,0,0,0,0,,,0,0,0,0,,,0,0,0,0,,,0,0,0,0,,,0,0,0,0,AAPL
2024-10-22 13:10:49.491758065+00:00,10,39,38,C,B,1,232.2,2000,130,203442,68528,232.4,,2000,0,1,0,,,0,0,0,0,,,0,0,0,0,,,0,0,0,0,,,0,0,0,0,,,0,0,0,0,,,0,0,0,0,,,0,0,0,0,,,0,0,0,0,,,0,0,0,0,AAPL
2024-10-22 13:10:51.688240265+00:00,10,39,38,C,B,0,232.4,2000,130,203382,68538,,,0,0,0,0,,,0,0,0,0,,,0,0,0,0,,,0,0,0,0,,,0,0,0,0,,,0,0,0,0,,,0,0,0,0,,,0,0,0,0,,,0,0,0,0,,,0,0,0,0,AAPL
2024-10-22 13:10:51.699223874+00:00,10,39,38,A,B,0,232.2,2000,130,203316,68539,232.2,,2000,0,1,0,,,0,0,0,0,,,0,0,0,0,,,0,0,0,0,,,0,0,0,0,,,0,0,0,0,,,0,0,0,0,,,0,0,0,0,,,0,0,0,0,,,0,0,0,0,AAPL
2024-10-22 13:10:51.715343513+00:00,10,39,38,C,B,0,232.2,2000,130,203413,68540,,,0,0,0,0,,,0,0,0,0,,,0,0,0,0,,,0,0,0,0,,,0,0,0,0,,,0,0,0,0,,,0,0,0,0,,,0,0,0,0,,,0,0,0,0,,,0,0,0,0,AAPL
2024-10-22 13:10:51.728570825+00:00,10,39,38,A,B,0,232.0,2000,130,203333,68541,232.0,,2000,0,1,0,,,0,0,0,0,,,0,0,0,0,,,0,0,0,0,,,0,0,0,0,,,0,0,0,0,,,0,0,0,0,,,0,0,0,0,,,0,0,0,0,,,0,0,0,0,AAPL
2024-10-22 13:10:55.269513667+00:00,10,39,38,A,B,0,232.2,2000,130,204157,68558,232.2,,2000,0,1,0,232.0,,2000,0,1,0,,,0,0,0,0,,,0,0,0,0,,,0,0,0,0,,,0,0,0,0,,,0,0,0,0,,,0,0,0,0,,,0,0,0,0,,,0,0,0,0,AAPL
2024-10-22 13:10:55.269713942+00:00,10,39,38,C,B,1,232.0,2000,130,203345,68559,232.2,,2000,0,1,0,,,0,0,0,0,,,0,0,0,0,,,0,0,0,0,,,0,0,0,0,,,0,0,0,0,,,0,0,0,0,,,0,0,0,0,,,0,0,0,0,,,0,0,0,0,AAPL
2024-10-22 13:10:55.296149891+00:00,10,39,38,C,B,0,232.2,2000,130,203395,68560,,,0,0,0,0,,,0,0,0,0,,,0,0,0,0,,,0,0,0,0,,,0,0,0,0,,,0,0,0,0,,,0,0,0,0,,,0,0,0,0,,,0,0,0,0,,,0,0,0,0,AAPL
2024-10-22 13:10:55.309117454+00:00,10,39,38,A,B,0,232.0,2000,130,203332,68561,232.0,,2000,0,1,0,,,0,0,0,0,,,0,0,0,0,,,0,0,0,0,,,0,0,0,0,,,0,0,0,0,,,0,0,0,0,,,0,0,0,0,,,0,0,0,0,,,0,0,0,0,AAPL
2024-10-22 13:10:55.529687589+00:00,10,39,38,A,B,0,232.4,2000,130,203478,68562,232.4,,2000,0,1,0,232.0,,2000,0,1,0,,,0,0,0,0,,,0,0,0,0,,,0,0,0,0,,,0,0,0,0,,,0,0,0,0,,,0,0,0,0,,,0,0,0,0,,,0,0,0,0,AAPL
2024-10-22 13:10:55.529877796+00:00,10,39,38,C,B,1,232.0,2000,130,203240,68563,232.4,,2000,0,1,0,,,0,0,0,0,,,0,0,0,0,,,0,0,0,0,,,0,0,0,0,,,0,0,0,0,,,0,0,0,0,,,0,0,0,0,,,0,0,0,0,,,0,0,0,0,AAPL
2024-10-22 13:10:55.581728350+00:00,10,39,38,C,B,0,232.4,2000,130,203254,68564,,,0,0,0,0,,,0,0,0,0,,,0,0,0,0,,,0,0,0,0,,,0,0,0,0,,,0,0,0,0,,,0,0,0,0,,,0,0,0,0,,,0,0,0,0,,,0,0,0,0,AAPL
2024-10-22 13:10:55.592620008+00:00,10,39,38,A,B,0,232.2,2000,130,203319,68565,232.2,,2000,0,1,0,,,0,0,0,0,,,0,0,0,0,,,0,0,0,0,,,0,0,0,0,,,0,0,0,0,,,0,0,0,0,,,0,0,0,0,,,0,0,0,0,,,0,0,0,0,AAPL
2024-10-22 13:11:00.002464562+00:00,10,40,38,A,B,0,234.25,200,194,204093,115869,,234.25,0,200,0,0,,,0,0,0,0,,,0,0,0,0,,,0,0,0,0,,,0,0,0,0,,,0,0,0,0,,,0,0,0,0,,,0,0,0,0,,,0,0,0,0,,,0,0,0,0,AAPL
2024-10-22 13:11:00.002477683+00:00,10,40,38,A,A,0,,0,194,204062,115870,,,0,0,0,0,,,0,0,0,0,,,0,0,0,0,,,0,0,0,0,,,0,0,0,0,,,0,0,0,0,,,0,0,0,0,,,0,0,0,0,,,0,0,0,0,,,0,0,0,0,AAPL
2024-10-22 13:11:00.002935759+00:00,10,41,38,A,B,0,234.2,200,194,57526,272222,,234.2,0,200,0,0,,,0,0,0,0,,,0,0,0,0,,,0,0,0,0,,,0,0,0,0,,,0,0,0,0,,,0,0,0,0,,,0,0,0,0,,,0,0,0,0,,,0,0,0,0,AAPL
2024-10-22 13:11:00.002942604+00:00,10,41,38,A,A,0,,0,194,54272,272224,,,0,0,0,0,,,0,0,0,0,,,0,0,0,0,,,0,0,0,0,,,0,0,0,0,,,0,0,0,0,,,0,0,0,0,,,0,0,0,0,,,0,0,0,0,,,0,0,0,0,AAPL
2024-10-22 13:11:00.506383651+00:00,10,40,38,A,A,0,234.26,200,194,204123,115928,,234.26,0,200,0,0,,,0,0,0,0,,,0,0,0,0,,,0,0,0,0,,,0,0,0,0,,,0,0,0,0,,,0,0,0,0,,,0,0,0,0,,,0,0,0,0,,,0,0,0,0,AAPL
2024-10-22 13:11:00.506573143+00:00,10,41,38,A,B,0,,0,194,56192,272550,233.65,,200,0,0,0,,,0,0,0,0,,,0,0,0,0,,,0,0,0,0,,,0,0,0,0,,,0,0,0,0,,,0,0,0,0,,,0,0,0,0,,,0,0,0,0,,,0,0,0,0,AAPL
2024-10-22 13:11:00.506602640+00:00,10,41,38,A,A,0,234.21,200,194,63660,272551,233.65,234.21,200,200,0,0,,,0,0,0,0,,,0,0,0,0,,,0,0,0,0,,,0,0,0,0,,,0,0,0,0,,,0,0,0,0,,,0,0,0,0,,,0,0,0,0,,,0,0,0,0,AAPL
2024-10-22 13:11:00.506514133+00:00,10,40,38,A,B,0,234.26,200,194,204018,115929,233.6,234.26,200,200,0,0,,,0,0,0,0,,,0,0,0,0,,,0,0,0,0,,,0,0,0,0,,,0,0,0,0,,,0,0,0,0,,,0,0,0,0,,,0,0,0,0,,,0,0,0,0,AAPL
2024-10-22 13:11:00.774294892+00:00,10,40,38,A,B,0,234.26,200,194,204001,115942,,234.26,0,200,0,0,,,0,0,0,0,,,0,0,0,0,,,0,0,0,0,,,0,0,0,0,,,0,0,0,0,,,0,0,0,0,,,0,0,0,0,,,0,0,0,0,,,0,0,0,0,AAPL
2024-10-22 13:11:01.377563274+00:00,10,39,38,A,B,0,232.4,2000,130,203152,68581,232.4,,2000,0,1,0,232.2,,2000,0,1,0,,,0,0,0,0,,,0,0,0,0,,,0,0,0,0,,,0,0,0,0,,,0,0,0,0,,,0,0,0,0,,,0,0,0,0,,,0,0,0,0,AAPL
2024-10-22 13:11:01.377764959+00:00,10,39,38,C,B,1,232.2,2000,130,203127,68582,232.4,,2000,0,1,0,,,0,0,0,0,,,0,0,0,0,,,0,0,0,0,,,0,0,0,0,,,0,0,0,0,,,0,0,0,0,,,0,0,0,0,,,0,0,0,0,,,0,0,0,0,AAPL
2024-10-22 13:11:01.626550261+00:00,10,40,38,A,B,0,234.26,200,194,204032,115955,233.61,234.26,200,200,0,0,,,0,0,0,0,,,0,0,0,0,,,0,0,0,0,,,0,0,0,0,,,0,0,0,0,,,0,0,0,0,,,0,0,0,0,,,0,0,0,0,,,0,0,0,0,AAPL
2024-10-22 13:11:01.663735925+00:00,10,39,38,C,B,0,232.4,2000,130,203243,68584,,,0,0,0,0,,,0,0,0,0,,,0,0,0,0,,,0,0,0,0,,,0,0,0,0,,,0,0,0,0,,,0,0,0,0,,,0,0,0,0,,,0,0,0,0,,,0,0,0,0,AAPL
2024-10-22 13:11:01.674440794+00:00,10,39,38,A,B,0,232.2,2000,130,203074,68585,232.2,,2000,0,1,0,,,0,0,0,0,,,0,0,0,0,,,0,0,0,0,,,0,0,0,0,,,0,0,0,0,,,0,0,0,0,,,0,0,0,0,,,0,0,0,0,,,0,0,0,0,AAPL
2024-10-22 13:11:05.697406163+00:00,10,39,10888,C,A,0,421.2,2000,130,203181,101069,,,0,0,0,0,,,0,0,0,0,,,0,0,0,0,,,0,0,0,0,,,0,0,0,0,,,0,0,0,0,,,0,0,0,0,,,0,0,0,0,,,0,0,0,0,,,0,0,0,0,MSFT
2024-10-22 13:11:05.734324586+00:00,10,39,10888,A,A,0,421.2,2000,130,203284,101071,,421.2,0,2000,0,1,,,0,0,0,0,,,0,0,0,0,,,0,0,0,0,,,0,0,0,0,,,0,0,0,0,,,0,0,0,0,,,0,0,0,0,,,0,0,0,0,,,0,0,0,0,MSFT
2024-10-22 13:11:19.612751584+00:00,10,39,38,A,B,0,232.4,2000,130,202595,68681,232.4,,2000,0,1,0,232.2,,2000,0,1,0,,,0,0,0,0,,,0,0,0,0,,,0,0,0,0,,,0,0,0,0,,,0,0,0,0,,,0,0,0,0,,,0,0,0,0,,,0,0,0,0,AAPL
2024-10-22 13:11:19.612944700+00:00,10,39,38,C,B,1,232.2,2000,130,202452,68682,232.4,,2000,0,1,0,,,0,0,0,0,,,0,0,0,0,,,0,0,0,0,,,0,0,0,0,,,0,0,0,0,,,0,0,0,0,,,0,0,0,0,,,0,0,0,0,,,0,0,0,0,AAPL
2024-10-22 13:11:19.637155153+00:00,10,39,38,C,B,0,232.4,2000,130,202386,68683,,,0,0,0,0,,,0,0,0,0,,,0,0,0,0,,,0,0,0,0,,,0,0,0,0,,,0,0,0,0,,,0,0,0,0,,,0,0,0,0,,,0,0,0,0,,,0,0,0,0,AAPL
2024-10-22 13:11:19.648112503+00:00,10,39,38,A,B,0,232.2,2000,130,202487,68684,232.2,,2000,0,1,0,,,0,0,0,0,,,0,0,0,0,,,0,0,0,0,,,0,0,0,0,,,0,0,0,0,,,0,0,0,0,,,0,0,0,0,,,0,0,0,0,,,0,0,0,0,AAPL
2024-10-22 13:11:19.873205101+00:00,10,39,38,A,B,0,232.4,2000,130,202739,68685,232.4,,2000,0,1,0,232.2,,2000,0,1,0,,,0,0,0,0,,,0,0,0,0,,,0,0,0,0,,,0,0,0,0,,,0,0,0,0,,,0,0,0,0,,,0,0,0,0,,,0,0,0,0,AAPL
2024-10-22 13:11:19.873378405+00:00,10,39,38,C,B,1,232.2,2000,130,202416,68686,232.4,,2000,0,1,0,,,0,0,0,0,,,0,0,0,0,,,0,0,0,0,,,0,0,0,0,,,0,0,0,0,,,0,0,0,0,,,0,0,0,0,,,0,0,0,0,,,0,0,0,0,AAPL
2024-10-22 13:11:19.923876426+00:00,10,39,38,C,B,0,232.4,2000,130,202549,68687,,,0,0,0,0,,,0,0,0,0,,,0,0,0,0,,,0,0,0,0,,,0,0,0,0,,,0,0,0,0,,,0,0,0,0,,,0,0,0,0,,,0,0,0,0,,,0,0,0,0,AAPL
2024-10-22 13:11:19.935487554+00:00,10,39,38,A,B,0,232.2,2000,130,202466,68688,232.2,,2000,0,1,0,,,0,0,0,0,,,0,0,0,0,,,0,0,0,0,,,0,0,0,0,,,0,0,0,0,,,0,0,0,0,,,0,0,0,0,,,0,0,0,0,,,0,0,0,0,AAPL
2024-10-22 13:11:22.204768162+00:00,10,39,38,A,B,0,232.4,2000,130,203344,68695,232.4,,2000,0,1,0,232.2,,2000,0,1,0,,,0,0,0,0,,,0,0,0,0,,,0,0,0,0,,,0,0,0,0,,,0,0,0,0,,,0,0,0,0,,,0,0,0,0,,,0,0,0,0,AAPL
2024-10-22 13:11:22.204955449+00:00,10,39,38,C,B,1,232.2,2000,130,202705,68696,232.4,,2000,0,1,0,,,0,0,0,0,,,0,0,0,0,,,0,0,0,0,,,0,0,0,0,,,0,0,0,0,,,0,0,0,0,,,0,0,0,0,,,0,0,0,0,,,0,0,0,0,AAPL
2024-10-22 13:11:22.455060895+00:00,10,39,38,C,B,0,232.4,2000,130,202855,68697,,,0,0,0,0,,,0,0,0,0,,,0,0,0,0,,,0,0,0,0,,,0,0,0,0,,,0,0,0,0,,,0,0,0,0,,,0,0,0,0,,,0,0,0,0,,,0,0,0,0,AAPL
2024-10-22 13:11:22.466275630+00:00,10,39,38,A,B,0,232.4,2000,130,202729,68698,232.4,,2000,0,1,0,,,0,0,0,0,,,0,0,0,0,,,0,0,0,0,,,0,0,0,0,,,0,0,0,0,,,0,0,0,0,,,0,0,0,0,,,0,0,0,0,,,0,0,0,0,AAPL
2024-10-22 13:11:24.890036150+00:00,10,39,10888,C,A,0,421.2,2000,130,203014,101194,,,0,0,0,0,,,0,0,0,0,,,0,0,0,0,,,0,0,0,0,,,0,0,0,0,,,0,0,0,0,,,0,0,0,0,,,0,0,0,0,,,0,0,0,0,,,0,0,0,0,MSFT
2024-10-22 13:11:24.900847464+00:00,10,39,10888,A,A,0,421.6,2000,130,202867,101195,,421.6,0,2000,0,1,,,0,0,0,0,,,0,0,0,0,,,0,0,0,0,,,0,0,0,0,,,0,0,0,0,,,0,0,0,0,,,0,0,0,0,,,0,0,0,0,,,0,0,0,0,MSFT
2024-10-22 13:11:24.918731962+00:00,10,39,10888,A,A,0,421.2,2000,130,202700,101196,,421.2,0,2000,0,1,,421.6,0,2000,0,1,,,0,0,0,0,,,0,0,0,0,,,0,0,0,0,,,0,0,0,0,,,0,0,0,0,,,0,0,0,0,,,0,0,0,0,,,0,0,0,0,MSFT
2024-10-22 13:11:24.918936488+00:00,10,39,10888,C,A,1,421.6,2000,130,202683,101197,,421.2,0,2000,0,1,,,0,0,0,0,,,0,0,0,0,,,0,0,0,0,,,0,0,0,0,,,0,0,0,0,,,0,0,0,0,,,0,0,0,0,,,0,0,0,0,,,0,0,0,0,MSFT
2024-10-22 13:11:25.413352276+00:00,10,39,38,C,B,0,232.4,2000,130,203051,68726,,,0,0,0,0,,,0,0,0,0,,,0,0,0,0,,,0,0,0,0,,,0,0,0,0,,,0,0,0,0,,,0,0,0,0,,,0,0,0,0,,,0,0,0,0,,,0,0,0,0,AAPL
2024-10-22 13:11:25.426455566+00:00,10,39,38,A,B,0,232.2,2000,130,202752,68727,232.2,,2000,0,1,0,,,0,0,0,0,,,0,0,0,0,,,0,0,0,0,,,0,0,0,0,,,0,0,0,0,,,0,0,0,0,,,0,0,0,0,,,0,0,0,0,,,0,0,0,0,AAPL
2024-10-22 13:11:25.612184506+00:00,10,39,38,A,B,0,232.4,2000,130,202844,68728,232.4,,2000,0,1,0,232.2,,2000,0,1,0,,,0,0,0,0,,,0,0,0,0,,,0,0,0,0,,,0,0,0,0,,,0,0,0,0,,,0,0,0,0,,,0,0,0,0,,,0,0,0,0,AAPL
2024-10-22 13:11:25.612374167+00:00,10,39,38,C,B,1,232.2,2000,130,202709,68729,232.4,,2000,0,1,0,,,0,0,0,0,,,0,0,0,0,,,0,0,0,0,,,0,0,0,0,,,0,0,0,0,,,0,0,0,0,,,0,0,0,0,,,0,0,0,0,,,0,0,0,0,AAPL
2024-10-22 13:11:25.916904297+00:00,10,41,38,A,A,0,,0,194,60760,273705,233.65,,200,0,0,0,,,0,0,0,0,,,0,0,0,0,,,0,0,0,0,,,0,0,0,0,,,0,0,0,0,,,0,0,0,0,,,0,0,0,0,,,0,0,0,0,,,0,0,0,0,AAPL
2024-10-22 13:11:25.916931539+00:00,10,41,38,A,A,0,234.3,200,194,55161,273706,233.65,234.3,200,200,0,0,,,0,0,0,0,,,0,0,0,0,,,0,0,0,0,,,0,0,0,0,,,0,0,0,0,,,0,0,0,0,,,0,0,0,0,,,0,0,0,0,,,0,0,0,0,AAPL
2024-10-22 13:11:32.596110563+00:00,10,39,38,C,B,0,232.4,2000,130,203356,68790,,,0,0,0,0,,,0,0,0,0,,,0,0,0,0,,,0,0,0,0,,,0,0,0,0,,,0,0,0,0,,,0,0,0,0,,,0,0,0,0,,,0,0,0,0,,,0,0,0,0,AAPL
2024-10-22 13:11:32.608746653+00:00,10,39,38,A,B,0,232.2,2000,130,203312,68791,232.2,,2000,0,1,0,,,0,0,0,0,,,0,0,0,0,,,0,0,0,0,,,0,0,0,0,,,0,0,0,0,,,0,0,0,0,,,0,0,0,0,,,0,0,0,0,,,0,0,0,0,AAPL
2024-10-22 13:11:32.806102337+00:00,10,39,38,A,B,0,232.4,2000,130,203346,68792,232.4,,2000,0,1,0,232.2,,2000,0,1,0,,,0,0,0,0,,,0,0,0,0,,,0,0,0,0,,,0,0,0,0,,,0,0,0,0,,,0,0,0,0,,,0,0,0,0,,,0,0,0,0,AAPL
2024-10-22 13:11:32.806288876+00:00,10,39,38,C,B,1,232.2,2000,130,203203,68793,232.4,,2000,0,1,0,,,0,0,0,0,,,0,0,0,0,,,0,0,0,0,,,0,0,0,0,,,0,0,0,0,,,0,0,0,0,,,0,0,0,0,,,0,0,0,0,,,0,0,0,0,AAPL
2024-10-22 13:11:32.898518779+00:00,10,40,38,A,B,0,234.26,200,194,203479,116285,,234.26,0,200,0,0,,,0,0,0,0,,,0,0,0,0,,,0,0,0,0,,,0,0,0,0,,,0,0,0,0,,,0,0,0,0,,,0,0,0,0,,,0,0,0,0,,,0,0,0,0,AAPL
2024-10-22 13:11:32.898538042+00:00,10,40,38,A,B,0,234.26,200,194,203378,116286,233.73,234.26,200,200,0,0,,,0,0,0,0,,,0,0,0,0,,,0,0,0,0,,,0,0,0,0,,,0,0,0,0,,,0,0,0,0,,,0,0,0,0,,,0,0,0,0,,,0,0,0,0,AAPL
2024-10-22 13:11:32.899086242+00:00,10,41,38,A,B,0,234.3,200,194,56007,273969,,234.3,0,200,0,0,,,0,0,0,0,,,0,0,0,0,,,0,0,0,0,,,0,0,0,0,,,0,0,0,0,,,0,0,0,0,,,0,0,0,0,,,0,0,0,0,,,0,0,0,0,AAPL
2024-10-22 13:11:32.899110363+00:00,10,41,38,A,B,0,234.3,200,194,55584,273970,233.78,234.3,200,200,0,0,,,0,0,0,0,,,0,0,0,0,,,0,0,0,0,,,0,0,0,0,,,0,0,0,0,,,0,0,0,0,,,0,0,0,0,,,0,0,0,0,,,0,0,0,0,AAPL
2024-10-22 13:11:32.909960500+00:00,10,39,38,A,A,0,236.4,2000,130,203470,68796,232.4,236.4,2000,2000,1,1,,,0,0,0,0,,,0,0,0,0,,,0,0,0,0,,,0,0,0,0,,,0,0,0,0,,,0,0,0,0,,,0,0,0,0,,,0,0,0,0,,,0,0,0,0,AAPL
2024-10-22 13:11:33.200482369+00:00,10,40,38,A,A,0,234.41,200,194,203704,116290,233.73,234.41,200,200,0,0,,,0,0,0,0,,,0,0,0,0,,,0,0,0,0,,,0,0,0,0,,,0,0,0,0,,,0,0,0,0,,,0,0,0,0,,,0,0,0,0,,,0,0,0,0,AAPL
2024-10-22 13:11:33.201527409+00:00,10,39,38,C,A,0,236.4,2000,130,204241,68798,232.4,,2000,0,1,0,,,0,0,0,0,,,0,0,0,0,,,0,0,0,0,,,0,0,0,0,,,0,0,0,0,,,0,0,0,0,,,0,0,0,0,,,0,0,0,0,,,0,0,0,0,AAPL
2024-10-22 13:11:38.648711910+00:00,10,39,38,C,B,0,232.4,2000,130,203572,68824,,,0,0,0,0,,,0,0,0,0,,,0,0,0,0,,,0,0,0,0,,,0,0,0,0,,,0,0,0,0,,,0,0,0,0,,,0,0,0,0,,,0,0,0,0,,,0,0,0,0,AAPL
2024-10-22 13:11:38.664968499+00:00,10,39,38,A,B,0,232.4,2000,130,203419,68825,232.4,,2000,0,1,0,,,0,0,0,0,,,0,0,0,0,,,0,0,0,0,,,0,0,0,0,,,0,0,0,0,,,0,0,0,0,,,0,0,0,0,,,0,0,0,0,,,0,0,0,0,AAPL
2024-10-22 13:11:42.922003424+00:00,10,39,38,C,B,0,232.4,2000,130,203877,68831,,,0,0,0,0,,,0,0,0,0,,,0,0,0,0,,,0,0,0,0,,,0,0,0,0,,,0,0,0,0,,,0,0,0,0,,,0,0,0,0,,,0,0,0,0,,,0,0,0,0,AAPL
2024-10-22 13:11:42.935586060+00:00,10,39,38,A,B,0,232.2,2000,130,203599,68832,232.2,,2000,0,1,0,,,0,0,0,0,,,0,0,0,0,,,0,0,0,0,,,0,0,0,0,,,0,0,0,0,,,0,0,0,0,,,0,0,0,0,,,0,0,0,0,,,0,0,0,0,AAPL
2024-10-22 13:11:43.628627161+00:00,10,39,38,A,B,0,232.4,2000,130,203849,68834,232.4,,2000,0,1,0,232.2,,2000,0,1,0,,,0,0,0,0,,,0,0,0,0,,,0,0,0,0,,,0,0,0,0,,,0,0,0,0,,,0,0,0,0,,,0,0,0,0,,,0,0,0,0,AAPL
2024-10-22 13:11:43.628810046+00:00,10,39,38,C,B,1,232.2,2000,130,203519,68835,232.4,,2000,0,1,0,,,0,0,0,0,,,0,0,0,0,,,0,0,0,0,,,0,0,0,0,,,0,0,0,0,,,0,0,0,0,,,0,0,0,0,,,0,0,0,0,,,0,0,0,0,AAPL
2024-10-22 13:11:43.920149506+00:00,10,41,38,A,A,0,,0,194,60584,274348,233.78,,200,0,0,0,,,0,0,0,0,,,0,0,0,0,,,0,0,0,0,,,0,0,0,0,,,0,0,0,0,,,0,0,0,0,,,0,0,0,0,,,0,0,0,0,,,0,0,0,0,AAPL
2024-10-22 13:11:43.920184975+00:00,10,41,38,A,A,0,234.4,200,194,54507,274349,233.78,234.4,200,200,0,0,,,0,0,0,0,,,0,0,0,0,,,0,0,0,0,,,0,0,0,0,,,0,0,0,0,,,0,0,0,0,,,0,0,0,0,,,0,0,0,0,,,0,0,0,0,AAPL
2024-10-22 13:11:44.143715329+00:00,10,39,38,C,B,0,232.4,2000,130,204254,68837,,,0,0,0,0,,,0,0,0,0,,,0,0,0,0,,,0,0,0,0,,,0,0,0,0,,,0,0,0,0,,,0,0,0,0,,,0,0,0,0,,,0,0,0,0,,,0,0,0,0,AAPL
2024-10-22 13:11:44.154701898+00:00,10,39,38,A,B,0,232.2,2000,130,203450,68838,232.2,,2000,0,1,0,,,0,0,0,0,,,0,0,0,0,,,0,0,0,0,,,0,0,0,0,,,0,0,0,0,,,0,0,0,0,,,0,0,0,0,,,0,0,0,0,,,0,0,0,0,AAPL
2024-10-22 13:11:45.447406057+00:00,10,39,10888,C,A,0,421.2,2000,130,203733,101347,,,0,0,0,0,,,0,0,0,0,,,0,0,0,0,,,0,0,0,0,,,0,0,0,0,,,0,0,0,0,,,0,0,0,0,,,0,0,0,0,,,0,0,0,0,,,0,0,0,0,MSFT
2024-10-22 13:11:45.482460390+00:00,10,39,10888,A,A,0,421.2,2000,130,203224,101351,,421.2,0,2000,0,1,,,0,0,0,0,,,0,0,0,0,,,0,0,0,0,,,0,0,0,0,,,0,0,0,0,,,0,0,0,0,,,0,0,0,0,,,0,0,0,0,,,0,0,0,0,MSFT
2024-10-22 13:11:46.886222202+00:00,10,41,10888,T,N,0,419.25,34,194,58829,274427,,,0,0,0,0,,,0,0,0,0,,,0,0,0,0,,,0,0,0,0,,,0,0,0,0,,,0,0,0,0,,,0,0,0,0,,,0,0,0,0,,,0,0,0,0,,,0,0,0,0,MSFT
2024-10-22 13:11:46.887269475+00:00,10,39,10888,C,A,0,421.2,2000,130,203476,101371,,,0,0,0,0,,,0,0,0,0,,,0,0,0,0,,,0,0,0,0,,,0,0,0,0,,,0,0,0,0,,,0,0,0,0,,,0,0,0,0,,,0,0,0,0,,,0,0,0,0,MSFT
2024-10-22 13:11:46.923461783+00:00,10,39,10888,A,A,0,421.2,2000,130,203257,101372,,421.2,0,2000,0,1,,,0,0,0,0,,,0,0,0,0,,,0,0,0,0,,,0,0,0,0,,,0,0,0,0,,,0,0,0,0,,,0,0,0,0,,,0,0,0,0,,,0,0,0,0,MSFT
2024-10-22 13:11:49.454195972+00:00,10,39,38,A,B,0,232.4,2000,130,203799,68871,232.4,,2000,0,1,0,232.2,,2000,0,1,0,,,0,0,0,0,,,0,0,0,0,,,0,0,0,0,,,0,0,0,0,,,0,0,0,0,,,0,0,0,0,,,0,0,0,0,,,0,0,0,0,AAPL
2024-10-22 13:11:49.454375933+00:00,10,39,38,C,B,1,232.2,2000,130,203382,68872,232.4,,2000,0,1,0,,,0,0,0,0,,,0,0,0,0,,,0,0,0,0,,,0,0,0,0,,,0,0,0,0,,,0,0,0,0,,,0,0,0,0,,,0,0,0,0,,,0,0,0,0,AAPL
2024-10-22 13:11:49.510953330+00:00,10,39,38,C,B,0,232.4,2000,130,203405,68873,,,0,0,0,0,,,0,0,0,0,,,0,0,0,0,,,0,0,0,0,,,0,0,0,0,,,0,0,0,0,,,0,0,0,0,,,0,0,0,0,,,0,0,0,0,,,0,0,0,0,AAPL
2024-10-22 13:11:49.521988245+00:00,10,39,38,A,B,0,232.2,2000,130,203353,68874,232.2,,2000,0,1,0,,,0,0,0,0,,,0,0,0,0,,,0,0,0,0,,,0,0,0,0,,,0,0,0,0,,,0,0,0,0,,,0,0,0,0,,,0,0,0,0,,,0,0,0,0,AAPL
2024-10-22 13:11:49.713332457+00:00,10,39,38,A,B,0,232.4,2000,130,203553,68875,232.4,,2000,0,1,0,232.2,,2000,0,1,0,,,0,0,0,0,,,0,0,0,0,,,0,0,0,0,,,0,0,0,0,,,0,0,0,0,,,0,0,0,0,,,0,0,0,0,,,0,0,0,0,AAPL
2024-10-22 13:11:49.713540911+00:00,10,39,38,C,B,1,232.2,2000,130,203420,68876,232.4,,2000,0,1,0,,,0,0,0,0,,,0,0,0,0,,,0,0,0,0,,,0,0,0,0,,,0,0,0,0,,,0,0,0,0,,,0,0,0,0,,,0,0,0,0,,,0,0,0,0,AAPL
2024-10-22 13:11:50.473774759+00:00,10,39,38,C,B,0,232.4,2000,130,203742,68878,,,0,0,0,0,,,0,0,0,0,,,0,0,0,0,,,0,0,0,0,,,0,0,0,0,,,0,0,0,0,,,0,0,0,0,,,0,0,0,0,,,0,0,0,0,,,0,0,0,0,AAPL
2024-10-22 13:11:50.484896160+00:00,10,39,38,A,B,0,232.2,2000,130,203487,68879,232.2,,2000,0,1,0,,,0,0,0,0,,,0,0,0,0,,,0,0,0,0,,,0,0,0,0,,,0,0,0,0,,,0,0,0,0,,,0,0,0,0,,,0,0,0,0,,,0,0,0,0,AAPL
2024-10-22 13:11:50.681735085+00:00,10,39,38,C,B,0,232.2,2000,130,203515,68880,,,0,0,0,0,,,0,0,0,0,,,0,0,0,0,,,0,0,0,0,,,0,0,0,0,,,0,0,0,0,,,0,0,0,0,,,0,0,0,0,,,0,0,0,0,,,0,0,0,0,AAPL
2024-10-22 13:11:50.692453814+00:00,10,39,38,A,B,0,232.0,2000,130,203420,68881,232.0,,2000,0,1,0,,,0,0,0,0,,,0,0,0,0,,,0,0,0,0,,,0,0,0,0,,,0,0,0,0,,,0,0,0,0,,,0,0,0,0,,,0,0,0,0,,,0,0,0,0,AAPL
2024-10-22 13:11:50.711859756+00:00,10,41,38,A,B,0,234.4,200,194,60990,274615,,234.4,0,200,0,0,,,0,0,0,0,,,0,0,0,0,,,0,0,0,0,,,0,0,0,0,,,0,0,0,0,,,0,0,0,0,,,0,0,0,0,,,0,0,0,0,,,0,0,0,0,AAPL
2024-10-22 13:11:50.711877681+00:00,10,41,38,A,B,0,234.4,200,194,54538,274616,233.87,234.4,200,200,0,0,,,0,0,0,0,,,0,0,0,0,,,0,0,0,0,,,0,0,0,0,,,0,0,0,0,,,0,0,0,0,,,0,0,0,0,,,0,0,0,0,,,0,0,0,0,AAPL
2024-10-22 13:11:50.871486828+00:00,10,39,38,A,B,0,232.2,2000,130,203776,68882,232.2,,2000,0,1,0,232.0,,2000,0,1,0,,,0,0,0,0,,,0,0,0,0,,,0,0,0,0,,,0,0,0,0,,,0,0,0,0,,,0,0,0,0,,,0,0,0,0,,,0,0,0,0,AAPL
2024-10-22 13:11:50.872219046+00:00,10,39,38,C,B,1,232.0,2000,130,203402,68883,232.2,,2000,0,1,0,,,0,0,0,0,,,0,0,0,0,,,0,0,0,0,,,0,0,0,0,,,0,0,0,0,,,0,0,0,0,,,0,0,0,0,,,0,0,0,0,,,0,0,0,0,AAPL
2024-10-22 13:11:53.054990838+00:00,10,39,38,A,B,0,232.4,2000,130,203804,68891,232.4,,2000,0,1,0,232.2,,2000,0,1,0,,,0,0,0,0,,,0,0,0,0,,,0,0,0,0,,,0,0,0,0,,,0,0,0,0,,,0,0,0,0,,,0,0,0,0,,,0,0,0,0,AAPL
2024-10-22 13:11:53.055185909+00:00,10,39,38,C,B,1,232.2,2000,130,203394,68892,232.4,,2000,0,1,0,,,0,0,0,0,,,0,0,0,0,,,0,0,0,0,,,0,0,0,0,,,0,0,0,0,,,0,0,0,0,,,0,0,0,0,,,0,0,0,0,,,0,0,0,0,AAPL
2024-10-22 13:11:57.652567675+00:00,10,39,38,C,B,0,232.4,2000,130,204155,68909,,,0,0,0,0,,,0,0,0,0,,,0,0,0,0,,,0,0,0,0,,,0,0,0,0,,,0,0,0,0,,,0,0,0,0,,,0,0,0,0,,,0,0,0,0,,,0,0,0,0,AAPL
2024-10-22 13:11:57.663297100+00:00,10,39,38,A,B,0,232.2,2000,130,203678,68910,232.2,,2000,0,1,0,,,0,0,0,0,,,0,0,0,0,,,0,0,0,0,,,0,0,0,0,,,0,0,0,0,,,0,0,0,0,,,0,0,0,0,,,0,0,0,0,,,0,0,0,0,AAPL
2024-10-22 13:11:57.712442487+00:00,10,39,38,C,B,0,232.2,2000,130,203711,68911,,,0,0,0,0,,,0,0,0,0,,,0,0,0,0,,,0,0,0,0,,,0,0,0,0,,,0,0,0,0,,,0,0,0,0,,,0,0,0,0,,,0,0,0,0,,,0,0,0,0,AAPL
2024-10-22 13:11:57.725532120+00:00,10,39,38,A,B,0,231.8,2000,130,203696,68912,231.8,,2000,0,1,0,,,0,0,0,0,,,0,0,0,0,,,0,0,0,0,,,0,0,0,0,,,0,0,0,0,,,0,0,0,0,,,0,0,0,0,,,0,0,0,0,,,0,0,0,0,AAPL
2024-10-22 13:11:57.936916957+00:00,10,39,38,A,A,0,236.4,2000,130,203617,68916,231.8,236.4,2000,2000,1,1,,,0,0,0,0,,,0,0,0,0,,,0,0,0,0,,,0,0,0,0,,,0,0,0,0,,,0,0,0,0,,,0,0,0,0,,,0,0,0,0,,,0,0,0,0,AAPL
2024-10-22 13:11:57.987443297+00:00,10,39,38,A,B,0,232.4,2000,130,203639,68918,232.4,236.4,2000,2000,1,1,231.8,,2000,0,1,0,,,0,0,0,0,,,0,0,0,0,,,0,0,0,0,,,0,0,0,0,,,0,0,0,0,,,0,0,0,0,,,0,0,0,0,,,0,0,0,0,AAPL
2024-10-22 13:11:57.987849204+00:00,10,39,38,C,B,1,231.8,2000,130,203622,68919,232.4,236.4,2000,2000,1,1,,,0,0,0,0,,,0,0,0,0,,,0,0,0,0,,,0,0,0,0,,,0,0,0,0,,,0,0,0,0,,,0,0,0,0,,,0,0,0,0,,,0,0,0,0,AAPL
2024-10-22 13:11:57.988907845+00:00,10,39,38,C,B,0,232.4,2000,130,203603,68920,,236.4,0,2000,0,1,,,0,0,0,0,,,0,0,0,0,,,0,0,0,0,,,0,0,0,0,,,0,0,0,0,,,0,0,0,0,,,0,0,0,0,,,0,0,0,0,,,0,0,0,0,AAPL
2024-10-22 13:11:58.000103071+00:00,10,39,38,A,B,0,232.2,2000,130,203784,68922,232.2,236.4,2000,2000,1,1,,,0,0,0,0,,,0,0,0,0,,,0,0,0,0,,,0,0,0,0,,,0,0,0,0,,,0,0,0,0,,,0,0,0,0,,,0,0,0,0,,,0,0,0,0,AAPL
2024-10-22 13:11:58.256480531+00:00,10,39,38,A,B,0,232.4,2000,130,203854,68923,232.4,236.4,2000,2000,1,1,232.2,,2000,0,1,0,,,0,0,0,0,,,0,0,0,0,,,0,0,0,0,,,0,0,0,0,,,0,0,0,0,,,0,0,0,0,,,0,0,0,0,,,0,0,0,0,AAPL
2024-10-22 13:11:58.256665569+00:00,10,39,38,C,B,1,232.2,2000,130,203574,68924,232.4,236.4,2000,2000,1,1,,,0,0,0,0,,,0,0,0,0,,,0,0,0,0,,,0,0,0,0,,,0,0,0,0,,,0,0,0,0,,,0,0,0,0,,,0,0,0,0,,,0,0,0,0,AAPL
2024-10-22 13:11:58.307297433+00:00,10,39,38,C,B,0,232.4,2000,130,203735,68926,,236.4,0,2000,0,1,,,0,0,0,0,,,0,0,0,0,,,0,0,0,0,,,0,0,0,0,,,0,0,0,0,,,0,0,0,0,,,0,0,0,0,,,0,0,0,0,,,0,0,0,0,AAPL
2024-10-22 13:11:58.324589541+00:00,10,39,38,A,B,0,232.2,2000,130,203608,68928,232.2,236.4,2000,2000,1,1,,,0,0,0,0,,,0,0,0,0,,,0,0,0,0,,,0,0,0,0,,,0,0,0,0,,,0,0,0,0,,,0,0,0,0,,,0,0,0,0,,,0,0,0,0,AAPL
2024-10-22 13:12:00.000297973+00:00,10,40,38,A,B,0,234.41,200,194,203260,116578,,234.41,0,200,0,0,,,0,0,0,0,,,0,0,0,0,,,0,0,0,0,,,0,0,0,0,,,0,0,0,0,,,0,0,0,0,,,0,0,0,0,,,0,0,0,0,,,0,0,0,0,AAPL
2024-10-22 13:12:00.000303715+00:00,10,40,38,A,A,0,,0,194,203340,116579,,,0,0,0,0,,,0,0,0,0,,,0,0,0,0,,,0,0,0,0,,,0,0,0,0,,,0,0,0,0,,,0,0,0,0,,,0,0,0,0,,,0,0,0,0,,,0,0,0,0,AAPL
2024-10-22 13:12:00.000822194+00:00,10,41,38,A,A,0,,0,194,61001,275040,233.87,,200,0,0,0,,,0,0,0,0,,,0,0,0,0,,,0,0,0,0,,,0,0,0,0,,,0,0,0,0,,,0,0,0,0,,,0,0,0,0,,,0,0,0,0,,,0,0,0,0,AAPL
2024-10-22 13:12:00.147130990+00:00,10,40,38,A,B,0,,0,194,203175,116639,233.81,,200,0,0,0,,,0,0,0,0,,,0,0,0,0,,,0,0,0,0,,,0,0,0,0,,,0,0,0,0,,,0,0,0,0,,,0,0,0,0,,,0,0,0,0,,,0,0,0,0,AAPL
2024-10-22 13:12:00.201705324+00:00,10,40,38,A,A,0,234.46,200,194,203180,116646,233.81,234.46,200,200,0,0,,,0,0,0,0,,,0,0,0,0,,,0,0,0,0,,,0,0,0,0,,,0,0,0,0,,,0,0,0,0,,,0,0,0,0,,,0,0,0,0,,,0,0,0,0,AAPL
2024-10-22 13:12:00.207103737+00:00,10,39,38,C,B,0,232.2,2000,130,203749,68955,,236.4,0,2000,0,1,,,0,0,0,0,,,0,0,0,0,,,0,0,0,0,,,0,0,0,0,,,0,0,0,0,,,0,0,0,0,,,0,0,0,0,,,0,0,0,0,,,0,0,0,0,AAPL
2024-10-22 13:12:00.220712019+00:00,10,39,38,A,B,0,232.2,2000,130,203713,68957,232.2,236.4,2000,2000,1,1,,,0,0,0,0,,,0,0,0,0,,,0,0,0,0,,,0,0,0,0,,,0,0,0,0,,,0,0,0,0,,,0,0,0,0,,,0,0,0,0,,,0,0,0,0,AAPL
2024-10-22 13:12:00.711691492+00:00,10,40,38,A,A,0,,0,194,203145,116666,233.81,,200,0,0,0,,,0,0,0,0,,,0,0,0,0,,,0,0,0,0,,,0,0,0,0,,,0,0,0,0,,,0,0,0,0,,,0,0,0,0,,,0,0,0,0,,,0,0,0,0,AAPL
2024-10-22 13:12:00.819521673+00:00,10,40,38,A,A,0,234.46,200,194,203202,116668,233.81,234.46,200,200,0,0,,,0,0,0,0,,,0,0,0,0,,,0,0,0,0,,,0,0,0,0,,,0,0,0,0,,,0,0,0,0,,,0,0,0,0,,,0,0,0,0,,,0,0,0,0,AAPL
2024-10-22 13:12:00.820015880+00:00,10,41,38,A,A,0,234.41,200,194,55821,275370,233.87,234.41,200,200,0,0,,,0,0,0,0,,,0,0,0,0,,,0,0,0,0,,,0,0,0,0,,,0,0,0,0,,,0,0,0,0,,,0,0,0,0,,,0,0,0,0,,,0,0,0,0,AAPL
2024-10-22 13:12:01.937534469+00:00,10,40,38,A,A,0,,0,194,203251,116697,233.81,,200,0,0,0,,,0,0,0,0,,,0,0,0,0,,,0,0,0,0,,,0,0,0,0,,,0,0,0,0,,,0,0,0,0,,,0,0,0,0,,,0,0,0,0,,,0,0,0,0,AAPL
2024-10-22 13:12:01.937848024+00:00,10,41,38,A,A,0,,0,194,55751,275449,233.87,,200,0,0,0,,,0,0,0,0,,,0,0,0,0,,,0,0,0,0,,,0,0,0,0,,,0,0,0,0,,,0,0,0,0,,,0,0,0,0,,,0,0,0,0,,,0,0,0,0,AAPL
2024-10-22 13:12:02.718408168+00:00,10,40,38,A,A,0,234.46,200,194,203349,116702,233.81,234.46,200,200,0,0,,,0,0,0,0,,,0,0,0,0,,,0,0,0,0,,,0,0,0,0,,,0,0,0,0,,,0,0,0,0,,,0,0,0,0,,,0,0,0,0,,,0,0,0,0,AAPL
2024-10-22 13:12:02.718888282+00:00,10,41,38,A,A,0,234.41,200,194,54780,275481,233.87,234.41,200,200,0,0,,,0,0,0,0,,,0,0,0,0,,,0,0,0,0,,,0,0,0,0,,,0,0,0,0,,,0,0,0,0,,,0,0,0,0,,,0,0,0,0,,,0,0,0,0,AAPL
2024-10-22 13:12:05.839767191+00:00,10,39,38,C,A,0,236.4,2000,130,203624,69001,232.2,,2000,0,1,0,,,0,0,0,0,,,0,0,0,0,,,0,0,0,0,,,0,0,0,0,,,0,0,0,0,,,0,0,0,0,,,0,0,0,0,,,0,0,0,0,,,0,0,0,0,AAPL
2024-10-22 13:12:05.864573856+00:00,10,39,38,A,A,0,236.4,2000,130,203494,69002,232.2,236.4,2000,2000,1,1,,,0,0,0,0,,,0,0,0,0,,,0,0,0,0,,,0,0,0,0,,,0,0,0,0,,,0,0,0,0,,,0,0,0,0,,,0,0,0,0,,,0,0,0,0,AAPL
2024-10-22 13:12:05.866544245+00:00,10,39,38,C,A,0,236.4,2000,130,203394,69003,232.2,,2000,0,1,0,,,0,0,0,0,,,0,0,0,0,,,0,0,0,0,,,0,0,0,0,,,0,0,0,0,,,0,0,0,0,,,0,0,0,0,,,0,0,0,0,,,0,0,0,0,AAPL
2024-10-22 13:12:05.878424544+00:00,10,39,38,A,A,0,236.4,2000,130,204012,69004,232.2,236.4,2000,2000,1,1,,,0,0,0,0,,,0,0,0,0,,,0,0,0,0,,,0,0,0,0,,,0,0,0,0,,,0,0,0,0,,,0,0,0,0,,,0,0,0,0,,,0,0,0,0,AAPL
2024-10-22 13:12:06.755225078+00:00,10,39,38,C,A,0,236.4,2000,130,204360,69006,232.2,,2000,0,1,0,,,0,0,0,0,,,0,0,0,0,,,0,0,0,0,,,0,0,0,0,,,0,0,0,0,,,0,0,0,0,,,0,0,0,0,,,0,0,0,0,,,0,0,0,0,AAPL
2024-10-22 13:12:06.771307144+00:00,10,39,38,A,B,0,232.4,2000,130,203552,69007,232.4,,2000,0,1,0,232.2,,2000,0,1,0,,,0,0,0,0,,,0,0,0,0,,,0,0,0,0,,,0,0,0,0,,,0,0,0,0,,,0,0,0,0,,,0,0,0,0,,,0,0,0,0,AAPL
2024-10-22 13:12:06.771499211+00:00,10,39,38,C,B,1,232.2,2000,130,203461,69008,232.4,,2000,0,1,0,,,0,0,0,0,,,0,0,0,0,,,0,0,0,0,,,0,0,0,0,,,0,0,0,0,,,0,0,0,0,,,0,0,0,0,,,0,0,0,0,,,0,0,0,0,AAPL
2024-10-22 13:12:06.790632110+00:00,10,39,38,A,A,0,236.6,2000,130,203509,69009,232.4,236.6,2000,2000,1,1,,,0,0,0,0,,,0,0,0,0,,,0,0,0,0,,,0,0,0,0,,,0,0,0,0,,,0,0,0,0,,,0,0,0,0,,,0,0,0,0,,,0,0,0,0,AAPL
2024-10-22 13:12:08.135721377+00:00,10,39,38,C,B,0,232.4,2000,130,204151,69025,,236.6,0,2000,0,1,,,0,0,0,0,,,0,0,0,0,,,0,0,0,0,,,0,0,0,0,,,0,0,0,0,,,0,0,0,0,,,0,0,0,0,,,0,0,0,0,,,0,0,0,0,AAPL
2024-10-22 13:12:08.148825558+00:00,10,39,38,A,B,0,232.2,2000,130,203557,69026,232.2,236.6,2000,2000,1,1,,,0,0,0,0,,,0,0,0,0,,,0,0,0,0,,,0,0,0,0,,,0,0,0,0,,,0,0,0,0,,,0,0,0,0,,,0,0,0,0,,,0,0,0,0,AAPL
2024-10-22 13:12:08.341298428+00:00,10,39,38,A,B,0,232.4,2000,130,203608,69027,232.4,236.6,2000,2000,1,1,232.2,,2000,0,1,0,,,0,0,0,0,,,0,0,0,0,,,0,0,0,0,,,0,0,0,0,,,0,0,0,0,,,0,0,0,0,,,0,0,0,0,,,0,0,0,0,AAPL
2024-10-22 13:12:08.341466583+00:00,10,39,38,C,B,1,232.2,2000,130,203523,69028,232.4,236.6,2000,2000,1,1,,,0,0,0,0,,,0,0,0,0,,,0,0,0,0,,,0,0,0,0,,,0,0,0,0,,,0,0,0,0,,,0,0,0,0,,,0,0,0,0,,,0,0,0,0,AAPL
2024-10-22 13:12:08.511731346+00:00,10,39,38,C,B,0,232.4,2000,130,203687,69029,,236.6,0,2000,0,1,,,0,0,0,0,,,0,0,0,0,,,0,0,0,0,,,0,0,0,0,,,0,0,0,0,,,0,0,0,0,,,0,0,0,0,,,0,0,0,0,,,0,0,0,0,AAPL
2024-10-22 13:12:08.521898971+00:00,10,39,38,A,A,0,236.4,2000,130,203683,69030,,236.4,0,2000,0,1,,236.6,0,2000,0,1,,,0,0,0,0,,,0,0,0,0,,,0,0,0,0,,,0,0,0,0,,,0,0,0,0,,,0,0,0,0,,,0,0,0,0,,,0,0,0,0,AAPL
2024-10-22 13:12:08.522083721+00:00,10,39,38,C,A,1,236.6,2000,130,203423,69031,,236.4,0,2000,0,1,,,0,0,0,0,,,0,0,0,0,,,0,0,0,0,,,0,0,0,0,,,0,0,0,0,,,0,0,0,0,,,0,0,0,0,,,0,0,0,0,,,0,0,0,0,AAPL
2024-10-22 13:12:08.548349943+00:00,10,39,38,A,B,0,231.8,2000,130,203503,69032,231.8,236.4,2000,2000,1,1,,,0,0,0,0,,,0,0,0,0,,,0,0,0,0,,,0,0,0,0,,,0,0,0,0,,,0,0,0,0,,,0,0,0,0,,,0,0,0,0,,,0,0,0,0,AAPL
2024-10-22 13:12:08.581622808+00:00,10,39,38,A,B,0,232.4,2000,130,203460,69034,232.4,236.4,2000,2000,1,1,231.8,,2000,0,1,0,,,0,0,0,0,,,0,0,0,0,,,0,0,0,0,,,0,0,0,0,,,0,0,0,0,,,0,0,0,0,,,0,0,0,0,,,0,0,0,0,AAPL
2024-10-22 13:12:08.581817302+00:00,10,39,38,C,B,1,231.8,2000,130,203419,69035,232.4,236.4,2000,2000,1,1,,,0,0,0,0,,,0,0,0,0,,,0,0,0,0,,,0,0,0,0,,,0,0,0,0,,,0,0,0,0,,,0,0,0,0,,,0,0,0,0,,,0,0,0,0,AAPL
2024-10-22 13:12:08.593984264+00:00,10,39,38,C,B,0,232.4,2000,130,203419,69036,,236.4,0,2000,0,1,,,0,0,0,0,,,0,0,0,0,,,0,0,0,0,,,0,0,0,0,,,0,0,0,0,,,0,0,0,0,,,0,0,0,0,,,0,0,0,0,,,0,0,0,0,AAPL
2024-10-22 13:12:08.605368873+00:00,10,39,38,A,B,0,232.2,2000,130,203445,69037,232.2,236.4,2000,2000,1,1,,,0,0,0,0,,,0,0,0,0,,,0,0,0,0,,,0,0,0,0,,,0,0,0,0,,,0,0,0,0,,,0,0,0,0,,,0,0,0,0,,,0,0,0,0,AAPL
2024-10-22 13:12:08.662806747+00:00,10,39,38,A,B,0,232.4,2000,130,203488,69038,232.4,236.4,2000,2000,1,1,232.2,,2000,0,1,0,,,0,0,0,0,,,0,0,0,0,,,0,0,0,0,,,0,0,0,0,,,0,0,0,0,,,0,0,0,0,,,0,0,0,0,,,0,0,0,0,AAPL
2024-10-22 13:12:08.663534661+00:00,10,39,38,C,B,1,232.2,2000,130,203411,69039,232.4,236.4,2000,2000,1,1,,,0,0,0,0,,,0,0,0,0,,,0,0,0,0,,,0,0,0,0,,,0,0,0,0,,,0,0,0,0,,,0,0,0,0,,,0,0,0,0,,,0,0,0,0,AAPL
2024-10-22 13:12:08.665993319+00:00,10,39,38,C,B,0,232.4,2000,130,203384,69040,,236.4,0,2000,0,1,,,0,0,0,0,,,0,0,0,0,,,0,0,0,0,,,0,0,0,0,,,0,0,0,0,,,0,0,0,0,,,0,0,0,0,,,0,0,0,0,,,0,0,0,0,AAPL
2024-10-22 13:12:08.680802073+00:00,10,39,38,A,B,0,232.4,2000,130,203498,69042,232.4,236.4,2000,2000,1,1,,,0,0,0,0,,,0,0,0,0,,,0,0,0,0,,,0,0,0,0,,,0,0,0,0,,,0,0,0,0,,,0,0,0,0,,,0,0,0,0,,,0,0,0,0,AAPL
2024-10-22 13:12:09.086478507+00:00,10,39,38,C,B,0,232.4,2000,130,203490,69052,,236.4,0,2000,0,1,,,0,0,0,0,,,0,0,0,0,,,0,0,0,0,,,0,0,0,0,,,0,0,0,0,,,0,0,0,0,,,0,0,0,0,,,0,0,0,0,,,0,0,0,0,AAPL
2024-10-22 13:12:09.097214675+00:00,10,39,38,A,B,0,232.2,2000,130,203496,69055,232.2,236.4,2000,2000,1,1,,,0,0,0,0,,,0,0,0,0,,,0,0,0,0,,,0,0,0,0,,,0,0,0,0,,,0,0,0,0,,,0,0,0,0,,,0,0,0,0,,,0,0,0,0,AAPL
2024-10-22 13:12:09.112578437+00:00,10,39,38,C,B,0,232.2,2000,130,203472,69056,,236.4,0,2000,0,1,,,0,0,0,0,,,0,0,0,0,,,0,0,0,0,,,0,0,0,0,,,0,0,0,0,,,0,0,0,0,,,0,0,0,0,,,0,0,0,0,,,0,0,0,0,AAPL
2024-10-22 13:12:09.123315116+00:00,10,39,38,A,B,0,232.0,2000,130,203629,69058,232.0,236.4,2000,2000,1,1,,,0,0,0,0,,,0,0,0,0,,,0,0,0,0,,,0,0,0,0,,,0,0,0,0,,,0,0,0,0,,,0,0,0,0,,,0,0,0,0,,,0,0,0,0,AAPL
2024-10-22 13:12:09.320976364+00:00,10,39,38,A,B,0,232.4,2000,130,203581,69062,232.4,236.4,2000,2000,1,1,232.0,,2000,0,1,0,,,0,0,0,0,,,0,0,0,0,,,0,0,0,0,,,0,0,0,0,,,0,0,0,0,,,0,0,0,0,,,0,0,0,0,,,0,0,0,0,AAPL
2024-10-22 13:12:09.321171060+00:00,10,39,38,C,B,1,232.0,2000,130,203501,69063,232.4,236.4,2000,2000,1,1,,,0,0,0,0,,,0,0,0,0,,,0,0,0,0,,,0,0,0,0,,,0,0,0,0,,,0,0,0,0,,,0,0,0,0,,,0,0,0,0,,,0,0,0,0,AAPL
2024-10-22 13:12:18.136060503+00:00,10,39,38,C,A,0,236.4,2000,130,203813,69096,232.4,,2000,0,1,0,,,0,0,0,0,,,0,0,0,0,,,0,0,0,0,,,0,0,0,0,,,0,0,0,0,,,0,0,0,0,,,0,0,0,0,,,0,0,0,0,,,0,0,0,0,AAPL
2024-10-22 13:12:26.630274339+00:00,10,39,10888,C,A,0,421.2,2000,130,203788,101629,,,0,0,0,0,,,0,0,0,0,,,0,0,0,0,,,0,0,0,0,,,0,0,0,0,,,0,0,0,0,,,0,0,0,0,,,0,0,0,0,,,0,0,0,0,,,0,0,0,0,MSFT
2024-10-22 13:12:26.667198373+00:00,10,39,10888,A,A,0,421.2,2000,130,203582,101630,,421.2,0,2000,0,1,,,0,0,0,0,,,0,0,0,0,,,0,0,0,0,,,0,0,0,0,,,0,0,0,0,,,0,0,0,0,,,0,0,0,0,,,0,0,0,0,,,0,0,0,0,MSFT
2024-10-22 13:12:30.144845632+00:00,10,39,38,A,A,0,236.4,2000,130,203984,69135,232.4,236.4,2000,2000,1,1,,,0,0,0,0,,,0,0,0,0,,,0,0,0,0,,,0,0,0,0,,,0,0,0,0,,,0,0,0,0,,,0,0,0,0,,,0,0,0,0,,,0,0,0,0,AAPL
2024-10-22 13:12:30.205292421+00:00,10,39,38,C,A,0,236.4,2000,130,203792,69136,232.4,,2000,0,1,0,,,0,0,0,0,,,0,0,0,0,,,0,0,0,0,,,0,0,0,0,,,0,0,0,0,,,0,0,0,0,,,0,0,0,0,,,0,0,0,0,,,0,0,0,0,AAPL
2024-10-22 13:12:30.235325511+00:00,10,39,38,A,A,0,236.4,2000,130,203823,69137,232.4,236.4,2000,2000,1,1,,,0,0,0,0,,,0,0,0,0,,,0,0,0,0,,,0,0,0,0,,,0,0,0,0,,,0,0,0,0,,,0,0,0,0,,,0,0,0,0,,,0,0,0,0,AAPL
2024-10-22 13:12:31.304974022+00:00,10,39,38,C,B,0,232.4,2000,130,203863,69140,,236.4,0,2000,0,1,,,0,0,0,0,,,0,0,0,0,,,0,0,0,0,,,0,0,0,0,,,0,0,0,0,,,0,0,0,0,,,0,0,0,0,,,0,0,0,0,,,0,0,0,0,AAPL
2024-10-22 13:12:31.315711983+00:00,10,39,38,A,B,0,232.2,2000,130,203770,69141,232.2,236.4,2000,2000,1,1,,,0,0,0,0,,,0,0,0,0,,,0,0,0,0,,,0,0,0,0,,,0,0,0,0,,,0,0,0,0,,,0,0,0,0,,,0,0,0,0,,,0,0,0,0,AAPL
2024-10-22 13:12:31.329334389+00:00,10,39,38,C,B,0,232.2,2000,130,203687,69142,,236.4,0,2000,0,1,,,0,0,0,0,,,0,0,0,0,,,0,0,0,0,,,0,0,0,0,,,0,0,0,0,,,0,0,0,0,,,0,0,0,0,,,0,0,0,0,,,0,0,0,0,AAPL
2024-10-22 13:12:31.340341902+00:00,10,39,38,A,B,0,232.0,2000,130,203719,69143,232.0,236.4,2000,2000,1,1,,,0,0,0,0,,,0,0,0,0,,,0,0,0,0,,,0,0,0,0,,,0,0,0,0,,,0,0,0,0,,,0,0,0,0,,,0,0,0,0,,,0,0,0,0,AAPL
2024-10-22 13:12:31.537654607+00:00,10,39,38,A,B,0,232.4,2000,130,203848,69144,232.4,236.4,2000,2000,1,1,232.0,,2000,0,1,0,,,0,0,0,0,,,0,0,0,0,,,0,0,0,0,,,0,0,0,0,,,0,0,0,0,,,0,0,0,0,,,0,0,0,0,,,0,0,0,0,AAPL
2024-10-22 13:12:31.537849164+00:00,10,39,38,C,B,1,232.0,2000,130,203588,69145,232.4,236.4,2000,2000,1,1,,,0,0,0,0,,,0,0,0,0,,,0,0,0,0,,,0,0,0,0,,,0,0,0,0,,,0,0,0,0,,,0,0,0,0,,,0,0,0,0,,,0,0,0,0,AAPL
2024-10-22 13:12:33.791520446+00:00,10,39,38,C,A,0,236.4,2000,130,203533,69176,232.4,,2000,0,1,0,,,0,0,0,0,,,0,0,0,0,,,0,0,0,0,,,0,0,0,0,,,0,0,0,0,,,0,0,0,0,,,0,0,0,0,,,0,0,0,0,,,0,0,0,0,AAPL
2024-10-22 13:13:00.035431041+00:00,10,40,38,A,A,0,,0,194,203513,117166,233.81,,200,0,0,0,,,0,0,0,0,,,0,0,0,0,,,0,0,0,0,,,0,0,0,0,,,0,0,0,0,,,0,0,0,0,,,0,0,0,0,,,0,0,0,0,,,0,0,0,0,AAPL
2024-10-22 13:13:00.035667752+00:00,10,41,38,A,B,0,234.41,200,194,55843,277756,,234.41,0,200,0,0,,,0,0,0,0,,,0,0,0,0,,,0,0,0,0,,,0,0,0,0,,,0,0,0,0,,,0,0,0,0,,,0,0,0,0,,,0,0,0,0,,,0,0,0,0,AAPL
2024-10-22 13:13:00.035678159+00:00,10,41,38,A,A,0,,0,194,54437,277757,,,0,0,0,0,,,0,0,0,0,,,0,0,0,0,,,0,0,0,0,,,0,0,0,0,,,0,0,0,0,,,0,0,0,0,,,0,0,0,0,,,0,0,0,0,,,0,0,0,0,AAPL
2024-10-22 13:13:00.126983331+00:00,10,41,38,A,B,0,,0,194,55350,277909,233.86,,200,0,0,0,,,0,0,0,0,,,0,0,0,0,,,0,0,0,0,,,0,0,0,0,,,0,0,0,0,,,0,0,0,0,,,0,0,0,0,,,0,0,0,0,,,0,0,0,0,AAPL
2024-10-22 13:13:00.337096144+00:00,10,40,38,A,A,0,234.46,200,194,203555,117210,233.81,234.46,200,200,0,0,,,0,0,0,0,,,0,0,0,0,,,0,0,0,0,,,0,0,0,0,,,0,0,0,0,,,0,0,0,0,,,0,0,0,0,,,0,0,0,0,,,0,0,0,0,AAPL
2024-10-22 13:13:02.754624288+00:00,10,41,38,A,A,0,234.41,200,194,55992,278161,233.86,234.41,200,200,0,0,,,0,0,0,0,,,0,0,0,0,,,0,0,0,0,,,0,0,0,0,,,0,0,0,0,,,0,0,0,0,,,0,0,0,0,,,0,0,0,0,,,0,0,0,0,AAPL
2024-10-22 13:13:04.451065549+00:00,10,39,38,A,B,0,232.6,2000,130,204420,69365,232.6,,2000,0,1,0,232.4,,2000,0,1,0,,,0,0,0,0,,,0,0,0,0,,,0,0,0,0,,,0,0,0,0,,,0,0,0,0,,,0,0,0,0,,,0,0,0,0,,,0,0,0,0,AAPL
2024-10-22 13:13:04.451260991+00:00,10,39,38,C,B,1,232.4,2000,130,204232,69366,232.6,,2000,0,1,0,,,0,0,0,0,,,0,0,0,0,,,0,0,0,0,,,0,0,0,0,,,0,0,0,0,,,0,0,0,0,,,0,0,0,0,,,0,0,0,0,,,0,0,0,0,AAPL
2024-10-22 13:13:14.451379076+00:00,10,39,10888,C,A,0,421.2,2000,130,203924,101883,,,0,0,0,0,,,0,0,0,0,,,0,0,0,0,,,0,0,0,0,,,0,0,0,0,,,0,0,0,0,,,0,0,0,0,,,0,0,0,0,,,0,0,0,0,,,0,0,0,0,MSFT
2024-10-22 13:13:14.471438200+00:00,10,39,10888,A,A,0,421.2,2000,130,203435,101885,,421.2,0,2000,0,1,,,0,0,0,0,,,0,0,0,0,,,0,0,0,0,,,0,0,0,0,,,0,0,0,0,,,0,0,0,0,,,0,0,0,0,,,0,0,0,0,,,0,0,0,0,MSFT
2024-10-22 13:13:21.053622041+00:00,10,39,10888,C,A,0,421.2,2000,130,203827,101962,,,0,0,0,0,,,0,0,0,0,,,0,0,0,0,,,0,0,0,0,,,0,0,0,0,,,0,0,0,0,,,0,0,0,0,,,0,0,0,0,,,0,0,0,0,,,0,0,0,0,MSFT
2024-10-22 13:13:21.090686578+00:00,10,39,10888,A,A,0,421.2,2000,130,203547,101963,,421.2,0,2000,0,1,,,0,0,0,0,,,0,0,0,0,,,0,0,0,0,,,0,0,0,0,,,0,0,0,0,,,0,0,0,0,,,0,0,0,0,,,0,0,0,0,,,0,0,0,0,MSFT
2024-10-22 13:14:00.050353854+00:00,10,40,38,A,B,0,234.46,200,194,203619,117795,,234.46,0,200,0,0,,,0,0,0,0,,,0,0,0,0,,,0,0,0,0,,,0,0,0,0,,,0,0,0,0,,,0,0,0,0,,,0,0,0,0,,,0,0,0,0,,,0,0,0,0,AAPL
2024-10-22 13:14:00.050361855+00:00,10,40,38,A,A,0,,0,194,203596,117796,,,0,0,0,0,,,0,0,0,0,,,0,0,0,0,,,0,0,0,0,,,0,0,0,0,,,0,0,0,0,,,0,0,0,0,,,0,0,0,0,,,0,0,0,0,,,0,0,0,0,AAPL
2024-10-22 13:14:00.050476241+00:00,10,40,38,A,B,0,,0,194,203556,117797,233.85,,200,0,0,0,,,0,0,0,0,,,0,0,0,0,,,0,0,0,0,,,0,0,0,0,,,0,0,0,0,,,0,0,0,0,,,0,0,0,0,,,0,0,0,0,,,0,0,0,0,AAPL
2024-10-22 13:14:00.050818338+00:00,10,41,38,A,A,0,,0,194,56774,280268,233.86,,200,0,0,0,,,0,0,0,0,,,0,0,0,0,,,0,0,0,0,,,0,0,0,0,,,0,0,0,0,,,0,0,0,0,,,0,0,0,0,,,0,0,0,0,,,0,0,0,0,AAPL
2024-10-22 13:14:00.050824073+00:00,10,41,38,A,B,0,,0,194,58858,280271,,,0,0,0,0,,,0,0,0,0,,,0,0,0,0,,,0,0,0,0,,,0,0,0,0,,,0,0,0,0,,,0,0,0,0,,,0,0,0,0,,,0,0,0,0,,,0,0,0,0,AAPL
2024-10-22 13:14:00.150660844+00:00,10,41,38,A,A,0,234.43,200,194,55525,280393,,234.43,0,200,0,0,,,0,0,0,0,,,0,0,0,0,,,0,0,0,0,,,0,0,0,0,,,0,0,0,0,,,0,0,0,0,,,0,0,0,0,,,0,0,0,0,,,0,0,0,0,AAPL
2024-10-22 13:14:00.250977566+00:00,10,41,38,A,B,0,234.43,200,194,55333,280439,233.9,234.43,200,200,0,0,,,0,0,0,0,,,0,0,0,0,,,0,0,0,0,,,0,0,0,0,,,0,0,0,0,,,0,0,0,0,,,0,0,0,0,,,0,0,0,0,,,0,0,0,0,AAPL
2024-10-22 13:14:00.251494789+00:00,10,41,38,A,A,0,,0,194,55132,280440,233.9,,200,0,0,0,,,0,0,0,0,,,0,0,0,0,,,0,0,0,0,,,0,0,0,0,,,0,0,0,0,,,0,0,0,0,,,0,0,0,0,,,0,0,0,0,,,0,0,0,0,AAPL
2024-10-22 13:14:00.351865029+00:00,10,41,38,A,A,0,234.43,200,194,55396,280460,233.9,234.43,200,200,0,0,,,0,0,0,0,,,0,0,0,0,,,0,0,0,0,,,0,0,0,0,,,0,0,0,0,,,0,0,0,0,,,0,0,0,0,,,0,0,0,0,,,0,0,0,0,AAPL
2024-10-22 13:14:00.553150201+00:00,10,40,38,A,A,0,234.48,200,194,203590,117846,233.85,234.48,200,200,0,0,,,0,0,0,0,,,0,0,0,0,,,0,0,0,0,,,0,0,0,0,,,0,0,0,0,,,0,0,0,0,,,0,0,0,0,,,0,0,0,0,,,0,0,0,0,AAPL
2024-10-22 13:14:18.253544307+00:00,10,39,10888,C,A,0,421.2,2000,130,203245,102234,,,0,0,0,0,,,0,0,0,0,,,0,0,0,0,,,0,0,0,0,,,0,0,0,0,,,0,0,0,0,,,0,0,0,0,,,0,0,0,0,,,0,0,0,0,,,0,0,0,0,MSFT
2024-10-22 13:14:18.290346673+00:00,10,39,10888,A,A,0,421.2,2000,130,203245,102235,,421.2,0,2000,0,1,,,0,0,0,0,,,0,0,0,0,,,0,0,0,0,,,0,0,0,0,,,0,0,0,0,,,0,0,0,0,,,0,0,0,0,,,0,0,0,0,,,0,0,0,0,MSFT
2024-10-22 13:14:21.086880602+00:00,10,39,38,A,A,0,236.4,2000,130,203581,69694,232.6,236.4,2000,2000,1,1,,,0,0,0,0,,,0,0,0,0,,,0,0,0,0,,,0,0,0,0,,,0,0,0,0,,,0,0,0,0,,,0,0,0,0,,,0,0,0,0,,,0,0,0,0,AAPL
2024-10-22 13:14:21.642901955+00:00,10,39,38,C,B,0,232.6,2000,130,203193,69695,,236.4,0,2000,0,1,,,0,0,0,0,,,0,0,0,0,,,0,0,0,0,,,0,0,0,0,,,0,0,0,0,,,0,0,0,0,,,0,0,0,0,,,0,0,0,0,,,0,0,0,0,AAPL
2024-10-22 13:14:21.654283936+00:00,10,39,38,A,B,0,232.4,2000,130,202882,69696,232.4,236.4,2000,2000,1,1,,,0,0,0,0,,,0,0,0,0,,,0,0,0,0,,,0,0,0,0,,,0,0,0,0,,,0,0,0,0,,,0,0,0,0,,,0,0,0,0,,,0,0,0,0,AAPL
2024-10-22 13:14:23.390750108+00:00,10,39,38,C,A,0,236.4,2000,130,203196,69709,232.4,,2000,0,1,0,,,0,0,0,0,,,0,0,0,0,,,0,0,0,0,,,0,0,0,0,,,0,0,0,0,,,0,0,0,0,,,0,0,0,0,,,0,0,0,0,,,0,0,0,0,AAPL
2024-10-22 13:14:23.401095093+00:00,10,39,38,A,B,0,232.6,2000,130,203308,69710,232.6,,2000,0,1,0,232.4,,2000,0,1,0,,,0,0,0,0,,,0,0,0,0,,,0,0,0,0,,,0,0,0,0,,,0,0,0,0,,,0,0,0,0,,,0,0,0,0,,,0,0,0,0,AAPL
2024-10-22 13:14:23.401489761+00:00,10,39,38,C,B,1,232.4,2000,130,203152,69711,232.6,,2000,0,1,0,,,0,0,0,0,,,0,0,0,0,,,0,0,0,0,,,0,0,0,0,,,0,0,0,0,,,0,0,0,0,,,0,0,0,0,,,0,0,0,0,,,0,0,0,0,AAPL
2024-10-22 13:14:23.422689245+00:00,10,39,38,C,B,0,232.6,2000,130,203122,69712,,,0,0,0,0,,,0,0,0,0,,,0,0,0,0,,,0,0,0,0,,,0,0,0,0,,,0,0,0,0,,,0,0,0,0,,,0,0,0,0,,,0,0,0,0,,,0,0,0,0,AAPL
2024-10-22 13:14:23.427434184+00:00,10,39,38,A,A,0,236.4,2000,130,203175,69713,,236.4,0,2000,0,1,,,0,0,0,0,,,0,0,0,0,,,0,0,0,0,,,0,0,0,0,,,0,0,0,0,,,0,0,0,0,,,0,0,0,0,,,0,0,0,0,,,0,0,0,0,AAPL
2024-10-22 13:14:23.433664974+00:00,10,39,38,A,B,0,232.4,2000,130,203148,69714,232.4,236.4,2000,2000,1,1,,,0,0,0,0,,,0,0,0,0,,,0,0,0,0,,,0,0,0,0,,,0,0,0,0,,,0,0,0,0,,,0,0,0,0,,,0,0,0,0,,,0,0,0,0,AAPL
2024-10-22 13:14:24.193927240+00:00,10,39,38,A,B,0,232.6,2000,130,203334,69717,232.6,236.4,2000,2000,1,1,232.4,,2000,0,1,0,,,0,0,0,0,,,0,0,0,0,,,0,0,0,0,,,0,0,0,0,,,0,0,0,0,,,0,0,0,0,,,0,0,0,0,,,0,0,0,0,AAPL
2024-10-22 13:14:24.194111662+00:00,10,39,38,C,B,1,232.4,2000,130,203306,69718,232.6,236.4,2000,2000,1,1,,,0,0,0,0,,,0,0,0,0,,,0,0,0,0,,,0,0,0,0,,,0,0,0,0,,,0,0,0,0,,,0,0,0,0,,,0,0,0,0,,,0,0,0,0,AAPL
2024-10-22 13:14:24.248502614+00:00,10,39,38,C,B,0,232.6,2000,130,203384,69719,,236.4,0,2000,0,1,,,0,0,0,0,,,0,0,0,0,,,0,0,0,0,,,0,0,0,0,,,0,0,0,0,,,0,0,0,0,,,0,0,0,0,,,0,0,0,0,,,0,0,0,0,AAPL
2024-10-22 13:14:24.260723924+00:00,10,39,38,A,B,0,232.4,2000,130,203353,69720,232.4,236.4,2000,2000,1,1,,,0,0,0,0,,,0,0,0,0,,,0,0,0,0,,,0,0,0,0,,,0,0,0,0,,,0,0,0,0,,,0,0,0,0,,,0,0,0,0,,,0,0,0,0,AAPL
2024-10-22 13:14:24.454908302+00:00,10,39,38,A,B,0,232.6,2000,130,203569,69721,232.6,236.4,2000,2000,1,1,232.4,,2000,0,1,0,,,0,0,0,0,,,0,0,0,0,,,0,0,0,0,,,0,0,0,0,,,0,0,0,0,,,0,0,0,0,,,0,0,0,0,,,0,0,0,0,AAPL
2024-10-22 13:14:24.455125406+00:00,10,39,38,C,B,1,232.4,2000,130,203220,69722,232.6,236.4,2000,2000,1,1,,,0,0,0,0,,,0,0,0,0,,,0,0,0,0,,,0,0,0,0,,,0,0,0,0,,,0,0,0,0,,,0,0,0,0,,,0,0,0,0,,,0,0,0,0,AAPL
2024-10-22 13:14:29.337480088+00:00,10,39,38,C,B,0,232.6,2000,130,203909,69733,,236.4,0,2000,0,1,,,0,0,0,0,,,0,0,0,0,,,0,0,0,0,,,0,0,0,0,,,0,0,0,0,,,0,0,0,0,,,0,0,0,0,,,0,0,0,0,,,0,0,0,0,AAPL
2024-10-22 13:14:29.348521424+00:00,10,39,38,A,B,0,232.4,2000,130,203656,69734,232.4,236.4,2000,2000,1,1,,,0,0,0,0,,,0,0,0,0,,,0,0,0,0,,,0,0,0,0,,,0,0,0,0,,,0,0,0,0,,,0,0,0,0,,,0,0,0,0,,,0,0,0,0,AAPL
2024-10-22 13:14:29.473076056+00:00,10,39,38,C,B,0,232.4,2000,130,203697,69735,,236.4,0,2000,0,1,,,0,0,0,0,,,0,0,0,0,,,0,0,0,0,,,0,0,0,0,,,0,0,0,0,,,0,0,0,0,,,0,0,0,0,,,0,0,0,0,,,0,0,0,0,AAPL
2024-10-22 13:14:29.501909349+00:00,10,39,38,A,B,0,232.2,2000,130,203689,69736,232.2,236.4,2000,2000,1,1,,,0,0,0,0,,,0,0,0,0,,,0,0,0,0,,,0,0,0,0,,,0,0,0,0,,,0,0,0,0,,,0,0,0,0,,,0,0,0,0,,,0,0,0,0,AAPL
2024-10-22 13:14:29.532712224+00:00,10,39,38,C,B,0,232.2,2000,130,203529,69737,,236.4,0,2000,0,1,,,0,0,0,0,,,0,0,0,0,,,0,0,0,0,,,0,0,0,0,,,0,0,0,0,,,0,0,0,0,,,0,0,0,0,,,0,0,0,0,,,0,0,0,0,AAPL
2024-10-22 13:14:29.543295033+00:00,10,39,38,A,B,0,232.4,2000,130,203581,69738,232.4,236.4,2000,2000,1,1,,,0,0,0,0,,,0,0,0,0,,,0,0,0,0,,,0,0,0,0,,,0,0,0,0,,,0,0,0,0,,,0,0,0,0,,,0,0,0,0,,,0,0,0,0,AAPL
2024-10-22 13:14:29.829814581+00:00,10,39,38,C,B,0,232.4,2000,130,203698,69742,,236.4,0,2000,0,1,,,0,0,0,0,,,0,0,0,0,,,0,0,0,0,,,0,0,0,0,,,0,0,0,0,,,0,0,0,0,,,0,0,0,0,,,0,0,0,0,,,0,0,0,0,AAPL
2024-10-22 13:14:29.840935832+00:00,10,39,38,A,B,0,232.2,2000,130,203638,69743,232.2,236.4,2000,2000,1,1,,,0,0,0,0,,,0,0,0,0,,,0,0,0,0,,,0,0,0,0,,,0,0,0,0,,,0,0,0,0,,,0,0,0,0,,,0,0,0,0,,,0,0,0,0,AAPL
2024-10-22 13:14:32.630678862+00:00,10,39,38,A,B,0,232.4,2000,130,203977,69761,232.4,236.4,2000,2000,1,1,232.2,,2000,0,1,0,,,0,0,0,0,,,0,0,0,0,,,0,0,0,0,,,0,0,0,0,,,0,0,0,0,,,0,0,0,0,,,0,0,0,0,,,0,0,0,0,AAPL
2024-10-22 13:14:32.630885804+00:00,10,39,38,C,B,1,232.2,2000,130,203820,69762,232.4,236.4,2000,2000,1,1,,,0,0,0,0,,,0,0,0,0,,,0,0,0,0,,,0,0,0,0,,,0,0,0,0,,,0,0,0,0,,,0,0,0,0,,,0,0,0,0,,,0,0,0,0,AAPL
2024-10-22 13:14:32.891307941+00:00,10,39,38,A,B,0,232.6,2000,130,203976,69763,232.6,236.4,2000,2000,1,1,232.4,,2000,0,1,0,,,0,0,0,0,,,0,0,0,0,,,0,0,0,0,,,0,0,0,0,,,0,0,0,0,,,0,0,0,0,,,0,0,0,0,,,0,0,0,0,AAPL
2024-10-22 13:14:32.891500460+00:00,10,39,38,C,B,1,232.4,2000,130,204183,69764,232.6,236.4,2000,2000,1,1,,,0,0,0,0,,,0,0,0,0,,,0,0,0,0,,,0,0,0,0,,,0,0,0,0,,,0,0,0,0,,,0,0,0,0,,,0,0,0,0,,,0,0,0,0,AAPL
2024-10-22 13:14:38.154855088+00:00,10,39,38,C,A,0,236.4,2000,130,203973,69780,232.6,,2000,0,1,0,,,0,0,0,0,,,0,0,0,0,,,0,0,0,0,,,0,0,0,0,,,0,0,0,0,,,0,0,0,0,,,0,0,0,0,,,0,0,0,0,,,0,0,0,0,AAPL
2024-10-22 13:14:38.190725542+00:00,10,39,38,A,A,0,236.4,2000,130,203716,69781,232.6,236.4,2000,2000,1,1,,,0,0,0,0,,,0,0,0,0,,,0,0,0,0,,,0,0,0,0,,,0,0,0,0,,,0,0,0,0,,,0,0,0,0,,,0,0,0,0,,,0,0,0,0,AAPL
2024-10-22 13:14:54.736025100+00:00,10,39,10888,C,A,0,421.2,2000,130,203602,102481,,,0,0,0,0,,,0,0,0,0,,,0,0,0,0,,,0,0,0,0,,,0,0,0,0,,,0,0,0,0,,,0,0,0,0,,,0,0,0,0,,,0,0,0,0,,,0,0,0,0,MSFT
2024-10-22 13:14:54.795611666+00:00,10,39,10888,A,A,0,421.2,2000,130,203635,102486,,421.2,0,2000,0,1,,,0,0,0,0,,,0,0,0,0,,,0,0,0,0,,,0,0,0,0,,,0,0,0,0,,,0,0,0,0,,,0,0,0,0,,,0,0,0,0,,,0,0,0,0,MSFT
2024-10-22 13:14:59.504384793+00:00,10,39,38,C,B,0,232.6,2000,130,204256,69838,,236.4,0,2000,0,1,,,0,0,0,0,,,0,0,0,0,,,0,0,0,0,,,0,0,0,0,,,0,0,0,0,,,0,0,0,0,,,0,0,0,0,,,0,0,0,0,,,0,0,0,0,AAPL
2024-10-22 13:14:59.515148546+00:00,10,39,38,A,B,0,232.4,2000,130,203817,69839,232.4,236.4,2000,2000,1,1,,,0,0,0,0,,,0,0,0,0,,,0,0,0,0,,,0,0,0,0,,,0,0,0,0,,,0,0,0,0,,,0,0,0,0,,,0,0,0,0,,,0,0,0,0,AAPL
2024-10-22 13:14:59.738119633+00:00,10,39,38,A,B,0,232.6,2000,130,203927,69840,232.6,236.4,2000,2000,1,1,232.4,,2000,0,1,0,,,0,0,0,0,,,0,0,0,0,,,0,0,0,0,,,0,0,0,0,,,0,0,0,0,,,0,0,0,0,,,0,0,0,0,,,0,0,0,0,AAPL
2024-10-22 13:14:59.738314935+00:00,10,39,38,C,B,1,232.4,2000,130,203994,69841,232.6,236.4,2000,2000,1,1,,,0,0,0,0,,,0,0,0,0,,,0,0,0,0,,,0,0,0,0,,,0,0,0,0,,,0,0,0,0,,,0,0,0,0,,,0,0,0,0,,,0,0,0,0,AAPL
2024-10-22 13:14:59.791293683+00:00,10,39,38,C,B,0,232.6,2000,130,203758,69842,,236.4,0,2000,0,1,,,0,0,0,0,,,0,0,0,0,,,0,0,0,0,,,0,0,0,0,,,0,0,0,0,,,0,0,0,0,,,0,0,0,0,,,0,0,0,0,,,0,0,0,0,AAPL
2024-10-22 13:14:59.802985714+00:00,10,39,38,A,B,0,232.4,2000,130,203745,69843,232.4,236.4,2000,2000,1,1,,,0,0,0,0,,,0,0,0,0,,,0,0,0,0,,,0,0,0,0,,,0,0,0,0,,,0,0,0,0,,,0,0,0,0,,,0,0,0,0,,,0,0,0,0,AAPL
2024-10-22 13:15:00.005374824+00:00,10,40,38,A,B,0,234.48,200,194,203134,118503,,234.48,0,200,0,0,,,0,0,0,0,,,0,0,0,0,,,0,0,0,0,,,0,0,0,0,,,0,0,0,0,,,0,0,0,0,,,0,0,0,0,,,0,0,0,0,,,0,0,0,0,AAPL
2024-10-22 13:15:00.005387007+00:00,10,40,38,A,A,0,,0,194,203148,118504,,,0,0,0,0,,,0,0,0,0,,,0,0,0,0,,,0,0,0,0,,,0,0,0,0,,,0,0,0,0,,,0,0,0,0,,,0,0,0,0,,,0,0,0,0,,,0,0,0,0,AAPL
2024-10-22 13:15:00.005750040+00:00,10,41,38,A,B,0,234.43,200,194,54994,283533,,234.43,0,200,0,0,,,0,0,0,0,,,0,0,0,0,,,0,0,0,0,,,0,0,0,0,,,0,0,0,0,,,0,0,0,0,,,0,0,0,0,,,0,0,0,0,,,0,0,0,0,AAPL
2024-10-22 13:15:00.005761426+00:00,10,41,38,A,A,0,,0,194,55432,283534,,,0,0,0,0,,,0,0,0,0,,,0,0,0,0,,,0,0,0,0,,,0,0,0,0,,,0,0,0,0,,,0,0,0,0,,,0,0,0,0,,,0,0,0,0,,,0,0,0,0,AAPL
2024-10-22 13:15:01.965461694+00:00,10,40,38,A,B,0,,0,194,203138,118641,233.87,,200,0,0,0,,,0,0,0,0,,,0,0,0,0,,,0,0,0,0,,,0,0,0,0,,,0,0,0,0,,,0,0,0,0,,,0,0,0,0,,,0,0,0,0,,,0,0,0,0,AAPL
2024-10-22 13:15:01.965468063+00:00,10,40,38,A,A,0,234.5,200,194,203139,118642,233.87,234.5,200,200,0,0,,,0,0,0,0,,,0,0,0,0,,,0,0,0,0,,,0,0,0,0,,,0,0,0,0,,,0,0,0,0,,,0,0,0,0,,,0,0,0,0,,,0,0,0,0,AAPL
2024-10-22 13:15:01.965693784+00:00,10,41,38,A,B,0,,0,194,55774,284155,233.92,,200,0,0,0,,,0,0,0,0,,,0,0,0,0,,,0,0,0,0,,,0,0,0,0,,,0,0,0,0,,,0,0,0,0,,,0,0,0,0,,,0,0,0,0,,,0,0,0,0,AAPL
2024-10-22 13:15:02.168204860+00:00,10,40,38,A,A,0,,0,194,203186,118646,233.87,,200,0,0,0,,,0,0,0,0,,,0,0,0,0,,,0,0,0,0,,,0,0,0,0,,,0,0,0,0,,,0,0,0,0,,,0,0,0,0,,,0,0,0,0,,,0,0,0,0,AAPL
2024-10-22 13:15:02.410203078+00:00,10,39,38,C,B,0,232.4,2000,130,203850,69850,,236.4,0,2000,0,1,,,0,0,0,0,,,0,0,0,0,,,0,0,0,0,,,0,0,0,0,,,0,0,0,0,,,0,0,0,0,,,0,0,0,0,,,0,0,0,0,,,0,0,0,0,AAPL
2024-10-22 13:15:02.423224503+00:00,10,39,38,A,B,0,232.2,2000,130,203849,69851,232.2,236.4,2000,2000,1,1,,,0,0,0,0,,,0,0,0,0,,,0,0,0,0,,,0,0,0,0,,,0,0,0,0,,,0,0,0,0,,,0,0,0,0,,,0,0,0,0,,,0,0,0,0,AAPL
2024-10-22 13:15:02.476643689+00:00,10,39,38,C,B,0,232.2,2000,130,203796,69852,,236.4,0,2000,0,1,,,0,0,0,0,,,0,0,0,0,,,0,0,0,0,,,0,0,0,0,,,0,0,0,0,,,0,0,0,0,,,0,0,0,0,,,0,0,0,0,,,0,0,0,0,AAPL
2024-10-22 13:15:02.487626728+00:00,10,39,38,A,B,0,232.0,2000,130,203763,69853,232.0,236.4,2000,2000,1,1,,,0,0,0,0,,,0,0,0,0,,,0,0,0,0,,,0,0,0,0,,,0,0,0,0,,,0,0,0,0,,,0,0,0,0,,,0,0,0,0,,,0,0,0,0,AAPL
2024-10-22 13:15:02.524653852+00:00,10,39,38,A,B,0,232.2,2000,130,203746,69854,232.2,236.4,2000,2000,1,1,232.0,,2000,0,1,0,,,0,0,0,0,,,0,0,0,0,,,0,0,0,0,,,0,0,0,0,,,0,0,0,0,,,0,0,0,0,,,0,0,0,0,,,0,0,0,0,AAPL
2024-10-22 13:15:02.525384531+00:00,10,39,38,C,B,1,232.0,2000,130,203677,69855,232.2,236.4,2000,2000,1,1,,,0,0,0,0,,,0,0,0,0,,,0,0,0,0,,,0,0,0,0,,,0,0,0,0,,,0,0,0,0,,,0,0,0,0,,,0,0,0,0,,,0,0,0,0,AAPL
2024-10-22 13:15:02.681523470+00:00,10,39,38,A,B,0,232.4,2000,130,203921,69856,232.4,236.4,2000,2000,1,1,232.2,,2000,0,1,0,,,0,0,0,0,,,0,0,0,0,,,0,0,0,0,,,0,0,0,0,,,0,0,0,0,,,0,0,0,0,,,0,0,0,0,,,0,0,0,0,AAPL
2024-10-22 13:15:02.681720659+00:00,10,39,38,C,B,1,232.2,2000,130,203692,69857,232.4,236.4,2000,2000,1,1,,,0,0,0,0,,,0,0,0,0,,,0,0,0,0,,,0,0,0,0,,,0,0,0,0,,,0,0,0,0,,,0,0,0,0,,,0,0,0,0,,,0,0,0,0,AAPL
2024-10-22 13:15:04.504877591+00:00,10,40,38,A,A,0,234.5,200,194,202965,118683,233.87,234.5,200,200,0,0,,,0,0,0,0,,,0,0,0,0,,,0,0,0,0,,,0,0,0,0,,,0,0,0,0,,,0,0,0,0,,,0,0,0,0,,,0,0,0,0,,,0,0,0,0,AAPL
2024-10-22 13:15:04.505132909+00:00,10,41,38,A,A,0,234.45,200,194,56076,284388,233.92,234.45,200,200,0,0,,,0,0,0,0,,,0,0,0,0,,,0,0,0,0,,,0,0,0,0,,,0,0,0,0,,,0,0,0,0,,,0,0,0,0,,,0,0,0,0,,,0,0,0,0,AAPL
2024-10-22 13:15:04.693977976+00:00,10,40,38,A,A,0,,0,194,202956,118687,233.87,,200,0,0,0,,,0,0,0,0,,,0,0,0,0,,,0,0,0,0,,,0,0,0,0,,,0,0,0,0,,,0,0,0,0,,,0,0,0,0,,,0,0,0,0,,,0,0,0,0,AAPL
2024-10-22 13:15:04.903776447+00:00,10,41,38,A,A,0,,0,194,55435,284411,233.92,,200,0,0,0,,,0,0,0,0,,,0,0,0,0,,,0,0,0,0,,,0,0,0,0,,,0,0,0,0,,,0,0,0,0,,,0,0,0,0,,,0,0,0,0,,,0,0,0,0,AAPL
2024-10-22 13:15:10.451096221+00:00,10,41,38,A,A,0,234.45,200,194,55551,284823,233.92,234.45,200,200,0,0,,,0,0,0,0,,,0,0,0,0,,,0,0,0,0,,,0,0,0,0,,,0,0,0,0,,,0,0,0,0,,,0,0,0,0,,,0,0,0,0,,,0,0,0,0,AAPL
2024-10-22 13:15:10.956898525+00:00,10,41,38,A,A,0,,0,194,60561,284852,233.92,,200,0,0,0,,,0,0,0,0,,,0,0,0,0,,,0,0,0,0,,,0,0,0,0,,,0,0,0,0,,,0,0,0,0,,,0,0,0,0,,,0,0,0,0,,,0,0,0,0,AAPL
2024-10-22 13:15:14.175687070+00:00,10,41,38,A,A,0,234.45,200,194,60499,285011,233.92,234.45,200,200,0,0,,,0,0,0,0,,,0,0,0,0,,,0,0,0,0,,,0,0,0,0,,,0,0,0,0,,,0,0,0,0,,,0,0,0,0,,,0,0,0,0,,,0,0,0,0,AAPL
2024-10-22 13:15:14.780896527+00:00,10,41,38,A,A,0,,0,194,55383,285036,233.92,,200,0,0,0,,,0,0,0,0,,,0,0,0,0,,,0,0,0,0,,,0,0,0,0,,,0,0,0,0,,,0,0,0,0,,,0,0,0,0,,,0,0,0,0,,,0,0,0,0,AAPL
2024-10-22 13:15:15.937803335+00:00,10,40,38,A,A,0,234.47,200,194,202797,118873,233.87,234.47,200,200,0,0,,,0,0,0,0,,,0,0,0,0,,,0,0,0,0,,,0,0,0,0,,,0,0,0,0,,,0,0,0,0,,,0,0,0,0,,,0,0,0,0,,,0,0,0,0,AAPL
2024-10-22 13:15:15.938060878+00:00,10,41,38,A,A,0,234.42,200,194,55720,285092,233.92,234.42,200,200,0,0,,,0,0,0,0,,,0,0,0,0,,,0,0,0,0,,,0,0,0,0,,,0,0,0,0,,,0,0,0,0,,,0,0,0,0,,,0,0,0,0,,,0,0,0,0,AAPL
2024-10-22 13:15:15.938059476+00:00,10,40,38,A,A,0,,0,194,202793,118874,233.87,,200,0,0,0,,,0,0,0,0,,,0,0,0,0,,,0,0,0,0,,,0,0,0,0,,,0,0,0,0,,,0,0,0,0,,,0,0,0,0,,,0,0,0,0,,,0,0,0,0,AAPL
2024-10-22 13:15:15.949120353+00:00,10,41,38,A,A,0,,0,194,55330,285093,233.92,,200,0,0,0,,,0,0,0,0,,,0,0,0,0,,,0,0,0,0,,,0,0,0,0,,,0,0,0,0,,,0,0,0,0,,,0,0,0,0,,,0,0,0,0,,,0,0,0,0,AAPL
2024-10-22 13:15:16.006261021+00:00,10,39,38,C,A,0,236.4,2000,130,204395,69940,232.4,,2000,0,1,0,,,0,0,0,0,,,0,0,0,0,,,0,0,0,0,,,0,0,0,0,,,0,0,0,0,,,0,0,0,0,,,0,0,0,0,,,0,0,0,0,,,0,0,0,0,AAPL
2024-10-22 13:15:16.106926827+00:00,10,41,38,A,A,0,234.42,200,194,55323,285098,233.92,234.42,200,200,0,0,,,0,0,0,0,,,0,0,0,0,,,0,0,0,0,,,0,0,0,0,,,0,0,0,0,,,0,0,0,0,,,0,0,0,0,,,0,0,0,0,,,0,0,0,0,AAPL
2024-10-22 13:15:16.207719885+00:00,10,41,38,A,A,0,,0,194,55227,285103,233.92,,200,0,0,0,,,0,0,0,0,,,0,0,0,0,,,0,0,0,0,,,0,0,0,0,,,0,0,0,0,,,0,0,0,0,,,0,0,0,0,,,0,0,0,0,,,0,0,0,0,AAPL
2024-10-22 13:15:17.711599088+00:00,10,40,38,A,A,0,234.47,200,194,202929,118891,233.87,234.47,200,200,0,0,,,0,0,0,0,,,0,0,0,0,,,0,0,0,0,,,0,0,0,0,,,0,0,0,0,,,0,0,0,0,,,0,0,0,0,,,0,0,0,0,,,0,0,0,0,AAPL
2024-10-22 13:15:17.712090374+00:00,10,41,38,A,A,0,234.42,200,194,55570,285172,233.92,234.42,200,200,0,0,,,0,0,0,0,,,0,0,0,0,,,0,0,0,0,,,0,0,0,0,,,0,0,0,0,,,0,0,0,0,,,0,0,0,0,,,0,0,0,0,,,0,0,0,0,AAPL
