ts_event,rtype,publisher_id,instrument_id,action,side,depth,price,size,flags,ts_in_delta,sequence,bid_px_00,ask_px_00,bid_sz_00,ask_sz_00,bid_ct_00,ask_ct_00,bid_px_01,ask_px_01,bid_sz_01,ask_sz_01,bid_ct_01,ask_ct_01,bid_px_02,ask_px_02,bid_sz_02,ask_sz_02,bid_ct_02,ask_ct_02,bid_px_03,ask_px_03,bid_sz_03,ask_sz_03,bid_ct_03,ask_ct_03,bid_px_04,ask_px_04,bid_sz_04,ask_sz_04,bid_ct_04,ask_ct_04,bid_px_05,ask_px_05,bid_sz_05,ask_sz_05,bid_ct_05,ask_ct_05,bid_px_06,ask_px_06,bid_sz_06,ask_sz_06,bid_ct_06,ask_ct_06,bid_px_07,ask_px_07,bid_sz_07,ask_sz_07,bid_ct_07,ask_ct_07,bid_px_08,ask_px_08,bid_sz_08,ask_sz_08,bid_ct_08,ask_ct_08,bid_px_09,ask_px_09,bid_sz_09,ask_sz_09,bid_ct_09,ask_ct_09,symbol
2024-10-22 11:00:00.080596024+00:00,10,40,38,A,N,0,235.35,200,194,204069,14968,234.42,235.35,200,200,0,0,,,0,0,0,0,,,0,0,0,0,,,0,0,0,0,,,0,0,0,0,,,0,0,0,0,,,0,0,0,0,,,0,0,0,0,,,0,0,0,0,,,0,0,0,0,AAPL
2024-10-22 11:00:00.618993091+00:00,10,40,38,A,B,0,235.35,200,194,203619,15176,,235.35,0,200,0,0,,,0,0,0,0,,,0,0,0,0,,,0,0,0,0,,,0,0,0,0,,,0,0,0,0,,,0,0,0,0,,,0,0,0,0,,,0,0,0,0,,,0,0,0,0,AAPL
2024-10-22 11:00:00.619013807+00:00,10,40,38,A,B,0,235.35,200,194,203665,15177,234.53,235.35,200,200,0,0,,,0,0,0,0,,,0,0,0,0,,,0,0,0,0,,,0,0,0,0,,,0,0,0,0,,,0,0,0,0,,,0,0,0,0,,,0,0,0,0,,,0,0,0,0,AAPL
2024-10-22 11:00:00.619083616+00:00,10,40,38,A,A,0,,0,194,203583,15178,234.53,,200,0,0,0,,,0,0,0,0,,,0,0,0,0,,,0,0,0,0,,,0,0,0,0,,,0,0,0,0,,,0,0,0,0,,,0,0,0,0,,,0,0,0,0,,,0,0,0,0,AAPL
2024-10-22 11:00:00.619158784+00:00,10,40,38,A,A,0,235.5,200,194,203639,15179,234.53,235.5,200,200,0,0,,,0,0,0,0,,,0,0,0,0,,,0,0,0,0,,,0,0,0,0,,,0,0,0,0,,,0,0,0,0,,,0,0,0,0,,,0,0,0,0,,,0,0,0,0,AAPL
2024-10-22 11:00:00.619198798+00:00,10,40,38,A,B,0,235.5,200,194,203610,15180,,235.5,0,200,0,0,,,0,0,0,0,,,0,0,0,0,,,0,0,0,0,,,0,0,0,0,,,0,0,0,0,,,0,0,0,0,,,0,0,0,0,,,0,0,0,0,,,0,0,0,0,AAPL
2024-10-22 11:00:00.619307396+00:00,10,40,38,A,A,0,,0,194,203610,15181,,,0,0,0,0,,,0,0,0,0,,,0,0,0,0,,,0,0,0,0,,,0,0,0,0,,,0,0,0,0,,,0,0,0,0,,,0,0,0,0,,,0,0,0,0,,,0,0,0,0,AAPL
2024-10-22 11:00:01.000910982+00:00,10,40,38,A,A,0,235.5,200,194,203388,15233,,235.5,0,200,0,0,,,0,0,0,0,,,0,0,0,0,,,0,0,0,0,,,0,0,0,0,,,0,0,0,0,,,0,0,0,0,,,0,0,0,0,,,0,0,0,0,,,0,0,0,0,AAPL
2024-10-22 11:00:01.001016625+00:00,10,40,38,A,B,0,235.5,200,194,203317,15234,234.57,235.5,200,200,0,0,,,0,0,0,0,,,0,0,0,0,,,0,0,0,0,,,0,0,0,0,,,0,0,0,0,,,0,0,0,0,,,0,0,0,0,,,0,0,0,0,,,0,0,0,0,AAPL
2024-10-22 11:00:01.007809603+00:00,10,40,38,A,B,0,235.5,200,194,203340,15237,,235.5,0,200,0,0,,,0,0,0,0,,,0,0,0,0,,,0,0,0,0,,,0,0,0,0,,,0,0,0,0,,,0,0,0,0,,,0,0,0,0,,,0,0,0,0,,,0,0,0,0,AAPL
2024-10-22 11:00:01.007881646+00:00,10,40,38,A,A,0,,0,194,203328,15238,,,0,0,0,0,,,0,0,0,0,,,0,0,0,0,,,0,0,0,0,,,0,0,0,0,,,0,0,0,0,,,0,0,0,0,,,0,0,0,0,,,0,0,0,0,,,0,0,0,0,AAPL
2024-10-22 11:00:01.151304760+00:00,10,40,38,A,B,0,,0,194,203376,15256,234.58,,200,0,0,0,,,0,0,0,0,,,0,0,0,0,,,0,0,0,0,,,0,0,0,0,,,0,0,0,0,,,0,0,0,0,,,0,0,0,0,,,0,0,0,0,,,0,0,0,0,AAPL
2024-10-22 11:00:01.151311188+00:00,10,40,38,A,A,0,235.5,200,194,203417,15257,234.58,235.5,200,200,0,0,,,0,0,0,0,,,0,0,0,0,,,0,0,0,0,,,0,0,0,0,,,0,0,0,0,,,0,0,0,0,,,0,0,0,0,,,0,0,0,0,,,0,0,0,0,AAPL
2024-10-22 11:00:01.263405879+00:00,10,40,38,A,A,0,,0,194,203371,15270,234.58,,200,0,0,0,,,0,0,0,0,,,0,0,0,0,,,0,0,0,0,,,0,0,0,0,,,0,0,0,0,,,0,0,0,0,,,0,0,0,0,,,0,0,0,0,,,0,0,0,0,AAPL
2024-10-22 11:00:01.263509637+00:00,10,40,38,A,B,0,,0,194,203353,15271,,,0,0,0,0,,,0,0,0,0,,,0,0,0,0,,,0,0,0,0,,,0,0,0,0,,,0,0,0,0,,,0,0,0,0,,,0,0,0,0,,,0,0,0,0,,,0,0,0,0,AAPL
2024-10-22 11:00:01.674317047+00:00,10,40,38,A,B,0,,0,194,203395,15309,234.58,,200,0,0,0,,,0,0,0,0,,,0,0,0,0,,,0,0,0,0,,,0,0,0,0,,,0,0,0,0,,,0,0,0,0,,,0,0,0,0,,,0,0,0,0,,,0,0,0,0,AAPL
2024-10-22 11:00:01.674322513+00:00,10,40,38,A,A,0,235.5,200,194,203375,15310,234.58,235.5,200,200,0,0,,,0,0,0,0,,,0,0,0,0,,,0,0,0,0,,,0,0,0,0,,,0,0,0,0,,,0,0,0,0,,,0,0,0,0,,,0,0,0,0,,,0,0,0,0,AAPL
2024-10-22 11:00:01.804888952+00:00,10,40,38,A,A,0,,0,194,203389,15321,234.58,,200,0,0,0,,,0,0,0,0,,,0,0,0,0,,,0,0,0,0,,,0,0,0,0,,,0,0,0,0,,,0,0,0,0,,,0,0,0,0,,,0,0,0,0,,,0,0,0,0,AAPL
2024-10-22 11:00:01.805031498+00:00,10,40,38,A,B,0,,0,194,203382,15322,,,0,0,0,0,,,0,0,0,0,,,0,0,0,0,,,0,0,0,0,,,0,0,0,0,,,0,0,0,0,,,0,0,0,0,,,0,0,0,0,,,0,0,0,0,,,0,0,0,0,AAPL
2024-10-22 11:00:03.114927093+00:00,10,40,38,A,B,0,,0,194,203638,15368,234.57,,200,0,0,0,,,0,0,0,0,,,0,0,0,0,,,0,0,0,0,,,0,0,0,0,,,0,0,0,0,,,0,0,0,0,,,0,0,0,0,,,0,0,0,0,,,0,0,0,0,AAPL
2024-10-22 11:00:03.115030904+00:00,10,40,38,A,A,0,235.49,200,194,203599,15369,234.57,235.49,200,200,0,0,,,0,0,0,0,,,0,0,0,0,,,0,0,0,0,,,0,0,0,0,,,0,0,0,0,,,0,0,0,0,,,0,0,0,0,,,0,0,0,0,,,0,0,0,0,AAPL
2024-10-22 11:00:03.244953276+00:00,10,40,38,A,A,0,,0,194,203724,15374,234.57,,200,0,0,0,,,0,0,0,0,,,0,0,0,0,,,0,0,0,0,,,0,0,0,0,,,0,0,0,0,,,0,0,0,0,,,0,0,0,0,,,0,0,0,0,,,0,0,0,0,AAPL
2024-10-22 11:00:03.245093987+00:00,10,40,38,A,B,0,,0,194,203609,15375,,,0,0,0,0,,,0,0,0,0,,,0,0,0,0,,,0,0,0,0,,,0,0,0,0,,,0,0,0,0,,,0,0,0,0,,,0,0,0,0,,,0,0,0,0,,,0,0,0,0,AAPL
2024-10-22 11:00:07.358785225+00:00,10,40,38,A,B,0,,0,194,203918,15536,234.57,,200,0,0,0,,,0,0,0,0,,,0,0,0,0,,,0,0,0,0,,,0,0,0,0,,,0,0,0,0,,,0,0,0,0,,,0,0,0,0,,,0,0,0,0,,,0,0,0,0,AAPL
2024-10-22 11:00:07.358793011+00:00,10,40,38,A,A,0,235.5,200,194,203946,15537,234.57,235.5,200,200,0,0,,,0,0,0,0,,,0,0,0,0,,,0,0,0,0,,,0,0,0,0,,,0,0,0,0,,,0,0,0,0,,,0,0,0,0,,,0,0,0,0,,,0,0,0,0,AAPL
2024-10-22 11:00:07.480123302+00:00,10,40,38,A,A,0,,0,194,204049,15544,234.57,,200,0,0,0,,,0,0,0,0,,,0,0,0,0,,,0,0,0,0,,,0,0,0,0,,,0,0,0,0,,,0,0,0,0,,,0,0,0,0,,,0,0,0,0,,,0,0,0,0,AAPL
2024-10-22 11:00:07.480268830+00:00,10,40,38,A,B,0,,0,194,203918,15545,,,0,0,0,0,,,0,0,0,0,,,0,0,0,0,,,0,0,0,0,,,0,0,0,0,,,0,0,0,0,,,0,0,0,0,,,0,0,0,0,,,0,0,0,0,,,0,0,0,0,AAPL
2024-10-22 11:00:17.335166279+00:00,10,40,38,A,B,0,,0,194,204001,15808,234.57,,200,0,0,0,,,0,0,0,0,,,0,0,0,0,,,0,0,0,0,,,0,0,0,0,,,0,0,0,0,,,0,0,0,0,,,0,0,0,0,,,0,0,0,0,,,0,0,0,0,AAPL
2024-10-22 11:00:17.335172335+00:00,10,40,38,A,A,0,235.51,200,194,203972,15809,234.57,235.51,200,200,0,0,,,0,0,0,0,,,0,0,0,0,,,0,0,0,0,,,0,0,0,0,,,0,0,0,0,,,0,0,0,0,,,0,0,0,0,,,0,0,0,0,,,0,0,0,0,AAPL
2024-10-22 11:00:17.454603502+00:00,10,40,38,A,B,0,235.51,200,194,203973,15834,,235.51,0,200,0,0,,,0,0,0,0,,,0,0,0,0,,,0,0,0,0,,,0,0,0,0,,,0,0,0,0,,,0,0,0,0,,,0,0,0,0,,,0,0,0,0,,,0,0,0,0,AAPL
2024-10-22 11:00:20.884878106+00:00,10,40,38,A,A,0,,0,194,204001,15898,,,0,0,0,0,,,0,0,0,0,,,0,0,0,0,,,0,0,0,0,,,0,0,0,0,,,0,0,0,0,,,0,0,0,0,,,0,0,0,0,,,0,0,0,0,,,0,0,0,0,AAPL
2024-10-22 11:00:21.689777015+00:00,10,40,38,A,A,0,235.51,200,194,203895,15907,,235.51,0,200,0,0,,,0,0,0,0,,,0,0,0,0,,,0,0,0,0,,,0,0,0,0,,,0,0,0,0,,,0,0,0,0,,,0,0,0,0,,,0,0,0,0,,,0,0,0,0,AAPL
2024-10-22 11:00:22.080881068+00:00,10,40,38,A,A,0,,0,194,203843,15915,,,0,0,0,0,,,0,0,0,0,,,0,0,0,0,,,0,0,0,0,,,0,0,0,0,,,0,0,0,0,,,0,0,0,0,,,0,0,0,0,,,0,0,0,0,,,0,0,0,0,AAPL
2024-10-22 11:00:22.322991748+00:00,10,40,38,A,A,0,235.51,200,194,203855,15927,,235.51,0,200,0,0,,,0,0,0,0,,,0,0,0,0,,,0,0,0,0,,,0,0,0,0,,,0,0,0,0,,,0,0,0,0,,,0,0,0,0,,,0,0,0,0,,,0,0,0,0,AAPL
2024-10-22 11:00:22.323091453+00:00,10,40,38,A,B,0,235.51,200,194,203842,15928,234.59,235.51,200,200,0,0,,,0,0,0,0,,,0,0,0,0,,,0,0,0,0,,,0,0,0,0,,,0,0,0,0,,,0,0,0,0,,,0,0,0,0,,,0,0,0,0,,,0,0,0,0,AAPL
2024-10-22 11:00:24.106032189+00:00,10,40,38,A,B,0,235.51,200,194,203968,15990,,235.51,0,200,0,0,,,0,0,0,0,,,0,0,0,0,,,0,0,0,0,,,0,0,0,0,,,0,0,0,0,,,0,0,0,0,,,0,0,0,0,,,0,0,0,0,,,0,0,0,0,AAPL
2024-10-22 11:00:24.715155560+00:00,10,40,38,A,A,0,,0,194,204150,16003,,,0,0,0,0,,,0,0,0,0,,,0,0,0,0,,,0,0,0,0,,,0,0,0,0,,,0,0,0,0,,,0,0,0,0,,,0,0,0,0,,,0,0,0,0,,,0,0,0,0,AAPL
2024-10-22 11:00:29.199296012+00:00,10,40,38,A,B,0,,0,194,204104,16112,234.59,,200,0,0,0,,,0,0,0,0,,,0,0,0,0,,,0,0,0,0,,,0,0,0,0,,,0,0,0,0,,,0,0,0,0,,,0,0,0,0,,,0,0,0,0,,,0,0,0,0,AAPL
2024-10-22 11:00:29.199421377+00:00,10,40,38,A,A,0,235.51,200,194,204071,16113,234.59,235.51,200,200,0,0,,,0,0,0,0,,,0,0,0,0,,,0,0,0,0,,,0,0,0,0,,,0,0,0,0,,,0,0,0,0,,,0,0,0,0,,,0,0,0,0,,,0,0,0,0,AAPL
2024-10-22 11:00:29.702949298+00:00,10,40,38,A,A,0,,0,194,204128,16125,234.59,,200,0,0,0,,,0,0,0,0,,,0,0,0,0,,,0,0,0,0,,,0,0,0,0,,,0,0,0,0,,,0,0,0,0,,,0,0,0,0,,,0,0,0,0,,,0,0,0,0,AAPL
2024-10-22 11:00:36.498813469+00:00,10,40,38,A,A,0,235.51,200,194,204105,16246,234.59,235.51,200,200,0,0,,,0,0,0,0,,,0,0,0,0,,,0,0,0,0,,,0,0,0,0,,,0,0,0,0,,,0,0,0,0,,,0,0,0,0,,,0,0,0,0,,,0,0,0,0,AAPL
2024-10-22 11:00:36.646371567+00:00,10,40,38,A,B,0,235.51,200,194,204057,16249,,235.51,0,200,0,0,,,0,0,0,0,,,0,0,0,0,,,0,0,0,0,,,0,0,0,0,,,0,0,0,0,,,0,0,0,0,,,0,0,0,0,,,0,0,0,0,,,0,0,0,0,AAPL
2024-10-22 11:00:36.646386247+00:00,10,40,38,A,B,0,235.51,200,194,204007,16250,234.57,235.51,200,200,0,0,,,0,0,0,0,,,0,0,0,0,,,0,0,0,0,,,0,0,0,0,,,0,0,0,0,,,0,0,0,0,,,0,0,0,0,,,0,0,0,0,,,0,0,0,0,AAPL
2024-10-22 11:00:36.746840556+00:00,10,40,38,A,B,0,235.51,200,194,204109,16251,,235.51,0,200,0,0,,,0,0,0,0,,,0,0,0,0,,,0,0,0,0,,,0,0,0,0,,,0,0,0,0,,,0,0,0,0,,,0,0,0,0,,,0,0,0,0,,,0,0,0,0,AAPL
2024-10-22 11:00:37.653791819+00:00,10,40,38,A,A,0,,0,194,204118,16261,,,0,0,0,0,,,0,0,0,0,,,0,0,0,0,,,0,0,0,0,,,0,0,0,0,,,0,0,0,0,,,0,0,0,0,,,0,0,0,0,,,0,0,0,0,,,0,0,0,0,AAPL
2024-10-22 11:00:38.412745571+00:00,10,40,38,A,N,0,235.51,200,194,204159,16274,234.62,235.51,200,200,0,0,,,0,0,0,0,,,0,0,0,0,,,0,0,0,0,,,0,0,0,0,,,0,0,0,0,,,0,0,0,0,,,0,0,0,0,,,0,0,0,0,,,0,0,0,0,AAPL
2024-10-22 11:00:42.275248322+00:00,10,40,38,A,B,0,235.51,200,194,203764,16360,,235.51,0,200,0,0,,,0,0,0,0,,,0,0,0,0,,,0,0,0,0,,,0,0,0,0,,,0,0,0,0,,,0,0,0,0,,,0,0,0,0,,,0,0,0,0,,,0,0,0,0,AAPL
2024-10-22 11:00:49.081224415+00:00,10,40,38,A,A,0,,0,194,203201,16438,,,0,0,0,0,,,0,0,0,0,,,0,0,0,0,,,0,0,0,0,,,0,0,0,0,,,0,0,0,0,,,0,0,0,0,,,0,0,0,0,,,0,0,0,0,,,0,0,0,0,AAPL
2024-10-22 11:00:49.081319895+00:00,10,40,38,A,A,0,235.51,200,194,203150,16439,,235.51,0,200,0,0,,,0,0,0,0,,,0,0,0,0,,,0,0,0,0,,,0,0,0,0,,,0,0,0,0,,,0,0,0,0,,,0,0,0,0,,,0,0,0,0,,,0,0,0,0,AAPL
2024-10-22 11:00:49.081455818+00:00,10,40,38,A,B,0,235.51,200,194,203101,16440,234.57,235.51,200,200,0,0,,,0,0,0,0,,,0,0,0,0,,,0,0,0,0,,,0,0,0,0,,,0,0,0,0,,,0,0,0,0,,,0,0,0,0,,,0,0,0,0,,,0,0,0,0,AAPL
2024-10-22 11:00:49.646329167+00:00,10,40,38,A,B,0,235.51,200,194,203034,16453,,235.51,0,200,0,0,,,0,0,0,0,,,0,0,0,0,,,0,0,0,0,,,0,0,0,0,,,0,0,0,0,,,0,0,0,0,,,0,0,0,0,,,0,0,0,0,,,0,0,0,0,AAPL
2024-10-22 11:00:49.977569659+00:00,10,40,38,A,A,0,,0,194,203039,16455,,,0,0,0,0,,,0,0,0,0,,,0,0,0,0,,,0,0,0,0,,,0,0,0,0,,,0,0,0,0,,,0,0,0,0,,,0,0,0,0,,,0,0,0,0,,,0,0,0,0,AAPL
2024-10-22 11:00:49.979432925+00:00,10,40,38,A,A,0,235.51,200,194,203048,16457,,235.51,0,200,0,0,,,0,0,0,0,,,0,0,0,0,,,0,0,0,0,,,0,0,0,0,,,0,0,0,0,,,0,0,0,0,,,0,0,0,0,,,0,0,0,0,,,0,0,0,0,AAPL
2024-10-22 11:00:49.979511798+00:00,10,40,38,A,B,0,235.51,200,194,203017,16458,234.57,235.51,200,200,0,0,,,0,0,0,0,,,0,0,0,0,,,0,0,0,0,,,0,0,0,0,,,0,0,0,0,,,0,0,0,0,,,0,0,0,0,,,0,0,0,0,,,0,0,0,0,AAPL
2024-10-22 11:00:50.087991023+00:00,10,40,38,A,N,0,,0,194,203327,16463,,,0,0,0,0,,,0,0,0,0,,,0,0,0,0,,,0,0,0,0,,,0,0,0,0,,,0,0,0,0,,,0,0,0,0,,,0,0,0,0,,,0,0,0,0,,,0,0,0,0,AAPL
2024-10-22 11:00:55.111089527+00:00,10,40,38,A,B,0,,0,194,202914,16511,234.57,,200,0,0,0,,,0,0,0,0,,,0,0,0,0,,,0,0,0,0,,,0,0,0,0,,,0,0,0,0,,,0,0,0,0,,,0,0,0,0,,,0,0,0,0,,,0,0,0,0,AAPL
2024-10-22 11:00:55.111096267+00:00,10,40,38,A,A,0,235.51,200,194,202928,16512,234.57,235.51,200,200,0,0,,,0,0,0,0,,,0,0,0,0,,,0,0,0,0,,,0,0,0,0,,,0,0,0,0,,,0,0,0,0,,,0,0,0,0,,,0,0,0,0,,,0,0,0,0,AAPL
2024-10-22 11:02:01.143763912+00:00,10,40,38,A,B,0,235.51,200,194,203791,17314,,235.51,0,200,0,0,,,0,0,0,0,,,0,0,0,0,,,0,0,0,0,,,0,0,0,0,,,0,0,0,0,,,0,0,0,0,,,0,0,0,0,,,0,0,0,0,,,0,0,0,0,AAPL
2024-10-22 11:02:01.143779303+00:00,10,40,38,A,B,0,235.51,200,194,203739,17315,234.62,235.51,200,200,0,0,,,0,0,0,0,,,0,0,0,0,,,0,0,0,0,,,0,0,0,0,,,0,0,0,0,,,0,0,0,0,,,0,0,0,0,,,0,0,0,0,,,0,0,0,0,AAPL
2024-10-22 11:03:00.026588686+00:00,10,40,38,A,B,0,235.51,200,194,202254,17899,,235.51,0,200,0,0,,,0,0,0,0,,,0,0,0,0,,,0,0,0,0,,,0,0,0,0,,,0,0,0,0,,,0,0,0,0,,,0,0,0,0,,,0,0,0,0,,,0,0,0,0,AAPL
2024-10-22 11:03:00.026614726+00:00,10,40,38,A,B,0,235.51,200,194,202211,17900,234.68,235.51,200,200,0,0,,,0,0,0,0,,,0,0,0,0,,,0,0,0,0,,,0,0,0,0,,,0,0,0,0,,,0,0,0,0,,,0,0,0,0,,,0,0,0,0,,,0,0,0,0,AAPL
2024-10-22 11:05:13.568780554+00:00,10,40,38,A,A,0,,0,194,204230,19302,234.68,,200,0,0,0,,,0,0,0,0,,,0,0,0,0,,,0,0,0,0,,,0,0,0,0,,,0,0,0,0,,,0,0,0,0,,,0,0,0,0,,,0,0,0,0,,,0,0,0,0,AAPL
2024-10-22 11:05:13.568805608+00:00,10,40,38,A,A,0,235.54,200,194,204121,19303,234.68,235.54,200,200,0,0,,,0,0,0,0,,,0,0,0,0,,,0,0,0,0,,,0,0,0,0,,,0,0,0,0,,,0,0,0,0,,,0,0,0,0,,,0,0,0,0,,,0,0,0,0,AAPL
2024-10-22 11:05:13.568861294+00:00,10,40,38,A,B,0,235.54,200,194,204131,19304,,235.54,0,200,0,0,,,0,0,0,0,,,0,0,0,0,,,0,0,0,0,,,0,0,0,0,,,0,0,0,0,,,0,0,0,0,,,0,0,0,0,,,0,0,0,0,,,0,0,0,0,AAPL
2024-10-22 11:05:13.568936034+00:00,10,40,38,A,B,0,235.54,200,194,204208,19305,234.67,235.54,200,200,0,0,,,0,0,0,0,,,0,0,0,0,,,0,0,0,0,,,0,0,0,0,,,0,0,0,0,,,0,0,0,0,,,0,0,0,0,,,0,0,0,0,,,0,0,0,0,AAPL
2024-10-22 11:05:13.568979165+00:00,10,40,38,A,A,0,,0,194,204138,19306,234.67,,200,0,0,0,,,0,0,0,0,,,0,0,0,0,,,0,0,0,0,,,0,0,0,0,,,0,0,0,0,,,0,0,0,0,,,0,0,0,0,,,0,0,0,0,,,0,0,0,0,AAPL
2024-10-22 11:05:13.569074239+00:00,10,40,38,A,B,0,,0,194,204109,19307,,,0,0,0,0,,,0,0,0,0,,,0,0,0,0,,,0,0,0,0,,,0,0,0,0,,,0,0,0,0,,,0,0,0,0,,,0,0,0,0,,,0,0,0,0,,,0,0,0,0,AAPL
2024-10-22 11:05:15.321085820+00:00,10,40,38,A,B,0,,0,194,204402,19323,234.67,,200,0,0,0,,,0,0,0,0,,,0,0,0,0,,,0,0,0,0,,,0,0,0,0,,,0,0,0,0,,,0,0,0,0,,,0,0,0,0,,,0,0,0,0,,,0,0,0,0,AAPL
2024-10-22 11:05:15.321098201+00:00,10,40,38,A,A,0,235.57,200,194,204297,19324,234.67,235.57,200,200,0,0,,,0,0,0,0,,,0,0,0,0,,,0,0,0,0,,,0,0,0,0,,,0,0,0,0,,,0,0,0,0,,,0,0,0,0,,,0,0,0,0,,,0,0,0,0,AAPL
2024-10-22 11:06:19.637998303+00:00,10,40,38,A,N,0,,0,194,204327,19883,,,0,0,0,0,,,0,0,0,0,,,0,0,0,0,,,0,0,0,0,,,0,0,0,0,,,0,0,0,0,,,0,0,0,0,,,0,0,0,0,,,0,0,0,0,,,0,0,0,0,AAPL
2024-10-22 11:06:24.689760482+00:00,10,40,38,A,B,0,,0,194,204168,19915,234.67,,200,0,0,0,,,0,0,0,0,,,0,0,0,0,,,0,0,0,0,,,0,0,0,0,,,0,0,0,0,,,0,0,0,0,,,0,0,0,0,,,0,0,0,0,,,0,0,0,0,AAPL
2024-10-22 11:06:24.689769115+00:00,10,40,38,A,A,0,235.58,200,194,203885,19916,234.67,235.58,200,200,0,0,,,0,0,0,0,,,0,0,0,0,,,0,0,0,0,,,0,0,0,0,,,0,0,0,0,,,0,0,0,0,,,0,0,0,0,,,0,0,0,0,,,0,0,0,0,AAPL
2024-10-22 11:07:09.387222517+00:00,10,39,38,A,A,0,237.4,2000,130,203623,17945,,237.4,0,2000,0,1,,,0,0,0,0,,,0,0,0,0,,,0,0,0,0,,,0,0,0,0,,,0,0,0,0,,,0,0,0,0,,,0,0,0,0,,,0,0,0,0,,,0,0,0,0,AAPL
2024-10-22 11:07:09.401471121+00:00,10,39,38,A,A,0,237.2,2000,130,203698,17946,,237.2,0,2000,0,1,,237.4,0,2000,0,1,,,0,0,0,0,,,0,0,0,0,,,0,0,0,0,,,0,0,0,0,,,0,0,0,0,,,0,0,0,0,,,0,0,0,0,,,0,0,0,0,AAPL
2024-10-22 11:07:09.401476728+00:00,10,39,38,A,B,0,232.8,2000,130,203681,17947,232.8,237.2,2000,2000,1,1,,237.4,0,2000,0,1,,,0,0,0,0,,,0,0,0,0,,,0,0,0,0,,,0,0,0,0,,,0,0,0,0,,,0,0,0,0,,,0,0,0,0,,,0,0,0,0,AAPL
2024-10-22 11:07:09.401504437+00:00,10,39,38,C,A,1,237.4,2000,130,203573,17948,232.8,237.2,2000,2000,1,1,,,0,0,0,0,,,0,0,0,0,,,0,0,0,0,,,0,0,0,0,,,0,0,0,0,,,0,0,0,0,,,0,0,0,0,,,0,0,0,0,,,0,0,0,0,AAPL
2024-10-22 11:07:09.447345210+00:00,10,39,38,C,B,0,232.8,2000,130,203613,17951,,237.2,0,2000,0,1,,,0,0,0,0,,,0,0,0,0,,,0,0,0,0,,,0,0,0,0,,,0,0,0,0,,,0,0,0,0,,,0,0,0,0,,,0,0,0,0,,,0,0,0,0,AAPL
2024-10-22 11:07:09.547851429+00:00,10,39,38,A,B,0,232.8,2000,130,203544,17956,232.8,237.2,2000,2000,1,1,,,0,0,0,0,,,0,0,0,0,,,0,0,0,0,,,0,0,0,0,,,0,0,0,0,,,0,0,0,0,,,0,0,0,0,,,0,0,0,0,,,0,0,0,0,AAPL
2024-10-22 11:08:00.011718643+00:00,10,40,38,A,B,0,235.58,200,194,203358,20795,,235.58,0,200,0,0,,,0,0,0,0,,,0,0,0,0,,,0,0,0,0,,,0,0,0,0,,,0,0,0,0,,,0,0,0,0,,,0,0,0,0,,,0,0,0,0,,,0,0,0,0,AAPL
2024-10-22 11:08:00.221502537+00:00,10,40,38,A,B,0,235.58,200,194,203356,20833,234.67,235.58,200,200,0,0,,,0,0,0,0,,,0,0,0,0,,,0,0,0,0,,,0,0,0,0,,,0,0,0,0,,,0,0,0,0,,,0,0,0,0,,,0,0,0,0,,,0,0,0,0,AAPL
2024-10-22 11:08:40.364769167+00:00,10,39,38,C,B,0,232.8,2000,130,204809,18531,,237.2,0,2000,0,1,,,0,0,0,0,,,0,0,0,0,,,0,0,0,0,,,0,0,0,0,,,0,0,0,0,,,0,0,0,0,,,0,0,0,0,,,0,0,0,0,,,0,0,0,0,AAPL
2024-10-22 11:08:40.401602703+00:00,10,39,38,A,B,0,232.8,2000,130,204109,18532,232.8,237.2,2000,2000,1,1,,,0,0,0,0,,,0,0,0,0,,,0,0,0,0,,,0,0,0,0,,,0,0,0,0,,,0,0,0,0,,,0,0,0,0,,,0,0,0,0,,,0,0,0,0,AAPL
2024-10-22 11:09:05.957922828+00:00,10,39,38,C,B,0,232.8,2000,130,203726,18648,,237.2,0,2000,0,1,,,0,0,0,0,,,0,0,0,0,,,0,0,0,0,,,0,0,0,0,,,0,0,0,0,,,0,0,0,0,,,0,0,0,0,,,0,0,0,0,,,0,0,0,0,AAPL
2024-10-22 11:09:05.993858908+00:00,10,39,38,A,B,0,232.8,2000,130,203765,18650,232.8,237.2,2000,2000,1,1,,,0,0,0,0,,,0,0,0,0,,,0,0,0,0,,,0,0,0,0,,,0,0,0,0,,,0,0,0,0,,,0,0,0,0,,,0,0,0,0,,,0,0,0,0,AAPL
2024-10-22 11:09:16.685370764+00:00,10,39,38,C,B,0,232.8,2000,130,203325,18696,,237.2,0,2000,0,1,,,0,0,0,0,,,0,0,0,0,,,0,0,0,0,,,0,0,0,0,,,0,0,0,0,,,0,0,0,0,,,0,0,0,0,,,0,0,0,0,,,0,0,0,0,AAPL
2024-10-22 11:09:21.768053645+00:00,10,40,38,A,N,0,,0,194,204061,21422,,,0,0,0,0,,,0,0,0,0,,,0,0,0,0,,,0,0,0,0,,,0,0,0,0,,,0,0,0,0,,,0,0,0,0,,,0,0,0,0,,,0,0,0,0,,,0,0,0,0,AAPL
2024-10-22 11:09:26.784175977+00:00,10,40,38,A,B,0,,0,194,204022,21479,234.62,,200,0,0,0,,,0,0,0,0,,,0,0,0,0,,,0,0,0,0,,,0,0,0,0,,,0,0,0,0,,,0,0,0,0,,,0,0,0,0,,,0,0,0,0,,,0,0,0,0,AAPL
2024-10-22 11:09:26.784184433+00:00,10,40,38,A,A,0,235.55,200,194,203637,21480,234.62,235.55,200,200,0,0,,,0,0,0,0,,,0,0,0,0,,,0,0,0,0,,,0,0,0,0,,,0,0,0,0,,,0,0,0,0,,,0,0,0,0,,,0,0,0,0,,,0,0,0,0,AAPL
2024-10-22 11:09:39.426491343+00:00,10,39,38,A,B,0,232.8,2000,130,204064,18819,232.8,237.2,2000,2000,1,1,,,0,0,0,0,,,0,0,0,0,,,0,0,0,0,,,0,0,0,0,,,0,0,0,0,,,0,0,0,0,,,0,0,0,0,,,0,0,0,0,,,0,0,0,0,AAPL
2024-10-22 11:09:58.756706189+00:00,10,39,38,C,B,0,232.8,2000,130,204089,18913,,237.2,0,2000,0,1,,,0,0,0,0,,,0,0,0,0,,,0,0,0,0,,,0,0,0,0,,,0,0,0,0,,,0,0,0,0,,,0,0,0,0,,,0,0,0,0,,,0,0,0,0,AAPL
2024-10-22 11:09:58.887883382+00:00,10,39,38,A,B,0,232.6,2000,130,203979,18914,232.6,237.2,2000,2000,1,1,,,0,0,0,0,,,0,0,0,0,,,0,0,0,0,,,0,0,0,0,,,0,0,0,0,,,0,0,0,0,,,0,0,0,0,,,0,0,0,0,,,0,0,0,0,AAPL
2024-10-22 11:10:00.064688727+00:00,10,40,38,A,B,0,235.55,200,194,204629,21779,,235.55,0,200,0,0,,,0,0,0,0,,,0,0,0,0,,,0,0,0,0,,,0,0,0,0,,,0,0,0,0,,,0,0,0,0,,,0,0,0,0,,,0,0,0,0,,,0,0,0,0,AAPL
2024-10-22 11:10:00.971694856+00:00,10,40,38,A,A,0,,0,194,204691,21854,,,0,0,0,0,,,0,0,0,0,,,0,0,0,0,,,0,0,0,0,,,0,0,0,0,,,0,0,0,0,,,0,0,0,0,,,0,0,0,0,,,0,0,0,0,,,0,0,0,0,AAPL
2024-10-22 11:10:00.971715722+00:00,10,40,38,A,A,0,235.51,200,194,204696,21855,,235.51,0,200,0,0,,,0,0,0,0,,,0,0,0,0,,,0,0,0,0,,,0,0,0,0,,,0,0,0,0,,,0,0,0,0,,,0,0,0,0,,,0,0,0,0,,,0,0,0,0,AAPL
2024-10-22 11:10:03.166699305+00:00,10,40,38,A,B,0,235.51,200,194,204651,21910,234.57,235.51,200,200,0,0,,,0,0,0,0,,,0,0,0,0,,,0,0,0,0,,,0,0,0,0,,,0,0,0,0,,,0,0,0,0,,,0,0,0,0,,,0,0,0,0,,,0,0,0,0,AAPL
2024-10-22 11:10:03.990917504+00:00,10,40,38,A,B,0,235.51,200,194,204578,21928,,235.51,0,200,0,0,,,0,0,0,0,,,0,0,0,0,,,0,0,0,0,,,0,0,0,0,,,0,0,0,0,,,0,0,0,0,,,0,0,0,0,,,0,0,0,0,,,0,0,0,0,AAPL
2024-10-22 11:10:05.777615729+00:00,10,40,38,A,B,0,235.51,200,194,204719,21944,234.58,235.51,200,200,0,0,,,0,0,0,0,,,0,0,0,0,,,0,0,0,0,,,0,0,0,0,,,0,0,0,0,,,0,0,0,0,,,0,0,0,0,,,0,0,0,0,,,0,0,0,0,AAPL
2024-10-22 11:10:07.313171219+00:00,10,40,38,A,B,0,235.51,200,194,204461,21960,,235.51,0,200,0,0,,,0,0,0,0,,,0,0,0,0,,,0,0,0,0,,,0,0,0,0,,,0,0,0,0,,,0,0,0,0,,,0,0,0,0,,,0,0,0,0,,,0,0,0,0,AAPL
2024-10-22 11:10:10.433062407+00:00,10,40,38,A,B,0,235.51,200,194,204651,21977,234.53,235.51,200,200,0,0,,,0,0,0,0,,,0,0,0,0,,,0,0,0,0,,,0,0,0,0,,,0,0,0,0,,,0,0,0,0,,,0,0,0,0,,,0,0,0,0,,,0,0,0,0,AAPL
2024-10-22 11:10:19.373670750+00:00,10,39,38,A,B,0,232.8,2000,130,203820,19016,232.8,237.2,2000,2000,1,1,232.6,,2000,0,1,0,,,0,0,0,0,,,0,0,0,0,,,0,0,0,0,,,0,0,0,0,,,0,0,0,0,,,0,0,0,0,,,0,0,0,0,,,0,0,0,0,AAPL
2024-10-22 11:10:19.374400844+00:00,10,39,38,C,B,1,232.6,2000,130,203291,19017,232.8,237.2,2000,2000,1,1,,,0,0,0,0,,,0,0,0,0,,,0,0,0,0,,,0,0,0,0,,,0,0,0,0,,,0,0,0,0,,,0,0,0,0,,,0,0,0,0,,,0,0,0,0,AAPL
2024-10-22 11:10:19.427702670+00:00,10,39,38,C,B,0,232.8,2000,130,203324,19018,,237.2,0,2000,0,1,,,0,0,0,0,,,0,0,0,0,,,0,0,0,0,,,0,0,0,0,,,0,0,0,0,,,0,0,0,0,,,0,0,0,0,,,0,0,0,0,,,0,0,0,0,AAPL
2024-10-22 11:10:19.427783090+00:00,10,40,38,A,B,0,235.51,200,194,204372,22052,,235.51,0,200,0,0,,,0,0,0,0,,,0,0,0,0,,,0,0,0,0,,,0,0,0,0,,,0,0,0,0,,,0,0,0,0,,,0,0,0,0,,,0,0,0,0,,,0,0,0,0,AAPL
2024-10-22 11:10:19.439075116+00:00,10,39,38,A,B,0,232.8,2000,130,203318,19019,232.8,237.2,2000,2000,1,1,,,0,0,0,0,,,0,0,0,0,,,0,0,0,0,,,0,0,0,0,,,0,0,0,0,,,0,0,0,0,,,0,0,0,0,,,0,0,0,0,,,0,0,0,0,AAPL
2024-10-22 11:10:20.535097746+00:00,10,40,38,A,B,0,235.51,200,194,204343,22055,234.57,235.51,200,200,0,0,,,0,0,0,0,,,0,0,0,0,,,0,0,0,0,,,0,0,0,0,,,0,0,0,0,,,0,0,0,0,,,0,0,0,0,,,0,0,0,0,,,0,0,0,0,AAPL
2024-10-22 11:10:23.996350276+00:00,10,40,38,A,B,0,235.51,200,194,204207,22101,,235.51,0,200,0,0,,,0,0,0,0,,,0,0,0,0,,,0,0,0,0,,,0,0,0,0,,,0,0,0,0,,,0,0,0,0,,,0,0,0,0,,,0,0,0,0,,,0,0,0,0,AAPL
2024-10-22 11:10:24.761859682+00:00,10,40,38,A,B,0,235.51,200,194,204439,22105,234.59,235.51,200,200,0,0,,,0,0,0,0,,,0,0,0,0,,,0,0,0,0,,,0,0,0,0,,,0,0,0,0,,,0,0,0,0,,,0,0,0,0,,,0,0,0,0,,,0,0,0,0,AAPL
2024-10-22 11:10:27.991710197+00:00,10,40,38,A,B,0,235.51,200,194,203980,22129,,235.51,0,200,0,0,,,0,0,0,0,,,0,0,0,0,,,0,0,0,0,,,0,0,0,0,,,0,0,0,0,,,0,0,0,0,,,0,0,0,0,,,0,0,0,0,,,0,0,0,0,AAPL
2024-10-22 11:10:29.052005806+00:00,10,40,38,A,B,0,235.51,200,194,204094,22143,234.59,235.51,200,200,0,0,,,0,0,0,0,,,0,0,0,0,,,0,0,0,0,,,0,0,0,0,,,0,0,0,0,,,0,0,0,0,,,0,0,0,0,,,0,0,0,0,,,0,0,0,0,AAPL
2024-10-22 11:10:38.020529025+00:00,10,39,38,C,B,0,232.8,2000,130,204001,19098,,237.2,0,2000,0,1,,,0,0,0,0,,,0,0,0,0,,,0,0,0,0,,,0,0,0,0,,,0,0,0,0,,,0,0,0,0,,,0,0,0,0,,,0,0,0,0,,,0,0,0,0,AAPL
2024-10-22 11:10:38.187068924+00:00,10,39,38,A,B,0,232.6,2000,130,203291,19106,232.6,237.2,2000,2000,1,1,,,0,0,0,0,,,0,0,0,0,,,0,0,0,0,,,0,0,0,0,,,0,0,0,0,,,0,0,0,0,,,0,0,0,0,,,0,0,0,0,,,0,0,0,0,AAPL
2024-10-22 11:10:39.337956019+00:00,10,39,38,A,B,0,232.8,2000,130,203386,19147,232.8,237.2,2000,2000,1,1,232.6,,2000,0,1,0,,,0,0,0,0,,,0,0,0,0,,,0,0,0,0,,,0,0,0,0,,,0,0,0,0,,,0,0,0,0,,,0,0,0,0,,,0,0,0,0,AAPL
2024-10-22 11:10:39.338683754+00:00,10,39,38,C,B,1,232.6,2000,130,203294,19148,232.8,237.2,2000,2000,1,1,,,0,0,0,0,,,0,0,0,0,,,0,0,0,0,,,0,0,0,0,,,0,0,0,0,,,0,0,0,0,,,0,0,0,0,,,0,0,0,0,,,0,0,0,0,AAPL
2024-10-22 11:10:48.217984185+00:00,10,39,38,C,B,0,232.8,2000,130,203721,19212,,237.2,0,2000,0,1,,,0,0,0,0,,,0,0,0,0,,,0,0,0,0,,,0,0,0,0,,,0,0,0,0,,,0,0,0,0,,,0,0,0,0,,,0,0,0,0,,,0,0,0,0,AAPL
2024-10-22 11:10:48.386543061+00:00,10,39,38,A,B,0,232.6,2000,130,203307,19215,232.6,237.2,2000,2000,1,1,,,0,0,0,0,,,0,0,0,0,,,0,0,0,0,,,0,0,0,0,,,0,0,0,0,,,0,0,0,0,,,0,0,0,0,,,0,0,0,0,,,0,0,0,0,AAPL
2024-10-22 11:11:02.941598034+00:00,10,39,38,C,B,0,232.6,2000,130,203558,19295,,237.2,0,2000,0,1,,,0,0,0,0,,,0,0,0,0,,,0,0,0,0,,,0,0,0,0,,,0,0,0,0,,,0,0,0,0,,,0,0,0,0,,,0,0,0,0,,,0,0,0,0,AAPL
2024-10-22 11:11:02.952001860+00:00,10,39,38,A,A,0,237.0,2000,130,203183,19296,,237.0,0,2000,0,1,,237.2,0,2000,0,1,,,0,0,0,0,,,0,0,0,0,,,0,0,0,0,,,0,0,0,0,,,0,0,0,0,,,0,0,0,0,,,0,0,0,0,,,0,0,0,0,AAPL
2024-10-22 11:11:02.952193310+00:00,10,39,38,C,A,1,237.2,2000,130,203214,19297,,237.0,0,2000,0,1,,,0,0,0,0,,,0,0,0,0,,,0,0,0,0,,,0,0,0,0,,,0,0,0,0,,,0,0,0,0,,,0,0,0,0,,,0,0,0,0,,,0,0,0,0,AAPL
2024-10-22 11:11:03.086686343+00:00,10,39,38,A,B,0,232.6,2000,130,203378,19299,232.6,237.0,2000,2000,1,1,,,0,0,0,0,,,0,0,0,0,,,0,0,0,0,,,0,0,0,0,,,0,0,0,0,,,0,0,0,0,,,0,0,0,0,,,0,0,0,0,,,0,0,0,0,AAPL
2024-10-22 11:11:11.834329493+00:00,10,39,38,A,B,0,232.8,2000,130,204589,19365,232.8,237.0,2000,2000,1,1,232.6,,2000,0,1,0,,,0,0,0,0,,,0,0,0,0,,,0,0,0,0,,,0,0,0,0,,,0,0,0,0,,,0,0,0,0,,,0,0,0,0,,,0,0,0,0,AAPL
2024-10-22 11:11:11.834507718+00:00,10,39,38,C,B,1,232.6,2000,130,203610,19366,232.8,237.0,2000,2000,1,1,,,0,0,0,0,,,0,0,0,0,,,0,0,0,0,,,0,0,0,0,,,0,0,0,0,,,0,0,0,0,,,0,0,0,0,,,0,0,0,0,,,0,0,0,0,AAPL
2024-10-22 11:11:11.890963490+00:00,10,39,38,C,B,0,232.8,2000,130,203610,19367,,237.0,0,2000,0,1,,,0,0,0,0,,,0,0,0,0,,,0,0,0,0,,,0,0,0,0,,,0,0,0,0,,,0,0,0,0,,,0,0,0,0,,,0,0,0,0,,,0,0,0,0,AAPL
2024-10-22 11:11:11.902515547+00:00,10,39,38,A,B,0,232.8,2000,130,203718,19368,232.8,237.0,2000,2000,1,1,,,0,0,0,0,,,0,0,0,0,,,0,0,0,0,,,0,0,0,0,,,0,0,0,0,,,0,0,0,0,,,0,0,0,0,,,0,0,0,0,,,0,0,0,0,AAPL
2024-10-22 11:11:42.662715595+00:00,10,39,38,C,B,0,232.8,2000,130,203553,19545,,237.0,0,2000,0,1,,,0,0,0,0,,,0,0,0,0,,,0,0,0,0,,,0,0,0,0,,,0,0,0,0,,,0,0,0,0,,,0,0,0,0,,,0,0,0,0,,,0,0,0,0,AAPL
2024-10-22 11:11:42.806940833+00:00,10,39,38,A,B,0,232.6,2000,130,203996,19554,232.6,237.0,2000,2000,1,1,,,0,0,0,0,,,0,0,0,0,,,0,0,0,0,,,0,0,0,0,,,0,0,0,0,,,0,0,0,0,,,0,0,0,0,,,0,0,0,0,,,0,0,0,0,AAPL
2024-10-22 11:11:46.600363969+00:00,10,39,38,C,A,0,237.0,2000,130,204128,19580,232.6,,2000,0,1,0,,,0,0,0,0,,,0,0,0,0,,,0,0,0,0,,,0,0,0,0,,,0,0,0,0,,,0,0,0,0,,,0,0,0,0,,,0,0,0,0,,,0,0,0,0,AAPL
2024-10-22 11:11:46.611238378+00:00,10,39,38,A,A,0,237.2,2000,130,203928,19581,232.6,237.2,2000,2000,1,1,,,0,0,0,0,,,0,0,0,0,,,0,0,0,0,,,0,0,0,0,,,0,0,0,0,,,0,0,0,0,,,0,0,0,0,,,0,0,0,0,,,0,0,0,0,AAPL
2024-10-22 11:12:00.022009826+00:00,10,40,38,A,B,0,235.51,200,194,202650,22998,,235.51,0,200,0,0,,,0,0,0,0,,,0,0,0,0,,,0,0,0,0,,,0,0,0,0,,,0,0,0,0,,,0,0,0,0,,,0,0,0,0,,,0,0,0,0,,,0,0,0,0,AAPL
2024-10-22 11:12:00.421565533+00:00,10,40,38,A,B,0,235.51,200,194,202743,23058,234.52,235.51,200,200,0,0,,,0,0,0,0,,,0,0,0,0,,,0,0,0,0,,,0,0,0,0,,,0,0,0,0,,,0,0,0,0,,,0,0,0,0,,,0,0,0,0,,,0,0,0,0,AAPL
2024-10-22 11:12:30.249158188+00:00,10,39,38,A,A,0,237.0,2000,130,204518,19766,232.6,237.0,2000,2000,1,1,,237.2,0,2000,0,1,,,0,0,0,0,,,0,0,0,0,,,0,0,0,0,,,0,0,0,0,,,0,0,0,0,,,0,0,0,0,,,0,0,0,0,,,0,0,0,0,AAPL
2024-10-22 11:12:30.249362724+00:00,10,39,38,C,A,1,237.2,2000,130,203850,19767,232.6,237.0,2000,2000,1,1,,,0,0,0,0,,,0,0,0,0,,,0,0,0,0,,,0,0,0,0,,,0,0,0,0,,,0,0,0,0,,,0,0,0,0,,,0,0,0,0,,,0,0,0,0,AAPL
2024-10-22 11:12:57.186584859+00:00,10,39,38,A,B,0,232.8,2000,130,203952,19838,232.8,237.0,2000,2000,1,1,232.6,,2000,0,1,0,,,0,0,0,0,,,0,0,0,0,,,0,0,0,0,,,0,0,0,0,,,0,0,0,0,,,0,0,0,0,,,0,0,0,0,,,0,0,0,0,AAPL
2024-10-22 11:12:57.186755764+00:00,10,39,38,C,B,1,232.6,2000,130,203494,19839,232.8,237.0,2000,2000,1,1,,,0,0,0,0,,,0,0,0,0,,,0,0,0,0,,,0,0,0,0,,,0,0,0,0,,,0,0,0,0,,,0,0,0,0,,,0,0,0,0,,,0,0,0,0,AAPL
2024-10-22 11:12:57.354188359+00:00,10,39,38,C,B,0,232.8,2000,130,203406,19840,,237.0,0,2000,0,1,,,0,0,0,0,,,0,0,0,0,,,0,0,0,0,,,0,0,0,0,,,0,0,0,0,,,0,0,0,0,,,0,0,0,0,,,0,0,0,0,,,0,0,0,0,AAPL
2024-10-22 11:12:57.365431081+00:00,10,39,38,A,B,0,232.6,2000,130,203549,19841,232.6,237.0,2000,2000,1,1,,,0,0,0,0,,,0,0,0,0,,,0,0,0,0,,,0,0,0,0,,,0,0,0,0,,,0,0,0,0,,,0,0,0,0,,,0,0,0,0,,,0,0,0,0,AAPL
2024-10-22 11:13:26.955615345+00:00,10,39,38,A,B,0,232.8,2000,130,203032,19995,232.8,237.0,2000,2000,1,1,232.6,,2000,0,1,0,,,0,0,0,0,,,0,0,0,0,,,0,0,0,0,,,0,0,0,0,,,0,0,0,0,,,0,0,0,0,,,0,0,0,0,,,0,0,0,0,AAPL
2024-10-22 11:13:26.956346987+00:00,10,39,38,C,B,1,232.6,2000,130,202952,19996,232.8,237.0,2000,2000,1,1,,,0,0,0,0,,,0,0,0,0,,,0,0,0,0,,,0,0,0,0,,,0,0,0,0,,,0,0,0,0,,,0,0,0,0,,,0,0,0,0,,,0,0,0,0,AAPL
2024-10-22 11:13:34.786162107+00:00,10,39,38,C,A,0,237.0,2000,130,203547,20016,232.8,,2000,0,1,0,,,0,0,0,0,,,0,0,0,0,,,0,0,0,0,,,0,0,0,0,,,0,0,0,0,,,0,0,0,0,,,0,0,0,0,,,0,0,0,0,,,0,0,0,0,AAPL
2024-10-22 11:13:34.822447631+00:00,10,39,38,A,A,0,237.2,2000,130,203468,20017,232.8,237.2,2000,2000,1,1,,,0,0,0,0,,,0,0,0,0,,,0,0,0,0,,,0,0,0,0,,,0,0,0,0,,,0,0,0,0,,,0,0,0,0,,,0,0,0,0,,,0,0,0,0,AAPL
2024-10-22 11:13:34.847885511+00:00,10,39,38,C,B,0,232.8,2000,130,203238,20018,,237.2,0,2000,0,1,,,0,0,0,0,,,0,0,0,0,,,0,0,0,0,,,0,0,0,0,,,0,0,0,0,,,0,0,0,0,,,0,0,0,0,,,0,0,0,0,,,0,0,0,0,AAPL
2024-10-22 11:13:34.859851361+00:00,10,39,38,A,B,0,232.8,2000,130,203223,20019,232.8,237.2,2000,2000,1,1,,,0,0,0,0,,,0,0,0,0,,,0,0,0,0,,,0,0,0,0,,,0,0,0,0,,,0,0,0,0,,,0,0,0,0,,,0,0,0,0,,,0,0,0,0,AAPL
2024-10-22 11:15:01.971263304+00:00,10,40,38,A,B,0,235.51,200,194,204389,24499,,235.51,0,200,0,0,,,0,0,0,0,,,0,0,0,0,,,0,0,0,0,,,0,0,0,0,,,0,0,0,0,,,0,0,0,0,,,0,0,0,0,,,0,0,0,0,,,0,0,0,0,AAPL
2024-10-22 11:15:02.775974681+00:00,10,40,38,A,B,0,235.51,200,194,204187,24501,234.6,235.51,200,200,0,0,,,0,0,0,0,,,0,0,0,0,,,0,0,0,0,,,0,0,0,0,,,0,0,0,0,,,0,0,0,0,,,0,0,0,0,,,0,0,0,0,,,0,0,0,0,AAPL
2024-10-22 11:15:07.943303212+00:00,10,40,38,A,A,0,,0,194,204023,24553,234.6,,200,0,0,0,,,0,0,0,0,,,0,0,0,0,,,0,0,0,0,,,0,0,0,0,,,0,0,0,0,,,0,0,0,0,,,0,0,0,0,,,0,0,0,0,,,0,0,0,0,AAPL
2024-10-22 11:15:08.027682209+00:00,10,40,38,A,A,0,235.51,200,194,204005,24558,234.6,235.51,200,200,0,0,,,0,0,0,0,,,0,0,0,0,,,0,0,0,0,,,0,0,0,0,,,0,0,0,0,,,0,0,0,0,,,0,0,0,0,,,0,0,0,0,,,0,0,0,0,AAPL
2024-10-22 11:15:08.094028606+00:00,10,40,38,A,A,0,,0,194,203872,24561,234.6,,200,0,0,0,,,0,0,0,0,,,0,0,0,0,,,0,0,0,0,,,0,0,0,0,,,0,0,0,0,,,0,0,0,0,,,0,0,0,0,,,0,0,0,0,,,0,0,0,0,AAPL
2024-10-22 11:15:09.409612802+00:00,10,40,38,A,A,0,235.51,200,194,203962,24579,234.6,235.51,200,200,0,0,,,0,0,0,0,,,0,0,0,0,,,0,0,0,0,,,0,0,0,0,,,0,0,0,0,,,0,0,0,0,,,0,0,0,0,,,0,0,0,0,,,0,0,0,0,AAPL
2024-10-22 11:15:25.109007240+00:00,10,39,38,C,B,0,232.8,2000,130,203391,20569,,237.2,0,2000,0,1,,,0,0,0,0,,,0,0,0,0,,,0,0,0,0,,,0,0,0,0,,,0,0,0,0,,,0,0,0,0,,,0,0,0,0,,,0,0,0,0,,,0,0,0,0,AAPL
2024-10-22 11:15:26.872258071+00:00,10,39,38,C,A,0,237.2,2000,130,203920,20577,,,0,0,0,0,,,0,0,0,0,,,0,0,0,0,,,0,0,0,0,,,0,0,0,0,,,0,0,0,0,,,0,0,0,0,,,0,0,0,0,,,0,0,0,0,,,0,0,0,0,AAPL
2024-10-22 11:15:26.882214039+00:00,10,39,38,A,B,0,232.8,2000,130,203416,20578,232.8,,2000,0,1,0,,,0,0,0,0,,,0,0,0,0,,,0,0,0,0,,,0,0,0,0,,,0,0,0,0,,,0,0,0,0,,,0,0,0,0,,,0,0,0,0,,,0,0,0,0,AAPL
2024-10-22 11:15:26.907651573+00:00,10,39,38,A,A,0,237.2,2000,130,203348,20579,232.8,237.2,2000,2000,1,1,,,0,0,0,0,,,0,0,0,0,,,0,0,0,0,,,0,0,0,0,,,0,0,0,0,,,0,0,0,0,,,0,0,0,0,,,0,0,0,0,,,0,0,0,0,AAPL
2024-10-22 11:15:48.575646148+00:00,10,39,38,C,B,0,232.8,2000,130,202949,20639,,237.2,0,2000,0,1,,,0,0,0,0,,,0,0,0,0,,,0,0,0,0,,,0,0,0,0,,,0,0,0,0,,,0,0,0,0,,,0,0,0,0,,,0,0,0,0,,,0,0,0,0,AAPL
2024-10-22 11:15:50.118627675+00:00,10,39,38,A,B,0,232.8,2000,130,203106,20641,232.8,237.2,2000,2000,1,1,,,0,0,0,0,,,0,0,0,0,,,0,0,0,0,,,0,0,0,0,,,0,0,0,0,,,0,0,0,0,,,0,0,0,0,,,0,0,0,0,,,0,0,0,0,AAPL
2024-10-22 11:16:00.034981725+00:00,10,40,38,A,B,0,235.51,200,194,203221,24896,,235.51,0,200,0,0,,,0,0,0,0,,,0,0,0,0,,,0,0,0,0,,,0,0,0,0,,,0,0,0,0,,,0,0,0,0,,,0,0,0,0,,,0,0,0,0,,,0,0,0,0,AAPL
2024-10-22 11:16:00.035179518+00:00,10,40,38,A,A,0,,0,194,203254,24898,,,0,0,0,0,,,0,0,0,0,,,0,0,0,0,,,0,0,0,0,,,0,0,0,0,,,0,0,0,0,,,0,0,0,0,,,0,0,0,0,,,0,0,0,0,,,0,0,0,0,AAPL
2024-10-22 11:16:00.133320362+00:00,10,40,38,A,A,0,235.55,200,194,203210,24917,,235.55,0,200,0,0,,,0,0,0,0,,,0,0,0,0,,,0,0,0,0,,,0,0,0,0,,,0,0,0,0,,,0,0,0,0,,,0,0,0,0,,,0,0,0,0,,,0,0,0,0,AAPL
2024-10-22 11:16:00.133419208+00:00,10,40,38,A,B,0,235.55,200,194,203251,24918,234.65,235.55,200,200,0,0,,,0,0,0,0,,,0,0,0,0,,,0,0,0,0,,,0,0,0,0,,,0,0,0,0,,,0,0,0,0,,,0,0,0,0,,,0,0,0,0,,,0,0,0,0,AAPL
2024-10-22 11:16:00.337393918+00:00,10,40,38,A,B,0,235.55,200,194,203221,24934,,235.55,0,200,0,0,,,0,0,0,0,,,0,0,0,0,,,0,0,0,0,,,0,0,0,0,,,0,0,0,0,,,0,0,0,0,,,0,0,0,0,,,0,0,0,0,,,0,0,0,0,AAPL
2024-10-22 11:16:02.735934453+00:00,10,40,38,A,B,0,235.55,200,194,203340,24961,234.65,235.55,200,200,0,0,,,0,0,0,0,,,0,0,0,0,,,0,0,0,0,,,0,0,0,0,,,0,0,0,0,,,0,0,0,0,,,0,0,0,0,,,0,0,0,0,,,0,0,0,0,AAPL
2024-10-22 11:16:37.521992216+00:00,10,39,38,C,B,0,232.8,2000,130,203853,20934,,237.2,0,2000,0,1,,,0,0,0,0,,,0,0,0,0,,,0,0,0,0,,,0,0,0,0,,,0,0,0,0,,,0,0,0,0,,,0,0,0,0,,,0,0,0,0,,,0,0,0,0,AAPL
2024-10-22 11:16:37.558304777+00:00,10,39,38,A,B,0,232.8,2000,130,203904,20935,232.8,237.2,2000,2000,1,1,,,0,0,0,0,,,0,0,0,0,,,0,0,0,0,,,0,0,0,0,,,0,0,0,0,,,0,0,0,0,,,0,0,0,0,,,0,0,0,0,,,0,0,0,0,AAPL
2024-10-22 11:16:44.305629225+00:00,10,39,38,C,B,0,232.8,2000,130,204374,20975,,237.2,0,2000,0,1,,,0,0,0,0,,,0,0,0,0,,,0,0,0,0,,,0,0,0,0,,,0,0,0,0,,,0,0,0,0,,,0,0,0,0,,,0,0,0,0,,,0,0,0,0,AAPL
2024-10-22 11:16:44.342956905+00:00,10,39,38,A,B,0,232.8,2000,130,204133,20976,232.8,237.2,2000,2000,1,1,,,0,0,0,0,,,0,0,0,0,,,0,0,0,0,,,0,0,0,0,,,0,0,0,0,,,0,0,0,0,,,0,0,0,0,,,0,0,0,0,,,0,0,0,0,AAPL
2024-10-22 11:17:00.039289919+00:00,10,40,38,A,B,0,235.55,200,194,202939,25406,,235.55,0,200,0,0,,,0,0,0,0,,,0,0,0,0,,,0,0,0,0,,,0,0,0,0,,,0,0,0,0,,,0,0,0,0,,,0,0,0,0,,,0,0,0,0,,,0,0,0,0,AAPL
2024-10-22 11:17:00.092524937+00:00,10,40,38,A,B,0,235.55,200,194,202943,25417,234.65,235.55,200,200,0,0,,,0,0,0,0,,,0,0,0,0,,,0,0,0,0,,,0,0,0,0,,,0,0,0,0,,,0,0,0,0,,,0,0,0,0,,,0,0,0,0,,,0,0,0,0,AAPL
2024-10-22 11:17:00.117330775+00:00,10,40,38,A,B,0,235.55,200,194,203035,25421,,235.55,0,200,0,0,,,0,0,0,0,,,0,0,0,0,,,0,0,0,0,,,0,0,0,0,,,0,0,0,0,,,0,0,0,0,,,0,0,0,0,,,0,0,0,0,,,0,0,0,0,AAPL
2024-10-22 11:17:01.778318812+00:00,10,40,38,A,B,0,235.55,200,194,202922,25456,234.65,235.55,200,200,0,0,,,0,0,0,0,,,0,0,0,0,,,0,0,0,0,,,0,0,0,0,,,0,0,0,0,,,0,0,0,0,,,0,0,0,0,,,0,0,0,0,,,0,0,0,0,AAPL
2024-10-22 11:17:25.423074440+00:00,10,39,38,C,A,0,237.2,2000,130,203813,21144,232.8,,2000,0,1,0,,,0,0,0,0,,,0,0,0,0,,,0,0,0,0,,,0,0,0,0,,,0,0,0,0,,,0,0,0,0,,,0,0,0,0,,,0,0,0,0,,,0,0,0,0,AAPL
2024-10-22 11:17:25.436890796+00:00,10,39,38,A,A,0,237.2,2000,130,203901,21145,232.8,237.2,2000,2000,1,1,,,0,0,0,0,,,0,0,0,0,,,0,0,0,0,,,0,0,0,0,,,0,0,0,0,,,0,0,0,0,,,0,0,0,0,,,0,0,0,0,,,0,0,0,0,AAPL
2024-10-22 11:18:16.003051401+00:00,10,39,38,C,B,0,232.8,2000,130,204175,21400,,237.2,0,2000,0,1,,,0,0,0,0,,,0,0,0,0,,,0,0,0,0,,,0,0,0,0,,,0,0,0,0,,,0,0,0,0,,,0,0,0,0,,,0,0,0,0,,,0,0,0,0,AAPL
2024-10-22 11:18:24.069473209+00:00,10,39,38,C,A,0,237.2,2000,130,203629,21439,,,0,0,0,0,,,0,0,0,0,,,0,0,0,0,,,0,0,0,0,,,0,0,0,0,,,0,0,0,0,,,0,0,0,0,,,0,0,0,0,,,0,0,0,0,,,0,0,0,0,AAPL
2024-10-22 11:18:24.105736114+00:00,10,39,38,A,A,0,237.2,2000,130,203217,21440,,237.2,0,2000,0,1,,,0,0,0,0,,,0,0,0,0,,,0,0,0,0,,,0,0,0,0,,,0,0,0,0,,,0,0,0,0,,,0,0,0,0,,,0,0,0,0,,,0,0,0,0,AAPL
2024-10-22 11:19:21.599824714+00:00,10,39,38,C,A,0,237.2,2000,130,204188,21824,,,0,0,0,0,,,0,0,0,0,,,0,0,0,0,,,0,0,0,0,,,0,0,0,0,,,0,0,0,0,,,0,0,0,0,,,0,0,0,0,,,0,0,0,0,,,0,0,0,0,AAPL
2024-10-22 11:19:21.635639239+00:00,10,39,38,A,A,0,237.2,2000,130,203673,21825,,237.2,0,2000,0,1,,,0,0,0,0,,,0,0,0,0,,,0,0,0,0,,,0,0,0,0,,,0,0,0,0,,,0,0,0,0,,,0,0,0,0,,,0,0,0,0,,,0,0,0,0,AAPL
2024-10-22 11:19:59.185271665+00:00,10,39,38,C,A,0,237.2,2000,130,204107,22047,,,0,0,0,0,,,0,0,0,0,,,0,0,0,0,,,0,0,0,0,,,0,0,0,0,,,0,0,0,0,,,0,0,0,0,,,0,0,0,0,,,0,0,0,0,,,0,0,0,0,AAPL
2024-10-22 11:19:59.220795900+00:00,10,39,38,A,A,0,237.2,2000,130,203829,22048,,237.2,0,2000,0,1,,,0,0,0,0,,,0,0,0,0,,,0,0,0,0,,,0,0,0,0,,,0,0,0,0,,,0,0,0,0,,,0,0,0,0,,,0,0,0,0,,,0,0,0,0,AAPL
2024-10-22 11:21:17.979974122+00:00,10,39,38,A,B,0,232.8,2000,130,204243,22466,232.8,237.2,2000,2000,1,1,,,0,0,0,0,,,0,0,0,0,,,0,0,0,0,,,0,0,0,0,,,0,0,0,0,,,0,0,0,0,,,0,0,0,0,,,0,0,0,0,,,0,0,0,0,AAPL
2024-10-22 11:21:17.980394329+00:00,10,39,38,A,A,0,237.0,2000,130,204155,22467,232.8,237.0,2000,2000,1,1,,237.2,0,2000,0,1,,,0,0,0,0,,,0,0,0,0,,,0,0,0,0,,,0,0,0,0,,,0,0,0,0,,,0,0,0,0,,,0,0,0,0,,,0,0,0,0,AAPL
2024-10-22 11:21:17.980589993+00:00,10,39,38,C,A,1,237.2,2000,130,204060,22468,232.8,237.0,2000,2000,1,1,,,0,0,0,0,,,0,0,0,0,,,0,0,0,0,,,0,0,0,0,,,0,0,0,0,,,0,0,0,0,,,0,0,0,0,,,0,0,0,0,,,0,0,0,0,AAPL
2024-10-22 11:21:18.775598465+00:00,10,39,38,A,B,0,233.0,2000,130,204227,22476,233.0,237.0,2000,2000,1,1,232.8,,2000,0,1,0,,,0,0,0,0,,,0,0,0,0,,,0,0,0,0,,,0,0,0,0,,,0,0,0,0,,,0,0,0,0,,,0,0,0,0,,,0,0,0,0,AAPL
2024-10-22 11:21:18.775806736+00:00,10,39,38,C,B,1,232.8,2000,128,204325,22480,233.0,237.0,2000,2000,1,1,,,0,0,0,0,,,0,0,0,0,,,0,0,0,0,,,0,0,0,0,,,0,0,0,0,,,0,0,0,0,,,0,0,0,0,,,0,0,0,0,,,0,0,0,0,AAPL
2024-10-22 11:21:20.627806867+00:00,10,39,38,A,A,0,236.8,2000,130,204754,22525,233.0,236.8,2000,2000,1,1,,237.0,0,2000,0,1,,,0,0,0,0,,,0,0,0,0,,,0,0,0,0,,,0,0,0,0,,,0,0,0,0,,,0,0,0,0,,,0,0,0,0,,,0,0,0,0,AAPL
2024-10-22 11:21:20.628532144+00:00,10,39,38,C,A,1,237.0,2000,130,204270,22526,233.0,236.8,2000,2000,1,1,,,0,0,0,0,,,0,0,0,0,,,0,0,0,0,,,0,0,0,0,,,0,0,0,0,,,0,0,0,0,,,0,0,0,0,,,0,0,0,0,,,0,0,0,0,AAPL
2024-10-22 11:21:20.869875781+00:00,10,39,38,A,B,0,233.2,2000,130,204344,22527,233.2,236.8,2000,2000,1,1,233.0,,2000,0,1,0,,,0,0,0,0,,,0,0,0,0,,,0,0,0,0,,,0,0,0,0,,,0,0,0,0,,,0,0,0,0,,,0,0,0,0,,,0,0,0,0,AAPL
2024-10-22 11:21:20.870616044+00:00,10,39,38,C,B,1,233.0,2000,130,204191,22528,233.2,236.8,2000,2000,1,1,,,0,0,0,0,,,0,0,0,0,,,0,0,0,0,,,0,0,0,0,,,0,0,0,0,,,0,0,0,0,,,0,0,0,0,,,0,0,0,0,,,0,0,0,0,AAPL
2024-10-22 11:21:27.551661858+00:00,10,39,38,C,A,0,236.8,2000,130,203953,22572,233.2,,2000,0,1,0,,,0,0,0,0,,,0,0,0,0,,,0,0,0,0,,,0,0,0,0,,,0,0,0,0,,,0,0,0,0,,,0,0,0,0,,,0,0,0,0,,,0,0,0,0,AAPL
2024-10-22 11:21:27.588349934+00:00,10,39,38,A,A,0,236.8,2000,130,203984,22573,233.2,236.8,2000,2000,1,1,,,0,0,0,0,,,0,0,0,0,,,0,0,0,0,,,0,0,0,0,,,0,0,0,0,,,0,0,0,0,,,0,0,0,0,,,0,0,0,0,,,0,0,0,0,AAPL
2024-10-22 11:21:33.438141768+00:00,10,39,38,C,A,0,236.8,2000,130,203681,22623,233.2,,2000,0,1,0,,,0,0,0,0,,,0,0,0,0,,,0,0,0,0,,,0,0,0,0,,,0,0,0,0,,,0,0,0,0,,,0,0,0,0,,,0,0,0,0,,,0,0,0,0,AAPL
2024-10-22 11:21:33.474435479+00:00,10,39,38,A,A,0,237.0,2000,130,203672,22624,233.2,237.0,2000,2000,1,1,,,0,0,0,0,,,0,0,0,0,,,0,0,0,0,,,0,0,0,0,,,0,0,0,0,,,0,0,0,0,,,0,0,0,0,,,0,0,0,0,,,0,0,0,0,AAPL
2024-10-22 11:21:37.944980241+00:00,10,39,38,C,B,0,233.2,2000,130,203517,22667,,237.0,0,2000,0,1,,,0,0,0,0,,,0,0,0,0,,,0,0,0,0,,,0,0,0,0,,,0,0,0,0,,,0,0,0,0,,,0,0,0,0,,,0,0,0,0,,,0,0,0,0,AAPL
2024-10-22 11:21:37.956111388+00:00,10,39,38,A,B,0,233.0,2000,130,203532,22668,233.0,237.0,2000,2000,1,1,,,0,0,0,0,,,0,0,0,0,,,0,0,0,0,,,0,0,0,0,,,0,0,0,0,,,0,0,0,0,,,0,0,0,0,,,0,0,0,0,,,0,0,0,0,AAPL
2024-10-22 11:21:37.988882262+00:00,10,39,38,A,B,0,233.2,2000,130,203477,22669,233.2,237.0,2000,2000,1,1,233.0,,2000,0,1,0,,,0,0,0,0,,,0,0,0,0,,,0,0,0,0,,,0,0,0,0,,,0,0,0,0,,,0,0,0,0,,,0,0,0,0,,,0,0,0,0,AAPL
2024-10-22 11:21:37.989603610+00:00,10,39,38,C,B,1,233.0,2000,130,203426,22670,233.2,237.0,2000,2000,1,1,,,0,0,0,0,,,0,0,0,0,,,0,0,0,0,,,0,0,0,0,,,0,0,0,0,,,0,0,0,0,,,0,0,0,0,,,0,0,0,0,,,0,0,0,0,AAPL
2024-10-22 11:21:38.292175400+00:00,10,39,38,C,A,0,237.0,2000,130,203947,22672,233.2,,2000,0,1,0,,,0,0,0,0,,,0,0,0,0,,,0,0,0,0,,,0,0,0,0,,,0,0,0,0,,,0,0,0,0,,,0,0,0,0,,,0,0,0,0,,,0,0,0,0,AAPL
2024-10-22 11:21:38.302465816+00:00,10,39,38,A,A,0,236.8,2000,130,203506,22673,233.2,236.8,2000,2000,1,1,,,0,0,0,0,,,0,0,0,0,,,0,0,0,0,,,0,0,0,0,,,0,0,0,0,,,0,0,0,0,,,0,0,0,0,,,0,0,0,0,,,0,0,0,0,AAPL
2024-10-22 11:21:41.174581079+00:00,10,39,38,C,B,0,233.2,2000,130,203404,22721,,236.8,0,2000,0,1,,,0,0,0,0,,,0,0,0,0,,,0,0,0,0,,,0,0,0,0,,,0,0,0,0,,,0,0,0,0,,,0,0,0,0,,,0,0,0,0,,,0,0,0,0,AAPL
2024-10-22 11:21:41.174810805+00:00,10,39,38,C,A,0,236.8,2000,130,203310,22722,,,0,0,0,0,,,0,0,0,0,,,0,0,0,0,,,0,0,0,0,,,0,0,0,0,,,0,0,0,0,,,0,0,0,0,,,0,0,0,0,,,0,0,0,0,,,0,0,0,0,AAPL
2024-10-22 11:21:41.186224960+00:00,10,39,38,A,A,0,237.0,2000,130,203364,22723,,237.0,0,2000,0,1,,,0,0,0,0,,,0,0,0,0,,,0,0,0,0,,,0,0,0,0,,,0,0,0,0,,,0,0,0,0,,,0,0,0,0,,,0,0,0,0,,,0,0,0,0,AAPL
2024-10-22 11:21:41.191380416+00:00,10,39,38,A,B,0,233.0,2000,130,203451,22724,233.0,237.0,2000,2000,1,1,,,0,0,0,0,,,0,0,0,0,,,0,0,0,0,,,0,0,0,0,,,0,0,0,0,,,0,0,0,0,,,0,0,0,0,,,0,0,0,0,,,0,0,0,0,AAPL
2024-10-22 11:21:41.517582849+00:00,10,39,38,C,A,0,237.0,2000,130,203530,22733,233.0,,2000,0,1,0,,,0,0,0,0,,,0,0,0,0,,,0,0,0,0,,,0,0,0,0,,,0,0,0,0,,,0,0,0,0,,,0,0,0,0,,,0,0,0,0,,,0,0,0,0,AAPL
2024-10-22 11:21:41.528847579+00:00,10,39,38,A,A,0,237.0,2000,130,203465,22734,233.0,237.0,2000,2000,1,1,,,0,0,0,0,,,0,0,0,0,,,0,0,0,0,,,0,0,0,0,,,0,0,0,0,,,0,0,0,0,,,0,0,0,0,,,0,0,0,0,,,0,0,0,0,AAPL
2024-10-22 11:21:41.776371479+00:00,10,40,38,A,A,0,,0,194,203275,28013,234.65,,200,0,0,0,,,0,0,0,0,,,0,0,0,0,,,0,0,0,0,,,0,0,0,0,,,0,0,0,0,,,0,0,0,0,,,0,0,0,0,,,0,0,0,0,,,0,0,0,0,AAPL
2024-10-22 11:21:41.776386443+00:00,10,40,38,A,A,0,235.73,200,194,203250,28014,234.65,235.73,200,200,0,0,,,0,0,0,0,,,0,0,0,0,,,0,0,0,0,,,0,0,0,0,,,0,0,0,0,,,0,0,0,0,,,0,0,0,0,,,0,0,0,0,,,0,0,0,0,AAPL
2024-10-22 11:21:42.426307427+00:00,10,39,38,A,B,0,233.2,2000,130,203775,22751,233.2,237.0,2000,2000,1,1,233.0,,2000,0,1,0,,,0,0,0,0,,,0,0,0,0,,,0,0,0,0,,,0,0,0,0,,,0,0,0,0,,,0,0,0,0,,,0,0,0,0,,,0,0,0,0,AAPL
2024-10-22 11:21:42.426488067+00:00,10,39,38,C,B,1,233.0,2000,130,203483,22752,233.2,237.0,2000,2000,1,1,,,0,0,0,0,,,0,0,0,0,,,0,0,0,0,,,0,0,0,0,,,0,0,0,0,,,0,0,0,0,,,0,0,0,0,,,0,0,0,0,,,0,0,0,0,AAPL
2024-10-22 11:22:07.339770536+00:00,10,39,38,C,A,0,237.0,2000,130,203177,22878,233.2,,2000,0,1,0,,,0,0,0,0,,,0,0,0,0,,,0,0,0,0,,,0,0,0,0,,,0,0,0,0,,,0,0,0,0,,,0,0,0,0,,,0,0,0,0,,,0,0,0,0,AAPL
2024-10-22 11:22:07.376425070+00:00,10,39,38,A,A,0,236.8,2000,130,203218,22880,233.2,236.8,2000,2000,1,1,,,0,0,0,0,,,0,0,0,0,,,0,0,0,0,,,0,0,0,0,,,0,0,0,0,,,0,0,0,0,,,0,0,0,0,,,0,0,0,0,,,0,0,0,0,AAPL
2024-10-22 11:22:37.639045033+00:00,10,39,38,C,B,0,233.2,2000,130,203521,23045,,236.8,0,2000,0,1,,,0,0,0,0,,,0,0,0,0,,,0,0,0,0,,,0,0,0,0,,,0,0,0,0,,,0,0,0,0,,,0,0,0,0,,,0,0,0,0,,,0,0,0,0,AAPL
2024-10-22 11:22:37.650040140+00:00,10,39,38,A,B,0,233.2,2000,130,203496,23046,233.2,236.8,2000,2000,1,1,,,0,0,0,0,,,0,0,0,0,,,0,0,0,0,,,0,0,0,0,,,0,0,0,0,,,0,0,0,0,,,0,0,0,0,,,0,0,0,0,,,0,0,0,0,AAPL
2024-10-22 11:22:37.885885041+00:00,10,40,38,A,B,0,235.73,200,194,202702,28527,,235.73,0,200,0,0,,,0,0,0,0,,,0,0,0,0,,,0,0,0,0,,,0,0,0,0,,,0,0,0,0,,,0,0,0,0,,,0,0,0,0,,,0,0,0,0,,,0,0,0,0,AAPL
2024-10-22 11:22:37.885910790+00:00,10,40,38,A,B,0,235.73,200,194,202688,28528,234.82,235.73,200,200,0,0,,,0,0,0,0,,,0,0,0,0,,,0,0,0,0,,,0,0,0,0,,,0,0,0,0,,,0,0,0,0,,,0,0,0,0,,,0,0,0,0,,,0,0,0,0,AAPL
2024-10-22 11:23:27.612596610+00:00,10,39,38,C,A,0,236.8,2000,130,203976,23322,233.2,,2000,0,1,0,,,0,0,0,0,,,0,0,0,0,,,0,0,0,0,,,0,0,0,0,,,0,0,0,0,,,0,0,0,0,,,0,0,0,0,,,0,0,0,0,,,0,0,0,0,AAPL
2024-10-22 11:23:27.647630759+00:00,10,39,38,A,A,0,236.8,2000,130,204133,23323,233.2,236.8,2000,2000,1,1,,,0,0,0,0,,,0,0,0,0,,,0,0,0,0,,,0,0,0,0,,,0,0,0,0,,,0,0,0,0,,,0,0,0,0,,,0,0,0,0,,,0,0,0,0,AAPL
2024-10-22 11:23:35.754071756+00:00,10,39,38,C,B,0,233.2,2000,130,203963,23369,,236.8,0,2000,0,1,,,0,0,0,0,,,0,0,0,0,,,0,0,0,0,,,0,0,0,0,,,0,0,0,0,,,0,0,0,0,,,0,0,0,0,,,0,0,0,0,,,0,0,0,0,AAPL
2024-10-22 11:23:35.754297733+00:00,10,39,38,C,A,0,236.8,2000,130,203618,23370,,,0,0,0,0,,,0,0,0,0,,,0,0,0,0,,,0,0,0,0,,,0,0,0,0,,,0,0,0,0,,,0,0,0,0,,,0,0,0,0,,,0,0,0,0,,,0,0,0,0,AAPL
2024-10-22 11:23:35.764796412+00:00,10,39,38,A,B,0,233.0,2000,130,203627,23371,233.0,,2000,0,1,0,,,0,0,0,0,,,0,0,0,0,,,0,0,0,0,,,0,0,0,0,,,0,0,0,0,,,0,0,0,0,,,0,0,0,0,,,0,0,0,0,,,0,0,0,0,AAPL
2024-10-22 11:23:35.765387236+00:00,10,39,38,A,A,0,237.0,2000,130,203677,23372,233.0,237.0,2000,2000,1,1,,,0,0,0,0,,,0,0,0,0,,,0,0,0,0,,,0,0,0,0,,,0,0,0,0,,,0,0,0,0,,,0,0,0,0,,,0,0,0,0,,,0,0,0,0,AAPL
2024-10-22 11:23:35.796307973+00:00,10,39,38,C,B,0,233.0,2000,130,203558,23374,,237.0,0,2000,0,1,,,0,0,0,0,,,0,0,0,0,,,0,0,0,0,,,0,0,0,0,,,0,0,0,0,,,0,0,0,0,,,0,0,0,0,,,0,0,0,0,,,0,0,0,0,AAPL
2024-10-22 11:23:35.796859635+00:00,10,39,38,C,A,0,237.0,2000,130,203532,23375,,,0,0,0,0,,,0,0,0,0,,,0,0,0,0,,,0,0,0,0,,,0,0,0,0,,,0,0,0,0,,,0,0,0,0,,,0,0,0,0,,,0,0,0,0,,,0,0,0,0,AAPL
2024-10-22 11:23:35.807749686+00:00,10,39,38,A,A,0,237.4,2000,130,203587,23376,,237.4,0,2000,0,1,,,0,0,0,0,,,0,0,0,0,,,0,0,0,0,,,0,0,0,0,,,0,0,0,0,,,0,0,0,0,,,0,0,0,0,,,0,0,0,0,,,0,0,0,0,AAPL
2024-10-22 11:23:35.813707974+00:00,10,39,38,C,A,0,237.4,2000,130,203639,23377,,,0,0,0,0,,,0,0,0,0,,,0,0,0,0,,,0,0,0,0,,,0,0,0,0,,,0,0,0,0,,,0,0,0,0,,,0,0,0,0,,,0,0,0,0,,,0,0,0,0,AAPL
2024-10-22 11:24:49.244754050+00:00,10,41,38,A,N,0,,0,192,34802804,105,,,0,0,0,0,,,0,0,0,0,,,0,0,0,0,,,0,0,0,0,,,0,0,0,0,,,0,0,0,0,,,0,0,0,0,,,0,0,0,0,,,0,0,0,0,,,0,0,0,0,AAPL
2024-10-22 11:24:49.259155589+00:00,10,41,10888,A,N,0,,0,192,283770055,33105,,,0,0,0,0,,,0,0,0,0,,,0,0,0,0,,,0,0,0,0,,,0,0,0,0,,,0,0,0,0,,,0,0,0,0,,,0,0,0,0,,,0,0,0,0,,,0,0,0,0,MSFT
2024-10-22 11:25:00.018063355+00:00,10,40,38,A,B,0,235.73,200,194,201723,29641,,235.73,0,200,0,0,,,0,0,0,0,,,0,0,0,0,,,0,0,0,0,,,0,0,0,0,,,0,0,0,0,,,0,0,0,0,,,0,0,0,0,,,0,0,0,0,,,0,0,0,0,AAPL
2024-10-22 11:25:00.018085146+00:00,10,40,38,A,A,0,,0,194,201692,29642,,,0,0,0,0,,,0,0,0,0,,,0,0,0,0,,,0,0,0,0,,,0,0,0,0,,,0,0,0,0,,,0,0,0,0,,,0,0,0,0,,,0,0,0,0,,,0,0,0,0,AAPL
2024-10-22 11:25:00.069094339+00:00,10,40,38,A,B,0,,0,194,201717,29675,234.86,,200,0,0,0,,,0,0,0,0,,,0,0,0,0,,,0,0,0,0,,,0,0,0,0,,,0,0,0,0,,,0,0,0,0,,,0,0,0,0,,,0,0,0,0,,,0,0,0,0,AAPL
2024-10-22 11:25:00.069101671+00:00,10,40,38,A,A,0,235.77,200,194,201700,29676,234.86,235.77,200,200,0,0,,,0,0,0,0,,,0,0,0,0,,,0,0,0,0,,,0,0,0,0,,,0,0,0,0,,,0,0,0,0,,,0,0,0,0,,,0,0,0,0,,,0,0,0,0,AAPL
2024-10-22 11:25:00.826382950+00:00,10,40,38,A,B,0,235.77,200,194,202044,29718,,235.77,0,200,0,0,,,0,0,0,0,,,0,0,0,0,,,0,0,0,0,,,0,0,0,0,,,0,0,0,0,,,0,0,0,0,,,0,0,0,0,,,0,0,0,0,,,0,0,0,0,AAPL
2024-10-22 11:25:00.882971461+00:00,10,40,38,A,B,0,235.77,200,194,201996,29719,234.86,235.77,200,200,0,0,,,0,0,0,0,,,0,0,0,0,,,0,0,0,0,,,0,0,0,0,,,0,0,0,0,,,0,0,0,0,,,0,0,0,0,,,0,0,0,0,,,0,0,0,0,AAPL
2024-10-22 11:25:04.526499644+00:00,10,39,38,A,A,0,237.6,2000,130,203339,23798,,237.6,0,2000,0,1,,,0,0,0,0,,,0,0,0,0,,,0,0,0,0,,,0,0,0,0,,,0,0,0,0,,,0,0,0,0,,,0,0,0,0,,,0,0,0,0,,,0,0,0,0,AAPL
2024-10-22 11:25:04.696356576+00:00,10,40,38,A,A,0,,0,194,202628,29755,234.86,,200,0,0,0,,,0,0,0,0,,,0,0,0,0,,,0,0,0,0,,,0,0,0,0,,,0,0,0,0,,,0,0,0,0,,,0,0,0,0,,,0,0,0,0,,,0,0,0,0,AAPL
2024-10-22 11:25:06.056905466+00:00,10,40,38,A,A,0,235.78,200,194,202441,29764,234.86,235.78,200,200,0,0,,,0,0,0,0,,,0,0,0,0,,,0,0,0,0,,,0,0,0,0,,,0,0,0,0,,,0,0,0,0,,,0,0,0,0,,,0,0,0,0,,,0,0,0,0,AAPL
2024-10-22 11:25:06.190591680+00:00,10,39,38,A,A,0,237.4,2000,130,203013,23821,,237.4,0,2000,0,1,,237.6,0,2000,0,1,,,0,0,0,0,,,0,0,0,0,,,0,0,0,0,,,0,0,0,0,,,0,0,0,0,,,0,0,0,0,,,0,0,0,0,,,0,0,0,0,AAPL
2024-10-22 11:25:06.191242712+00:00,10,39,38,C,A,1,237.6,2000,130,202810,23822,,237.4,0,2000,0,1,,,0,0,0,0,,,0,0,0,0,,,0,0,0,0,,,0,0,0,0,,,0,0,0,0,,,0,0,0,0,,,0,0,0,0,,,0,0,0,0,,,0,0,0,0,AAPL
2024-10-22 11:25:06.407086091+00:00,10,39,38,C,A,0,237.4,2000,130,202878,23823,,,0,0,0,0,,,0,0,0,0,,,0,0,0,0,,,0,0,0,0,,,0,0,0,0,,,0,0,0,0,,,0,0,0,0,,,0,0,0,0,,,0,0,0,0,,,0,0,0,0,AAPL
2024-10-22 11:25:06.417805004+00:00,10,39,38,A,A,0,237.6,2000,130,202906,23824,,237.6,0,2000,0,1,,,0,0,0,0,,,0,0,0,0,,,0,0,0,0,,,0,0,0,0,,,0,0,0,0,,,0,0,0,0,,,0,0,0,0,,,0,0,0,0,,,0,0,0,0,AAPL
2024-10-22 11:25:06.807474807+00:00,10,39,38,A,A,0,237.4,2000,130,202984,23828,,237.4,0,2000,0,1,,237.6,0,2000,0,1,,,0,0,0,0,,,0,0,0,0,,,0,0,0,0,,,0,0,0,0,,,0,0,0,0,,,0,0,0,0,,,0,0,0,0,,,0,0,0,0,AAPL
2024-10-22 11:25:06.808206724+00:00,10,39,38,C,A,1,237.6,2000,130,202884,23829,,237.4,0,2000,0,1,,,0,0,0,0,,,0,0,0,0,,,0,0,0,0,,,0,0,0,0,,,0,0,0,0,,,0,0,0,0,,,0,0,0,0,,,0,0,0,0,,,0,0,0,0,AAPL
2024-10-22 11:25:11.768183719+00:00,10,39,38,C,A,0,237.4,2000,130,203832,23857,,,0,0,0,0,,,0,0,0,0,,,0,0,0,0,,,0,0,0,0,,,0,0,0,0,,,0,0,0,0,,,0,0,0,0,,,0,0,0,0,,,0,0,0,0,,,0,0,0,0,AAPL
2024-10-22 11:25:11.804194548+00:00,10,39,38,A,A,0,237.4,2000,130,203302,23858,,237.4,0,2000,0,1,,,0,0,0,0,,,0,0,0,0,,,0,0,0,0,,,0,0,0,0,,,0,0,0,0,,,0,0,0,0,,,0,0,0,0,,,0,0,0,0,,,0,0,0,0,AAPL
2024-10-22 11:27:02.134582698+00:00,10,39,38,C,A,0,237.4,2000,130,202797,24455,,,0,0,0,0,,,0,0,0,0,,,0,0,0,0,,,0,0,0,0,,,0,0,0,0,,,0,0,0,0,,,0,0,0,0,,,0,0,0,0,,,0,0,0,0,,,0,0,0,0,AAPL
2024-10-22 11:27:02.170632708+00:00,10,39,38,A,A,0,237.4,2000,130,202573,24456,,237.4,0,2000,0,1,,,0,0,0,0,,,0,0,0,0,,,0,0,0,0,,,0,0,0,0,,,0,0,0,0,,,0,0,0,0,,,0,0,0,0,,,0,0,0,0,,,0,0,0,0,AAPL
2024-10-22 11:28:00.129179625+00:00,10,40,38,A,B,0,235.78,200,194,204399,31325,,235.78,0,200,0,0,,,0,0,0,0,,,0,0,0,0,,,0,0,0,0,,,0,0,0,0,,,0,0,0,0,,,0,0,0,0,,,0,0,0,0,,,0,0,0,0,,,0,0,0,0,AAPL
2024-10-22 11:28:00.144594379+00:00,10,40,38,A,B,0,235.78,200,194,204403,31327,234.89,235.78,200,200,0,0,,,0,0,0,0,,,0,0,0,0,,,0,0,0,0,,,0,0,0,0,,,0,0,0,0,,,0,0,0,0,,,0,0,0,0,,,0,0,0,0,,,0,0,0,0,AAPL
2024-10-22 11:28:14.201835935+00:00,10,39,38,A,B,0,233.4,2000,130,203654,24841,233.4,237.4,2000,2000,1,1,,,0,0,0,0,,,0,0,0,0,,,0,0,0,0,,,0,0,0,0,,,0,0,0,0,,,0,0,0,0,,,0,0,0,0,,,0,0,0,0,,,0,0,0,0,AAPL
2024-10-22 11:28:14.201847074+00:00,10,39,38,A,A,0,236.8,2000,130,203375,24842,233.4,236.8,2000,2000,1,1,,237.4,0,2000,0,1,,,0,0,0,0,,,0,0,0,0,,,0,0,0,0,,,0,0,0,0,,,0,0,0,0,,,0,0,0,0,,,0,0,0,0,,,0,0,0,0,AAPL
2024-10-22 11:28:14.201875174+00:00,10,39,38,C,A,1,237.4,2000,130,203296,24843,233.4,236.8,2000,2000,1,1,,,0,0,0,0,,,0,0,0,0,,,0,0,0,0,,,0,0,0,0,,,0,0,0,0,,,0,0,0,0,,,0,0,0,0,,,0,0,0,0,,,0,0,0,0,AAPL
2024-10-22 11:28:14.307367971+00:00,10,39,38,C,B,0,233.4,2000,130,203305,24846,,236.8,0,2000,0,1,,,0,0,0,0,,,0,0,0,0,,,0,0,0,0,,,0,0,0,0,,,0,0,0,0,,,0,0,0,0,,,0,0,0,0,,,0,0,0,0,,,0,0,0,0,AAPL
2024-10-22 11:28:14.318148412+00:00,10,39,38,A,B,0,233.2,2000,130,203318,24847,233.2,236.8,2000,2000,1,1,,,0,0,0,0,,,0,0,0,0,,,0,0,0,0,,,0,0,0,0,,,0,0,0,0,,,0,0,0,0,,,0,0,0,0,,,0,0,0,0,,,0,0,0,0,AAPL
2024-10-22 11:28:14.437998048+00:00,10,39,38,A,B,0,233.4,2000,130,203691,24848,233.4,236.8,2000,2000,1,1,233.2,,2000,0,1,0,,,0,0,0,0,,,0,0,0,0,,,0,0,0,0,,,0,0,0,0,,,0,0,0,0,,,0,0,0,0,,,0,0,0,0,,,0,0,0,0,AAPL
2024-10-22 11:28:14.438493928+00:00,10,39,38,C,B,1,233.2,2000,130,203395,24849,233.4,236.8,2000,2000,1,1,,,0,0,0,0,,,0,0,0,0,,,0,0,0,0,,,0,0,0,0,,,0,0,0,0,,,0,0,0,0,,,0,0,0,0,,,0,0,0,0,,,0,0,0,0,AAPL
2024-10-22 11:28:21.063929888+00:00,10,39,38,C,B,0,233.4,2000,130,203750,24882,,236.8,0,2000,0,1,,,0,0,0,0,,,0,0,0,0,,,0,0,0,0,,,0,0,0,0,,,0,0,0,0,,,0,0,0,0,,,0,0,0,0,,,0,0,0,0,,,0,0,0,0,AAPL
2024-10-22 11:28:21.100439862+00:00,10,39,38,A,B,0,233.4,2000,130,203669,24883,233.4,236.8,2000,2000,1,1,,,0,0,0,0,,,0,0,0,0,,,0,0,0,0,,,0,0,0,0,,,0,0,0,0,,,0,0,0,0,,,0,0,0,0,,,0,0,0,0,,,0,0,0,0,AAPL
2024-10-22 11:28:21.118376300+00:00,10,39,38,C,A,0,236.8,2000,130,203634,24885,233.4,,2000,0,1,0,,,0,0,0,0,,,0,0,0,0,,,0,0,0,0,,,0,0,0,0,,,0,0,0,0,,,0,0,0,0,,,0,0,0,0,,,0,0,0,0,,,0,0,0,0,AAPL
2024-10-22 11:28:21.129118230+00:00,10,39,38,A,A,0,237.0,2000,130,203544,24887,233.4,237.0,2000,2000,1,1,,,0,0,0,0,,,0,0,0,0,,,0,0,0,0,,,0,0,0,0,,,0,0,0,0,,,0,0,0,0,,,0,0,0,0,,,0,0,0,0,,,0,0,0,0,AAPL
2024-10-22 11:28:21.149661713+00:00,10,39,38,C,A,0,237.0,2000,130,203468,24888,233.4,,2000,0,1,0,,,0,0,0,0,,,0,0,0,0,,,0,0,0,0,,,0,0,0,0,,,0,0,0,0,,,0,0,0,0,,,0,0,0,0,,,0,0,0,0,,,0,0,0,0,AAPL
2024-10-22 11:28:21.160590271+00:00,10,39,38,A,A,0,237.4,2000,130,203538,24889,233.4,237.4,2000,2000,1,1,,,0,0,0,0,,,0,0,0,0,,,0,0,0,0,,,0,0,0,0,,,0,0,0,0,,,0,0,0,0,,,0,0,0,0,,,0,0,0,0,,,0,0,0,0,AAPL
2024-10-22 11:28:42.844836625+00:00,10,39,38,C,A,0,237.4,2000,130,203496,25023,233.4,,2000,0,1,0,,,0,0,0,0,,,0,0,0,0,,,0,0,0,0,,,0,0,0,0,,,0,0,0,0,,,0,0,0,0,,,0,0,0,0,,,0,0,0,0,,,0,0,0,0,AAPL
2024-10-22 11:28:42.880882282+00:00,10,39,38,A,A,0,236.8,2000,130,203572,25024,233.4,236.8,2000,2000,1,1,,,0,0,0,0,,,0,0,0,0,,,0,0,0,0,,,0,0,0,0,,,0,0,0,0,,,0,0,0,0,,,0,0,0,0,,,0,0,0,0,,,0,0,0,0,AAPL
2024-10-22 11:29:06.131611645+00:00,10,39,38,C,B,0,233.4,2000,130,204070,25235,,236.8,0,2000,0,1,,,0,0,0,0,,,0,0,0,0,,,0,0,0,0,,,0,0,0,0,,,0,0,0,0,,,0,0,0,0,,,0,0,0,0,,,0,0,0,0,,,0,0,0,0,AAPL
2024-10-22 11:29:06.142343509+00:00,10,39,38,A,B,0,233.2,2000,130,204137,25236,233.2,236.8,2000,2000,1,1,,,0,0,0,0,,,0,0,0,0,,,0,0,0,0,,,0,0,0,0,,,0,0,0,0,,,0,0,0,0,,,0,0,0,0,,,0,0,0,0,,,0,0,0,0,AAPL
2024-10-22 11:29:06.161063293+00:00,10,39,38,C,B,0,233.2,2000,130,204078,25238,,236.8,0,2000,0,1,,,0,0,0,0,,,0,0,0,0,,,0,0,0,0,,,0,0,0,0,,,0,0,0,0,,,0,0,0,0,,,0,0,0,0,,,0,0,0,0,,,0,0,0,0,AAPL
2024-10-22 11:29:06.171816088+00:00,10,39,38,A,B,0,233.0,2000,130,204091,25240,233.0,236.8,2000,2000,1,1,,,0,0,0,0,,,0,0,0,0,,,0,0,0,0,,,0,0,0,0,,,0,0,0,0,,,0,0,0,0,,,0,0,0,0,,,0,0,0,0,,,0,0,0,0,AAPL
2024-10-22 11:29:06.333101947+00:00,10,39,38,C,A,0,236.8,2000,130,204259,25243,233.0,,2000,0,1,0,,,0,0,0,0,,,0,0,0,0,,,0,0,0,0,,,0,0,0,0,,,0,0,0,0,,,0,0,0,0,,,0,0,0,0,,,0,0,0,0,,,0,0,0,0,AAPL
2024-10-22 11:29:06.344187459+00:00,10,39,38,A,B,0,233.4,2000,130,204144,25244,233.4,,2000,0,1,0,233.0,,2000,0,1,0,,,0,0,0,0,,,0,0,0,0,,,0,0,0,0,,,0,0,0,0,,,0,0,0,0,,,0,0,0,0,,,0,0,0,0,,,0,0,0,0,AAPL
2024-10-22 11:29:06.344918341+00:00,10,39,38,C,B,1,233.0,2000,130,204150,25245,233.4,,2000,0,1,0,,,0,0,0,0,,,0,0,0,0,,,0,0,0,0,,,0,0,0,0,,,0,0,0,0,,,0,0,0,0,,,0,0,0,0,,,0,0,0,0,,,0,0,0,0,AAPL
2024-10-22 11:29:06.344937924+00:00,10,39,38,A,A,0,236.8,2000,130,204112,25246,233.4,236.8,2000,2000,1,1,,,0,0,0,0,,,0,0,0,0,,,0,0,0,0,,,0,0,0,0,,,0,0,0,0,,,0,0,0,0,,,0,0,0,0,,,0,0,0,0,,,0,0,0,0,AAPL
2024-10-22 11:29:07.329507831+00:00,10,39,38,C,B,0,233.4,2000,130,204361,25256,,236.8,0,2000,0,1,,,0,0,0,0,,,0,0,0,0,,,0,0,0,0,,,0,0,0,0,,,0,0,0,0,,,0,0,0,0,,,0,0,0,0,,,0,0,0,0,,,0,0,0,0,AAPL
2024-10-22 11:29:07.342198037+00:00,10,39,38,A,B,0,233.2,2000,130,204172,25257,233.2,236.8,2000,2000,1,1,,,0,0,0,0,,,0,0,0,0,,,0,0,0,0,,,0,0,0,0,,,0,0,0,0,,,0,0,0,0,,,0,0,0,0,,,0,0,0,0,,,0,0,0,0,AAPL
2024-10-22 11:29:54.319967255+00:00,10,39,38,C,B,0,233.2,2000,130,203917,25601,,236.8,0,2000,0,1,,,0,0,0,0,,,0,0,0,0,,,0,0,0,0,,,0,0,0,0,,,0,0,0,0,,,0,0,0,0,,,0,0,0,0,,,0,0,0,0,,,0,0,0,0,AAPL
2024-10-22 11:29:54.357290884+00:00,10,39,38,A,B,0,233.2,2000,130,204108,25606,233.2,236.8,2000,2000,1,1,,,0,0,0,0,,,0,0,0,0,,,0,0,0,0,,,0,0,0,0,,,0,0,0,0,,,0,0,0,0,,,0,0,0,0,,,0,0,0,0,,,0,0,0,0,AAPL
2024-10-22 11:30:00.080628944+00:00,10,40,38,A,B,0,235.78,200,194,201942,32791,,235.78,0,200,0,0,,,0,0,0,0,,,0,0,0,0,,,0,0,0,0,,,0,0,0,0,,,0,0,0,0,,,0,0,0,0,,,0,0,0,0,,,0,0,0,0,,,0,0,0,0,AAPL
2024-10-22 11:30:00.080636138+00:00,10,40,38,A,A,0,,0,194,201802,32792,,,0,0,0,0,,,0,0,0,0,,,0,0,0,0,,,0,0,0,0,,,0,0,0,0,,,0,0,0,0,,,0,0,0,0,,,0,0,0,0,,,0,0,0,0,,,0,0,0,0,AAPL
2024-10-22 11:30:12.687088710+00:00,10,40,38,A,B,0,,0,194,202145,33180,234.87,,200,0,0,0,,,0,0,0,0,,,0,0,0,0,,,0,0,0,0,,,0,0,0,0,,,0,0,0,0,,,0,0,0,0,,,0,0,0,0,,,0,0,0,0,,,0,0,0,0,AAPL
2024-10-22 11:30:12.697546714+00:00,10,39,38,A,B,0,233.4,2000,130,203379,25784,233.4,236.8,2000,2000,1,1,233.2,,2000,0,1,0,,,0,0,0,0,,,0,0,0,0,,,0,0,0,0,,,0,0,0,0,,,0,0,0,0,,,0,0,0,0,,,0,0,0,0,,,0,0,0,0,AAPL
2024-10-22 11:30:12.698274511+00:00,10,39,38,C,B,1,233.2,2000,130,203266,25785,233.4,236.8,2000,2000,1,1,,,0,0,0,0,,,0,0,0,0,,,0,0,0,0,,,0,0,0,0,,,0,0,0,0,,,0,0,0,0,,,0,0,0,0,,,0,0,0,0,,,0,0,0,0,AAPL
2024-10-22 11:30:12.791688796+00:00,10,40,38,A,B,0,,0,194,202039,33183,,,0,0,0,0,,,0,0,0,0,,,0,0,0,0,,,0,0,0,0,,,0,0,0,0,,,0,0,0,0,,,0,0,0,0,,,0,0,0,0,,,0,0,0,0,,,0,0,0,0,AAPL
2024-10-22 11:30:24.945092901+00:00,10,40,38,A,B,0,,0,194,202121,33329,234.87,,200,0,0,0,,,0,0,0,0,,,0,0,0,0,,,0,0,0,0,,,0,0,0,0,,,0,0,0,0,,,0,0,0,0,,,0,0,0,0,,,0,0,0,0,,,0,0,0,0,AAPL
2024-10-22 11:30:24.945567983+00:00,10,40,38,A,A,0,235.72,200,194,201984,33330,234.87,235.72,200,200,0,0,,,0,0,0,0,,,0,0,0,0,,,0,0,0,0,,,0,0,0,0,,,0,0,0,0,,,0,0,0,0,,,0,0,0,0,,,0,0,0,0,,,0,0,0,0,AAPL
2024-10-22 11:30:24.946047551+00:00,10,39,38,C,B,0,233.4,2000,130,203611,25876,,236.8,0,2000,0,1,,,0,0,0,0,,,0,0,0,0,,,0,0,0,0,,,0,0,0,0,,,0,0,0,0,,,0,0,0,0,,,0,0,0,0,,,0,0,0,0,,,0,0,0,0,AAPL
2024-10-22 11:30:24.982869121+00:00,10,39,38,A,B,0,233.4,2000,130,203299,25877,233.4,236.8,2000,2000,1,1,,,0,0,0,0,,,0,0,0,0,,,0,0,0,0,,,0,0,0,0,,,0,0,0,0,,,0,0,0,0,,,0,0,0,0,,,0,0,0,0,,,0,0,0,0,AAPL
2024-10-22 11:30:24.982932388+00:00,10,40,38,A,N,0,,0,194,202055,33332,,,0,0,0,0,,,0,0,0,0,,,0,0,0,0,,,0,0,0,0,,,0,0,0,0,,,0,0,0,0,,,0,0,0,0,,,0,0,0,0,,,0,0,0,0,,,0,0,0,0,AAPL
2024-10-22 11:30:24.983672291+00:00,10,39,38,C,A,0,236.8,2000,130,203178,25878,233.4,,2000,0,1,0,,,0,0,0,0,,,0,0,0,0,,,0,0,0,0,,,0,0,0,0,,,0,0,0,0,,,0,0,0,0,,,0,0,0,0,,,0,0,0,0,,,0,0,0,0,AAPL
2024-10-22 11:30:24.983910806+00:00,10,39,38,C,B,0,233.4,2000,130,203172,25879,,,0,0,0,0,,,0,0,0,0,,,0,0,0,0,,,0,0,0,0,,,0,0,0,0,,,0,0,0,0,,,0,0,0,0,,,0,0,0,0,,,0,0,0,0,,,0,0,0,0,AAPL
2024-10-22 11:30:24.994388388+00:00,10,39,38,A,A,0,237.2,2000,130,203235,25880,,237.2,0,2000,0,1,,,0,0,0,0,,,0,0,0,0,,,0,0,0,0,,,0,0,0,0,,,0,0,0,0,,,0,0,0,0,,,0,0,0,0,,,0,0,0,0,,,0,0,0,0,AAPL
2024-10-22 11:30:25.014592093+00:00,10,39,38,C,A,0,237.2,2000,130,203129,25882,,,0,0,0,0,,,0,0,0,0,,,0,0,0,0,,,0,0,0,0,,,0,0,0,0,,,0,0,0,0,,,0,0,0,0,,,0,0,0,0,,,0,0,0,0,,,0,0,0,0,AAPL
2024-10-22 11:30:25.025290875+00:00,10,39,38,A,A,0,237.6,2000,130,203135,25883,,237.6,0,2000,0,1,,,0,0,0,0,,,0,0,0,0,,,0,0,0,0,,,0,0,0,0,,,0,0,0,0,,,0,0,0,0,,,0,0,0,0,,,0,0,0,0,,,0,0,0,0,AAPL
2024-10-22 11:30:25.046881852+00:00,10,39,38,C,A,0,237.6,2000,130,203114,25884,,,0,0,0,0,,,0,0,0,0,,,0,0,0,0,,,0,0,0,0,,,0,0,0,0,,,0,0,0,0,,,0,0,0,0,,,0,0,0,0,,,0,0,0,0,,,0,0,0,0,AAPL
2024-10-22 11:30:25.083359415+00:00,10,39,38,A,A,0,237.4,2000,130,203123,25889,,237.4,0,2000,0,1,,,0,0,0,0,,,0,0,0,0,,,0,0,0,0,,,0,0,0,0,,,0,0,0,0,,,0,0,0,0,,,0,0,0,0,,,0,0,0,0,,,0,0,0,0,AAPL
2024-10-22 11:30:32.292960618+00:00,10,40,38,A,B,0,,0,194,202093,33477,234.85,,200,0,0,0,,,0,0,0,0,,,0,0,0,0,,,0,0,0,0,,,0,0,0,0,,,0,0,0,0,,,0,0,0,0,,,0,0,0,0,,,0,0,0,0,,,0,0,0,0,AAPL
2024-10-22 11:30:32.293107836+00:00,10,40,38,A,A,0,235.71,200,194,202028,33478,234.85,235.71,200,200,0,0,,,0,0,0,0,,,0,0,0,0,,,0,0,0,0,,,0,0,0,0,,,0,0,0,0,,,0,0,0,0,,,0,0,0,0,,,0,0,0,0,,,0,0,0,0,AAPL
2024-10-22 11:30:32.341661387+00:00,10,40,38,A,A,0,,0,194,202041,33479,234.85,,200,0,0,0,,,0,0,0,0,,,0,0,0,0,,,0,0,0,0,,,0,0,0,0,,,0,0,0,0,,,0,0,0,0,,,0,0,0,0,,,0,0,0,0,,,0,0,0,0,AAPL
2024-10-22 11:30:32.395663195+00:00,10,40,38,A,B,0,,0,194,202109,33480,,,0,0,0,0,,,0,0,0,0,,,0,0,0,0,,,0,0,0,0,,,0,0,0,0,,,0,0,0,0,,,0,0,0,0,,,0,0,0,0,,,0,0,0,0,,,0,0,0,0,AAPL
2024-10-22 11:30:33.735087051+00:00,10,40,38,A,B,0,,0,194,202391,33488,234.82,,200,0,0,0,,,0,0,0,0,,,0,0,0,0,,,0,0,0,0,,,0,0,0,0,,,0,0,0,0,,,0,0,0,0,,,0,0,0,0,,,0,0,0,0,,,0,0,0,0,AAPL
2024-10-22 11:30:33.735264044+00:00,10,40,38,A,A,0,235.7,200,194,202144,33489,234.82,235.7,200,200,0,0,,,0,0,0,0,,,0,0,0,0,,,0,0,0,0,,,0,0,0,0,,,0,0,0,0,,,0,0,0,0,,,0,0,0,0,,,0,0,0,0,,,0,0,0,0,AAPL
2024-10-22 11:30:33.785793912+00:00,10,40,38,A,A,0,,0,194,202119,33490,234.82,,200,0,0,0,,,0,0,0,0,,,0,0,0,0,,,0,0,0,0,,,0,0,0,0,,,0,0,0,0,,,0,0,0,0,,,0,0,0,0,,,0,0,0,0,,,0,0,0,0,AAPL
2024-10-22 11:30:33.842153040+00:00,10,40,38,A,B,0,,0,194,202098,33491,,,0,0,0,0,,,0,0,0,0,,,0,0,0,0,,,0,0,0,0,,,0,0,0,0,,,0,0,0,0,,,0,0,0,0,,,0,0,0,0,,,0,0,0,0,,,0,0,0,0,AAPL
2024-10-22 11:30:39.298925440+00:00,10,40,38,A,B,0,,0,194,202449,33543,234.82,,200,0,0,0,,,0,0,0,0,,,0,0,0,0,,,0,0,0,0,,,0,0,0,0,,,0,0,0,0,,,0,0,0,0,,,0,0,0,0,,,0,0,0,0,,,0,0,0,0,AAPL
2024-10-22 11:30:39.299141393+00:00,10,40,38,A,A,0,235.7,200,194,202244,33544,234.82,235.7,200,200,0,0,,,0,0,0,0,,,0,0,0,0,,,0,0,0,0,,,0,0,0,0,,,0,0,0,0,,,0,0,0,0,,,0,0,0,0,,,0,0,0,0,,,0,0,0,0,AAPL
2024-10-22 11:30:39.366367017+00:00,10,40,38,A,A,0,,0,194,202296,33545,234.82,,200,0,0,0,,,0,0,0,0,,,0,0,0,0,,,0,0,0,0,,,0,0,0,0,,,0,0,0,0,,,0,0,0,0,,,0,0,0,0,,,0,0,0,0,,,0,0,0,0,AAPL
2024-10-22 11:30:39.366803697+00:00,10,40,38,A,B,0,,0,194,202261,33546,,,0,0,0,0,,,0,0,0,0,,,0,0,0,0,,,0,0,0,0,,,0,0,0,0,,,0,0,0,0,,,0,0,0,0,,,0,0,0,0,,,0,0,0,0,,,0,0,0,0,AAPL
2024-10-22 11:30:40.560310729+00:00,10,40,38,A,B,0,,0,194,202301,33560,234.82,,200,0,0,0,,,0,0,0,0,,,0,0,0,0,,,0,0,0,0,,,0,0,0,0,,,0,0,0,0,,,0,0,0,0,,,0,0,0,0,,,0,0,0,0,,,0,0,0,0,AAPL
2024-10-22 11:30:40.560495870+00:00,10,40,38,A,A,0,235.7,200,194,202218,33561,234.82,235.7,200,200,0,0,,,0,0,0,0,,,0,0,0,0,,,0,0,0,0,,,0,0,0,0,,,0,0,0,0,,,0,0,0,0,,,0,0,0,0,,,0,0,0,0,,,0,0,0,0,AAPL
2024-10-22 11:30:40.597480938+00:00,10,40,38,A,A,0,,0,194,202342,33562,234.82,,200,0,0,0,,,0,0,0,0,,,0,0,0,0,,,0,0,0,0,,,0,0,0,0,,,0,0,0,0,,,0,0,0,0,,,0,0,0,0,,,0,0,0,0,,,0,0,0,0,AAPL
2024-10-22 11:30:41.641697935+00:00,10,40,38,A,B,0,,0,194,202424,33569,,,0,0,0,0,,,0,0,0,0,,,0,0,0,0,,,0,0,0,0,,,0,0,0,0,,,0,0,0,0,,,0,0,0,0,,,0,0,0,0,,,0,0,0,0,,,0,0,0,0,AAPL
2024-10-22 11:30:42.710197602+00:00,10,40,38,A,B,0,,0,194,202401,33578,234.77,,200,0,0,0,,,0,0,0,0,,,0,0,0,0,,,0,0,0,0,,,0,0,0,0,,,0,0,0,0,,,0,0,0,0,,,0,0,0,0,,,0,0,0,0,,,0,0,0,0,AAPL
2024-10-22 11:30:42.710352629+00:00,10,40,38,A,A,0,235.7,200,194,202183,33579,234.77,235.7,200,200,0,0,,,0,0,0,0,,,0,0,0,0,,,0,0,0,0,,,0,0,0,0,,,0,0,0,0,,,0,0,0,0,,,0,0,0,0,,,0,0,0,0,,,0,0,0,0,AAPL
2024-10-22 11:30:42.812014209+00:00,10,40,38,A,A,0,,0,194,202202,33580,234.77,,200,0,0,0,,,0,0,0,0,,,0,0,0,0,,,0,0,0,0,,,0,0,0,0,,,0,0,0,0,,,0,0,0,0,,,0,0,0,0,,,0,0,0,0,,,0,0,0,0,AAPL
2024-10-22 11:30:42.840276776+00:00,10,40,38,A,B,0,,0,194,202223,33582,,,0,0,0,0,,,0,0,0,0,,,0,0,0,0,,,0,0,0,0,,,0,0,0,0,,,0,0,0,0,,,0,0,0,0,,,0,0,0,0,,,0,0,0,0,,,0,0,0,0,AAPL
2024-10-22 11:30:43.523898997+00:00,10,40,38,A,B,0,,0,194,202388,33586,234.77,,200,0,0,0,,,0,0,0,0,,,0,0,0,0,,,0,0,0,0,,,0,0,0,0,,,0,0,0,0,,,0,0,0,0,,,0,0,0,0,,,0,0,0,0,,,0,0,0,0,AAPL
2024-10-22 11:30:43.524071303+00:00,10,40,38,A,A,0,235.7,200,194,202177,33587,234.77,235.7,200,200,0,0,,,0,0,0,0,,,0,0,0,0,,,0,0,0,0,,,0,0,0,0,,,0,0,0,0,,,0,0,0,0,,,0,0,0,0,,,0,0,0,0,,,0,0,0,0,AAPL
2024-10-22 11:30:43.626365730+00:00,10,40,38,A,A,0,,0,194,202146,33588,234.77,,200,0,0,0,,,0,0,0,0,,,0,0,0,0,,,0,0,0,0,,,0,0,0,0,,,0,0,0,0,,,0,0,0,0,,,0,0,0,0,,,0,0,0,0,,,0,0,0,0,AAPL
2024-10-22 11:30:43.640308583+00:00,10,40,38,A,B,0,,0,194,202133,33589,,,0,0,0,0,,,0,0,0,0,,,0,0,0,0,,,0,0,0,0,,,0,0,0,0,,,0,0,0,0,,,0,0,0,0,,,0,0,0,0,,,0,0,0,0,,,0,0,0,0,AAPL
2024-10-22 11:30:53.666682949+00:00,10,40,38,A,B,0,,0,194,202590,33689,234.77,,200,0,0,0,,,0,0,0,0,,,0,0,0,0,,,0,0,0,0,,,0,0,0,0,,,0,0,0,0,,,0,0,0,0,,,0,0,0,0,,,0,0,0,0,,,0,0,0,0,AAPL
2024-10-22 11:30:53.666689586+00:00,10,40,38,A,A,0,235.7,200,194,202588,33690,234.77,235.7,200,200,0,0,,,0,0,0,0,,,0,0,0,0,,,0,0,0,0,,,0,0,0,0,,,0,0,0,0,,,0,0,0,0,,,0,0,0,0,,,0,0,0,0,,,0,0,0,0,AAPL
2024-10-22 11:30:53.771204004+00:00,10,40,38,A,A,0,,0,194,202595,33698,234.77,,200,0,0,0,,,0,0,0,0,,,0,0,0,0,,,0,0,0,0,,,0,0,0,0,,,0,0,0,0,,,0,0,0,0,,,0,0,0,0,,,0,0,0,0,,,0,0,0,0,AAPL
2024-10-22 11:30:53.771335569+00:00,10,40,38,A,B,0,,0,194,202490,33699,,,0,0,0,0,,,0,0,0,0,,,0,0,0,0,,,0,0,0,0,,,0,0,0,0,,,0,0,0,0,,,0,0,0,0,,,0,0,0,0,,,0,0,0,0,,,0,0,0,0,AAPL
2024-10-22 11:30:56.523131342+00:00,10,40,38,A,N,0,235.7,200,194,202994,33740,234.77,235.7,200,200,0,0,,,0,0,0,0,,,0,0,0,0,,,0,0,0,0,,,0,0,0,0,,,0,0,0,0,,,0,0,0,0,,,0,0,0,0,,,0,0,0,0,,,0,0,0,0,AAPL
2024-10-22 11:30:56.726362298+00:00,10,40,38,A,A,0,,0,194,202765,33750,234.77,,200,0,0,0,,,0,0,0,0,,,0,0,0,0,,,0,0,0,0,,,0,0,0,0,,,0,0,0,0,,,0,0,0,0,,,0,0,0,0,,,0,0,0,0,,,0,0,0,0,AAPL
2024-10-22 11:30:56.726497183+00:00,10,40,38,A,B,0,,0,194,202757,33751,,,0,0,0,0,,,0,0,0,0,,,0,0,0,0,,,0,0,0,0,,,0,0,0,0,,,0,0,0,0,,,0,0,0,0,,,0,0,0,0,,,0,0,0,0,,,0,0,0,0,AAPL
2024-10-22 11:30:57.532839740+00:00,10,40,38,A,B,0,,0,194,202836,33763,234.77,,200,0,0,0,,,0,0,0,0,,,0,0,0,0,,,0,0,0,0,,,0,0,0,0,,,0,0,0,0,,,0,0,0,0,,,0,0,0,0,,,0,0,0,0,,,0,0,0,0,AAPL
2024-10-22 11:30:57.836363457+00:00,10,40,38,A,B,0,,0,194,202785,33767,,,0,0,0,0,,,0,0,0,0,,,0,0,0,0,,,0,0,0,0,,,0,0,0,0,,,0,0,0,0,,,0,0,0,0,,,0,0,0,0,,,0,0,0,0,,,0,0,0,0,AAPL
2024-10-22 11:31:00.589327357+00:00,10,39,38,A,A,0,237.2,2000,130,203471,26109,,237.2,0,2000,0,1,,237.4,0,2000,0,1,,,0,0,0,0,,,0,0,0,0,,,0,0,0,0,,,0,0,0,0,,,0,0,0,0,,,0,0,0,0,,,0,0,0,0,,,0,0,0,0,AAPL
2024-10-22 11:31:00.589506217+00:00,10,39,38,C,A,1,237.4,2000,130,203280,26110,,237.2,0,2000,0,1,,,0,0,0,0,,,0,0,0,0,,,0,0,0,0,,,0,0,0,0,,,0,0,0,0,,,0,0,0,0,,,0,0,0,0,,,0,0,0,0,,,0,0,0,0,AAPL
2024-10-22 11:31:06.459812836+00:00,10,40,38,A,B,0,,0,194,202937,34063,234.77,,200,0,0,0,,,0,0,0,0,,,0,0,0,0,,,0,0,0,0,,,0,0,0,0,,,0,0,0,0,,,0,0,0,0,,,0,0,0,0,,,0,0,0,0,,,0,0,0,0,AAPL
2024-10-22 11:31:06.459936442+00:00,10,40,38,A,A,0,235.69,200,194,202752,34064,234.77,235.69,200,200,0,0,,,0,0,0,0,,,0,0,0,0,,,0,0,0,0,,,0,0,0,0,,,0,0,0,0,,,0,0,0,0,,,0,0,0,0,,,0,0,0,0,,,0,0,0,0,AAPL
2024-10-22 11:31:06.917633722+00:00,10,40,38,A,A,0,,0,194,202992,34073,234.77,,200,0,0,0,,,0,0,0,0,,,0,0,0,0,,,0,0,0,0,,,0,0,0,0,,,0,0,0,0,,,0,0,0,0,,,0,0,0,0,,,0,0,0,0,,,0,0,0,0,AAPL
2024-10-22 11:31:07.301033355+00:00,10,40,38,A,B,0,,0,194,202657,34083,,,0,0,0,0,,,0,0,0,0,,,0,0,0,0,,,0,0,0,0,,,0,0,0,0,,,0,0,0,0,,,0,0,0,0,,,0,0,0,0,,,0,0,0,0,,,0,0,0,0,AAPL
2024-10-22 11:31:11.215109350+00:00,10,40,38,A,B,0,,0,194,202846,34151,234.77,,200,0,0,0,,,0,0,0,0,,,0,0,0,0,,,0,0,0,0,,,0,0,0,0,,,0,0,0,0,,,0,0,0,0,,,0,0,0,0,,,0,0,0,0,,,0,0,0,0,AAPL
2024-10-22 11:31:11.215121524+00:00,10,40,38,A,A,0,235.69,200,194,202824,34152,234.77,235.69,200,200,0,0,,,0,0,0,0,,,0,0,0,0,,,0,0,0,0,,,0,0,0,0,,,0,0,0,0,,,0,0,0,0,,,0,0,0,0,,,0,0,0,0,,,0,0,0,0,AAPL
2024-10-22 11:31:11.279694027+00:00,10,39,38,C,A,0,237.2,2000,130,203535,26146,,,0,0,0,0,,,0,0,0,0,,,0,0,0,0,,,0,0,0,0,,,0,0,0,0,,,0,0,0,0,,,0,0,0,0,,,0,0,0,0,,,0,0,0,0,,,0,0,0,0,AAPL
2024-10-22 11:31:11.339932791+00:00,10,39,38,A,B,0,232.8,2000,130,203365,26147,232.8,,2000,0,1,0,,,0,0,0,0,,,0,0,0,0,,,0,0,0,0,,,0,0,0,0,,,0,0,0,0,,,0,0,0,0,,,0,0,0,0,,,0,0,0,0,,,0,0,0,0,AAPL
2024-10-22 11:31:11.340022414+00:00,10,40,38,A,A,0,,0,194,202805,34155,234.77,,200,0,0,0,,,0,0,0,0,,,0,0,0,0,,,0,0,0,0,,,0,0,0,0,,,0,0,0,0,,,0,0,0,0,,,0,0,0,0,,,0,0,0,0,,,0,0,0,0,AAPL
2024-10-22 11:31:11.418414806+00:00,10,40,38,A,A,0,235.58,200,194,202872,34156,234.77,235.58,200,200,0,0,,,0,0,0,0,,,0,0,0,0,,,0,0,0,0,,,0,0,0,0,,,0,0,0,0,,,0,0,0,0,,,0,0,0,0,,,0,0,0,0,,,0,0,0,0,AAPL
2024-10-22 11:31:11.487206159+00:00,10,39,38,A,A,0,237.4,2000,130,203568,26148,232.8,237.4,2000,2000,1,1,,,0,0,0,0,,,0,0,0,0,,,0,0,0,0,,,0,0,0,0,,,0,0,0,0,,,0,0,0,0,,,0,0,0,0,,,0,0,0,0,,,0,0,0,0,AAPL
2024-10-22 11:31:11.498223461+00:00,10,39,38,C,A,0,237.4,2000,130,203235,26149,232.8,,2000,0,1,0,,,0,0,0,0,,,0,0,0,0,,,0,0,0,0,,,0,0,0,0,,,0,0,0,0,,,0,0,0,0,,,0,0,0,0,,,0,0,0,0,,,0,0,0,0,AAPL
2024-10-22 11:31:11.509445443+00:00,10,39,38,A,A,0,237.6,2000,130,203283,26150,232.8,237.6,2000,2000,1,1,,,0,0,0,0,,,0,0,0,0,,,0,0,0,0,,,0,0,0,0,,,0,0,0,0,,,0,0,0,0,,,0,0,0,0,,,0,0,0,0,,,0,0,0,0,AAPL
2024-10-22 11:31:11.536017985+00:00,10,39,38,A,A,0,237.4,2000,130,203257,26151,232.8,237.4,2000,2000,1,1,,237.6,0,2000,0,1,,,0,0,0,0,,,0,0,0,0,,,0,0,0,0,,,0,0,0,0,,,0,0,0,0,,,0,0,0,0,,,0,0,0,0,,,0,0,0,0,AAPL
2024-10-22 11:31:11.536188343+00:00,10,39,38,C,A,1,237.6,2000,130,203166,26152,232.8,237.4,2000,2000,1,1,,,0,0,0,0,,,0,0,0,0,,,0,0,0,0,,,0,0,0,0,,,0,0,0,0,,,0,0,0,0,,,0,0,0,0,,,0,0,0,0,,,0,0,0,0,AAPL
2024-10-22 11:31:11.559562836+00:00,10,39,38,C,A,0,237.4,2000,130,203280,26153,232.8,,2000,0,1,0,,,0,0,0,0,,,0,0,0,0,,,0,0,0,0,,,0,0,0,0,,,0,0,0,0,,,0,0,0,0,,,0,0,0,0,,,0,0,0,0,,,0,0,0,0,AAPL
2024-10-22 11:31:11.573320398+00:00,10,39,38,A,A,0,237.4,2000,130,203284,26154,232.8,237.4,2000,2000,1,1,,,0,0,0,0,,,0,0,0,0,,,0,0,0,0,,,0,0,0,0,,,0,0,0,0,,,0,0,0,0,,,0,0,0,0,,,0,0,0,0,,,0,0,0,0,AAPL
2024-10-22 11:31:11.879608951+00:00,10,40,38,A,B,0,235.58,200,194,202936,34159,,235.58,0,200,0,0,,,0,0,0,0,,,0,0,0,0,,,0,0,0,0,,,0,0,0,0,,,0,0,0,0,,,0,0,0,0,,,0,0,0,0,,,0,0,0,0,,,0,0,0,0,AAPL
2024-10-22 11:31:11.879729376+00:00,10,40,38,A,A,0,,0,194,202944,34160,,,0,0,0,0,,,0,0,0,0,,,0,0,0,0,,,0,0,0,0,,,0,0,0,0,,,0,0,0,0,,,0,0,0,0,,,0,0,0,0,,,0,0,0,0,,,0,0,0,0,AAPL
2024-10-22 11:31:11.879746956+00:00,10,40,38,A,A,0,235.69,200,194,202910,34161,,235.69,0,200,0,0,,,0,0,0,0,,,0,0,0,0,,,0,0,0,0,,,0,0,0,0,,,0,0,0,0,,,0,0,0,0,,,0,0,0,0,,,0,0,0,0,,,0,0,0,0,AAPL
2024-10-22 11:31:13.176918684+00:00,10,40,38,A,A,0,,0,194,202942,34175,,,0,0,0,0,,,0,0,0,0,,,0,0,0,0,,,0,0,0,0,,,0,0,0,0,,,0,0,0,0,,,0,0,0,0,,,0,0,0,0,,,0,0,0,0,,,0,0,0,0,AAPL
2024-10-22 11:31:13.177687570+00:00,10,39,38,C,A,0,237.4,2000,130,203367,26160,232.8,,2000,0,1,0,,,0,0,0,0,,,0,0,0,0,,,0,0,0,0,,,0,0,0,0,,,0,0,0,0,,,0,0,0,0,,,0,0,0,0,,,0,0,0,0,,,0,0,0,0,AAPL
2024-10-22 11:31:13.188310451+00:00,10,39,38,A,A,0,237.2,2000,130,203327,26161,232.8,237.2,2000,2000,1,1,,,0,0,0,0,,,0,0,0,0,,,0,0,0,0,,,0,0,0,0,,,0,0,0,0,,,0,0,0,0,,,0,0,0,0,,,0,0,0,0,,,0,0,0,0,AAPL
2024-10-22 11:31:13.485417041+00:00,10,40,38,A,B,0,,0,194,203038,34182,234.68,,200,0,0,0,,,0,0,0,0,,,0,0,0,0,,,0,0,0,0,,,0,0,0,0,,,0,0,0,0,,,0,0,0,0,,,0,0,0,0,,,0,0,0,0,,,0,0,0,0,AAPL
2024-10-22 11:31:13.485423864+00:00,10,40,38,A,A,0,235.7,200,194,202931,34183,234.68,235.7,200,200,0,0,,,0,0,0,0,,,0,0,0,0,,,0,0,0,0,,,0,0,0,0,,,0,0,0,0,,,0,0,0,0,,,0,0,0,0,,,0,0,0,0,,,0,0,0,0,AAPL
2024-10-22 11:31:13.680761827+00:00,10,40,38,A,B,0,235.7,200,194,202925,34184,,235.7,0,200,0,0,,,0,0,0,0,,,0,0,0,0,,,0,0,0,0,,,0,0,0,0,,,0,0,0,0,,,0,0,0,0,,,0,0,0,0,,,0,0,0,0,,,0,0,0,0,AAPL
2024-10-22 11:31:13.680916846+00:00,10,40,38,A,A,0,,0,194,202965,34185,,,0,0,0,0,,,0,0,0,0,,,0,0,0,0,,,0,0,0,0,,,0,0,0,0,,,0,0,0,0,,,0,0,0,0,,,0,0,0,0,,,0,0,0,0,,,0,0,0,0,AAPL
2024-10-22 11:31:19.202393579+00:00,10,40,38,A,B,0,,0,194,203259,34244,234.68,,200,0,0,0,,,0,0,0,0,,,0,0,0,0,,,0,0,0,0,,,0,0,0,0,,,0,0,0,0,,,0,0,0,0,,,0,0,0,0,,,0,0,0,0,,,0,0,0,0,AAPL
2024-10-22 11:31:19.202400251+00:00,10,40,38,A,A,0,235.7,200,194,202998,34245,234.68,235.7,200,200,0,0,,,0,0,0,0,,,0,0,0,0,,,0,0,0,0,,,0,0,0,0,,,0,0,0,0,,,0,0,0,0,,,0,0,0,0,,,0,0,0,0,,,0,0,0,0,AAPL
2024-10-22 11:31:19.696800309+00:00,10,40,38,A,B,0,235.7,200,194,202935,34261,,235.7,0,200,0,0,,,0,0,0,0,,,0,0,0,0,,,0,0,0,0,,,0,0,0,0,,,0,0,0,0,,,0,0,0,0,,,0,0,0,0,,,0,0,0,0,,,0,0,0,0,AAPL
2024-10-22 11:31:20.314076408+00:00,10,40,38,A,B,0,235.7,200,194,202965,34268,234.68,235.7,200,200,0,0,,,0,0,0,0,,,0,0,0,0,,,0,0,0,0,,,0,0,0,0,,,0,0,0,0,,,0,0,0,0,,,0,0,0,0,,,0,0,0,0,,,0,0,0,0,AAPL
2024-10-22 11:31:20.611562334+00:00,10,40,38,A,B,0,235.7,200,194,203432,34273,,235.7,0,200,0,0,,,0,0,0,0,,,0,0,0,0,,,0,0,0,0,,,0,0,0,0,,,0,0,0,0,,,0,0,0,0,,,0,0,0,0,,,0,0,0,0,,,0,0,0,0,AAPL
2024-10-22 11:31:23.236362488+00:00,10,40,38,A,B,0,235.7,200,194,202984,34307,234.68,235.7,200,200,0,0,,,0,0,0,0,,,0,0,0,0,,,0,0,0,0,,,0,0,0,0,,,0,0,0,0,,,0,0,0,0,,,0,0,0,0,,,0,0,0,0,,,0,0,0,0,AAPL
2024-10-22 11:31:29.088935449+00:00,10,40,38,A,B,0,235.7,200,194,203121,34375,,235.7,0,200,0,0,,,0,0,0,0,,,0,0,0,0,,,0,0,0,0,,,0,0,0,0,,,0,0,0,0,,,0,0,0,0,,,0,0,0,0,,,0,0,0,0,,,0,0,0,0,AAPL
2024-10-22 11:31:29.153515755+00:00,10,39,38,C,B,0,232.8,2000,130,203372,26216,,237.2,0,2000,0,1,,,0,0,0,0,,,0,0,0,0,,,0,0,0,0,,,0,0,0,0,,,0,0,0,0,,,0,0,0,0,,,0,0,0,0,,,0,0,0,0,,,0,0,0,0,AAPL
2024-10-22 11:31:40.486364606+00:00,10,40,38,A,B,0,235.7,200,194,203535,34494,234.71,235.7,200,200,0,0,,,0,0,0,0,,,0,0,0,0,,,0,0,0,0,,,0,0,0,0,,,0,0,0,0,,,0,0,0,0,,,0,0,0,0,,,0,0,0,0,,,0,0,0,0,AAPL
2024-10-22 11:31:40.586349105+00:00,10,40,38,A,B,0,235.7,200,194,203445,34495,,235.7,0,200,0,0,,,0,0,0,0,,,0,0,0,0,,,0,0,0,0,,,0,0,0,0,,,0,0,0,0,,,0,0,0,0,,,0,0,0,0,,,0,0,0,0,,,0,0,0,0,AAPL
2024-10-22 11:31:40.788206056+00:00,10,40,38,A,B,0,235.7,200,194,203491,34498,234.71,235.7,200,200,0,0,,,0,0,0,0,,,0,0,0,0,,,0,0,0,0,,,0,0,0,0,,,0,0,0,0,,,0,0,0,0,,,0,0,0,0,,,0,0,0,0,,,0,0,0,0,AAPL
2024-10-22 11:31:41.630777970+00:00,10,40,38,A,B,0,235.7,200,194,203491,34512,,235.7,0,200,0,0,,,0,0,0,0,,,0,0,0,0,,,0,0,0,0,,,0,0,0,0,,,0,0,0,0,,,0,0,0,0,,,0,0,0,0,,,0,0,0,0,,,0,0,0,0,AAPL
2024-10-22 11:31:46.828528490+00:00,10,40,38,A,B,0,235.7,200,194,203881,34575,234.71,235.7,200,200,0,0,,,0,0,0,0,,,0,0,0,0,,,0,0,0,0,,,0,0,0,0,,,0,0,0,0,,,0,0,0,0,,,0,0,0,0,,,0,0,0,0,,,0,0,0,0,AAPL
2024-10-22 11:31:54.622368898+00:00,10,40,38,A,B,0,235.7,200,194,203682,34637,,235.7,0,200,0,0,,,0,0,0,0,,,0,0,0,0,,,0,0,0,0,,,0,0,0,0,,,0,0,0,0,,,0,0,0,0,,,0,0,0,0,,,0,0,0,0,,,0,0,0,0,AAPL
2024-10-22 11:31:54.622444756+00:00,10,40,38,A,B,0,235.7,200,194,203486,34638,234.71,235.7,200,200,0,0,,,0,0,0,0,,,0,0,0,0,,,0,0,0,0,,,0,0,0,0,,,0,0,0,0,,,0,0,0,0,,,0,0,0,0,,,0,0,0,0,,,0,0,0,0,AAPL
2024-10-22 11:31:54.686401566+00:00,10,39,38,C,A,0,237.2,2000,130,204156,26342,,,0,0,0,0,,,0,0,0,0,,,0,0,0,0,,,0,0,0,0,,,0,0,0,0,,,0,0,0,0,,,0,0,0,0,,,0,0,0,0,,,0,0,0,0,,,0,0,0,0,AAPL
2024-10-22 11:31:54.697180229+00:00,10,39,38,A,A,0,237.6,2000,130,203675,26343,,237.6,0,2000,0,1,,,0,0,0,0,,,0,0,0,0,,,0,0,0,0,,,0,0,0,0,,,0,0,0,0,,,0,0,0,0,,,0,0,0,0,,,0,0,0,0,,,0,0,0,0,AAPL
2024-10-22 11:31:56.050315156+00:00,10,39,38,A,B,0,232.8,2000,130,203742,26347,232.8,237.6,2000,2000,1,1,,,0,0,0,0,,,0,0,0,0,,,0,0,0,0,,,0,0,0,0,,,0,0,0,0,,,0,0,0,0,,,0,0,0,0,,,0,0,0,0,,,0,0,0,0,AAPL
2024-10-22 11:31:57.294792131+00:00,10,39,38,A,A,0,237.2,2000,130,203737,26352,232.8,237.2,2000,2000,1,1,,237.6,0,2000,0,1,,,0,0,0,0,,,0,0,0,0,,,0,0,0,0,,,0,0,0,0,,,0,0,0,0,,,0,0,0,0,,,0,0,0,0,,,0,0,0,0,AAPL
2024-10-22 11:31:57.294792400+00:00,10,39,38,A,B,0,233.2,2000,130,203494,26353,233.2,237.2,2000,2000,1,1,232.8,237.6,2000,2000,1,1,,,0,0,0,0,,,0,0,0,0,,,0,0,0,0,,,0,0,0,0,,,0,0,0,0,,,0,0,0,0,,,0,0,0,0,,,0,0,0,0,AAPL
2024-10-22 11:31:57.294836573+00:00,10,39,38,C,A,1,237.6,2000,130,203476,26354,233.2,237.2,2000,2000,1,1,232.8,,2000,0,1,0,,,0,0,0,0,,,0,0,0,0,,,0,0,0,0,,,0,0,0,0,,,0,0,0,0,,,0,0,0,0,,,0,0,0,0,,,0,0,0,0,AAPL
2024-10-22 11:31:57.294838810+00:00,10,39,38,C,B,1,232.8,2000,130,203588,26355,233.2,237.2,2000,2000,1,1,,,0,0,0,0,,,0,0,0,0,,,0,0,0,0,,,0,0,0,0,,,0,0,0,0,,,0,0,0,0,,,0,0,0,0,,,0,0,0,0,,,0,0,0,0,AAPL
2024-10-22 11:32:00.024419124+00:00,10,40,38,A,B,0,235.7,200,194,203313,34715,,235.7,0,200,0,0,,,0,0,0,0,,,0,0,0,0,,,0,0,0,0,,,0,0,0,0,,,0,0,0,0,,,0,0,0,0,,,0,0,0,0,,,0,0,0,0,,,0,0,0,0,AAPL
2024-10-22 11:32:00.024430438+00:00,10,40,38,A,A,0,,0,194,203303,34716,,,0,0,0,0,,,0,0,0,0,,,0,0,0,0,,,0,0,0,0,,,0,0,0,0,,,0,0,0,0,,,0,0,0,0,,,0,0,0,0,,,0,0,0,0,,,0,0,0,0,AAPL
2024-10-22 11:32:00.074063272+00:00,10,40,38,A,A,0,235.68,200,194,203299,34773,,235.68,0,200,0,0,,,0,0,0,0,,,0,0,0,0,,,0,0,0,0,,,0,0,0,0,,,0,0,0,0,,,0,0,0,0,,,0,0,0,0,,,0,0,0,0,,,0,0,0,0,AAPL
2024-10-22 11:32:00.964802118+00:00,10,40,38,A,A,0,,0,194,203347,34899,,,0,0,0,0,,,0,0,0,0,,,0,0,0,0,,,0,0,0,0,,,0,0,0,0,,,0,0,0,0,,,0,0,0,0,,,0,0,0,0,,,0,0,0,0,,,0,0,0,0,AAPL
2024-10-22 11:32:02.265582404+00:00,10,39,38,C,B,0,233.2,2000,130,203652,26378,,237.2,0,2000,0,1,,,0,0,0,0,,,0,0,0,0,,,0,0,0,0,,,0,0,0,0,,,0,0,0,0,,,0,0,0,0,,,0,0,0,0,,,0,0,0,0,,,0,0,0,0,AAPL
2024-10-22 11:32:02.276325273+00:00,10,39,38,A,B,0,233.0,2000,130,203582,26379,233.0,237.2,2000,2000,1,1,,,0,0,0,0,,,0,0,0,0,,,0,0,0,0,,,0,0,0,0,,,0,0,0,0,,,0,0,0,0,,,0,0,0,0,,,0,0,0,0,,,0,0,0,0,AAPL
2024-10-22 11:32:07.564288887+00:00,10,40,38,A,N,0,235.68,200,194,204212,34987,234.75,235.68,200,200,0,0,,,0,0,0,0,,,0,0,0,0,,,0,0,0,0,,,0,0,0,0,,,0,0,0,0,,,0,0,0,0,,,0,0,0,0,,,0,0,0,0,,,0,0,0,0,AAPL
2024-10-22 11:32:08.314089106+00:00,10,39,38,A,A,0,237.0,2000,130,204172,26396,233.0,237.0,2000,2000,1,1,,237.2,0,2000,0,1,,,0,0,0,0,,,0,0,0,0,,,0,0,0,0,,,0,0,0,0,,,0,0,0,0,,,0,0,0,0,,,0,0,0,0,,,0,0,0,0,AAPL
2024-10-22 11:32:08.314291641+00:00,10,39,38,C,A,1,237.2,2000,130,203590,26397,233.0,237.0,2000,2000,1,1,,,0,0,0,0,,,0,0,0,0,,,0,0,0,0,,,0,0,0,0,,,0,0,0,0,,,0,0,0,0,,,0,0,0,0,,,0,0,0,0,,,0,0,0,0,AAPL
2024-10-22 11:32:10.191760742+00:00,10,39,38,C,B,0,233.0,2000,130,204058,26405,,237.0,0,2000,0,1,,,0,0,0,0,,,0,0,0,0,,,0,0,0,0,,,0,0,0,0,,,0,0,0,0,,,0,0,0,0,,,0,0,0,0,,,0,0,0,0,,,0,0,0,0,AAPL
2024-10-22 11:32:10.205235225+00:00,10,39,38,A,B,0,232.8,2000,130,203780,26406,232.8,237.0,2000,2000,1,1,,,0,0,0,0,,,0,0,0,0,,,0,0,0,0,,,0,0,0,0,,,0,0,0,0,,,0,0,0,0,,,0,0,0,0,,,0,0,0,0,,,0,0,0,0,AAPL
2024-10-22 11:32:13.094466790+00:00,10,39,38,A,B,0,233.0,2000,130,203959,26422,233.0,237.0,2000,2000,1,1,232.8,,2000,0,1,0,,,0,0,0,0,,,0,0,0,0,,,0,0,0,0,,,0,0,0,0,,,0,0,0,0,,,0,0,0,0,,,0,0,0,0,,,0,0,0,0,AAPL
2024-10-22 11:32:13.094742816+00:00,10,39,38,C,B,1,232.8,2000,130,203718,26423,233.0,237.0,2000,2000,1,1,,,0,0,0,0,,,0,0,0,0,,,0,0,0,0,,,0,0,0,0,,,0,0,0,0,,,0,0,0,0,,,0,0,0,0,,,0,0,0,0,,,0,0,0,0,AAPL
2024-10-22 11:32:20.912023131+00:00,10,39,38,C,B,0,233.0,2000,130,203623,26466,,237.0,0,2000,0,1,,,0,0,0,0,,,0,0,0,0,,,0,0,0,0,,,0,0,0,0,,,0,0,0,0,,,0,0,0,0,,,0,0,0,0,,,0,0,0,0,,,0,0,0,0,AAPL
2024-10-22 11:32:20.923399752+00:00,10,39,38,A,B,0,232.8,2000,130,203507,26467,232.8,237.0,2000,2000,1,1,,,0,0,0,0,,,0,0,0,0,,,0,0,0,0,,,0,0,0,0,,,0,0,0,0,,,0,0,0,0,,,0,0,0,0,,,0,0,0,0,,,0,0,0,0,AAPL
2024-10-22 11:32:40.180634890+00:00,10,39,38,A,B,0,233.0,2000,130,203565,26570,233.0,237.0,2000,2000,1,1,232.8,,2000,0,1,0,,,0,0,0,0,,,0,0,0,0,,,0,0,0,0,,,0,0,0,0,,,0,0,0,0,,,0,0,0,0,,,0,0,0,0,,,0,0,0,0,AAPL
2024-10-22 11:32:40.180821062+00:00,10,39,38,C,B,1,232.8,2000,130,203480,26571,233.0,237.0,2000,2000,1,1,,,0,0,0,0,,,0,0,0,0,,,0,0,0,0,,,0,0,0,0,,,0,0,0,0,,,0,0,0,0,,,0,0,0,0,,,0,0,0,0,,,0,0,0,0,AAPL
2024-10-22 11:32:59.454651379+00:00,10,39,38,C,B,0,233.0,2000,130,203387,26657,,237.0,0,2000,0,1,,,0,0,0,0,,,0,0,0,0,,,0,0,0,0,,,0,0,0,0,,,0,0,0,0,,,0,0,0,0,,,0,0,0,0,,,0,0,0,0,,,0,0,0,0,AAPL
2024-10-22 11:32:59.465431662+00:00,10,39,38,A,B,0,232.8,2000,130,203128,26658,232.8,237.0,2000,2000,1,1,,,0,0,0,0,,,0,0,0,0,,,0,0,0,0,,,0,0,0,0,,,0,0,0,0,,,0,0,0,0,,,0,0,0,0,,,0,0,0,0,,,0,0,0,0,AAPL
2024-10-22 11:33:00.031501799+00:00,10,40,38,A,B,0,235.68,200,194,204767,35478,,235.68,0,200,0,0,,,0,0,0,0,,,0,0,0,0,,,0,0,0,0,,,0,0,0,0,,,0,0,0,0,,,0,0,0,0,,,0,0,0,0,,,0,0,0,0,,,0,0,0,0,AAPL
2024-10-22 11:33:00.043719925+00:00,10,40,38,A,B,0,235.68,200,194,204543,35494,234.73,235.68,200,200,0,0,,,0,0,0,0,,,0,0,0,0,,,0,0,0,0,,,0,0,0,0,,,0,0,0,0,,,0,0,0,0,,,0,0,0,0,,,0,0,0,0,,,0,0,0,0,AAPL
2024-10-22 11:33:26.645334394+00:00,10,39,38,A,B,0,233.0,2000,130,202935,26882,233.0,237.0,2000,2000,1,1,232.8,,2000,0,1,0,,,0,0,0,0,,,0,0,0,0,,,0,0,0,0,,,0,0,0,0,,,0,0,0,0,,,0,0,0,0,,,0,0,0,0,,,0,0,0,0,AAPL
2024-10-22 11:33:26.645555113+00:00,10,39,38,C,B,1,232.8,2000,130,202873,26883,233.0,237.0,2000,2000,1,1,,,0,0,0,0,,,0,0,0,0,,,0,0,0,0,,,0,0,0,0,,,0,0,0,0,,,0,0,0,0,,,0,0,0,0,,,0,0,0,0,,,0,0,0,0,AAPL
2024-10-22 11:33:26.714824821+00:00,10,39,38,C,B,0,233.0,2000,130,203028,26884,,237.0,0,2000,0,1,,,0,0,0,0,,,0,0,0,0,,,0,0,0,0,,,0,0,0,0,,,0,0,0,0,,,0,0,0,0,,,0,0,0,0,,,0,0,0,0,,,0,0,0,0,AAPL
2024-10-22 11:33:26.751362503+00:00,10,39,38,A,B,0,233.0,2000,130,203009,26885,233.0,237.0,2000,2000,1,1,,,0,0,0,0,,,0,0,0,0,,,0,0,0,0,,,0,0,0,0,,,0,0,0,0,,,0,0,0,0,,,0,0,0,0,,,0,0,0,0,,,0,0,0,0,AAPL
2024-10-22 11:33:47.396711256+00:00,10,39,38,A,B,0,233.2,2000,130,204035,27098,233.2,237.0,2000,2000,1,1,233.0,,2000,0,1,0,,,0,0,0,0,,,0,0,0,0,,,0,0,0,0,,,0,0,0,0,,,0,0,0,0,,,0,0,0,0,,,0,0,0,0,,,0,0,0,0,AAPL
2024-10-22 11:33:47.396879513+00:00,10,39,38,C,B,1,233.0,2000,130,203696,27099,233.2,237.0,2000,2000,1,1,,,0,0,0,0,,,0,0,0,0,,,0,0,0,0,,,0,0,0,0,,,0,0,0,0,,,0,0,0,0,,,0,0,0,0,,,0,0,0,0,,,0,0,0,0,AAPL
2024-10-22 11:34:00.005257330+00:00,10,40,38,A,B,0,235.68,200,194,203110,36298,,235.68,0,200,0,0,,,0,0,0,0,,,0,0,0,0,,,0,0,0,0,,,0,0,0,0,,,0,0,0,0,,,0,0,0,0,,,0,0,0,0,,,0,0,0,0,,,0,0,0,0,AAPL
2024-10-22 11:34:00.098384464+00:00,10,40,38,A,B,0,235.68,200,194,203010,36383,234.77,235.68,200,200,0,0,,,0,0,0,0,,,0,0,0,0,,,0,0,0,0,,,0,0,0,0,,,0,0,0,0,,,0,0,0,0,,,0,0,0,0,,,0,0,0,0,,,0,0,0,0,AAPL
2024-10-22 11:34:04.854652417+00:00,10,39,38,C,B,0,233.2,2000,130,204083,27181,,237.0,0,2000,0,1,,,0,0,0,0,,,0,0,0,0,,,0,0,0,0,,,0,0,0,0,,,0,0,0,0,,,0,0,0,0,,,0,0,0,0,,,0,0,0,0,,,0,0,0,0,AAPL
2024-10-22 11:34:04.891333599+00:00,10,39,38,A,B,0,232.8,2000,130,203731,27182,232.8,237.0,2000,2000,1,1,,,0,0,0,0,,,0,0,0,0,,,0,0,0,0,,,0,0,0,0,,,0,0,0,0,,,0,0,0,0,,,0,0,0,0,,,0,0,0,0,,,0,0,0,0,AAPL
2024-10-22 11:34:04.920438022+00:00,10,39,38,C,A,0,237.0,2000,130,203608,27183,232.8,,2000,0,1,0,,,0,0,0,0,,,0,0,0,0,,,0,0,0,0,,,0,0,0,0,,,0,0,0,0,,,0,0,0,0,,,0,0,0,0,,,0,0,0,0,,,0,0,0,0,AAPL
2024-10-22 11:34:04.931798010+00:00,10,39,38,A,A,0,237.0,2000,130,203625,27184,232.8,237.0,2000,2000,1,1,,,0,0,0,0,,,0,0,0,0,,,0,0,0,0,,,0,0,0,0,,,0,0,0,0,,,0,0,0,0,,,0,0,0,0,,,0,0,0,0,,,0,0,0,0,AAPL
2024-10-22 11:34:42.143664290+00:00,10,39,38,A,B,0,233.0,2000,130,204185,27429,233.0,237.0,2000,2000,1,1,232.8,,2000,0,1,0,,,0,0,0,0,,,0,0,0,0,,,0,0,0,0,,,0,0,0,0,,,0,0,0,0,,,0,0,0,0,,,0,0,0,0,,,0,0,0,0,AAPL
2024-10-22 11:34:42.143849089+00:00,10,39,38,C,B,1,232.8,2000,130,204269,27430,233.0,237.0,2000,2000,1,1,,,0,0,0,0,,,0,0,0,0,,,0,0,0,0,,,0,0,0,0,,,0,0,0,0,,,0,0,0,0,,,0,0,0,0,,,0,0,0,0,,,0,0,0,0,AAPL
2024-10-22 11:34:43.470654954+00:00,10,39,38,A,B,0,233.2,2000,130,204124,27436,233.2,237.0,2000,2000,1,1,233.0,,2000,0,1,0,,,0,0,0,0,,,0,0,0,0,,,0,0,0,0,,,0,0,0,0,,,0,0,0,0,,,0,0,0,0,,,0,0,0,0,,,0,0,0,0,AAPL
2024-10-22 11:34:43.471378778+00:00,10,39,38,C,B,1,233.0,2000,130,203826,27437,233.2,237.0,2000,2000,1,1,,,0,0,0,0,,,0,0,0,0,,,0,0,0,0,,,0,0,0,0,,,0,0,0,0,,,0,0,0,0,,,0,0,0,0,,,0,0,0,0,,,0,0,0,0,AAPL
2024-10-22 11:34:45.233688383+00:00,10,39,38,C,B,0,233.2,2000,130,204231,27441,,237.0,0,2000,0,1,,,0,0,0,0,,,0,0,0,0,,,0,0,0,0,,,0,0,0,0,,,0,0,0,0,,,0,0,0,0,,,0,0,0,0,,,0,0,0,0,,,0,0,0,0,AAPL
2024-10-22 11:34:45.245017156+00:00,10,39,38,A,B,0,233.2,2000,130,203777,27442,233.2,237.0,2000,2000,1,1,,,0,0,0,0,,,0,0,0,0,,,0,0,0,0,,,0,0,0,0,,,0,0,0,0,,,0,0,0,0,,,0,0,0,0,,,0,0,0,0,,,0,0,0,0,AAPL
2024-10-22 11:34:45.260425469+00:00,10,39,38,C,B,0,233.2,2000,130,203724,27443,,237.0,0,2000,0,1,,,0,0,0,0,,,0,0,0,0,,,0,0,0,0,,,0,0,0,0,,,0,0,0,0,,,0,0,0,0,,,0,0,0,0,,,0,0,0,0,,,0,0,0,0,AAPL
2024-10-22 11:34:45.271395554+00:00,10,39,38,A,B,0,232.8,2000,130,203774,27444,232.8,237.0,2000,2000,1,1,,,0,0,0,0,,,0,0,0,0,,,0,0,0,0,,,0,0,0,0,,,0,0,0,0,,,0,0,0,0,,,0,0,0,0,,,0,0,0,0,,,0,0,0,0,AAPL
2024-10-22 11:34:52.914664518+00:00,10,39,38,C,B,0,232.8,2000,130,204471,27468,,237.0,0,2000,0,1,,,0,0,0,0,,,0,0,0,0,,,0,0,0,0,,,0,0,0,0,,,0,0,0,0,,,0,0,0,0,,,0,0,0,0,,,0,0,0,0,,,0,0,0,0,AAPL
2024-10-22 11:34:52.915099668+00:00,10,39,38,C,A,0,237.0,2000,130,203983,27469,,,0,0,0,0,,,0,0,0,0,,,0,0,0,0,,,0,0,0,0,,,0,0,0,0,,,0,0,0,0,,,0,0,0,0,,,0,0,0,0,,,0,0,0,0,,,0,0,0,0,AAPL
2024-10-22 11:34:52.960438385+00:00,10,39,38,A,A,0,237.0,2000,130,204074,27470,,237.0,0,2000,0,1,,,0,0,0,0,,,0,0,0,0,,,0,0,0,0,,,0,0,0,0,,,0,0,0,0,,,0,0,0,0,,,0,0,0,0,,,0,0,0,0,,,0,0,0,0,AAPL
2024-10-22 11:34:52.962828959+00:00,10,39,38,A,B,0,233.0,2000,130,204028,27471,233.0,237.0,2000,2000,1,1,,,0,0,0,0,,,0,0,0,0,,,0,0,0,0,,,0,0,0,0,,,0,0,0,0,,,0,0,0,0,,,0,0,0,0,,,0,0,0,0,,,0,0,0,0,AAPL
2024-10-22 11:34:52.979159782+00:00,10,39,38,C,A,0,237.0,2000,130,203989,27472,233.0,,2000,0,1,0,,,0,0,0,0,,,0,0,0,0,,,0,0,0,0,,,0,0,0,0,,,0,0,0,0,,,0,0,0,0,,,0,0,0,0,,,0,0,0,0,,,0,0,0,0,AAPL
2024-10-22 11:34:52.992113796+00:00,10,39,38,A,A,0,237.2,2000,130,203952,27473,233.0,237.2,2000,2000,1,1,,,0,0,0,0,,,0,0,0,0,,,0,0,0,0,,,0,0,0,0,,,0,0,0,0,,,0,0,0,0,,,0,0,0,0,,,0,0,0,0,,,0,0,0,0,AAPL
2024-10-22 11:34:53.005379390+00:00,10,39,38,C,B,0,233.0,2000,130,203947,27475,,237.2,0,2000,0,1,,,0,0,0,0,,,0,0,0,0,,,0,0,0,0,,,0,0,0,0,,,0,0,0,0,,,0,0,0,0,,,0,0,0,0,,,0,0,0,0,,,0,0,0,0,AAPL
2024-10-22 11:34:53.016306897+00:00,10,39,38,A,B,0,232.8,2000,130,203967,27476,232.8,237.2,2000,2000,1,1,,,0,0,0,0,,,0,0,0,0,,,0,0,0,0,,,0,0,0,0,,,0,0,0,0,,,0,0,0,0,,,0,0,0,0,,,0,0,0,0,,,0,0,0,0,AAPL
2024-10-22 11:34:53.038283180+00:00,10,39,38,A,B,0,233.0,2000,130,203955,27477,233.0,237.2,2000,2000,1,1,232.8,,2000,0,1,0,,,0,0,0,0,,,0,0,0,0,,,0,0,0,0,,,0,0,0,0,,,0,0,0,0,,,0,0,0,0,,,0,0,0,0,,,0,0,0,0,AAPL
2024-10-22 11:34:53.039012184+00:00,10,39,38,C,B,1,232.8,2000,130,203883,27478,233.0,237.2,2000,2000,1,1,,,0,0,0,0,,,0,0,0,0,,,0,0,0,0,,,0,0,0,0,,,0,0,0,0,,,0,0,0,0,,,0,0,0,0,,,0,0,0,0,,,0,0,0,0,AAPL
2024-10-22 11:34:53.271303767+00:00,10,40,38,A,A,0,,0,194,202763,36944,234.77,,200,0,0,0,,,0,0,0,0,,,0,0,0,0,,,0,0,0,0,,,0,0,0,0,,,0,0,0,0,,,0,0,0,0,,,0,0,0,0,,,0,0,0,0,,,0,0,0,0,AAPL
2024-10-22 11:34:53.271323515+00:00,10,40,38,A,A,0,235.53,200,194,202706,36945,234.77,235.53,200,200,0,0,,,0,0,0,0,,,0,0,0,0,,,0,0,0,0,,,0,0,0,0,,,0,0,0,0,,,0,0,0,0,,,0,0,0,0,,,0,0,0,0,,,0,0,0,0,AAPL
2024-10-22 11:35:00.034222700+00:00,10,40,38,A,B,0,235.53,200,194,202608,37105,,235.53,0,200,0,0,,,0,0,0,0,,,0,0,0,0,,,0,0,0,0,,,0,0,0,0,,,0,0,0,0,,,0,0,0,0,,,0,0,0,0,,,0,0,0,0,,,0,0,0,0,AAPL
2024-10-22 11:35:00.034232216+00:00,10,40,38,A,A,0,,0,194,202631,37106,,,0,0,0,0,,,0,0,0,0,,,0,0,0,0,,,0,0,0,0,,,0,0,0,0,,,0,0,0,0,,,0,0,0,0,,,0,0,0,0,,,0,0,0,0,,,0,0,0,0,AAPL
2024-10-22 11:35:00.332637418+00:00,10,40,38,A,B,0,,0,194,202653,37311,234.64,,200,0,0,0,,,0,0,0,0,,,0,0,0,0,,,0,0,0,0,,,0,0,0,0,,,0,0,0,0,,,0,0,0,0,,,0,0,0,0,,,0,0,0,0,,,0,0,0,0,AAPL
2024-10-22 11:35:00.940929732+00:00,10,40,38,A,B,0,,0,194,202727,37339,,,0,0,0,0,,,0,0,0,0,,,0,0,0,0,,,0,0,0,0,,,0,0,0,0,,,0,0,0,0,,,0,0,0,0,,,0,0,0,0,,,0,0,0,0,,,0,0,0,0,AAPL
2024-10-22 11:35:01.724939577+00:00,10,40,38,A,B,0,,0,194,202880,37357,234.64,,200,0,0,0,,,0,0,0,0,,,0,0,0,0,,,0,0,0,0,,,0,0,0,0,,,0,0,0,0,,,0,0,0,0,,,0,0,0,0,,,0,0,0,0,,,0,0,0,0,AAPL
2024-10-22 11:35:01.724946335+00:00,10,40,38,A,A,0,235.53,200,194,202577,37358,234.64,235.53,200,200,0,0,,,0,0,0,0,,,0,0,0,0,,,0,0,0,0,,,0,0,0,0,,,0,0,0,0,,,0,0,0,0,,,0,0,0,0,,,0,0,0,0,,,0,0,0,0,AAPL
2024-10-22 11:35:01.927689120+00:00,10,40,38,A,B,0,235.53,200,194,202611,37360,,235.53,0,200,0,0,,,0,0,0,0,,,0,0,0,0,,,0,0,0,0,,,0,0,0,0,,,0,0,0,0,,,0,0,0,0,,,0,0,0,0,,,0,0,0,0,,,0,0,0,0,AAPL
2024-10-22 11:35:02.699367619+00:00,10,40,38,A,A,0,,0,194,202789,37370,,,0,0,0,0,,,0,0,0,0,,,0,0,0,0,,,0,0,0,0,,,0,0,0,0,,,0,0,0,0,,,0,0,0,0,,,0,0,0,0,,,0,0,0,0,,,0,0,0,0,AAPL
2024-10-22 11:35:04.053787498+00:00,10,40,38,A,B,0,,0,194,203044,37390,234.64,,200,0,0,0,,,0,0,0,0,,,0,0,0,0,,,0,0,0,0,,,0,0,0,0,,,0,0,0,0,,,0,0,0,0,,,0,0,0,0,,,0,0,0,0,,,0,0,0,0,AAPL
2024-10-22 11:35:04.053795761+00:00,10,40,38,A,A,0,235.53,200,194,202681,37391,234.64,235.53,200,200,0,0,,,0,0,0,0,,,0,0,0,0,,,0,0,0,0,,,0,0,0,0,,,0,0,0,0,,,0,0,0,0,,,0,0,0,0,,,0,0,0,0,,,0,0,0,0,AAPL
2024-10-22 11:35:04.054968305+00:00,10,39,38,C,B,0,233.0,2000,130,204110,27527,,237.2,0,2000,0,1,,,0,0,0,0,,,0,0,0,0,,,0,0,0,0,,,0,0,0,0,,,0,0,0,0,,,0,0,0,0,,,0,0,0,0,,,0,0,0,0,,,0,0,0,0,AAPL
2024-10-22 11:35:04.054971309+00:00,10,39,38,C,A,0,237.2,2000,130,203544,27528,,,0,0,0,0,,,0,0,0,0,,,0,0,0,0,,,0,0,0,0,,,0,0,0,0,,,0,0,0,0,,,0,0,0,0,,,0,0,0,0,,,0,0,0,0,,,0,0,0,0,AAPL
2024-10-22 11:35:04.090349431+00:00,10,39,38,A,A,0,237.4,2000,130,203607,27529,,237.4,0,2000,0,1,,,0,0,0,0,,,0,0,0,0,,,0,0,0,0,,,0,0,0,0,,,0,0,0,0,,,0,0,0,0,,,0,0,0,0,,,0,0,0,0,,,0,0,0,0,AAPL
2024-10-22 11:35:04.097866857+00:00,10,39,38,C,A,0,237.4,2000,130,203506,27530,,,0,0,0,0,,,0,0,0,0,,,0,0,0,0,,,0,0,0,0,,,0,0,0,0,,,0,0,0,0,,,0,0,0,0,,,0,0,0,0,,,0,0,0,0,,,0,0,0,0,AAPL
2024-10-22 11:35:04.132785621+00:00,10,39,38,A,A,0,237.4,2000,130,203591,27531,,237.4,0,2000,0,1,,,0,0,0,0,,,0,0,0,0,,,0,0,0,0,,,0,0,0,0,,,0,0,0,0,,,0,0,0,0,,,0,0,0,0,,,0,0,0,0,,,0,0,0,0,AAPL
2024-10-22 11:35:04.189732501+00:00,10,40,38,A,B,0,235.53,200,194,202723,37392,,235.53,0,200,0,0,,,0,0,0,0,,,0,0,0,0,,,0,0,0,0,,,0,0,0,0,,,0,0,0,0,,,0,0,0,0,,,0,0,0,0,,,0,0,0,0,,,0,0,0,0,AAPL
2024-10-22 11:35:09.053989696+00:00,10,40,38,A,B,0,235.53,200,194,202976,37450,234.64,235.53,200,200,0,0,,,0,0,0,0,,,0,0,0,0,,,0,0,0,0,,,0,0,0,0,,,0,0,0,0,,,0,0,0,0,,,0,0,0,0,,,0,0,0,0,,,0,0,0,0,AAPL
2024-10-22 11:35:20.958070588+00:00,10,40,38,A,N,0,,0,194,203033,37603,,,0,0,0,0,,,0,0,0,0,,,0,0,0,0,,,0,0,0,0,,,0,0,0,0,,,0,0,0,0,,,0,0,0,0,,,0,0,0,0,,,0,0,0,0,,,0,0,0,0,AAPL
2024-10-22 11:35:25.975717279+00:00,10,40,38,A,N,0,235.62,200,194,202897,37625,234.65,235.62,200,200,0,0,,,0,0,0,0,,,0,0,0,0,,,0,0,0,0,,,0,0,0,0,,,0,0,0,0,,,0,0,0,0,,,0,0,0,0,,,0,0,0,0,,,0,0,0,0,AAPL
2024-10-22 11:35:40.794809303+00:00,10,39,38,C,A,0,237.4,2000,130,204368,27724,,,0,0,0,0,,,0,0,0,0,,,0,0,0,0,,,0,0,0,0,,,0,0,0,0,,,0,0,0,0,,,0,0,0,0,,,0,0,0,0,,,0,0,0,0,,,0,0,0,0,AAPL
2024-10-22 11:35:40.904474054+00:00,10,40,38,A,B,0,235.62,200,194,202459,37751,,235.62,0,200,0,0,,,0,0,0,0,,,0,0,0,0,,,0,0,0,0,,,0,0,0,0,,,0,0,0,0,,,0,0,0,0,,,0,0,0,0,,,0,0,0,0,,,0,0,0,0,AAPL
2024-10-22 11:35:40.904490890+00:00,10,40,38,A,B,0,235.62,200,194,202396,37752,234.5,235.62,200,200,0,0,,,0,0,0,0,,,0,0,0,0,,,0,0,0,0,,,0,0,0,0,,,0,0,0,0,,,0,0,0,0,,,0,0,0,0,,,0,0,0,0,,,0,0,0,0,AAPL
2024-10-22 11:35:41.019231965+00:00,10,40,38,A,B,0,235.62,200,194,202717,37756,,235.62,0,200,0,0,,,0,0,0,0,,,0,0,0,0,,,0,0,0,0,,,0,0,0,0,,,0,0,0,0,,,0,0,0,0,,,0,0,0,0,,,0,0,0,0,,,0,0,0,0,AAPL
2024-10-22 11:35:41.070279557+00:00,10,40,38,A,A,0,,0,194,202456,37757,,,0,0,0,0,,,0,0,0,0,,,0,0,0,0,,,0,0,0,0,,,0,0,0,0,,,0,0,0,0,,,0,0,0,0,,,0,0,0,0,,,0,0,0,0,,,0,0,0,0,AAPL
2024-10-22 11:35:41.070296416+00:00,10,40,38,A,A,0,235.42,200,194,202443,37758,,235.42,0,200,0,0,,,0,0,0,0,,,0,0,0,0,,,0,0,0,0,,,0,0,0,0,,,0,0,0,0,,,0,0,0,0,,,0,0,0,0,,,0,0,0,0,,,0,0,0,0,AAPL
2024-10-22 11:35:41.751542482+00:00,10,40,38,A,B,0,235.42,200,194,202619,37762,234.5,235.42,200,200,0,0,,,0,0,0,0,,,0,0,0,0,,,0,0,0,0,,,0,0,0,0,,,0,0,0,0,,,0,0,0,0,,,0,0,0,0,,,0,0,0,0,,,0,0,0,0,AAPL
2024-10-22 11:35:41.762460975+00:00,10,39,38,A,A,0,237.4,2000,130,203852,27733,,237.4,0,2000,0,1,,,0,0,0,0,,,0,0,0,0,,,0,0,0,0,,,0,0,0,0,,,0,0,0,0,,,0,0,0,0,,,0,0,0,0,,,0,0,0,0,,,0,0,0,0,AAPL
2024-10-22 11:35:41.771480306+00:00,10,39,38,C,A,0,237.4,2000,130,203764,27734,,,0,0,0,0,,,0,0,0,0,,,0,0,0,0,,,0,0,0,0,,,0,0,0,0,,,0,0,0,0,,,0,0,0,0,,,0,0,0,0,,,0,0,0,0,,,0,0,0,0,AAPL
2024-10-22 11:35:41.783153545+00:00,10,39,38,A,A,0,237.4,2000,130,203813,27735,,237.4,0,2000,0,1,,,0,0,0,0,,,0,0,0,0,,,0,0,0,0,,,0,0,0,0,,,0,0,0,0,,,0,0,0,0,,,0,0,0,0,,,0,0,0,0,,,0,0,0,0,AAPL
2024-10-22 11:35:41.827622402+00:00,10,39,38,C,A,0,237.4,2000,130,203797,27740,,,0,0,0,0,,,0,0,0,0,,,0,0,0,0,,,0,0,0,0,,,0,0,0,0,,,0,0,0,0,,,0,0,0,0,,,0,0,0,0,,,0,0,0,0,,,0,0,0,0,AAPL
2024-10-22 11:35:41.838341865+00:00,10,39,38,A,A,0,237.6,2000,130,203829,27741,,237.6,0,2000,0,1,,,0,0,0,0,,,0,0,0,0,,,0,0,0,0,,,0,0,0,0,,,0,0,0,0,,,0,0,0,0,,,0,0,0,0,,,0,0,0,0,,,0,0,0,0,AAPL
2024-10-22 11:35:41.862678558+00:00,10,39,38,A,A,0,237.4,2000,130,203817,27742,,237.4,0,2000,0,1,,237.6,0,2000,0,1,,,0,0,0,0,,,0,0,0,0,,,0,0,0,0,,,0,0,0,0,,,0,0,0,0,,,0,0,0,0,,,0,0,0,0,,,0,0,0,0,AAPL
2024-10-22 11:35:41.863406895+00:00,10,39,38,C,A,1,237.6,2000,130,203765,27743,,237.4,0,2000,0,1,,,0,0,0,0,,,0,0,0,0,,,0,0,0,0,,,0,0,0,0,,,0,0,0,0,,,0,0,0,0,,,0,0,0,0,,,0,0,0,0,,,0,0,0,0,AAPL
2024-10-22 11:35:41.886944553+00:00,10,39,38,C,A,0,237.4,2000,130,203775,27744,,,0,0,0,0,,,0,0,0,0,,,0,0,0,0,,,0,0,0,0,,,0,0,0,0,,,0,0,0,0,,,0,0,0,0,,,0,0,0,0,,,0,0,0,0,,,0,0,0,0,AAPL
2024-10-22 11:35:41.899147832+00:00,10,39,38,A,A,0,237.6,2000,130,203877,27745,,237.6,0,2000,0,1,,,0,0,0,0,,,0,0,0,0,,,0,0,0,0,,,0,0,0,0,,,0,0,0,0,,,0,0,0,0,,,0,0,0,0,,,0,0,0,0,,,0,0,0,0,AAPL
2024-10-22 11:35:41.910414051+00:00,10,39,38,A,A,0,237.4,2000,130,203791,27746,,237.4,0,2000,0,1,,237.6,0,2000,0,1,,,0,0,0,0,,,0,0,0,0,,,0,0,0,0,,,0,0,0,0,,,0,0,0,0,,,0,0,0,0,,,0,0,0,0,,,0,0,0,0,AAPL
2024-10-22 11:35:41.910610682+00:00,10,39,38,C,A,1,237.6,2000,130,203782,27747,,237.4,0,2000,0,1,,,0,0,0,0,,,0,0,0,0,,,0,0,0,0,,,0,0,0,0,,,0,0,0,0,,,0,0,0,0,,,0,0,0,0,,,0,0,0,0,,,0,0,0,0,AAPL
2024-10-22 11:35:41.915615820+00:00,10,39,38,C,A,0,237.4,2000,130,203724,27748,,,0,0,0,0,,,0,0,0,0,,,0,0,0,0,,,0,0,0,0,,,0,0,0,0,,,0,0,0,0,,,0,0,0,0,,,0,0,0,0,,,0,0,0,0,,,0,0,0,0,AAPL
2024-10-22 11:35:41.926376884+00:00,10,39,38,A,A,0,237.6,2000,130,203868,27749,,237.6,0,2000,0,1,,,0,0,0,0,,,0,0,0,0,,,0,0,0,0,,,0,0,0,0,,,0,0,0,0,,,0,0,0,0,,,0,0,0,0,,,0,0,0,0,,,0,0,0,0,AAPL
2024-10-22 11:35:41.940772292+00:00,10,39,38,A,A,0,237.4,2000,130,203786,27750,,237.4,0,2000,0,1,,237.6,0,2000,0,1,,,0,0,0,0,,,0,0,0,0,,,0,0,0,0,,,0,0,0,0,,,0,0,0,0,,,0,0,0,0,,,0,0,0,0,,,0,0,0,0,AAPL
2024-10-22 11:35:41.941036343+00:00,10,39,38,C,A,1,237.6,2000,130,203793,27751,,237.4,0,2000,0,1,,,0,0,0,0,,,0,0,0,0,,,0,0,0,0,,,0,0,0,0,,,0,0,0,0,,,0,0,0,0,,,0,0,0,0,,,0,0,0,0,,,0,0,0,0,AAPL
2024-10-22 11:35:42.109911990+00:00,10,40,38,A,A,0,,0,194,202869,37764,234.5,,200,0,0,0,,,0,0,0,0,,,0,0,0,0,,,0,0,0,0,,,0,0,0,0,,,0,0,0,0,,,0,0,0,0,,,0,0,0,0,,,0,0,0,0,,,0,0,0,0,AAPL
2024-10-22 11:35:42.109931189+00:00,10,40,38,A,A,0,235.63,200,194,203059,37765,234.5,235.63,200,200,0,0,,,0,0,0,0,,,0,0,0,0,,,0,0,0,0,,,0,0,0,0,,,0,0,0,0,,,0,0,0,0,,,0,0,0,0,,,0,0,0,0,,,0,0,0,0,AAPL
2024-10-22 11:35:42.331904513+00:00,10,40,38,A,B,0,235.63,200,194,202743,37766,,235.63,0,200,0,0,,,0,0,0,0,,,0,0,0,0,,,0,0,0,0,,,0,0,0,0,,,0,0,0,0,,,0,0,0,0,,,0,0,0,0,,,0,0,0,0,,,0,0,0,0,AAPL
2024-10-22 11:35:42.534081876+00:00,10,40,38,A,B,0,235.63,200,194,202612,37771,234.5,235.63,200,200,0,0,,,0,0,0,0,,,0,0,0,0,,,0,0,0,0,,,0,0,0,0,,,0,0,0,0,,,0,0,0,0,,,0,0,0,0,,,0,0,0,0,,,0,0,0,0,AAPL
2024-10-22 11:35:50.472113982+00:00,10,39,38,C,A,0,237.4,2000,130,203734,27801,,,0,0,0,0,,,0,0,0,0,,,0,0,0,0,,,0,0,0,0,,,0,0,0,0,,,0,0,0,0,,,0,0,0,0,,,0,0,0,0,,,0,0,0,0,,,0,0,0,0,AAPL
2024-10-22 11:35:58.535778694+00:00,10,40,38,A,B,0,235.63,200,194,202689,37894,,235.63,0,200,0,0,,,0,0,0,0,,,0,0,0,0,,,0,0,0,0,,,0,0,0,0,,,0,0,0,0,,,0,0,0,0,,,0,0,0,0,,,0,0,0,0,,,0,0,0,0,AAPL
2024-10-22 11:35:58.535799498+00:00,10,40,38,A,B,0,235.63,200,194,202588,37895,234.55,235.63,200,200,0,0,,,0,0,0,0,,,0,0,0,0,,,0,0,0,0,,,0,0,0,0,,,0,0,0,0,,,0,0,0,0,,,0,0,0,0,,,0,0,0,0,,,0,0,0,0,AAPL
2024-10-22 11:36:00.004806963+00:00,10,40,38,A,B,0,235.63,200,194,202574,37916,,235.63,0,200,0,0,,,0,0,0,0,,,0,0,0,0,,,0,0,0,0,,,0,0,0,0,,,0,0,0,0,,,0,0,0,0,,,0,0,0,0,,,0,0,0,0,,,0,0,0,0,AAPL
2024-10-22 11:36:00.004928954+00:00,10,40,38,A,A,0,,0,194,202580,37917,,,0,0,0,0,,,0,0,0,0,,,0,0,0,0,,,0,0,0,0,,,0,0,0,0,,,0,0,0,0,,,0,0,0,0,,,0,0,0,0,,,0,0,0,0,,,0,0,0,0,AAPL
2024-10-22 11:36:00.004951869+00:00,10,40,38,A,A,0,235.62,200,194,202567,37918,,235.62,0,200,0,0,,,0,0,0,0,,,0,0,0,0,,,0,0,0,0,,,0,0,0,0,,,0,0,0,0,,,0,0,0,0,,,0,0,0,0,,,0,0,0,0,,,0,0,0,0,AAPL
2024-10-22 11:36:00.911084229+00:00,10,40,38,A,B,0,235.62,200,194,202694,38072,234.57,235.62,200,200,0,0,,,0,0,0,0,,,0,0,0,0,,,0,0,0,0,,,0,0,0,0,,,0,0,0,0,,,0,0,0,0,,,0,0,0,0,,,0,0,0,0,,,0,0,0,0,AAPL
2024-10-22 11:37:16.507511495+00:00,10,39,38,A,A,0,237.4,2000,130,203935,28117,,237.4,0,2000,0,1,,,0,0,0,0,,,0,0,0,0,,,0,0,0,0,,,0,0,0,0,,,0,0,0,0,,,0,0,0,0,,,0,0,0,0,,,0,0,0,0,,,0,0,0,0,AAPL
2024-10-22 11:37:16.558081280+00:00,10,39,38,C,A,0,237.4,2000,130,203941,28118,,,0,0,0,0,,,0,0,0,0,,,0,0,0,0,,,0,0,0,0,,,0,0,0,0,,,0,0,0,0,,,0,0,0,0,,,0,0,0,0,,,0,0,0,0,,,0,0,0,0,AAPL
2024-10-22 11:37:25.851696193+00:00,10,39,38,A,A,0,237.4,2000,130,204026,28154,,237.4,0,2000,0,1,,,0,0,0,0,,,0,0,0,0,,,0,0,0,0,,,0,0,0,0,,,0,0,0,0,,,0,0,0,0,,,0,0,0,0,,,0,0,0,0,,,0,0,0,0,AAPL
2024-10-22 11:37:27.147684536+00:00,10,39,38,C,A,0,237.4,2000,130,204376,28170,,,0,0,0,0,,,0,0,0,0,,,0,0,0,0,,,0,0,0,0,,,0,0,0,0,,,0,0,0,0,,,0,0,0,0,,,0,0,0,0,,,0,0,0,0,,,0,0,0,0,AAPL
2024-10-22 11:37:27.159534679+00:00,10,39,38,A,A,0,237.4,2000,130,204043,28171,,237.4,0,2000,0,1,,,0,0,0,0,,,0,0,0,0,,,0,0,0,0,,,0,0,0,0,,,0,0,0,0,,,0,0,0,0,,,0,0,0,0,,,0,0,0,0,,,0,0,0,0,AAPL
2024-10-22 11:37:34.681732380+00:00,10,39,38,C,A,0,237.4,2000,130,204085,28221,,,0,0,0,0,,,0,0,0,0,,,0,0,0,0,,,0,0,0,0,,,0,0,0,0,,,0,0,0,0,,,0,0,0,0,,,0,0,0,0,,,0,0,0,0,,,0,0,0,0,AAPL
2024-10-22 11:38:03.165697370+00:00,10,40,38,A,A,0,,0,194,203912,39501,234.57,,200,0,0,0,,,0,0,0,0,,,0,0,0,0,,,0,0,0,0,,,0,0,0,0,,,0,0,0,0,,,0,0,0,0,,,0,0,0,0,,,0,0,0,0,,,0,0,0,0,AAPL
2024-10-22 11:38:03.165720188+00:00,10,40,38,A,A,0,235.47,200,194,203879,39502,234.57,235.47,200,200,0,0,,,0,0,0,0,,,0,0,0,0,,,0,0,0,0,,,0,0,0,0,,,0,0,0,0,,,0,0,0,0,,,0,0,0,0,,,0,0,0,0,,,0,0,0,0,AAPL
2024-10-22 11:39:05.141538923+00:00,10,39,38,A,A,0,237.4,2000,130,203841,28712,,237.4,0,2000,0,1,,,0,0,0,0,,,0,0,0,0,,,0,0,0,0,,,0,0,0,0,,,0,0,0,0,,,0,0,0,0,,,0,0,0,0,,,0,0,0,0,,,0,0,0,0,AAPL
2024-10-22 11:39:05.193225306+00:00,10,39,38,C,A,0,237.4,2000,130,203413,28713,,,0,0,0,0,,,0,0,0,0,,,0,0,0,0,,,0,0,0,0,,,0,0,0,0,,,0,0,0,0,,,0,0,0,0,,,0,0,0,0,,,0,0,0,0,,,0,0,0,0,AAPL
2024-10-22 11:39:19.016473373+00:00,10,39,38,A,A,0,237.4,2000,130,203696,28752,,237.4,0,2000,0,1,,,0,0,0,0,,,0,0,0,0,,,0,0,0,0,,,0,0,0,0,,,0,0,0,0,,,0,0,0,0,,,0,0,0,0,,,0,0,0,0,,,0,0,0,0,AAPL
2024-10-22 11:39:19.043023765+00:00,10,39,38,C,A,0,237.4,2000,130,203428,28753,,,0,0,0,0,,,0,0,0,0,,,0,0,0,0,,,0,0,0,0,,,0,0,0,0,,,0,0,0,0,,,0,0,0,0,,,0,0,0,0,,,0,0,0,0,,,0,0,0,0,AAPL
2024-10-22 11:40:00.078134500+00:00,10,40,38,A,B,0,235.47,200,194,202541,40602,,235.47,0,200,0,0,,,0,0,0,0,,,0,0,0,0,,,0,0,0,0,,,0,0,0,0,,,0,0,0,0,,,0,0,0,0,,,0,0,0,0,,,0,0,0,0,,,0,0,0,0,AAPL
2024-10-22 11:40:00.078146735+00:00,10,40,38,A,A,0,,0,194,202561,40603,,,0,0,0,0,,,0,0,0,0,,,0,0,0,0,,,0,0,0,0,,,0,0,0,0,,,0,0,0,0,,,0,0,0,0,,,0,0,0,0,,,0,0,0,0,,,0,0,0,0,AAPL
2024-10-22 11:40:00.419653688+00:00,10,40,38,A,A,0,235.49,200,194,202588,40750,,235.49,0,200,0,0,,,0,0,0,0,,,0,0,0,0,,,0,0,0,0,,,0,0,0,0,,,0,0,0,0,,,0,0,0,0,,,0,0,0,0,,,0,0,0,0,,,0,0,0,0,AAPL
2024-10-22 11:40:00.454106929+00:00,10,40,38,A,B,0,235.49,200,194,202549,40755,234.62,235.49,200,200,0,0,,,0,0,0,0,,,0,0,0,0,,,0,0,0,0,,,0,0,0,0,,,0,0,0,0,,,0,0,0,0,,,0,0,0,0,,,0,0,0,0,,,0,0,0,0,AAPL
2024-10-22 11:40:00.959926258+00:00,10,40,38,A,N,0,,0,194,202640,40782,,,0,0,0,0,,,0,0,0,0,,,0,0,0,0,,,0,0,0,0,,,0,0,0,0,,,0,0,0,0,,,0,0,0,0,,,0,0,0,0,,,0,0,0,0,,,0,0,0,0,AAPL
2024-10-22 11:40:09.694846225+00:00,10,40,38,A,B,0,,0,194,202225,40936,234.62,,200,0,0,0,,,0,0,0,0,,,0,0,0,0,,,0,0,0,0,,,0,0,0,0,,,0,0,0,0,,,0,0,0,0,,,0,0,0,0,,,0,0,0,0,,,0,0,0,0,AAPL
2024-10-22 11:40:09.694853529+00:00,10,40,38,A,A,0,235.49,200,194,202145,40937,234.62,235.49,200,200,0,0,,,0,0,0,0,,,0,0,0,0,,,0,0,0,0,,,0,0,0,0,,,0,0,0,0,,,0,0,0,0,,,0,0,0,0,,,0,0,0,0,,,0,0,0,0,AAPL
2024-10-22 11:40:09.949913806+00:00,10,40,38,A,B,0,235.49,200,194,202442,40938,,235.49,0,200,0,0,,,0,0,0,0,,,0,0,0,0,,,0,0,0,0,,,0,0,0,0,,,0,0,0,0,,,0,0,0,0,,,0,0,0,0,,,0,0,0,0,,,0,0,0,0,AAPL
2024-10-22 11:40:10.299342852+00:00,10,40,38,A,B,0,235.49,200,194,202228,40943,234.62,235.49,200,200,0,0,,,0,0,0,0,,,0,0,0,0,,,0,0,0,0,,,0,0,0,0,,,0,0,0,0,,,0,0,0,0,,,0,0,0,0,,,0,0,0,0,,,0,0,0,0,AAPL
2024-10-22 11:40:12.391411606+00:00,10,40,38,A,B,0,235.49,200,194,202173,40979,,235.49,0,200,0,0,,,0,0,0,0,,,0,0,0,0,,,0,0,0,0,,,0,0,0,0,,,0,0,0,0,,,0,0,0,0,,,0,0,0,0,,,0,0,0,0,,,0,0,0,0,AAPL
2024-10-22 11:40:14.072975708+00:00,10,40,38,A,B,0,235.49,200,194,202324,40992,234.62,235.49,200,200,0,0,,,0,0,0,0,,,0,0,0,0,,,0,0,0,0,,,0,0,0,0,,,0,0,0,0,,,0,0,0,0,,,0,0,0,0,,,0,0,0,0,,,0,0,0,0,AAPL
2024-10-22 11:40:34.428345225+00:00,10,39,38,A,A,0,237.4,2000,130,203944,29144,,237.4,0,2000,0,1,,,0,0,0,0,,,0,0,0,0,,,0,0,0,0,,,0,0,0,0,,,0,0,0,0,,,0,0,0,0,,,0,0,0,0,,,0,0,0,0,,,0,0,0,0,AAPL
2024-10-22 11:40:34.474291675+00:00,10,39,38,C,A,0,237.4,2000,130,204115,29145,,,0,0,0,0,,,0,0,0,0,,,0,0,0,0,,,0,0,0,0,,,0,0,0,0,,,0,0,0,0,,,0,0,0,0,,,0,0,0,0,,,0,0,0,0,,,0,0,0,0,AAPL
2024-10-22 11:40:43.421745023+00:00,10,40,38,A,B,0,235.49,200,194,202391,41229,,235.49,0,200,0,0,,,0,0,0,0,,,0,0,0,0,,,0,0,0,0,,,0,0,0,0,,,0,0,0,0,,,0,0,0,0,,,0,0,0,0,,,0,0,0,0,,,0,0,0,0,AAPL
2024-10-22 11:40:43.421772381+00:00,10,40,38,A,B,0,235.49,200,194,202419,41230,234.57,235.49,200,200,0,0,,,0,0,0,0,,,0,0,0,0,,,0,0,0,0,,,0,0,0,0,,,0,0,0,0,,,0,0,0,0,,,0,0,0,0,,,0,0,0,0,,,0,0,0,0,AAPL
2024-10-22 11:42:37.318002425+00:00,10,39,38,A,A,0,237.4,2000,130,203700,29603,,237.4,0,2000,0,1,,,0,0,0,0,,,0,0,0,0,,,0,0,0,0,,,0,0,0,0,,,0,0,0,0,,,0,0,0,0,,,0,0,0,0,,,0,0,0,0,,,0,0,0,0,AAPL
2024-10-22 11:44:50.236817990+00:00,10,39,38,C,A,0,237.4,2000,130,203336,30518,,,0,0,0,0,,,0,0,0,0,,,0,0,0,0,,,0,0,0,0,,,0,0,0,0,,,0,0,0,0,,,0,0,0,0,,,0,0,0,0,,,0,0,0,0,,,0,0,0,0,AAPL
2024-10-22 11:45:00.027161731+00:00,10,40,38,A,B,0,235.49,200,194,202662,43929,,235.49,0,200,0,0,,,0,0,0,0,,,0,0,0,0,,,0,0,0,0,,,0,0,0,0,,,0,0,0,0,,,0,0,0,0,,,0,0,0,0,,,0,0,0,0,,,0,0,0,0,AAPL
2024-10-22 11:45:00.027172609+00:00,10,40,38,A,A,0,,0,194,202774,43930,,,0,0,0,0,,,0,0,0,0,,,0,0,0,0,,,0,0,0,0,,,0,0,0,0,,,0,0,0,0,,,0,0,0,0,,,0,0,0,0,,,0,0,0,0,,,0,0,0,0,AAPL
2024-10-22 11:45:00.100654054+00:00,10,40,38,A,A,0,235.4,200,194,202584,44075,,235.4,0,200,0,0,,,0,0,0,0,,,0,0,0,0,,,0,0,0,0,,,0,0,0,0,,,0,0,0,0,,,0,0,0,0,,,0,0,0,0,,,0,0,0,0,,,0,0,0,0,AAPL
2024-10-22 11:45:00.130925420+00:00,10,40,38,A,A,0,,0,194,202571,44100,,,0,0,0,0,,,0,0,0,0,,,0,0,0,0,,,0,0,0,0,,,0,0,0,0,,,0,0,0,0,,,0,0,0,0,,,0,0,0,0,,,0,0,0,0,,,0,0,0,0,AAPL
2024-10-22 11:45:00.426550769+00:00,10,40,38,A,B,0,,0,194,202559,44204,234.53,,200,0,0,0,,,0,0,0,0,,,0,0,0,0,,,0,0,0,0,,,0,0,0,0,,,0,0,0,0,,,0,0,0,0,,,0,0,0,0,,,0,0,0,0,,,0,0,0,0,AAPL
2024-10-22 11:45:00.426560944+00:00,10,40,38,A,A,0,235.4,200,194,202541,44205,234.53,235.4,200,200,0,0,,,0,0,0,0,,,0,0,0,0,,,0,0,0,0,,,0,0,0,0,,,0,0,0,0,,,0,0,0,0,,,0,0,0,0,,,0,0,0,0,,,0,0,0,0,AAPL
2024-10-22 11:45:00.531367892+00:00,10,40,38,A,B,0,235.4,200,194,202535,44220,,235.4,0,200,0,0,,,0,0,0,0,,,0,0,0,0,,,0,0,0,0,,,0,0,0,0,,,0,0,0,0,,,0,0,0,0,,,0,0,0,0,,,0,0,0,0,,,0,0,0,0,AAPL
2024-10-22 11:45:07.116699703+00:00,10,40,38,A,B,0,235.4,200,194,202192,44353,234.53,235.4,200,200,0,0,,,0,0,0,0,,,0,0,0,0,,,0,0,0,0,,,0,0,0,0,,,0,0,0,0,,,0,0,0,0,,,0,0,0,0,,,0,0,0,0,,,0,0,0,0,AAPL
2024-10-22 11:47:00.538774908+00:00,10,40,38,A,B,0,235.4,200,194,202586,45974,,235.4,0,200,0,0,,,0,0,0,0,,,0,0,0,0,,,0,0,0,0,,,0,0,0,0,,,0,0,0,0,,,0,0,0,0,,,0,0,0,0,,,0,0,0,0,,,0,0,0,0,AAPL
2024-10-22 11:47:01.509326873+00:00,10,40,38,A,B,0,235.4,200,194,202672,45988,234.5,235.4,200,200,0,0,,,0,0,0,0,,,0,0,0,0,,,0,0,0,0,,,0,0,0,0,,,0,0,0,0,,,0,0,0,0,,,0,0,0,0,,,0,0,0,0,,,0,0,0,0,AAPL
2024-10-22 11:47:01.610430464+00:00,10,40,38,A,B,0,235.4,200,194,202628,45991,,235.4,0,200,0,0,,,0,0,0,0,,,0,0,0,0,,,0,0,0,0,,,0,0,0,0,,,0,0,0,0,,,0,0,0,0,,,0,0,0,0,,,0,0,0,0,,,0,0,0,0,AAPL
2024-10-22 11:47:06.238289681+00:00,10,40,38,A,B,0,235.4,200,194,202587,46107,234.5,235.4,200,200,0,0,,,0,0,0,0,,,0,0,0,0,,,0,0,0,0,,,0,0,0,0,,,0,0,0,0,,,0,0,0,0,,,0,0,0,0,,,0,0,0,0,,,0,0,0,0,AAPL
2024-10-22 11:48:50.292573005+00:00,10,39,38,A,B,0,233.0,2000,130,204559,32226,233.0,,2000,0,1,0,,,0,0,0,0,,,0,0,0,0,,,0,0,0,0,,,0,0,0,0,,,0,0,0,0,,,0,0,0,0,,,0,0,0,0,,,0,0,0,0,,,0,0,0,0,AAPL
2024-10-22 11:48:50.293991487+00:00,10,39,38,A,A,0,237.0,2000,130,204015,32227,233.0,237.0,2000,2000,1,1,,,0,0,0,0,,,0,0,0,0,,,0,0,0,0,,,0,0,0,0,,,0,0,0,0,,,0,0,0,0,,,0,0,0,0,,,0,0,0,0,,,0,0,0,0,AAPL
2024-10-22 11:48:56.855659943+00:00,10,39,38,C,B,0,233.0,2000,130,204105,32271,,237.0,0,2000,0,1,,,0,0,0,0,,,0,0,0,0,,,0,0,0,0,,,0,0,0,0,,,0,0,0,0,,,0,0,0,0,,,0,0,0,0,,,0,0,0,0,,,0,0,0,0,AAPL
2024-10-22 11:48:56.866524224+00:00,10,39,38,A,B,0,232.8,2000,130,204111,32272,232.8,237.0,2000,2000,1,1,,,0,0,0,0,,,0,0,0,0,,,0,0,0,0,,,0,0,0,0,,,0,0,0,0,,,0,0,0,0,,,0,0,0,0,,,0,0,0,0,,,0,0,0,0,AAPL
2024-10-22 11:48:57.673375723+00:00,10,39,38,A,B,0,233.0,2000,130,204308,32277,233.0,237.0,2000,2000,1,1,232.8,,2000,0,1,0,,,0,0,0,0,,,0,0,0,0,,,0,0,0,0,,,0,0,0,0,,,0,0,0,0,,,0,0,0,0,,,0,0,0,0,,,0,0,0,0,AAPL
2024-10-22 11:48:57.673552085+00:00,10,39,38,C,B,1,232.8,2000,130,204030,32278,233.0,237.0,2000,2000,1,1,,,0,0,0,0,,,0,0,0,0,,,0,0,0,0,,,0,0,0,0,,,0,0,0,0,,,0,0,0,0,,,0,0,0,0,,,0,0,0,0,,,0,0,0,0,AAPL
2024-10-22 11:49:45.791169558+00:00,10,39,38,C,B,0,233.0,2000,130,204564,32661,,237.0,0,2000,0,1,,,0,0,0,0,,,0,0,0,0,,,0,0,0,0,,,0,0,0,0,,,0,0,0,0,,,0,0,0,0,,,0,0,0,0,,,0,0,0,0,,,0,0,0,0,AAPL
2024-10-22 11:49:45.807324958+00:00,10,39,38,A,B,0,233.0,2000,130,204161,32662,233.0,237.0,2000,2000,1,1,,,0,0,0,0,,,0,0,0,0,,,0,0,0,0,,,0,0,0,0,,,0,0,0,0,,,0,0,0,0,,,0,0,0,0,,,0,0,0,0,,,0,0,0,0,AAPL
2024-10-22 11:49:45.832745124+00:00,10,39,38,C,B,0,233.0,2000,130,204123,32665,,237.0,0,2000,0,1,,,0,0,0,0,,,0,0,0,0,,,0,0,0,0,,,0,0,0,0,,,0,0,0,0,,,0,0,0,0,,,0,0,0,0,,,0,0,0,0,,,0,0,0,0,AAPL
2024-10-22 11:49:45.848996349+00:00,10,39,38,A,B,0,233.0,2000,130,204170,32666,233.0,237.0,2000,2000,1,1,,,0,0,0,0,,,0,0,0,0,,,0,0,0,0,,,0,0,0,0,,,0,0,0,0,,,0,0,0,0,,,0,0,0,0,,,0,0,0,0,,,0,0,0,0,AAPL
2024-10-22 11:49:45.889309813+00:00,10,39,38,C,B,0,233.0,2000,130,204099,32668,,237.0,0,2000,0,1,,,0,0,0,0,,,0,0,0,0,,,0,0,0,0,,,0,0,0,0,,,0,0,0,0,,,0,0,0,0,,,0,0,0,0,,,0,0,0,0,,,0,0,0,0,AAPL
2024-10-22 11:49:45.900405566+00:00,10,39,38,A,B,0,232.8,2000,130,204168,32669,232.8,237.0,2000,2000,1,1,,,0,0,0,0,,,0,0,0,0,,,0,0,0,0,,,0,0,0,0,,,0,0,0,0,,,0,0,0,0,,,0,0,0,0,,,0,0,0,0,,,0,0,0,0,AAPL
2024-10-22 11:49:45.928722643+00:00,10,39,38,A,B,0,233.0,2000,130,205058,32670,233.0,237.0,2000,2000,1,1,232.8,,2000,0,1,0,,,0,0,0,0,,,0,0,0,0,,,0,0,0,0,,,0,0,0,0,,,0,0,0,0,,,0,0,0,0,,,0,0,0,0,,,0,0,0,0,AAPL
2024-10-22 11:49:45.929451871+00:00,10,39,38,C,B,1,232.8,2000,130,204036,32671,233.0,237.0,2000,2000,1,1,,,0,0,0,0,,,0,0,0,0,,,0,0,0,0,,,0,0,0,0,,,0,0,0,0,,,0,0,0,0,,,0,0,0,0,,,0,0,0,0,,,0,0,0,0,AAPL
2024-10-22 11:49:53.414885856+00:00,10,39,38,C,B,0,233.0,2000,130,204012,32735,,237.0,0,2000,0,1,,,0,0,0,0,,,0,0,0,0,,,0,0,0,0,,,0,0,0,0,,,0,0,0,0,,,0,0,0,0,,,0,0,0,0,,,0,0,0,0,,,0,0,0,0,AAPL
2024-10-22 11:49:53.450343275+00:00,10,39,38,A,B,0,233.0,2000,130,204004,32736,233.0,237.0,2000,2000,1,1,,,0,0,0,0,,,0,0,0,0,,,0,0,0,0,,,0,0,0,0,,,0,0,0,0,,,0,0,0,0,,,0,0,0,0,,,0,0,0,0,,,0,0,0,0,AAPL
2024-10-22 11:50:00.033394425+00:00,10,40,38,A,B,0,235.4,200,194,203514,49128,,235.4,0,200,0,0,,,0,0,0,0,,,0,0,0,0,,,0,0,0,0,,,0,0,0,0,,,0,0,0,0,,,0,0,0,0,,,0,0,0,0,,,0,0,0,0,,,0,0,0,0,AAPL
2024-10-22 11:50:00.033409865+00:00,10,40,38,A,A,0,,0,194,203567,49129,,,0,0,0,0,,,0,0,0,0,,,0,0,0,0,,,0,0,0,0,,,0,0,0,0,,,0,0,0,0,,,0,0,0,0,,,0,0,0,0,,,0,0,0,0,,,0,0,0,0,AAPL
2024-10-22 11:50:04.969929432+00:00,10,40,38,A,A,0,235.39,200,194,203517,49464,,235.39,0,200,0,0,,,0,0,0,0,,,0,0,0,0,,,0,0,0,0,,,0,0,0,0,,,0,0,0,0,,,0,0,0,0,,,0,0,0,0,,,0,0,0,0,,,0,0,0,0,AAPL
2024-10-22 11:50:06.176344445+00:00,10,40,38,A,B,0,235.39,200,194,203622,49473,234.47,235.39,200,200,0,0,,,0,0,0,0,,,0,0,0,0,,,0,0,0,0,,,0,0,0,0,,,0,0,0,0,,,0,0,0,0,,,0,0,0,0,,,0,0,0,0,,,0,0,0,0,AAPL
2024-10-22 11:50:06.895365860+00:00,10,40,38,A,B,0,235.39,200,194,203574,49475,,235.39,0,200,0,0,,,0,0,0,0,,,0,0,0,0,,,0,0,0,0,,,0,0,0,0,,,0,0,0,0,,,0,0,0,0,,,0,0,0,0,,,0,0,0,0,,,0,0,0,0,AAPL
2024-10-22 11:50:09.586597654+00:00,10,40,38,A,B,0,235.39,200,194,203365,49508,234.47,235.39,200,200,0,0,,,0,0,0,0,,,0,0,0,0,,,0,0,0,0,,,0,0,0,0,,,0,0,0,0,,,0,0,0,0,,,0,0,0,0,,,0,0,0,0,,,0,0,0,0,AAPL
2024-10-22 11:50:25.336692013+00:00,10,39,38,C,B,0,233.0,2000,130,203787,33047,,237.0,0,2000,0,1,,,0,0,0,0,,,0,0,0,0,,,0,0,0,0,,,0,0,0,0,,,0,0,0,0,,,0,0,0,0,,,0,0,0,0,,,0,0,0,0,,,0,0,0,0,AAPL
2024-10-22 11:50:25.400261664+00:00,10,39,38,A,B,0,233.0,2000,130,203406,33049,233.0,237.0,2000,2000,1,1,,,0,0,0,0,,,0,0,0,0,,,0,0,0,0,,,0,0,0,0,,,0,0,0,0,,,0,0,0,0,,,0,0,0,0,,,0,0,0,0,,,0,0,0,0,AAPL
2024-10-22 11:50:30.563737007+00:00,10,39,38,C,B,0,233.0,2000,130,204022,33094,,237.0,0,2000,0,1,,,0,0,0,0,,,0,0,0,0,,,0,0,0,0,,,0,0,0,0,,,0,0,0,0,,,0,0,0,0,,,0,0,0,0,,,0,0,0,0,,,0,0,0,0,AAPL
2024-10-22 11:50:30.599385535+00:00,10,39,38,A,B,0,233.0,2000,130,202965,33097,233.0,237.0,2000,2000,1,1,,,0,0,0,0,,,0,0,0,0,,,0,0,0,0,,,0,0,0,0,,,0,0,0,0,,,0,0,0,0,,,0,0,0,0,,,0,0,0,0,,,0,0,0,0,AAPL
2024-10-22 11:50:38.885440996+00:00,10,39,38,C,B,0,233.0,2000,130,202884,33179,,237.0,0,2000,0,1,,,0,0,0,0,,,0,0,0,0,,,0,0,0,0,,,0,0,0,0,,,0,0,0,0,,,0,0,0,0,,,0,0,0,0,,,0,0,0,0,,,0,0,0,0,AAPL
2024-10-22 11:50:38.896491120+00:00,10,39,38,A,B,0,232.8,2000,130,202833,33180,232.8,237.0,2000,2000,1,1,,,0,0,0,0,,,0,0,0,0,,,0,0,0,0,,,0,0,0,0,,,0,0,0,0,,,0,0,0,0,,,0,0,0,0,,,0,0,0,0,,,0,0,0,0,AAPL
2024-10-22 11:50:53.428818084+00:00,10,39,38,A,B,0,233.0,2000,130,203586,33303,233.0,237.0,2000,2000,1,1,232.8,,2000,0,1,0,,,0,0,0,0,,,0,0,0,0,,,0,0,0,0,,,0,0,0,0,,,0,0,0,0,,,0,0,0,0,,,0,0,0,0,,,0,0,0,0,AAPL
2024-10-22 11:50:53.429532858+00:00,10,39,38,C,B,1,232.8,2000,130,203497,33304,233.0,237.0,2000,2000,1,1,,,0,0,0,0,,,0,0,0,0,,,0,0,0,0,,,0,0,0,0,,,0,0,0,0,,,0,0,0,0,,,0,0,0,0,,,0,0,0,0,,,0,0,0,0,AAPL
2024-10-22 11:50:53.540860929+00:00,10,39,38,C,B,0,233.0,2000,130,203509,33305,,237.0,0,2000,0,1,,,0,0,0,0,,,0,0,0,0,,,0,0,0,0,,,0,0,0,0,,,0,0,0,0,,,0,0,0,0,,,0,0,0,0,,,0,0,0,0,,,0,0,0,0,AAPL
2024-10-22 11:50:53.577357433+00:00,10,39,38,A,B,0,233.0,2000,130,203430,33306,233.0,237.0,2000,2000,1,1,,,0,0,0,0,,,0,0,0,0,,,0,0,0,0,,,0,0,0,0,,,0,0,0,0,,,0,0,0,0,,,0,0,0,0,,,0,0,0,0,,,0,0,0,0,AAPL
2024-10-22 11:51:00.074829005+00:00,10,40,38,A,B,0,235.39,200,194,203568,50001,,235.39,0,200,0,0,,,0,0,0,0,,,0,0,0,0,,,0,0,0,0,,,0,0,0,0,,,0,0,0,0,,,0,0,0,0,,,0,0,0,0,,,0,0,0,0,,,0,0,0,0,AAPL
2024-10-22 11:51:00.241875633+00:00,10,40,38,A,B,0,235.39,200,194,203702,50040,234.52,235.39,200,200,0,0,,,0,0,0,0,,,0,0,0,0,,,0,0,0,0,,,0,0,0,0,,,0,0,0,0,,,0,0,0,0,,,0,0,0,0,,,0,0,0,0,,,0,0,0,0,AAPL
2024-10-22 11:51:02.449255551+00:00,10,39,38,C,A,0,237.0,2000,130,203726,33422,233.0,,2000,0,1,0,,,0,0,0,0,,,0,0,0,0,,,0,0,0,0,,,0,0,0,0,,,0,0,0,0,,,0,0,0,0,,,0,0,0,0,,,0,0,0,0,,,0,0,0,0,AAPL
2024-10-22 11:51:02.485612645+00:00,10,39,38,A,A,0,237.0,2000,130,203283,33423,233.0,237.0,2000,2000,1,1,,,0,0,0,0,,,0,0,0,0,,,0,0,0,0,,,0,0,0,0,,,0,0,0,0,,,0,0,0,0,,,0,0,0,0,,,0,0,0,0,,,0,0,0,0,AAPL
2024-10-22 11:51:45.503796128+00:00,10,39,38,C,A,0,237.0,2000,130,203985,33846,233.0,,2000,0,1,0,,,0,0,0,0,,,0,0,0,0,,,0,0,0,0,,,0,0,0,0,,,0,0,0,0,,,0,0,0,0,,,0,0,0,0,,,0,0,0,0,,,0,0,0,0,AAPL
2024-10-22 11:51:45.515724845+00:00,10,39,38,A,A,0,237.2,2000,130,203800,33847,233.0,237.2,2000,2000,1,1,,,0,0,0,0,,,0,0,0,0,,,0,0,0,0,,,0,0,0,0,,,0,0,0,0,,,0,0,0,0,,,0,0,0,0,,,0,0,0,0,,,0,0,0,0,AAPL
2024-10-22 11:51:55.422274787+00:00,10,39,38,C,B,0,233.0,2000,130,204752,33908,,237.2,0,2000,0,1,,,0,0,0,0,,,0,0,0,0,,,0,0,0,0,,,0,0,0,0,,,0,0,0,0,,,0,0,0,0,,,0,0,0,0,,,0,0,0,0,,,0,0,0,0,AAPL
2024-10-22 11:51:55.458968503+00:00,10,39,38,A,B,0,233.0,2000,130,203949,33909,233.0,237.2,2000,2000,1,1,,,0,0,0,0,,,0,0,0,0,,,0,0,0,0,,,0,0,0,0,,,0,0,0,0,,,0,0,0,0,,,0,0,0,0,,,0,0,0,0,,,0,0,0,0,AAPL
2024-10-22 11:52:00.078012742+00:00,10,40,38,A,B,0,235.39,200,194,202394,50587,,235.39,0,200,0,0,,,0,0,0,0,,,0,0,0,0,,,0,0,0,0,,,0,0,0,0,,,0,0,0,0,,,0,0,0,0,,,0,0,0,0,,,0,0,0,0,,,0,0,0,0,AAPL
2024-10-22 11:52:05.696367121+00:00,10,40,38,A,B,0,235.39,200,194,202947,50691,234.52,235.39,200,200,0,0,,,0,0,0,0,,,0,0,0,0,,,0,0,0,0,,,0,0,0,0,,,0,0,0,0,,,0,0,0,0,,,0,0,0,0,,,0,0,0,0,,,0,0,0,0,AAPL
2024-10-22 11:52:07.432019519+00:00,10,39,38,A,A,0,237.0,2000,130,204726,33969,233.0,237.0,2000,2000,1,1,,237.2,0,2000,0,1,,,0,0,0,0,,,0,0,0,0,,,0,0,0,0,,,0,0,0,0,,,0,0,0,0,,,0,0,0,0,,,0,0,0,0,,,0,0,0,0,AAPL
2024-10-22 11:52:07.432205810+00:00,10,39,38,C,A,1,237.2,2000,130,203872,33970,233.0,237.0,2000,2000,1,1,,,0,0,0,0,,,0,0,0,0,,,0,0,0,0,,,0,0,0,0,,,0,0,0,0,,,0,0,0,0,,,0,0,0,0,,,0,0,0,0,,,0,0,0,0,AAPL
2024-10-22 11:52:08.223562786+00:00,10,39,38,C,B,0,233.0,2000,130,204520,33972,,237.0,0,2000,0,1,,,0,0,0,0,,,0,0,0,0,,,0,0,0,0,,,0,0,0,0,,,0,0,0,0,,,0,0,0,0,,,0,0,0,0,,,0,0,0,0,,,0,0,0,0,AAPL
2024-10-22 11:52:08.260684621+00:00,10,39,38,A,B,0,233.0,2000,130,204066,33973,233.0,237.0,2000,2000,1,1,,,0,0,0,0,,,0,0,0,0,,,0,0,0,0,,,0,0,0,0,,,0,0,0,0,,,0,0,0,0,,,0,0,0,0,,,0,0,0,0,,,0,0,0,0,AAPL
2024-10-22 11:52:20.793682893+00:00,10,39,38,C,B,0,233.0,2000,130,204634,34022,,237.0,0,2000,0,1,,,0,0,0,0,,,0,0,0,0,,,0,0,0,0,,,0,0,0,0,,,0,0,0,0,,,0,0,0,0,,,0,0,0,0,,,0,0,0,0,,,0,0,0,0,AAPL
2024-10-22 11:52:20.831098023+00:00,10,39,38,A,B,0,232.6,2000,130,204388,34023,232.6,237.0,2000,2000,1,1,,,0,0,0,0,,,0,0,0,0,,,0,0,0,0,,,0,0,0,0,,,0,0,0,0,,,0,0,0,0,,,0,0,0,0,,,0,0,0,0,,,0,0,0,0,AAPL
2024-10-22 11:52:31.758010637+00:00,10,39,38,A,B,0,232.8,2000,130,204685,34065,232.8,237.0,2000,2000,1,1,232.6,,2000,0,1,0,,,0,0,0,0,,,0,0,0,0,,,0,0,0,0,,,0,0,0,0,,,0,0,0,0,,,0,0,0,0,,,0,0,0,0,,,0,0,0,0,AAPL
2024-10-22 11:52:31.758211877+00:00,10,39,38,C,B,1,232.6,2000,130,204427,34066,232.8,237.0,2000,2000,1,1,,,0,0,0,0,,,0,0,0,0,,,0,0,0,0,,,0,0,0,0,,,0,0,0,0,,,0,0,0,0,,,0,0,0,0,,,0,0,0,0,,,0,0,0,0,AAPL
2024-10-22 11:52:33.805852126+00:00,10,39,38,C,A,0,237.0,2000,130,204862,34073,232.8,,2000,0,1,0,,,0,0,0,0,,,0,0,0,0,,,0,0,0,0,,,0,0,0,0,,,0,0,0,0,,,0,0,0,0,,,0,0,0,0,,,0,0,0,0,,,0,0,0,0,AAPL
2024-10-22 11:52:33.820740668+00:00,10,39,38,A,A,0,237.2,2000,130,204570,34074,232.8,237.2,2000,2000,1,1,,,0,0,0,0,,,0,0,0,0,,,0,0,0,0,,,0,0,0,0,,,0,0,0,0,,,0,0,0,0,,,0,0,0,0,,,0,0,0,0,,,0,0,0,0,AAPL
2024-10-22 11:52:47.483851423+00:00,10,39,38,A,B,0,233.0,2000,130,204275,34129,233.0,237.2,2000,2000,1,1,232.8,,2000,0,1,0,,,0,0,0,0,,,0,0,0,0,,,0,0,0,0,,,0,0,0,0,,,0,0,0,0,,,0,0,0,0,,,0,0,0,0,,,0,0,0,0,AAPL
2024-10-22 11:52:47.484571422+00:00,10,39,38,C,B,1,232.8,2000,130,203837,34130,233.0,237.2,2000,2000,1,1,,,0,0,0,0,,,0,0,0,0,,,0,0,0,0,,,0,0,0,0,,,0,0,0,0,,,0,0,0,0,,,0,0,0,0,,,0,0,0,0,,,0,0,0,0,AAPL
2024-10-22 11:52:56.518244549+00:00,10,39,38,A,A,0,237.0,2000,130,204610,34207,233.0,237.0,2000,2000,1,1,,237.2,0,2000,0,1,,,0,0,0,0,,,0,0,0,0,,,0,0,0,0,,,0,0,0,0,,,0,0,0,0,,,0,0,0,0,,,0,0,0,0,,,0,0,0,0,AAPL
2024-10-22 11:52:56.518431873+00:00,10,39,38,C,A,1,237.2,2000,130,203487,34208,233.0,237.0,2000,2000,1,1,,,0,0,0,0,,,0,0,0,0,,,0,0,0,0,,,0,0,0,0,,,0,0,0,0,,,0,0,0,0,,,0,0,0,0,,,0,0,0,0,,,0,0,0,0,AAPL
2024-10-22 11:53:15.036314100+00:00,10,39,38,C,A,0,237.0,2000,130,203751,34278,233.0,,2000,0,1,0,,,0,0,0,0,,,0,0,0,0,,,0,0,0,0,,,0,0,0,0,,,0,0,0,0,,,0,0,0,0,,,0,0,0,0,,,0,0,0,0,,,0,0,0,0,AAPL
2024-10-22 11:53:15.072155604+00:00,10,39,38,A,A,0,237.2,2000,130,203376,34279,233.0,237.2,2000,2000,1,1,,,0,0,0,0,,,0,0,0,0,,,0,0,0,0,,,0,0,0,0,,,0,0,0,0,,,0,0,0,0,,,0,0,0,0,,,0,0,0,0,,,0,0,0,0,AAPL
2024-10-22 11:53:24.270161935+00:00,10,39,38,A,A,0,237.0,2000,130,203925,34351,233.0,237.0,2000,2000,1,1,,237.2,0,2000,0,1,,,0,0,0,0,,,0,0,0,0,,,0,0,0,0,,,0,0,0,0,,,0,0,0,0,,,0,0,0,0,,,0,0,0,0,,,0,0,0,0,AAPL
2024-10-22 11:53:24.270369757+00:00,10,39,38,C,A,1,237.2,2000,130,203202,34352,233.0,237.0,2000,2000,1,1,,,0,0,0,0,,,0,0,0,0,,,0,0,0,0,,,0,0,0,0,,,0,0,0,0,,,0,0,0,0,,,0,0,0,0,,,0,0,0,0,,,0,0,0,0,AAPL
2024-10-22 11:53:45.067164220+00:00,10,39,38,C,A,0,237.0,2000,130,203614,34426,233.0,,2000,0,1,0,,,0,0,0,0,,,0,0,0,0,,,0,0,0,0,,,0,0,0,0,,,0,0,0,0,,,0,0,0,0,,,0,0,0,0,,,0,0,0,0,,,0,0,0,0,AAPL
2024-10-22 11:53:45.080900713+00:00,10,39,38,A,A,0,237.2,2000,130,203421,34427,233.0,237.2,2000,2000,1,1,,,0,0,0,0,,,0,0,0,0,,,0,0,0,0,,,0,0,0,0,,,0,0,0,0,,,0,0,0,0,,,0,0,0,0,,,0,0,0,0,,,0,0,0,0,AAPL
2024-10-22 11:53:50.614689933+00:00,10,39,38,C,B,0,233.0,2000,130,203623,34452,,237.2,0,2000,0,1,,,0,0,0,0,,,0,0,0,0,,,0,0,0,0,,,0,0,0,0,,,0,0,0,0,,,0,0,0,0,,,0,0,0,0,,,0,0,0,0,,,0,0,0,0,AAPL
2024-10-22 11:53:50.652231952+00:00,10,39,38,A,B,0,233.0,2000,130,203516,34453,233.0,237.2,2000,2000,1,1,,,0,0,0,0,,,0,0,0,0,,,0,0,0,0,,,0,0,0,0,,,0,0,0,0,,,0,0,0,0,,,0,0,0,0,,,0,0,0,0,,,0,0,0,0,AAPL
2024-10-22 11:54:08.078801183+00:00,10,39,38,C,B,0,233.0,2000,130,203235,34560,,237.2,0,2000,0,1,,,0,0,0,0,,,0,0,0,0,,,0,0,0,0,,,0,0,0,0,,,0,0,0,0,,,0,0,0,0,,,0,0,0,0,,,0,0,0,0,,,0,0,0,0,AAPL
2024-10-22 11:54:08.090303131+00:00,10,39,38,A,B,0,232.8,2000,130,203177,34561,232.8,237.2,2000,2000,1,1,,,0,0,0,0,,,0,0,0,0,,,0,0,0,0,,,0,0,0,0,,,0,0,0,0,,,0,0,0,0,,,0,0,0,0,,,0,0,0,0,,,0,0,0,0,AAPL
2024-10-22 11:54:18.767149470+00:00,10,39,38,C,A,0,237.2,2000,130,203784,34601,232.8,,2000,0,1,0,,,0,0,0,0,,,0,0,0,0,,,0,0,0,0,,,0,0,0,0,,,0,0,0,0,,,0,0,0,0,,,0,0,0,0,,,0,0,0,0,,,0,0,0,0,AAPL
2024-10-22 11:54:18.793963178+00:00,10,39,38,A,A,0,237.0,2000,130,203581,34602,232.8,237.0,2000,2000,1,1,,,0,0,0,0,,,0,0,0,0,,,0,0,0,0,,,0,0,0,0,,,0,0,0,0,,,0,0,0,0,,,0,0,0,0,,,0,0,0,0,,,0,0,0,0,AAPL
2024-10-22 11:54:27.277837248+00:00,10,39,38,A,B,0,233.0,2000,130,204299,34659,233.0,237.0,2000,2000,1,1,232.8,,2000,0,1,0,,,0,0,0,0,,,0,0,0,0,,,0,0,0,0,,,0,0,0,0,,,0,0,0,0,,,0,0,0,0,,,0,0,0,0,,,0,0,0,0,AAPL
2024-10-22 11:54:27.278583022+00:00,10,39,38,C,B,1,232.8,2000,130,203805,34660,233.0,237.0,2000,2000,1,1,,,0,0,0,0,,,0,0,0,0,,,0,0,0,0,,,0,0,0,0,,,0,0,0,0,,,0,0,0,0,,,0,0,0,0,,,0,0,0,0,,,0,0,0,0,AAPL
2024-10-22 11:54:31.718177366+00:00,10,39,38,C,A,0,237.0,2000,130,204450,34671,233.0,,2000,0,1,0,,,0,0,0,0,,,0,0,0,0,,,0,0,0,0,,,0,0,0,0,,,0,0,0,0,,,0,0,0,0,,,0,0,0,0,,,0,0,0,0,,,0,0,0,0,AAPL
2024-10-22 11:54:31.754649766+00:00,10,39,38,A,A,0,237.0,2000,130,203911,34672,233.0,237.0,2000,2000,1,1,,,0,0,0,0,,,0,0,0,0,,,0,0,0,0,,,0,0,0,0,,,0,0,0,0,,,0,0,0,0,,,0,0,0,0,,,0,0,0,0,,,0,0,0,0,AAPL
2024-10-22 11:54:54.615505727+00:00,10,39,38,C,A,0,237.0,2000,130,203233,34796,233.0,,2000,0,1,0,,,0,0,0,0,,,0,0,0,0,,,0,0,0,0,,,0,0,0,0,,,0,0,0,0,,,0,0,0,0,,,0,0,0,0,,,0,0,0,0,,,0,0,0,0,AAPL
2024-10-22 11:54:54.649429620+00:00,10,39,38,C,B,0,233.0,2000,130,203360,34797,,,0,0,0,0,,,0,0,0,0,,,0,0,0,0,,,0,0,0,0,,,0,0,0,0,,,0,0,0,0,,,0,0,0,0,,,0,0,0,0,,,0,0,0,0,,,0,0,0,0,AAPL
2024-10-22 11:54:54.651360084+00:00,10,39,38,A,A,0,237.0,2000,130,203334,34798,,237.0,0,2000,0,1,,,0,0,0,0,,,0,0,0,0,,,0,0,0,0,,,0,0,0,0,,,0,0,0,0,,,0,0,0,0,,,0,0,0,0,,,0,0,0,0,,,0,0,0,0,AAPL
2024-10-22 11:54:54.660670751+00:00,10,39,38,A,B,0,233.0,2000,130,203218,34801,233.0,237.0,2000,2000,1,1,,,0,0,0,0,,,0,0,0,0,,,0,0,0,0,,,0,0,0,0,,,0,0,0,0,,,0,0,0,0,,,0,0,0,0,,,0,0,0,0,,,0,0,0,0,AAPL
2024-10-22 11:54:54.866721785+00:00,10,39,38,C,B,0,233.0,2000,130,203281,34803,,237.0,0,2000,0,1,,,0,0,0,0,,,0,0,0,0,,,0,0,0,0,,,0,0,0,0,,,0,0,0,0,,,0,0,0,0,,,0,0,0,0,,,0,0,0,0,,,0,0,0,0,AAPL
2024-10-22 11:54:54.883464865+00:00,10,39,38,A,B,0,233.0,2000,130,203273,34804,233.0,237.0,2000,2000,1,1,,,0,0,0,0,,,0,0,0,0,,,0,0,0,0,,,0,0,0,0,,,0,0,0,0,,,0,0,0,0,,,0,0,0,0,,,0,0,0,0,,,0,0,0,0,AAPL
2024-10-22 11:55:00.053915292+00:00,10,40,38,A,B,0,235.39,200,194,203102,52136,,235.39,0,200,0,0,,,0,0,0,0,,,0,0,0,0,,,0,0,0,0,,,0,0,0,0,,,0,0,0,0,,,0,0,0,0,,,0,0,0,0,,,0,0,0,0,,,0,0,0,0,AAPL
2024-10-22 11:55:00.053930099+00:00,10,40,38,A,A,0,,0,194,203117,52137,,,0,0,0,0,,,0,0,0,0,,,0,0,0,0,,,0,0,0,0,,,0,0,0,0,,,0,0,0,0,,,0,0,0,0,,,0,0,0,0,,,0,0,0,0,,,0,0,0,0,AAPL
2024-10-22 11:55:02.257675620+00:00,10,39,38,A,B,0,233.6,2000,130,204127,34846,233.6,237.0,2000,2000,1,1,233.0,,2000,0,1,0,,,0,0,0,0,,,0,0,0,0,,,0,0,0,0,,,0,0,0,0,,,0,0,0,0,,,0,0,0,0,,,0,0,0,0,,,0,0,0,0,AAPL
2024-10-22 11:55:02.257852631+00:00,10,39,38,C,B,1,233.0,2000,130,203695,34847,233.6,237.0,2000,2000,1,1,,,0,0,0,0,,,0,0,0,0,,,0,0,0,0,,,0,0,0,0,,,0,0,0,0,,,0,0,0,0,,,0,0,0,0,,,0,0,0,0,,,0,0,0,0,AAPL
2024-10-22 11:55:06.211790343+00:00,10,40,38,A,N,0,235.43,200,194,203691,52419,234.47,235.43,200,200,0,0,,,0,0,0,0,,,0,0,0,0,,,0,0,0,0,,,0,0,0,0,,,0,0,0,0,,,0,0,0,0,,,0,0,0,0,,,0,0,0,0,,,0,0,0,0,AAPL
2024-10-22 11:55:12.340867465+00:00,10,39,38,C,B,0,233.6,2000,130,204180,34873,,237.0,0,2000,0,1,,,0,0,0,0,,,0,0,0,0,,,0,0,0,0,,,0,0,0,0,,,0,0,0,0,,,0,0,0,0,,,0,0,0,0,,,0,0,0,0,,,0,0,0,0,AAPL
2024-10-22 11:55:12.352041666+00:00,10,39,38,A,B,0,233.6,2000,130,203837,34874,233.6,237.0,2000,2000,1,1,,,0,0,0,0,,,0,0,0,0,,,0,0,0,0,,,0,0,0,0,,,0,0,0,0,,,0,0,0,0,,,0,0,0,0,,,0,0,0,0,,,0,0,0,0,AAPL
2024-10-22 11:55:25.059382334+00:00,10,39,38,A,A,0,236.8,2000,130,204173,34966,233.6,236.8,2000,2000,1,1,,237.0,0,2000,0,1,,,0,0,0,0,,,0,0,0,0,,,0,0,0,0,,,0,0,0,0,,,0,0,0,0,,,0,0,0,0,,,0,0,0,0,,,0,0,0,0,AAPL
2024-10-22 11:55:25.060103158+00:00,10,39,38,C,A,1,237.0,2000,130,203699,34967,233.6,236.8,2000,2000,1,1,,,0,0,0,0,,,0,0,0,0,,,0,0,0,0,,,0,0,0,0,,,0,0,0,0,,,0,0,0,0,,,0,0,0,0,,,0,0,0,0,,,0,0,0,0,AAPL
2024-10-22 11:55:44.390636729+00:00,10,39,38,C,B,0,233.6,2000,130,203935,35116,,236.8,0,2000,0,1,,,0,0,0,0,,,0,0,0,0,,,0,0,0,0,,,0,0,0,0,,,0,0,0,0,,,0,0,0,0,,,0,0,0,0,,,0,0,0,0,,,0,0,0,0,AAPL
2024-10-22 11:55:44.403007393+00:00,10,39,38,A,B,0,233.4,2000,130,203687,35117,233.4,236.8,2000,2000,1,1,,,0,0,0,0,,,0,0,0,0,,,0,0,0,0,,,0,0,0,0,,,0,0,0,0,,,0,0,0,0,,,0,0,0,0,,,0,0,0,0,,,0,0,0,0,AAPL
2024-10-22 11:55:44.447540227+00:00,10,39,38,C,B,0,233.4,2000,130,203381,35118,,236.8,0,2000,0,1,,,0,0,0,0,,,0,0,0,0,,,0,0,0,0,,,0,0,0,0,,,0,0,0,0,,,0,0,0,0,,,0,0,0,0,,,0,0,0,0,,,0,0,0,0,AAPL
2024-10-22 11:55:44.491104583+00:00,10,39,38,A,B,0,233.4,2000,130,203337,35121,233.4,236.8,2000,2000,1,1,,,0,0,0,0,,,0,0,0,0,,,0,0,0,0,,,0,0,0,0,,,0,0,0,0,,,0,0,0,0,,,0,0,0,0,,,0,0,0,0,,,0,0,0,0,AAPL
2024-10-22 11:55:44.601193032+00:00,10,39,38,C,B,0,233.4,2000,130,203365,35124,,236.8,0,2000,0,1,,,0,0,0,0,,,0,0,0,0,,,0,0,0,0,,,0,0,0,0,,,0,0,0,0,,,0,0,0,0,,,0,0,0,0,,,0,0,0,0,,,0,0,0,0,AAPL
2024-10-22 11:55:44.637177725+00:00,10,39,38,A,B,0,233.6,2000,130,203417,35125,233.6,236.8,2000,2000,1,1,,,0,0,0,0,,,0,0,0,0,,,0,0,0,0,,,0,0,0,0,,,0,0,0,0,,,0,0,0,0,,,0,0,0,0,,,0,0,0,0,,,0,0,0,0,AAPL
2024-10-22 11:55:44.639685996+00:00,10,39,38,C,A,0,236.8,2000,130,203358,35126,233.6,,2000,0,1,0,,,0,0,0,0,,,0,0,0,0,,,0,0,0,0,,,0,0,0,0,,,0,0,0,0,,,0,0,0,0,,,0,0,0,0,,,0,0,0,0,,,0,0,0,0,AAPL
2024-10-22 11:55:44.652693012+00:00,10,39,38,A,A,0,237.0,2000,130,203435,35127,233.6,237.0,2000,2000,1,1,,,0,0,0,0,,,0,0,0,0,,,0,0,0,0,,,0,0,0,0,,,0,0,0,0,,,0,0,0,0,,,0,0,0,0,,,0,0,0,0,,,0,0,0,0,AAPL
2024-10-22 11:55:44.667671832+00:00,10,39,38,C,B,0,233.6,2000,130,203354,35128,,237.0,0,2000,0,1,,,0,0,0,0,,,0,0,0,0,,,0,0,0,0,,,0,0,0,0,,,0,0,0,0,,,0,0,0,0,,,0,0,0,0,,,0,0,0,0,,,0,0,0,0,AAPL
2024-10-22 11:55:44.675565261+00:00,10,39,38,A,A,0,236.8,2000,130,203398,35129,,236.8,0,2000,0,1,,237.0,0,2000,0,1,,,0,0,0,0,,,0,0,0,0,,,0,0,0,0,,,0,0,0,0,,,0,0,0,0,,,0,0,0,0,,,0,0,0,0,,,0,0,0,0,AAPL
2024-10-22 11:55:44.675758665+00:00,10,39,38,C,A,1,237.0,2000,130,203326,35130,,236.8,0,2000,0,1,,,0,0,0,0,,,0,0,0,0,,,0,0,0,0,,,0,0,0,0,,,0,0,0,0,,,0,0,0,0,,,0,0,0,0,,,0,0,0,0,,,0,0,0,0,AAPL
2024-10-22 11:55:44.700558118+00:00,10,39,38,A,B,0,233.6,2000,130,203370,35132,233.6,236.8,2000,2000,1,1,,,0,0,0,0,,,0,0,0,0,,,0,0,0,0,,,0,0,0,0,,,0,0,0,0,,,0,0,0,0,,,0,0,0,0,,,0,0,0,0,,,0,0,0,0,AAPL
2024-10-22 11:55:44.703137188+00:00,10,39,38,C,A,0,236.8,2000,130,203293,35133,233.6,,2000,0,1,0,,,0,0,0,0,,,0,0,0,0,,,0,0,0,0,,,0,0,0,0,,,0,0,0,0,,,0,0,0,0,,,0,0,0,0,,,0,0,0,0,,,0,0,0,0,AAPL
2024-10-22 11:55:44.715350176+00:00,10,39,38,A,A,0,237.0,2000,130,203406,35134,233.6,237.0,2000,2000,1,1,,,0,0,0,0,,,0,0,0,0,,,0,0,0,0,,,0,0,0,0,,,0,0,0,0,,,0,0,0,0,,,0,0,0,0,,,0,0,0,0,,,0,0,0,0,AAPL
2024-10-22 11:55:44.721437033+00:00,10,39,38,C,N,0,233.6,2000,130,203523,35136,,,0,0,0,0,,,0,0,0,0,,,0,0,0,0,,,0,0,0,0,,,0,0,0,0,,,0,0,0,0,,,0,0,0,0,,,0,0,0,0,,,0,0,0,0,,,0,0,0,0,AAPL
2024-10-22 11:55:44.732686102+00:00,10,39,38,A,N,0,233.4,2000,130,203596,35138,233.4,237.2,2000,2000,1,1,,,0,0,0,0,,,0,0,0,0,,,0,0,0,0,,,0,0,0,0,,,0,0,0,0,,,0,0,0,0,,,0,0,0,0,,,0,0,0,0,,,0,0,0,0,AAPL
2024-10-22 11:55:44.749009406+00:00,10,39,38,A,A,0,237.0,2000,130,203372,35139,233.4,237.0,2000,2000,1,1,,237.2,0,2000,0,1,,,0,0,0,0,,,0,0,0,0,,,0,0,0,0,,,0,0,0,0,,,0,0,0,0,,,0,0,0,0,,,0,0,0,0,,,0,0,0,0,AAPL
2024-10-22 11:55:44.749212238+00:00,10,39,38,C,A,1,237.2,2000,130,203333,35140,233.4,237.0,2000,2000,1,1,,,0,0,0,0,,,0,0,0,0,,,0,0,0,0,,,0,0,0,0,,,0,0,0,0,,,0,0,0,0,,,0,0,0,0,,,0,0,0,0,,,0,0,0,0,AAPL
2024-10-22 11:55:44.802289119+00:00,10,39,38,C,A,0,237.0,2000,130,203415,35141,233.4,,2000,0,1,0,,,0,0,0,0,,,0,0,0,0,,,0,0,0,0,,,0,0,0,0,,,0,0,0,0,,,0,0,0,0,,,0,0,0,0,,,0,0,0,0,,,0,0,0,0,AAPL
2024-10-22 11:55:44.813453399+00:00,10,39,38,A,A,0,237.2,2000,130,203418,35142,233.4,237.2,2000,2000,1,1,,,0,0,0,0,,,0,0,0,0,,,0,0,0,0,,,0,0,0,0,,,0,0,0,0,,,0,0,0,0,,,0,0,0,0,,,0,0,0,0,,,0,0,0,0,AAPL
2024-10-22 11:55:47.705943043+00:00,10,39,38,C,A,0,237.2,2000,130,203447,35156,233.4,,2000,0,1,0,,,0,0,0,0,,,0,0,0,0,,,0,0,0,0,,,0,0,0,0,,,0,0,0,0,,,0,0,0,0,,,0,0,0,0,,,0,0,0,0,,,0,0,0,0,AAPL
2024-10-22 11:55:47.709424505+00:00,10,39,38,C,B,0,233.4,2000,130,203212,35157,,,0,0,0,0,,,0,0,0,0,,,0,0,0,0,,,0,0,0,0,,,0,0,0,0,,,0,0,0,0,,,0,0,0,0,,,0,0,0,0,,,0,0,0,0,,,0,0,0,0,AAPL
2024-10-22 11:55:47.725713310+00:00,10,39,38,A,B,0,233.4,2000,130,203280,35158,233.4,,2000,0,1,0,,,0,0,0,0,,,0,0,0,0,,,0,0,0,0,,,0,0,0,0,,,0,0,0,0,,,0,0,0,0,,,0,0,0,0,,,0,0,0,0,,,0,0,0,0,AAPL
2024-10-22 11:55:47.742213144+00:00,10,39,38,A,A,0,237.2,2000,130,203276,35159,233.4,237.2,2000,2000,1,1,,,0,0,0,0,,,0,0,0,0,,,0,0,0,0,,,0,0,0,0,,,0,0,0,0,,,0,0,0,0,,,0,0,0,0,,,0,0,0,0,,,0,0,0,0,AAPL
2024-10-22 11:55:58.939355782+00:00,10,39,38,C,B,0,233.4,2000,130,203436,35272,,237.2,0,2000,0,1,,,0,0,0,0,,,0,0,0,0,,,0,0,0,0,,,0,0,0,0,,,0,0,0,0,,,0,0,0,0,,,0,0,0,0,,,0,0,0,0,,,0,0,0,0,AAPL
2024-10-22 11:55:58.951551325+00:00,10,39,38,A,B,0,233.2,2000,130,202930,35273,233.2,237.2,2000,2000,1,1,,,0,0,0,0,,,0,0,0,0,,,0,0,0,0,,,0,0,0,0,,,0,0,0,0,,,0,0,0,0,,,0,0,0,0,,,0,0,0,0,,,0,0,0,0,AAPL
2024-10-22 11:56:03.517287302+00:00,10,39,10888,A,B,0,418.31,200,130,202838,50078,418.31,,200,0,1,0,,,0,0,0,0,,,0,0,0,0,,,0,0,0,0,,,0,0,0,0,,,0,0,0,0,,,0,0,0,0,,,0,0,0,0,,,0,0,0,0,,,0,0,0,0,MSFT
2024-10-22 11:56:06.316074579+00:00,10,39,38,A,A,0,237.0,2000,130,203439,35335,233.2,237.0,2000,2000,1,1,,237.2,0,2000,0,1,,,0,0,0,0,,,0,0,0,0,,,0,0,0,0,,,0,0,0,0,,,0,0,0,0,,,0,0,0,0,,,0,0,0,0,,,0,0,0,0,AAPL
2024-10-22 11:56:06.316800997+00:00,10,39,38,C,A,1,237.2,2000,130,203005,35336,233.2,237.0,2000,2000,1,1,,,0,0,0,0,,,0,0,0,0,,,0,0,0,0,,,0,0,0,0,,,0,0,0,0,,,0,0,0,0,,,0,0,0,0,,,0,0,0,0,,,0,0,0,0,AAPL
2024-10-22 11:56:10.028059199+00:00,10,39,10888,C,B,0,418.31,200,130,203535,50191,,,0,0,0,0,,,0,0,0,0,,,0,0,0,0,,,0,0,0,0,,,0,0,0,0,,,0,0,0,0,,,0,0,0,0,,,0,0,0,0,,,0,0,0,0,,,0,0,0,0,MSFT
2024-10-22 11:56:16.703299451+00:00,10,39,38,C,A,0,237.0,2000,130,203383,35419,233.2,,2000,0,1,0,,,0,0,0,0,,,0,0,0,0,,,0,0,0,0,,,0,0,0,0,,,0,0,0,0,,,0,0,0,0,,,0,0,0,0,,,0,0,0,0,,,0,0,0,0,AAPL
2024-10-22 11:56:16.714714136+00:00,10,39,38,A,A,0,237.0,2000,130,203314,35420,233.2,237.0,2000,2000,1,1,,,0,0,0,0,,,0,0,0,0,,,0,0,0,0,,,0,0,0,0,,,0,0,0,0,,,0,0,0,0,,,0,0,0,0,,,0,0,0,0,,,0,0,0,0,AAPL
2024-10-22 11:56:25.724954755+00:00,10,40,10888,A,B,0,,0,194,203550,53158,418.32,,200,0,0,0,,,0,0,0,0,,,0,0,0,0,,,0,0,0,0,,,0,0,0,0,,,0,0,0,0,,,0,0,0,0,,,0,0,0,0,,,0,0,0,0,,,0,0,0,0,MSFT
2024-10-22 11:56:42.827624978+00:00,10,40,10888,A,B,0,,0,194,203304,53264,,,0,0,0,0,,,0,0,0,0,,,0,0,0,0,,,0,0,0,0,,,0,0,0,0,,,0,0,0,0,,,0,0,0,0,,,0,0,0,0,,,0,0,0,0,,,0,0,0,0,MSFT
2024-10-22 11:57:18.458054865+00:00,10,40,38,A,N,0,,0,194,204839,53659,,,0,0,0,0,,,0,0,0,0,,,0,0,0,0,,,0,0,0,0,,,0,0,0,0,,,0,0,0,0,,,0,0,0,0,,,0,0,0,0,,,0,0,0,0,,,0,0,0,0,AAPL
2024-10-22 11:57:23.491752686+00:00,10,40,38,A,B,0,,0,194,204568,53688,234.47,,200,0,0,0,,,0,0,0,0,,,0,0,0,0,,,0,0,0,0,,,0,0,0,0,,,0,0,0,0,,,0,0,0,0,,,0,0,0,0,,,0,0,0,0,,,0,0,0,0,AAPL
2024-10-22 11:57:23.491760232+00:00,10,40,38,A,A,0,235.4,200,194,204496,53689,234.47,235.4,200,200,0,0,,,0,0,0,0,,,0,0,0,0,,,0,0,0,0,,,0,0,0,0,,,0,0,0,0,,,0,0,0,0,,,0,0,0,0,,,0,0,0,0,,,0,0,0,0,AAPL
2024-10-22 11:57:47.898683751+00:00,10,39,38,C,B,0,233.2,2000,130,204312,35857,,237.0,0,2000,0,1,,,0,0,0,0,,,0,0,0,0,,,0,0,0,0,,,0,0,0,0,,,0,0,0,0,,,0,0,0,0,,,0,0,0,0,,,0,0,0,0,,,0,0,0,0,AAPL
2024-10-22 11:57:47.934678759+00:00,10,39,38,A,B,0,233.4,2000,130,204315,35860,233.4,237.0,2000,2000,1,1,,,0,0,0,0,,,0,0,0,0,,,0,0,0,0,,,0,0,0,0,,,0,0,0,0,,,0,0,0,0,,,0,0,0,0,,,0,0,0,0,,,0,0,0,0,AAPL
2024-10-22 11:57:48.156703623+00:00,10,39,38,C,A,0,237.0,2000,130,204304,35863,233.4,,2000,0,1,0,,,0,0,0,0,,,0,0,0,0,,,0,0,0,0,,,0,0,0,0,,,0,0,0,0,,,0,0,0,0,,,0,0,0,0,,,0,0,0,0,,,0,0,0,0,AAPL
2024-10-22 11:57:48.172443916+00:00,10,39,38,A,A,0,237.0,2000,130,204315,35865,233.4,237.0,2000,2000,1,1,,,0,0,0,0,,,0,0,0,0,,,0,0,0,0,,,0,0,0,0,,,0,0,0,0,,,0,0,0,0,,,0,0,0,0,,,0,0,0,0,,,0,0,0,0,AAPL
2024-10-22 11:58:00.081709597+00:00,10,40,38,A,B,0,235.4,200,194,203237,54051,,235.4,0,200,0,0,,,0,0,0,0,,,0,0,0,0,,,0,0,0,0,,,0,0,0,0,,,0,0,0,0,,,0,0,0,0,,,0,0,0,0,,,0,0,0,0,,,0,0,0,0,AAPL
2024-10-22 11:58:00.326193321+00:00,10,40,38,A,B,0,235.4,200,194,203201,54099,234.44,235.4,200,200,0,0,,,0,0,0,0,,,0,0,0,0,,,0,0,0,0,,,0,0,0,0,,,0,0,0,0,,,0,0,0,0,,,0,0,0,0,,,0,0,0,0,,,0,0,0,0,AAPL
2024-10-22 11:58:50.640957821+00:00,10,39,38,A,B,0,233.6,2000,130,203942,36219,233.6,237.0,2000,2000,1,1,233.4,,2000,0,1,0,,,0,0,0,0,,,0,0,0,0,,,0,0,0,0,,,0,0,0,0,,,0,0,0,0,,,0,0,0,0,,,0,0,0,0,,,0,0,0,0,AAPL
2024-10-22 11:58:50.641685908+00:00,10,39,38,C,B,1,233.4,2000,130,203160,36220,233.6,237.0,2000,2000,1,1,,,0,0,0,0,,,0,0,0,0,,,0,0,0,0,,,0,0,0,0,,,0,0,0,0,,,0,0,0,0,,,0,0,0,0,,,0,0,0,0,,,0,0,0,0,AAPL
2024-10-22 11:59:02.681632288+00:00,10,39,38,C,B,0,233.6,2000,130,203009,36354,,237.0,0,2000,0,1,,,0,0,0,0,,,0,0,0,0,,,0,0,0,0,,,0,0,0,0,,,0,0,0,0,,,0,0,0,0,,,0,0,0,0,,,0,0,0,0,,,0,0,0,0,AAPL
2024-10-22 11:59:02.723418038+00:00,10,39,38,A,B,0,233.4,2000,130,203119,36355,233.4,237.0,2000,2000,1,1,,,0,0,0,0,,,0,0,0,0,,,0,0,0,0,,,0,0,0,0,,,0,0,0,0,,,0,0,0,0,,,0,0,0,0,,,0,0,0,0,,,0,0,0,0,AAPL
2024-10-22 11:59:02.750993527+00:00,10,39,38,C,B,0,233.4,2000,130,203207,36356,,237.0,0,2000,0,1,,,0,0,0,0,,,0,0,0,0,,,0,0,0,0,,,0,0,0,0,,,0,0,0,0,,,0,0,0,0,,,0,0,0,0,,,0,0,0,0,,,0,0,0,0,AAPL
2024-10-22 11:59:02.762420950+00:00,10,39,38,A,B,0,233.2,2000,130,203017,36357,233.2,237.0,2000,2000,1,1,,,0,0,0,0,,,0,0,0,0,,,0,0,0,0,,,0,0,0,0,,,0,0,0,0,,,0,0,0,0,,,0,0,0,0,,,0,0,0,0,,,0,0,0,0,AAPL
2024-10-22 11:59:02.775909914+00:00,10,39,38,A,B,0,233.4,2000,130,202952,36358,233.4,237.0,2000,2000,1,1,233.2,,2000,0,1,0,,,0,0,0,0,,,0,0,0,0,,,0,0,0,0,,,0,0,0,0,,,0,0,0,0,,,0,0,0,0,,,0,0,0,0,,,0,0,0,0,AAPL
2024-10-22 11:59:02.776102807+00:00,10,39,38,C,B,1,233.2,2000,130,202919,36359,233.4,237.0,2000,2000,1,1,,,0,0,0,0,,,0,0,0,0,,,0,0,0,0,,,0,0,0,0,,,0,0,0,0,,,0,0,0,0,,,0,0,0,0,,,0,0,0,0,,,0,0,0,0,AAPL
2024-10-22 11:59:02.785765503+00:00,10,39,38,C,B,0,233.4,2000,130,202920,36360,,237.0,0,2000,0,1,,,0,0,0,0,,,0,0,0,0,,,0,0,0,0,,,0,0,0,0,,,0,0,0,0,,,0,0,0,0,,,0,0,0,0,,,0,0,0,0,,,0,0,0,0,AAPL
2024-10-22 11:59:02.834636142+00:00,10,39,38,A,B,0,233.6,2000,130,203051,36361,233.6,237.0,2000,2000,1,1,,,0,0,0,0,,,0,0,0,0,,,0,0,0,0,,,0,0,0,0,,,0,0,0,0,,,0,0,0,0,,,0,0,0,0,,,0,0,0,0,,,0,0,0,0,AAPL
2024-10-22 11:59:03.759463293+00:00,10,39,38,C,B,0,233.6,2000,130,203595,36365,,237.0,0,2000,0,1,,,0,0,0,0,,,0,0,0,0,,,0,0,0,0,,,0,0,0,0,,,0,0,0,0,,,0,0,0,0,,,0,0,0,0,,,0,0,0,0,,,0,0,0,0,AAPL
2024-10-22 11:59:03.770305435+00:00,10,39,38,A,B,0,233.4,2000,130,203160,36366,233.4,237.0,2000,2000,1,1,,,0,0,0,0,,,0,0,0,0,,,0,0,0,0,,,0,0,0,0,,,0,0,0,0,,,0,0,0,0,,,0,0,0,0,,,0,0,0,0,,,0,0,0,0,AAPL
2024-10-22 11:59:14.184592051+00:00,10,39,38,A,A,0,236.8,2000,130,203351,36445,233.4,236.8,2000,2000,1,1,,237.0,0,2000,0,1,,,0,0,0,0,,,0,0,0,0,,,0,0,0,0,,,0,0,0,0,,,0,0,0,0,,,0,0,0,0,,,0,0,0,0,,,0,0,0,0,AAPL
2024-10-22 11:59:14.184776225+00:00,10,39,38,C,A,1,237.0,2000,130,202767,36446,233.4,236.8,2000,2000,1,1,,,0,0,0,0,,,0,0,0,0,,,0,0,0,0,,,0,0,0,0,,,0,0,0,0,,,0,0,0,0,,,0,0,0,0,,,0,0,0,0,,,0,0,0,0,AAPL
2024-10-22 11:59:15.815274888+00:00,10,39,10888,A,A,0,418.41,100,130,203762,52444,,418.41,0,100,0,1,,,0,0,0,0,,,0,0,0,0,,,0,0,0,0,,,0,0,0,0,,,0,0,0,0,,,0,0,0,0,,,0,0,0,0,,,0,0,0,0,,,0,0,0,0,MSFT
2024-10-22 11:59:32.940076356+00:00,10,39,10888,C,A,0,418.41,100,130,203362,52748,,,0,0,0,0,,,0,0,0,0,,,0,0,0,0,,,0,0,0,0,,,0,0,0,0,,,0,0,0,0,,,0,0,0,0,,,0,0,0,0,,,0,0,0,0,,,0,0,0,0,MSFT
2024-10-22 11:59:33.308417848+00:00,10,39,10888,A,A,0,418.38,100,130,203530,52750,,418.38,0,100,0,1,,,0,0,0,0,,,0,0,0,0,,,0,0,0,0,,,0,0,0,0,,,0,0,0,0,,,0,0,0,0,,,0,0,0,0,,,0,0,0,0,,,0,0,0,0,MSFT
2024-10-22 11:59:37.598087135+00:00,10,39,10888,C,A,0,418.38,100,130,203026,52806,,,0,0,0,0,,,0,0,0,0,,,0,0,0,0,,,0,0,0,0,,,0,0,0,0,,,0,0,0,0,,,0,0,0,0,,,0,0,0,0,,,0,0,0,0,,,0,0,0,0,MSFT
2024-10-22 11:59:38.205559061+00:00,10,39,10888,A,A,0,418.37,100,130,203273,52826,,418.37,0,100,0,1,,,0,0,0,0,,,0,0,0,0,,,0,0,0,0,,,0,0,0,0,,,0,0,0,0,,,0,0,0,0,,,0,0,0,0,,,0,0,0,0,,,0,0,0,0,MSFT
2024-10-22 11:59:40.092035653+00:00,10,39,10888,C,A,0,418.37,100,130,203221,52861,,,0,0,0,0,,,0,0,0,0,,,0,0,0,0,,,0,0,0,0,,,0,0,0,0,,,0,0,0,0,,,0,0,0,0,,,0,0,0,0,,,0,0,0,0,,,0,0,0,0,MSFT
2024-10-22 11:59:55.436686661+00:00,10,39,38,C,A,0,236.8,2000,130,203700,36610,233.4,,2000,0,1,0,,,0,0,0,0,,,0,0,0,0,,,0,0,0,0,,,0,0,0,0,,,0,0,0,0,,,0,0,0,0,,,0,0,0,0,,,0,0,0,0,,,0,0,0,0,AAPL
2024-10-22 11:59:55.472562827+00:00,10,39,38,A,A,0,237.0,2000,130,203426,36612,233.4,237.0,2000,2000,1,1,,,0,0,0,0,,,0,0,0,0,,,0,0,0,0,,,0,0,0,0,,,0,0,0,0,,,0,0,0,0,,,0,0,0,0,,,0,0,0,0,,,0,0,0,0,AAPL
2024-10-22 11:59:55.472563105+00:00,10,39,38,A,B,0,233.6,2000,130,203476,36613,233.6,237.0,2000,2000,1,1,233.4,,2000,0,1,0,,,0,0,0,0,,,0,0,0,0,,,0,0,0,0,,,0,0,0,0,,,0,0,0,0,,,0,0,0,0,,,0,0,0,0,,,0,0,0,0,AAPL
2024-10-22 11:59:55.472587111+00:00,10,39,38,C,B,1,233.4,2000,130,203322,36614,233.6,237.0,2000,2000,1,1,,,0,0,0,0,,,0,0,0,0,,,0,0,0,0,,,0,0,0,0,,,0,0,0,0,,,0,0,0,0,,,0,0,0,0,,,0,0,0,0,,,0,0,0,0,AAPL
2024-10-22 11:59:55.500922521+00:00,10,39,38,C,B,0,233.6,2000,130,203348,36615,,237.0,0,2000,0,1,,,0,0,0,0,,,0,0,0,0,,,0,0,0,0,,,0,0,0,0,,,0,0,0,0,,,0,0,0,0,,,0,0,0,0,,,0,0,0,0,,,0,0,0,0,AAPL
2024-10-22 11:59:55.512501831+00:00,10,39,38,A,B,0,233.4,2000,130,203324,36616,233.4,237.0,2000,2000,1,1,,,0,0,0,0,,,0,0,0,0,,,0,0,0,0,,,0,0,0,0,,,0,0,0,0,,,0,0,0,0,,,0,0,0,0,,,0,0,0,0,,,0,0,0,0,AAPL
2024-10-22 12:00:00.001346840+00:00,10,40,38,A,N,0,,0,194,203266,55116,,,0,0,0,0,,,0,0,0,0,,,0,0,0,0,,,0,0,0,0,,,0,0,0,0,,,0,0,0,0,,,0,0,0,0,,,0,0,0,0,,,0,0,0,0,,,0,0,0,0,AAPL
2024-10-22 12:00:00.176926405+00:00,10,40,38,A,A,0,235.36,200,194,202945,55504,,235.36,0,200,0,0,,,0,0,0,0,,,0,0,0,0,,,0,0,0,0,,,0,0,0,0,,,0,0,0,0,,,0,0,0,0,,,0,0,0,0,,,0,0,0,0,,,0,0,0,0,AAPL
2024-10-22 12:00:00.177642308+00:00,10,40,38,A,B,0,235.36,200,194,202987,55505,234.49,235.36,200,200,0,0,,,0,0,0,0,,,0,0,0,0,,,0,0,0,0,,,0,0,0,0,,,0,0,0,0,,,0,0,0,0,,,0,0,0,0,,,0,0,0,0,,,0,0,0,0,AAPL
2024-10-22 12:00:00.013729337+00:00,10,41,38,A,A,0,235.28,200,194,57021,56161,,235.28,0,200,0,0,,,0,0,0,0,,,0,0,0,0,,,0,0,0,0,,,0,0,0,0,,,0,0,0,0,,,0,0,0,0,,,0,0,0,0,,,0,0,0,0,,,0,0,0,0,AAPL
2024-10-22 12:00:00.014860102+00:00,10,41,38,A,A,0,,0,194,55357,56171,,,0,0,0,0,,,0,0,0,0,,,0,0,0,0,,,0,0,0,0,,,0,0,0,0,,,0,0,0,0,,,0,0,0,0,,,0,0,0,0,,,0,0,0,0,,,0,0,0,0,AAPL
2024-10-22 12:00:00.223046376+00:00,10,40,38,A,B,0,235.36,200,194,203083,55524,,235.36,0,200,0,0,,,0,0,0,0,,,0,0,0,0,,,0,0,0,0,,,0,0,0,0,,,0,0,0,0,,,0,0,0,0,,,0,0,0,0,,,0,0,0,0,,,0,0,0,0,AAPL
2024-10-22 12:00:00.177621049+00:00,10,41,38,A,A,0,235.29,200,194,56644,56495,,235.29,0,200,0,0,,,0,0,0,0,,,0,0,0,0,,,0,0,0,0,,,0,0,0,0,,,0,0,0,0,,,0,0,0,0,,,0,0,0,0,,,0,0,0,0,,,0,0,0,0,AAPL
2024-10-22 12:00:00.177962820+00:00,10,41,38,A,B,0,235.29,200,194,55232,56496,234.56,235.29,200,200,0,0,,,0,0,0,0,,,0,0,0,0,,,0,0,0,0,,,0,0,0,0,,,0,0,0,0,,,0,0,0,0,,,0,0,0,0,,,0,0,0,0,,,0,0,0,0,AAPL
2024-10-22 12:00:00.242963966+00:00,10,41,38,A,B,0,235.29,200,194,56814,56517,,235.29,0,200,0,0,,,0,0,0,0,,,0,0,0,0,,,0,0,0,0,,,0,0,0,0,,,0,0,0,0,,,0,0,0,0,,,0,0,0,0,,,0,0,0,0,,,0,0,0,0,AAPL
2024-10-22 12:00:00.609397582+00:00,10,40,38,A,B,0,235.36,200,194,203029,55587,234.49,235.36,200,200,0,0,,,0,0,0,0,,,0,0,0,0,,,0,0,0,0,,,0,0,0,0,,,0,0,0,0,,,0,0,0,0,,,0,0,0,0,,,0,0,0,0,,,0,0,0,0,AAPL
2024-10-22 12:00:00.609872181+00:00,10,41,38,A,B,0,235.29,200,194,56967,56632,234.56,235.29,200,200,0,0,,,0,0,0,0,,,0,0,0,0,,,0,0,0,0,,,0,0,0,0,,,0,0,0,0,,,0,0,0,0,,,0,0,0,0,,,0,0,0,0,,,0,0,0,0,AAPL
2024-10-22 12:00:00.753034761+00:00,10,40,38,A,B,0,235.36,200,194,203048,55597,,235.36,0,200,0,0,,,0,0,0,0,,,0,0,0,0,,,0,0,0,0,,,0,0,0,0,,,0,0,0,0,,,0,0,0,0,,,0,0,0,0,,,0,0,0,0,,,0,0,0,0,AAPL
2024-10-22 12:00:00.753169460+00:00,10,40,38,A,A,0,,0,194,202978,55598,,,0,0,0,0,,,0,0,0,0,,,0,0,0,0,,,0,0,0,0,,,0,0,0,0,,,0,0,0,0,,,0,0,0,0,,,0,0,0,0,,,0,0,0,0,,,0,0,0,0,AAPL
2024-10-22 12:00:00.753443024+00:00,10,41,38,A,B,0,235.29,200,194,56625,56660,,235.29,0,200,0,0,,,0,0,0,0,,,0,0,0,0,,,0,0,0,0,,,0,0,0,0,,,0,0,0,0,,,0,0,0,0,,,0,0,0,0,,,0,0,0,0,,,0,0,0,0,AAPL
2024-10-22 12:00:00.782516574+00:00,10,41,38,A,A,0,,0,194,55829,56672,,,0,0,0,0,,,0,0,0,0,,,0,0,0,0,,,0,0,0,0,,,0,0,0,0,,,0,0,0,0,,,0,0,0,0,,,0,0,0,0,,,0,0,0,0,,,0,0,0,0,AAPL
2024-10-22 12:00:01.313063593+00:00,10,40,38,A,B,0,,0,194,203086,55624,234.49,,200,0,0,0,,,0,0,0,0,,,0,0,0,0,,,0,0,0,0,,,0,0,0,0,,,0,0,0,0,,,0,0,0,0,,,0,0,0,0,,,0,0,0,0,,,0,0,0,0,AAPL
2024-10-22 12:00:01.313070289+00:00,10,40,38,A,A,0,235.36,200,194,203013,55625,234.49,235.36,200,200,0,0,,,0,0,0,0,,,0,0,0,0,,,0,0,0,0,,,0,0,0,0,,,0,0,0,0,,,0,0,0,0,,,0,0,0,0,,,0,0,0,0,,,0,0,0,0,AAPL
2024-10-22 12:00:01.313936803+00:00,10,39,38,C,B,0,233.4,2000,130,203455,36669,,237.0,0,2000,0,1,,,0,0,0,0,,,0,0,0,0,,,0,0,0,0,,,0,0,0,0,,,0,0,0,0,,,0,0,0,0,,,0,0,0,0,,,0,0,0,0,,,0,0,0,0,AAPL
2024-10-22 12:00:01.313791841+00:00,10,41,38,A,A,0,235.29,200,194,56052,56974,,235.29,0,200,0,0,,,0,0,0,0,,,0,0,0,0,,,0,0,0,0,,,0,0,0,0,,,0,0,0,0,,,0,0,0,0,,,0,0,0,0,,,0,0,0,0,,,0,0,0,0,AAPL
2024-10-22 12:00:01.313881760+00:00,10,41,38,A,B,0,235.29,200,194,55674,56975,234.52,235.29,200,200,0,0,,,0,0,0,0,,,0,0,0,0,,,0,0,0,0,,,0,0,0,0,,,0,0,0,0,,,0,0,0,0,,,0,0,0,0,,,0,0,0,0,,,0,0,0,0,AAPL
2024-10-22 12:00:01.340314507+00:00,10,41,38,A,B,0,235.29,200,194,55823,56979,,235.29,0,200,0,0,,,0,0,0,0,,,0,0,0,0,,,0,0,0,0,,,0,0,0,0,,,0,0,0,0,,,0,0,0,0,,,0,0,0,0,,,0,0,0,0,,,0,0,0,0,AAPL
2024-10-22 12:00:01.342209386+00:00,10,40,38,A,B,0,235.36,200,194,203017,55627,,235.36,0,200,0,0,,,0,0,0,0,,,0,0,0,0,,,0,0,0,0,,,0,0,0,0,,,0,0,0,0,,,0,0,0,0,,,0,0,0,0,,,0,0,0,0,,,0,0,0,0,AAPL
2024-10-22 12:00:01.351172218+00:00,10,39,38,A,B,0,233.2,2000,130,203607,36670,233.2,237.0,2000,2000,1,1,,,0,0,0,0,,,0,0,0,0,,,0,0,0,0,,,0,0,0,0,,,0,0,0,0,,,0,0,0,0,,,0,0,0,0,,,0,0,0,0,,,0,0,0,0,AAPL
2024-10-22 12:00:01.423433847+00:00,10,40,38,A,A,0,,0,194,203078,55632,,,0,0,0,0,,,0,0,0,0,,,0,0,0,0,,,0,0,0,0,,,0,0,0,0,,,0,0,0,0,,,0,0,0,0,,,0,0,0,0,,,0,0,0,0,,,0,0,0,0,AAPL
2024-10-22 12:00:01.423791166+00:00,10,41,38,A,A,0,,0,194,56965,56987,,,0,0,0,0,,,0,0,0,0,,,0,0,0,0,,,0,0,0,0,,,0,0,0,0,,,0,0,0,0,,,0,0,0,0,,,0,0,0,0,,,0,0,0,0,,,0,0,0,0,AAPL
2024-10-22 12:00:01.517709695+00:00,10,41,38,A,A,0,235.29,200,194,56501,56994,,235.29,0,200,0,0,,,0,0,0,0,,,0,0,0,0,,,0,0,0,0,,,0,0,0,0,,,0,0,0,0,,,0,0,0,0,,,0,0,0,0,,,0,0,0,0,,,0,0,0,0,AAPL
2024-10-22 12:00:01.613904138+00:00,10,41,38,A,A,0,,0,194,57429,57003,,,0,0,0,0,,,0,0,0,0,,,0,0,0,0,,,0,0,0,0,,,0,0,0,0,,,0,0,0,0,,,0,0,0,0,,,0,0,0,0,,,0,0,0,0,,,0,0,0,0,AAPL
2024-10-22 12:00:01.790765201+00:00,10,41,38,A,A,0,235.29,200,194,56414,57024,,235.29,0,200,0,0,,,0,0,0,0,,,0,0,0,0,,,0,0,0,0,,,0,0,0,0,,,0,0,0,0,,,0,0,0,0,,,0,0,0,0,,,0,0,0,0,,,0,0,0,0,AAPL
2024-10-22 12:00:01.802350260+00:00,10,41,38,A,A,0,,0,194,55653,57028,,,0,0,0,0,,,0,0,0,0,,,0,0,0,0,,,0,0,0,0,,,0,0,0,0,,,0,0,0,0,,,0,0,0,0,,,0,0,0,0,,,0,0,0,0,,,0,0,0,0,AAPL
2024-10-22 12:00:01.946098926+00:00,10,41,38,A,A,0,235.29,200,194,56413,57045,,235.29,0,200,0,0,,,0,0,0,0,,,0,0,0,0,,,0,0,0,0,,,0,0,0,0,,,0,0,0,0,,,0,0,0,0,,,0,0,0,0,,,0,0,0,0,,,0,0,0,0,AAPL
2024-10-22 12:00:01.971976364+00:00,10,41,38,A,A,0,,0,194,55550,57051,,,0,0,0,0,,,0,0,0,0,,,0,0,0,0,,,0,0,0,0,,,0,0,0,0,,,0,0,0,0,,,0,0,0,0,,,0,0,0,0,,,0,0,0,0,,,0,0,0,0,AAPL
2024-10-22 12:00:02.153194685+00:00,10,41,38,A,A,0,235.29,200,194,56906,57089,,235.29,0,200,0,0,,,0,0,0,0,,,0,0,0,0,,,0,0,0,0,,,0,0,0,0,,,0,0,0,0,,,0,0,0,0,,,0,0,0,0,,,0,0,0,0,,,0,0,0,0,AAPL
2024-10-22 12:00:02.341756922+00:00,10,41,38,A,A,0,,0,194,56020,57115,,,0,0,0,0,,,0,0,0,0,,,0,0,0,0,,,0,0,0,0,,,0,0,0,0,,,0,0,0,0,,,0,0,0,0,,,0,0,0,0,,,0,0,0,0,,,0,0,0,0,AAPL
2024-10-22 12:00:03.103943684+00:00,10,39,38,A,B,0,233.6,2000,130,203576,36696,233.6,237.0,2000,2000,1,1,233.2,,2000,0,1,0,,,0,0,0,0,,,0,0,0,0,,,0,0,0,0,,,0,0,0,0,,,0,0,0,0,,,0,0,0,0,,,0,0,0,0,,,0,0,0,0,AAPL
2024-10-22 12:00:03.104120835+00:00,10,39,38,C,B,1,233.2,2000,130,203411,36697,233.6,237.0,2000,2000,1,1,,,0,0,0,0,,,0,0,0,0,,,0,0,0,0,,,0,0,0,0,,,0,0,0,0,,,0,0,0,0,,,0,0,0,0,,,0,0,0,0,,,0,0,0,0,AAPL
2024-10-22 12:00:03.867075103+00:00,10,40,38,A,A,0,235.36,200,194,203102,55701,,235.36,0,200,0,0,,,0,0,0,0,,,0,0,0,0,,,0,0,0,0,,,0,0,0,0,,,0,0,0,0,,,0,0,0,0,,,0,0,0,0,,,0,0,0,0,,,0,0,0,0,AAPL
2024-10-22 12:00:03.867249619+00:00,10,40,38,A,B,0,235.36,200,194,203113,55702,234.42,235.36,200,200,0,0,,,0,0,0,0,,,0,0,0,0,,,0,0,0,0,,,0,0,0,0,,,0,0,0,0,,,0,0,0,0,,,0,0,0,0,,,0,0,0,0,,,0,0,0,0,AAPL
2024-10-22 12:00:03.867564784+00:00,10,41,38,A,A,0,235.29,200,194,56276,57324,,235.29,0,200,0,0,,,0,0,0,0,,,0,0,0,0,,,0,0,0,0,,,0,0,0,0,,,0,0,0,0,,,0,0,0,0,,,0,0,0,0,,,0,0,0,0,,,0,0,0,0,AAPL
2024-10-22 12:00:03.867801469+00:00,10,41,38,A,B,0,235.29,200,194,55239,57325,234.49,235.29,200,200,0,0,,,0,0,0,0,,,0,0,0,0,,,0,0,0,0,,,0,0,0,0,,,0,0,0,0,,,0,0,0,0,,,0,0,0,0,,,0,0,0,0,,,0,0,0,0,AAPL
2024-10-22 12:00:03.884560620+00:00,10,40,38,A,B,0,235.36,200,194,203047,55704,,235.36,0,200,0,0,,,0,0,0,0,,,0,0,0,0,,,0,0,0,0,,,0,0,0,0,,,0,0,0,0,,,0,0,0,0,,,0,0,0,0,,,0,0,0,0,,,0,0,0,0,AAPL
2024-10-22 12:00:03.884644756+00:00,10,40,38,A,A,0,,0,194,203029,55705,,,0,0,0,0,,,0,0,0,0,,,0,0,0,0,,,0,0,0,0,,,0,0,0,0,,,0,0,0,0,,,0,0,0,0,,,0,0,0,0,,,0,0,0,0,,,0,0,0,0,AAPL
2024-10-22 12:00:04.942359549+00:00,10,41,38,A,B,0,235.29,200,194,57109,57429,,235.29,0,200,0,0,,,0,0,0,0,,,0,0,0,0,,,0,0,0,0,,,0,0,0,0,,,0,0,0,0,,,0,0,0,0,,,0,0,0,0,,,0,0,0,0,,,0,0,0,0,AAPL
2024-10-22 12:00:04.952004220+00:00,10,41,38,A,A,0,,0,194,54899,57432,,,0,0,0,0,,,0,0,0,0,,,0,0,0,0,,,0,0,0,0,,,0,0,0,0,,,0,0,0,0,,,0,0,0,0,,,0,0,0,0,,,0,0,0,0,,,0,0,0,0,AAPL
2024-10-22 12:00:05.015887284+00:00,10,41,38,A,A,0,235.29,200,194,55645,57444,,235.29,0,200,0,0,,,0,0,0,0,,,0,0,0,0,,,0,0,0,0,,,0,0,0,0,,,0,0,0,0,,,0,0,0,0,,,0,0,0,0,,,0,0,0,0,,,0,0,0,0,AAPL
2024-10-22 12:00:05.016688943+00:00,10,41,38,A,B,0,235.29,200,194,55533,57445,234.49,235.29,200,200,0,0,,,0,0,0,0,,,0,0,0,0,,,0,0,0,0,,,0,0,0,0,,,0,0,0,0,,,0,0,0,0,,,0,0,0,0,,,0,0,0,0,,,0,0,0,0,AAPL
2024-10-22 12:00:05.046123616+00:00,10,41,38,A,A,0,,0,194,56327,57448,234.49,,200,0,0,0,,,0,0,0,0,,,0,0,0,0,,,0,0,0,0,,,0,0,0,0,,,0,0,0,0,,,0,0,0,0,,,0,0,0,0,,,0,0,0,0,,,0,0,0,0,AAPL
2024-10-22 12:00:05.166346314+00:00,10,41,38,A,A,0,235.29,200,194,63347,57458,234.49,235.29,200,200,0,0,,,0,0,0,0,,,0,0,0,0,,,0,0,0,0,,,0,0,0,0,,,0,0,0,0,,,0,0,0,0,,,0,0,0,0,,,0,0,0,0,,,0,0,0,0,AAPL
2024-10-22 12:00:05.234408333+00:00,10,41,38,A,B,0,235.29,200,194,56110,57460,,235.29,0,200,0,0,,,0,0,0,0,,,0,0,0,0,,,0,0,0,0,,,0,0,0,0,,,0,0,0,0,,,0,0,0,0,,,0,0,0,0,,,0,0,0,0,,,0,0,0,0,AAPL
2024-10-22 12:00:05.428011918+00:00,10,40,38,A,A,0,235.36,200,194,203108,55744,,235.36,0,200,0,0,,,0,0,0,0,,,0,0,0,0,,,0,0,0,0,,,0,0,0,0,,,0,0,0,0,,,0,0,0,0,,,0,0,0,0,,,0,0,0,0,,,0,0,0,0,AAPL
2024-10-22 12:00:05.428171741+00:00,10,40,38,A,B,0,235.36,200,194,203024,55745,234.38,235.36,200,200,0,0,,,0,0,0,0,,,0,0,0,0,,,0,0,0,0,,,0,0,0,0,,,0,0,0,0,,,0,0,0,0,,,0,0,0,0,,,0,0,0,0,,,0,0,0,0,AAPL
2024-10-22 12:00:05.428571681+00:00,10,41,38,A,B,0,235.29,200,194,64150,57483,234.49,235.29,200,200,0,0,,,0,0,0,0,,,0,0,0,0,,,0,0,0,0,,,0,0,0,0,,,0,0,0,0,,,0,0,0,0,,,0,0,0,0,,,0,0,0,0,,,0,0,0,0,AAPL
2024-10-22 12:00:05.429139211+00:00,10,39,38,C,B,0,233.6,2000,130,203793,36710,,237.0,0,2000,0,1,,,0,0,0,0,,,0,0,0,0,,,0,0,0,0,,,0,0,0,0,,,0,0,0,0,,,0,0,0,0,,,0,0,0,0,,,0,0,0,0,,,0,0,0,0,AAPL
2024-10-22 12:00:05.439243501+00:00,10,39,38,A,A,0,236.8,2000,130,203795,36711,,236.8,0,2000,0,1,,237.0,0,2000,0,1,,,0,0,0,0,,,0,0,0,0,,,0,0,0,0,,,0,0,0,0,,,0,0,0,0,,,0,0,0,0,,,0,0,0,0,,,0,0,0,0,AAPL
2024-10-22 12:00:05.439443649+00:00,10,39,38,C,A,1,237.0,2000,130,203789,36712,,236.8,0,2000,0,1,,,0,0,0,0,,,0,0,0,0,,,0,0,0,0,,,0,0,0,0,,,0,0,0,0,,,0,0,0,0,,,0,0,0,0,,,0,0,0,0,,,0,0,0,0,AAPL
2024-10-22 12:00:05.464474113+00:00,10,39,38,A,B,0,233.6,2000,130,203881,36713,233.6,236.8,2000,2000,1,1,,,0,0,0,0,,,0,0,0,0,,,0,0,0,0,,,0,0,0,0,,,0,0,0,0,,,0,0,0,0,,,0,0,0,0,,,0,0,0,0,,,0,0,0,0,AAPL
2024-10-22 12:00:05.464524064+00:00,10,40,38,A,B,0,235.36,200,194,203102,55747,,235.36,0,200,0,0,,,0,0,0,0,,,0,0,0,0,,,0,0,0,0,,,0,0,0,0,,,0,0,0,0,,,0,0,0,0,,,0,0,0,0,,,0,0,0,0,,,0,0,0,0,AAPL
2024-10-22 12:00:05.476906567+00:00,10,41,38,A,B,0,235.29,200,194,55897,57490,,235.29,0,200,0,0,,,0,0,0,0,,,0,0,0,0,,,0,0,0,0,,,0,0,0,0,,,0,0,0,0,,,0,0,0,0,,,0,0,0,0,,,0,0,0,0,,,0,0,0,0,AAPL
2024-10-22 12:00:05.707816178+00:00,10,40,38,A,B,0,235.36,200,194,203096,55762,234.38,235.36,200,200,0,0,,,0,0,0,0,,,0,0,0,0,,,0,0,0,0,,,0,0,0,0,,,0,0,0,0,,,0,0,0,0,,,0,0,0,0,,,0,0,0,0,,,0,0,0,0,AAPL
2024-10-22 12:00:05.707905331+00:00,10,40,38,A,B,0,235.36,200,194,203097,55763,,235.36,0,200,0,0,,,0,0,0,0,,,0,0,0,0,,,0,0,0,0,,,0,0,0,0,,,0,0,0,0,,,0,0,0,0,,,0,0,0,0,,,0,0,0,0,,,0,0,0,0,AAPL
2024-10-22 12:00:05.708055497+00:00,10,40,38,A,A,0,,0,194,203009,55764,,,0,0,0,0,,,0,0,0,0,,,0,0,0,0,,,0,0,0,0,,,0,0,0,0,,,0,0,0,0,,,0,0,0,0,,,0,0,0,0,,,0,0,0,0,,,0,0,0,0,AAPL
2024-10-22 12:00:05.708147412+00:00,10,41,38,A,B,0,235.29,200,194,56337,57519,234.45,235.29,200,200,0,0,,,0,0,0,0,,,0,0,0,0,,,0,0,0,0,,,0,0,0,0,,,0,0,0,0,,,0,0,0,0,,,0,0,0,0,,,0,0,0,0,,,0,0,0,0,AAPL
2024-10-22 12:00:05.708221128+00:00,10,40,38,A,A,0,235.34,200,194,203138,55765,,235.34,0,200,0,0,,,0,0,0,0,,,0,0,0,0,,,0,0,0,0,,,0,0,0,0,,,0,0,0,0,,,0,0,0,0,,,0,0,0,0,,,0,0,0,0,,,0,0,0,0,AAPL
2024-10-22 12:00:05.708320864+00:00,10,39,38,C,B,0,233.6,2000,130,204086,36716,,236.8,0,2000,0,1,,,0,0,0,0,,,0,0,0,0,,,0,0,0,0,,,0,0,0,0,,,0,0,0,0,,,0,0,0,0,,,0,0,0,0,,,0,0,0,0,,,0,0,0,0,AAPL
2024-10-22 12:00:05.743539284+00:00,10,39,38,A,B,0,233.4,2000,130,203857,36717,233.4,236.8,2000,2000,1,1,,,0,0,0,0,,,0,0,0,0,,,0,0,0,0,,,0,0,0,0,,,0,0,0,0,,,0,0,0,0,,,0,0,0,0,,,0,0,0,0,,,0,0,0,0,AAPL
2024-10-22 12:00:05.760219409+00:00,10,41,38,A,B,0,235.29,200,194,54820,57526,,235.29,0,200,0,0,,,0,0,0,0,,,0,0,0,0,,,0,0,0,0,,,0,0,0,0,,,0,0,0,0,,,0,0,0,0,,,0,0,0,0,,,0,0,0,0,,,0,0,0,0,AAPL
2024-10-22 12:00:05.760735513+00:00,10,39,38,C,A,0,236.8,2000,130,204027,36718,233.4,,2000,0,1,0,,,0,0,0,0,,,0,0,0,0,,,0,0,0,0,,,0,0,0,0,,,0,0,0,0,,,0,0,0,0,,,0,0,0,0,,,0,0,0,0,,,0,0,0,0,AAPL
2024-10-22 12:00:05.778840653+00:00,10,39,38,A,A,0,236.8,2000,130,203722,36719,233.4,236.8,2000,2000,1,1,,,0,0,0,0,,,0,0,0,0,,,0,0,0,0,,,0,0,0,0,,,0,0,0,0,,,0,0,0,0,,,0,0,0,0,,,0,0,0,0,,,0,0,0,0,AAPL
2024-10-22 12:00:05.811788747+00:00,10,39,38,C,A,0,236.8,2000,130,203831,36720,233.4,,2000,0,1,0,,,0,0,0,0,,,0,0,0,0,,,0,0,0,0,,,0,0,0,0,,,0,0,0,0,,,0,0,0,0,,,0,0,0,0,,,0,0,0,0,,,0,0,0,0,AAPL
2024-10-22 12:00:05.825913811+00:00,10,39,38,A,A,0,236.8,2000,130,203770,36721,233.4,236.8,2000,2000,1,1,,,0,0,0,0,,,0,0,0,0,,,0,0,0,0,,,0,0,0,0,,,0,0,0,0,,,0,0,0,0,,,0,0,0,0,,,0,0,0,0,,,0,0,0,0,AAPL
2024-10-22 12:00:05.990107541+00:00,10,40,38,A,B,0,235.34,200,194,203136,55783,234.36,235.34,200,200,0,0,,,0,0,0,0,,,0,0,0,0,,,0,0,0,0,,,0,0,0,0,,,0,0,0,0,,,0,0,0,0,,,0,0,0,0,,,0,0,0,0,,,0,0,0,0,AAPL
2024-10-22 12:00:05.990252691+00:00,10,41,38,A,B,0,235.29,200,194,56636,57549,234.44,235.29,200,200,0,0,,,0,0,0,0,,,0,0,0,0,,,0,0,0,0,,,0,0,0,0,,,0,0,0,0,,,0,0,0,0,,,0,0,0,0,,,0,0,0,0,,,0,0,0,0,AAPL
2024-10-22 12:00:05.990485533+00:00,10,39,38,C,B,0,233.4,2000,130,203826,36722,,236.8,0,2000,0,1,,,0,0,0,0,,,0,0,0,0,,,0,0,0,0,,,0,0,0,0,,,0,0,0,0,,,0,0,0,0,,,0,0,0,0,,,0,0,0,0,,,0,0,0,0,AAPL
2024-10-22 12:00:06.020908151+00:00,10,40,38,A,B,0,235.34,200,194,203256,55786,,235.34,0,200,0,0,,,0,0,0,0,,,0,0,0,0,,,0,0,0,0,,,0,0,0,0,,,0,0,0,0,,,0,0,0,0,,,0,0,0,0,,,0,0,0,0,,,0,0,0,0,AAPL
2024-10-22 12:00:06.021219175+00:00,10,41,38,A,B,0,235.29,200,194,56240,57550,,235.29,0,200,0,0,,,0,0,0,0,,,0,0,0,0,,,0,0,0,0,,,0,0,0,0,,,0,0,0,0,,,0,0,0,0,,,0,0,0,0,,,0,0,0,0,,,0,0,0,0,AAPL
2024-10-22 12:00:06.021586503+00:00,10,39,38,C,A,0,236.8,2000,130,203824,36724,,,0,0,0,0,,,0,0,0,0,,,0,0,0,0,,,0,0,0,0,,,0,0,0,0,,,0,0,0,0,,,0,0,0,0,,,0,0,0,0,,,0,0,0,0,,,0,0,0,0,AAPL
2024-10-22 12:00:06.027098271+00:00,10,39,38,A,B,0,233.0,2000,130,204337,36725,233.0,,2000,0,1,0,,,0,0,0,0,,,0,0,0,0,,,0,0,0,0,,,0,0,0,0,,,0,0,0,0,,,0,0,0,0,,,0,0,0,0,,,0,0,0,0,,,0,0,0,0,AAPL
2024-10-22 12:00:06.034859511+00:00,10,39,38,A,A,0,237.0,2000,130,203867,36726,233.0,237.0,2000,2000,1,1,,,0,0,0,0,,,0,0,0,0,,,0,0,0,0,,,0,0,0,0,,,0,0,0,0,,,0,0,0,0,,,0,0,0,0,,,0,0,0,0,,,0,0,0,0,AAPL
2024-10-22 12:00:06.047432248+00:00,10,39,38,A,A,0,236.8,2000,130,203767,36727,233.0,236.8,2000,2000,1,1,,237.0,0,2000,0,1,,,0,0,0,0,,,0,0,0,0,,,0,0,0,0,,,0,0,0,0,,,0,0,0,0,,,0,0,0,0,,,0,0,0,0,,,0,0,0,0,AAPL
2024-10-22 12:00:06.047623357+00:00,10,39,38,C,A,1,237.0,2000,130,203710,36728,233.0,236.8,2000,2000,1,1,,,0,0,0,0,,,0,0,0,0,,,0,0,0,0,,,0,0,0,0,,,0,0,0,0,,,0,0,0,0,,,0,0,0,0,,,0,0,0,0,,,0,0,0,0,AAPL
2024-10-22 12:00:06.099558303+00:00,10,39,38,C,A,0,236.8,2000,130,203840,36729,233.0,,2000,0,1,0,,,0,0,0,0,,,0,0,0,0,,,0,0,0,0,,,0,0,0,0,,,0,0,0,0,,,0,0,0,0,,,0,0,0,0,,,0,0,0,0,,,0,0,0,0,AAPL
2024-10-22 12:00:06.110696682+00:00,10,39,38,A,A,0,237.0,2000,130,203807,36730,233.0,237.0,2000,2000,1,1,,,0,0,0,0,,,0,0,0,0,,,0,0,0,0,,,0,0,0,0,,,0,0,0,0,,,0,0,0,0,,,0,0,0,0,,,0,0,0,0,,,0,0,0,0,AAPL
2024-10-22 12:00:06.242499761+00:00,10,40,38,A,A,0,,0,194,203131,55799,,,0,0,0,0,,,0,0,0,0,,,0,0,0,0,,,0,0,0,0,,,0,0,0,0,,,0,0,0,0,,,0,0,0,0,,,0,0,0,0,,,0,0,0,0,,,0,0,0,0,AAPL
2024-10-22 12:00:06.242799621+00:00,10,41,38,A,A,0,,0,194,56411,57572,,,0,0,0,0,,,0,0,0,0,,,0,0,0,0,,,0,0,0,0,,,0,0,0,0,,,0,0,0,0,,,0,0,0,0,,,0,0,0,0,,,0,0,0,0,,,0,0,0,0,AAPL
2024-10-22 12:00:06.722886692+00:00,10,41,38,A,A,0,235.28,200,194,56182,57594,,235.28,0,200,0,0,,,0,0,0,0,,,0,0,0,0,,,0,0,0,0,,,0,0,0,0,,,0,0,0,0,,,0,0,0,0,,,0,0,0,0,,,0,0,0,0,,,0,0,0,0,AAPL
2024-10-22 12:00:07.010677181+00:00,10,39,38,C,B,0,233.0,2000,130,204614,36738,,237.0,0,2000,0,1,,,0,0,0,0,,,0,0,0,0,,,0,0,0,0,,,0,0,0,0,,,0,0,0,0,,,0,0,0,0,,,0,0,0,0,,,0,0,0,0,,,0,0,0,0,AAPL
2024-10-22 12:00:07.022235378+00:00,10,39,38,A,B,0,232.8,2000,130,203948,36739,232.8,237.0,2000,2000,1,1,,,0,0,0,0,,,0,0,0,0,,,0,0,0,0,,,0,0,0,0,,,0,0,0,0,,,0,0,0,0,,,0,0,0,0,,,0,0,0,0,,,0,0,0,0,AAPL
2024-10-22 12:00:07.103944952+00:00,10,40,38,A,A,0,235.35,200,194,203245,55839,,235.35,0,200,0,0,,,0,0,0,0,,,0,0,0,0,,,0,0,0,0,,,0,0,0,0,,,0,0,0,0,,,0,0,0,0,,,0,0,0,0,,,0,0,0,0,,,0,0,0,0,AAPL
2024-10-22 12:00:07.104084517+00:00,10,40,38,A,B,0,235.35,200,194,203152,55840,234.37,235.35,200,200,0,0,,,0,0,0,0,,,0,0,0,0,,,0,0,0,0,,,0,0,0,0,,,0,0,0,0,,,0,0,0,0,,,0,0,0,0,,,0,0,0,0,,,0,0,0,0,AAPL
2024-10-22 12:00:07.104441165+00:00,10,41,38,A,B,0,235.28,200,194,56214,57617,234.44,235.28,200,200,0,0,,,0,0,0,0,,,0,0,0,0,,,0,0,0,0,,,0,0,0,0,,,0,0,0,0,,,0,0,0,0,,,0,0,0,0,,,0,0,0,0,,,0,0,0,0,AAPL
2024-10-22 12:00:07.148091363+00:00,10,40,38,A,B,0,235.35,200,194,203129,55843,,235.35,0,200,0,0,,,0,0,0,0,,,0,0,0,0,,,0,0,0,0,,,0,0,0,0,,,0,0,0,0,,,0,0,0,0,,,0,0,0,0,,,0,0,0,0,,,0,0,0,0,AAPL
2024-10-22 12:00:07.148413312+00:00,10,41,38,A,B,0,235.28,200,194,57308,57624,,235.28,0,200,0,0,,,0,0,0,0,,,0,0,0,0,,,0,0,0,0,,,0,0,0,0,,,0,0,0,0,,,0,0,0,0,,,0,0,0,0,,,0,0,0,0,,,0,0,0,0,AAPL
2024-10-22 12:00:07.176152246+00:00,10,40,38,A,A,0,,0,194,203140,55846,,,0,0,0,0,,,0,0,0,0,,,0,0,0,0,,,0,0,0,0,,,0,0,0,0,,,0,0,0,0,,,0,0,0,0,,,0,0,0,0,,,0,0,0,0,,,0,0,0,0,AAPL
2024-10-22 12:00:07.349325042+00:00,10,40,38,A,A,0,235.35,200,194,203223,55854,,235.35,0,200,0,0,,,0,0,0,0,,,0,0,0,0,,,0,0,0,0,,,0,0,0,0,,,0,0,0,0,,,0,0,0,0,,,0,0,0,0,,,0,0,0,0,,,0,0,0,0,AAPL
2024-10-22 12:00:07.550701434+00:00,10,40,38,A,A,0,,0,194,203206,55858,,,0,0,0,0,,,0,0,0,0,,,0,0,0,0,,,0,0,0,0,,,0,0,0,0,,,0,0,0,0,,,0,0,0,0,,,0,0,0,0,,,0,0,0,0,,,0,0,0,0,AAPL
2024-10-22 12:00:07.640974197+00:00,10,40,38,A,A,0,235.35,200,194,203250,55859,,235.35,0,200,0,0,,,0,0,0,0,,,0,0,0,0,,,0,0,0,0,,,0,0,0,0,,,0,0,0,0,,,0,0,0,0,,,0,0,0,0,,,0,0,0,0,,,0,0,0,0,AAPL
2024-10-22 12:00:07.659664261+00:00,10,40,38,A,B,0,235.35,200,194,203143,55861,234.35,235.35,200,200,0,0,,,0,0,0,0,,,0,0,0,0,,,0,0,0,0,,,0,0,0,0,,,0,0,0,0,,,0,0,0,0,,,0,0,0,0,,,0,0,0,0,,,0,0,0,0,AAPL
2024-10-22 12:00:07.659744055+00:00,10,40,38,A,B,0,235.35,200,194,203147,55862,,235.35,0,200,0,0,,,0,0,0,0,,,0,0,0,0,,,0,0,0,0,,,0,0,0,0,,,0,0,0,0,,,0,0,0,0,,,0,0,0,0,,,0,0,0,0,,,0,0,0,0,AAPL
2024-10-22 12:00:07.660301942+00:00,10,41,38,A,B,0,235.28,200,194,57211,57716,234.42,235.28,200,200,0,0,,,0,0,0,0,,,0,0,0,0,,,0,0,0,0,,,0,0,0,0,,,0,0,0,0,,,0,0,0,0,,,0,0,0,0,,,0,0,0,0,,,0,0,0,0,AAPL
2024-10-22 12:00:07.660346760+00:00,10,41,38,A,B,0,235.28,200,194,56355,57717,,235.28,0,200,0,0,,,0,0,0,0,,,0,0,0,0,,,0,0,0,0,,,0,0,0,0,,,0,0,0,0,,,0,0,0,0,,,0,0,0,0,,,0,0,0,0,,,0,0,0,0,AAPL
2024-10-22 12:00:07.665263990+00:00,10,39,38,C,A,0,237.0,2000,130,204383,36740,232.8,,2000,0,1,0,,,0,0,0,0,,,0,0,0,0,,,0,0,0,0,,,0,0,0,0,,,0,0,0,0,,,0,0,0,0,,,0,0,0,0,,,0,0,0,0,,,0,0,0,0,AAPL
2024-10-22 12:00:07.676424557+00:00,10,39,38,A,A,0,237.2,2000,130,203890,36741,232.8,237.2,2000,2000,1,1,,,0,0,0,0,,,0,0,0,0,,,0,0,0,0,,,0,0,0,0,,,0,0,0,0,,,0,0,0,0,,,0,0,0,0,,,0,0,0,0,,,0,0,0,0,AAPL
2024-10-22 12:00:07.687726729+00:00,10,39,38,A,A,0,237.0,2000,130,203920,36742,232.8,237.0,2000,2000,1,1,,237.2,0,2000,0,1,,,0,0,0,0,,,0,0,0,0,,,0,0,0,0,,,0,0,0,0,,,0,0,0,0,,,0,0,0,0,,,0,0,0,0,,,0,0,0,0,AAPL
2024-10-22 12:00:07.687902511+00:00,10,39,38,C,A,1,237.2,2000,130,203846,36743,232.8,237.0,2000,2000,1,1,,,0,0,0,0,,,0,0,0,0,,,0,0,0,0,,,0,0,0,0,,,0,0,0,0,,,0,0,0,0,,,0,0,0,0,,,0,0,0,0,,,0,0,0,0,AAPL
2024-10-22 12:00:07.726166733+00:00,10,39,38,C,A,0,237.0,2000,130,203847,36744,232.8,,2000,0,1,0,,,0,0,0,0,,,0,0,0,0,,,0,0,0,0,,,0,0,0,0,,,0,0,0,0,,,0,0,0,0,,,0,0,0,0,,,0,0,0,0,,,0,0,0,0,AAPL
2024-10-22 12:00:07.745148331+00:00,10,39,38,A,A,0,237.0,2000,130,203852,36745,232.8,237.0,2000,2000,1,1,,,0,0,0,0,,,0,0,0,0,,,0,0,0,0,,,0,0,0,0,,,0,0,0,0,,,0,0,0,0,,,0,0,0,0,,,0,0,0,0,,,0,0,0,0,AAPL
2024-10-22 12:00:09.458524564+00:00,10,41,38,A,B,0,235.28,200,194,55735,57874,234.42,235.28,200,200,0,0,,,0,0,0,0,,,0,0,0,0,,,0,0,0,0,,,0,0,0,0,,,0,0,0,0,,,0,0,0,0,,,0,0,0,0,,,0,0,0,0,,,0,0,0,0,AAPL
2024-10-22 12:00:09.458786049+00:00,10,39,38,C,B,0,232.8,2000,130,204382,36767,,237.0,0,2000,0,1,,,0,0,0,0,,,0,0,0,0,,,0,0,0,0,,,0,0,0,0,,,0,0,0,0,,,0,0,0,0,,,0,0,0,0,,,0,0,0,0,,,0,0,0,0,AAPL
2024-10-22 12:00:09.459420300+00:00,10,41,38,A,B,0,235.28,200,194,56766,57875,,235.28,0,200,0,0,,,0,0,0,0,,,0,0,0,0,,,0,0,0,0,,,0,0,0,0,,,0,0,0,0,,,0,0,0,0,,,0,0,0,0,,,0,0,0,0,,,0,0,0,0,AAPL
2024-10-22 12:00:09.494724227+00:00,10,39,38,A,B,0,232.8,2000,130,204200,36768,232.8,237.0,2000,2000,1,1,,,0,0,0,0,,,0,0,0,0,,,0,0,0,0,,,0,0,0,0,,,0,0,0,0,,,0,0,0,0,,,0,0,0,0,,,0,0,0,0,,,0,0,0,0,AAPL
2024-10-22 12:00:09.522273178+00:00,10,39,38,C,A,0,237.0,2000,130,204223,36769,232.8,,2000,0,1,0,,,0,0,0,0,,,0,0,0,0,,,0,0,0,0,,,0,0,0,0,,,0,0,0,0,,,0,0,0,0,,,0,0,0,0,,,0,0,0,0,,,0,0,0,0,AAPL
2024-10-22 12:00:09.528485916+00:00,10,39,38,C,B,0,232.8,2000,130,204043,36770,,,0,0,0,0,,,0,0,0,0,,,0,0,0,0,,,0,0,0,0,,,0,0,0,0,,,0,0,0,0,,,0,0,0,0,,,0,0,0,0,,,0,0,0,0,,,0,0,0,0,AAPL
2024-10-22 12:00:09.533810737+00:00,10,39,38,A,A,0,237.2,2000,130,204082,36771,,237.2,0,2000,0,1,,,0,0,0,0,,,0,0,0,0,,,0,0,0,0,,,0,0,0,0,,,0,0,0,0,,,0,0,0,0,,,0,0,0,0,,,0,0,0,0,,,0,0,0,0,AAPL
2024-10-22 12:00:09.542392340+00:00,10,39,38,A,B,0,232.8,2000,130,204231,36772,232.8,237.2,2000,2000,1,1,,,0,0,0,0,,,0,0,0,0,,,0,0,0,0,,,0,0,0,0,,,0,0,0,0,,,0,0,0,0,,,0,0,0,0,,,0,0,0,0,,,0,0,0,0,AAPL
2024-10-22 12:00:09.652692966+00:00,10,40,38,A,B,0,235.35,200,194,203352,55954,234.34,235.35,200,200,0,0,,,0,0,0,0,,,0,0,0,0,,,0,0,0,0,,,0,0,0,0,,,0,0,0,0,,,0,0,0,0,,,0,0,0,0,,,0,0,0,0,,,0,0,0,0,AAPL
2024-10-22 12:00:09.653095101+00:00,10,41,38,A,B,0,235.28,200,194,57998,57907,234.41,235.28,200,200,0,0,,,0,0,0,0,,,0,0,0,0,,,0,0,0,0,,,0,0,0,0,,,0,0,0,0,,,0,0,0,0,,,0,0,0,0,,,0,0,0,0,,,0,0,0,0,AAPL
2024-10-22 12:00:09.653393848+00:00,10,39,38,C,B,0,232.8,2000,130,204011,36774,,237.2,0,2000,0,1,,,0,0,0,0,,,0,0,0,0,,,0,0,0,0,,,0,0,0,0,,,0,0,0,0,,,0,0,0,0,,,0,0,0,0,,,0,0,0,0,,,0,0,0,0,AAPL
2024-10-22 12:00:09.664065862+00:00,10,39,38,A,A,0,236.8,2000,130,204027,36777,,236.8,0,2000,0,1,,237.2,0,2000,0,1,,,0,0,0,0,,,0,0,0,0,,,0,0,0,0,,,0,0,0,0,,,0,0,0,0,,,0,0,0,0,,,0,0,0,0,,,0,0,0,0,AAPL
2024-10-22 12:00:09.664446447+00:00,10,39,38,C,A,1,237.2,2000,130,204036,36778,,236.8,0,2000,0,1,,,0,0,0,0,,,0,0,0,0,,,0,0,0,0,,,0,0,0,0,,,0,0,0,0,,,0,0,0,0,,,0,0,0,0,,,0,0,0,0,,,0,0,0,0,AAPL
2024-10-22 12:00:09.689281476+00:00,10,39,38,C,A,0,236.8,2000,130,204023,36779,,,0,0,0,0,,,0,0,0,0,,,0,0,0,0,,,0,0,0,0,,,0,0,0,0,,,0,0,0,0,,,0,0,0,0,,,0,0,0,0,,,0,0,0,0,,,0,0,0,0,AAPL
2024-10-22 12:00:09.689373871+00:00,10,40,38,A,B,0,235.35,200,194,203324,55961,,235.35,0,200,0,0,,,0,0,0,0,,,0,0,0,0,,,0,0,0,0,,,0,0,0,0,,,0,0,0,0,,,0,0,0,0,,,0,0,0,0,,,0,0,0,0,,,0,0,0,0,AAPL
2024-10-22 12:00:09.701829715+00:00,10,39,38,A,A,0,236.8,2000,130,204020,36782,,236.8,0,2000,0,1,,,0,0,0,0,,,0,0,0,0,,,0,0,0,0,,,0,0,0,0,,,0,0,0,0,,,0,0,0,0,,,0,0,0,0,,,0,0,0,0,,,0,0,0,0,AAPL
2024-10-22 12:00:09.721236941+00:00,10,39,38,C,A,0,236.8,2000,130,204032,36784,,,0,0,0,0,,,0,0,0,0,,,0,0,0,0,,,0,0,0,0,,,0,0,0,0,,,0,0,0,0,,,0,0,0,0,,,0,0,0,0,,,0,0,0,0,,,0,0,0,0,AAPL
2024-10-22 12:00:09.732586136+00:00,10,39,38,A,A,0,237.0,2000,130,204063,36785,,237.0,0,2000,0,1,,,0,0,0,0,,,0,0,0,0,,,0,0,0,0,,,0,0,0,0,,,0,0,0,0,,,0,0,0,0,,,0,0,0,0,,,0,0,0,0,,,0,0,0,0,AAPL
2024-10-22 12:00:09.777762581+00:00,10,41,38,A,B,0,235.28,200,194,58000,57920,,235.28,0,200,0,0,,,0,0,0,0,,,0,0,0,0,,,0,0,0,0,,,0,0,0,0,,,0,0,0,0,,,0,0,0,0,,,0,0,0,0,,,0,0,0,0,,,0,0,0,0,AAPL
2024-10-22 12:00:09.804121206+00:00,10,40,38,A,B,0,235.35,200,194,203360,55970,234.28,235.35,200,200,0,0,,,0,0,0,0,,,0,0,0,0,,,0,0,0,0,,,0,0,0,0,,,0,0,0,0,,,0,0,0,0,,,0,0,0,0,,,0,0,0,0,,,0,0,0,0,AAPL
2024-10-22 12:00:09.804563756+00:00,10,41,38,A,B,0,235.28,200,194,56087,57923,234.35,235.28,200,200,0,0,,,0,0,0,0,,,0,0,0,0,,,0,0,0,0,,,0,0,0,0,,,0,0,0,0,,,0,0,0,0,,,0,0,0,0,,,0,0,0,0,,,0,0,0,0,AAPL
2024-10-22 12:00:09.817305652+00:00,10,39,38,A,B,0,232.4,2000,130,204172,36786,232.4,237.0,2000,2000,1,1,,,0,0,0,0,,,0,0,0,0,,,0,0,0,0,,,0,0,0,0,,,0,0,0,0,,,0,0,0,0,,,0,0,0,0,,,0,0,0,0,,,0,0,0,0,AAPL
2024-10-22 12:00:09.919908999+00:00,10,40,38,A,B,0,235.35,200,194,203286,55976,,235.35,0,200,0,0,,,0,0,0,0,,,0,0,0,0,,,0,0,0,0,,,0,0,0,0,,,0,0,0,0,,,0,0,0,0,,,0,0,0,0,,,0,0,0,0,,,0,0,0,0,AAPL
2024-10-22 12:00:09.920217824+00:00,10,41,38,A,B,0,235.28,200,194,61968,57932,,235.28,0,200,0,0,,,0,0,0,0,,,0,0,0,0,,,0,0,0,0,,,0,0,0,0,,,0,0,0,0,,,0,0,0,0,,,0,0,0,0,,,0,0,0,0,,,0,0,0,0,AAPL
2024-10-22 12:00:10.164280297+00:00,10,40,38,A,B,0,235.35,200,194,203270,55992,234.27,235.35,200,200,0,0,,,0,0,0,0,,,0,0,0,0,,,0,0,0,0,,,0,0,0,0,,,0,0,0,0,,,0,0,0,0,,,0,0,0,0,,,0,0,0,0,,,0,0,0,0,AAPL
2024-10-22 12:00:10.164949301+00:00,10,41,38,A,B,0,235.28,200,194,63853,57963,234.34,235.28,200,200,0,0,,,0,0,0,0,,,0,0,0,0,,,0,0,0,0,,,0,0,0,0,,,0,0,0,0,,,0,0,0,0,,,0,0,0,0,,,0,0,0,0,,,0,0,0,0,AAPL
2024-10-22 12:00:10.175357275+00:00,10,39,38,A,A,0,236.8,2000,130,204243,36788,232.4,236.8,2000,2000,1,1,,237.0,0,2000,0,1,,,0,0,0,0,,,0,0,0,0,,,0,0,0,0,,,0,0,0,0,,,0,0,0,0,,,0,0,0,0,,,0,0,0,0,,,0,0,0,0,AAPL
2024-10-22 12:00:10.175660601+00:00,10,39,38,C,A,1,237.0,2000,130,204036,36789,232.4,236.8,2000,2000,1,1,,,0,0,0,0,,,0,0,0,0,,,0,0,0,0,,,0,0,0,0,,,0,0,0,0,,,0,0,0,0,,,0,0,0,0,,,0,0,0,0,,,0,0,0,0,AAPL
2024-10-22 12:00:10.276442473+00:00,10,40,38,A,B,0,235.35,200,194,203269,56001,,235.35,0,200,0,0,,,0,0,0,0,,,0,0,0,0,,,0,0,0,0,,,0,0,0,0,,,0,0,0,0,,,0,0,0,0,,,0,0,0,0,,,0,0,0,0,,,0,0,0,0,AAPL
2024-10-22 12:00:10.276811331+00:00,10,41,38,A,B,0,235.28,200,194,56216,57974,,235.28,0,200,0,0,,,0,0,0,0,,,0,0,0,0,,,0,0,0,0,,,0,0,0,0,,,0,0,0,0,,,0,0,0,0,,,0,0,0,0,,,0,0,0,0,,,0,0,0,0,AAPL
2024-10-22 12:00:11.677827527+00:00,10,40,38,A,A,0,,0,194,203228,56032,,,0,0,0,0,,,0,0,0,0,,,0,0,0,0,,,0,0,0,0,,,0,0,0,0,,,0,0,0,0,,,0,0,0,0,,,0,0,0,0,,,0,0,0,0,,,0,0,0,0,AAPL
2024-10-22 12:00:11.677851545+00:00,10,40,38,A,A,0,235.28,200,194,203180,56033,,235.28,0,200,0,0,,,0,0,0,0,,,0,0,0,0,,,0,0,0,0,,,0,0,0,0,,,0,0,0,0,,,0,0,0,0,,,0,0,0,0,,,0,0,0,0,,,0,0,0,0,AAPL
2024-10-22 12:00:11.877342455+00:00,10,40,38,A,A,0,,0,194,203176,56040,,,0,0,0,0,,,0,0,0,0,,,0,0,0,0,,,0,0,0,0,,,0,0,0,0,,,0,0,0,0,,,0,0,0,0,,,0,0,0,0,,,0,0,0,0,,,0,0,0,0,AAPL
2024-10-22 12:00:12.246091552+00:00,10,40,38,A,A,0,235.28,200,194,203147,56056,,235.28,0,200,0,0,,,0,0,0,0,,,0,0,0,0,,,0,0,0,0,,,0,0,0,0,,,0,0,0,0,,,0,0,0,0,,,0,0,0,0,,,0,0,0,0,,,0,0,0,0,AAPL
2024-10-22 12:00:12.298908199+00:00,10,40,38,A,A,0,,0,194,203128,56059,,,0,0,0,0,,,0,0,0,0,,,0,0,0,0,,,0,0,0,0,,,0,0,0,0,,,0,0,0,0,,,0,0,0,0,,,0,0,0,0,,,0,0,0,0,,,0,0,0,0,AAPL
2024-10-22 12:00:12.513996199+00:00,10,40,38,A,B,0,,0,194,203343,56068,234.27,,200,0,0,0,,,0,0,0,0,,,0,0,0,0,,,0,0,0,0,,,0,0,0,0,,,0,0,0,0,,,0,0,0,0,,,0,0,0,0,,,0,0,0,0,,,0,0,0,0,AAPL
2024-10-22 12:00:12.514002703+00:00,10,40,38,A,A,0,235.28,200,194,203195,56069,234.27,235.28,200,200,0,0,,,0,0,0,0,,,0,0,0,0,,,0,0,0,0,,,0,0,0,0,,,0,0,0,0,,,0,0,0,0,,,0,0,0,0,,,0,0,0,0,,,0,0,0,0,AAPL
2024-10-22 12:00:12.514337546+00:00,10,41,38,A,B,0,235.28,200,194,56492,58154,234.34,235.28,200,200,0,0,,,0,0,0,0,,,0,0,0,0,,,0,0,0,0,,,0,0,0,0,,,0,0,0,0,,,0,0,0,0,,,0,0,0,0,,,0,0,0,0,,,0,0,0,0,AAPL
2024-10-22 12:00:12.671069080+00:00,10,40,38,A,B,0,235.28,200,194,203161,56073,,235.28,0,200,0,0,,,0,0,0,0,,,0,0,0,0,,,0,0,0,0,,,0,0,0,0,,,0,0,0,0,,,0,0,0,0,,,0,0,0,0,,,0,0,0,0,,,0,0,0,0,AAPL
2024-10-22 12:00:12.671225374+00:00,10,40,38,A,A,0,,0,194,203146,56074,,,0,0,0,0,,,0,0,0,0,,,0,0,0,0,,,0,0,0,0,,,0,0,0,0,,,0,0,0,0,,,0,0,0,0,,,0,0,0,0,,,0,0,0,0,,,0,0,0,0,AAPL
2024-10-22 12:00:13.369715298+00:00,10,41,38,A,B,0,235.28,200,194,54990,58229,,235.28,0,200,0,0,,,0,0,0,0,,,0,0,0,0,,,0,0,0,0,,,0,0,0,0,,,0,0,0,0,,,0,0,0,0,,,0,0,0,0,,,0,0,0,0,,,0,0,0,0,AAPL
2024-10-22 12:00:13.370197955+00:00,10,40,38,A,A,0,235.28,200,194,203141,56090,,235.28,0,200,0,0,,,0,0,0,0,,,0,0,0,0,,,0,0,0,0,,,0,0,0,0,,,0,0,0,0,,,0,0,0,0,,,0,0,0,0,,,0,0,0,0,,,0,0,0,0,AAPL
2024-10-22 12:00:13.370319092+00:00,10,40,38,A,B,0,235.28,200,194,203214,56091,234.27,235.28,200,200,0,0,,,0,0,0,0,,,0,0,0,0,,,0,0,0,0,,,0,0,0,0,,,0,0,0,0,,,0,0,0,0,,,0,0,0,0,,,0,0,0,0,,,0,0,0,0,AAPL
2024-10-22 12:00:13.571045246+00:00,10,40,38,A,B,0,235.28,200,194,203201,56108,,235.28,0,200,0,0,,,0,0,0,0,,,0,0,0,0,,,0,0,0,0,,,0,0,0,0,,,0,0,0,0,,,0,0,0,0,,,0,0,0,0,,,0,0,0,0,,,0,0,0,0,AAPL
2024-10-22 12:00:13.571155667+00:00,10,40,38,A,A,0,,0,194,203192,56109,,,0,0,0,0,,,0,0,0,0,,,0,0,0,0,,,0,0,0,0,,,0,0,0,0,,,0,0,0,0,,,0,0,0,0,,,0,0,0,0,,,0,0,0,0,,,0,0,0,0,AAPL
2024-10-22 12:00:13.741155365+00:00,10,40,38,A,A,0,235.28,200,194,203211,56113,,235.28,0,200,0,0,,,0,0,0,0,,,0,0,0,0,,,0,0,0,0,,,0,0,0,0,,,0,0,0,0,,,0,0,0,0,,,0,0,0,0,,,0,0,0,0,,,0,0,0,0,AAPL
2024-10-22 12:00:13.771023580+00:00,10,40,38,A,A,0,,0,194,203186,56117,,,0,0,0,0,,,0,0,0,0,,,0,0,0,0,,,0,0,0,0,,,0,0,0,0,,,0,0,0,0,,,0,0,0,0,,,0,0,0,0,,,0,0,0,0,,,0,0,0,0,AAPL
2024-10-22 12:00:15.873513850+00:00,10,40,38,A,A,0,235.28,200,194,203252,56188,,235.28,0,200,0,0,,,0,0,0,0,,,0,0,0,0,,,0,0,0,0,,,0,0,0,0,,,0,0,0,0,,,0,0,0,0,,,0,0,0,0,,,0,0,0,0,,,0,0,0,0,AAPL
2024-10-22 12:00:15.974703776+00:00,10,40,38,A,A,0,,0,194,203235,56194,,,0,0,0,0,,,0,0,0,0,,,0,0,0,0,,,0,0,0,0,,,0,0,0,0,,,0,0,0,0,,,0,0,0,0,,,0,0,0,0,,,0,0,0,0,,,0,0,0,0,AAPL
2024-10-22 12:00:16.076362328+00:00,10,40,38,A,A,0,235.28,200,194,203289,56202,,235.28,0,200,0,0,,,0,0,0,0,,,0,0,0,0,,,0,0,0,0,,,0,0,0,0,,,0,0,0,0,,,0,0,0,0,,,0,0,0,0,,,0,0,0,0,,,0,0,0,0,AAPL
2024-10-22 12:00:18.487293552+00:00,10,40,38,A,B,0,235.28,200,194,203388,56282,234.27,235.28,200,200,0,0,,,0,0,0,0,,,0,0,0,0,,,0,0,0,0,,,0,0,0,0,,,0,0,0,0,,,0,0,0,0,,,0,0,0,0,,,0,0,0,0,,,0,0,0,0,AAPL
2024-10-22 12:00:18.488156039+00:00,10,41,38,A,B,0,235.28,200,194,56600,58575,234.34,235.28,200,200,0,0,,,0,0,0,0,,,0,0,0,0,,,0,0,0,0,,,0,0,0,0,,,0,0,0,0,,,0,0,0,0,,,0,0,0,0,,,0,0,0,0,,,0,0,0,0,AAPL
2024-10-22 12:00:18.741180379+00:00,10,40,38,A,B,0,235.28,200,194,203248,56290,,235.28,0,200,0,0,,,0,0,0,0,,,0,0,0,0,,,0,0,0,0,,,0,0,0,0,,,0,0,0,0,,,0,0,0,0,,,0,0,0,0,,,0,0,0,0,,,0,0,0,0,AAPL
2024-10-22 12:00:18.741540447+00:00,10,41,38,A,B,0,235.28,200,194,56769,58594,,235.28,0,200,0,0,,,0,0,0,0,,,0,0,0,0,,,0,0,0,0,,,0,0,0,0,,,0,0,0,0,,,0,0,0,0,,,0,0,0,0,,,0,0,0,0,,,0,0,0,0,AAPL
2024-10-22 12:00:19.192003885+00:00,10,40,38,A,B,0,235.28,200,194,203297,56303,234.27,235.28,200,200,0,0,,,0,0,0,0,,,0,0,0,0,,,0,0,0,0,,,0,0,0,0,,,0,0,0,0,,,0,0,0,0,,,0,0,0,0,,,0,0,0,0,,,0,0,0,0,AAPL
2024-10-22 12:00:19.192740350+00:00,10,41,38,A,B,0,235.28,200,194,65586,58634,234.34,235.28,200,200,0,0,,,0,0,0,0,,,0,0,0,0,,,0,0,0,0,,,0,0,0,0,,,0,0,0,0,,,0,0,0,0,,,0,0,0,0,,,0,0,0,0,,,0,0,0,0,AAPL
2024-10-22 12:00:19.401516714+00:00,10,40,38,A,B,0,235.28,200,194,203305,56309,,235.28,0,200,0,0,,,0,0,0,0,,,0,0,0,0,,,0,0,0,0,,,0,0,0,0,,,0,0,0,0,,,0,0,0,0,,,0,0,0,0,,,0,0,0,0,,,0,0,0,0,AAPL
2024-10-22 12:00:19.401820971+00:00,10,41,38,A,B,0,235.28,200,194,55906,58641,,235.28,0,200,0,0,,,0,0,0,0,,,0,0,0,0,,,0,0,0,0,,,0,0,0,0,,,0,0,0,0,,,0,0,0,0,,,0,0,0,0,,,0,0,0,0,,,0,0,0,0,AAPL
2024-10-22 12:00:19.594580306+00:00,10,40,38,A,B,0,235.28,200,194,203227,56321,234.27,235.28,200,200,0,0,,,0,0,0,0,,,0,0,0,0,,,0,0,0,0,,,0,0,0,0,,,0,0,0,0,,,0,0,0,0,,,0,0,0,0,,,0,0,0,0,,,0,0,0,0,AAPL
2024-10-22 12:00:19.595101113+00:00,10,41,38,A,B,0,235.28,200,194,56179,58658,234.34,235.28,200,200,0,0,,,0,0,0,0,,,0,0,0,0,,,0,0,0,0,,,0,0,0,0,,,0,0,0,0,,,0,0,0,0,,,0,0,0,0,,,0,0,0,0,,,0,0,0,0,AAPL
2024-10-22 12:00:19.601210236+00:00,10,40,38,A,B,0,235.28,200,194,203240,56322,,235.28,0,200,0,0,,,0,0,0,0,,,0,0,0,0,,,0,0,0,0,,,0,0,0,0,,,0,0,0,0,,,0,0,0,0,,,0,0,0,0,,,0,0,0,0,,,0,0,0,0,AAPL
2024-10-22 12:00:19.601501191+00:00,10,41,38,A,B,0,235.28,200,194,56244,58659,,235.28,0,200,0,0,,,0,0,0,0,,,0,0,0,0,,,0,0,0,0,,,0,0,0,0,,,0,0,0,0,,,0,0,0,0,,,0,0,0,0,,,0,0,0,0,,,0,0,0,0,AAPL
2024-10-22 12:00:19.777633460+00:00,10,40,38,A,B,0,235.28,200,194,203272,56328,234.27,235.28,200,200,0,0,,,0,0,0,0,,,0,0,0,0,,,0,0,0,0,,,0,0,0,0,,,0,0,0,0,,,0,0,0,0,,,0,0,0,0,,,0,0,0,0,,,0,0,0,0,AAPL
2024-10-22 12:00:19.778012973+00:00,10,41,38,A,B,0,235.28,200,194,56612,58678,234.34,235.28,200,200,0,0,,,0,0,0,0,,,0,0,0,0,,,0,0,0,0,,,0,0,0,0,,,0,0,0,0,,,0,0,0,0,,,0,0,0,0,,,0,0,0,0,,,0,0,0,0,AAPL
2024-10-22 12:00:19.911224287+00:00,10,40,38,A,B,0,235.28,200,194,203377,56329,,235.28,0,200,0,0,,,0,0,0,0,,,0,0,0,0,,,0,0,0,0,,,0,0,0,0,,,0,0,0,0,,,0,0,0,0,,,0,0,0,0,,,0,0,0,0,,,0,0,0,0,AAPL
2024-10-22 12:00:19.976971331+00:00,10,41,38,A,B,0,235.28,200,194,56157,58683,,235.28,0,200,0,0,,,0,0,0,0,,,0,0,0,0,,,0,0,0,0,,,0,0,0,0,,,0,0,0,0,,,0,0,0,0,,,0,0,0,0,,,0,0,0,0,,,0,0,0,0,AAPL
2024-10-22 12:00:21.661802534+00:00,10,40,38,A,A,0,,0,194,203434,56375,,,0,0,0,0,,,0,0,0,0,,,0,0,0,0,,,0,0,0,0,,,0,0,0,0,,,0,0,0,0,,,0,0,0,0,,,0,0,0,0,,,0,0,0,0,,,0,0,0,0,AAPL
2024-10-22 12:00:21.661896055+00:00,10,39,38,C,A,0,236.8,2000,130,204454,36859,232.4,,2000,0,1,0,,,0,0,0,0,,,0,0,0,0,,,0,0,0,0,,,0,0,0,0,,,0,0,0,0,,,0,0,0,0,,,0,0,0,0,,,0,0,0,0,,,0,0,0,0,AAPL
2024-10-22 12:00:21.672754058+00:00,10,39,38,A,A,0,237.0,2000,130,204330,36860,232.4,237.0,2000,2000,1,1,,,0,0,0,0,,,0,0,0,0,,,0,0,0,0,,,0,0,0,0,,,0,0,0,0,,,0,0,0,0,,,0,0,0,0,,,0,0,0,0,,,0,0,0,0,AAPL
2024-10-22 12:00:21.701547880+00:00,10,41,38,A,A,0,,0,194,55733,58805,,,0,0,0,0,,,0,0,0,0,,,0,0,0,0,,,0,0,0,0,,,0,0,0,0,,,0,0,0,0,,,0,0,0,0,,,0,0,0,0,,,0,0,0,0,,,0,0,0,0,AAPL
2024-10-22 12:00:21.825172746+00:00,10,41,38,A,A,0,235.21,200,194,55665,58813,,235.21,0,200,0,0,,,0,0,0,0,,,0,0,0,0,,,0,0,0,0,,,0,0,0,0,,,0,0,0,0,,,0,0,0,0,,,0,0,0,0,,,0,0,0,0,,,0,0,0,0,AAPL
2024-10-22 12:00:21.865593901+00:00,10,40,38,A,A,0,235.28,200,194,203497,56379,,235.28,0,200,0,0,,,0,0,0,0,,,0,0,0,0,,,0,0,0,0,,,0,0,0,0,,,0,0,0,0,,,0,0,0,0,,,0,0,0,0,,,0,0,0,0,,,0,0,0,0,AAPL
2024-10-22 12:00:21.964796882+00:00,10,40,38,A,A,0,,0,194,203391,56382,,,0,0,0,0,,,0,0,0,0,,,0,0,0,0,,,0,0,0,0,,,0,0,0,0,,,0,0,0,0,,,0,0,0,0,,,0,0,0,0,,,0,0,0,0,,,0,0,0,0,AAPL
2024-10-22 12:00:22.251381671+00:00,10,41,38,A,A,0,,0,194,55217,58846,,,0,0,0,0,,,0,0,0,0,,,0,0,0,0,,,0,0,0,0,,,0,0,0,0,,,0,0,0,0,,,0,0,0,0,,,0,0,0,0,,,0,0,0,0,,,0,0,0,0,AAPL
2024-10-22 12:00:22.457933076+00:00,10,41,38,A,A,0,235.21,200,194,56028,58857,,235.21,0,200,0,0,,,0,0,0,0,,,0,0,0,0,,,0,0,0,0,,,0,0,0,0,,,0,0,0,0,,,0,0,0,0,,,0,0,0,0,,,0,0,0,0,,,0,0,0,0,AAPL
2024-10-22 12:00:22.551670763+00:00,10,41,38,A,A,0,,0,194,55399,58866,,,0,0,0,0,,,0,0,0,0,,,0,0,0,0,,,0,0,0,0,,,0,0,0,0,,,0,0,0,0,,,0,0,0,0,,,0,0,0,0,,,0,0,0,0,,,0,0,0,0,AAPL
2024-10-22 12:00:22.659199033+00:00,10,41,38,A,A,0,235.21,200,194,55692,58873,,235.21,0,200,0,0,,,0,0,0,0,,,0,0,0,0,,,0,0,0,0,,,0,0,0,0,,,0,0,0,0,,,0,0,0,0,,,0,0,0,0,,,0,0,0,0,,,0,0,0,0,AAPL
2024-10-22 12:00:24.209368241+00:00,10,39,38,C,B,0,232.4,2000,130,204619,36873,,237.0,0,2000,0,1,,,0,0,0,0,,,0,0,0,0,,,0,0,0,0,,,0,0,0,0,,,0,0,0,0,,,0,0,0,0,,,0,0,0,0,,,0,0,0,0,,,0,0,0,0,AAPL
2024-10-22 12:00:24.361500195+00:00,10,41,38,A,A,0,,0,194,56109,58937,,,0,0,0,0,,,0,0,0,0,,,0,0,0,0,,,0,0,0,0,,,0,0,0,0,,,0,0,0,0,,,0,0,0,0,,,0,0,0,0,,,0,0,0,0,,,0,0,0,0,AAPL
2024-10-22 12:00:24.542279697+00:00,10,41,38,A,A,0,235.21,200,194,55603,58945,,235.21,0,200,0,0,,,0,0,0,0,,,0,0,0,0,,,0,0,0,0,,,0,0,0,0,,,0,0,0,0,,,0,0,0,0,,,0,0,0,0,,,0,0,0,0,,,0,0,0,0,AAPL
2024-10-22 12:00:25.421761704+00:00,10,41,38,A,A,0,,0,194,56494,59411,,,0,0,0,0,,,0,0,0,0,,,0,0,0,0,,,0,0,0,0,,,0,0,0,0,,,0,0,0,0,,,0,0,0,0,,,0,0,0,0,,,0,0,0,0,,,0,0,0,0,AAPL
2024-10-22 12:00:25.551308793+00:00,10,41,38,A,A,0,235.21,200,194,57294,59516,,235.21,0,200,0,0,,,0,0,0,0,,,0,0,0,0,,,0,0,0,0,,,0,0,0,0,,,0,0,0,0,,,0,0,0,0,,,0,0,0,0,,,0,0,0,0,,,0,0,0,0,AAPL
2024-10-22 12:00:25.731438858+00:00,10,41,38,A,A,0,,0,194,55842,59554,,,0,0,0,0,,,0,0,0,0,,,0,0,0,0,,,0,0,0,0,,,0,0,0,0,,,0,0,0,0,,,0,0,0,0,,,0,0,0,0,,,0,0,0,0,,,0,0,0,0,AAPL
2024-10-22 12:00:26.001324119+00:00,10,41,38,A,A,0,235.21,200,194,55640,59586,,235.21,0,200,0,0,,,0,0,0,0,,,0,0,0,0,,,0,0,0,0,,,0,0,0,0,,,0,0,0,0,,,0,0,0,0,,,0,0,0,0,,,0,0,0,0,,,0,0,0,0,AAPL
2024-10-22 12:00:26.140722855+00:00,10,40,38,A,A,0,235.28,200,194,203270,56479,,235.28,0,200,0,0,,,0,0,0,0,,,0,0,0,0,,,0,0,0,0,,,0,0,0,0,,,0,0,0,0,,,0,0,0,0,,,0,0,0,0,,,0,0,0,0,,,0,0,0,0,AAPL
2024-10-22 12:00:26.640954119+00:00,10,40,38,A,A,0,,0,194,203602,56495,,,0,0,0,0,,,0,0,0,0,,,0,0,0,0,,,0,0,0,0,,,0,0,0,0,,,0,0,0,0,,,0,0,0,0,,,0,0,0,0,,,0,0,0,0,,,0,0,0,0,AAPL
2024-10-22 12:00:26.846153424+00:00,10,40,38,A,B,0,,0,194,203377,56499,234.31,,200,0,0,0,,,0,0,0,0,,,0,0,0,0,,,0,0,0,0,,,0,0,0,0,,,0,0,0,0,,,0,0,0,0,,,0,0,0,0,,,0,0,0,0,,,0,0,0,0,AAPL
2024-10-22 12:00:26.846161889+00:00,10,40,38,A,A,0,235.28,200,194,203174,56500,234.31,235.28,200,200,0,0,,,0,0,0,0,,,0,0,0,0,,,0,0,0,0,,,0,0,0,0,,,0,0,0,0,,,0,0,0,0,,,0,0,0,0,,,0,0,0,0,,,0,0,0,0,AAPL
2024-10-22 12:00:26.846869376+00:00,10,41,38,A,B,0,235.21,200,194,59133,59685,234.38,235.21,200,200,0,0,,,0,0,0,0,,,0,0,0,0,,,0,0,0,0,,,0,0,0,0,,,0,0,0,0,,,0,0,0,0,,,0,0,0,0,,,0,0,0,0,,,0,0,0,0,AAPL
2024-10-22 12:00:27.095654406+00:00,10,40,38,A,A,0,,0,194,203578,56505,234.31,,200,0,0,0,,,0,0,0,0,,,0,0,0,0,,,0,0,0,0,,,0,0,0,0,,,0,0,0,0,,,0,0,0,0,,,0,0,0,0,,,0,0,0,0,,,0,0,0,0,AAPL
2024-10-22 12:00:27.095807920+00:00,10,40,38,A,B,0,,0,194,203260,56506,,,0,0,0,0,,,0,0,0,0,,,0,0,0,0,,,0,0,0,0,,,0,0,0,0,,,0,0,0,0,,,0,0,0,0,,,0,0,0,0,,,0,0,0,0,,,0,0,0,0,AAPL
2024-10-22 12:00:27.241568676+00:00,10,40,38,A,A,0,235.28,200,194,203253,56513,,235.28,0,200,0,0,,,0,0,0,0,,,0,0,0,0,,,0,0,0,0,,,0,0,0,0,,,0,0,0,0,,,0,0,0,0,,,0,0,0,0,,,0,0,0,0,,,0,0,0,0,AAPL
2024-10-22 12:00:27.241668568+00:00,10,40,38,A,B,0,235.28,200,194,203196,56514,234.31,235.28,200,200,0,0,,,0,0,0,0,,,0,0,0,0,,,0,0,0,0,,,0,0,0,0,,,0,0,0,0,,,0,0,0,0,,,0,0,0,0,,,0,0,0,0,,,0,0,0,0,AAPL
2024-10-22 12:00:27.421507971+00:00,10,40,38,A,N,0,,0,194,203370,56524,,,0,0,0,0,,,0,0,0,0,,,0,0,0,0,,,0,0,0,0,,,0,0,0,0,,,0,0,0,0,,,0,0,0,0,,,0,0,0,0,,,0,0,0,0,,,0,0,0,0,AAPL
2024-10-22 12:00:27.421786901+00:00,10,41,38,A,B,0,235.21,200,194,65345,59757,,235.21,0,200,0,0,,,0,0,0,0,,,0,0,0,0,,,0,0,0,0,,,0,0,0,0,,,0,0,0,0,,,0,0,0,0,,,0,0,0,0,,,0,0,0,0,,,0,0,0,0,AAPL
2024-10-22 12:00:27.421798107+00:00,10,41,38,A,A,0,,0,194,56500,59758,,,0,0,0,0,,,0,0,0,0,,,0,0,0,0,,,0,0,0,0,,,0,0,0,0,,,0,0,0,0,,,0,0,0,0,,,0,0,0,0,,,0,0,0,0,,,0,0,0,0,AAPL
2024-10-22 12:00:27.480319893+00:00,10,40,38,A,A,0,235.28,200,194,203413,56525,,235.28,0,200,0,0,,,0,0,0,0,,,0,0,0,0,,,0,0,0,0,,,0,0,0,0,,,0,0,0,0,,,0,0,0,0,,,0,0,0,0,,,0,0,0,0,,,0,0,0,0,AAPL
2024-10-22 12:00:27.480437420+00:00,10,40,38,A,B,0,235.28,200,194,203154,56526,234.31,235.28,200,200,0,0,,,0,0,0,0,,,0,0,0,0,,,0,0,0,0,,,0,0,0,0,,,0,0,0,0,,,0,0,0,0,,,0,0,0,0,,,0,0,0,0,,,0,0,0,0,AAPL
2024-10-22 12:00:27.481056078+00:00,10,41,38,A,B,0,,0,194,55384,59761,234.38,,200,0,0,0,,,0,0,0,0,,,0,0,0,0,,,0,0,0,0,,,0,0,0,0,,,0,0,0,0,,,0,0,0,0,,,0,0,0,0,,,0,0,0,0,,,0,0,0,0,AAPL
2024-10-22 12:00:27.481813652+00:00,10,41,38,A,A,0,235.21,200,194,55246,59762,234.38,235.21,200,200,0,0,,,0,0,0,0,,,0,0,0,0,,,0,0,0,0,,,0,0,0,0,,,0,0,0,0,,,0,0,0,0,,,0,0,0,0,,,0,0,0,0,,,0,0,0,0,AAPL
2024-10-22 12:00:27.530973984+00:00,10,40,38,A,B,0,235.28,200,194,203299,56528,,235.28,0,200,0,0,,,0,0,0,0,,,0,0,0,0,,,0,0,0,0,,,0,0,0,0,,,0,0,0,0,,,0,0,0,0,,,0,0,0,0,,,0,0,0,0,,,0,0,0,0,AAPL
2024-10-22 12:00:27.530983070+00:00,10,40,38,A,A,0,,0,194,203237,56529,,,0,0,0,0,,,0,0,0,0,,,0,0,0,0,,,0,0,0,0,,,0,0,0,0,,,0,0,0,0,,,0,0,0,0,,,0,0,0,0,,,0,0,0,0,,,0,0,0,0,AAPL
2024-10-22 12:00:27.531266621+00:00,10,41,38,A,A,0,,0,194,55756,59764,234.38,,200,0,0,0,,,0,0,0,0,,,0,0,0,0,,,0,0,0,0,,,0,0,0,0,,,0,0,0,0,,,0,0,0,0,,,0,0,0,0,,,0,0,0,0,,,0,0,0,0,AAPL
2024-10-22 12:00:27.531267547+00:00,10,41,38,A,B,0,,0,194,54624,59765,,,0,0,0,0,,,0,0,0,0,,,0,0,0,0,,,0,0,0,0,,,0,0,0,0,,,0,0,0,0,,,0,0,0,0,,,0,0,0,0,,,0,0,0,0,,,0,0,0,0,AAPL
2024-10-22 12:00:27.716379812+00:00,10,40,38,A,A,0,235.28,200,194,203282,56535,,235.28,0,200,0,0,,,0,0,0,0,,,0,0,0,0,,,0,0,0,0,,,0,0,0,0,,,0,0,0,0,,,0,0,0,0,,,0,0,0,0,,,0,0,0,0,,,0,0,0,0,AAPL
2024-10-22 12:00:27.716501954+00:00,10,40,38,A,B,0,235.28,200,194,203171,56536,234.31,235.28,200,200,0,0,,,0,0,0,0,,,0,0,0,0,,,0,0,0,0,,,0,0,0,0,,,0,0,0,0,,,0,0,0,0,,,0,0,0,0,,,0,0,0,0,,,0,0,0,0,AAPL
2024-10-22 12:00:27.717073863+00:00,10,41,38,A,B,0,,0,194,62174,59770,234.38,,200,0,0,0,,,0,0,0,0,,,0,0,0,0,,,0,0,0,0,,,0,0,0,0,,,0,0,0,0,,,0,0,0,0,,,0,0,0,0,,,0,0,0,0,,,0,0,0,0,AAPL
2024-10-22 12:00:27.717813603+00:00,10,41,38,A,A,0,235.21,200,194,56229,59771,234.38,235.21,200,200,0,0,,,0,0,0,0,,,0,0,0,0,,,0,0,0,0,,,0,0,0,0,,,0,0,0,0,,,0,0,0,0,,,0,0,0,0,,,0,0,0,0,,,0,0,0,0,AAPL
2024-10-22 12:00:27.841167130+00:00,10,40,38,A,B,0,235.28,200,194,203197,56538,,235.28,0,200,0,0,,,0,0,0,0,,,0,0,0,0,,,0,0,0,0,,,0,0,0,0,,,0,0,0,0,,,0,0,0,0,,,0,0,0,0,,,0,0,0,0,,,0,0,0,0,AAPL
2024-10-22 12:00:27.841174585+00:00,10,40,38,A,A,0,,0,194,203170,56539,,,0,0,0,0,,,0,0,0,0,,,0,0,0,0,,,0,0,0,0,,,0,0,0,0,,,0,0,0,0,,,0,0,0,0,,,0,0,0,0,,,0,0,0,0,,,0,0,0,0,AAPL
2024-10-22 12:00:27.841457252+00:00,10,41,38,A,B,0,235.21,200,194,55987,59775,,235.21,0,200,0,0,,,0,0,0,0,,,0,0,0,0,,,0,0,0,0,,,0,0,0,0,,,0,0,0,0,,,0,0,0,0,,,0,0,0,0,,,0,0,0,0,,,0,0,0,0,AAPL
2024-10-22 12:00:27.841468976+00:00,10,41,38,A,A,0,,0,194,63300,59776,,,0,0,0,0,,,0,0,0,0,,,0,0,0,0,,,0,0,0,0,,,0,0,0,0,,,0,0,0,0,,,0,0,0,0,,,0,0,0,0,,,0,0,0,0,,,0,0,0,0,AAPL
2024-10-22 12:00:27.876959202+00:00,10,40,38,A,A,0,235.28,200,194,203190,56540,,235.28,0,200,0,0,,,0,0,0,0,,,0,0,0,0,,,0,0,0,0,,,0,0,0,0,,,0,0,0,0,,,0,0,0,0,,,0,0,0,0,,,0,0,0,0,,,0,0,0,0,AAPL
2024-10-22 12:00:27.877073320+00:00,10,40,38,A,B,0,235.28,200,194,203161,56541,234.31,235.28,200,200,0,0,,,0,0,0,0,,,0,0,0,0,,,0,0,0,0,,,0,0,0,0,,,0,0,0,0,,,0,0,0,0,,,0,0,0,0,,,0,0,0,0,,,0,0,0,0,AAPL
2024-10-22 12:00:27.877423910+00:00,10,41,38,A,B,0,,0,194,55942,59777,234.38,,200,0,0,0,,,0,0,0,0,,,0,0,0,0,,,0,0,0,0,,,0,0,0,0,,,0,0,0,0,,,0,0,0,0,,,0,0,0,0,,,0,0,0,0,,,0,0,0,0,AAPL
2024-10-22 12:00:27.878277848+00:00,10,41,38,A,A,0,235.21,200,194,54458,59778,234.38,235.21,200,200,0,0,,,0,0,0,0,,,0,0,0,0,,,0,0,0,0,,,0,0,0,0,,,0,0,0,0,,,0,0,0,0,,,0,0,0,0,,,0,0,0,0,,,0,0,0,0,AAPL
2024-10-22 12:00:27.971333314+00:00,10,40,38,A,B,0,235.28,200,194,203168,56544,,235.28,0,200,0,0,,,0,0,0,0,,,0,0,0,0,,,0,0,0,0,,,0,0,0,0,,,0,0,0,0,,,0,0,0,0,,,0,0,0,0,,,0,0,0,0,,,0,0,0,0,AAPL
2024-10-22 12:00:27.971342611+00:00,10,40,38,A,A,0,,0,194,203161,56545,,,0,0,0,0,,,0,0,0,0,,,0,0,0,0,,,0,0,0,0,,,0,0,0,0,,,0,0,0,0,,,0,0,0,0,,,0,0,0,0,,,0,0,0,0,,,0,0,0,0,AAPL
2024-10-22 12:00:27.971605831+00:00,10,41,38,A,B,0,235.21,200,194,55838,59792,,235.21,0,200,0,0,,,0,0,0,0,,,0,0,0,0,,,0,0,0,0,,,0,0,0,0,,,0,0,0,0,,,0,0,0,0,,,0,0,0,0,,,0,0,0,0,,,0,0,0,0,AAPL
2024-10-22 12:00:27.971618259+00:00,10,41,38,A,A,0,,0,194,54681,59793,,,0,0,0,0,,,0,0,0,0,,,0,0,0,0,,,0,0,0,0,,,0,0,0,0,,,0,0,0,0,,,0,0,0,0,,,0,0,0,0,,,0,0,0,0,,,0,0,0,0,AAPL
2024-10-22 12:00:28.218323235+00:00,10,40,38,A,A,0,235.28,200,194,203203,56553,,235.28,0,200,0,0,,,0,0,0,0,,,0,0,0,0,,,0,0,0,0,,,0,0,0,0,,,0,0,0,0,,,0,0,0,0,,,0,0,0,0,,,0,0,0,0,,,0,0,0,0,AAPL
2024-10-22 12:00:28.218414503+00:00,10,40,38,A,B,0,235.28,200,194,203190,56554,234.31,235.28,200,200,0,0,,,0,0,0,0,,,0,0,0,0,,,0,0,0,0,,,0,0,0,0,,,0,0,0,0,,,0,0,0,0,,,0,0,0,0,,,0,0,0,0,,,0,0,0,0,AAPL
2024-10-22 12:00:28.218962133+00:00,10,41,38,A,B,0,,0,194,55997,59807,234.38,,200,0,0,0,,,0,0,0,0,,,0,0,0,0,,,0,0,0,0,,,0,0,0,0,,,0,0,0,0,,,0,0,0,0,,,0,0,0,0,,,0,0,0,0,,,0,0,0,0,AAPL
2024-10-22 12:00:28.219694134+00:00,10,41,38,A,A,0,235.21,200,194,64818,59808,234.38,235.21,200,200,0,0,,,0,0,0,0,,,0,0,0,0,,,0,0,0,0,,,0,0,0,0,,,0,0,0,0,,,0,0,0,0,,,0,0,0,0,,,0,0,0,0,,,0,0,0,0,AAPL
2024-10-22 12:00:28.332616021+00:00,10,39,10888,A,A,0,418.43,100,130,204102,53567,,418.43,0,100,0,1,,,0,0,0,0,,,0,0,0,0,,,0,0,0,0,,,0,0,0,0,,,0,0,0,0,,,0,0,0,0,,,0,0,0,0,,,0,0,0,0,,,0,0,0,0,MSFT
2024-10-22 12:00:30.197129505+00:00,10,40,38,A,B,0,235.28,200,194,203208,56599,,235.28,0,200,0,0,,,0,0,0,0,,,0,0,0,0,,,0,0,0,0,,,0,0,0,0,,,0,0,0,0,,,0,0,0,0,,,0,0,0,0,,,0,0,0,0,,,0,0,0,0,AAPL
2024-10-22 12:00:30.197254237+00:00,10,40,38,A,A,0,,0,194,203465,56600,,,0,0,0,0,,,0,0,0,0,,,0,0,0,0,,,0,0,0,0,,,0,0,0,0,,,0,0,0,0,,,0,0,0,0,,,0,0,0,0,,,0,0,0,0,,,0,0,0,0,AAPL
2024-10-22 12:00:30.197623296+00:00,10,41,38,A,B,0,235.21,200,194,56283,59948,,235.21,0,200,0,0,,,0,0,0,0,,,0,0,0,0,,,0,0,0,0,,,0,0,0,0,,,0,0,0,0,,,0,0,0,0,,,0,0,0,0,,,0,0,0,0,,,0,0,0,0,AAPL
2024-10-22 12:00:30.495170305+00:00,10,40,38,A,A,0,235.28,200,194,203241,56610,,235.28,0,200,0,0,,,0,0,0,0,,,0,0,0,0,,,0,0,0,0,,,0,0,0,0,,,0,0,0,0,,,0,0,0,0,,,0,0,0,0,,,0,0,0,0,,,0,0,0,0,AAPL
2024-10-22 12:00:30.495479337+00:00,10,40,38,A,B,0,235.28,200,194,203255,56611,234.31,235.28,200,200,0,0,,,0,0,0,0,,,0,0,0,0,,,0,0,0,0,,,0,0,0,0,,,0,0,0,0,,,0,0,0,0,,,0,0,0,0,,,0,0,0,0,,,0,0,0,0,AAPL
2024-10-22 12:00:30.495486242+00:00,10,40,38,A,A,0,,0,194,203140,56612,234.31,,200,0,0,0,,,0,0,0,0,,,0,0,0,0,,,0,0,0,0,,,0,0,0,0,,,0,0,0,0,,,0,0,0,0,,,0,0,0,0,,,0,0,0,0,,,0,0,0,0,AAPL
2024-10-22 12:00:30.495589518+00:00,10,40,38,A,B,0,,0,194,203161,56614,,,0,0,0,0,,,0,0,0,0,,,0,0,0,0,,,0,0,0,0,,,0,0,0,0,,,0,0,0,0,,,0,0,0,0,,,0,0,0,0,,,0,0,0,0,,,0,0,0,0,AAPL
2024-10-22 12:00:30.696932935+00:00,10,40,38,A,A,0,235.28,200,194,203197,56622,,235.28,0,200,0,0,,,0,0,0,0,,,0,0,0,0,,,0,0,0,0,,,0,0,0,0,,,0,0,0,0,,,0,0,0,0,,,0,0,0,0,,,0,0,0,0,,,0,0,0,0,AAPL
2024-10-22 12:00:30.925908918+00:00,10,39,10888,C,A,0,418.43,100,130,203560,53616,,,0,0,0,0,,,0,0,0,0,,,0,0,0,0,,,0,0,0,0,,,0,0,0,0,,,0,0,0,0,,,0,0,0,0,,,0,0,0,0,,,0,0,0,0,,,0,0,0,0,MSFT
2024-10-22 12:00:31.311774521+00:00,10,40,38,A,A,0,,0,194,203214,56640,,,0,0,0,0,,,0,0,0,0,,,0,0,0,0,,,0,0,0,0,,,0,0,0,0,,,0,0,0,0,,,0,0,0,0,,,0,0,0,0,,,0,0,0,0,,,0,0,0,0,AAPL
2024-10-22 12:00:31.312051606+00:00,10,41,38,A,A,0,,0,194,55877,59999,,,0,0,0,0,,,0,0,0,0,,,0,0,0,0,,,0,0,0,0,,,0,0,0,0,,,0,0,0,0,,,0,0,0,0,,,0,0,0,0,,,0,0,0,0,,,0,0,0,0,AAPL
2024-10-22 12:00:31.644580464+00:00,10,40,38,A,A,0,235.28,200,194,203176,56653,,235.28,0,200,0,0,,,0,0,0,0,,,0,0,0,0,,,0,0,0,0,,,0,0,0,0,,,0,0,0,0,,,0,0,0,0,,,0,0,0,0,,,0,0,0,0,,,0,0,0,0,AAPL
2024-10-22 12:00:31.645093394+00:00,10,41,38,A,A,0,235.21,200,194,56144,60024,,235.21,0,200,0,0,,,0,0,0,0,,,0,0,0,0,,,0,0,0,0,,,0,0,0,0,,,0,0,0,0,,,0,0,0,0,,,0,0,0,0,,,0,0,0,0,,,0,0,0,0,AAPL
2024-10-22 12:00:33.919503551+00:00,10,40,38,A,A,0,,0,194,203209,56704,,,0,0,0,0,,,0,0,0,0,,,0,0,0,0,,,0,0,0,0,,,0,0,0,0,,,0,0,0,0,,,0,0,0,0,,,0,0,0,0,,,0,0,0,0,,,0,0,0,0,AAPL
2024-10-22 12:00:33.919792933+00:00,10,41,38,A,A,0,,0,194,61068,60184,,,0,0,0,0,,,0,0,0,0,,,0,0,0,0,,,0,0,0,0,,,0,0,0,0,,,0,0,0,0,,,0,0,0,0,,,0,0,0,0,,,0,0,0,0,,,0,0,0,0,AAPL
2024-10-22 12:00:34.359363567+00:00,10,40,38,A,A,0,235.28,200,194,203160,56712,,235.28,0,200,0,0,,,0,0,0,0,,,0,0,0,0,,,0,0,0,0,,,0,0,0,0,,,0,0,0,0,,,0,0,0,0,,,0,0,0,0,,,0,0,0,0,,,0,0,0,0,AAPL
2024-10-22 12:00:34.360046830+00:00,10,41,38,A,A,0,235.21,200,194,58100,60212,,235.21,0,200,0,0,,,0,0,0,0,,,0,0,0,0,,,0,0,0,0,,,0,0,0,0,,,0,0,0,0,,,0,0,0,0,,,0,0,0,0,,,0,0,0,0,,,0,0,0,0,AAPL
2024-10-22 12:00:40.684548541+00:00,10,40,38,A,A,0,,0,194,203558,56772,,,0,0,0,0,,,0,0,0,0,,,0,0,0,0,,,0,0,0,0,,,0,0,0,0,,,0,0,0,0,,,0,0,0,0,,,0,0,0,0,,,0,0,0,0,,,0,0,0,0,AAPL
2024-10-22 12:00:40.684836387+00:00,10,41,38,A,A,0,,0,194,61032,60416,,,0,0,0,0,,,0,0,0,0,,,0,0,0,0,,,0,0,0,0,,,0,0,0,0,,,0,0,0,0,,,0,0,0,0,,,0,0,0,0,,,0,0,0,0,,,0,0,0,0,AAPL
2024-10-22 12:00:40.686226776+00:00,10,40,38,A,B,0,,0,194,203361,56773,234.31,,200,0,0,0,,,0,0,0,0,,,0,0,0,0,,,0,0,0,0,,,0,0,0,0,,,0,0,0,0,,,0,0,0,0,,,0,0,0,0,,,0,0,0,0,,,0,0,0,0,AAPL
2024-10-22 12:00:40.686232868+00:00,10,40,38,A,A,0,235.28,200,194,203304,56774,234.31,235.28,200,200,0,0,,,0,0,0,0,,,0,0,0,0,,,0,0,0,0,,,0,0,0,0,,,0,0,0,0,,,0,0,0,0,,,0,0,0,0,,,0,0,0,0,,,0,0,0,0,AAPL
2024-10-22 12:00:40.686686991+00:00,10,41,38,A,B,0,,0,194,56530,60417,234.38,,200,0,0,0,,,0,0,0,0,,,0,0,0,0,,,0,0,0,0,,,0,0,0,0,,,0,0,0,0,,,0,0,0,0,,,0,0,0,0,,,0,0,0,0,,,0,0,0,0,AAPL
2024-10-22 12:00:40.686749708+00:00,10,41,38,A,A,0,235.21,200,194,54563,60418,234.38,235.21,200,200,0,0,,,0,0,0,0,,,0,0,0,0,,,0,0,0,0,,,0,0,0,0,,,0,0,0,0,,,0,0,0,0,,,0,0,0,0,,,0,0,0,0,,,0,0,0,0,AAPL
2024-10-22 12:00:42.003359367+00:00,10,40,38,A,B,0,235.28,200,194,203398,56792,,235.28,0,200,0,0,,,0,0,0,0,,,0,0,0,0,,,0,0,0,0,,,0,0,0,0,,,0,0,0,0,,,0,0,0,0,,,0,0,0,0,,,0,0,0,0,,,0,0,0,0,AAPL
2024-10-22 12:00:42.003948707+00:00,10,41,38,A,B,0,235.21,200,194,55582,60482,,235.21,0,200,0,0,,,0,0,0,0,,,0,0,0,0,,,0,0,0,0,,,0,0,0,0,,,0,0,0,0,,,0,0,0,0,,,0,0,0,0,,,0,0,0,0,,,0,0,0,0,AAPL
2024-10-22 12:00:42.581933876+00:00,10,40,38,A,B,0,235.28,200,194,203179,56800,234.31,235.28,200,200,0,0,,,0,0,0,0,,,0,0,0,0,,,0,0,0,0,,,0,0,0,0,,,0,0,0,0,,,0,0,0,0,,,0,0,0,0,,,0,0,0,0,,,0,0,0,0,AAPL
2024-10-22 12:00:42.582548467+00:00,10,41,38,A,B,0,235.21,200,194,56234,60513,234.38,235.21,200,200,0,0,,,0,0,0,0,,,0,0,0,0,,,0,0,0,0,,,0,0,0,0,,,0,0,0,0,,,0,0,0,0,,,0,0,0,0,,,0,0,0,0,,,0,0,0,0,AAPL
2024-10-22 12:00:42.747738410+00:00,10,41,38,A,B,0,235.21,200,194,55550,60517,,235.21,0,200,0,0,,,0,0,0,0,,,0,0,0,0,,,0,0,0,0,,,0,0,0,0,,,0,0,0,0,,,0,0,0,0,,,0,0,0,0,,,0,0,0,0,,,0,0,0,0,AAPL
2024-10-22 12:00:42.947282577+00:00,10,41,38,A,B,0,235.21,200,194,60490,60532,234.38,235.21,200,200,0,0,,,0,0,0,0,,,0,0,0,0,,,0,0,0,0,,,0,0,0,0,,,0,0,0,0,,,0,0,0,0,,,0,0,0,0,,,0,0,0,0,,,0,0,0,0,AAPL
2024-10-22 12:00:42.957422829+00:00,10,39,38,A,A,0,236.8,2000,130,203469,37021,,236.8,0,2000,0,1,,237.0,0,2000,0,1,,,0,0,0,0,,,0,0,0,0,,,0,0,0,0,,,0,0,0,0,,,0,0,0,0,,,0,0,0,0,,,0,0,0,0,,,0,0,0,0,AAPL
2024-10-22 12:00:42.957609970+00:00,10,39,38,C,A,1,237.0,2000,130,203352,37022,,236.8,0,2000,0,1,,,0,0,0,0,,,0,0,0,0,,,0,0,0,0,,,0,0,0,0,,,0,0,0,0,,,0,0,0,0,,,0,0,0,0,,,0,0,0,0,,,0,0,0,0,AAPL
2024-10-22 12:00:43.008084249+00:00,10,39,38,C,A,0,236.8,2000,130,203383,37029,,,0,0,0,0,,,0,0,0,0,,,0,0,0,0,,,0,0,0,0,,,0,0,0,0,,,0,0,0,0,,,0,0,0,0,,,0,0,0,0,,,0,0,0,0,,,0,0,0,0,AAPL
2024-10-22 12:00:43.019285307+00:00,10,39,38,A,A,0,236.8,2000,130,203338,37032,,236.8,0,2000,0,1,,,0,0,0,0,,,0,0,0,0,,,0,0,0,0,,,0,0,0,0,,,0,0,0,0,,,0,0,0,0,,,0,0,0,0,,,0,0,0,0,,,0,0,0,0,AAPL
2024-10-22 12:00:43.304277340+00:00,10,41,38,A,B,0,235.21,200,194,55643,60553,,235.21,0,200,0,0,,,0,0,0,0,,,0,0,0,0,,,0,0,0,0,,,0,0,0,0,,,0,0,0,0,,,0,0,0,0,,,0,0,0,0,,,0,0,0,0,,,0,0,0,0,AAPL
2024-10-22 12:00:43.314559136+00:00,10,39,38,A,B,0,232.6,2000,130,203404,37037,232.6,236.8,2000,2000,1,1,,,0,0,0,0,,,0,0,0,0,,,0,0,0,0,,,0,0,0,0,,,0,0,0,0,,,0,0,0,0,,,0,0,0,0,,,0,0,0,0,,,0,0,0,0,AAPL
2024-10-22 12:00:43.371263882+00:00,10,39,38,C,B,0,232.6,2000,130,203354,37038,,236.8,0,2000,0,1,,,0,0,0,0,,,0,0,0,0,,,0,0,0,0,,,0,0,0,0,,,0,0,0,0,,,0,0,0,0,,,0,0,0,0,,,0,0,0,0,,,0,0,0,0,AAPL
2024-10-22 12:00:43.384726956+00:00,10,39,38,A,B,0,232.4,2000,130,203372,37039,232.4,236.8,2000,2000,1,1,,,0,0,0,0,,,0,0,0,0,,,0,0,0,0,,,0,0,0,0,,,0,0,0,0,,,0,0,0,0,,,0,0,0,0,,,0,0,0,0,,,0,0,0,0,AAPL
2024-10-22 12:00:43.648843286+00:00,10,40,38,A,B,0,235.28,200,194,203373,56819,,235.28,0,200,0,0,,,0,0,0,0,,,0,0,0,0,,,0,0,0,0,,,0,0,0,0,,,0,0,0,0,,,0,0,0,0,,,0,0,0,0,,,0,0,0,0,,,0,0,0,0,AAPL
2024-10-22 12:00:47.876210419+00:00,10,39,38,C,A,0,236.8,2000,130,203242,37051,232.4,,2000,0,1,0,,,0,0,0,0,,,0,0,0,0,,,0,0,0,0,,,0,0,0,0,,,0,0,0,0,,,0,0,0,0,,,0,0,0,0,,,0,0,0,0,,,0,0,0,0,AAPL
2024-10-22 12:00:47.877555102+00:00,10,40,38,A,B,0,235.28,200,194,203265,56862,234.32,235.28,200,200,0,0,,,0,0,0,0,,,0,0,0,0,,,0,0,0,0,,,0,0,0,0,,,0,0,0,0,,,0,0,0,0,,,0,0,0,0,,,0,0,0,0,,,0,0,0,0,AAPL
2024-10-22 12:00:47.877722375+00:00,10,40,38,A,B,0,235.28,200,194,203238,56863,,235.28,0,200,0,0,,,0,0,0,0,,,0,0,0,0,,,0,0,0,0,,,0,0,0,0,,,0,0,0,0,,,0,0,0,0,,,0,0,0,0,,,0,0,0,0,,,0,0,0,0,AAPL
2024-10-22 12:00:47.877998656+00:00,10,41,38,A,B,0,235.21,200,194,55914,60762,234.39,235.21,200,200,0,0,,,0,0,0,0,,,0,0,0,0,,,0,0,0,0,,,0,0,0,0,,,0,0,0,0,,,0,0,0,0,,,0,0,0,0,,,0,0,0,0,,,0,0,0,0,AAPL
2024-10-22 12:00:47.878033624+00:00,10,41,38,A,B,0,235.21,200,194,54193,60763,,235.21,0,200,0,0,,,0,0,0,0,,,0,0,0,0,,,0,0,0,0,,,0,0,0,0,,,0,0,0,0,,,0,0,0,0,,,0,0,0,0,,,0,0,0,0,,,0,0,0,0,AAPL
2024-10-22 12:00:47.878688968+00:00,10,39,38,C,B,0,232.4,2000,130,203298,37052,,,0,0,0,0,,,0,0,0,0,,,0,0,0,0,,,0,0,0,0,,,0,0,0,0,,,0,0,0,0,,,0,0,0,0,,,0,0,0,0,,,0,0,0,0,,,0,0,0,0,AAPL
2024-10-22 12:00:47.890842842+00:00,10,39,38,A,B,0,232.4,2000,130,203272,37053,232.4,,2000,0,1,0,,,0,0,0,0,,,0,0,0,0,,,0,0,0,0,,,0,0,0,0,,,0,0,0,0,,,0,0,0,0,,,0,0,0,0,,,0,0,0,0,,,0,0,0,0,AAPL
2024-10-22 12:00:47.893397703+00:00,10,39,38,A,A,0,237.0,2000,130,203201,37054,232.4,237.0,2000,2000,1,1,,,0,0,0,0,,,0,0,0,0,,,0,0,0,0,,,0,0,0,0,,,0,0,0,0,,,0,0,0,0,,,0,0,0,0,,,0,0,0,0,,,0,0,0,0,AAPL
2024-10-22 12:00:47.946243229+00:00,10,39,38,C,A,0,237.0,2000,130,203095,37056,232.4,,2000,0,1,0,,,0,0,0,0,,,0,0,0,0,,,0,0,0,0,,,0,0,0,0,,,0,0,0,0,,,0,0,0,0,,,0,0,0,0,,,0,0,0,0,,,0,0,0,0,AAPL
2024-10-22 12:00:47.947137147+00:00,10,39,38,C,B,0,232.4,2000,130,203079,37057,,,0,0,0,0,,,0,0,0,0,,,0,0,0,0,,,0,0,0,0,,,0,0,0,0,,,0,0,0,0,,,0,0,0,0,,,0,0,0,0,,,0,0,0,0,,,0,0,0,0,AAPL
2024-10-22 12:00:47.957364591+00:00,10,39,38,A,A,0,237.2,2000,130,203167,37058,,237.2,0,2000,0,1,,,0,0,0,0,,,0,0,0,0,,,0,0,0,0,,,0,0,0,0,,,0,0,0,0,,,0,0,0,0,,,0,0,0,0,,,0,0,0,0,,,0,0,0,0,AAPL
2024-10-22 12:00:47.973827490+00:00,10,39,38,A,B,0,232.4,2000,130,203130,37059,232.4,237.2,2000,2000,1,1,,,0,0,0,0,,,0,0,0,0,,,0,0,0,0,,,0,0,0,0,,,0,0,0,0,,,0,0,0,0,,,0,0,0,0,,,0,0,0,0,,,0,0,0,0,AAPL
2024-10-22 12:00:48.114181289+00:00,10,40,38,A,B,0,235.28,200,194,203226,56871,234.31,235.28,200,200,0,0,,,0,0,0,0,,,0,0,0,0,,,0,0,0,0,,,0,0,0,0,,,0,0,0,0,,,0,0,0,0,,,0,0,0,0,,,0,0,0,0,,,0,0,0,0,AAPL
2024-10-22 12:00:48.114515319+00:00,10,41,38,A,B,0,235.21,200,194,55707,60777,234.38,235.21,200,200,0,0,,,0,0,0,0,,,0,0,0,0,,,0,0,0,0,,,0,0,0,0,,,0,0,0,0,,,0,0,0,0,,,0,0,0,0,,,0,0,0,0,,,0,0,0,0,AAPL
2024-10-22 12:00:54.058396869+00:00,10,41,38,A,B,0,235.21,200,194,56060,61002,,235.21,0,200,0,0,,,0,0,0,0,,,0,0,0,0,,,0,0,0,0,,,0,0,0,0,,,0,0,0,0,,,0,0,0,0,,,0,0,0,0,,,0,0,0,0,,,0,0,0,0,AAPL
2024-10-22 12:00:56.152490568+00:00,10,41,38,A,B,0,235.21,200,194,55665,61081,234.38,235.21,200,200,0,0,,,0,0,0,0,,,0,0,0,0,,,0,0,0,0,,,0,0,0,0,,,0,0,0,0,,,0,0,0,0,,,0,0,0,0,,,0,0,0,0,,,0,0,0,0,AAPL
2024-10-22 12:00:57.506367815+00:00,10,40,38,A,B,0,235.28,200,194,203831,56990,,235.28,0,200,0,0,,,0,0,0,0,,,0,0,0,0,,,0,0,0,0,,,0,0,0,0,,,0,0,0,0,,,0,0,0,0,,,0,0,0,0,,,0,0,0,0,,,0,0,0,0,AAPL
2024-10-22 12:00:57.806995356+00:00,10,41,38,A,B,0,235.21,200,194,55390,61146,,235.21,0,200,0,0,,,0,0,0,0,,,0,0,0,0,,,0,0,0,0,,,0,0,0,0,,,0,0,0,0,,,0,0,0,0,,,0,0,0,0,,,0,0,0,0,,,0,0,0,0,AAPL
2024-10-22 12:01:03.047516578+00:00,10,39,38,A,A,0,236.8,2000,130,203153,37156,232.4,236.8,2000,2000,1,1,,237.2,0,2000,0,1,,,0,0,0,0,,,0,0,0,0,,,0,0,0,0,,,0,0,0,0,,,0,0,0,0,,,0,0,0,0,,,0,0,0,0,,,0,0,0,0,AAPL
2024-10-22 12:01:03.047694567+00:00,10,39,38,C,A,1,237.2,2000,130,203076,37157,232.4,236.8,2000,2000,1,1,,,0,0,0,0,,,0,0,0,0,,,0,0,0,0,,,0,0,0,0,,,0,0,0,0,,,0,0,0,0,,,0,0,0,0,,,0,0,0,0,,,0,0,0,0,AAPL
2024-10-22 12:01:03.071302108+00:00,10,39,38,C,A,0,236.8,2000,130,203061,37160,232.4,,2000,0,1,0,,,0,0,0,0,,,0,0,0,0,,,0,0,0,0,,,0,0,0,0,,,0,0,0,0,,,0,0,0,0,,,0,0,0,0,,,0,0,0,0,,,0,0,0,0,AAPL
2024-10-22 12:01:03.082328071+00:00,10,39,38,A,A,0,237.0,2000,130,203212,37161,232.4,237.0,2000,2000,1,1,,,0,0,0,0,,,0,0,0,0,,,0,0,0,0,,,0,0,0,0,,,0,0,0,0,,,0,0,0,0,,,0,0,0,0,,,0,0,0,0,,,0,0,0,0,AAPL
2024-10-22 12:01:03.098009143+00:00,10,39,38,C,A,0,237.0,2000,130,203111,37163,232.4,,2000,0,1,0,,,0,0,0,0,,,0,0,0,0,,,0,0,0,0,,,0,0,0,0,,,0,0,0,0,,,0,0,0,0,,,0,0,0,0,,,0,0,0,0,,,0,0,0,0,AAPL
2024-10-22 12:01:03.115294375+00:00,10,39,38,A,A,0,237.2,2000,130,203151,37164,232.4,237.2,2000,2000,1,1,,,0,0,0,0,,,0,0,0,0,,,0,0,0,0,,,0,0,0,0,,,0,0,0,0,,,0,0,0,0,,,0,0,0,0,,,0,0,0,0,,,0,0,0,0,AAPL
2024-10-22 12:01:04.058082412+00:00,10,39,38,C,A,0,237.2,2000,130,203067,37185,232.4,,2000,0,1,0,,,0,0,0,0,,,0,0,0,0,,,0,0,0,0,,,0,0,0,0,,,0,0,0,0,,,0,0,0,0,,,0,0,0,0,,,0,0,0,0,,,0,0,0,0,AAPL
2024-10-22 12:01:04.068188276+00:00,10,40,38,A,B,0,235.28,200,194,203468,57289,234.31,235.28,200,200,0,0,,,0,0,0,0,,,0,0,0,0,,,0,0,0,0,,,0,0,0,0,,,0,0,0,0,,,0,0,0,0,,,0,0,0,0,,,0,0,0,0,,,0,0,0,0,AAPL
2024-10-22 12:01:04.068544149+00:00,10,41,38,A,B,0,235.21,200,194,63012,62431,234.38,235.21,200,200,0,0,,,0,0,0,0,,,0,0,0,0,,,0,0,0,0,,,0,0,0,0,,,0,0,0,0,,,0,0,0,0,,,0,0,0,0,,,0,0,0,0,,,0,0,0,0,AAPL
2024-10-22 12:01:04.068856667+00:00,10,39,38,C,B,0,232.4,2000,130,203032,37188,,,0,0,0,0,,,0,0,0,0,,,0,0,0,0,,,0,0,0,0,,,0,0,0,0,,,0,0,0,0,,,0,0,0,0,,,0,0,0,0,,,0,0,0,0,,,0,0,0,0,AAPL
2024-10-22 12:01:04.079787389+00:00,10,39,38,A,A,0,236.8,2000,130,203136,37191,,236.8,0,2000,0,1,,,0,0,0,0,,,0,0,0,0,,,0,0,0,0,,,0,0,0,0,,,0,0,0,0,,,0,0,0,0,,,0,0,0,0,,,0,0,0,0,,,0,0,0,0,AAPL
2024-10-22 12:01:04.103657506+00:00,10,39,38,C,A,0,236.8,2000,130,203208,37194,,,0,0,0,0,,,0,0,0,0,,,0,0,0,0,,,0,0,0,0,,,0,0,0,0,,,0,0,0,0,,,0,0,0,0,,,0,0,0,0,,,0,0,0,0,,,0,0,0,0,AAPL
2024-10-22 12:01:04.105622188+00:00,10,39,38,A,B,0,232.6,2000,130,203121,37195,232.6,,2000,0,1,0,,,0,0,0,0,,,0,0,0,0,,,0,0,0,0,,,0,0,0,0,,,0,0,0,0,,,0,0,0,0,,,0,0,0,0,,,0,0,0,0,,,0,0,0,0,AAPL
2024-10-22 12:01:04.114812375+00:00,10,39,38,A,A,0,236.8,2000,130,203127,37196,232.6,236.8,2000,2000,1,1,,,0,0,0,0,,,0,0,0,0,,,0,0,0,0,,,0,0,0,0,,,0,0,0,0,,,0,0,0,0,,,0,0,0,0,,,0,0,0,0,,,0,0,0,0,AAPL
2024-10-22 12:01:04.132429199+00:00,10,39,38,C,A,0,236.8,2000,130,203108,37197,232.6,,2000,0,1,0,,,0,0,0,0,,,0,0,0,0,,,0,0,0,0,,,0,0,0,0,,,0,0,0,0,,,0,0,0,0,,,0,0,0,0,,,0,0,0,0,,,0,0,0,0,AAPL
2024-10-22 12:01:04.144034730+00:00,10,39,38,A,A,0,237.0,2000,130,203198,37198,232.6,237.0,2000,2000,1,1,,,0,0,0,0,,,0,0,0,0,,,0,0,0,0,,,0,0,0,0,,,0,0,0,0,,,0,0,0,0,,,0,0,0,0,,,0,0,0,0,,,0,0,0,0,AAPL
2024-10-22 12:01:05.291709145+00:00,10,40,38,A,B,0,235.28,200,194,203618,57327,,235.28,0,200,0,0,,,0,0,0,0,,,0,0,0,0,,,0,0,0,0,,,0,0,0,0,,,0,0,0,0,,,0,0,0,0,,,0,0,0,0,,,0,0,0,0,,,0,0,0,0,AAPL
2024-10-22 12:01:09.398811412+00:00,10,40,38,A,B,0,235.28,200,194,203568,57390,234.32,235.28,200,200,0,0,,,0,0,0,0,,,0,0,0,0,,,0,0,0,0,,,0,0,0,0,,,0,0,0,0,,,0,0,0,0,,,0,0,0,0,,,0,0,0,0,,,0,0,0,0,AAPL
2024-10-22 12:01:10.609691738+00:00,10,39,38,A,A,0,236.8,2000,130,203471,37240,232.6,236.8,2000,2000,1,1,,237.0,0,2000,0,1,,,0,0,0,0,,,0,0,0,0,,,0,0,0,0,,,0,0,0,0,,,0,0,0,0,,,0,0,0,0,,,0,0,0,0,,,0,0,0,0,AAPL
2024-10-22 12:01:10.610241643+00:00,10,39,38,C,A,1,237.0,2000,130,203255,37241,232.6,236.8,2000,2000,1,1,,,0,0,0,0,,,0,0,0,0,,,0,0,0,0,,,0,0,0,0,,,0,0,0,0,,,0,0,0,0,,,0,0,0,0,,,0,0,0,0,,,0,0,0,0,AAPL
2024-10-22 12:01:23.211279200+00:00,10,39,38,C,B,0,232.6,2000,130,203408,37328,,236.8,0,2000,0,1,,,0,0,0,0,,,0,0,0,0,,,0,0,0,0,,,0,0,0,0,,,0,0,0,0,,,0,0,0,0,,,0,0,0,0,,,0,0,0,0,,,0,0,0,0,AAPL
2024-10-22 12:01:23.212568825+00:00,10,39,38,C,A,0,236.8,2000,130,203365,37329,,,0,0,0,0,,,0,0,0,0,,,0,0,0,0,,,0,0,0,0,,,0,0,0,0,,,0,0,0,0,,,0,0,0,0,,,0,0,0,0,,,0,0,0,0,,,0,0,0,0,AAPL
2024-10-22 12:01:23.242696677+00:00,10,39,38,A,A,0,237.0,2000,130,203390,37333,,237.0,0,2000,0,1,,,0,0,0,0,,,0,0,0,0,,,0,0,0,0,,,0,0,0,0,,,0,0,0,0,,,0,0,0,0,,,0,0,0,0,,,0,0,0,0,,,0,0,0,0,AAPL
2024-10-22 12:01:23.246724656+00:00,10,39,38,A,B,0,232.6,2000,130,203403,37334,232.6,237.0,2000,2000,1,1,,,0,0,0,0,,,0,0,0,0,,,0,0,0,0,,,0,0,0,0,,,0,0,0,0,,,0,0,0,0,,,0,0,0,0,,,0,0,0,0,,,0,0,0,0,AAPL
2024-10-22 12:01:23.251576588+00:00,10,39,38,C,B,0,232.6,2000,130,203354,37336,,237.0,0,2000,0,1,,,0,0,0,0,,,0,0,0,0,,,0,0,0,0,,,0,0,0,0,,,0,0,0,0,,,0,0,0,0,,,0,0,0,0,,,0,0,0,0,,,0,0,0,0,AAPL
2024-10-22 12:01:23.262388016+00:00,10,39,38,A,B,0,232.4,2000,130,203421,37338,232.4,237.0,2000,2000,1,1,,,0,0,0,0,,,0,0,0,0,,,0,0,0,0,,,0,0,0,0,,,0,0,0,0,,,0,0,0,0,,,0,0,0,0,,,0,0,0,0,,,0,0,0,0,AAPL
2024-10-22 12:01:23.276553862+00:00,10,39,38,A,B,0,232.6,2000,130,203382,37343,232.6,237.0,2000,2000,1,1,232.4,,2000,0,1,0,,,0,0,0,0,,,0,0,0,0,,,0,0,0,0,,,0,0,0,0,,,0,0,0,0,,,0,0,0,0,,,0,0,0,0,,,0,0,0,0,AAPL
2024-10-22 12:01:23.276752306+00:00,10,39,38,C,B,1,232.4,2000,130,203386,37344,232.6,237.0,2000,2000,1,1,,,0,0,0,0,,,0,0,0,0,,,0,0,0,0,,,0,0,0,0,,,0,0,0,0,,,0,0,0,0,,,0,0,0,0,,,0,0,0,0,,,0,0,0,0,AAPL
2024-10-22 12:01:23.346785174+00:00,10,40,38,A,B,0,235.28,200,194,203386,57591,,235.28,0,200,0,0,,,0,0,0,0,,,0,0,0,0,,,0,0,0,0,,,0,0,0,0,,,0,0,0,0,,,0,0,0,0,,,0,0,0,0,,,0,0,0,0,,,0,0,0,0,AAPL
2024-10-22 12:01:23.347114753+00:00,10,41,38,A,B,0,235.21,200,194,55278,63163,,235.21,0,200,0,0,,,0,0,0,0,,,0,0,0,0,,,0,0,0,0,,,0,0,0,0,,,0,0,0,0,,,0,0,0,0,,,0,0,0,0,,,0,0,0,0,,,0,0,0,0,AAPL
2024-10-22 12:01:25.096359183+00:00,10,40,38,A,A,0,,0,194,203515,57620,,,0,0,0,0,,,0,0,0,0,,,0,0,0,0,,,0,0,0,0,,,0,0,0,0,,,0,0,0,0,,,0,0,0,0,,,0,0,0,0,,,0,0,0,0,,,0,0,0,0,AAPL
2024-10-22 12:01:25.682888091+00:00,10,40,38,A,B,0,,0,194,203552,57625,234.29,,200,0,0,0,,,0,0,0,0,,,0,0,0,0,,,0,0,0,0,,,0,0,0,0,,,0,0,0,0,,,0,0,0,0,,,0,0,0,0,,,0,0,0,0,,,0,0,0,0,AAPL
2024-10-22 12:01:25.682895291+00:00,10,40,38,A,A,0,235.27,200,194,203511,57626,234.29,235.27,200,200,0,0,,,0,0,0,0,,,0,0,0,0,,,0,0,0,0,,,0,0,0,0,,,0,0,0,0,,,0,0,0,0,,,0,0,0,0,,,0,0,0,0,,,0,0,0,0,AAPL
2024-10-22 12:01:25.683251494+00:00,10,41,38,A,B,0,235.21,200,194,55995,63278,234.36,235.21,200,200,0,0,,,0,0,0,0,,,0,0,0,0,,,0,0,0,0,,,0,0,0,0,,,0,0,0,0,,,0,0,0,0,,,0,0,0,0,,,0,0,0,0,,,0,0,0,0,AAPL
2024-10-22 12:01:28.781421071+00:00,10,39,38,C,A,0,237.0,2000,130,203488,37409,232.6,,2000,0,1,0,,,0,0,0,0,,,0,0,0,0,,,0,0,0,0,,,0,0,0,0,,,0,0,0,0,,,0,0,0,0,,,0,0,0,0,,,0,0,0,0,,,0,0,0,0,AAPL
2024-10-22 12:01:28.793517305+00:00,10,39,38,A,A,0,237.2,2000,130,203287,37410,232.6,237.2,2000,2000,1,1,,,0,0,0,0,,,0,0,0,0,,,0,0,0,0,,,0,0,0,0,,,0,0,0,0,,,0,0,0,0,,,0,0,0,0,,,0,0,0,0,,,0,0,0,0,AAPL
2024-10-22 12:01:35.824532516+00:00,10,39,38,A,A,0,236.8,2000,130,203769,37434,232.6,236.8,2000,2000,1,1,,237.2,0,2000,0,1,,,0,0,0,0,,,0,0,0,0,,,0,0,0,0,,,0,0,0,0,,,0,0,0,0,,,0,0,0,0,,,0,0,0,0,,,0,0,0,0,AAPL
2024-10-22 12:01:35.824725274+00:00,10,39,38,C,A,1,237.2,2000,130,203251,37435,232.6,236.8,2000,2000,1,1,,,0,0,0,0,,,0,0,0,0,,,0,0,0,0,,,0,0,0,0,,,0,0,0,0,,,0,0,0,0,,,0,0,0,0,,,0,0,0,0,,,0,0,0,0,AAPL
2024-10-22 12:01:35.855492136+00:00,10,39,38,C,A,0,236.8,2000,130,203265,37436,232.6,,2000,0,1,0,,,0,0,0,0,,,0,0,0,0,,,0,0,0,0,,,0,0,0,0,,,0,0,0,0,,,0,0,0,0,,,0,0,0,0,,,0,0,0,0,,,0,0,0,0,AAPL
2024-10-22 12:01:35.855583002+00:00,10,40,38,A,B,0,235.27,200,194,203697,57743,,235.27,0,200,0,0,,,0,0,0,0,,,0,0,0,0,,,0,0,0,0,,,0,0,0,0,,,0,0,0,0,,,0,0,0,0,,,0,0,0,0,,,0,0,0,0,,,0,0,0,0,AAPL
2024-10-22 12:01:35.866344453+00:00,10,39,38,A,A,0,237.0,2000,130,203338,37437,232.6,237.0,2000,2000,1,1,,,0,0,0,0,,,0,0,0,0,,,0,0,0,0,,,0,0,0,0,,,0,0,0,0,,,0,0,0,0,,,0,0,0,0,,,0,0,0,0,,,0,0,0,0,AAPL
2024-10-22 12:01:35.909770772+00:00,10,40,38,A,A,0,,0,194,203699,57744,,,0,0,0,0,,,0,0,0,0,,,0,0,0,0,,,0,0,0,0,,,0,0,0,0,,,0,0,0,0,,,0,0,0,0,,,0,0,0,0,,,0,0,0,0,,,0,0,0,0,AAPL
2024-10-22 12:01:35.909793677+00:00,10,40,38,A,A,0,235.13,200,194,203593,57745,,235.13,0,200,0,0,,,0,0,0,0,,,0,0,0,0,,,0,0,0,0,,,0,0,0,0,,,0,0,0,0,,,0,0,0,0,,,0,0,0,0,,,0,0,0,0,,,0,0,0,0,AAPL
2024-10-22 12:01:35.910087272+00:00,10,41,38,A,B,0,235.21,200,194,61843,63677,,235.21,0,200,0,0,,,0,0,0,0,,,0,0,0,0,,,0,0,0,0,,,0,0,0,0,,,0,0,0,0,,,0,0,0,0,,,0,0,0,0,,,0,0,0,0,,,0,0,0,0,AAPL
2024-10-22 12:01:36.100315647+00:00,10,41,38,A,A,0,,0,194,56167,63679,,,0,0,0,0,,,0,0,0,0,,,0,0,0,0,,,0,0,0,0,,,0,0,0,0,,,0,0,0,0,,,0,0,0,0,,,0,0,0,0,,,0,0,0,0,,,0,0,0,0,AAPL
2024-10-22 12:01:36.100390676+00:00,10,41,38,A,A,0,235.06,200,194,55443,63680,,235.06,0,200,0,0,,,0,0,0,0,,,0,0,0,0,,,0,0,0,0,,,0,0,0,0,,,0,0,0,0,,,0,0,0,0,,,0,0,0,0,,,0,0,0,0,,,0,0,0,0,AAPL
2024-10-22 12:01:36.371607493+00:00,10,40,38,A,B,0,235.13,200,194,203547,57756,234.25,235.13,200,200,0,0,,,0,0,0,0,,,0,0,0,0,,,0,0,0,0,,,0,0,0,0,,,0,0,0,0,,,0,0,0,0,,,0,0,0,0,,,0,0,0,0,,,0,0,0,0,AAPL
2024-10-22 12:01:36.372348731+00:00,10,41,38,A,B,0,235.06,200,194,57148,63682,234.32,235.06,200,200,0,0,,,0,0,0,0,,,0,0,0,0,,,0,0,0,0,,,0,0,0,0,,,0,0,0,0,,,0,0,0,0,,,0,0,0,0,,,0,0,0,0,,,0,0,0,0,AAPL
2024-10-22 12:01:36.575408784+00:00,10,40,38,A,B,0,235.13,200,194,203704,57757,,235.13,0,200,0,0,,,0,0,0,0,,,0,0,0,0,,,0,0,0,0,,,0,0,0,0,,,0,0,0,0,,,0,0,0,0,,,0,0,0,0,,,0,0,0,0,,,0,0,0,0,AAPL
2024-10-22 12:01:36.575744342+00:00,10,41,38,A,B,0,235.06,200,194,62727,63684,,235.06,0,200,0,0,,,0,0,0,0,,,0,0,0,0,,,0,0,0,0,,,0,0,0,0,,,0,0,0,0,,,0,0,0,0,,,0,0,0,0,,,0,0,0,0,,,0,0,0,0,AAPL
2024-10-22 12:01:39.442607887+00:00,10,40,38,A,B,0,235.13,200,194,203596,57771,234.26,235.13,200,200,0,0,,,0,0,0,0,,,0,0,0,0,,,0,0,0,0,,,0,0,0,0,,,0,0,0,0,,,0,0,0,0,,,0,0,0,0,,,0,0,0,0,,,0,0,0,0,AAPL
2024-10-22 12:01:39.443193137+00:00,10,41,38,A,B,0,235.06,200,194,61880,63754,234.33,235.06,200,200,0,0,,,0,0,0,0,,,0,0,0,0,,,0,0,0,0,,,0,0,0,0,,,0,0,0,0,,,0,0,0,0,,,0,0,0,0,,,0,0,0,0,,,0,0,0,0,AAPL
2024-10-22 12:01:39.598798215+00:00,10,40,38,A,B,0,235.13,200,194,203773,57772,,235.13,0,200,0,0,,,0,0,0,0,,,0,0,0,0,,,0,0,0,0,,,0,0,0,0,,,0,0,0,0,,,0,0,0,0,,,0,0,0,0,,,0,0,0,0,,,0,0,0,0,AAPL
2024-10-22 12:01:39.599497456+00:00,10,41,38,A,B,0,235.06,200,194,56301,63759,,235.06,0,200,0,0,,,0,0,0,0,,,0,0,0,0,,,0,0,0,0,,,0,0,0,0,,,0,0,0,0,,,0,0,0,0,,,0,0,0,0,,,0,0,0,0,,,0,0,0,0,AAPL
2024-10-22 12:01:39.738741159+00:00,10,40,38,A,B,0,235.13,200,194,203640,57773,234.25,235.13,200,200,0,0,,,0,0,0,0,,,0,0,0,0,,,0,0,0,0,,,0,0,0,0,,,0,0,0,0,,,0,0,0,0,,,0,0,0,0,,,0,0,0,0,,,0,0,0,0,AAPL
2024-10-22 12:01:39.739175397+00:00,10,41,38,A,B,0,235.06,200,194,55930,63765,234.32,235.06,200,200,0,0,,,0,0,0,0,,,0,0,0,0,,,0,0,0,0,,,0,0,0,0,,,0,0,0,0,,,0,0,0,0,,,0,0,0,0,,,0,0,0,0,,,0,0,0,0,AAPL
2024-10-22 12:01:39.739449323+00:00,10,39,38,C,B,0,232.6,2000,130,203225,37448,,237.0,0,2000,0,1,,,0,0,0,0,,,0,0,0,0,,,0,0,0,0,,,0,0,0,0,,,0,0,0,0,,,0,0,0,0,,,0,0,0,0,,,0,0,0,0,,,0,0,0,0,AAPL
2024-10-22 12:01:40.269933836+00:00,10,39,38,A,B,0,232.4,2000,130,203664,37450,232.4,237.0,2000,2000,1,1,,,0,0,0,0,,,0,0,0,0,,,0,0,0,0,,,0,0,0,0,,,0,0,0,0,,,0,0,0,0,,,0,0,0,0,,,0,0,0,0,,,0,0,0,0,AAPL
2024-10-22 12:01:41.057392522+00:00,10,39,38,A,B,0,232.6,2000,130,203633,37457,232.6,237.0,2000,2000,1,1,232.4,,2000,0,1,0,,,0,0,0,0,,,0,0,0,0,,,0,0,0,0,,,0,0,0,0,,,0,0,0,0,,,0,0,0,0,,,0,0,0,0,,,0,0,0,0,AAPL
2024-10-22 12:01:41.057573207+00:00,10,39,38,C,B,1,232.4,2000,130,203293,37458,232.6,237.0,2000,2000,1,1,,,0,0,0,0,,,0,0,0,0,,,0,0,0,0,,,0,0,0,0,,,0,0,0,0,,,0,0,0,0,,,0,0,0,0,,,0,0,0,0,,,0,0,0,0,AAPL
2024-10-22 12:01:41.078522103+00:00,10,39,38,C,B,0,232.6,2000,130,203208,37459,,237.0,0,2000,0,1,,,0,0,0,0,,,0,0,0,0,,,0,0,0,0,,,0,0,0,0,,,0,0,0,0,,,0,0,0,0,,,0,0,0,0,,,0,0,0,0,,,0,0,0,0,AAPL
2024-10-22 12:01:41.089558745+00:00,10,39,38,A,B,0,232.4,2000,130,203274,37460,232.4,237.0,2000,2000,1,1,,,0,0,0,0,,,0,0,0,0,,,0,0,0,0,,,0,0,0,0,,,0,0,0,0,,,0,0,0,0,,,0,0,0,0,,,0,0,0,0,,,0,0,0,0,AAPL
2024-10-22 12:01:43.364427385+00:00,10,39,38,C,B,0,232.4,2000,130,203241,37475,,237.0,0,2000,0,1,,,0,0,0,0,,,0,0,0,0,,,0,0,0,0,,,0,0,0,0,,,0,0,0,0,,,0,0,0,0,,,0,0,0,0,,,0,0,0,0,,,0,0,0,0,AAPL
2024-10-22 12:01:43.401398991+00:00,10,39,38,A,B,0,232.6,2000,130,203333,37476,232.6,237.0,2000,2000,1,1,,,0,0,0,0,,,0,0,0,0,,,0,0,0,0,,,0,0,0,0,,,0,0,0,0,,,0,0,0,0,,,0,0,0,0,,,0,0,0,0,,,0,0,0,0,AAPL
2024-10-22 12:01:43.459267138+00:00,10,39,38,C,B,0,232.6,2000,130,203230,37477,,237.0,0,2000,0,1,,,0,0,0,0,,,0,0,0,0,,,0,0,0,0,,,0,0,0,0,,,0,0,0,0,,,0,0,0,0,,,0,0,0,0,,,0,0,0,0,,,0,0,0,0,AAPL
2024-10-22 12:01:43.471385080+00:00,10,39,38,A,B,0,232.6,2000,130,203332,37478,232.6,237.0,2000,2000,1,1,,,0,0,0,0,,,0,0,0,0,,,0,0,0,0,,,0,0,0,0,,,0,0,0,0,,,0,0,0,0,,,0,0,0,0,,,0,0,0,0,,,0,0,0,0,AAPL
2024-10-22 12:01:43.472107331+00:00,10,41,38,A,B,0,235.06,200,194,55320,63887,,235.06,0,200,0,0,,,0,0,0,0,,,0,0,0,0,,,0,0,0,0,,,0,0,0,0,,,0,0,0,0,,,0,0,0,0,,,0,0,0,0,,,0,0,0,0,,,0,0,0,0,AAPL
2024-10-22 12:01:44.519620460+00:00,10,40,38,A,B,0,235.13,200,194,203642,57853,,235.13,0,200,0,0,,,0,0,0,0,,,0,0,0,0,,,0,0,0,0,,,0,0,0,0,,,0,0,0,0,,,0,0,0,0,,,0,0,0,0,,,0,0,0,0,,,0,0,0,0,AAPL
2024-10-22 12:01:45.091892616+00:00,10,40,38,A,B,0,235.13,200,194,203784,57862,234.18,235.13,200,200,0,0,,,0,0,0,0,,,0,0,0,0,,,0,0,0,0,,,0,0,0,0,,,0,0,0,0,,,0,0,0,0,,,0,0,0,0,,,0,0,0,0,,,0,0,0,0,AAPL
2024-10-22 12:01:45.092590223+00:00,10,41,38,A,B,0,235.06,200,194,56006,63920,234.25,235.06,200,200,0,0,,,0,0,0,0,,,0,0,0,0,,,0,0,0,0,,,0,0,0,0,,,0,0,0,0,,,0,0,0,0,,,0,0,0,0,,,0,0,0,0,,,0,0,0,0,AAPL
2024-10-22 12:01:45.292559487+00:00,10,40,38,A,B,0,235.13,200,194,203652,57865,,235.13,0,200,0,0,,,0,0,0,0,,,0,0,0,0,,,0,0,0,0,,,0,0,0,0,,,0,0,0,0,,,0,0,0,0,,,0,0,0,0,,,0,0,0,0,,,0,0,0,0,AAPL
